<?xml version="1.0" ?>
<!-- =================================================================================== -->
<!-- |    This document was autogenerated by xacro from WheeledAtlas.urdf.xacro        | -->
<!-- |    EDITING THIS FILE BY HAND IS NOT RECOMMENDED                                 | -->
<!-- =================================================================================== -->

<robot name="wheeled_atlas" xmlns:body="http://playerstage.sourceforge.net/gazebo/xmlschema/#body" xmlns:controller="http://playerstage.sourceforge.net/gazebo/xmlschema/#controller" xmlns:geom="http://playerstage.sourceforge.net/gazebo/xmlschema/#geom" xmlns:interface="http://playerstage.sourceforge.net/gazebo/xmlschema/#interface" xmlns:joint="http://playerstage.sourceforge.net/gazebo/xmlschema/#slider" xmlns:sensor="http://playerstage.sourceforge.net/gazebo/xmlschema/#sensor" xmlns:xacro="http://ros.org/wiki/xacro">
  <!--Properties of the robot-->
  <!--Inertial element for cylinder, axis along z-->
  <!--Inertial element for a box-->
  <!--Create the visual element for a cylinder-->
  <!--Create the visual element for a box-->
  <!--Creates a link in the form of a cylinder-->
  <!--Creates a link in the form of a box-->
  <!--Creates a simple joint between two cylindrical links.-->
  <!--Creates a simple joint between two cylindrical links.-->
  <!--Creates a simple fixed joint-->
  <!--Creates a left and a right of some cylinder-->
  <!--Creates a left and a right of some cylinder-->
  <!--Creates a SIMPLE left and a right joints-->
  <!--Creates a COMPLEX left and a right joints-->
  <!--Creates a COMPLEX left and a right joints-->
  <!--Creates two fixed joints-->
  <!--Creates a transmission at a joint.-->
  <!--Creates a pair of transmissions-->

  <material name="LightGrey">
    <color rgba="0.8 0.8 0.8 1.0"/>
  </material>
  <material name="Grey">
    <color rgba="0.6 0.6 0.6 1.0"/>
  </material>
  <material name="DarkGrey">
    <color rgba="0.3 0.3 0.3 1.0"/>
  </material>
  <material name="Black">
    <color rgba="0.1 0.1 0.1 1.0"/>
  </material> 


<link name="Torso">
    <!-- assuming the rotational inertia of the torso is of a cuboid -->
    <inertial>
      <mass value="19.267"/>
      <inertia ixx="0.769042349872" ixy="0.0" ixz="0.0" iyy="0.418881944536" iyz="0.0" izz="0.452546488768"/>
    </inertial>
    <visual>
      <origin rpy="0 0 0" xyz="0.0 0.0 0.43927308"/>
      <geometry>
        <cylinder length="0.97854616" radius="0.025"/>
      </geometry>
    </visual>
    <collision>
      <origin rpy="0 0 0" xyz="0.0 0.0 0.43927308"/>
      <geometry>
        <box size=" 0.178562 0.4999736 0.97854616"/>
      </geometry>
    </collision>
  </link>

   <link name="NeckYaw_link">
    <inertial>
      <mass value="0.9"/>
      <inertia ixx="0.00530271247008" ixy="0.0" ixz="0.0" iyy="0.00530271247008" iyz="0.0" izz="0.00201768391825"/>
    </inertial>
  </link>
  <link name="NeckPitch_link">
    <inertial>
      <mass value="0.9"/>
      <inertia ixx="0.00530271247008" ixy="0.0" ixz="0.0" iyy="0.00530271247008" iyz="0.0" izz="0.00201768391825"/>
    </inertial>
    <visual>
      <origin rpy="1.57079632679 0 0" xyz="0 0 0.13749274"/>
      <geometry>
        <cylinder length="0.22141688" radius="0.06696075"/>
        <!--  <sphere radius="${(l_head/2)*height}"/>-->
      </geometry>
    </visual>
    <collision>
      <origin rpy="1.57 0 0" xyz="0 0 0.13749274"/>
      <geometry>
        <cylinder length="0.23927308" radius="0.06696075"/>
      </geometry>
    </collision>
  </link>
   <link name="LShoulderYaw_link">
    <inertial>
      <mass value="2.18522222222"/>
     <inertia ixx="0.0231667622255" ixy="0.0" ixz="0.0" iyy="0.0231667622255" iyz="0.0" izz="0.00217732727683"/>
    </inertial>
  </link>
  <link name="LShoulderPitch_link">
    <inertial>
      <mass value="2.18522222222"/>
      <inertia ixx="0.0231667622255" ixy="0.0" ixz="0.0" iyy="0.0231667622255" iyz="0.0" izz="0.00217732727683"/>
    </inertial>
  </link>
  <link name="LShoulderRoll_link">
    <inertial>
      <mass value="2.18522222222"/>
      <inertia ixx="0.0231667622255" ixy="0.0" ixz="0.0" iyy="0.0231667622255" iyz="0.0" izz="0.00217732727683"/>
    </inertial>
    <visual>
      <origin rpy="0 0 0" xyz="0 0 -0.17409795"/>
      <geometry>
        <cylinder length="0.3081959" radius="0.025"/>
      </geometry>
    </visual>
    <collision>
      <origin rpy="0 0 0" xyz="0 0 -0.17409795"/>
      <geometry>
        <cylinder length="0.3481959" radius="0.025"/>
      </geometry>
    </collision>
  </link>
  <link name="LElbowPitch_link">
    <inertial>
      <mass value="3.27783333333"/>
      <inertia ixx="0.0268028987778" ixy="0.0" ixz="0.0" iyy="0.0268028987778" iyz="0.0" izz="0.00326599091525"/>
    </inertial>
    <visual>
      <origin rpy="0 0 0" xyz="0 0 -0.1517777"/>
      <geometry>
        <cylinder length="0.2635554" radius="0.025"/>
      </geometry>
    </visual>
    <collision>
      <origin rpy="0 0 0" xyz="0 0 -0.1517777"/>
      <geometry>
        <cylinder length="0.3035554" radius="0.025"/>
      </geometry>
    </collision>
  </link>
  <link name="LWristYaw_link">
    <inertial>
      <mass value="1.0"/>
      <inertia ixx="0.0048720194876" ixy="0.0" ixz="0.0" iyy="0.0048720194876" iyz="0.0" izz="0.00199277424025"/>
    </inertial>
  </link>
  <link name="LWristRoll_link">
    <inertial>
      <mass value="1.0"/>
  <inertia ixx="0.0048720194876" ixy="0.0" ixz="0.0" iyy="0.0048720194876" iyz="0.0" izz="0.00199277424025"/>
    </inertial>
    <visual>
      <origin rpy="0 0 0" xyz="0 0 -0.076245974"/>
      <geometry>
        <cylinder length="0.112491948" radius="0.025"/>
      </geometry>
    </visual>
    <collision>
      <origin rpy="0 0 0" xyz="0 0 -0.076245974"/>
      <geometry>
        <cylinder length="0.152491948" radius="0.025"/>
      </geometry>
    </collision>
  </link>
  <link name="RShoulderYaw_link">
    <inertial>
      <mass value="2.18522222222"/>
      <inertia ixx="0.0231667622255" ixy="0.0" ixz="0.0" iyy="0.0231667622255" iyz="0.0" izz="0.00217732727683"/>
    </inertial>
  </link>
  <link name="RShoulderPitch_link">
    <inertial>
      <mass value="2.18522222222"/>
      <inertia ixx="0.0231667622255" ixy="0.0" ixz="0.0" iyy="0.0231667622255" iyz="0.0" izz="0.00217732727683"/>
    </inertial>
  </link>
  <link name="RShoulderRoll_link">
    <inertial>
      <mass value="2.18522222222"/>
      <inertia ixx="0.0231667622255" ixy="0.0" ixz="0.0" iyy="0.0231667622255" iyz="0.0" izz="0.00217732727683"/>
    </inertial>
    <visual>
      <origin rpy="0 0 0" xyz="0 0 -0.17409795"/>
      <geometry>
        <cylinder length="0.3081959" radius="0.025"/>
      </geometry>
    </visual>
    <collision>
      <origin rpy="0 0 0" xyz="0 0 -0.17409795"/>
      <geometry>
        <cylinder length="0.3481959" radius="0.025"/>
      </geometry>
    </collision>
  </link>
  <link name="RElbowPitch_link">
    <inertial>
      <mass value="3.27783333333"/>
      <inertia ixx="0.0268028987778" ixy="0.0" ixz="0.0" iyy="0.0268028987778" iyz="0.0" izz="0.00326599091525"/>
    </inertial>
    <visual>
      <origin rpy="0 0 0" xyz="0 0 -0.1517777"/>
      <geometry>
        <cylinder length="0.2635554" radius="0.025"/>
      </geometry>
    </visual>
    <collision>
      <origin rpy="0 0 0" xyz="0 0 -0.1517777"/>
      <geometry>
        <cylinder length="0.3035554" radius="0.025"/>
      </geometry>
    </collision>
  </link>
  <link name="RWristYaw_link">
    <inertial>
      <mass value="1.0"/>
   <inertia ixx="0.0048720194876" ixy="0.0" ixz="0.0" iyy="0.0048720194876" iyz="0.0" izz="0.00199277424025"/>
    </inertial>
  </link>
  <link name="RWristRoll_link">
    <inertial>
      <mass value="1.0"/>
     <inertia ixx="0.0048720194876" ixy="0.0" ixz="0.0" iyy="0.0048720194876" iyz="0.0" izz="0.00199277424025"/>
    </inertial>
    <visual>
      <origin rpy="0 0 0" xyz="0 0 -0.076245974"/>
      <geometry>
        <cylinder length="0.112491948" radius="0.025"/>
      </geometry>
    </visual>
    <collision>
      <origin rpy="0 0 0" xyz="0 0 -0.076245974"/>
      <geometry>
        <cylinder length="0.152491948" radius="0.025"/>
      </geometry>
    </collision>
  </link>

 <!-- Base and Wheels -->
  <link name="base_link">
    <inertial>
      <origin rpy="0 0 0" xyz="0 0 0"/>
      <mass value="0.01"/>
      <inertia ixx="0.0001" ixy="0.0" ixz="0.0" iyy="0.0001" iyz="0.0" izz="0.0001"/>
    </inertial>
  </link>
  <link name="base">
    <inertial>
      <mass value="121.06"/>
      <inertia ixx="1.70235" ixy="0" ixz="0" iyy="1.70235" iyz="0" izz="0.5616"/>
    </inertial>
    <visual>
      <origin rpy="0 0 0" xyz="0 0 0"/>
      <geometry>
        <box size="0.4 0.4 0.3"/>
      </geometry>
    </visual>
    <collision>
      <origin rpy="0 0 0" xyz="0 0 0"/>
      <geometry>
        <box size="0.4 0.4 0.3"/>
      </geometry>
    </collision>
  </link>
  <link name="LfrontWheel">
    <inertial>
      <mass value="13.51"/>
      <inertia ixx="0.021177" ixy="0" ixz="0" iyy="0.021177" iyz="0" izz="0.0394875"/>
    </inertial>
    <visual>
      <origin rpy="0 0 0" xyz="0 0 0"/>
      <geometry>
        <cylinder length="0.07" radius="0.15"/>
      </geometry>
    </visual>
    <collision>
      <origin rpy="0 0 0" xyz="0 0 0"/>
      <geometry>
        <cylinder length="0.07" radius="0.15"/>
      </geometry>
    </collision>
  </link>
  <link name="RfrontWheel">
    <inertial>
      <mass value="13.51"/>
      <inertia ixx="0.021177" ixy="0" ixz="0" iyy="0.021177" iyz="0" izz="0.0394875"/>
    </inertial>
    <visual>
      <origin rpy="0 0 0" xyz="0 0 0"/>
      <geometry>
        <cylinder length="0.07" radius="0.15"/>
      </geometry>
    </visual>
    <collision>
      <origin rpy="0 0 0" xyz="0 0 0"/>
      <geometry>
        <cylinder length="0.07" radius="0.15"/>
      </geometry>
    </collision>
  </link>
  <link name="LbackWheel">
    <inertial>
      <mass value="13.51"/>
      <inertia ixx="0.021177" ixy="0" ixz="0" iyy="0.021177" iyz="0" izz="0.0394875"/>
    </inertial>
    <visual>
      <origin rpy="0 0 0" xyz="0 0 0"/>
      <geometry>
        <cylinder length="0.07" radius="0.15"/>
      </geometry>
    </visual>
    <collision>
      <origin rpy="0 0 0" xyz="0 0 0"/>
      <geometry>
        <cylinder length="0.07" radius="0.15"/>
      </geometry>
    </collision>
  </link>
  <link name="RbackWheel">
    <inertial>
      <mass value="13.51"/>
      <inertia ixx="0.021177" ixy="0" ixz="0" iyy="0.021177" iyz="0" izz="0.0394875"/>
    </inertial>
    <visual>
      <origin rpy="0 0 0" xyz="0 0 0"/>
      <geometry>
        <cylinder length="0.07" radius="0.15"/>
      </geometry>
    </visual>
    <collision>
      <origin rpy="0 0 0" xyz="0 0 0"/>
      <geometry>
        <cylinder length="0.07" radius="0.15"/>
      </geometry>
    </collision>
  </link>
  
  
 <!-- JOINTS -->
  <joint name="base_joint" type="fixed">
    <child link="base"/>
    <parent link="base_link"/>
    <origin rpy="0 0 0" xyz="0 0 0"/>
  </joint>

  <joint name="Base_Torso_joint" type="fixed">
    <child link="Torso"/>
    <parent link="base"/>
    <origin rpy="0 0 0" xyz="0 0 0.15"/>
  </joint>

  <joint name="NeckYaw" type="revolute">
    <parent link="Torso"/>
    <child link="NeckYaw_link"/>
    <origin rpy="0 0 0" xyz="0 0 0.87854616"/>
    <axis xyz="0 0 1"/>
    <limit effort="54" lower="-1.5707963259" upper="1.5707963259" velocity="3"/>
 <!--   <dynamics damping="100" friction="10"/>-->
    <dynamics damping="1" friction="10"/>
  </joint>
  <joint name="NeckPitch" type="revolute">
    <parent link="NeckYaw_link"/>
    <child link="NeckPitch_link"/>
    <origin rpy="0 0 0" xyz="0 0 0"/>
    <axis xyz="0 1 0"/>
    <limit effort="25" lower="-0.78539816295" upper="0.78539816295" velocity="3"/>
 <!--   <dynamics damping="100" friction="10"/>-->
    <dynamics damping="1" friction="10"/>
  </joint>
  <joint name="LShoulderRoll" type="revolute">
    <parent link="LShoulderPitch_link"/>
    <child link="LShoulderRoll_link"/>
    <origin rpy="0 0 0" xyz="0 0 0"/>
    <axis xyz="1 0 0"/>
    <limit effort="110" lower="0.0" upper="2.00712863865" velocity="3"/>
 <!--   <dynamics damping="100" friction="10"/>-->
    <dynamics damping="1" friction="10"/>
  </joint>
  <joint name="RShoulderRoll" type="revolute">
    <parent link="RShoulderPitch_link"/>
    <child link="RShoulderRoll_link"/>
    <origin rpy="0 0 0" xyz="0 0 0"/>
    <axis xyz="1 0 0"/>
    <limit effort="110" lower="-2.00712863865" upper="-0.0" velocity="3"/>
 <!--   <dynamics damping="100" friction="10"/>-->
    <dynamics damping="1" friction="10"/>
  </joint>
  <joint name="LShoulderYaw" type="revolute">
    <parent link="base"/>
    <child link="LShoulderYaw_link"/>
    <origin rpy="0 0 0" xyz="0 0.2410587 0.96426384"/>
    <axis xyz="0 0 1"/>
    <limit effort="80" lower="-0.6981317004" upper="1.745329251" velocity="3"/>
 <!--   <dynamics damping="100" friction="10"/>-->
    <dynamics damping="1" friction="10"/>
  </joint>
  <joint name="LShoulderPitch" type="revolute">
    <parent link="LShoulderYaw_link"/>
    <child link="LShoulderPitch_link"/>
    <origin rpy="0 0 0" xyz="0 0 0"/>
    <axis xyz="0 1 0"/>
    <limit effort="110" lower="-1.5707963259" upper="0.8726646255" velocity="3"/>
 <!--   <dynamics damping="100" friction="10"/>-->
    <dynamics damping="1" friction="10"/>
  </joint>
  <joint name="LElbowPitch" type="revolute">
    <parent link="LShoulderRoll_link"/>
    <child link="LElbowPitch_link"/>
    <origin rpy="0 0 0" xyz="0 0 -0.3481959"/>
    <axis xyz="0 1 0"/>
    <limit effort="100" lower="-2.35619448885" upper="0.0" velocity="3"/>
 <!--   <dynamics damping="100" friction="10"/>-->
    <dynamics damping="1" friction="10"/>
  </joint>
  <joint name="LWristYaw" type="revolute">
    <parent link="LElbowPitch_link"/>
    <child link="LWristYaw_link"/>
    <origin rpy="0 0 0" xyz="0 0 -0.3035554"/>
    <axis xyz="0 0 1"/>
    <limit effort="15" lower="-1.48352986335" upper="1.48352986335" velocity="3"/>
 <!--   <dynamics damping="100" friction="10"/>-->
    <dynamics damping="1" friction="10"/>
  </joint>
  <joint name="RShoulderYaw" type="revolute">
    <parent link="base"/>
    <child link="RShoulderYaw_link"/>
    <origin rpy="0 0 0" xyz="0 -0.2410587 0.96426384"/>
    <axis xyz="0 0 1"/>
    <limit effort="80" lower="-0.6981317004" upper="1.745329251" velocity="3"/>
 <!--   <dynamics damping="100" friction="10"/>-->
    <dynamics damping="1" friction="10"/>
  </joint>
  <joint name="RShoulderPitch" type="revolute">
    <parent link="RShoulderYaw_link"/>
    <child link="RShoulderPitch_link"/>
    <origin rpy="0 0 0" xyz="0 0 0"/>
    <axis xyz="0 1 0"/>
    <limit effort="110" lower="-1.5707963259" upper="0.8726646255" velocity="3"/>
 <!--   <dynamics damping="100" friction="10"/>-->
    <dynamics damping="1" friction="10"/>
  </joint>
  <joint name="RElbowPitch" type="revolute">
    <parent link="RShoulderRoll_link"/>
    <child link="RElbowPitch_link"/>
    <origin rpy="0 0 0" xyz="0 0 -0.3481959"/>
    <axis xyz="0 1 0"/>
    <limit effort="100" lower="-2.35619448885" upper="0.0" velocity="3"/>
 <!--   <dynamics damping="100" friction="10"/>-->
    <dynamics damping="1" friction="10"/>
  </joint>
  <joint name="RWristYaw" type="revolute">
    <parent link="RElbowPitch_link"/>
    <child link="RWristYaw_link"/>
    <origin rpy="0 0 0" xyz="0 0 -0.3035554"/>
    <axis xyz="0 0 1"/>
    <limit effort="15" lower="-1.48352986335" upper="1.48352986335" velocity="3"/>
 <!--   <dynamics damping="100" friction="10"/>-->
    <dynamics damping="1" friction="10"/>
  </joint>
  <joint name="LWristRoll" type="revolute">
    <parent link="LWristYaw_link"/>
    <child link="LWristRoll_link"/>
    <origin rpy="0 0 0" xyz="0 0 0"/>
    <axis xyz="1 0 0"/>
    <limit effort="30" lower="-0.5235987753" upper="1.0471975506" velocity="3"/>
 <!--   <dynamics damping="100" friction="10"/>-->
    <dynamics damping="1" friction="10"/>
  </joint>
  <joint name="RWristRoll" type="revolute">
    <parent link="RWristYaw_link"/>
    <child link="RWristRoll_link"/>
    <origin rpy="0 0 0" xyz="0 0 0"/>
    <axis xyz="1 0 0"/>
    <limit effort="30" lower="-1.0471975506" upper="0.5235987753" velocity="3"/>
 <!--   <dynamics damping="100" friction="10"/>-->
    <dynamics damping="1" friction="10"/>
  </joint>
  
  <!-- WHEELS -->
  <joint name="RfrontWheel_joint" type="continuous">
    <parent link="base"/>
    <child link="RfrontWheel"/>
    <origin rpy="0 1.570796325 1.570796325" xyz="-0.2 -0.235 -0.15"/>
    <axis xyz="0 0 1"/>
     <dynamics damping="1"/> 
  </joint>
  <joint name="LfrontWheel_joint" type="continuous">
    <parent link="base"/>
    <child link="LfrontWheel"/>
    <origin rpy="0 1.570796325 1.570796325" xyz="-0.2 0.235 -0.15"/>
    <axis xyz="0 0 1"/>
     <dynamics damping="1"/> 
  </joint>
  <joint name="RbackWheel_joint" type="continuous">
    <parent link="base"/>
    <child link="RbackWheel"/>
    <origin rpy="0 1.570796325 1.570796325" xyz="0.2 -0.235 -0.15"/>
    <axis xyz="0 0 1"/>
     <dynamics damping="1"/> 
  </joint>
  <joint name="LbackWheel_joint" type="continuous">
    <parent link="base"/>
    <child link="LbackWheel"/>
    <origin rpy="0 1.570796325 1.570796325" xyz="0.2 0.235 -0.15"/>
    <axis xyz="0 0 1"/>
    <dynamics damping="1"/> 
  </joint>

<gazebo>
    <!-- robot model offset -->
    <pose>0 0 0.93 0 0 0</pose>
  </gazebo>

<gazebo>

    <plugin name="differential_drive_controller" filename="libfourWheeled_diffdrive_plugin.so">
     <alwaysOn>true</alwaysOn>
     <frontleftJoint>LfrontWheel_joint</frontleftJoint>
        <frontrightJoint>RfrontWheel_joint</frontrightJoint>
        <rearleftJoint>LbackWheel_joint</rearleftJoint>
        <rearrightJoint>RbackWheel_joint</rearrightJoint>
        <wheelSeparation>0.47</wheelSeparation>
        <wheelDiameter>0.15</wheelDiameter>
        <torque>100</torque>
         <interface:position name="position_iface_0"/> 
        <topicName>cmd_vel</topicName>
     </plugin>
  
     <plugin name="joint_torque_controller" filename="libjoint_actuation_plugin.so">
        <alwaysOn>true</alwaysOn>
        <topicName>actuator_cmd</topicName>
      </plugin> 
      
     <plugin name="gazebo_ros_pub_robot_controller" filename="libgazebo_ros_pub_robot_state.so">
     	 <alwaysOn>true</alwaysOn>
     	 <updateRate>100.0</updateRate>
     	 <topicName>true_robot_state</topicName>
   	 </plugin>


    <!-- somehow fixes message dropout issue at startup. Without this, the first 10 or so robot state msgs are dropped. Not sure what fixes it - Sisir  -->
    <plugin filename="libgazebo_ros_controller_manager.so" name="gazebo_ros_controller_manager">
      <alwaysOn>true</alwaysOn>
      <updateRate>1000.0</updateRate>
    </plugin>

   </gazebo>
</robot>
