<?xml version="1.0" ?>
<!-- =================================================================================== -->
<!-- |    This document was autogenerated by xacro from atlas_sandia_hands.urdf.xacro  | -->
<!-- |    EDITING THIS FILE BY HAND IS NOT RECOMMENDED                                 | -->
<!-- =================================================================================== -->
<robot name="atlas" xmlns:xacro="http://www.ros.org/wiki/xacro">
  <link name="l_clav">
    <inertial>
      <mass value="2.369"/>
      <origin rpy="0 -0 0" xyz="0.014 0.058 0.029"/>
      <inertia ixx="0.004" ixy="0.001" ixz="0" iyy="0.006" iyz="0" izz="0.007"/>
    </inertial>
    <visual>
      <origin rpy="0 -0 0" xyz="0 0 0"/>
      <geometry>
        <mesh filename="package://mit_drcsim_scripts/models/mit_robot/meshes/l_clav.wrl" scale="1 1 1"/>
      </geometry>
    </visual>
  </link>
  <link name="l_farm">
    <inertial>
      <mass value="0.981"/>
      <origin rpy="0 -0 0" xyz="0 0.041 0"/>
      <inertia ixx="0.003" ixy="0" ixz="0" iyy="0.001" iyz="0" izz="0.003"/>
    </inertial>
    <visual>
      <origin rpy="0 -0 0" xyz="0 0 0"/>
      <geometry>
        <mesh filename="package://mit_drcsim_scripts/models/mit_robot/meshes/l_farm.wrl" scale="1 1 1"/>
      </geometry>
    </visual>
  </link>
  <link name="l_foot">
    <inertial>
      <mass value="0.867"/>
      <origin rpy="0 -0 0" xyz="0.027 0 -0.067"/>
      <inertia ixx="0.002" ixy="0" ixz="0" iyy="0.00350421" iyz="0" izz="0.00400651"/>
    </inertial>
    <visual>
      <origin rpy="0 -0 0" xyz="0 0 0"/>
      <geometry>
        <mesh filename="package://mit_drcsim_scripts/models/mit_robot/meshes/l_foot.wrl" scale="1 1 1"/>
      </geometry>
    </visual>
    <collision group="heel">
      <origin rpy="0 0 0" xyz="-0.082 0.0624435 -0.081119"/>
      <geometry>
        <sphere radius="0"/>
      </geometry>
    </collision>
    <collision group="heel">
      <origin rpy="0 0 0" xyz="-0.082 -0.0624435 -0.081119"/>
      <geometry>
        <sphere radius="0"/>
      </geometry>
    </collision>
    <collision group="toe">
      <origin rpy="0 0 0" xyz="0.178 0.0624435 -0.081119"/>
      <geometry>
        <sphere radius="0"/>
      </geometry>
    </collision>
    <collision group="toe">
      <origin rpy="0 0 0" xyz="0.178 -0.0624435 -0.081119"/>
      <geometry>
        <sphere radius="0"/>
      </geometry>
    </collision>
  </link>
  <link name="l_hand">
    <inertial>
      <mass value="2.263"/>
      <origin rpy="0 -0 0" xyz="0 0.093 0"/>
      <inertia ixx="0.01" ixy="0" ixz="0" iyy="0.002" iyz="0" izz="0.01"/>
    </inertial>
    <visual>
      <origin rpy="0 -0 0" xyz="0 0 0"/>
      <geometry>
        <mesh filename="package://mit_drcsim_scripts/models/mit_robot/meshes/l_hand.wrl" scale="1 1 1"/>
      </geometry>
    </visual>
    <collision>
      <origin rpy="0 0 0" xyz="0.0 0.115 0.0"/>
      <geometry>
        <sphere radius="0"/>
      </geometry>
    </collision>
  </link>
  <link name="l_larm">
    <inertial>
      <mass value="2.148"/>
      <origin rpy="0 -0 0" xyz="-0.003 0.099 -0.014"/>
      <inertia ixx="0.005" ixy="0" ixz="0" iyy="0.003" iyz="0" izz="0.006"/>
    </inertial>
    <visual>
      <origin rpy="0 -0 0" xyz="0 0 0"/>
      <geometry>
        <mesh filename="package://mit_drcsim_scripts/models/mit_robot/meshes/l_larm.wrl" scale="1 1 1"/>
      </geometry>
    </visual>
  </link>
  <link name="l_lglut">
    <inertial>
      <mass value="0.803"/>
      <origin rpy="0 -0 0" xyz="0.0133341 0.0170484 -0.0312052"/>
      <inertia ixx="0.0453457" ixy="2.24344e-05" ixz="2.50508e-06" iyy="0.0174182" iyz="-0.000137862" izz="0.0071591"/>
    </inertial>
    <visual>
      <origin rpy="0 -0 0" xyz="0 0 0"/>
      <geometry>
        <mesh filename="package://mit_drcsim_scripts/models/mit_robot/meshes/l_lglut.wrl" scale="1 1 1"/>
      </geometry>
    </visual>
  </link>
  <link name="l_lleg">
    <inertial>
      <mass value="4.367"/>
      <origin rpy="0 -0 0" xyz="0.001 0 -0.187"/>
      <inertia ixx="0.077" ixy="0" ixz="-0.003" iyy="0.076" iyz="0" izz="0.01"/>
    </inertial>
    <visual>
      <origin rpy="0 -0 0" xyz="0 0 0"/>
      <geometry>
        <mesh filename="package://mit_drcsim_scripts/models/mit_robot/meshes/l_lleg.wrl" scale="1 1 1"/>
      </geometry>
    </visual>
    <collision>
      <origin rpy="0 0 0" xyz="0.049 0.0 -0.05"/>
      <geometry>
        <sphere radius="0"/>
      </geometry>
    </collision>
  </link>
  <link name="l_scap">
    <inertial>
      <mass value="2.707"/>
      <origin rpy="0 -0 0" xyz="-0.002 0.108 0"/>
      <inertia ixx="0.01" ixy="0" ixz="0" iyy="0.005" iyz="0" izz="0.013"/>
    </inertial>
    <visual>
      <origin rpy="0 -0 0" xyz="0 0 0"/>
      <geometry>
        <mesh filename="package://mit_drcsim_scripts/models/mit_robot/meshes/l_scap.wrl" scale="1 1 1"/>
      </geometry>
    </visual>
  </link>
  <link name="l_talus">
    <inertial>
      <mass value="0.867"/>
      <origin rpy="0 -0 0" xyz="0 0 0"/>
      <inertia ixx="0.001" ixy="0" ixz="0" iyy="0.00350421" iyz="0" izz="0.00400651"/>
    </inertial>
    <visual>
      <origin rpy="0 -0 0" xyz="0 0 0"/>
      <geometry>
        <mesh filename="package://mit_drcsim_scripts/models/mit_robot/meshes/l_talus.wrl" scale="1 1 1"/>
      </geometry>
    </visual>
  </link>
  <link name="l_uarm">
    <inertial>
      <mass value="1.881"/>
      <origin rpy="0 -0 0" xyz="0.007 0.114 0.008"/>
      <inertia ixx="0.002" ixy="0" ixz="0" iyy="0.003" iyz="0" izz="0.003"/>
    </inertial>
    <visual>
      <origin rpy="0 -0 0" xyz="0 0 0"/>
      <geometry>
        <mesh filename="package://mit_drcsim_scripts/models/mit_robot/meshes/l_uarm.wrl" scale="1 1 1"/>
      </geometry>
    </visual>
  </link>
  <link name="l_uglut">
    <inertial>
      <mass value="1.51622"/>
      <origin rpy="0 -0 0" xyz="0.00529262 -0.00344732 0.00313046"/>
      <inertia ixx="0.0327037" ixy="3.79607e-08" ixz="-2.79549e-05" iyy="0.0174182" iyz="3.2735e-08" izz="0.0071591"/>
    </inertial>
    <visual>
      <origin rpy="0 -0 0" xyz="0 0 0"/>
      <geometry>
        <mesh filename="package://mit_drcsim_scripts/models/mit_robot/meshes/l_uglut.wrl" scale="1 1 1"/>
      </geometry>
    </visual>
  </link>
  <link name="l_uleg">
    <inertial>
      <mass value="7.227"/>
      <origin rpy="0 -0 0" xyz="0 0 -0.21"/>
      <inertia ixx="0.0453457" ixy="0" ixz="0" iyy="0.09" iyz="0" izz="0.0071591"/>
    </inertial>
    <visual>
      <origin rpy="0 -0 0" xyz="0 0 0"/>
      <geometry>
        <mesh filename="package://mit_drcsim_scripts/models/mit_robot/meshes/l_uleg.wrl" scale="1 1 1"/>
      </geometry>
    </visual>
  </link>
  <link name="ltorso">
    <inertial>
      <mass value="1.62729"/>
      <origin rpy="0 -0 0" xyz="-0.0112984 -3.15366e-06 0.0746835"/>
      <inertia ixx="0.0646646" ixy="-5.04491e-08" ixz="-0.000342157" iyy="0.050298" iyz="4.87119e-07" izz="0.10973"/>
    </inertial>
    <visual>
      <origin rpy="0 -0 0" xyz="0 0 0"/>
      <geometry>
        <mesh filename="package://mit_drcsim_scripts/models/mit_robot/meshes/ltorso.wrl" scale="1 1 1"/>
      </geometry>
    </visual>
  </link>
  <link name="mtorso">
    <inertial>
      <mass value="3.8068"/>
      <origin rpy="0 -0 0" xyz="-0.00816266 -0.0131245 0.0305974"/>
      <inertia ixx="0.1975" ixy="-6.10764e-05" ixz="3.94009e-05" iyy="0.544742" iyz="5.27463e-05" izz="0.10973"/>
    </inertial>
    <visual>
      <origin rpy="0 -0 0" xyz="0 0 0"/>
      <geometry>
        <mesh filename="package://mit_drcsim_scripts/models/mit_robot/meshes/mtorso.wrl" scale="1 1 1"/>
      </geometry>
    </visual>
  </link>
  <link name="pelvis">
    <inertial>
      <mass value="12.54638"/>
      <origin rpy="0 -0 0" xyz="0.0111 0 0.0271"/>
      <inertia ixx="0.0327037" ixy="0.0008" ixz="-0.0007" iyy="0.0174182" iyz="-0.0005" izz="0.118059"/>
    </inertial>
    <visual>
      <origin rpy="0 -0 0" xyz="0 0 0"/>
      <geometry>
        <mesh filename="package://mit_drcsim_scripts/models/mit_robot/meshes/pelvis.wrl" scale="1 1 1"/>
      </geometry>
    </visual>
  </link>
  <link name="r_clav">
    <inertial>
      <mass value="2.369"/>
      <origin rpy="0 -0 0" xyz="0.014 -0.058 0.029"/>
      <inertia ixx="0.004" ixy="-0.001" ixz="0" iyy="0.006" iyz="0" izz="0.007"/>
    </inertial>
    <visual>
      <origin rpy="0 -0 0" xyz="0 0 0"/>
      <geometry>
        <mesh filename="package://mit_drcsim_scripts/models/mit_robot/meshes/r_clav.wrl" scale="1 1 1"/>
      </geometry>
    </visual>
  </link>
  <link name="r_farm">
    <inertial>
      <mass value="0.981"/>
      <origin rpy="0 -0 0" xyz="0 -0.041 0"/>
      <inertia ixx="0.003" ixy="0" ixz="0" iyy="0.001" iyz="0" izz="0.003"/>
    </inertial>
    <visual>
      <origin rpy="0 -0 0" xyz="0 0 0"/>
      <geometry>
        <mesh filename="package://mit_drcsim_scripts/models/mit_robot/meshes/r_farm.wrl" scale="1 1 1"/>
      </geometry>
    </visual>
  </link>
  <link name="r_foot">
    <inertial>
      <mass value="0.867"/>
      <origin rpy="0 -0 0" xyz="0.027 0 -0.067"/>
      <inertia ixx="0.002" ixy="0" ixz="0" iyy="0.00350421" iyz="0" izz="0.00400651"/>
    </inertial>
    <visual>
      <origin rpy="0 -0 0" xyz="0 0 0"/>
      <geometry>
        <mesh filename="package://mit_drcsim_scripts/models/mit_robot/meshes/r_foot.wrl" scale="1 1 1"/>
      </geometry>
    </visual>
    <collision group="heel">
      <origin rpy="0 0 0" xyz="-0.082 0.0624435 -0.081119"/>
      <geometry>
        <sphere radius="0"/>
      </geometry>
    </collision>
    <collision group="heel">
      <origin rpy="0 0 0" xyz="-0.082 -0.0624435 -0.081119"/>
      <geometry>
        <sphere radius="0"/>
      </geometry>
    </collision>
    <collision group="toe">
      <origin rpy="0 0 0" xyz="0.178 0.0624435 -0.081119"/>
      <geometry>
        <sphere radius="0"/>
      </geometry>
    </collision>
    <collision group="toe">
      <origin rpy="0 0 0" xyz="0.178 -0.0624435 -0.081119"/>
      <geometry>
        <sphere radius="0"/>
      </geometry>
    </collision>
  </link>
  <link name="r_hand">
    <inertial>
      <mass value="2.263"/>
      <origin rpy="0 -0 0" xyz="0 -0.093 0"/>
      <inertia ixx="0.01" ixy="0" ixz="0" iyy="0.002" iyz="0" izz="0.01"/>
    </inertial>
    <visual>
      <origin rpy="0 -0 0" xyz="0 0 0"/>
      <geometry>
        <mesh filename="package://mit_drcsim_scripts/models/mit_robot/meshes/r_hand.wrl" scale="1 1 1"/>
      </geometry>
    </visual>
    <collision>
      <origin rpy="0 0 0" xyz="0.0 -0.115 0.0"/>
      <geometry>
        <sphere radius="0"/>
      </geometry>
    </collision>
  </link>
  <link name="r_larm">
    <inertial>
      <mass value="2.148"/>
      <origin rpy="0 -0 0" xyz="-0.003 -0.099 -0.014"/>
      <inertia ixx="0.005" ixy="0" ixz="0" iyy="0.003" iyz="0" izz="0.006"/>
    </inertial>
    <visual>
      <origin rpy="0 -0 0" xyz="0 0 0"/>
      <geometry>
        <mesh filename="package://mit_drcsim_scripts/models/mit_robot/meshes/r_larm.wrl" scale="1 1 1"/>
      </geometry>
    </visual>
  </link>
  <link name="r_lglut">
    <inertial>
      <mass value="0.803"/>
      <origin rpy="0 -0 0" xyz="0.0133341 -0.0170484 -0.0312052"/>
      <inertia ixx="0.0453457" ixy="2.24344e-05" ixz="2.50508e-06" iyy="0.0174182" iyz="-0.000137862" izz="0.0071591"/>
    </inertial>
    <visual>
      <origin rpy="0 -0 0" xyz="0 0 0"/>
      <geometry>
        <mesh filename="package://mit_drcsim_scripts/models/mit_robot/meshes/r_lglut.wrl" scale="1 1 1"/>
      </geometry>
    </visual>
  </link>
  <link name="r_lleg">
    <inertial>
      <mass value="4.367"/>
      <origin rpy="0 -0 0" xyz="0.001 0 -0.187"/>
      <inertia ixx="0.077" ixy="-0" ixz="-0.003" iyy="0.076" iyz="-0" izz="0.01"/>
    </inertial>
    <visual>
      <origin rpy="0 -0 0" xyz="0 0 0"/>
      <geometry>
        <mesh filename="package://mit_drcsim_scripts/models/mit_robot/meshes/r_lleg.wrl" scale="1 1 1"/>
      </geometry>
    </visual>
    <collision>
      <origin rpy="0 0 0" xyz="0.049 0.0 -0.05"/>
      <geometry>
        <sphere radius="0"/>
      </geometry>
    </collision>
  </link>
  <link name="r_scap">
    <inertial>
      <mass value="2.707"/>
      <origin rpy="0 -0 0" xyz="-0.002 -0.108 0"/>
      <inertia ixx="0.01" ixy="0" ixz="0" iyy="0.005" iyz="0" izz="0.013"/>
    </inertial>
    <visual>
      <origin rpy="0 -0 0" xyz="0 0 0"/>
      <geometry>
        <mesh filename="package://mit_drcsim_scripts/models/mit_robot/meshes/r_scap.wrl" scale="1 1 1"/>
      </geometry>
    </visual>
  </link>
  <link name="r_talus">
    <inertial>
      <mass value="0.867"/>
      <origin rpy="0 -0 0" xyz="0 0 0"/>
      <inertia ixx="0.001" ixy="0" ixz="0" iyy="0.00350421" iyz="0" izz="0.00400651"/>
    </inertial>
    <visual>
      <origin rpy="0 -0 0" xyz="0 0 0"/>
      <geometry>
        <mesh filename="package://mit_drcsim_scripts/models/mit_robot/meshes/r_talus.wrl" scale="1 1 1"/>
      </geometry>
    </visual>
  </link>
  <link name="r_uarm">
    <inertial>
      <mass value="1.881"/>
      <origin rpy="0 -0 0" xyz="0.007 -0.114 0.008"/>
      <inertia ixx="0.002" ixy="0" ixz="0" iyy="0.003" iyz="0" izz="0.003"/>
    </inertial>
    <visual>
      <origin rpy="0 -0 0" xyz="0 0 0"/>
      <geometry>
        <mesh filename="package://mit_drcsim_scripts/models/mit_robot/meshes/r_uarm.wrl" scale="1 1 1"/>
      </geometry>
    </visual>
  </link>
  <link name="r_uglut">
    <inertial>
      <mass value="1.51622"/>
      <origin rpy="0 -0 0" xyz="0.00529262 0.00344732 0.00313046"/>
      <inertia ixx="0.0327037" ixy="3.79607e-08" ixz="-2.79549e-05" iyy="0.0174182" iyz="3.2735e-08" izz="0.0071591"/>
    </inertial>
    <visual>
      <origin rpy="0 -0 0" xyz="0 0 0"/>
      <geometry>
        <mesh filename="package://mit_drcsim_scripts/models/mit_robot/meshes/r_uglut.wrl" scale="1 1 1"/>
      </geometry>
    </visual>
  </link>
  <link name="r_uleg">
    <inertial>
      <mass value="7.227"/>
      <origin rpy="0 -0 0" xyz="0 0 -0.21"/>
      <inertia ixx="0.0453457" ixy="0" ixz="0" iyy="0.09" iyz="0" izz="0.0071591"/>
    </inertial>
    <visual>
      <origin rpy="0 -0 0" xyz="0 0 0"/>
      <geometry>
        <mesh filename="package://mit_drcsim_scripts/models/mit_robot/meshes/r_uleg.wrl" scale="1 1 1"/>
      </geometry>
    </visual>
  </link>
  <link name="utorso">
    <inertial>
      <mass value="15.2272"/>
      <origin rpy="0 -0 0" xyz="0.02 -0.001 0.211"/>
      <inertia ixx="0.395" ixy="0" ixz="0.083" iyy="0.544742" iyz="-0.003" izz="0.10973"/>
    </inertial>
    <visual>
      <origin rpy="0 -0 0" xyz="0 0 0"/>
      <geometry>
        <mesh filename="package://mit_drcsim_scripts/models/mit_robot/meshes/utorso.wrl" scale="1 1 1"/>
      </geometry>
    </visual>
  </link>
  <joint name="back_lbz" type="revolute">
    <origin rpy="0 -0 0" xyz="-0.0125 0 0"/>
    <axis xyz="0 0 1"/>
    <parent link="pelvis"/>
    <child link="ltorso"/>
    <dynamics damping="10" friction="0"/>
    <limit effort="124.016" lower="-0.610865" upper="0.610865" velocity="12"/>
    <safety_controller k_position="100" k_velocity="100" soft_lower_limit="-10.6109" soft_upper_limit="10.6109"/>
  </joint>
  <joint name="back_mby" type="revolute">
    <origin rpy="0 -0 0" xyz="0 0 0.09"/>
    <axis xyz="0 1 0"/>
    <parent link="ltorso"/>
    <child link="mtorso"/>
    <dynamics damping="10" friction="0"/>
    <limit effort="206.843" lower="-1.2" upper="1.28" velocity="12"/>
    <safety_controller k_position="100" k_velocity="100" soft_lower_limit="-11.2" soft_upper_limit="11.28"/>
  </joint>
  <joint name="back_ubx" type="revolute">
    <origin rpy="0 -0 0" xyz="0 0 0.05"/>
    <axis xyz="1 0 0"/>
    <parent link="mtorso"/>
    <child link="utorso"/>
    <dynamics damping="10" friction="0"/>
    <limit effort="94.91" lower="-0.790809" upper="0.790809" velocity="12"/>
    <safety_controller k_position="100" k_velocity="100" soft_lower_limit="-10.7908" soft_upper_limit="10.7908"/>
  </joint>
  <joint name="l_arm_elx" type="revolute">
    <origin rpy="0 -0 0" xyz="0 0.121 0.013"/>
    <axis xyz="1 0 0"/>
    <parent link="l_uarm"/>
    <child link="l_larm"/>
    <dynamics damping="0.1" friction="0"/>
    <limit effort="114" lower="0" upper="2.35619" velocity="12"/>
    <safety_controller k_position="100" k_velocity="100" soft_lower_limit="-10" soft_upper_limit="12.3562"/>
  </joint>
  <joint name="l_arm_ely" type="revolute">
    <origin rpy="0 -0 0" xyz="0 0.185 0"/>
    <axis xyz="0 1 0"/>
    <parent link="l_scap"/>
    <child link="l_uarm"/>
    <dynamics damping="0.1" friction="0"/>
    <limit effort="114" lower="0" upper="3.14159" velocity="12"/>
    <safety_controller k_position="100" k_velocity="100" soft_lower_limit="-10" soft_upper_limit="13.1416"/>
  </joint>
  <joint name="l_arm_mwx" type="revolute">
    <origin rpy="0 -0 0" xyz="0 0.058 0"/>
    <axis xyz="1 0 0"/>
    <parent link="l_farm"/>
    <child link="l_hand"/>
    <dynamics damping="0.1" friction="0"/>
    <limit effort="60" lower="-0.436" upper="1.571" velocity="12"/>
    <safety_controller k_position="100" k_velocity="100" soft_lower_limit="-10.436" soft_upper_limit="11.571"/>
  </joint>
  <joint name="l_arm_shx" type="revolute">
    <origin rpy="0 -0 0" xyz="0 0.075 0.036"/>
    <axis xyz="1 0 0"/>
    <parent link="l_clav"/>
    <child link="l_scap"/>
    <dynamics damping="0.1" friction="0"/>
    <limit effort="170" lower="-1.39626" upper="1.74533" velocity="12"/>
    <safety_controller k_position="100" k_velocity="100" soft_lower_limit="-11.3963" soft_upper_limit="11.7453"/>
  </joint>
  <joint name="l_arm_usy" type="revolute">
    <origin rpy="0 -0 0" xyz="0.024 0.221 0.289"/>
    <axis xyz="0 0.5 0.866025"/>
    <parent link="utorso"/>
    <child link="l_clav"/>
    <dynamics damping="0.1" friction="0"/>
    <limit effort="212" lower="-1.9635" upper="1.9635" velocity="12"/>
    <safety_controller k_position="100" k_velocity="100" soft_lower_limit="-11.9635" soft_upper_limit="11.9635"/>
  </joint>
  <joint name="l_arm_uwy" type="revolute">
    <origin rpy="0 -0 0" xyz="0 0.188 -0.013"/>
    <axis xyz="0 1 0"/>
    <parent link="l_larm"/>
    <child link="l_farm"/>
    <dynamics damping="0.1" friction="0"/>
    <limit effort="114" lower="-1.571" upper="1.571" velocity="12"/>
    <safety_controller k_position="100" k_velocity="100" soft_lower_limit="-11.571" soft_upper_limit="11.571"/>
  </joint>
  <joint name="l_leg_kny" type="revolute">
    <origin rpy="0 -0 0" xyz="-0.05 0 -0.374"/>
    <axis xyz="0 1 0"/>
    <parent link="l_uleg"/>
    <child link="l_lleg"/>
    <dynamics damping="0.1" friction="0"/>
    <limit effort="220" lower="0" upper="2.45" velocity="12"/>
    <safety_controller k_position="100" k_velocity="100" soft_lower_limit="-10" soft_upper_limit="12.45"/>
  </joint>
  <joint name="l_leg_lax" type="revolute">
    <origin rpy="0 -0 0" xyz="0 0 0"/>
    <axis xyz="1 0 0"/>
    <parent link="l_talus"/>
    <child link="l_foot"/>
    <dynamics damping="0.1" friction="0"/>
    <limit effort="90" lower="-0.436" upper="0.436" velocity="12"/>
    <safety_controller k_position="100" k_velocity="100" soft_lower_limit="-10.436" soft_upper_limit="10.436"/>
  </joint>
  <joint name="l_leg_lhy" type="revolute">
    <origin rpy="0 -0 0" xyz="0.05 0 -0.05"/>
    <axis xyz="0 1 0"/>
    <parent link="l_lglut"/>
    <child link="l_uleg"/>
    <dynamics damping="10" friction="0"/>
    <limit effort="260" lower="-1.75" upper="0.524" velocity="12"/>
    <safety_controller k_position="100" k_velocity="100" soft_lower_limit="-11.75" soft_upper_limit="10.524"/>
  </joint>
  <joint name="l_leg_mhx" type="revolute">
    <origin rpy="0 -0 0" xyz="0 0 0"/>
    <axis xyz="1 0 0"/>
    <parent link="l_uglut"/>
    <child link="l_lglut"/>
    <dynamics damping="10" friction="0"/>
    <limit effort="180" lower="-0.47" upper="0.495" velocity="12"/>
    <safety_controller k_position="100" k_velocity="100" soft_lower_limit="-10.47" soft_upper_limit="10.495"/>
  </joint>
  <joint name="l_leg_uay" type="revolute">
    <origin rpy="0 -0 0" xyz="0 0 -0.422"/>
    <axis xyz="0 1 0"/>
    <parent link="l_lleg"/>
    <child link="l_talus"/>
    <dynamics damping="0.1" friction="0"/>
    <limit effort="220" lower="-0.698" upper="0.698" velocity="12"/>
    <safety_controller k_position="100" k_velocity="100" soft_lower_limit="-10.698" soft_upper_limit="10.698"/>
  </joint>
  <joint name="l_leg_uhz" type="revolute">
    <origin rpy="0 -0 0" xyz="0 0.089 0"/>
    <axis xyz="0 0 1"/>
    <parent link="pelvis"/>
    <child link="l_uglut"/>
    <dynamics damping="10" friction="0"/>
    <limit effort="110" lower="-0.32" upper="1.14" velocity="12"/>
    <safety_controller k_position="100" k_velocity="100" soft_lower_limit="-10.32" soft_upper_limit="11.14"/>
  </joint>
  <joint name="neck_ay" type="revolute">
    <!-- per slides on sensor head kinematics 2012-12-14 -->
    <origin rpy="0 -0 0" xyz="0.16555 0 0.50823"/>
    <axis xyz="0 1 0"/>
    <parent link="utorso"/>
    <child link="head"/>
    <dynamics damping="0.1" friction="0"/>
    <!-- per slides on sensor head kinematics 2012-12-14 -->
    <limit effort="5" lower="-0.610865238" upper="1.13446401" velocity="12"/>
    <safety_controller k_position="100" k_velocity="100" soft_lower_limit="-10.610865238" soft_upper_limit="11.13446401"/>
  </joint>
  <joint name="r_arm_elx" type="revolute">
    <origin rpy="0 -0 0" xyz="0 -0.121 0.013"/>
    <axis xyz="1 0 0"/>
    <parent link="r_uarm"/>
    <child link="r_larm"/>
    <dynamics damping="0.1" friction="0"/>
    <limit effort="114" lower="-2.35619" upper="0" velocity="12"/>
    <safety_controller k_position="100" k_velocity="100" soft_lower_limit="-12.3562" soft_upper_limit="10"/>
  </joint>
  <joint name="r_arm_ely" type="revolute">
    <origin rpy="0 -0 0" xyz="0 -0.185 0"/>
    <axis xyz="0 1 0"/>
    <parent link="r_scap"/>
    <child link="r_uarm"/>
    <dynamics damping="0.1" friction="0"/>
    <limit effort="114" lower="0" upper="3.14159" velocity="12"/>
    <safety_controller k_position="100" k_velocity="100" soft_lower_limit="-10" soft_upper_limit="13.1416"/>
  </joint>
  <joint name="r_arm_mwx" type="revolute">
    <origin rpy="0 -0 0" xyz="0 -0.058 0"/>
    <axis xyz="1 0 0"/>
    <parent link="r_farm"/>
    <child link="r_hand"/>
    <dynamics damping="0.1" friction="0"/>
    <limit effort="60" lower="-1.571" upper="0.436" velocity="12"/>
    <safety_controller k_position="100" k_velocity="100" soft_lower_limit="-11.571" soft_upper_limit="10.436"/>
  </joint>
  <joint name="r_arm_shx" type="revolute">
    <origin rpy="0 -0 0" xyz="0 -0.075 0.036"/>
    <axis xyz="1 0 0"/>
    <parent link="r_clav"/>
    <child link="r_scap"/>
    <dynamics damping="0.1" friction="0"/>
    <limit effort="170" lower="-1.74533" upper="1.39626" velocity="12"/>
    <safety_controller k_position="100" k_velocity="100" soft_lower_limit="-11.7453" soft_upper_limit="11.3963"/>
  </joint>
  <joint name="r_arm_usy" type="revolute">
    <origin rpy="0 -0 0" xyz="0.024 -0.221 0.289"/>
    <axis xyz="0 0.5 -0.866025"/>
    <parent link="utorso"/>
    <child link="r_clav"/>
    <dynamics damping="0.1" friction="0"/>
    <limit effort="212" lower="-1.9635" upper="1.9635" velocity="12"/>
    <safety_controller k_position="100" k_velocity="100" soft_lower_limit="-11.9635" soft_upper_limit="11.9635"/>
  </joint>
  <joint name="r_arm_uwy" type="revolute">
    <origin rpy="0 -0 0" xyz="0 -0.188 -0.013"/>
    <axis xyz="0 1 0"/>
    <parent link="r_larm"/>
    <child link="r_farm"/>
    <dynamics damping="0.1" friction="0"/>
    <limit effort="114" lower="-1.571" upper="1.571" velocity="12"/>
    <safety_controller k_position="100" k_velocity="100" soft_lower_limit="-11.571" soft_upper_limit="11.571"/>
  </joint>
  <joint name="r_leg_kny" type="revolute">
    <origin rpy="0 -0 0" xyz="-0.05 0 -0.374"/>
    <axis xyz="0 1 0"/>
    <parent link="r_uleg"/>
    <child link="r_lleg"/>
    <dynamics damping="0.1" friction="0"/>
    <limit effort="220" lower="0" upper="2.45" velocity="12"/>
    <safety_controller k_position="100" k_velocity="100" soft_lower_limit="-10" soft_upper_limit="12.45"/>
  </joint>
  <joint name="r_leg_lax" type="revolute">
    <origin rpy="0 -0 0" xyz="0 0 0"/>
    <axis xyz="1 0 0"/>
    <parent link="r_talus"/>
    <child link="r_foot"/>
    <dynamics damping="0.1" friction="0"/>
    <limit effort="90" lower="-0.436" upper="0.436" velocity="12"/>
    <safety_controller k_position="100" k_velocity="100" soft_lower_limit="-10.436" soft_upper_limit="10.436"/>
  </joint>
  <joint name="r_leg_lhy" type="revolute">
    <origin rpy="0 -0 0" xyz="0.05 0 -0.05"/>
    <axis xyz="0 1 0"/>
    <parent link="r_lglut"/>
    <child link="r_uleg"/>
    <dynamics damping="10" friction="0"/>
    <limit effort="260" lower="-1.745" upper="0.524" velocity="12"/>
    <safety_controller k_position="100" k_velocity="100" soft_lower_limit="-11.745" soft_upper_limit="10.524"/>
  </joint>
  <joint name="r_leg_mhx" type="revolute">
    <origin rpy="0 -0 0" xyz="0 0 0"/>
    <axis xyz="1 0 0"/>
    <parent link="r_uglut"/>
    <child link="r_lglut"/>
    <dynamics damping="10" friction="0"/>
    <limit effort="180" lower="-0.495" upper="0.47" velocity="12"/>
    <safety_controller k_position="100" k_velocity="100" soft_lower_limit="-10.495" soft_upper_limit="10.47"/>
  </joint>
  <joint name="r_leg_uay" type="revolute">
    <origin rpy="0 -0 0" xyz="0 0 -0.422"/>
    <axis xyz="0 1 0"/>
    <parent link="r_lleg"/>
    <child link="r_talus"/>
    <dynamics damping="0.1" friction="0"/>
    <limit effort="220" lower="-0.698" upper="0.698" velocity="12"/>
    <safety_controller k_position="100" k_velocity="100" soft_lower_limit="-10.698" soft_upper_limit="10.698"/>
  </joint>
  <joint name="r_leg_uhz" type="revolute">
    <origin rpy="0 -0 0" xyz="0 -0.089 0"/>
    <axis xyz="0 0 1"/>
    <parent link="pelvis"/>
    <child link="r_uglut"/>
    <dynamics damping="10" friction="0"/>
    <limit effort="260" lower="-1.14" upper="0.32" velocity="12"/>
    <safety_controller k_position="100" k_velocity="100" soft_lower_limit="-11.14" soft_upper_limit="10.32"/>
  </joint>
  <link name="right_palm">
    <origin rpy="0 0 0" xyz="0 0 0"/>
    <inertial>
      <mass value="0.3"/>
      <origin xyz="0 0 0"/>
      <inertia ixx="0.01" ixy="0" ixz="0" iyy="0.01" iyz="0" izz="0.01"/>
    </inertial>
    <!-- begin simple shape approximation of palm -->
    <!-- <collision group="default">
        <origin xyz="0.069 ${0.016 * reflect} 0.038" rpy="0 ${M_pi/2} ${-0.9 * reflect}"/>
        <geometry>
          <cylinder radius="0.013" length="0.100" />
        </geometry>
      </collision> -->
    <!-- <collision group="other">
        <origin xyz="0.064 ${0.008 * reflect} 0.021" rpy="0.41 0 ${-0.9 * reflect}"/>
        <geometry>
          <box size="0.09 .035 .05" />
        </geometry>
      </collision> -->
    <!-- <collision group="other">
        <origin xyz="0.02 0 -0.005" rpy="0 ${M_pi/2} 0"/>
        <geometry>
          <cylinder radius="0.038" length="0.05" />
        </geometry>
      </collision> -->
    <!-- <collision group="other">
        <origin xyz="0.11 ${-0.01*reflect} -0.005" rpy="0 0 ${0.37*reflect}"/>
        <geometry>
          <box size="0.09 .03 .06" />
        </geometry>
      </collision> -->
    <!-- <collision group="other">
        <origin xyz="0.09 ${0.02*reflect} -0.005" rpy="0 0 ${0.37*reflect}"/>
        <geometry>
          <box size="0.09 .03 .06" />
        </geometry>
      </collision> -->
    <!--<collision group="other">
        <origin xyz="0.060 ${0.050*reflect} -0.005" rpy="0 0 ${0.37*reflect}"/>
        <geometry>
          <box size="0.09 .03 .06" />
        </geometry>
      </collision> -->
    <!-- <collision group="other">
        <origin xyz="0.044 ${-0.04*reflect} -0.005" rpy="0 0 ${0.79*reflect}"/>
        <geometry>
          <box size="0.09 .03 .06" />
        </geometry>
      </collision>-->
    <!--   end simple shape approximation of palm -->
    <!-- begin visual shape approximation of palm -->
    <visual>
      <origin rpy="0 1.57079632679 -0.9" xyz="0.069 0.016 0.038"/>
      <geometry>
        <cylinder length="0.100" radius="0.013"/>
      </geometry>
      <material name="right_sandia_hand_skin">
        <color rgba="0.835 0.655 0.345 1.0"/>
      </material>
    </visual>
    <visual>
      <origin rpy="0.41 0 -0.9" xyz="0.064 0.008 0.021"/>
      <geometry>
        <box size="0.09 .035 .05"/>
      </geometry>
      <material name="right_sandia_hand_skin">
        <color rgba="0.835 0.655 0.345 1.0"/>
      </material>
    </visual>
    <visual>
      <origin rpy="0 1.57079632679 0" xyz="0.02 0 -0.005"/>
      <geometry>
        <cylinder length="0.05" radius="0.038"/>
      </geometry>
      <material name="right_sandia_hand_skin">
        <color rgba="0.835 0.655 0.345 1.0"/>
      </material>
    </visual>
    <visual>
      <origin rpy="0 0 0.37" xyz="0.11 -0.01 -0.005"/>
      <geometry>
        <box size="0.09 .03 .06"/>
      </geometry>
      <material name="right_sandia_hand_skin">
        <color rgba="0.835 0.655 0.345 1.0"/>
      </material>
    </visual>
    <visual>
      <origin rpy="0 0 0.37" xyz="0.09 0.02 -0.005"/>
      <geometry>
        <box size="0.09 .03 .06"/>
      </geometry>
      <material name="right_sandia_hand_skin">
        <color rgba="0.835 0.655 0.345 1.0"/>
      </material>
    </visual>
    <visual>
      <origin rpy="0 0 0.37" xyz="0.060 0.05 -0.005"/>
      <geometry>
        <box size="0.09 .03 .06"/>
      </geometry>
      <material name="right_sandia_hand_skin">
        <color rgba="0.835 0.655 0.345 1.0"/>
      </material>
    </visual>
    <visual>
      <origin rpy="0 0 0.79" xyz="0.044 -0.04 -0.005"/>
      <geometry>
        <box size="0.09 .03 .06"/>
      </geometry>
      <material name="right_sandia_hand_skin">
        <color rgba="0.835 0.655 0.345 1.0"/>
      </material>
    </visual>
    <!--   end visual shape approximation of palm -->
    <!-- begin collision mesh of f2 ->
      <collision group="default">
        <origin xyz="0 0 0" rpy="0 0 0"/>
        <geometry>
          <mesh filename="package://sandia_hand_description/meshes/palm.stl"/>
        </geometry>
      </collision>
      <!-   end collision mesh of f2 -->
    <!-- begin visual mesh of f2    ->
      <visual>
        <origin xyz="0 0 0" rpy="0 0 0"/>
        <geometry>
          <mesh filename="package://sandia_hand_description/meshes/palm.stl"/>
        </geometry>
        <material name="${side}_sandia_hand_skin">
          <color rgba="0.835 0.655 0.345 1.0"/>
        </material>
      </visual>
      <!-   end visual mesh of f2 -->
  </link>
  <joint name="right_sandia_hand_joint" type="fixed">
    <parent link="r_hand"/>
    <child link="right_palm"/>
    <origin rpy="-1.57079 0 -1.57079" xyz="0 -0.1 0"/>
  </joint>
  <link name="right_f0_base">
    <origin rpy="0 0 0" xyz="0 0 0"/>
    <inertial>
      <mass value="0.35"/>
      <origin xyz="0 0 0"/>
      <inertia ixx="0.01" ixy="0" ixz="0" iyy="0.01" iyz="0" izz="0.01"/>
    </inertial>
  </link>
  <link name="right_f0_fixed_accel">
    <origin rpy="0 0 0" xyz="0 0 0"/>
    <inertial>
      <mass value="0.001"/>
      <origin xyz="0 0 0"/>
      <inertia ixx="0.01" ixy="0" ixz="0" iyy="0.01" iyz="0" izz="0.01"/>
    </inertial>
    <!-- ############ MIT ADDITION ############ -->
    <collision>
      <origin rpy="0 0 0" xyz="0 0 0.05"/>
      <geometry>
        <sphere radius="0"/>
      </geometry>
    </collision>
    <!-- ############    END     ############ -->
  </link>
  <link name="right_f0_0">
    <origin rpy="0 0 0" xyz="0 0 0"/>
    <inertial>
      <mass value="0.05"/>
      <origin xyz="0 0 0"/>
      <inertia ixx="0.01" ixy="0" ixz="0" iyy="0.01" iyz="0" izz="0.01"/>
    </inertial>
    <!-- begin simple shape approximation of f0 -->
    <!-- <collision group="default">
        <origin xyz="0 0 0.003" rpy="0 0 0"/>
        <geometry>
          <cylinder radius="0.015" length="0.023" />
        </geometry>
      </collision> -->
    <!-- <collision group="other">
        <origin xyz="0.011 0 0.003" rpy="${M_pi/2} 0 0"/>
        <geometry>
          <cylinder radius="0.01" length="0.023" />
        </geometry>
      </collision> -->
    <!--   end simple shape approximation of f0 -->
    <!-- begin visual shape approximation of f0 -->
    <visual>
      <origin rpy="0 0 0" xyz="0 0 0.003"/>
      <geometry>
        <cylinder length="0.023" radius="0.015"/>
      </geometry>
      <material name="right_sandia_hand_skin_suntan">
        <color rgba="0.7 0.4 0.2 1.0"/>
      </material>
    </visual>
    <visual>
      <origin rpy="1.57079632679 0 0" xyz="0.011 0 0.003"/>
      <geometry>
        <cylinder length="0.023" radius="0.01"/>
      </geometry>
      <material name="right_sandia_hand_skin_suntan">
        <color rgba="0.7 0.4 0.2 1.0"/>
      </material>
    </visual>
    <!--   end visual shape approximation of f0 -->
    <!-- begin collision mesh of f0 ->
      <collision group="default">
        <origin xyz="0 0 0" rpy="0 0 0"/>
        <geometry>
          <mesh filename="package://sandia_hand_description/meshes/f0.stl"/>
        </geometry>
      </collision>
      <!-   end collision mesh of f0 -->
    <!-- begin visual mesh of f0 ->
      <visual>
        <origin xyz="0 0 0" rpy="0 0 0"/>
        <geometry>
          <mesh filename="package://sandia_hand_description/meshes/f0.stl"/>
        </geometry>
        <material name="${side}_sandia_hand_skin_suntan">
          <color rgba="0.7 0.4 0.2 1.0"/>
        </material>
      </visual>
      <!-   end visual mesh of f0 -->
  </link>
  <link name="right_f0_1">
    <origin rpy="0 0 0" xyz="0 0 0"/>
    <inertial>
      <mass value="0.05"/>
      <origin xyz="0 0 0"/>
      <inertia ixx="0.01" ixy="0" ixz="0" iyy="0.01" iyz="0" izz="0.01"/>
    </inertial>
    <!-- begin simple shape approximation of f1 -->
    <!-- <collision group="default">
        <origin xyz="0.024 0 0" rpy="0 ${M_pi/2} 0"/>
        <geometry>
          <cylinder radius="0.01" length="0.067" />
        </geometry>
      </collision> -->
    <!--   end simple shape approximation of f1 -->
    <!-- begin visual shape approximation of f1 -->
    <visual>
      <origin rpy="0 1.57079632679 0" xyz="0.024 0 0"/>
      <geometry>
        <cylinder length="0.067" radius="0.01"/>
      </geometry>
      <material name="right_sandia_hand_skin">
        <color rgba="0.835 0.655 0.345 1.0"/>
      </material>
    </visual>
    <!--   end visual shape approximation of f1 -->
    <!-- begin collision mesh of f1 ->
      <collision group="default">
        <origin xyz="0 0 0" rpy="0 0 0"/>
        <geometry>
          <mesh filename="package://sandia_hand_description/meshes/f1.stl"/>
        </geometry>
      </collision>
      <!-   end collision mesh of f1 -->
    <!-- begin visual mesh of f1 ->
      <visual>
        <origin xyz="0 0 0" rpy="0 0 0"/>
        <geometry>
          <mesh filename="package://sandia_hand_description/meshes/f1.stl"/>
        </geometry>
        <material name="${side}_sandia_hand_skin">
          <color rgba="0.835 0.655 0.345 1.0"/>
        </material>
      </visual>
      <!-   end visual mesh of f1 -->
  </link>
  <link name="right_f0_1_accel">
    <origin rpy="0 0 0" xyz="0 0 0"/>
    <inertial>
      <mass value="0.001"/>
      <origin xyz="0 0 0"/>
      <inertia ixx="0.01" ixy="0" ixz="0" iyy="0.01" iyz="0" izz="0.01"/>
    </inertial>
    <!-- ############ MIT ADDITION ############ -->
    <!--      <collision>-->
    <!--        <origin rpy="0 0 0" xyz="0 0 0.01"/>-->
    <!--        <geometry>-->
    <!--          <sphere radius="0"/>-->
    <!--        </geometry>-->
    <!--      </collision>  -->
    <!-- ############    END     ############ -->
  </link>
  <link name="right_f0_2">
    <origin rpy="0 0 0" xyz="0 0 0"/>
    <inertial>
      <mass value="0.05"/>
      <origin xyz="0 0 0"/>
      <inertia ixx="0.01" ixy="0" ixz="0" iyy="0.01" iyz="0" izz="0.01"/>
    </inertial>
    <!-- begin simple shape approximation of f2 -->
    <!-- <collision group="default">
        <origin xyz="0.024 0 0" rpy="0 ${M_pi/2} 0"/>
        <geometry>
          <cylinder radius="0.009" length="0.057" />
        </geometry>
      </collision> -->
    <!-- <collision group="other">
        <origin xyz="0.052 0 0" rpy="0 0 0"/>
        <geometry>
          <sphere radius="0.009" />
        </geometry>
      </collision> -->
    <!--   end simple shape approximation of f2 -->
    <!-- begin visual shape approximation of f2 -->
    <visual>
      <origin rpy="0 1.57079632679 0" xyz="0.024 0 0"/>
      <geometry>
        <cylinder length="0.057" radius="0.009"/>
      </geometry>
      <material name="right_sandia_hand_skin_suntan">
        <color rgba="0.8 0.6 0.3 1.0"/>
      </material>
    </visual>
    <visual>
      <origin rpy="0 0 0" xyz="0.052 0 0"/>
      <geometry>
        <sphere radius="0.009"/>
      </geometry>
      <material name="right_sandia_hand_skin_suntan">
        <color rgba="0.8 0.6 0.3 1.0"/>
      </material>
    </visual>
    <!-- begin collision mesh of f2    ->
      <collision group="default">
        <origin xyz="0 0 0" rpy="0 0 0"/>
        <geometry>
          <mesh filename="package://sandia_hand_description/meshes/f2.stl"/>
        </geometry>
      </collision>
      <!-   end collision mesh of f2 -->
    <!-- begin visual mesh of f2    ->
      <visual>
        <origin xyz="0 0 0" rpy="0 0 0"/>
        <geometry>
          <mesh filename="package://sandia_hand_description/meshes/f2.stl"/>
        </geometry>
        <material name="${side}_sandia_hand_skin_suntan">
          <color rgba="0.8 0.6 0.3 1.0"/>
        </material>
      </visual>
      <!-   end visual mesh of f2 -->
  </link>
  <link name="right_f0_2_accel">
    <origin rpy="0 0 0" xyz="0 0 0"/>
    <inertial>
      <mass value="0.001"/>
      <origin xyz="0 0 0"/>
      <inertia ixx="0.01" ixy="0" ixz="0" iyy="0.01" iyz="0" izz="0.01"/>
    </inertial>
    <!-- ############ MIT ADDITION ############ -->
    <collision>
      <origin rpy="0 0 0" xyz="0 0 0.001"/>
      <geometry>
        <sphere radius="0"/>
      </geometry>
    </collision>
    <!-- ############    END     ############ -->
  </link>
  <link name="right_f0_2_accel_dummy1">
    <origin rpy="0 0 0" xyz="0 0 0"/>
    <inertial>
      <mass value="0.001"/>
      <origin xyz="0 0 0"/>
      <inertia ixx="0.01" ixy="0" ixz="0" iyy="0.01" iyz="0" izz="0.01"/>
    </inertial>
    <collision>
      <origin rpy="0 0 0" xyz="-0.02 0.0 0.01"/>
      <geometry>
        <sphere radius="0"/>
      </geometry>
    </collision>
  </link>
  <joint name="right_f0_2_accel_dummy1" type="fixed">
    <parent link="right_f0_2"/>
    <child link="right_f0_2_accel_dummy1"/>
    <origin rpy="-1.57079632679 0 0" xyz="0.04 0 0"/>
  </joint>
  <joint name="right_f0_base" type="fixed">
    <parent link="right_palm"/>
    <child link="right_f0_base"/>
    <origin rpy="0 0 0.3" xyz="0.14 0.0 0"/>
  </joint>
  <joint name="right_f0_j1" type="revolute">
    <axis xyz="0 0 1"/>
    <parent link="right_f0_0"/>
    <child link="right_f0_1"/>
    <limit effort="1" lower="-1.57079632679" upper="1.57079632679" velocity="1"/>
    <safety_controller k_position="1000.0" k_velocity="1000.0" soft_lower_limit="-11.57079" soft_upper_limit="11.57079"/>
    <dynamics damping="0.2"/>
    <origin rpy="1.57079632679 0 0" xyz="0.028 0 0"/>
  </joint>
  <joint name="right_f0_j2" type="revolute">
    <axis xyz="0 0 1"/>
    <parent link="right_f0_1"/>
    <child link="right_f0_2"/>
    <origin rpy="0 0 0" xyz="0.05 0 0"/>
    <safety_controller k_position="1000.0" k_velocity="1000.0" soft_lower_limit="-11.57079" soft_upper_limit="11.57079"/>
    <dynamics damping="0.2"/>
    <limit effort="1" lower="-1.57079632679" upper="1.57079632679" velocity="1"/>
  </joint>
  <joint name="right_f0_fixed_accel" type="fixed">
    <parent link="right_f0_base"/>
    <child link="right_f0_fixed_accel"/>
    <origin rpy="0 0 0" xyz="-0.05 0 0"/>
  </joint>
  <joint name="right_f0_1_accel" type="fixed">
    <parent link="right_f0_1"/>
    <child link="right_f0_1_accel"/>
    <origin rpy="-1.57079632679 0 0" xyz="0.03 0 0"/>
  </joint>
  <joint name="right_f0_2_accel" type="fixed">
    <parent link="right_f0_2"/>
    <child link="right_f0_2_accel"/>
    <origin rpy="-1.57079632679 0 0" xyz="0.04 0 0"/>
  </joint>
  <link name="right_f0_knuckle_dummy_contact">
    <origin rpy="0 0 0" xyz="0 0 0"/>
    <inertial>
      <mass value="0.001"/>
      <origin xyz="0 0 0"/>
      <inertia ixx="0.001" ixy="0" ixz="0" iyy="0.001" iyz="0" izz="0.001"/>
    </inertial>
    <collision>
      <origin rpy="0 0 0" xyz="0.058 0 0.034"/>
      <geometry>
        <sphere radius="0"/>
      </geometry>
    </collision>
  </link>
  <joint name="right_f0_knuckle_dummy_contact" type="fixed">
    <parent link="right_f0_base"/>
    <child link="right_f0_knuckle_dummy_contact"/>
    <origin rpy="0 0 0" xyz="-0.05 0 0"/>
  </joint>
  <transmission name="right_f0_j0" type="pr2_mechanism_model/SimpleTransmission">
    <joint name="right_f0_j0"/>
    <actuator name="right_f0_j0_motor"/>
    <mechanicalReduction>1</mechanicalReduction>
  </transmission>
  <transmission name="right_f0_j1" type="pr2_mechanism_model/SimpleTransmission">
    <joint name="right_f0_j1"/>
    <actuator name="right_f0_j1_motor"/>
    <mechanicalReduction>1</mechanicalReduction>
  </transmission>
  <transmission name="right_f0_j2" type="pr2_mechanism_model/SimpleTransmission">
    <joint name="right_f0_j2"/>
    <actuator name="right_f0_j2_motor"/>
    <mechanicalReduction>1</mechanicalReduction>
  </transmission>
  <link name="right_f1_base">
    <origin rpy="0 0 0" xyz="0 0 0"/>
    <inertial>
      <mass value="0.35"/>
      <origin xyz="0 0 0"/>
      <inertia ixx="0.01" ixy="0" ixz="0" iyy="0.01" iyz="0" izz="0.01"/>
    </inertial>
  </link>
  <link name="right_f1_fixed_accel">
    <origin rpy="0 0 0" xyz="0 0 0"/>
    <inertial>
      <mass value="0.001"/>
      <origin xyz="0 0 0"/>
      <inertia ixx="0.01" ixy="0" ixz="0" iyy="0.01" iyz="0" izz="0.01"/>
    </inertial>
    <!-- ############ MIT ADDITION ############ -->
    <collision>
      <origin rpy="0 0 0" xyz="0 0 0.05"/>
      <geometry>
        <sphere radius="0"/>
      </geometry>
    </collision>
    <!-- ############    END     ############ -->
  </link>
  <link name="right_f1_0">
    <origin rpy="0 0 0" xyz="0 0 0"/>
    <inertial>
      <mass value="0.05"/>
      <origin xyz="0 0 0"/>
      <inertia ixx="0.01" ixy="0" ixz="0" iyy="0.01" iyz="0" izz="0.01"/>
    </inertial>
    <!-- begin simple shape approximation of f0 -->
    <!-- <collision group="default">
        <origin xyz="0 0 0.003" rpy="0 0 0"/>
        <geometry>
          <cylinder radius="0.015" length="0.023" />
        </geometry>
      </collision> -->
    <!-- <collision group="other">
        <origin xyz="0.011 0 0.003" rpy="${M_pi/2} 0 0"/>
        <geometry>
          <cylinder radius="0.01" length="0.023" />
        </geometry>
      </collision> -->
    <!--   end simple shape approximation of f0 -->
    <!-- begin visual shape approximation of f0 -->
    <visual>
      <origin rpy="0 0 0" xyz="0 0 0.003"/>
      <geometry>
        <cylinder length="0.023" radius="0.015"/>
      </geometry>
      <material name="right_sandia_hand_skin_suntan">
        <color rgba="0.7 0.4 0.2 1.0"/>
      </material>
    </visual>
    <visual>
      <origin rpy="1.57079632679 0 0" xyz="0.011 0 0.003"/>
      <geometry>
        <cylinder length="0.023" radius="0.01"/>
      </geometry>
      <material name="right_sandia_hand_skin_suntan">
        <color rgba="0.7 0.4 0.2 1.0"/>
      </material>
    </visual>
    <!--   end visual shape approximation of f0 -->
    <!-- begin collision mesh of f0 ->
      <collision group="default">
        <origin xyz="0 0 0" rpy="0 0 0"/>
        <geometry>
          <mesh filename="package://sandia_hand_description/meshes/f0.stl"/>
        </geometry>
      </collision>
      <!-   end collision mesh of f0 -->
    <!-- begin visual mesh of f0 ->
      <visual>
        <origin xyz="0 0 0" rpy="0 0 0"/>
        <geometry>
          <mesh filename="package://sandia_hand_description/meshes/f0.stl"/>
        </geometry>
        <material name="${side}_sandia_hand_skin_suntan">
          <color rgba="0.7 0.4 0.2 1.0"/>
        </material>
      </visual>
      <!-   end visual mesh of f0 -->
  </link>
  <link name="right_f1_1">
    <origin rpy="0 0 0" xyz="0 0 0"/>
    <inertial>
      <mass value="0.05"/>
      <origin xyz="0 0 0"/>
      <inertia ixx="0.01" ixy="0" ixz="0" iyy="0.01" iyz="0" izz="0.01"/>
    </inertial>
    <!-- begin simple shape approximation of f1 -->
    <!-- <collision group="default">
        <origin xyz="0.024 0 0" rpy="0 ${M_pi/2} 0"/>
        <geometry>
          <cylinder radius="0.01" length="0.067" />
        </geometry>
      </collision> -->
    <!--   end simple shape approximation of f1 -->
    <!-- begin visual shape approximation of f1 -->
    <visual>
      <origin rpy="0 1.57079632679 0" xyz="0.024 0 0"/>
      <geometry>
        <cylinder length="0.067" radius="0.01"/>
      </geometry>
      <material name="right_sandia_hand_skin">
        <color rgba="0.835 0.655 0.345 1.0"/>
      </material>
    </visual>
    <!--   end visual shape approximation of f1 -->
    <!-- begin collision mesh of f1 ->
      <collision group="default">
        <origin xyz="0 0 0" rpy="0 0 0"/>
        <geometry>
          <mesh filename="package://sandia_hand_description/meshes/f1.stl"/>
        </geometry>
      </collision>
      <!-   end collision mesh of f1 -->
    <!-- begin visual mesh of f1 ->
      <visual>
        <origin xyz="0 0 0" rpy="0 0 0"/>
        <geometry>
          <mesh filename="package://sandia_hand_description/meshes/f1.stl"/>
        </geometry>
        <material name="${side}_sandia_hand_skin">
          <color rgba="0.835 0.655 0.345 1.0"/>
        </material>
      </visual>
      <!-   end visual mesh of f1 -->
  </link>
  <link name="right_f1_1_accel">
    <origin rpy="0 0 0" xyz="0 0 0"/>
    <inertial>
      <mass value="0.001"/>
      <origin xyz="0 0 0"/>
      <inertia ixx="0.01" ixy="0" ixz="0" iyy="0.01" iyz="0" izz="0.01"/>
    </inertial>
    <!-- ############ MIT ADDITION ############ -->
    <!--      <collision>-->
    <!--        <origin rpy="0 0 0" xyz="0 0 0.01"/>-->
    <!--        <geometry>-->
    <!--          <sphere radius="0"/>-->
    <!--        </geometry>-->
    <!--      </collision>  -->
    <!-- ############    END     ############ -->
  </link>
  <link name="right_f1_2">
    <origin rpy="0 0 0" xyz="0 0 0"/>
    <inertial>
      <mass value="0.05"/>
      <origin xyz="0 0 0"/>
      <inertia ixx="0.01" ixy="0" ixz="0" iyy="0.01" iyz="0" izz="0.01"/>
    </inertial>
    <!-- begin simple shape approximation of f2 -->
    <!-- <collision group="default">
        <origin xyz="0.024 0 0" rpy="0 ${M_pi/2} 0"/>
        <geometry>
          <cylinder radius="0.009" length="0.057" />
        </geometry>
      </collision> -->
    <!-- <collision group="other">
        <origin xyz="0.052 0 0" rpy="0 0 0"/>
        <geometry>
          <sphere radius="0.009" />
        </geometry>
      </collision> -->
    <!--   end simple shape approximation of f2 -->
    <!-- begin visual shape approximation of f2 -->
    <visual>
      <origin rpy="0 1.57079632679 0" xyz="0.024 0 0"/>
      <geometry>
        <cylinder length="0.057" radius="0.009"/>
      </geometry>
      <material name="right_sandia_hand_skin_suntan">
        <color rgba="0.8 0.6 0.3 1.0"/>
      </material>
    </visual>
    <visual>
      <origin rpy="0 0 0" xyz="0.052 0 0"/>
      <geometry>
        <sphere radius="0.009"/>
      </geometry>
      <material name="right_sandia_hand_skin_suntan">
        <color rgba="0.8 0.6 0.3 1.0"/>
      </material>
    </visual>
    <!-- begin collision mesh of f2    ->
      <collision group="default">
        <origin xyz="0 0 0" rpy="0 0 0"/>
        <geometry>
          <mesh filename="package://sandia_hand_description/meshes/f2.stl"/>
        </geometry>
      </collision>
      <!-   end collision mesh of f2 -->
    <!-- begin visual mesh of f2    ->
      <visual>
        <origin xyz="0 0 0" rpy="0 0 0"/>
        <geometry>
          <mesh filename="package://sandia_hand_description/meshes/f2.stl"/>
        </geometry>
        <material name="${side}_sandia_hand_skin_suntan">
          <color rgba="0.8 0.6 0.3 1.0"/>
        </material>
      </visual>
      <!-   end visual mesh of f2 -->
  </link>
  <link name="right_f1_2_accel">
    <origin rpy="0 0 0" xyz="0 0 0"/>
    <inertial>
      <mass value="0.001"/>
      <origin xyz="0 0 0"/>
      <inertia ixx="0.01" ixy="0" ixz="0" iyy="0.01" iyz="0" izz="0.01"/>
    </inertial>
    <!-- ############ MIT ADDITION ############ -->
    <collision>
      <origin rpy="0 0 0" xyz="0 0 0.001"/>
      <geometry>
        <sphere radius="0"/>
      </geometry>
    </collision>
    <!-- ############    END     ############ -->
  </link>
  <link name="right_f1_2_accel_dummy1">
    <origin rpy="0 0 0" xyz="0 0 0"/>
    <inertial>
      <mass value="0.001"/>
      <origin xyz="0 0 0"/>
      <inertia ixx="0.01" ixy="0" ixz="0" iyy="0.01" iyz="0" izz="0.01"/>
    </inertial>
    <collision>
      <origin rpy="0 0 0" xyz="-0.02 0.0 0.01"/>
      <geometry>
        <sphere radius="0"/>
      </geometry>
    </collision>
  </link>
  <joint name="right_f1_2_accel_dummy1" type="fixed">
    <parent link="right_f1_2"/>
    <child link="right_f1_2_accel_dummy1"/>
    <origin rpy="-1.57079632679 0 0" xyz="0.04 0 0"/>
  </joint>
  <joint name="right_f1_base" type="fixed">
    <parent link="right_palm"/>
    <child link="right_f1_base"/>
    <origin rpy="0 0 0.3" xyz="0.115 0.03122 0"/>
  </joint>
  <joint name="right_f1_j1" type="revolute">
    <axis xyz="0 0 1"/>
    <parent link="right_f1_0"/>
    <child link="right_f1_1"/>
    <limit effort="1" lower="-1.57079632679" upper="1.57079632679" velocity="1"/>
    <safety_controller k_position="1000.0" k_velocity="1000.0" soft_lower_limit="-11.57079" soft_upper_limit="11.57079"/>
    <dynamics damping="0.2"/>
    <origin rpy="1.57079632679 0 0" xyz="0.028 0 0"/>
  </joint>
  <joint name="right_f1_j2" type="revolute">
    <axis xyz="0 0 1"/>
    <parent link="right_f1_1"/>
    <child link="right_f1_2"/>
    <origin rpy="0 0 0" xyz="0.05 0 0"/>
    <safety_controller k_position="1000.0" k_velocity="1000.0" soft_lower_limit="-11.57079" soft_upper_limit="11.57079"/>
    <dynamics damping="0.2"/>
    <limit effort="1" lower="-1.57079632679" upper="1.57079632679" velocity="1"/>
  </joint>
  <joint name="right_f1_fixed_accel" type="fixed">
    <parent link="right_f1_base"/>
    <child link="right_f1_fixed_accel"/>
    <origin rpy="0 0 0" xyz="-0.05 0 0"/>
  </joint>
  <joint name="right_f1_1_accel" type="fixed">
    <parent link="right_f1_1"/>
    <child link="right_f1_1_accel"/>
    <origin rpy="-1.57079632679 0 0" xyz="0.03 0 0"/>
  </joint>
  <joint name="right_f1_2_accel" type="fixed">
    <parent link="right_f1_2"/>
    <child link="right_f1_2_accel"/>
    <origin rpy="-1.57079632679 0 0" xyz="0.04 0 0"/>
  </joint>
  <link name="right_f1_knuckle_dummy_contact">
    <origin rpy="0 0 0" xyz="0 0 0"/>
    <inertial>
      <mass value="0.001"/>
      <origin xyz="0 0 0"/>
      <inertia ixx="0.001" ixy="0" ixz="0" iyy="0.001" iyz="0" izz="0.001"/>
    </inertial>
    <collision>
      <origin rpy="0 0 0" xyz="0.058 0 0.034"/>
      <geometry>
        <sphere radius="0"/>
      </geometry>
    </collision>
  </link>
  <joint name="right_f1_knuckle_dummy_contact" type="fixed">
    <parent link="right_f1_base"/>
    <child link="right_f1_knuckle_dummy_contact"/>
    <origin rpy="0 0 0" xyz="-0.05 0 0"/>
  </joint>
  <transmission name="right_f1_j0" type="pr2_mechanism_model/SimpleTransmission">
    <joint name="right_f1_j0"/>
    <actuator name="right_f1_j0_motor"/>
    <mechanicalReduction>1</mechanicalReduction>
  </transmission>
  <transmission name="right_f1_j1" type="pr2_mechanism_model/SimpleTransmission">
    <joint name="right_f1_j1"/>
    <actuator name="right_f1_j1_motor"/>
    <mechanicalReduction>1</mechanicalReduction>
  </transmission>
  <transmission name="right_f1_j2" type="pr2_mechanism_model/SimpleTransmission">
    <joint name="right_f1_j2"/>
    <actuator name="right_f1_j2_motor"/>
    <mechanicalReduction>1</mechanicalReduction>
  </transmission>
  <link name="right_f2_base">
    <origin rpy="0 0 0" xyz="0 0 0"/>
    <inertial>
      <mass value="0.35"/>
      <origin xyz="0 0 0"/>
      <inertia ixx="0.01" ixy="0" ixz="0" iyy="0.01" iyz="0" izz="0.01"/>
    </inertial>
  </link>
  <link name="right_f2_fixed_accel">
    <origin rpy="0 0 0" xyz="0 0 0"/>
    <inertial>
      <mass value="0.001"/>
      <origin xyz="0 0 0"/>
      <inertia ixx="0.01" ixy="0" ixz="0" iyy="0.01" iyz="0" izz="0.01"/>
    </inertial>
    <!-- ############ MIT ADDITION ############ -->
    <collision>
      <origin rpy="0 0 0" xyz="0 0 0.05"/>
      <geometry>
        <sphere radius="0"/>
      </geometry>
    </collision>
    <!-- ############    END     ############ -->
  </link>
  <link name="right_f2_0">
    <origin rpy="0 0 0" xyz="0 0 0"/>
    <inertial>
      <mass value="0.05"/>
      <origin xyz="0 0 0"/>
      <inertia ixx="0.01" ixy="0" ixz="0" iyy="0.01" iyz="0" izz="0.01"/>
    </inertial>
    <!-- begin simple shape approximation of f0 -->
    <!-- <collision group="default">
        <origin xyz="0 0 0.003" rpy="0 0 0"/>
        <geometry>
          <cylinder radius="0.015" length="0.023" />
        </geometry>
      </collision> -->
    <!-- <collision group="other">
        <origin xyz="0.011 0 0.003" rpy="${M_pi/2} 0 0"/>
        <geometry>
          <cylinder radius="0.01" length="0.023" />
        </geometry>
      </collision> -->
    <!--   end simple shape approximation of f0 -->
    <!-- begin visual shape approximation of f0 -->
    <visual>
      <origin rpy="0 0 0" xyz="0 0 0.003"/>
      <geometry>
        <cylinder length="0.023" radius="0.015"/>
      </geometry>
      <material name="right_sandia_hand_skin_suntan">
        <color rgba="0.7 0.4 0.2 1.0"/>
      </material>
    </visual>
    <visual>
      <origin rpy="1.57079632679 0 0" xyz="0.011 0 0.003"/>
      <geometry>
        <cylinder length="0.023" radius="0.01"/>
      </geometry>
      <material name="right_sandia_hand_skin_suntan">
        <color rgba="0.7 0.4 0.2 1.0"/>
      </material>
    </visual>
    <!--   end visual shape approximation of f0 -->
    <!-- begin collision mesh of f0 ->
      <collision group="default">
        <origin xyz="0 0 0" rpy="0 0 0"/>
        <geometry>
          <mesh filename="package://sandia_hand_description/meshes/f0.stl"/>
        </geometry>
      </collision>
      <!-   end collision mesh of f0 -->
    <!-- begin visual mesh of f0 ->
      <visual>
        <origin xyz="0 0 0" rpy="0 0 0"/>
        <geometry>
          <mesh filename="package://sandia_hand_description/meshes/f0.stl"/>
        </geometry>
        <material name="${side}_sandia_hand_skin_suntan">
          <color rgba="0.7 0.4 0.2 1.0"/>
        </material>
      </visual>
      <!-   end visual mesh of f0 -->
  </link>
  <link name="right_f2_1">
    <origin rpy="0 0 0" xyz="0 0 0"/>
    <inertial>
      <mass value="0.05"/>
      <origin xyz="0 0 0"/>
      <inertia ixx="0.01" ixy="0" ixz="0" iyy="0.01" iyz="0" izz="0.01"/>
    </inertial>
    <!-- begin simple shape approximation of f1 -->
    <!-- <collision group="default">
        <origin xyz="0.024 0 0" rpy="0 ${M_pi/2} 0"/>
        <geometry>
          <cylinder radius="0.01" length="0.067" />
        </geometry>
      </collision> -->
    <!--   end simple shape approximation of f1 -->
    <!-- begin visual shape approximation of f1 -->
    <visual>
      <origin rpy="0 1.57079632679 0" xyz="0.024 0 0"/>
      <geometry>
        <cylinder length="0.067" radius="0.01"/>
      </geometry>
      <material name="right_sandia_hand_skin">
        <color rgba="0.835 0.655 0.345 1.0"/>
      </material>
    </visual>
    <!--   end visual shape approximation of f1 -->
    <!-- begin collision mesh of f1 ->
      <collision group="default">
        <origin xyz="0 0 0" rpy="0 0 0"/>
        <geometry>
          <mesh filename="package://sandia_hand_description/meshes/f1.stl"/>
        </geometry>
      </collision>
      <!-   end collision mesh of f1 -->
    <!-- begin visual mesh of f1 ->
      <visual>
        <origin xyz="0 0 0" rpy="0 0 0"/>
        <geometry>
          <mesh filename="package://sandia_hand_description/meshes/f1.stl"/>
        </geometry>
        <material name="${side}_sandia_hand_skin">
          <color rgba="0.835 0.655 0.345 1.0"/>
        </material>
      </visual>
      <!-   end visual mesh of f1 -->
  </link>
  <link name="right_f2_1_accel">
    <origin rpy="0 0 0" xyz="0 0 0"/>
    <inertial>
      <mass value="0.001"/>
      <origin xyz="0 0 0"/>
      <inertia ixx="0.01" ixy="0" ixz="0" iyy="0.01" iyz="0" izz="0.01"/>
    </inertial>
    <!-- ############ MIT ADDITION ############ -->
    <!--      <collision>-->
    <!--        <origin rpy="0 0 0" xyz="0 0 0.01"/>-->
    <!--        <geometry>-->
    <!--          <sphere radius="0"/>-->
    <!--        </geometry>-->
    <!--      </collision>  -->
    <!-- ############    END     ############ -->
  </link>
  <link name="right_f2_2">
    <origin rpy="0 0 0" xyz="0 0 0"/>
    <inertial>
      <mass value="0.05"/>
      <origin xyz="0 0 0"/>
      <inertia ixx="0.01" ixy="0" ixz="0" iyy="0.01" iyz="0" izz="0.01"/>
    </inertial>
    <!-- begin simple shape approximation of f2 -->
    <!-- <collision group="default">
        <origin xyz="0.024 0 0" rpy="0 ${M_pi/2} 0"/>
        <geometry>
          <cylinder radius="0.009" length="0.057" />
        </geometry>
      </collision> -->
    <!-- <collision group="other">
        <origin xyz="0.052 0 0" rpy="0 0 0"/>
        <geometry>
          <sphere radius="0.009" />
        </geometry>
      </collision> -->
    <!--   end simple shape approximation of f2 -->
    <!-- begin visual shape approximation of f2 -->
    <visual>
      <origin rpy="0 1.57079632679 0" xyz="0.024 0 0"/>
      <geometry>
        <cylinder length="0.057" radius="0.009"/>
      </geometry>
      <material name="right_sandia_hand_skin_suntan">
        <color rgba="0.8 0.6 0.3 1.0"/>
      </material>
    </visual>
    <visual>
      <origin rpy="0 0 0" xyz="0.052 0 0"/>
      <geometry>
        <sphere radius="0.009"/>
      </geometry>
      <material name="right_sandia_hand_skin_suntan">
        <color rgba="0.8 0.6 0.3 1.0"/>
      </material>
    </visual>
    <!-- begin collision mesh of f2    ->
      <collision group="default">
        <origin xyz="0 0 0" rpy="0 0 0"/>
        <geometry>
          <mesh filename="package://sandia_hand_description/meshes/f2.stl"/>
        </geometry>
      </collision>
      <!-   end collision mesh of f2 -->
    <!-- begin visual mesh of f2    ->
      <visual>
        <origin xyz="0 0 0" rpy="0 0 0"/>
        <geometry>
          <mesh filename="package://sandia_hand_description/meshes/f2.stl"/>
        </geometry>
        <material name="${side}_sandia_hand_skin_suntan">
          <color rgba="0.8 0.6 0.3 1.0"/>
        </material>
      </visual>
      <!-   end visual mesh of f2 -->
  </link>
  <link name="right_f2_2_accel">
    <origin rpy="0 0 0" xyz="0 0 0"/>
    <inertial>
      <mass value="0.001"/>
      <origin xyz="0 0 0"/>
      <inertia ixx="0.01" ixy="0" ixz="0" iyy="0.01" iyz="0" izz="0.01"/>
    </inertial>
    <!-- ############ MIT ADDITION ############ -->
    <collision>
      <origin rpy="0 0 0" xyz="0 0 0.001"/>
      <geometry>
        <sphere radius="0"/>
      </geometry>
    </collision>
    <!-- ############    END     ############ -->
  </link>
  <link name="right_f2_2_accel_dummy1">
    <origin rpy="0 0 0" xyz="0 0 0"/>
    <inertial>
      <mass value="0.001"/>
      <origin xyz="0 0 0"/>
      <inertia ixx="0.01" ixy="0" ixz="0" iyy="0.01" iyz="0" izz="0.01"/>
    </inertial>
    <collision>
      <origin rpy="0 0 0" xyz="-0.02 0.0 0.01"/>
      <geometry>
        <sphere radius="0"/>
      </geometry>
    </collision>
  </link>
  <joint name="right_f2_2_accel_dummy1" type="fixed">
    <parent link="right_f2_2"/>
    <child link="right_f2_2_accel_dummy1"/>
    <origin rpy="-1.57079632679 0 0" xyz="0.04 0 0"/>
  </joint>
  <joint name="right_f2_base" type="fixed">
    <parent link="right_palm"/>
    <child link="right_f2_base"/>
    <origin rpy="0 0 0.3" xyz="0.09 0.06245 0"/>
  </joint>
  <joint name="right_f2_j1" type="revolute">
    <axis xyz="0 0 1"/>
    <parent link="right_f2_0"/>
    <child link="right_f2_1"/>
    <limit effort="1" lower="-1.57079632679" upper="1.57079632679" velocity="1"/>
    <safety_controller k_position="1000.0" k_velocity="1000.0" soft_lower_limit="-11.57079" soft_upper_limit="11.57079"/>
    <dynamics damping="0.2"/>
    <origin rpy="1.57079632679 0 0" xyz="0.028 0 0"/>
  </joint>
  <joint name="right_f2_j2" type="revolute">
    <axis xyz="0 0 1"/>
    <parent link="right_f2_1"/>
    <child link="right_f2_2"/>
    <origin rpy="0 0 0" xyz="0.05 0 0"/>
    <safety_controller k_position="1000.0" k_velocity="1000.0" soft_lower_limit="-11.57079" soft_upper_limit="11.57079"/>
    <dynamics damping="0.2"/>
    <limit effort="1" lower="-1.57079632679" upper="1.57079632679" velocity="1"/>
  </joint>
  <joint name="right_f2_fixed_accel" type="fixed">
    <parent link="right_f2_base"/>
    <child link="right_f2_fixed_accel"/>
    <origin rpy="0 0 0" xyz="-0.05 0 0"/>
  </joint>
  <joint name="right_f2_1_accel" type="fixed">
    <parent link="right_f2_1"/>
    <child link="right_f2_1_accel"/>
    <origin rpy="-1.57079632679 0 0" xyz="0.03 0 0"/>
  </joint>
  <joint name="right_f2_2_accel" type="fixed">
    <parent link="right_f2_2"/>
    <child link="right_f2_2_accel"/>
    <origin rpy="-1.57079632679 0 0" xyz="0.04 0 0"/>
  </joint>
  <link name="right_f2_knuckle_dummy_contact">
    <origin rpy="0 0 0" xyz="0 0 0"/>
    <inertial>
      <mass value="0.001"/>
      <origin xyz="0 0 0"/>
      <inertia ixx="0.001" ixy="0" ixz="0" iyy="0.001" iyz="0" izz="0.001"/>
    </inertial>
    <collision>
      <origin rpy="0 0 0" xyz="0.058 0 0.034"/>
      <geometry>
        <sphere radius="0"/>
      </geometry>
    </collision>
  </link>
  <joint name="right_f2_knuckle_dummy_contact" type="fixed">
    <parent link="right_f2_base"/>
    <child link="right_f2_knuckle_dummy_contact"/>
    <origin rpy="0 0 0" xyz="-0.05 0 0"/>
  </joint>
  <transmission name="right_f2_j0" type="pr2_mechanism_model/SimpleTransmission">
    <joint name="right_f2_j0"/>
    <actuator name="right_f2_j0_motor"/>
    <mechanicalReduction>1</mechanicalReduction>
  </transmission>
  <transmission name="right_f2_j1" type="pr2_mechanism_model/SimpleTransmission">
    <joint name="right_f2_j1"/>
    <actuator name="right_f2_j1_motor"/>
    <mechanicalReduction>1</mechanicalReduction>
  </transmission>
  <transmission name="right_f2_j2" type="pr2_mechanism_model/SimpleTransmission">
    <joint name="right_f2_j2"/>
    <actuator name="right_f2_j2_motor"/>
    <mechanicalReduction>1</mechanicalReduction>
  </transmission>
  <link name="right_f3_base">
    <origin rpy="0 0 0" xyz="0 0 0"/>
    <inertial>
      <mass value="0.35"/>
      <origin xyz="0 0 0"/>
      <inertia ixx="0.01" ixy="0" ixz="0" iyy="0.01" iyz="0" izz="0.01"/>
    </inertial>
  </link>
  <link name="right_f3_fixed_accel">
    <origin rpy="0 0 0" xyz="0 0 0"/>
    <inertial>
      <mass value="0.001"/>
      <origin xyz="0 0 0"/>
      <inertia ixx="0.01" ixy="0" ixz="0" iyy="0.01" iyz="0" izz="0.01"/>
    </inertial>
  </link>
  <link name="right_f3_0">
    <origin rpy="0 0 0" xyz="0 0 0"/>
    <inertial>
      <mass value="0.05"/>
      <origin xyz="0 0 0"/>
      <inertia ixx="0.01" ixy="0" ixz="0" iyy="0.01" iyz="0" izz="0.01"/>
    </inertial>
    <!-- begin simple shape approximation of f0 -->
    <!-- <collision group="default">
        <origin xyz="0 0 0.003" rpy="0 0 0"/>
        <geometry>
          <cylinder radius="0.015" length="0.023" />
        </geometry>
      </collision> -->
    <!-- <collision group="other">
        <origin xyz="0.011 0 0.003" rpy="${M_pi/2} 0 0"/>
        <geometry>
          <cylinder radius="0.01" length="0.023" />
        </geometry>
      </collision> -->
    <!--   end simple shape approximation of f0 -->
    <!-- begin visual shape approximation of f0 -->
    <visual>
      <origin rpy="0 0 0" xyz="0 0 0.003"/>
      <geometry>
        <cylinder length="0.023" radius="0.015"/>
      </geometry>
      <material name="right_sandia_hand_skin_suntan">
        <color rgba="0.7 0.4 0.2 1.0"/>
      </material>
    </visual>
    <visual>
      <origin rpy="1.57079632679 0 0" xyz="0.011 0 0.003"/>
      <geometry>
        <cylinder length="0.023" radius="0.01"/>
      </geometry>
      <material name="right_sandia_hand_skin_suntan">
        <color rgba="0.7 0.4 0.2 1.0"/>
      </material>
    </visual>
    <!--   end visual shape approximation of f0 -->
    <!-- begin collision mesh of f0 ->
      <collision group="default">
        <origin xyz="0 0 0" rpy="0 0 0"/>
        <geometry>
          <mesh filename="package://sandia_hand_description/meshes/f0.stl"/>
        </geometry>
      </collision>
      <!-   end collision mesh of f0 -->
    <!-- begin visual mesh of f0 ->
      <visual>
        <origin xyz="0 0 0" rpy="0 0 0"/>
        <geometry>
          <mesh filename="package://sandia_hand_description/meshes/f0.stl"/>
        </geometry>
        <material name="${side}_sandia_hand_skin_suntan">
          <color rgba="0.7 0.4 0.2 1.0"/>
        </material>
      </visual>
      <!-   end visual mesh of f0 -->
  </link>
  <link name="right_f3_1">
    <origin rpy="0 0 0" xyz="0 0 0"/>
    <inertial>
      <mass value="0.05"/>
      <origin xyz="0 0 0"/>
      <inertia ixx="0.01" ixy="0" ixz="0" iyy="0.01" iyz="0" izz="0.01"/>
    </inertial>
    <!-- begin simple shape approximation of f1 -->
    <!-- <collision group="default">
        <origin xyz="0.024 0 0" rpy="0 ${M_pi/2} 0"/>
        <geometry>
          <cylinder radius="0.01" length="0.067" />
        </geometry>
      </collision> -->
    <!--   end simple shape approximation of f1 -->
    <!-- begin visual shape approximation of f1 -->
    <visual>
      <origin rpy="0 1.57079632679 0" xyz="0.024 0 0"/>
      <geometry>
        <cylinder length="0.067" radius="0.01"/>
      </geometry>
      <material name="right_sandia_hand_skin">
        <color rgba="0.835 0.655 0.345 1.0"/>
      </material>
    </visual>
    <!--   end visual shape approximation of f1 -->
    <!-- begin collision mesh of f1 ->
      <collision group="default">
        <origin xyz="0 0 0" rpy="0 0 0"/>
        <geometry>
          <mesh filename="package://sandia_hand_description/meshes/f1.stl"/>
        </geometry>
      </collision>
      <!-   end collision mesh of f1 -->
    <!-- begin visual mesh of f1 ->
      <visual>
        <origin xyz="0 0 0" rpy="0 0 0"/>
        <geometry>
          <mesh filename="package://sandia_hand_description/meshes/f1.stl"/>
        </geometry>
        <material name="${side}_sandia_hand_skin">
          <color rgba="0.835 0.655 0.345 1.0"/>
        </material>
      </visual>
      <!-   end visual mesh of f1 -->
  </link>
  <link name="right_f3_1_accel">
    <origin rpy="0 0 0" xyz="0 0 0"/>
    <inertial>
      <mass value="0.001"/>
      <origin xyz="0 0 0"/>
      <inertia ixx="0.01" ixy="0" ixz="0" iyy="0.01" iyz="0" izz="0.01"/>
    </inertial>
  </link>
  <link name="right_f3_2">
    <origin rpy="0 0 0" xyz="0 0 0"/>
    <inertial>
      <mass value="0.05"/>
      <origin xyz="0 0 0"/>
      <inertia ixx="0.01" ixy="0" ixz="0" iyy="0.01" iyz="0" izz="0.01"/>
    </inertial>
    <!-- begin simple shape approximation of f2 -->
    <!-- <collision group="default">
        <origin xyz="0.024 0 0" rpy="0 ${M_pi/2} 0"/>
        <geometry>
          <cylinder radius="0.009" length="0.057" />
        </geometry>
      </collision> -->
    <!-- <collision group="other">
        <origin xyz="0.052 0 0" rpy="0 0 0"/>
        <geometry>
          <sphere radius="0.009" />
        </geometry>
      </collision> -->
    <!--   end simple shape approximation of f2 -->
    <!-- begin visual shape approximation of f2 -->
    <visual>
      <origin rpy="0 1.57079632679 0" xyz="0.024 0 0"/>
      <geometry>
        <cylinder length="0.057" radius="0.009"/>
      </geometry>
      <material name="right_sandia_hand_skin_suntan">
        <color rgba="0.8 0.6 0.3 1.0"/>
      </material>
    </visual>
    <visual>
      <origin rpy="0 0 0" xyz="0.052 0 0"/>
      <geometry>
        <sphere radius="0.009"/>
      </geometry>
      <material name="right_sandia_hand_skin_suntan">
        <color rgba="0.8 0.6 0.3 1.0"/>
      </material>
    </visual>
    <!-- begin collision mesh of f2    ->
      <collision group="default">
        <origin xyz="0 0 0" rpy="0 0 0"/>
        <geometry>
          <mesh filename="package://sandia_hand_description/meshes/f2.stl"/>
        </geometry>
      </collision>
      <!-   end collision mesh of f2 -->
    <!-- begin visual mesh of f2    ->
      <visual>
        <origin xyz="0 0 0" rpy="0 0 0"/>
        <geometry>
          <mesh filename="package://sandia_hand_description/meshes/f2.stl"/>
        </geometry>
        <material name="${side}_sandia_hand_skin_suntan">
          <color rgba="0.8 0.6 0.3 1.0"/>
        </material>
      </visual>
      <!-   end visual mesh of f2 -->
  </link>
  <link name="right_f3_2_accel">
    <origin rpy="0 0 0" xyz="0 0 0"/>
    <inertial>
      <mass value="0.001"/>
      <origin xyz="0 0 0"/>
      <inertia ixx="0.01" ixy="0" ixz="0" iyy="0.01" iyz="0" izz="0.01"/>
    </inertial>
    <!-- ############ MIT ADDITION ############ -->
    <collision>
      <origin rpy="0 0 0" xyz="0 0 0.001"/>
      <geometry>
        <sphere radius="0"/>
      </geometry>
    </collision>
    <!-- ############    END     ############ -->
  </link>
  <link name="right_f3_2_accel_dummy1">
    <origin rpy="0 0 0" xyz="0 0 0"/>
    <inertial>
      <mass value="0.001"/>
      <origin xyz="0 0 0"/>
      <inertia ixx="0.01" ixy="0" ixz="0" iyy="0.01" iyz="0" izz="0.01"/>
    </inertial>
    <collision>
      <origin rpy="0 0 0" xyz="-0.02 0.0 0.01"/>
      <geometry>
        <sphere radius="0"/>
      </geometry>
    </collision>
  </link>
  <joint name="right_f3_2_accel_dummy1" type="fixed">
    <parent link="right_f3_2"/>
    <child link="right_f3_2_accel_dummy1"/>
    <origin rpy="-1.57079632679 0 0" xyz="0.04 0 0"/>
  </joint>
  <joint name="right_f3_base" type="fixed">
    <parent link="right_palm"/>
    <child link="right_f3_base"/>
    <origin rpy="0 -1.57079632679 -2.3562" xyz="0.03995 -0.04383 0.014"/>
  </joint>
  <joint name="right_f3_j0" type="revolute">
    <axis xyz="0 0 1"/>
    <parent link="right_f3_base"/>
    <child link="right_f3_0"/>
    <limit effort="1" lower="-1.57079632679" upper="1.57079632679" velocity="1"/>
    <safety_controller k_position="1000.0" k_velocity="1000.0" soft_lower_limit="-11.57079" soft_upper_limit="11.57079"/>
    <dynamics damping="0.2"/>
    <origin rpy="0 0 0" xyz="0 0 0"/>
  </joint>
  <joint name="right_f3_j1" type="revolute">
    <axis xyz="0 0 1"/>
    <parent link="right_f3_0"/>
    <child link="right_f3_1"/>
    <limit effort="1" lower="-1.57079632679" upper="1.57079632679" velocity="1"/>
    <safety_controller k_position="1000.0" k_velocity="1000.0" soft_lower_limit="-11.57079" soft_upper_limit="11.57079"/>
    <dynamics damping="0.2"/>
    <origin rpy="1.57079632679 0 0" xyz="0.028 0 0"/>
  </joint>
  <joint name="right_f3_j2" type="revolute">
    <axis xyz="0 0 1"/>
    <parent link="right_f3_1"/>
    <child link="right_f3_2"/>
    <origin rpy="0 0 0" xyz="0.05 0 0"/>
    <safety_controller k_position="1000.0" k_velocity="1000.0" soft_lower_limit="-11.57079" soft_upper_limit="11.57079"/>
    <dynamics damping="0.2"/>
    <limit effort="1" lower="-1.57079632679" upper="1.57079632679" velocity="1"/>
  </joint>
  <joint name="right_f3_fixed_accel" type="fixed">
    <parent link="right_f3_base"/>
    <child link="right_f3_fixed_accel"/>
    <origin rpy="0 0 0" xyz="-0.05 0 0"/>
  </joint>
  <joint name="right_f3_1_accel" type="fixed">
    <parent link="right_f3_1"/>
    <child link="right_f3_1_accel"/>
    <origin rpy="-1.57079632679 0 0" xyz="0.03 0 0"/>
  </joint>
  <joint name="right_f3_2_accel" type="fixed">
    <parent link="right_f3_2"/>
    <child link="right_f3_2_accel"/>
    <origin rpy="-1.57079632679 0 0" xyz="0.04 0 0"/>
  </joint>
  <transmission name="right_f3_j0" type="pr2_mechanism_model/SimpleTransmission">
    <joint name="right_f3_j0"/>
    <actuator name="right_f3_j0_motor"/>
    <mechanicalReduction>1</mechanicalReduction>
  </transmission>
  <transmission name="right_f3_j1" type="pr2_mechanism_model/SimpleTransmission">
    <joint name="right_f3_j1"/>
    <actuator name="right_f3_j1_motor"/>
    <mechanicalReduction>1</mechanicalReduction>
  </transmission>
  <transmission name="right_f3_j2" type="pr2_mechanism_model/SimpleTransmission">
    <joint name="right_f3_j2"/>
    <actuator name="right_f3_j2_motor"/>
    <mechanicalReduction>1</mechanicalReduction>
  </transmission>
  <joint name="right_f0_j0" type="revolute">
    <axis xyz="0 0 1"/>
    <parent link="right_f0_base"/>
    <child link="right_f0_0"/>
    <!--    <limit effort="1" lower="-1.57079" upper="1.57079" velocity="1"/>-->
    <limit effort="1" lower="-1.57079632679" upper="0" velocity="1"/>
    <safety_controller k_position="1000.0" k_velocity="1000.0" soft_lower_limit="-11.57079" soft_upper_limit="11.57079"/>
    <dynamics damping="0.2"/>
    <origin rpy="0 0 0" xyz="0 0 0"/>
  </joint>
  <joint name="right_f1_j0" type="revolute">
    <axis xyz="0 0 1"/>
    <parent link="right_f1_base"/>
    <child link="right_f1_0"/>
    <!--    <limit effort="1" lower="-1.57079" upper="1.57079" velocity="1"/>-->
    <limit effort="1" lower="-0.09" upper="0.09" velocity="1"/>
    <safety_controller k_position="1000.0" k_velocity="1000.0" soft_lower_limit="-11.57079" soft_upper_limit="11.57079"/>
    <dynamics damping="0.2"/>
    <origin rpy="0 0 0" xyz="0 0 0"/>
  </joint>
  <joint name="right_f2_j0" type="revolute">
    <axis xyz="0 0 1"/>
    <parent link="right_f2_base"/>
    <child link="right_f2_0"/>
    <!--    <limit effort="1" lower="-1.57079" upper="1.57079" velocity="1"/>-->
    <limit effort="1" lower="0" upper="1.57079632679" velocity="1"/>
    <safety_controller k_position="1000.0" k_velocity="1000.0" soft_lower_limit="-11.57079" soft_upper_limit="11.57079"/>
    <dynamics damping="0.2"/>
    <origin rpy="0 0 0" xyz="0 0 0"/>
  </joint>
  <link name="left_palm">
    <origin rpy="0 0 0" xyz="0 0 0"/>
    <inertial>
      <mass value="0.3"/>
      <origin xyz="0 0 0"/>
      <inertia ixx="0.01" ixy="0" ixz="0" iyy="0.01" iyz="0" izz="0.01"/>
    </inertial>
    <!-- begin simple shape approximation of palm -->
    <!-- <collision group="default">
        <origin xyz="0.069 ${0.016 * reflect} 0.038" rpy="0 ${M_pi/2} ${-0.9 * reflect}"/>
        <geometry>
          <cylinder radius="0.013" length="0.100" />
        </geometry>
      </collision> -->
    <!-- <collision group="other">
        <origin xyz="0.064 ${0.008 * reflect} 0.021" rpy="0.41 0 ${-0.9 * reflect}"/>
        <geometry>
          <box size="0.09 .035 .05" />
        </geometry>
      </collision> -->
    <!-- <collision group="other">
        <origin xyz="0.02 0 -0.005" rpy="0 ${M_pi/2} 0"/>
        <geometry>
          <cylinder radius="0.038" length="0.05" />
        </geometry>
      </collision> -->
    <!-- <collision group="other">
        <origin xyz="0.11 ${-0.01*reflect} -0.005" rpy="0 0 ${0.37*reflect}"/>
        <geometry>
          <box size="0.09 .03 .06" />
        </geometry>
      </collision> -->
    <!-- <collision group="other">
        <origin xyz="0.09 ${0.02*reflect} -0.005" rpy="0 0 ${0.37*reflect}"/>
        <geometry>
          <box size="0.09 .03 .06" />
        </geometry>
      </collision> -->
    <!--<collision group="other">
        <origin xyz="0.060 ${0.050*reflect} -0.005" rpy="0 0 ${0.37*reflect}"/>
        <geometry>
          <box size="0.09 .03 .06" />
        </geometry>
      </collision> -->
    <!-- <collision group="other">
        <origin xyz="0.044 ${-0.04*reflect} -0.005" rpy="0 0 ${0.79*reflect}"/>
        <geometry>
          <box size="0.09 .03 .06" />
        </geometry>
      </collision>-->
    <!--   end simple shape approximation of palm -->
    <!-- begin visual shape approximation of palm -->
    <visual>
      <origin rpy="0 1.57079632679 0.9" xyz="0.069 -0.016 0.038"/>
      <geometry>
        <cylinder length="0.100" radius="0.013"/>
      </geometry>
      <material name="left_sandia_hand_skin">
        <color rgba="0.835 0.655 0.345 1.0"/>
      </material>
    </visual>
    <visual>
      <origin rpy="0.41 0 0.9" xyz="0.064 -0.008 0.021"/>
      <geometry>
        <box size="0.09 .035 .05"/>
      </geometry>
      <material name="left_sandia_hand_skin">
        <color rgba="0.835 0.655 0.345 1.0"/>
      </material>
    </visual>
    <visual>
      <origin rpy="0 1.57079632679 0" xyz="0.02 0 -0.005"/>
      <geometry>
        <cylinder length="0.05" radius="0.038"/>
      </geometry>
      <material name="left_sandia_hand_skin">
        <color rgba="0.835 0.655 0.345 1.0"/>
      </material>
    </visual>
    <visual>
      <origin rpy="0 0 -0.37" xyz="0.11 0.01 -0.005"/>
      <geometry>
        <box size="0.09 .03 .06"/>
      </geometry>
      <material name="left_sandia_hand_skin">
        <color rgba="0.835 0.655 0.345 1.0"/>
      </material>
    </visual>
    <visual>
      <origin rpy="0 0 -0.37" xyz="0.09 -0.02 -0.005"/>
      <geometry>
        <box size="0.09 .03 .06"/>
      </geometry>
      <material name="left_sandia_hand_skin">
        <color rgba="0.835 0.655 0.345 1.0"/>
      </material>
    </visual>
    <visual>
      <origin rpy="0 0 -0.37" xyz="0.060 -0.05 -0.005"/>
      <geometry>
        <box size="0.09 .03 .06"/>
      </geometry>
      <material name="left_sandia_hand_skin">
        <color rgba="0.835 0.655 0.345 1.0"/>
      </material>
    </visual>
    <visual>
      <origin rpy="0 0 -0.79" xyz="0.044 0.04 -0.005"/>
      <geometry>
        <box size="0.09 .03 .06"/>
      </geometry>
      <material name="left_sandia_hand_skin">
        <color rgba="0.835 0.655 0.345 1.0"/>
      </material>
    </visual>
    <!--   end visual shape approximation of palm -->
    <!-- begin collision mesh of f2 ->
      <collision group="default">
        <origin xyz="0 0 0" rpy="0 0 0"/>
        <geometry>
          <mesh filename="package://sandia_hand_description/meshes/palm.stl"/>
        </geometry>
      </collision>
      <!-   end collision mesh of f2 -->
    <!-- begin visual mesh of f2    ->
      <visual>
        <origin xyz="0 0 0" rpy="0 0 0"/>
        <geometry>
          <mesh filename="package://sandia_hand_description/meshes/palm.stl"/>
        </geometry>
        <material name="${side}_sandia_hand_skin">
          <color rgba="0.835 0.655 0.345 1.0"/>
        </material>
      </visual>
      <!-   end visual mesh of f2 -->
  </link>
  <joint name="left_sandia_hand_joint" type="fixed">
    <parent link="l_hand"/>
    <child link="left_palm"/>
    <origin rpy=" 1.57079 0  1.57079" xyz="0  0.1 0"/>
  </joint>
  <link name="left_f0_base">
    <origin rpy="0 0 0" xyz="0 0 0"/>
    <inertial>
      <mass value="0.35"/>
      <origin xyz="0 0 0"/>
      <inertia ixx="0.01" ixy="0" ixz="0" iyy="0.01" iyz="0" izz="0.01"/>
    </inertial>
  </link>
  <link name="left_f0_fixed_accel">
    <origin rpy="0 0 0" xyz="0 0 0"/>
    <inertial>
      <mass value="0.001"/>
      <origin xyz="0 0 0"/>
      <inertia ixx="0.01" ixy="0" ixz="0" iyy="0.01" iyz="0" izz="0.01"/>
    </inertial>
    <!-- ############ MIT ADDITION ############ -->
    <collision>
      <origin rpy="0 0 0" xyz="0 0 0.05"/>
      <geometry>
        <sphere radius="0"/>
      </geometry>
    </collision>
    <!-- ############    END     ############ -->
  </link>
  <link name="left_f0_0">
    <origin rpy="0 0 0" xyz="0 0 0"/>
    <inertial>
      <mass value="0.05"/>
      <origin xyz="0 0 0"/>
      <inertia ixx="0.01" ixy="0" ixz="0" iyy="0.01" iyz="0" izz="0.01"/>
    </inertial>
    <!-- begin simple shape approximation of f0 -->
    <!-- <collision group="default">
        <origin xyz="0 0 0.003" rpy="0 0 0"/>
        <geometry>
          <cylinder radius="0.015" length="0.023" />
        </geometry>
      </collision> -->
    <!-- <collision group="other">
        <origin xyz="0.011 0 0.003" rpy="${M_pi/2} 0 0"/>
        <geometry>
          <cylinder radius="0.01" length="0.023" />
        </geometry>
      </collision> -->
    <!--   end simple shape approximation of f0 -->
    <!-- begin visual shape approximation of f0 -->
    <visual>
      <origin rpy="0 0 0" xyz="0 0 0.003"/>
      <geometry>
        <cylinder length="0.023" radius="0.015"/>
      </geometry>
      <material name="left_sandia_hand_skin_suntan">
        <color rgba="0.7 0.4 0.2 1.0"/>
      </material>
    </visual>
    <visual>
      <origin rpy="1.57079632679 0 0" xyz="0.011 0 0.003"/>
      <geometry>
        <cylinder length="0.023" radius="0.01"/>
      </geometry>
      <material name="left_sandia_hand_skin_suntan">
        <color rgba="0.7 0.4 0.2 1.0"/>
      </material>
    </visual>
    <!--   end visual shape approximation of f0 -->
    <!-- begin collision mesh of f0 ->
      <collision group="default">
        <origin xyz="0 0 0" rpy="0 0 0"/>
        <geometry>
          <mesh filename="package://sandia_hand_description/meshes/f0.stl"/>
        </geometry>
      </collision>
      <!-   end collision mesh of f0 -->
    <!-- begin visual mesh of f0 ->
      <visual>
        <origin xyz="0 0 0" rpy="0 0 0"/>
        <geometry>
          <mesh filename="package://sandia_hand_description/meshes/f0.stl"/>
        </geometry>
        <material name="${side}_sandia_hand_skin_suntan">
          <color rgba="0.7 0.4 0.2 1.0"/>
        </material>
      </visual>
      <!-   end visual mesh of f0 -->
  </link>
  <link name="left_f0_1">
    <origin rpy="0 0 0" xyz="0 0 0"/>
    <inertial>
      <mass value="0.05"/>
      <origin xyz="0 0 0"/>
      <inertia ixx="0.01" ixy="0" ixz="0" iyy="0.01" iyz="0" izz="0.01"/>
    </inertial>
    <!-- begin simple shape approximation of f1 -->
    <!-- <collision group="default">
        <origin xyz="0.024 0 0" rpy="0 ${M_pi/2} 0"/>
        <geometry>
          <cylinder radius="0.01" length="0.067" />
        </geometry>
      </collision> -->
    <!--   end simple shape approximation of f1 -->
    <!-- begin visual shape approximation of f1 -->
    <visual>
      <origin rpy="0 1.57079632679 0" xyz="0.024 0 0"/>
      <geometry>
        <cylinder length="0.067" radius="0.01"/>
      </geometry>
      <material name="left_sandia_hand_skin">
        <color rgba="0.835 0.655 0.345 1.0"/>
      </material>
    </visual>
    <!--   end visual shape approximation of f1 -->
    <!-- begin collision mesh of f1 ->
      <collision group="default">
        <origin xyz="0 0 0" rpy="0 0 0"/>
        <geometry>
          <mesh filename="package://sandia_hand_description/meshes/f1.stl"/>
        </geometry>
      </collision>
      <!-   end collision mesh of f1 -->
    <!-- begin visual mesh of f1 ->
      <visual>
        <origin xyz="0 0 0" rpy="0 0 0"/>
        <geometry>
          <mesh filename="package://sandia_hand_description/meshes/f1.stl"/>
        </geometry>
        <material name="${side}_sandia_hand_skin">
          <color rgba="0.835 0.655 0.345 1.0"/>
        </material>
      </visual>
      <!-   end visual mesh of f1 -->
  </link>
  <link name="left_f0_1_accel">
    <origin rpy="0 0 0" xyz="0 0 0"/>
    <inertial>
      <mass value="0.001"/>
      <origin xyz="0 0 0"/>
      <inertia ixx="0.01" ixy="0" ixz="0" iyy="0.01" iyz="0" izz="0.01"/>
    </inertial>
    <!-- ############ MIT ADDITION ############ -->
    <!--      <collision>-->
    <!--        <origin rpy="0 0 0" xyz="0 0 0.01"/>-->
    <!--        <geometry>-->
    <!--          <sphere radius="0"/>-->
    <!--        </geometry>-->
    <!--      </collision>  -->
    <!-- ############    END     ############ -->
  </link>
  <link name="left_f0_2">
    <origin rpy="0 0 0" xyz="0 0 0"/>
    <inertial>
      <mass value="0.05"/>
      <origin xyz="0 0 0"/>
      <inertia ixx="0.01" ixy="0" ixz="0" iyy="0.01" iyz="0" izz="0.01"/>
    </inertial>
    <!-- begin simple shape approximation of f2 -->
    <!-- <collision group="default">
        <origin xyz="0.024 0 0" rpy="0 ${M_pi/2} 0"/>
        <geometry>
          <cylinder radius="0.009" length="0.057" />
        </geometry>
      </collision> -->
    <!-- <collision group="other">
        <origin xyz="0.052 0 0" rpy="0 0 0"/>
        <geometry>
          <sphere radius="0.009" />
        </geometry>
      </collision> -->
    <!--   end simple shape approximation of f2 -->
    <!-- begin visual shape approximation of f2 -->
    <visual>
      <origin rpy="0 1.57079632679 0" xyz="0.024 0 0"/>
      <geometry>
        <cylinder length="0.057" radius="0.009"/>
      </geometry>
      <material name="left_sandia_hand_skin_suntan">
        <color rgba="0.8 0.6 0.3 1.0"/>
      </material>
    </visual>
    <visual>
      <origin rpy="0 0 0" xyz="0.052 0 0"/>
      <geometry>
        <sphere radius="0.009"/>
      </geometry>
      <material name="left_sandia_hand_skin_suntan">
        <color rgba="0.8 0.6 0.3 1.0"/>
      </material>
    </visual>
    <!-- begin collision mesh of f2    ->
      <collision group="default">
        <origin xyz="0 0 0" rpy="0 0 0"/>
        <geometry>
          <mesh filename="package://sandia_hand_description/meshes/f2.stl"/>
        </geometry>
      </collision>
      <!-   end collision mesh of f2 -->
    <!-- begin visual mesh of f2    ->
      <visual>
        <origin xyz="0 0 0" rpy="0 0 0"/>
        <geometry>
          <mesh filename="package://sandia_hand_description/meshes/f2.stl"/>
        </geometry>
        <material name="${side}_sandia_hand_skin_suntan">
          <color rgba="0.8 0.6 0.3 1.0"/>
        </material>
      </visual>
      <!-   end visual mesh of f2 -->
  </link>
  <link name="left_f0_2_accel">
    <origin rpy="0 0 0" xyz="0 0 0"/>
    <inertial>
      <mass value="0.001"/>
      <origin xyz="0 0 0"/>
      <inertia ixx="0.01" ixy="0" ixz="0" iyy="0.01" iyz="0" izz="0.01"/>
    </inertial>
    <!-- ############ MIT ADDITION ############ -->
    <collision>
      <origin rpy="0 0 0" xyz="0 0 0.001"/>
      <geometry>
        <sphere radius="0"/>
      </geometry>
    </collision>
    <!-- ############    END     ############ -->
  </link>
  <link name="left_f0_2_accel_dummy1">
    <origin rpy="0 0 0" xyz="0 0 0"/>
    <inertial>
      <mass value="0.001"/>
      <origin xyz="0 0 0"/>
      <inertia ixx="0.01" ixy="0" ixz="0" iyy="0.01" iyz="0" izz="0.01"/>
    </inertial>
    <collision>
      <origin rpy="0 0 0" xyz="-0.02 0.0 0.01"/>
      <geometry>
        <sphere radius="0"/>
      </geometry>
    </collision>
  </link>
  <joint name="left_f0_2_accel_dummy1" type="fixed">
    <parent link="left_f0_2"/>
    <child link="left_f0_2_accel_dummy1"/>
    <origin rpy="-1.57079632679 0 0" xyz="0.04 0 0"/>
  </joint>
  <joint name="left_f0_base" type="fixed">
    <parent link="left_palm"/>
    <child link="left_f0_base"/>
    <origin rpy="0 0 -0.3" xyz="0.14 0.0 0"/>
  </joint>
  <joint name="left_f0_j1" type="revolute">
    <axis xyz="0 0 1"/>
    <parent link="left_f0_0"/>
    <child link="left_f0_1"/>
    <limit effort="1" lower="-1.57079632679" upper="1.57079632679" velocity="1"/>
    <safety_controller k_position="1000.0" k_velocity="1000.0" soft_lower_limit="-11.57079" soft_upper_limit="11.57079"/>
    <dynamics damping="0.2"/>
    <origin rpy="1.57079632679 0 0" xyz="0.028 0 0"/>
  </joint>
  <joint name="left_f0_j2" type="revolute">
    <axis xyz="0 0 1"/>
    <parent link="left_f0_1"/>
    <child link="left_f0_2"/>
    <origin rpy="0 0 0" xyz="0.05 0 0"/>
    <safety_controller k_position="1000.0" k_velocity="1000.0" soft_lower_limit="-11.57079" soft_upper_limit="11.57079"/>
    <dynamics damping="0.2"/>
    <limit effort="1" lower="-1.57079632679" upper="1.57079632679" velocity="1"/>
  </joint>
  <joint name="left_f0_fixed_accel" type="fixed">
    <parent link="left_f0_base"/>
    <child link="left_f0_fixed_accel"/>
    <origin rpy="0 0 0" xyz="-0.05 0 0"/>
  </joint>
  <joint name="left_f0_1_accel" type="fixed">
    <parent link="left_f0_1"/>
    <child link="left_f0_1_accel"/>
    <origin rpy="-1.57079632679 0 0" xyz="0.03 0 0"/>
  </joint>
  <joint name="left_f0_2_accel" type="fixed">
    <parent link="left_f0_2"/>
    <child link="left_f0_2_accel"/>
    <origin rpy="-1.57079632679 0 0" xyz="0.04 0 0"/>
  </joint>
  <link name="left_f0_knuckle_dummy_contact">
    <origin rpy="0 0 0" xyz="0 0 0"/>
    <inertial>
      <mass value="0.001"/>
      <origin xyz="0 0 0"/>
      <inertia ixx="0.001" ixy="0" ixz="0" iyy="0.001" iyz="0" izz="0.001"/>
    </inertial>
    <collision>
      <origin rpy="0 0 0" xyz="0.058 0 0.034"/>
      <geometry>
        <sphere radius="0"/>
      </geometry>
    </collision>
  </link>
  <joint name="left_f0_knuckle_dummy_contact" type="fixed">
    <parent link="left_f0_base"/>
    <child link="left_f0_knuckle_dummy_contact"/>
    <origin rpy="0 0 0" xyz="-0.05 0 0"/>
  </joint>
  <transmission name="left_f0_j0" type="pr2_mechanism_model/SimpleTransmission">
    <joint name="left_f0_j0"/>
    <actuator name="left_f0_j0_motor"/>
    <mechanicalReduction>1</mechanicalReduction>
  </transmission>
  <transmission name="left_f0_j1" type="pr2_mechanism_model/SimpleTransmission">
    <joint name="left_f0_j1"/>
    <actuator name="left_f0_j1_motor"/>
    <mechanicalReduction>1</mechanicalReduction>
  </transmission>
  <transmission name="left_f0_j2" type="pr2_mechanism_model/SimpleTransmission">
    <joint name="left_f0_j2"/>
    <actuator name="left_f0_j2_motor"/>
    <mechanicalReduction>1</mechanicalReduction>
  </transmission>
  <link name="left_f1_base">
    <origin rpy="0 0 0" xyz="0 0 0"/>
    <inertial>
      <mass value="0.35"/>
      <origin xyz="0 0 0"/>
      <inertia ixx="0.01" ixy="0" ixz="0" iyy="0.01" iyz="0" izz="0.01"/>
    </inertial>
  </link>
  <link name="left_f1_fixed_accel">
    <origin rpy="0 0 0" xyz="0 0 0"/>
    <inertial>
      <mass value="0.001"/>
      <origin xyz="0 0 0"/>
      <inertia ixx="0.01" ixy="0" ixz="0" iyy="0.01" iyz="0" izz="0.01"/>
    </inertial>
    <!-- ############ MIT ADDITION ############ -->
    <collision>
      <origin rpy="0 0 0" xyz="0 0 0.05"/>
      <geometry>
        <sphere radius="0"/>
      </geometry>
    </collision>
    <!-- ############    END     ############ -->
  </link>
  <link name="left_f1_0">
    <origin rpy="0 0 0" xyz="0 0 0"/>
    <inertial>
      <mass value="0.05"/>
      <origin xyz="0 0 0"/>
      <inertia ixx="0.01" ixy="0" ixz="0" iyy="0.01" iyz="0" izz="0.01"/>
    </inertial>
    <!-- begin simple shape approximation of f0 -->
    <!-- <collision group="default">
        <origin xyz="0 0 0.003" rpy="0 0 0"/>
        <geometry>
          <cylinder radius="0.015" length="0.023" />
        </geometry>
      </collision> -->
    <!-- <collision group="other">
        <origin xyz="0.011 0 0.003" rpy="${M_pi/2} 0 0"/>
        <geometry>
          <cylinder radius="0.01" length="0.023" />
        </geometry>
      </collision> -->
    <!--   end simple shape approximation of f0 -->
    <!-- begin visual shape approximation of f0 -->
    <visual>
      <origin rpy="0 0 0" xyz="0 0 0.003"/>
      <geometry>
        <cylinder length="0.023" radius="0.015"/>
      </geometry>
      <material name="left_sandia_hand_skin_suntan">
        <color rgba="0.7 0.4 0.2 1.0"/>
      </material>
    </visual>
    <visual>
      <origin rpy="1.57079632679 0 0" xyz="0.011 0 0.003"/>
      <geometry>
        <cylinder length="0.023" radius="0.01"/>
      </geometry>
      <material name="left_sandia_hand_skin_suntan">
        <color rgba="0.7 0.4 0.2 1.0"/>
      </material>
    </visual>
    <!--   end visual shape approximation of f0 -->
    <!-- begin collision mesh of f0 ->
      <collision group="default">
        <origin xyz="0 0 0" rpy="0 0 0"/>
        <geometry>
          <mesh filename="package://sandia_hand_description/meshes/f0.stl"/>
        </geometry>
      </collision>
      <!-   end collision mesh of f0 -->
    <!-- begin visual mesh of f0 ->
      <visual>
        <origin xyz="0 0 0" rpy="0 0 0"/>
        <geometry>
          <mesh filename="package://sandia_hand_description/meshes/f0.stl"/>
        </geometry>
        <material name="${side}_sandia_hand_skin_suntan">
          <color rgba="0.7 0.4 0.2 1.0"/>
        </material>
      </visual>
      <!-   end visual mesh of f0 -->
  </link>
  <link name="left_f1_1">
    <origin rpy="0 0 0" xyz="0 0 0"/>
    <inertial>
      <mass value="0.05"/>
      <origin xyz="0 0 0"/>
      <inertia ixx="0.01" ixy="0" ixz="0" iyy="0.01" iyz="0" izz="0.01"/>
    </inertial>
    <!-- begin simple shape approximation of f1 -->
    <!-- <collision group="default">
        <origin xyz="0.024 0 0" rpy="0 ${M_pi/2} 0"/>
        <geometry>
          <cylinder radius="0.01" length="0.067" />
        </geometry>
      </collision> -->
    <!--   end simple shape approximation of f1 -->
    <!-- begin visual shape approximation of f1 -->
    <visual>
      <origin rpy="0 1.57079632679 0" xyz="0.024 0 0"/>
      <geometry>
        <cylinder length="0.067" radius="0.01"/>
      </geometry>
      <material name="left_sandia_hand_skin">
        <color rgba="0.835 0.655 0.345 1.0"/>
      </material>
    </visual>
    <!--   end visual shape approximation of f1 -->
    <!-- begin collision mesh of f1 ->
      <collision group="default">
        <origin xyz="0 0 0" rpy="0 0 0"/>
        <geometry>
          <mesh filename="package://sandia_hand_description/meshes/f1.stl"/>
        </geometry>
      </collision>
      <!-   end collision mesh of f1 -->
    <!-- begin visual mesh of f1 ->
      <visual>
        <origin xyz="0 0 0" rpy="0 0 0"/>
        <geometry>
          <mesh filename="package://sandia_hand_description/meshes/f1.stl"/>
        </geometry>
        <material name="${side}_sandia_hand_skin">
          <color rgba="0.835 0.655 0.345 1.0"/>
        </material>
      </visual>
      <!-   end visual mesh of f1 -->
  </link>
  <link name="left_f1_1_accel">
    <origin rpy="0 0 0" xyz="0 0 0"/>
    <inertial>
      <mass value="0.001"/>
      <origin xyz="0 0 0"/>
      <inertia ixx="0.01" ixy="0" ixz="0" iyy="0.01" iyz="0" izz="0.01"/>
    </inertial>
    <!-- ############ MIT ADDITION ############ -->
    <!--      <collision>-->
    <!--        <origin rpy="0 0 0" xyz="0 0 0.01"/>-->
    <!--        <geometry>-->
    <!--          <sphere radius="0"/>-->
    <!--        </geometry>-->
    <!--      </collision>  -->
    <!-- ############    END     ############ -->
  </link>
  <link name="left_f1_2">
    <origin rpy="0 0 0" xyz="0 0 0"/>
    <inertial>
      <mass value="0.05"/>
      <origin xyz="0 0 0"/>
      <inertia ixx="0.01" ixy="0" ixz="0" iyy="0.01" iyz="0" izz="0.01"/>
    </inertial>
    <!-- begin simple shape approximation of f2 -->
    <!-- <collision group="default">
        <origin xyz="0.024 0 0" rpy="0 ${M_pi/2} 0"/>
        <geometry>
          <cylinder radius="0.009" length="0.057" />
        </geometry>
      </collision> -->
    <!-- <collision group="other">
        <origin xyz="0.052 0 0" rpy="0 0 0"/>
        <geometry>
          <sphere radius="0.009" />
        </geometry>
      </collision> -->
    <!--   end simple shape approximation of f2 -->
    <!-- begin visual shape approximation of f2 -->
    <visual>
      <origin rpy="0 1.57079632679 0" xyz="0.024 0 0"/>
      <geometry>
        <cylinder length="0.057" radius="0.009"/>
      </geometry>
      <material name="left_sandia_hand_skin_suntan">
        <color rgba="0.8 0.6 0.3 1.0"/>
      </material>
    </visual>
    <visual>
      <origin rpy="0 0 0" xyz="0.052 0 0"/>
      <geometry>
        <sphere radius="0.009"/>
      </geometry>
      <material name="left_sandia_hand_skin_suntan">
        <color rgba="0.8 0.6 0.3 1.0"/>
      </material>
    </visual>
    <!-- begin collision mesh of f2    ->
      <collision group="default">
        <origin xyz="0 0 0" rpy="0 0 0"/>
        <geometry>
          <mesh filename="package://sandia_hand_description/meshes/f2.stl"/>
        </geometry>
      </collision>
      <!-   end collision mesh of f2 -->
    <!-- begin visual mesh of f2    ->
      <visual>
        <origin xyz="0 0 0" rpy="0 0 0"/>
        <geometry>
          <mesh filename="package://sandia_hand_description/meshes/f2.stl"/>
        </geometry>
        <material name="${side}_sandia_hand_skin_suntan">
          <color rgba="0.8 0.6 0.3 1.0"/>
        </material>
      </visual>
      <!-   end visual mesh of f2 -->
  </link>
  <link name="left_f1_2_accel">
    <origin rpy="0 0 0" xyz="0 0 0"/>
    <inertial>
      <mass value="0.001"/>
      <origin xyz="0 0 0"/>
      <inertia ixx="0.01" ixy="0" ixz="0" iyy="0.01" iyz="0" izz="0.01"/>
    </inertial>
    <!-- ############ MIT ADDITION ############ -->
    <collision>
      <origin rpy="0 0 0" xyz="0 0 0.001"/>
      <geometry>
        <sphere radius="0"/>
      </geometry>
    </collision>
    <!-- ############    END     ############ -->
  </link>
  <link name="left_f1_2_accel_dummy1">
    <origin rpy="0 0 0" xyz="0 0 0"/>
    <inertial>
      <mass value="0.001"/>
      <origin xyz="0 0 0"/>
      <inertia ixx="0.01" ixy="0" ixz="0" iyy="0.01" iyz="0" izz="0.01"/>
    </inertial>
    <collision>
      <origin rpy="0 0 0" xyz="-0.02 0.0 0.01"/>
      <geometry>
        <sphere radius="0"/>
      </geometry>
    </collision>
  </link>
  <joint name="left_f1_2_accel_dummy1" type="fixed">
    <parent link="left_f1_2"/>
    <child link="left_f1_2_accel_dummy1"/>
    <origin rpy="-1.57079632679 0 0" xyz="0.04 0 0"/>
  </joint>
  <joint name="left_f1_base" type="fixed">
    <parent link="left_palm"/>
    <child link="left_f1_base"/>
    <origin rpy="0 0 -0.3" xyz="0.115 -0.03122 0"/>
  </joint>
  <joint name="left_f1_j1" type="revolute">
    <axis xyz="0 0 1"/>
    <parent link="left_f1_0"/>
    <child link="left_f1_1"/>
    <limit effort="1" lower="-1.57079632679" upper="1.57079632679" velocity="1"/>
    <safety_controller k_position="1000.0" k_velocity="1000.0" soft_lower_limit="-11.57079" soft_upper_limit="11.57079"/>
    <dynamics damping="0.2"/>
    <origin rpy="1.57079632679 0 0" xyz="0.028 0 0"/>
  </joint>
  <joint name="left_f1_j2" type="revolute">
    <axis xyz="0 0 1"/>
    <parent link="left_f1_1"/>
    <child link="left_f1_2"/>
    <origin rpy="0 0 0" xyz="0.05 0 0"/>
    <safety_controller k_position="1000.0" k_velocity="1000.0" soft_lower_limit="-11.57079" soft_upper_limit="11.57079"/>
    <dynamics damping="0.2"/>
    <limit effort="1" lower="-1.57079632679" upper="1.57079632679" velocity="1"/>
  </joint>
  <joint name="left_f1_fixed_accel" type="fixed">
    <parent link="left_f1_base"/>
    <child link="left_f1_fixed_accel"/>
    <origin rpy="0 0 0" xyz="-0.05 0 0"/>
  </joint>
  <joint name="left_f1_1_accel" type="fixed">
    <parent link="left_f1_1"/>
    <child link="left_f1_1_accel"/>
    <origin rpy="-1.57079632679 0 0" xyz="0.03 0 0"/>
  </joint>
  <joint name="left_f1_2_accel" type="fixed">
    <parent link="left_f1_2"/>
    <child link="left_f1_2_accel"/>
    <origin rpy="-1.57079632679 0 0" xyz="0.04 0 0"/>
  </joint>
  <link name="left_f1_knuckle_dummy_contact">
    <origin rpy="0 0 0" xyz="0 0 0"/>
    <inertial>
      <mass value="0.001"/>
      <origin xyz="0 0 0"/>
      <inertia ixx="0.001" ixy="0" ixz="0" iyy="0.001" iyz="0" izz="0.001"/>
    </inertial>
    <collision>
      <origin rpy="0 0 0" xyz="0.058 0 0.034"/>
      <geometry>
        <sphere radius="0"/>
      </geometry>
    </collision>
  </link>
  <joint name="left_f1_knuckle_dummy_contact" type="fixed">
    <parent link="left_f1_base"/>
    <child link="left_f1_knuckle_dummy_contact"/>
    <origin rpy="0 0 0" xyz="-0.05 0 0"/>
  </joint>
  <transmission name="left_f1_j0" type="pr2_mechanism_model/SimpleTransmission">
    <joint name="left_f1_j0"/>
    <actuator name="left_f1_j0_motor"/>
    <mechanicalReduction>1</mechanicalReduction>
  </transmission>
  <transmission name="left_f1_j1" type="pr2_mechanism_model/SimpleTransmission">
    <joint name="left_f1_j1"/>
    <actuator name="left_f1_j1_motor"/>
    <mechanicalReduction>1</mechanicalReduction>
  </transmission>
  <transmission name="left_f1_j2" type="pr2_mechanism_model/SimpleTransmission">
    <joint name="left_f1_j2"/>
    <actuator name="left_f1_j2_motor"/>
    <mechanicalReduction>1</mechanicalReduction>
  </transmission>
  <link name="left_f2_base">
    <origin rpy="0 0 0" xyz="0 0 0"/>
    <inertial>
      <mass value="0.35"/>
      <origin xyz="0 0 0"/>
      <inertia ixx="0.01" ixy="0" ixz="0" iyy="0.01" iyz="0" izz="0.01"/>
    </inertial>
  </link>
  <link name="left_f2_fixed_accel">
    <origin rpy="0 0 0" xyz="0 0 0"/>
    <inertial>
      <mass value="0.001"/>
      <origin xyz="0 0 0"/>
      <inertia ixx="0.01" ixy="0" ixz="0" iyy="0.01" iyz="0" izz="0.01"/>
    </inertial>
    <!-- ############ MIT ADDITION ############ -->
    <collision>
      <origin rpy="0 0 0" xyz="0 0 0.05"/>
      <geometry>
        <sphere radius="0"/>
      </geometry>
    </collision>
    <!-- ############    END     ############ -->
  </link>
  <link name="left_f2_0">
    <origin rpy="0 0 0" xyz="0 0 0"/>
    <inertial>
      <mass value="0.05"/>
      <origin xyz="0 0 0"/>
      <inertia ixx="0.01" ixy="0" ixz="0" iyy="0.01" iyz="0" izz="0.01"/>
    </inertial>
    <!-- begin simple shape approximation of f0 -->
    <!-- <collision group="default">
        <origin xyz="0 0 0.003" rpy="0 0 0"/>
        <geometry>
          <cylinder radius="0.015" length="0.023" />
        </geometry>
      </collision> -->
    <!-- <collision group="other">
        <origin xyz="0.011 0 0.003" rpy="${M_pi/2} 0 0"/>
        <geometry>
          <cylinder radius="0.01" length="0.023" />
        </geometry>
      </collision> -->
    <!--   end simple shape approximation of f0 -->
    <!-- begin visual shape approximation of f0 -->
    <visual>
      <origin rpy="0 0 0" xyz="0 0 0.003"/>
      <geometry>
        <cylinder length="0.023" radius="0.015"/>
      </geometry>
      <material name="left_sandia_hand_skin_suntan">
        <color rgba="0.7 0.4 0.2 1.0"/>
      </material>
    </visual>
    <visual>
      <origin rpy="1.57079632679 0 0" xyz="0.011 0 0.003"/>
      <geometry>
        <cylinder length="0.023" radius="0.01"/>
      </geometry>
      <material name="left_sandia_hand_skin_suntan">
        <color rgba="0.7 0.4 0.2 1.0"/>
      </material>
    </visual>
    <!--   end visual shape approximation of f0 -->
    <!-- begin collision mesh of f0 ->
      <collision group="default">
        <origin xyz="0 0 0" rpy="0 0 0"/>
        <geometry>
          <mesh filename="package://sandia_hand_description/meshes/f0.stl"/>
        </geometry>
      </collision>
      <!-   end collision mesh of f0 -->
    <!-- begin visual mesh of f0 ->
      <visual>
        <origin xyz="0 0 0" rpy="0 0 0"/>
        <geometry>
          <mesh filename="package://sandia_hand_description/meshes/f0.stl"/>
        </geometry>
        <material name="${side}_sandia_hand_skin_suntan">
          <color rgba="0.7 0.4 0.2 1.0"/>
        </material>
      </visual>
      <!-   end visual mesh of f0 -->
  </link>
  <link name="left_f2_1">
    <origin rpy="0 0 0" xyz="0 0 0"/>
    <inertial>
      <mass value="0.05"/>
      <origin xyz="0 0 0"/>
      <inertia ixx="0.01" ixy="0" ixz="0" iyy="0.01" iyz="0" izz="0.01"/>
    </inertial>
    <!-- begin simple shape approximation of f1 -->
    <!-- <collision group="default">
        <origin xyz="0.024 0 0" rpy="0 ${M_pi/2} 0"/>
        <geometry>
          <cylinder radius="0.01" length="0.067" />
        </geometry>
      </collision> -->
    <!--   end simple shape approximation of f1 -->
    <!-- begin visual shape approximation of f1 -->
    <visual>
      <origin rpy="0 1.57079632679 0" xyz="0.024 0 0"/>
      <geometry>
        <cylinder length="0.067" radius="0.01"/>
      </geometry>
      <material name="left_sandia_hand_skin">
        <color rgba="0.835 0.655 0.345 1.0"/>
      </material>
    </visual>
    <!--   end visual shape approximation of f1 -->
    <!-- begin collision mesh of f1 ->
      <collision group="default">
        <origin xyz="0 0 0" rpy="0 0 0"/>
        <geometry>
          <mesh filename="package://sandia_hand_description/meshes/f1.stl"/>
        </geometry>
      </collision>
      <!-   end collision mesh of f1 -->
    <!-- begin visual mesh of f1 ->
      <visual>
        <origin xyz="0 0 0" rpy="0 0 0"/>
        <geometry>
          <mesh filename="package://sandia_hand_description/meshes/f1.stl"/>
        </geometry>
        <material name="${side}_sandia_hand_skin">
          <color rgba="0.835 0.655 0.345 1.0"/>
        </material>
      </visual>
      <!-   end visual mesh of f1 -->
  </link>
  <link name="left_f2_1_accel">
    <origin rpy="0 0 0" xyz="0 0 0"/>
    <inertial>
      <mass value="0.001"/>
      <origin xyz="0 0 0"/>
      <inertia ixx="0.01" ixy="0" ixz="0" iyy="0.01" iyz="0" izz="0.01"/>
    </inertial>
    <!-- ############ MIT ADDITION ############ -->
    <!--      <collision>-->
    <!--        <origin rpy="0 0 0" xyz="0 0 0.01"/>-->
    <!--        <geometry>-->
    <!--          <sphere radius="0"/>-->
    <!--        </geometry>-->
    <!--      </collision>  -->
    <!-- ############    END     ############ -->
  </link>
  <link name="left_f2_2">
    <origin rpy="0 0 0" xyz="0 0 0"/>
    <inertial>
      <mass value="0.05"/>
      <origin xyz="0 0 0"/>
      <inertia ixx="0.01" ixy="0" ixz="0" iyy="0.01" iyz="0" izz="0.01"/>
    </inertial>
    <!-- begin simple shape approximation of f2 -->
    <!-- <collision group="default">
        <origin xyz="0.024 0 0" rpy="0 ${M_pi/2} 0"/>
        <geometry>
          <cylinder radius="0.009" length="0.057" />
        </geometry>
      </collision> -->
    <!-- <collision group="other">
        <origin xyz="0.052 0 0" rpy="0 0 0"/>
        <geometry>
          <sphere radius="0.009" />
        </geometry>
      </collision> -->
    <!--   end simple shape approximation of f2 -->
    <!-- begin visual shape approximation of f2 -->
    <visual>
      <origin rpy="0 1.57079632679 0" xyz="0.024 0 0"/>
      <geometry>
        <cylinder length="0.057" radius="0.009"/>
      </geometry>
      <material name="left_sandia_hand_skin_suntan">
        <color rgba="0.8 0.6 0.3 1.0"/>
      </material>
    </visual>
    <visual>
      <origin rpy="0 0 0" xyz="0.052 0 0"/>
      <geometry>
        <sphere radius="0.009"/>
      </geometry>
      <material name="left_sandia_hand_skin_suntan">
        <color rgba="0.8 0.6 0.3 1.0"/>
      </material>
    </visual>
    <!-- begin collision mesh of f2    ->
      <collision group="default">
        <origin xyz="0 0 0" rpy="0 0 0"/>
        <geometry>
          <mesh filename="package://sandia_hand_description/meshes/f2.stl"/>
        </geometry>
      </collision>
      <!-   end collision mesh of f2 -->
    <!-- begin visual mesh of f2    ->
      <visual>
        <origin xyz="0 0 0" rpy="0 0 0"/>
        <geometry>
          <mesh filename="package://sandia_hand_description/meshes/f2.stl"/>
        </geometry>
        <material name="${side}_sandia_hand_skin_suntan">
          <color rgba="0.8 0.6 0.3 1.0"/>
        </material>
      </visual>
      <!-   end visual mesh of f2 -->
  </link>
  <link name="left_f2_2_accel">
    <origin rpy="0 0 0" xyz="0 0 0"/>
    <inertial>
      <mass value="0.001"/>
      <origin xyz="0 0 0"/>
      <inertia ixx="0.01" ixy="0" ixz="0" iyy="0.01" iyz="0" izz="0.01"/>
    </inertial>
    <!-- ############ MIT ADDITION ############ -->
    <collision>
      <origin rpy="0 0 0" xyz="0 0 0.001"/>
      <geometry>
        <sphere radius="0"/>
      </geometry>
    </collision>
    <!-- ############    END     ############ -->
  </link>
  <link name="left_f2_2_accel_dummy1">
    <origin rpy="0 0 0" xyz="0 0 0"/>
    <inertial>
      <mass value="0.001"/>
      <origin xyz="0 0 0"/>
      <inertia ixx="0.01" ixy="0" ixz="0" iyy="0.01" iyz="0" izz="0.01"/>
    </inertial>
    <collision>
      <origin rpy="0 0 0" xyz="-0.02 0.0 0.01"/>
      <geometry>
        <sphere radius="0"/>
      </geometry>
    </collision>
  </link>
  <joint name="left_f2_2_accel_dummy1" type="fixed">
    <parent link="left_f2_2"/>
    <child link="left_f2_2_accel_dummy1"/>
    <origin rpy="-1.57079632679 0 0" xyz="0.04 0 0"/>
  </joint>
  <joint name="left_f2_base" type="fixed">
    <parent link="left_palm"/>
    <child link="left_f2_base"/>
    <origin rpy="0 0 -0.3" xyz="0.09 -0.06245 0"/>
  </joint>
  <joint name="left_f2_j1" type="revolute">
    <axis xyz="0 0 1"/>
    <parent link="left_f2_0"/>
    <child link="left_f2_1"/>
    <limit effort="1" lower="-1.57079632679" upper="1.57079632679" velocity="1"/>
    <safety_controller k_position="1000.0" k_velocity="1000.0" soft_lower_limit="-11.57079" soft_upper_limit="11.57079"/>
    <dynamics damping="0.2"/>
    <origin rpy="1.57079632679 0 0" xyz="0.028 0 0"/>
  </joint>
  <joint name="left_f2_j2" type="revolute">
    <axis xyz="0 0 1"/>
    <parent link="left_f2_1"/>
    <child link="left_f2_2"/>
    <origin rpy="0 0 0" xyz="0.05 0 0"/>
    <safety_controller k_position="1000.0" k_velocity="1000.0" soft_lower_limit="-11.57079" soft_upper_limit="11.57079"/>
    <dynamics damping="0.2"/>
    <limit effort="1" lower="-1.57079632679" upper="1.57079632679" velocity="1"/>
  </joint>
  <joint name="left_f2_fixed_accel" type="fixed">
    <parent link="left_f2_base"/>
    <child link="left_f2_fixed_accel"/>
    <origin rpy="0 0 0" xyz="-0.05 0 0"/>
  </joint>
  <joint name="left_f2_1_accel" type="fixed">
    <parent link="left_f2_1"/>
    <child link="left_f2_1_accel"/>
    <origin rpy="-1.57079632679 0 0" xyz="0.03 0 0"/>
  </joint>
  <joint name="left_f2_2_accel" type="fixed">
    <parent link="left_f2_2"/>
    <child link="left_f2_2_accel"/>
    <origin rpy="-1.57079632679 0 0" xyz="0.04 0 0"/>
  </joint>
  <link name="left_f2_knuckle_dummy_contact">
    <origin rpy="0 0 0" xyz="0 0 0"/>
    <inertial>
      <mass value="0.001"/>
      <origin xyz="0 0 0"/>
      <inertia ixx="0.001" ixy="0" ixz="0" iyy="0.001" iyz="0" izz="0.001"/>
    </inertial>
    <collision>
      <origin rpy="0 0 0" xyz="0.058 0 0.034"/>
      <geometry>
        <sphere radius="0"/>
      </geometry>
    </collision>
  </link>
  <joint name="left_f2_knuckle_dummy_contact" type="fixed">
    <parent link="left_f2_base"/>
    <child link="left_f2_knuckle_dummy_contact"/>
    <origin rpy="0 0 0" xyz="-0.05 0 0"/>
  </joint>
  <transmission name="left_f2_j0" type="pr2_mechanism_model/SimpleTransmission">
    <joint name="left_f2_j0"/>
    <actuator name="left_f2_j0_motor"/>
    <mechanicalReduction>1</mechanicalReduction>
  </transmission>
  <transmission name="left_f2_j1" type="pr2_mechanism_model/SimpleTransmission">
    <joint name="left_f2_j1"/>
    <actuator name="left_f2_j1_motor"/>
    <mechanicalReduction>1</mechanicalReduction>
  </transmission>
  <transmission name="left_f2_j2" type="pr2_mechanism_model/SimpleTransmission">
    <joint name="left_f2_j2"/>
    <actuator name="left_f2_j2_motor"/>
    <mechanicalReduction>1</mechanicalReduction>
  </transmission>
  <link name="left_f3_base">
    <origin rpy="0 0 0" xyz="0 0 0"/>
    <inertial>
      <mass value="0.35"/>
      <origin xyz="0 0 0"/>
      <inertia ixx="0.01" ixy="0" ixz="0" iyy="0.01" iyz="0" izz="0.01"/>
    </inertial>
  </link>
  <link name="left_f3_fixed_accel">
    <origin rpy="0 0 0" xyz="0 0 0"/>
    <inertial>
      <mass value="0.001"/>
      <origin xyz="0 0 0"/>
      <inertia ixx="0.01" ixy="0" ixz="0" iyy="0.01" iyz="0" izz="0.01"/>
    </inertial>
  </link>
  <link name="left_f3_0">
    <origin rpy="0 0 0" xyz="0 0 0"/>
    <inertial>
      <mass value="0.05"/>
      <origin xyz="0 0 0"/>
      <inertia ixx="0.01" ixy="0" ixz="0" iyy="0.01" iyz="0" izz="0.01"/>
    </inertial>
    <!-- begin simple shape approximation of f0 -->
    <!-- <collision group="default">
        <origin xyz="0 0 0.003" rpy="0 0 0"/>
        <geometry>
          <cylinder radius="0.015" length="0.023" />
        </geometry>
      </collision> -->
    <!-- <collision group="other">
        <origin xyz="0.011 0 0.003" rpy="${M_pi/2} 0 0"/>
        <geometry>
          <cylinder radius="0.01" length="0.023" />
        </geometry>
      </collision> -->
    <!--   end simple shape approximation of f0 -->
    <!-- begin visual shape approximation of f0 -->
    <visual>
      <origin rpy="0 0 0" xyz="0 0 0.003"/>
      <geometry>
        <cylinder length="0.023" radius="0.015"/>
      </geometry>
      <material name="left_sandia_hand_skin_suntan">
        <color rgba="0.7 0.4 0.2 1.0"/>
      </material>
    </visual>
    <visual>
      <origin rpy="1.57079632679 0 0" xyz="0.011 0 0.003"/>
      <geometry>
        <cylinder length="0.023" radius="0.01"/>
      </geometry>
      <material name="left_sandia_hand_skin_suntan">
        <color rgba="0.7 0.4 0.2 1.0"/>
      </material>
    </visual>
    <!--   end visual shape approximation of f0 -->
    <!-- begin collision mesh of f0 ->
      <collision group="default">
        <origin xyz="0 0 0" rpy="0 0 0"/>
        <geometry>
          <mesh filename="package://sandia_hand_description/meshes/f0.stl"/>
        </geometry>
      </collision>
      <!-   end collision mesh of f0 -->
    <!-- begin visual mesh of f0 ->
      <visual>
        <origin xyz="0 0 0" rpy="0 0 0"/>
        <geometry>
          <mesh filename="package://sandia_hand_description/meshes/f0.stl"/>
        </geometry>
        <material name="${side}_sandia_hand_skin_suntan">
          <color rgba="0.7 0.4 0.2 1.0"/>
        </material>
      </visual>
      <!-   end visual mesh of f0 -->
  </link>
  <link name="left_f3_1">
    <origin rpy="0 0 0" xyz="0 0 0"/>
    <inertial>
      <mass value="0.05"/>
      <origin xyz="0 0 0"/>
      <inertia ixx="0.01" ixy="0" ixz="0" iyy="0.01" iyz="0" izz="0.01"/>
    </inertial>
    <!-- begin simple shape approximation of f1 -->
    <!-- <collision group="default">
        <origin xyz="0.024 0 0" rpy="0 ${M_pi/2} 0"/>
        <geometry>
          <cylinder radius="0.01" length="0.067" />
        </geometry>
      </collision> -->
    <!--   end simple shape approximation of f1 -->
    <!-- begin visual shape approximation of f1 -->
    <visual>
      <origin rpy="0 1.57079632679 0" xyz="0.024 0 0"/>
      <geometry>
        <cylinder length="0.067" radius="0.01"/>
      </geometry>
      <material name="left_sandia_hand_skin">
        <color rgba="0.835 0.655 0.345 1.0"/>
      </material>
    </visual>
    <!--   end visual shape approximation of f1 -->
    <!-- begin collision mesh of f1 ->
      <collision group="default">
        <origin xyz="0 0 0" rpy="0 0 0"/>
        <geometry>
          <mesh filename="package://sandia_hand_description/meshes/f1.stl"/>
        </geometry>
      </collision>
      <!-   end collision mesh of f1 -->
    <!-- begin visual mesh of f1 ->
      <visual>
        <origin xyz="0 0 0" rpy="0 0 0"/>
        <geometry>
          <mesh filename="package://sandia_hand_description/meshes/f1.stl"/>
        </geometry>
        <material name="${side}_sandia_hand_skin">
          <color rgba="0.835 0.655 0.345 1.0"/>
        </material>
      </visual>
      <!-   end visual mesh of f1 -->
  </link>
  <link name="left_f3_1_accel">
    <origin rpy="0 0 0" xyz="0 0 0"/>
    <inertial>
      <mass value="0.001"/>
      <origin xyz="0 0 0"/>
      <inertia ixx="0.01" ixy="0" ixz="0" iyy="0.01" iyz="0" izz="0.01"/>
    </inertial>
  </link>
  <link name="left_f3_2">
    <origin rpy="0 0 0" xyz="0 0 0"/>
    <inertial>
      <mass value="0.05"/>
      <origin xyz="0 0 0"/>
      <inertia ixx="0.01" ixy="0" ixz="0" iyy="0.01" iyz="0" izz="0.01"/>
    </inertial>
    <!-- begin simple shape approximation of f2 -->
    <!-- <collision group="default">
        <origin xyz="0.024 0 0" rpy="0 ${M_pi/2} 0"/>
        <geometry>
          <cylinder radius="0.009" length="0.057" />
        </geometry>
      </collision> -->
    <!-- <collision group="other">
        <origin xyz="0.052 0 0" rpy="0 0 0"/>
        <geometry>
          <sphere radius="0.009" />
        </geometry>
      </collision> -->
    <!--   end simple shape approximation of f2 -->
    <!-- begin visual shape approximation of f2 -->
    <visual>
      <origin rpy="0 1.57079632679 0" xyz="0.024 0 0"/>
      <geometry>
        <cylinder length="0.057" radius="0.009"/>
      </geometry>
      <material name="left_sandia_hand_skin_suntan">
        <color rgba="0.8 0.6 0.3 1.0"/>
      </material>
    </visual>
    <visual>
      <origin rpy="0 0 0" xyz="0.052 0 0"/>
      <geometry>
        <sphere radius="0.009"/>
      </geometry>
      <material name="left_sandia_hand_skin_suntan">
        <color rgba="0.8 0.6 0.3 1.0"/>
      </material>
    </visual>
    <!-- begin collision mesh of f2    ->
      <collision group="default">
        <origin xyz="0 0 0" rpy="0 0 0"/>
        <geometry>
          <mesh filename="package://sandia_hand_description/meshes/f2.stl"/>
        </geometry>
      </collision>
      <!-   end collision mesh of f2 -->
    <!-- begin visual mesh of f2    ->
      <visual>
        <origin xyz="0 0 0" rpy="0 0 0"/>
        <geometry>
          <mesh filename="package://sandia_hand_description/meshes/f2.stl"/>
        </geometry>
        <material name="${side}_sandia_hand_skin_suntan">
          <color rgba="0.8 0.6 0.3 1.0"/>
        </material>
      </visual>
      <!-   end visual mesh of f2 -->
  </link>
  <link name="left_f3_2_accel">
    <origin rpy="0 0 0" xyz="0 0 0"/>
    <inertial>
      <mass value="0.001"/>
      <origin xyz="0 0 0"/>
      <inertia ixx="0.01" ixy="0" ixz="0" iyy="0.01" iyz="0" izz="0.01"/>
    </inertial>
    <!-- ############ MIT ADDITION ############ -->
    <collision>
      <origin rpy="0 0 0" xyz="0 0 0.001"/>
      <geometry>
        <sphere radius="0"/>
      </geometry>
    </collision>
    <!-- ############    END     ############ -->
  </link>
  <link name="left_f3_2_accel_dummy1">
    <origin rpy="0 0 0" xyz="0 0 0"/>
    <inertial>
      <mass value="0.001"/>
      <origin xyz="0 0 0"/>
      <inertia ixx="0.01" ixy="0" ixz="0" iyy="0.01" iyz="0" izz="0.01"/>
    </inertial>
    <collision>
      <origin rpy="0 0 0" xyz="-0.02 0.0 0.01"/>
      <geometry>
        <sphere radius="0"/>
      </geometry>
    </collision>
  </link>
  <joint name="left_f3_2_accel_dummy1" type="fixed">
    <parent link="left_f3_2"/>
    <child link="left_f3_2_accel_dummy1"/>
    <origin rpy="-1.57079632679 0 0" xyz="0.04 0 0"/>
  </joint>
  <joint name="left_f3_base" type="fixed">
    <parent link="left_palm"/>
    <child link="left_f3_base"/>
    <origin rpy="0 -1.57079632679 2.3562" xyz="0.03995 0.04383 0.014"/>
  </joint>
  <joint name="left_f3_j0" type="revolute">
    <axis xyz="0 0 -1"/>
    <parent link="left_f3_base"/>
    <child link="left_f3_0"/>
    <limit effort="1" lower="-1.57079632679" upper="1.57079632679" velocity="1"/>
    <safety_controller k_position="1000.0" k_velocity="1000.0" soft_lower_limit="-11.57079" soft_upper_limit="11.57079"/>
    <dynamics damping="0.2"/>
    <origin rpy="0 0 0" xyz="0 0 0"/>
  </joint>
  <joint name="left_f3_j1" type="revolute">
    <axis xyz="0 0 1"/>
    <parent link="left_f3_0"/>
    <child link="left_f3_1"/>
    <limit effort="1" lower="-1.57079632679" upper="1.57079632679" velocity="1"/>
    <safety_controller k_position="1000.0" k_velocity="1000.0" soft_lower_limit="-11.57079" soft_upper_limit="11.57079"/>
    <dynamics damping="0.2"/>
    <origin rpy="1.57079632679 0 0" xyz="0.028 0 0"/>
  </joint>
  <joint name="left_f3_j2" type="revolute">
    <axis xyz="0 0 1"/>
    <parent link="left_f3_1"/>
    <child link="left_f3_2"/>
    <origin rpy="0 0 0" xyz="0.05 0 0"/>
    <safety_controller k_position="1000.0" k_velocity="1000.0" soft_lower_limit="-11.57079" soft_upper_limit="11.57079"/>
    <dynamics damping="0.2"/>
    <limit effort="1" lower="-1.57079632679" upper="1.57079632679" velocity="1"/>
  </joint>
  <joint name="left_f3_fixed_accel" type="fixed">
    <parent link="left_f3_base"/>
    <child link="left_f3_fixed_accel"/>
    <origin rpy="0 0 0" xyz="-0.05 0 0"/>
  </joint>
  <joint name="left_f3_1_accel" type="fixed">
    <parent link="left_f3_1"/>
    <child link="left_f3_1_accel"/>
    <origin rpy="-1.57079632679 0 0" xyz="0.03 0 0"/>
  </joint>
  <joint name="left_f3_2_accel" type="fixed">
    <parent link="left_f3_2"/>
    <child link="left_f3_2_accel"/>
    <origin rpy="-1.57079632679 0 0" xyz="0.04 0 0"/>
  </joint>
  <transmission name="left_f3_j0" type="pr2_mechanism_model/SimpleTransmission">
    <joint name="left_f3_j0"/>
    <actuator name="left_f3_j0_motor"/>
    <mechanicalReduction>1</mechanicalReduction>
  </transmission>
  <transmission name="left_f3_j1" type="pr2_mechanism_model/SimpleTransmission">
    <joint name="left_f3_j1"/>
    <actuator name="left_f3_j1_motor"/>
    <mechanicalReduction>1</mechanicalReduction>
  </transmission>
  <transmission name="left_f3_j2" type="pr2_mechanism_model/SimpleTransmission">
    <joint name="left_f3_j2"/>
    <actuator name="left_f3_j2_motor"/>
    <mechanicalReduction>1</mechanicalReduction>
  </transmission>
  <joint name="left_f0_j0" type="revolute">
    <axis xyz="0 0 -1"/>
    <parent link="left_f0_base"/>
    <child link="left_f0_0"/>
    <!--    <limit effort="1" lower="-1.57079" upper="1.57079" velocity="1"/>-->
    <limit effort="1" lower="-1.57079632679" upper="0" velocity="1"/>
    <safety_controller k_position="1000.0" k_velocity="1000.0" soft_lower_limit="-11.57079" soft_upper_limit="11.57079"/>
    <dynamics damping="0.2"/>
    <origin rpy="0 0 0" xyz="0 0 0"/>
  </joint>
  <joint name="left_f1_j0" type="revolute">
    <axis xyz="0 0 -1"/>
    <parent link="left_f1_base"/>
    <child link="left_f1_0"/>
    <!--    <limit effort="1" lower="-1.57079" upper="1.57079" velocity="1"/>-->
    <limit effort="1" lower="-0.09" upper="0.09" velocity="1"/>
    <safety_controller k_position="1000.0" k_velocity="1000.0" soft_lower_limit="-11.57079" soft_upper_limit="11.57079"/>
    <dynamics damping="0.2"/>
    <origin rpy="0 0 0" xyz="0 0 0"/>
  </joint>
  <joint name="left_f2_j0" type="revolute">
    <axis xyz="0 0 -1"/>
    <parent link="left_f2_base"/>
    <child link="left_f2_0"/>
    <!--    <limit effort="1" lower="-1.57079" upper="1.57079" velocity="1"/>-->
    <limit effort="1" lower="0" upper="1.57079632679" velocity="1"/>
    <safety_controller k_position="1000.0" k_velocity="1000.0" soft_lower_limit="-11.57079" soft_upper_limit="11.57079"/>
    <dynamics damping="0.2"/>
    <origin rpy="0 0 0" xyz="0 0 0"/>
  </joint>
  <!--<joint name='rwrist' type='fixed'>
  you can specify xyz offset to locate the manipulator
  <origin rpy="0 3.1416  1.57079" xyz="0 -0.1 -0.03"/>
  <parent link='r_hand' />
  <child link='right_palm'/>
  </joint>

  <joint name='lwrist' type='fixed'>
   you can specify xyz offset to locate the manipulator
  <origin rpy="0 3.1416  -1.57079" xyz="0 0.1 -0.03"/>
  <parent link='l_hand' />
  <child link='left_palm'/>
  </joint> -->
  <transmission name="back_lbz_trans" type="pr2_mechanism_model/SimpleTransmission">
    <joint name="back_lbz"/>
    <actuator name="back_lbz_motor"/>
    <mechanicalReduction>1</mechanicalReduction>
  </transmission>
  <transmission name="back_mby_trans" type="pr2_mechanism_model/SimpleTransmission">
    <actuator name="back_mby_motor"/>
    <joint name="back_mby"/>
    <mechanicalReduction>1</mechanicalReduction>
  </transmission>
  <transmission name="back_ubx_trans" type="pr2_mechanism_model/SimpleTransmission">
    <actuator name="back_ubx_motor"/>
    <joint name="back_ubx"/>
    <mechanicalReduction>1</mechanicalReduction>
  </transmission>
  <transmission name="l_arm_elx_trans" type="pr2_mechanism_model/SimpleTransmission">
    <actuator name="l_arm_elx_motor"/>
    <joint name="l_arm_elx"/>
    <mechanicalReduction>1</mechanicalReduction>
  </transmission>
  <transmission name="l_arm_ely_trans" type="pr2_mechanism_model/SimpleTransmission">
    <actuator name="l_arm_ely_motor"/>
    <joint name="l_arm_ely"/>
    <mechanicalReduction>1</mechanicalReduction>
  </transmission>
  <transmission name="l_arm_mwx_trans" type="pr2_mechanism_model/SimpleTransmission">
    <actuator name="l_arm_mwx_motor"/>
    <joint name="l_arm_mwx"/>
    <mechanicalReduction>1</mechanicalReduction>
  </transmission>
  <transmission name="l_arm_shx_trans" type="pr2_mechanism_model/SimpleTransmission">
    <actuator name="l_arm_shx_motor"/>
    <joint name="l_arm_shx"/>
    <mechanicalReduction>1</mechanicalReduction>
  </transmission>
  <transmission name="l_arm_usy_trans" type="pr2_mechanism_model/SimpleTransmission">
    <actuator name="l_arm_usy_motor"/>
    <joint name="l_arm_usy"/>
    <mechanicalReduction>1</mechanicalReduction>
  </transmission>
  <transmission name="l_arm_uwy_trans" type="pr2_mechanism_model/SimpleTransmission">
    <actuator name="l_arm_uwy_motor"/>
    <joint name="l_arm_uwy"/>
    <mechanicalReduction>1</mechanicalReduction>
  </transmission>
  <transmission name="l_leg_kny_trans" type="pr2_mechanism_model/SimpleTransmission">
    <actuator name="l_leg_kny_motor"/>
    <joint name="l_leg_kny"/>
    <mechanicalReduction>1</mechanicalReduction>
  </transmission>
  <transmission name="l_leg_lax_trans" type="pr2_mechanism_model/SimpleTransmission">
    <actuator name="l_leg_lax_motor"/>
    <joint name="l_leg_lax"/>
    <mechanicalReduction>1</mechanicalReduction>
  </transmission>
  <transmission name="l_leg_lhy_trans" type="pr2_mechanism_model/SimpleTransmission">
    <actuator name="l_leg_lhy_motor"/>
    <joint name="l_leg_lhy"/>
    <mechanicalReduction>1</mechanicalReduction>
  </transmission>
  <transmission name="l_leg_mhx_trans" type="pr2_mechanism_model/SimpleTransmission">
    <actuator name="l_leg_mhx_motor"/>
    <joint name="l_leg_mhx"/>
    <mechanicalReduction>1</mechanicalReduction>
  </transmission>
  <transmission name="l_leg_uay_trans" type="pr2_mechanism_model/SimpleTransmission">
    <actuator name="l_leg_uay_motor"/>
    <joint name="l_leg_uay"/>
    <mechanicalReduction>1</mechanicalReduction>
  </transmission>
  <transmission name="l_leg_uhz_trans" type="pr2_mechanism_model/SimpleTransmission">
    <actuator name="l_leg_uhz_motor"/>
    <joint name="l_leg_uhz"/>
    <mechanicalReduction>1</mechanicalReduction>
  </transmission>
  <transmission name="neck_ay_trans" type="pr2_mechanism_model/SimpleTransmission">
    <actuator name="neck_ay_motor"/>
    <joint name="neck_ay"/>
    <mechanicalReduction>1</mechanicalReduction>
  </transmission>
  <transmission name="r_arm_elx_trans" type="pr2_mechanism_model/SimpleTransmission">
    <actuator name="r_arm_elx_motor"/>
    <joint name="r_arm_elx"/>
    <mechanicalReduction>1</mechanicalReduction>
  </transmission>
  <transmission name="r_arm_ely_trans" type="pr2_mechanism_model/SimpleTransmission">
    <actuator name="r_arm_ely_motor"/>
    <joint name="r_arm_ely"/>
    <mechanicalReduction>1</mechanicalReduction>
  </transmission>
  <transmission name="r_arm_mwx_trans" type="pr2_mechanism_model/SimpleTransmission">
    <actuator name="r_arm_mwx_motor"/>
    <joint name="r_arm_mwx"/>
    <mechanicalReduction>1</mechanicalReduction>
  </transmission>
  <transmission name="r_arm_shx_trans" type="pr2_mechanism_model/SimpleTransmission">
    <actuator name="r_arm_shx_motor"/>
    <joint name="r_arm_shx"/>
    <mechanicalReduction>1</mechanicalReduction>
  </transmission>
  <transmission name="r_arm_usy_trans" type="pr2_mechanism_model/SimpleTransmission">
    <actuator name="r_arm_usy_motor"/>
    <joint name="r_arm_usy"/>
    <mechanicalReduction>1</mechanicalReduction>
  </transmission>
  <transmission name="r_arm_uwy_trans" type="pr2_mechanism_model/SimpleTransmission">
    <actuator name="r_arm_uwy_motor"/>
    <joint name="r_arm_uwy"/>
    <mechanicalReduction>1</mechanicalReduction>
  </transmission>
  <transmission name="r_leg_kny_trans" type="pr2_mechanism_model/SimpleTransmission">
    <actuator name="r_leg_kny_motor"/>
    <joint name="r_leg_kny"/>
    <mechanicalReduction>1</mechanicalReduction>
  </transmission>
  <transmission name="r_leg_lax_trans" type="pr2_mechanism_model/SimpleTransmission">
    <actuator name="r_leg_lax_motor"/>
    <joint name="r_leg_lax"/>
    <mechanicalReduction>1</mechanicalReduction>
  </transmission>
  <transmission name="r_leg_lhy_trans" type="pr2_mechanism_model/SimpleTransmission">
    <actuator name="r_leg_lhy_motor"/>
    <joint name="r_leg_lhy"/>
    <mechanicalReduction>1</mechanicalReduction>
  </transmission>
  <transmission name="r_leg_mhx_trans" type="pr2_mechanism_model/SimpleTransmission">
    <actuator name="r_leg_mhx_motor"/>
    <joint name="r_leg_mhx"/>
    <mechanicalReduction>1</mechanicalReduction>
  </transmission>
  <transmission name="r_leg_uay_trans" type="pr2_mechanism_model/SimpleTransmission">
    <actuator name="r_leg_uay_motor"/>
    <joint name="r_leg_uay"/>
    <mechanicalReduction>1</mechanicalReduction>
  </transmission>
  <transmission name="r_leg_uhz_trans" type="pr2_mechanism_model/SimpleTransmission">
    <actuator name="r_leg_uhz_motor"/>
    <joint name="r_leg_uhz"/>
    <mechanicalReduction>1</mechanicalReduction>
  </transmission>
  <link name="head">
    <inertial>
      <origin rpy="0 0 0" xyz="-0.075493 3.3383E-05 0.02774"/>
      <mass value="1.4199"/>
      <inertia ixx="0.0039688" ixy="-1.5797E-06" ixz="-0.00089293" iyy="0.0041178" iyz="-6.8415E-07" izz="0.0035243"/>
    </inertial>
    <visual>
      <origin rpy="0 0 1.570795" xyz="-0.0446 0 0.0880"/>
      <geometry>
        <mesh filename="package://mit_drcsim_scripts/models/multisense_sl/meshes/base_link.wrl"/>
      </geometry>
      <material name="">
        <color rgba="0.9098 0.44314 0.031373 1"/>
      </material>
    </visual>
  </link>
  <gazebo reference="r_foot">
    <!-- contact sensor -->
    <sensor name="r_foot_contact_sensor" type="contact">
      <update_rate>1000.0</update_rate>
      <always_on>1</always_on>
      <contact>
        <collision>r_foot_collision</collision>
        <topic>/r_foot_contact</topic>
      </contact>
    </sensor>
  </gazebo>
  <gazebo reference="l_foot">
    <!-- contact sensor -->
    <sensor name="l_foot_contact_sensor" type="contact">
      <update_rate>1000.0</update_rate>
      <always_on>1</always_on>
      <contact>
        <collision>l_foot_collision</collision>
        <topic>/l_foot_contact</topic>
      </contact>
    </sensor>
  </gazebo>
  <gazebo>
    <plugin filename="libMultiSenseSLPlugin.so" name="multisense_plugin"/>
  </gazebo>
</robot>

