<?xml version="1.0" ?>
<!-- =================================================================================== -->
<!-- |    This document was autogenerated by xacro from atlas_point_hands.urdf.xacro   | -->
<!-- |    EDITING THIS FILE BY HAND IS NOT RECOMMENDED                                 | -->
<!-- =================================================================================== -->
<robot name="atlas" xmlns:xacro="http://www.ros.org/wiki/xacro">
  <link name="l_clav">
    <inertial>
      <mass value="2.369"/>
      <origin rpy="0 -0 0" xyz="0.014 0.058 0.029"/>
      <inertia ixx="0.004" ixy="0.001" ixz="0" iyy="0.006" iyz="0" izz="0.007"/>
    </inertial>
    <visual>
      <origin rpy="1.04719755 0 0" xyz="0 0 0"/>
      <geometry>
        <mesh filename="package://mit_drcsim_scripts/models/mit_robot/meshes/l_clav.wrl" scale="1 1 1"/>
      </geometry>
    </visual>
  </link>
  <link name="l_farm">
    <inertial>
      <mass value="0.981"/>
      <origin rpy="0 -0 0" xyz="0 0.041 0"/>
      <inertia ixx="0.003" ixy="0" ixz="0" iyy="0.001" iyz="0" izz="0.003"/>
    </inertial>
    <visual>
      <origin rpy="0 -0 0" xyz="0 -0.06 0"/>
      <geometry>
        <mesh filename="package://mit_drcsim_scripts/models/mit_robot/meshes/l_farm.wrl" scale="1 1 1"/>
      </geometry>
    </visual>
  </link>
  <link name="l_foot">
    <inertial>
      <mass value="0.867"/>
      <origin rpy="0 -0 0" xyz="0.027 0 -0.067"/>
      <inertia ixx="0.002" ixy="0" ixz="0" iyy="0.00350421" iyz="0" izz="0.00400651"/>
    </inertial>
    <visual>
      <origin rpy="0 -0 0" xyz="0 0 0"/>
      <geometry>
        <mesh filename="package://mit_drcsim_scripts/models/mit_robot/meshes/l_foot.wrl" scale="1 1 1"/>
      </geometry>
    </visual>
    <collision group="heel">
      <origin rpy="0 0 0" xyz="-0.082 0.0624435 -0.081119"/>
      <geometry>
        <sphere radius="0"/>
      </geometry>
    </collision>
    <visual>
      <origin rpy="0 0 0" xyz="-0.082 0.0624435 -0.081119"/>
      <geometry>
        <sphere radius="0.01"/>
      </geometry>
    </visual>
    <collision group="heel">
      <origin rpy="0 0 0" xyz="-0.082 -0.0624435 -0.081119"/>
      <geometry>
        <sphere radius="0"/>
      </geometry>
    </collision>
    <visual>
      <origin rpy="0 0 0" xyz="-0.082 -0.0624435 -0.081119"/>
      <geometry>
        <sphere radius="0.01"/>
      </geometry>
    </visual>
    <collision group="toe">
      <origin rpy="0 0 0" xyz="0.178 0.0624435 -0.081119"/>
      <geometry>
        <sphere radius="0"/>
      </geometry>
    </collision>
    <visual>
      <origin rpy="0 0 0" xyz="0.178 0.0624435 -0.081119"/>
      <geometry>
        <sphere radius="0.01"/>
      </geometry>
    </visual>
    <collision group="toe">
      <origin rpy="0 0 0" xyz="0.178 -0.0624435 -0.081119"/>
      <geometry>
        <sphere radius="0"/>
      </geometry>
    </collision>
    <visual>
      <origin rpy="0 0 0" xyz="0.178 -0.0624435 -0.081119"/>
      <geometry>
        <sphere radius="0.01"/>
      </geometry>
    </visual>
  </link>
  <link name="l_hand">
    <inertial>
      <mass value="2.263"/>
      <origin rpy="0 -0 0" xyz="0 0.093 0"/>
      <inertia ixx="0.01" ixy="0" ixz="0" iyy="0.002" iyz="0" izz="0.01"/>
    </inertial>
    <visual>
      <origin rpy="0 -0 0" xyz="0 0 0"/>
      <geometry>
        <mesh filename="package://mit_drcsim_scripts/models/mit_robot/meshes/l_hand.wrl" scale="1 1 1"/>
      </geometry>
    </visual>
    <collision group="default">
      <origin rpy="0 0 0" xyz="0.0 0.115 0.0"/>
      <geometry>
        <sphere radius="0"/>
      </geometry>
    </collision>
    <visual>
      <origin rpy="0 0 0" xyz="0.0 0.115 0.0"/>
      <geometry>
        <sphere radius="0.01"/>
      </geometry>
    </visual>
  </link>
  <link name="l_larm">
    <inertial>
      <mass value="2.148"/>
      <origin rpy="0 -0 0" xyz="-0.003 0.099 -0.014"/>
      <inertia ixx="0.005" ixy="0" ixz="0" iyy="0.003" iyz="0" izz="0.006"/>
    </inertial>
    <visual>
      <origin rpy="0 -0 0" xyz="0 0 0"/>
      <geometry>
        <mesh filename="package://mit_drcsim_scripts/models/mit_robot/meshes/l_larm.wrl" scale="1 1 1"/>
      </geometry>
    </visual>
  </link>
  <link name="l_lglut">
    <inertial>
      <mass value="0.803"/>
      <origin rpy="0 -0 0" xyz="0.0133341 0.0170484 -0.0312052"/>
      <inertia ixx="0.0453457" ixy="-2.24344e-05" ixz="2.50508e-06" iyy="0.0174182" iyz="0.000137862" izz="0.0071591"/>
    </inertial>
    <visual>
      <origin rpy="0 -0 0" xyz="0 0 0"/>
      <geometry>
        <mesh filename="package://mit_drcsim_scripts/models/mit_robot/meshes/l_lglut.wrl" scale="1 1 1"/>
      </geometry>
    </visual>
  </link>
  <link name="l_lleg">
    <inertial>
      <mass value="4.367"/>
      <origin rpy="0 -0 0" xyz="0.001 0 -0.187"/>
      <inertia ixx="0.077" ixy="0" ixz="-0.003" iyy="0.076" iyz="0" izz="0.01"/>
    </inertial>
    <visual>
      <origin rpy="0 -0 0" xyz="0 0 0"/>
      <geometry>
        <mesh filename="package://mit_drcsim_scripts/models/mit_robot/meshes/l_lleg.wrl" scale="100. 100. 100."/>
      </geometry>
    </visual>
    <collision group="knee">
      <origin rpy="0 0 0" xyz="0.1096 0.0029 0.012"/>
      <geometry>
        <sphere radius="0"/>
      </geometry>
    </collision>
    <visual>
      <origin rpy="0 0 0" xyz="0.1096 0.0029 0.012"/>
      <geometry>
        <sphere radius="0.01"/>
      </geometry>
    </visual>
  </link>
  <link name="l_scap">
    <inertial>
      <mass value="2.707"/>
      <origin rpy="0 -0 0" xyz="-0.002 0.108 0"/>
      <inertia ixx="0.01" ixy="0" ixz="0" iyy="0.005" iyz="0" izz="0.013"/>
    </inertial>
    <visual>
      <origin rpy="0 0 0" xyz="0 0 0"/>
      <geometry>
        <mesh filename="package://mit_drcsim_scripts/models/mit_robot/meshes/l_scap.wrl" scale="1 1 1"/>
      </geometry>
    </visual>
  </link>
  <link name="l_talus">
    <inertial>
      <mass value="0.867"/>
      <origin rpy="0 -0 0" xyz="0 0 0"/>
      <inertia ixx="0.001" ixy="0" ixz="0" iyy="0.00350421" iyz="0" izz="0.00400651"/>
    </inertial>
    <visual>
      <origin rpy="0 -0 0" xyz="0 0 0"/>
      <geometry>
        <mesh filename="package://mit_drcsim_scripts/models/mit_robot/meshes/l_talus.wrl" scale="1 1 1"/>
      </geometry>
    </visual>
  </link>
  <link name="l_uarm">
    <inertial>
      <mass value="1.881"/>
      <origin rpy="0 -0 0" xyz="0.007 0.114 0.008"/>
      <inertia ixx="0.002" ixy="0" ixz="0" iyy="0.003" iyz="0" izz="0.003"/>
    </inertial>
    <visual>
      <origin rpy="0 -0 0" xyz="0 0 0"/>
      <geometry>
        <mesh filename="package://mit_drcsim_scripts/models/mit_robot/meshes/l_uarm.wrl" scale="1 1 1"/>
      </geometry>
    </visual>
  </link>
  <link name="l_uglut">
    <inertial>
      <mass value="1.51622"/>
      <origin rpy="0 -0 0" xyz="0.00529262 -0.00344732 0.00313046"/>
      <inertia ixx="0.0327037" ixy="-3.79607e-08" ixz="-2.79549e-05" iyy="0.0174182" iyz="-3.2735e-08" izz="0.0071591"/>
    </inertial>
    <visual>
      <origin rpy="0 -0 0" xyz="0 0 0"/>
      <geometry>
        <mesh filename="package://mit_drcsim_scripts/models/mit_robot/meshes/l_uglut.wrl" scale="1 1 1"/>
      </geometry>
    </visual>
  </link>
  <link name="l_uleg">
    <inertial>
      <mass value="7.227"/>
      <origin rpy="0 -0 0" xyz="0 0 -0.21"/>
      <inertia ixx="0.0453457" ixy="0" ixz="0" iyy="0.09" iyz="0" izz="0.0071591"/>
    </inertial>
    <visual>
      <origin rpy="0 -0 0" xyz="0 0 0"/>
      <geometry>
        <mesh filename="package://mit_drcsim_scripts/models/mit_robot/meshes/l_uleg.wrl" scale="1. 1. 1."/>
      </geometry>
    </visual>
    <collision group="hamstring">
      <origin rpy="0 0 0" xyz="-0.1179 0.02085 -0.18"/>
      <geometry>
        <sphere radius="0"/>
      </geometry>
    </collision>
    <visual>
      <origin rpy="0 0 0" xyz="-0.1179 0.02085 -0.18"/>
      <geometry>
        <sphere radius="0.01"/>
      </geometry>
    </visual>
    <collision group="hamstring">
      <origin rpy="0 0 0" xyz="-0.1179 0.02085 -0.08"/>
      <geometry>
        <sphere radius="0"/>
      </geometry>
    </collision>
    <visual>
      <origin rpy="0 0 0" xyz="-0.1179 0.02085 -0.08"/>
      <geometry>
        <sphere radius="0.01"/>
      </geometry>
    </visual>
  </link>
  <link name="ltorso">
    <inertial>
      <mass value="1.62729"/>
      <origin rpy="0 -0 0" xyz="-0.0112984 -3.15366e-06 0.0746835"/>
      <inertia ixx="0.0646646" ixy="-5.04491e-08" ixz="-0.000342157" iyy="0.050298" iyz="4.87119e-07" izz="0.10973"/>
    </inertial>
    <visual>
      <origin rpy="0 -0 0" xyz="0 0 0"/>
      <geometry>
        <mesh filename="package://mit_drcsim_scripts/models/mit_robot/meshes/ltorso.wrl" scale="1 1 1"/>
      </geometry>
    </visual>
  </link>
  <link name="mtorso">
    <inertial>
      <mass value="3.8068"/>
      <origin rpy="0 -0 0" xyz="-0.00816266 -0.0131245 0.0305974"/>
      <inertia ixx="0.1975" ixy="-6.10764e-05" ixz="3.94009e-05" iyy="0.544742" iyz="5.27463e-05" izz="0.10973"/>
    </inertial>
    <visual>
      <origin rpy="0 -0 0" xyz="0 0 0"/>
      <geometry>
        <mesh filename="package://mit_drcsim_scripts/models/mit_robot/meshes/mtorso.wrl" scale="1 1 1"/>
      </geometry>
    </visual>
  </link>
  <link name="pelvis">
    <inertial>
      <mass value="12.64638"/>
      <!-- 0.1 added to adjust for IMU link -->
      <origin rpy="0 -0 0" xyz="0.0111 0 0.0271"/>
      <inertia ixx="0.0327037" ixy="0.0008" ixz="-0.0007" iyy="0.0174182" iyz="-0.0005" izz="0.118059"/>
    </inertial>
    <visual>
      <origin rpy="0 -0 0" xyz="0 0 0"/>
      <geometry>
        <mesh filename="package://mit_drcsim_scripts/models/mit_robot/meshes/pelvis.wrl" scale="1. 1. 1."/>
      </geometry>
    </visual>
    <collision group="front">
      <origin rpy="0 0 0" xyz="0.17 0.042 0.09"/>
      <geometry>
        <sphere radius="0"/>
      </geometry>
    </collision>
    <visual>
      <origin rpy="0 0 0" xyz="0.17 0.042 0.09"/>
      <geometry>
        <sphere radius="0.01"/>
      </geometry>
    </visual>
    <collision group="front">
      <origin rpy="0 0 0" xyz="0.17 -0.042 0.09"/>
      <geometry>
        <sphere radius="0"/>
      </geometry>
    </collision>
    <visual>
      <origin rpy="0 0 0" xyz="0.17 -0.042 0.09"/>
      <geometry>
        <sphere radius="0.01"/>
      </geometry>
    </visual>
    <collision group="front">
      <origin rpy="0 0 0" xyz="0.156 0.0 -0.02"/>
      <geometry>
        <sphere radius="0"/>
      </geometry>
    </collision>
    <visual>
      <origin rpy="0 0 0" xyz="0.156 0.0 -0.02"/>
      <geometry>
        <sphere radius="0.01"/>
      </geometry>
    </visual>
    <collision group="butt">
      <origin rpy="0 0 0" xyz="-0.15 0.075 -0.15"/>
      <geometry>
        <sphere radius="0"/>
      </geometry>
    </collision>
    <visual>
      <origin rpy="0 0 0" xyz="-0.15 0.075 -0.15"/>
      <geometry>
        <sphere radius="0.01"/>
      </geometry>
    </visual>
    <collision group="butt">
      <origin rpy="0 0 0" xyz="-0.15 -0.075 -0.15"/>
      <geometry>
        <sphere radius="0"/>
      </geometry>
    </collision>
    <visual>
      <origin rpy="0 0 0" xyz="-0.15 -0.075 -0.15"/>
      <geometry>
        <sphere radius="0.01"/>
      </geometry>
    </visual>
  </link>
  <link name="r_clav">
    <inertial>
      <mass value="2.369"/>
      <origin rpy="0 -0 0" xyz="0.014 -0.058 0.029"/>
      <inertia ixx="0.004" ixy="-0.001" ixz="0" iyy="0.006" iyz="0" izz="0.007"/>
    </inertial>
    <visual>
      <origin rpy="-1.04719755 0 0" xyz="0 0 0"/>
      <geometry>
        <mesh filename="package://mit_drcsim_scripts/models/mit_robot/meshes/r_clav.wrl" scale="1 1 1"/>
      </geometry>
    </visual>
  </link>
  <link name="r_farm">
    <inertial>
      <mass value="0.981"/>
      <origin rpy="0 -0 0" xyz="0 -0.041 0"/>
      <inertia ixx="0.003" ixy="0" ixz="0" iyy="0.001" iyz="0" izz="0.003"/>
    </inertial>
    <visual>
      <origin rpy="0 -0 0" xyz="0 0.06 0"/>
      <geometry>
        <mesh filename="package://mit_drcsim_scripts/models/mit_robot/meshes/r_farm.wrl" scale="1 1 1"/>
      </geometry>
    </visual>
  </link>
  <link name="r_foot">
    <inertial>
      <mass value="0.867"/>
      <origin rpy="0 -0 0" xyz="0.027 0 -0.067"/>
      <inertia ixx="0.002" ixy="0" ixz="0" iyy="0.00350421" iyz="0" izz="0.00400651"/>
    </inertial>
    <visual>
      <origin rpy="0 -0 0" xyz="0 0 0"/>
      <geometry>
        <mesh filename="package://mit_drcsim_scripts/models/mit_robot/meshes/r_foot.wrl" scale="1 1 1"/>
      </geometry>
    </visual>
    <collision group="heel">
      <origin rpy="0 0 0" xyz="-0.082 0.0624435 -0.081119"/>
      <geometry>
        <sphere radius="0"/>
      </geometry>
    </collision>
    <visual>
      <origin rpy="0 0 0" xyz="-0.082 0.0624435 -0.081119"/>
      <geometry>
        <sphere radius="0.01"/>
      </geometry>
    </visual>
    <collision group="heel">
      <origin rpy="0 0 0" xyz="-0.082 -0.0624435 -0.081119"/>
      <geometry>
        <sphere radius="0"/>
      </geometry>
    </collision>
    <visual>
      <origin rpy="0 0 0" xyz="-0.082 -0.0624435 -0.081119"/>
      <geometry>
        <sphere radius="0.01"/>
      </geometry>
    </visual>
    <collision group="toe">
      <origin rpy="0 0 0" xyz="0.178 0.0624435 -0.081119"/>
      <geometry>
        <sphere radius="0"/>
      </geometry>
    </collision>
    <visual>
      <origin rpy="0 0 0" xyz="0.178 0.0624435 -0.081119"/>
      <geometry>
        <sphere radius="0.01"/>
      </geometry>
    </visual>
    <collision group="toe">
      <origin rpy="0 0 0" xyz="0.178 -0.0624435 -0.081119"/>
      <geometry>
        <sphere radius="0"/>
      </geometry>
    </collision>
    <visual>
      <origin rpy="0 0 0" xyz="0.178 -0.0624435 -0.081119"/>
      <geometry>
        <sphere radius="0.01"/>
      </geometry>
    </visual>
  </link>
  <link name="r_hand">
    <inertial>
      <mass value="2.263"/>
      <origin rpy="0 -0 0" xyz="0 -0.093 0"/>
      <inertia ixx="0.01" ixy="0" ixz="0" iyy="0.002" iyz="0" izz="0.01"/>
    </inertial>
    <visual>
      <origin rpy="0 -0 0" xyz="0 0 0"/>
      <geometry>
        <mesh filename="package://mit_drcsim_scripts/models/mit_robot/meshes/r_hand.wrl" scale="1 1 1"/>
      </geometry>
    </visual>
    <collision group="palm">
      <origin rpy="0 0 0" xyz="0.0 -0.115 0.0"/>
      <geometry>
        <sphere radius="0"/>
      </geometry>
    </collision>
    <visual>
      <origin rpy="0 0 0" xyz="0.0 -0.115 0.0"/>
      <geometry>
        <sphere radius="0.01"/>
      </geometry>
    </visual>
  </link>
  <link name="r_larm">
    <inertial>
      <mass value="2.148"/>
      <origin rpy="0 -0 0" xyz="-0.003 -0.099 -0.014"/>
      <inertia ixx="0.005" ixy="0" ixz="0" iyy="0.003" iyz="0" izz="0.006"/>
    </inertial>
    <visual>
      <origin rpy="0 -0 0" xyz="0 0 0"/>
      <geometry>
        <mesh filename="package://mit_drcsim_scripts/models/mit_robot/meshes/r_larm.wrl" scale="1. 1. 1."/>
      </geometry>
    </visual>
  </link>
  <link name="r_lglut">
    <inertial>
      <mass value="0.803"/>
      <origin rpy="0 -0 0" xyz="0.0133341 -0.0170484 -0.0312052"/>
      <inertia ixx="0.0453457" ixy="2.24344e-05" ixz="2.50508e-06" iyy="0.0174182" iyz="-0.000137862" izz="0.0071591"/>
    </inertial>
    <visual>
      <origin rpy="0 -0 0" xyz="0 0 0"/>
      <geometry>
        <mesh filename="package://mit_drcsim_scripts/models/mit_robot/meshes/r_lglut.wrl" scale="1. 1. 1."/>
      </geometry>
    </visual>
  </link>
  <link name="r_lleg">
    <inertial>
      <mass value="4.367"/>
      <origin rpy="0 -0 0" xyz="0.001 0 -0.187"/>
      <inertia ixx="0.077" ixy="-0" ixz="-0.003" iyy="0.076" iyz="-0" izz="0.01"/>
    </inertial>
    <visual>
      <origin rpy="0 -0 0" xyz="0 0 0"/>
      <geometry>
        <mesh filename="package://mit_drcsim_scripts/models/mit_robot/meshes/r_lleg.wrl" scale="1. 1. 1."/>
      </geometry>
    </visual>
    <collision group="knee">
      <origin rpy="0 0 0" xyz="0.1096 0.0029 0.012"/>
      <geometry>
        <sphere radius="0"/>
      </geometry>
    </collision>
    <visual>
      <origin rpy="0 0 0" xyz="0.1096 0.0029 0.012"/>
      <geometry>
        <sphere radius="0.01"/>
      </geometry>
    </visual>
  </link>
  <link name="r_scap">
    <inertial>
      <mass value="2.707"/>
      <origin rpy="0 -0 0" xyz="-0.002 -0.108 0"/>
      <inertia ixx="0.01" ixy="0" ixz="0" iyy="0.005" iyz="0" izz="0.013"/>
    </inertial>
    <visual>
      <origin rpy="0 -0 0" xyz="0 0 0"/>
      <geometry>
        <mesh filename="package://mit_drcsim_scripts/models/mit_robot/meshes/r_scap.wrl" scale="1 1 1"/>
      </geometry>
    </visual>
  </link>
  <link name="r_talus">
    <inertial>
      <mass value="0.867"/>
      <origin rpy="0 -0 0" xyz="0 0 0"/>
      <inertia ixx="0.001" ixy="0" ixz="0" iyy="0.00350421" iyz="0" izz="0.00400651"/>
    </inertial>
    <visual>
      <origin rpy="0 -0 0" xyz="0 0 0"/>
      <geometry>
        <mesh filename="package://mit_drcsim_scripts/models/mit_robot/meshes/r_talus.wrl" scale="1 1 1"/>
      </geometry>
    </visual>
  </link>
  <link name="r_uarm">
    <inertial>
      <mass value="1.881"/>
      <origin rpy="0 -0 0" xyz="0.007 -0.114 0.008"/>
      <inertia ixx="0.002" ixy="0" ixz="0" iyy="0.003" iyz="0" izz="0.003"/>
    </inertial>
    <visual>
      <origin rpy="0 -0 0" xyz="0 0 0"/>
      <geometry>
        <mesh filename="package://mit_drcsim_scripts/models/mit_robot/meshes/r_uarm.wrl" scale="1. 1. 1."/>
      </geometry>
    </visual>
  </link>
  <link name="r_uglut">
    <inertial>
      <mass value="1.51622"/>
      <origin rpy="0 -0 0" xyz="0.00529262 0.00344732 0.00313046"/>
      <inertia ixx="0.0327037" ixy="3.79607e-08" ixz="-2.79549e-05" iyy="0.0174182" iyz="3.2735e-08" izz="0.0071591"/>
    </inertial>
    <visual>
      <origin rpy="0 -0 0" xyz="0 0 0"/>
      <geometry>
        <mesh filename="package://mit_drcsim_scripts/models/mit_robot/meshes/r_uglut.wrl" scale="1. 1. 1."/>
      </geometry>
    </visual>
  </link>
  <link name="r_uleg">
    <inertial>
      <mass value="7.227"/>
      <origin rpy="0 -0 0" xyz="0 0 -0.21"/>
      <inertia ixx="0.0453457" ixy="0" ixz="0" iyy="0.09" iyz="0" izz="0.0071591"/>
    </inertial>
    <visual>
      <origin rpy="0 -0 0" xyz="0 0 0"/>
      <geometry>
        <mesh filename="package://mit_drcsim_scripts/models/mit_robot/meshes/r_uleg.wrl" scale="1. 1. 1."/>
      </geometry>
    </visual>
    <collision group="hamstring">
      <origin rpy="0 0 0" xyz="-0.1179 -0.02085 -0.18"/>
      <geometry>
        <sphere radius="0"/>
      </geometry>
    </collision>
    <visual>
      <origin rpy="0 0 0" xyz="-0.1179 -0.02085 -0.18"/>
      <geometry>
        <sphere radius="0.01"/>
      </geometry>
    </visual>
    <collision group="hamstring">
      <origin rpy="0 0 0" xyz="-0.1179 -0.02085 -0.08"/>
      <geometry>
        <sphere radius="0"/>
      </geometry>
    </collision>
    <visual>
      <origin rpy="0 0 0" xyz="-0.1179 -0.02085 -0.08"/>
      <geometry>
        <sphere radius="0.01"/>
      </geometry>
    </visual>
  </link>
  <link name="utorso">
    <inertial>
      <mass value="15.2272"/>
      <origin rpy="0 -0 0" xyz="0.02 -0.001 0.211"/>
      <inertia ixx="0.395" ixy="0" ixz="0.083" iyy="0.544742" iyz="-0.003" izz="0.10973"/>
    </inertial>
    <visual>
      <origin rpy="0 -0 0" xyz="0 0 0"/>
      <geometry>
        <mesh filename="package://mit_drcsim_scripts/models/mit_robot/meshes/utorso.wrl" scale="1 1 1"/>
      </geometry>
    </visual>
    <collision group="front">
      <origin rpy="0 0 0" xyz="0.2040 0.12 0.3471"/>
      <geometry>
        <sphere radius="0"/>
      </geometry>
    </collision>
    <visual>
      <origin rpy="0 0 0" xyz="0.2040 0.12 0.3471"/>
      <geometry>
        <sphere radius="0.01"/>
      </geometry>
    </visual>
    <collision group="front">
      <origin rpy="0 0 0" xyz="0.2040 -0.12 0.3471"/>
      <geometry>
        <sphere radius="0"/>
      </geometry>
    </collision>
    <visual>
      <origin rpy="0 0 0" xyz="0.2040 -0.12 0.3471"/>
      <geometry>
        <sphere radius="0.01"/>
      </geometry>
    </visual>
    <collision group="front">
      <origin rpy="0 0 0" xyz="0.2040 0.12 0.0309"/>
      <geometry>
        <sphere radius="0"/>
      </geometry>
    </collision>
    <visual>
      <origin rpy="0 0 0" xyz="0.2040 0.12 0.0309"/>
      <geometry>
        <sphere radius="0.01"/>
      </geometry>
    </visual>
    <collision group="front">
      <origin rpy="0 0 0" xyz="0.2040 -0.12 0.0309"/>
      <geometry>
        <sphere radius="0"/>
      </geometry>
    </collision>
    <visual>
      <origin rpy="0 0 0" xyz="0.2040 -0.12 0.0309"/>
      <geometry>
        <sphere radius="0.01"/>
      </geometry>
    </visual>
    <collision group="back">
      <origin rpy="0 0 0" xyz="-0.1148 0.12 0.3471"/>
      <geometry>
        <sphere radius="0"/>
      </geometry>
    </collision>
    <visual>
      <origin rpy="0 0 0" xyz="-0.1148 0.12 0.3471"/>
      <geometry>
        <sphere radius="0.01"/>
      </geometry>
    </visual>
    <collision group="back">
      <origin rpy="0 0 0" xyz="-0.1148 -0.12 0.3471"/>
      <geometry>
        <sphere radius="0"/>
      </geometry>
    </collision>
    <visual>
      <origin rpy="0 0 0" xyz="-0.1148 -0.12 0.3471"/>
      <geometry>
        <sphere radius="0.01"/>
      </geometry>
    </visual>
    <collision group="back">
      <origin rpy="0 0 0" xyz="-0.1148 0.12 0.0309"/>
      <geometry>
        <sphere radius="0"/>
      </geometry>
    </collision>
    <visual>
      <origin rpy="0 0 0" xyz="-0.1148 0.12 0.0309"/>
      <geometry>
        <sphere radius="0.01"/>
      </geometry>
    </visual>
    <collision group="back">
      <origin rpy="0 0 0" xyz="-0.1148 -0.12 0.0309"/>
      <geometry>
        <sphere radius="0"/>
      </geometry>
    </collision>
    <visual>
      <origin rpy="0 0 0" xyz="-0.1148 -0.12 0.0309"/>
      <geometry>
        <sphere radius="0.01"/>
      </geometry>
    </visual>
  </link>
  <joint name="back_lbz" type="revolute">
    <origin rpy="0 -0 0" xyz="-0.0125 0 0"/>
    <axis xyz="0 0 1"/>
    <parent link="pelvis"/>
    <child link="ltorso"/>
    <dynamics damping="10" friction="0"/>
    <limit effort="124.016" lower="-0.610865" upper="0.610865" velocity="12"/>
    <safety_controller k_position="100" k_velocity="100" soft_lower_limit="-10.6109" soft_upper_limit="10.6109"/>
  </joint>
  <joint name="back_mby" type="revolute">
    <origin rpy="0 -0 0" xyz="0 0 0.09"/>
    <axis xyz="0 1 0"/>
    <parent link="ltorso"/>
    <child link="mtorso"/>
    <dynamics damping="10" friction="0"/>
    <limit effort="206.843" lower="-1.2" upper="1.28" velocity="12"/>
    <safety_controller k_position="100" k_velocity="100" soft_lower_limit="-11.2" soft_upper_limit="11.28"/>
  </joint>
  <joint name="back_ubx" type="revolute">
    <origin rpy="0 -0 0" xyz="0 0 0.05"/>
    <axis xyz="1 0 0"/>
    <parent link="mtorso"/>
    <child link="utorso"/>
    <dynamics damping="10" friction="0"/>
    <limit effort="94.91" lower="-0.790809" upper="0.790809" velocity="12"/>
    <safety_controller k_position="100" k_velocity="100" soft_lower_limit="-10.7908" soft_upper_limit="10.7908"/>
  </joint>
  <joint name="l_arm_elx" type="revolute">
    <origin rpy="0 -0 0" xyz="0 0.121 0.013"/>
    <axis xyz="1 0 0"/>
    <parent link="l_uarm"/>
    <child link="l_larm"/>
    <dynamics damping="1.0" friction="0"/>
    <limit effort="114" lower="0" upper="2.35619" velocity="12"/>
    <safety_controller k_position="100" k_velocity="100" soft_lower_limit="-10" soft_upper_limit="12.3562"/>
  </joint>
  <joint name="l_arm_ely" type="revolute">
    <origin rpy="0 -0 0" xyz="0 0.185 0"/>
    <axis xyz="0 1 0"/>
    <parent link="l_scap"/>
    <child link="l_uarm"/>
    <dynamics damping="1.0" friction="0"/>
    <limit effort="114" lower="0" upper="3.14159" velocity="12"/>
    <safety_controller k_position="100" k_velocity="100" soft_lower_limit="-10" soft_upper_limit="13.1416"/>
  </joint>
  <joint name="l_arm_mwx" type="revolute">
    <origin rpy="0 -0 0" xyz="0 0.058 0"/>
    <axis xyz="1 0 0"/>
    <parent link="l_farm"/>
    <child link="l_hand"/>
    <dynamics damping="1.0" friction="0"/>
    <limit effort="60" lower="-0.436" upper="1.571" velocity="12"/>
    <safety_controller k_position="100" k_velocity="100" soft_lower_limit="-10.436" soft_upper_limit="11.571"/>
  </joint>
  <joint name="l_arm_shx" type="revolute">
    <origin rpy="0 -0 0" xyz="0 0.075 0.036"/>
    <axis xyz="1 0 0"/>
    <parent link="l_clav"/>
    <child link="l_scap"/>
    <dynamics damping="1.0" friction="0"/>
    <limit effort="170" lower="-1.39626" upper="1.74533" velocity="12"/>
    <safety_controller k_position="100" k_velocity="100" soft_lower_limit="-11.3963" soft_upper_limit="11.7453"/>
  </joint>
  <joint name="l_arm_usy" type="revolute">
    <origin rpy="0 -0 0" xyz="0.024 0.221 0.289"/>
    <axis xyz="0 0.5 0.866025"/>
    <parent link="utorso"/>
    <child link="l_clav"/>
    <dynamics damping="1.0" friction="0"/>
    <limit effort="212" lower="-1.9635" upper="1.9635" velocity="12"/>
    <safety_controller k_position="100" k_velocity="100" soft_lower_limit="-11.9635" soft_upper_limit="11.9635"/>
  </joint>
  <joint name="l_arm_uwy" type="revolute">
    <origin rpy="0 -0 0" xyz="0 0.188 -0.013"/>
    <axis xyz="0 1 0"/>
    <parent link="l_larm"/>
    <child link="l_farm"/>
    <dynamics damping="1.0" friction="0"/>
    <limit effort="114" lower="-1.571" upper="1.571" velocity="12"/>
    <safety_controller k_position="100" k_velocity="100" soft_lower_limit="-11.571" soft_upper_limit="11.571"/>
  </joint>
  <joint name="l_leg_kny" type="revolute">
    <origin rpy="0 -0 0" xyz="-0.05 0 -0.374"/>
    <axis xyz="0 1 0"/>
    <parent link="l_uleg"/>
    <child link="l_lleg"/>
    <dynamics damping="1.0" friction="0"/>
    <limit effort="400" lower="0" upper="2.45" velocity="12"/>
    <safety_controller k_position="100" k_velocity="100" soft_lower_limit="-10" soft_upper_limit="12.45"/>
  </joint>
  <joint name="l_leg_lax" type="revolute">
    <origin rpy="0 -0 0" xyz="0 0 0"/>
    <axis xyz="1 0 0"/>
    <parent link="l_talus"/>
    <child link="l_foot"/>
    <dynamics damping="1.0" friction="0"/>
    <limit effort="90" lower="-0.436" upper="0.436" velocity="12"/>
    <safety_controller k_position="100" k_velocity="100" soft_lower_limit="-10.436" soft_upper_limit="10.436"/>
  </joint>
  <joint name="l_leg_lhy" type="revolute">
    <origin rpy="0 -0 0" xyz="0.05 0 -0.05"/>
    <axis xyz="0 1 0"/>
    <parent link="l_lglut"/>
    <child link="l_uleg"/>
    <dynamics damping="1.0" friction="0"/>
    <limit effort="260" lower="-1.75" upper="0.524" velocity="12"/>
    <safety_controller k_position="100" k_velocity="100" soft_lower_limit="-11.75" soft_upper_limit="10.524"/>
  </joint>
  <joint name="l_leg_mhx" type="revolute">
    <origin rpy="0 -0 0" xyz="0 0 0"/>
    <axis xyz="1 0 0"/>
    <parent link="l_uglut"/>
    <child link="l_lglut"/>
    <dynamics damping="1.0" friction="0"/>
    <limit effort="180" lower="-0.47" upper="0.495" velocity="12"/>
    <safety_controller k_position="100" k_velocity="100" soft_lower_limit="-10.47" soft_upper_limit="10.495"/>
  </joint>
  <joint name="l_leg_uay" type="revolute">
    <origin rpy="0 -0 0" xyz="0 0 -0.422"/>
    <axis xyz="0 1 0"/>
    <parent link="l_lleg"/>
    <child link="l_talus"/>
    <dynamics damping="1.0" friction="0"/>
    <limit effort="220" lower="-0.9" upper="0.698" velocity="12"/>
    <safety_controller k_position="100" k_velocity="100" soft_lower_limit="-10.698" soft_upper_limit="10.698"/>
  </joint>
  <joint name="l_leg_uhz" type="revolute">
    <origin rpy="0 -0 0" xyz="0 0.089 0"/>
    <axis xyz="0 0 1"/>
    <parent link="pelvis"/>
    <child link="l_uglut"/>
    <dynamics damping="1.0" friction="0"/>
    <limit effort="110" lower="-0.32" upper="1.14" velocity="12"/>
    <safety_controller k_position="100" k_velocity="100" soft_lower_limit="-10.32" soft_upper_limit="11.14"/>
  </joint>
  <joint name="neck_ay" type="revolute">
    <!-- per slides on sensor head kinematics 2013-02-13 -->
    <origin rpy="0 -0 0" xyz="0.21672 0 0.53796"/>
    <axis xyz="0 1 0"/>
    <parent link="utorso"/>
    <child link="head"/>
    <dynamics damping="1.0" friction="0"/>
    <!-- per slides on sensor head kinematics 2012-12-14 -->
    <limit effort="5" lower="-0.610865238" upper="1.13446401" velocity="12"/>
    <safety_controller k_position="100" k_velocity="100" soft_lower_limit="-10.610865238" soft_upper_limit="11.13446401"/>
  </joint>
  <joint name="r_arm_elx" type="revolute">
    <origin rpy="0 -0 0" xyz="0 -0.121 0.013"/>
    <axis xyz="1 0 0"/>
    <parent link="r_uarm"/>
    <child link="r_larm"/>
    <dynamics damping="1.0" friction="0"/>
    <limit effort="114" lower="-2.35619" upper="0" velocity="12"/>
    <safety_controller k_position="100" k_velocity="100" soft_lower_limit="-12.3562" soft_upper_limit="10"/>
  </joint>
  <joint name="r_arm_ely" type="revolute">
    <origin rpy="0 -0 0" xyz="0 -0.185 0"/>
    <axis xyz="0 1 0"/>
    <parent link="r_scap"/>
    <child link="r_uarm"/>
    <dynamics damping="1.0" friction="0"/>
    <limit effort="114" lower="0" upper="3.14159" velocity="12"/>
    <safety_controller k_position="100" k_velocity="100" soft_lower_limit="-10" soft_upper_limit="13.1416"/>
  </joint>
  <joint name="r_arm_mwx" type="revolute">
    <origin rpy="0 -0 0" xyz="0 -0.058 0"/>
    <axis xyz="1 0 0"/>
    <parent link="r_farm"/>
    <child link="r_hand"/>
    <dynamics damping="1.0" friction="0"/>
    <limit effort="60" lower="-1.571" upper="0.436" velocity="12"/>
    <safety_controller k_position="100" k_velocity="100" soft_lower_limit="-11.571" soft_upper_limit="10.436"/>
  </joint>
  <joint name="r_arm_shx" type="revolute">
    <origin rpy="0 -0 0" xyz="0 -0.075 0.036"/>
    <axis xyz="1 0 0"/>
    <parent link="r_clav"/>
    <child link="r_scap"/>
    <dynamics damping="1.0" friction="0"/>
    <limit effort="170" lower="-1.74533" upper="1.39626" velocity="12"/>
    <safety_controller k_position="100" k_velocity="100" soft_lower_limit="-11.7453" soft_upper_limit="11.3963"/>
  </joint>
  <joint name="r_arm_usy" type="revolute">
    <origin rpy="0 -0 0" xyz="0.024 -0.221 0.289"/>
    <axis xyz="0 0.5 -0.866025"/>
    <parent link="utorso"/>
    <child link="r_clav"/>
    <dynamics damping="1.0" friction="0"/>
    <limit effort="212" lower="-1.9635" upper="1.9635" velocity="12"/>
    <safety_controller k_position="100" k_velocity="100" soft_lower_limit="-11.9635" soft_upper_limit="11.9635"/>
  </joint>
  <joint name="r_arm_uwy" type="revolute">
    <origin rpy="0 -0 0" xyz="0 -0.188 -0.013"/>
    <axis xyz="0 1 0"/>
    <parent link="r_larm"/>
    <child link="r_farm"/>
    <dynamics damping="1.0" friction="0"/>
    <limit effort="114" lower="-1.571" upper="1.571" velocity="12"/>
    <safety_controller k_position="100" k_velocity="100" soft_lower_limit="-11.571" soft_upper_limit="11.571"/>
  </joint>
  <joint name="r_leg_kny" type="revolute">
    <origin rpy="0 -0 0" xyz="-0.05 0 -0.374"/>
    <axis xyz="0 1 0"/>
    <parent link="r_uleg"/>
    <child link="r_lleg"/>
    <dynamics damping="1.0" friction="0"/>
    <limit effort="400" lower="0" upper="2.45" velocity="12"/>
    <safety_controller k_position="100" k_velocity="100" soft_lower_limit="-10" soft_upper_limit="12.45"/>
  </joint>
  <joint name="r_leg_lax" type="revolute">
    <origin rpy="0 -0 0" xyz="0 0 0"/>
    <axis xyz="1 0 0"/>
    <parent link="r_talus"/>
    <child link="r_foot"/>
    <dynamics damping="1.0" friction="0"/>
    <limit effort="90" lower="-0.436" upper="0.436" velocity="12"/>
    <safety_controller k_position="100" k_velocity="100" soft_lower_limit="-10.436" soft_upper_limit="10.436"/>
  </joint>
  <joint name="r_leg_lhy" type="revolute">
    <origin rpy="0 -0 0" xyz="0.05 0 -0.05"/>
    <axis xyz="0 1 0"/>
    <parent link="r_lglut"/>
    <child link="r_uleg"/>
    <dynamics damping="1.0" friction="0"/>
    <limit effort="260" lower="-1.745" upper="0.524" velocity="12"/>
    <safety_controller k_position="100" k_velocity="100" soft_lower_limit="-11.745" soft_upper_limit="10.524"/>
  </joint>
  <joint name="r_leg_mhx" type="revolute">
    <origin rpy="0 -0 0" xyz="0 0 0"/>
    <axis xyz="1 0 0"/>
    <parent link="r_uglut"/>
    <child link="r_lglut"/>
    <dynamics damping="1.0" friction="0"/>
    <limit effort="180" lower="-0.495" upper="0.47" velocity="12"/>
    <safety_controller k_position="100" k_velocity="100" soft_lower_limit="-10.495" soft_upper_limit="10.47"/>
  </joint>
  <joint name="r_leg_uay" type="revolute">
    <origin rpy="0 -0 0" xyz="0 0 -0.422"/>
    <axis xyz="0 1 0"/>
    <parent link="r_lleg"/>
    <child link="r_talus"/>
    <dynamics damping="1.0" friction="0"/>
    <limit effort="220" lower="-0.9" upper="0.698" velocity="12"/>
    <safety_controller k_position="100" k_velocity="100" soft_lower_limit="-10.698" soft_upper_limit="10.698"/>
  </joint>
  <joint name="r_leg_uhz" type="revolute">
    <origin rpy="0 -0 0" xyz="0 -0.089 0"/>
    <axis xyz="0 0 1"/>
    <parent link="pelvis"/>
    <child link="r_uglut"/>
    <dynamics damping="1.0" friction="0"/>
    <limit effort="260" lower="-1.14" upper="0.32" velocity="12"/>
    <safety_controller k_position="100" k_velocity="100" soft_lower_limit="-11.14" soft_upper_limit="10.32"/>
  </joint>
  <link name="l_hand_point_mass">
    <origin rpy="0 0 0" xyz="0 0 0"/>
    <inertial>
      <mass value="3.131"/>
      <!--NEW value-->
      <!-- <mass value="2.312"/>-->
      <!--OLD value-->
      <origin xyz="0 0 0"/>
      <inertia ixx="0.01" ixy="0" ixz="0" iyy="0.01" iyz="0" izz="0.01"/>
    </inertial>
    <visual>
      <origin rpy="0 0 0" xyz="0 0 0"/>
      <geometry>
        <sphere radius="0.03"/>
      </geometry>
    </visual>
  </link>
  <link name="r_hand_point_mass">
    <origin rpy="0 0 0" xyz="0 0 0"/>
    <inertial>
      <mass value="3.131"/>
      <!--NEW value-->
      <!-- <mass value="2.312"/>-->
      <!--OLD value-->
      <origin xyz="0 0 0"/>
      <inertia ixx="0.01" ixy="0" ixz="0" iyy="0.01" iyz="0" izz="0.01"/>
    </inertial>
    <visual>
      <origin rpy="0 0 0" xyz="0 0 0"/>
      <geometry>
        <sphere radius="0.03"/>
      </geometry>
    </visual>
  </link>
  <joint name="l_hand_joint" type="fixed">
    <parent link="l_hand"/>
    <child link="l_hand_point_mass"/>
    <origin rpy="0 0 0" xyz="0.0037 0.1603 -0.0087"/>
    <!--NEW value-->
    <!-- <origin rpy="0 0 0" xyz="0.0054 0.1905 -0.0129"/>-->
    <!--OLD value-->
  </joint>
  <joint name="r_hand_joint" type="fixed">
    <parent link="r_hand"/>
    <child link="r_hand_point_mass"/>
    <origin rpy="0 0 0" xyz="0.0037 -0.1603 -0.0087"/>
    <!--NEW value-->
    <!--   <origin rpy="0 0 0" xyz="0.0054 -0.1905 -0.0129"/>-->
    <!--OLD value-->
  </joint>
  <transmission name="back_lbz_trans" type="pr2_mechanism_model/SimpleTransmission">
    <joint name="back_lbz"/>
    <actuator name="back_lbz_motor"/>
    <mechanicalReduction>1</mechanicalReduction>
  </transmission>
  <transmission name="back_mby_trans" type="pr2_mechanism_model/SimpleTransmission">
    <actuator name="back_mby_motor"/>
    <joint name="back_mby"/>
    <mechanicalReduction>1</mechanicalReduction>
  </transmission>
  <transmission name="back_ubx_trans" type="pr2_mechanism_model/SimpleTransmission">
    <actuator name="back_ubx_motor"/>
    <joint name="back_ubx"/>
    <mechanicalReduction>1</mechanicalReduction>
  </transmission>
  <transmission name="l_arm_elx_trans" type="pr2_mechanism_model/SimpleTransmission">
    <actuator name="l_arm_elx_motor"/>
    <joint name="l_arm_elx"/>
    <mechanicalReduction>1</mechanicalReduction>
  </transmission>
  <transmission name="l_arm_ely_trans" type="pr2_mechanism_model/SimpleTransmission">
    <actuator name="l_arm_ely_motor"/>
    <joint name="l_arm_ely"/>
    <mechanicalReduction>1</mechanicalReduction>
  </transmission>
  <transmission name="l_arm_mwx_trans" type="pr2_mechanism_model/SimpleTransmission">
    <actuator name="l_arm_mwx_motor"/>
    <joint name="l_arm_mwx"/>
    <mechanicalReduction>1</mechanicalReduction>
  </transmission>
  <transmission name="l_arm_shx_trans" type="pr2_mechanism_model/SimpleTransmission">
    <actuator name="l_arm_shx_motor"/>
    <joint name="l_arm_shx"/>
    <mechanicalReduction>1</mechanicalReduction>
  </transmission>
  <transmission name="l_arm_usy_trans" type="pr2_mechanism_model/SimpleTransmission">
    <actuator name="l_arm_usy_motor"/>
    <joint name="l_arm_usy"/>
    <mechanicalReduction>1</mechanicalReduction>
  </transmission>
  <transmission name="l_arm_uwy_trans" type="pr2_mechanism_model/SimpleTransmission">
    <actuator name="l_arm_uwy_motor"/>
    <joint name="l_arm_uwy"/>
    <mechanicalReduction>1</mechanicalReduction>
  </transmission>
  <transmission name="l_leg_kny_trans" type="pr2_mechanism_model/SimpleTransmission">
    <actuator name="l_leg_kny_motor"/>
    <joint name="l_leg_kny"/>
    <mechanicalReduction>1</mechanicalReduction>
  </transmission>
  <transmission name="l_leg_lax_trans" type="pr2_mechanism_model/SimpleTransmission">
    <actuator name="l_leg_lax_motor"/>
    <joint name="l_leg_lax"/>
    <mechanicalReduction>1</mechanicalReduction>
  </transmission>
  <transmission name="l_leg_lhy_trans" type="pr2_mechanism_model/SimpleTransmission">
    <actuator name="l_leg_lhy_motor"/>
    <joint name="l_leg_lhy"/>
    <mechanicalReduction>1</mechanicalReduction>
  </transmission>
  <transmission name="l_leg_mhx_trans" type="pr2_mechanism_model/SimpleTransmission">
    <actuator name="l_leg_mhx_motor"/>
    <joint name="l_leg_mhx"/>
    <mechanicalReduction>1</mechanicalReduction>
  </transmission>
  <transmission name="l_leg_uay_trans" type="pr2_mechanism_model/SimpleTransmission">
    <actuator name="l_leg_uay_motor"/>
    <joint name="l_leg_uay"/>
    <mechanicalReduction>1</mechanicalReduction>
  </transmission>
  <transmission name="l_leg_uhz_trans" type="pr2_mechanism_model/SimpleTransmission">
    <actuator name="l_leg_uhz_motor"/>
    <joint name="l_leg_uhz"/>
    <mechanicalReduction>1</mechanicalReduction>
  </transmission>
  <transmission name="neck_ay_trans" type="pr2_mechanism_model/SimpleTransmission">
    <actuator name="neck_ay_motor"/>
    <joint name="neck_ay"/>
    <mechanicalReduction>1</mechanicalReduction>
  </transmission>
  <transmission name="r_arm_elx_trans" type="pr2_mechanism_model/SimpleTransmission">
    <actuator name="r_arm_elx_motor"/>
    <joint name="r_arm_elx"/>
    <mechanicalReduction>1</mechanicalReduction>
  </transmission>
  <transmission name="r_arm_ely_trans" type="pr2_mechanism_model/SimpleTransmission">
    <actuator name="r_arm_ely_motor"/>
    <joint name="r_arm_ely"/>
    <mechanicalReduction>1</mechanicalReduction>
  </transmission>
  <transmission name="r_arm_mwx_trans" type="pr2_mechanism_model/SimpleTransmission">
    <actuator name="r_arm_mwx_motor"/>
    <joint name="r_arm_mwx"/>
    <mechanicalReduction>1</mechanicalReduction>
  </transmission>
  <transmission name="r_arm_shx_trans" type="pr2_mechanism_model/SimpleTransmission">
    <actuator name="r_arm_shx_motor"/>
    <joint name="r_arm_shx"/>
    <mechanicalReduction>1</mechanicalReduction>
  </transmission>
  <transmission name="r_arm_usy_trans" type="pr2_mechanism_model/SimpleTransmission">
    <actuator name="r_arm_usy_motor"/>
    <joint name="r_arm_usy"/>
    <mechanicalReduction>1</mechanicalReduction>
  </transmission>
  <transmission name="r_arm_uwy_trans" type="pr2_mechanism_model/SimpleTransmission">
    <actuator name="r_arm_uwy_motor"/>
    <joint name="r_arm_uwy"/>
    <mechanicalReduction>1</mechanicalReduction>
  </transmission>
  <transmission name="r_leg_kny_trans" type="pr2_mechanism_model/SimpleTransmission">
    <actuator name="r_leg_kny_motor"/>
    <joint name="r_leg_kny"/>
    <mechanicalReduction>1</mechanicalReduction>
  </transmission>
  <transmission name="r_leg_lax_trans" type="pr2_mechanism_model/SimpleTransmission">
    <actuator name="r_leg_lax_motor"/>
    <joint name="r_leg_lax"/>
    <mechanicalReduction>1</mechanicalReduction>
  </transmission>
  <transmission name="r_leg_lhy_trans" type="pr2_mechanism_model/SimpleTransmission">
    <actuator name="r_leg_lhy_motor"/>
    <joint name="r_leg_lhy"/>
    <mechanicalReduction>1</mechanicalReduction>
  </transmission>
  <transmission name="r_leg_mhx_trans" type="pr2_mechanism_model/SimpleTransmission">
    <actuator name="r_leg_mhx_motor"/>
    <joint name="r_leg_mhx"/>
    <mechanicalReduction>1</mechanicalReduction>
  </transmission>
  <transmission name="r_leg_uay_trans" type="pr2_mechanism_model/SimpleTransmission">
    <actuator name="r_leg_uay_motor"/>
    <joint name="r_leg_uay"/>
    <mechanicalReduction>1</mechanicalReduction>
  </transmission>
  <transmission name="r_leg_uhz_trans" type="pr2_mechanism_model/SimpleTransmission">
    <actuator name="r_leg_uhz_motor"/>
    <joint name="r_leg_uhz"/>
    <mechanicalReduction>1</mechanicalReduction>
  </transmission>
  <link name="head">
    <inertial>
      <origin rpy="0 0 0" xyz="-0.075493 3.3383E-05 0.02774"/>
      <mass value="1.477574"/>
      <inertia ixx="0.0039688" ixy="-1.5797E-06" ixz="-0.00089293" iyy="0.0041178" iyz="-6.8415E-07" izz="0.0035243"/>
    </inertial>
    <visual>
      <origin rpy="0 0 1.570795" xyz="-0.0446 0 0.0880"/>
      <geometry>
        <mesh filename="package://mit_drcsim_scripts/models/multisense_sl/meshes/base_link.wrl"/>
      </geometry>
      <material name="">
        <color rgba="0.9098 0.44314 0.031373 1"/>
      </material>
    </visual>
  </link>
  <gazebo>
    <plugin filename="libMultiSenseSLPlugin.so" name="multisense_plugin"/>
  </gazebo>
</robot>

