<?xml version="1.0" ?>
<!-- =================================================================================== -->
<!-- |    This document was autogenerated by xacro from ROShover.urdf.xacro            | -->
<!-- |    EDITING THIS FILE BY HAND IS NOT RECOMMENDED                                 | -->
<!-- =================================================================================== -->
<robot name="simpleHoverBot" xmlns:xacro="http://www.ros.org/wiki/xacro">
  <!--Properties of the robot-->
  <!--Create the visual element for a box-->
  <!--Create a small inertial element-->
  <!--Inertial element for a box-->
  <!--Creates a link in the form of a box-->
  <!--Creates a transmission at a joint.-->
  <link name="base_link"/>
  <link name="Z_link">
    <inertial>
      <mass value="0.0001"/>
      <inertia ixx="0.0001" ixy="0" ixz="0" iyy="0.0001" iyz="0" izz="0.0001"/>
    </inertial>
  </link>
  <link name="X_link">
    <inertial>
      <mass value="0.0001"/>
      <inertia ixx="0.0001" ixy="0" ixz="0" iyy="0.0001" iyz="0" izz="0.0001"/>
    </inertial>
  </link>
  <link name="final_link">
    <inertial>
      <mass value="10"/>
      <inertia ixx="0.15" ixy="0" ixz="0" iyy="0.15" iyz="0" izz="0.15"/>
    </inertial>
    <visual>
      <origin rpy="0 0 0" xyz="0 0 0"/>
      <geometry>
        <box size="0.3 0.3 0.3"/>
      </geometry>
      <material name="grey">
        <color rgba=".8 .8 .8 1"/>
      </material>
    </visual>
    <!--<collision>
        <origin xyz="0 0 0" rpy="0 0 0"/>
        <geometry>
           <sphere radius="0"/>
        </geometry>
      </collision>-->
  </link>
  <joint name="Z" type="prismatic">
    <parent link="base_link"/>
    <child link="Z_link"/>
    <axis xyz="0 0 1"/>
    <limit effort="200" lower="-100" upper="100" velocity="30.0"/>
  </joint>
  <joint name="X" type="prismatic">
    <parent link="Z_link"/>
    <child link="X_link"/>
    <axis xyz="1 0 0"/>
    <limit effort="200" lower="-100" upper="100" velocity="30.0"/>
  </joint>
  <joint name="Theta" type="continuous">
    <parent link="X_link"/>
    <child link="final_link"/>
    <axis xyz="0 1 0"/>
  </joint>
  <transmission name="Z_act" type="SimpleTransmission">
    <actuator name="Z_tranny"/>
    <joint name="Z"/>
    <mechanicalReduction>1</mechanicalReduction>
  </transmission>
  <transmission name="X_act" type="SimpleTransmission">
    <actuator name="X_tranny"/>
    <joint name="X"/>
    <mechanicalReduction>1</mechanicalReduction>
  </transmission>
  <transmission name="Theta_act" type="SimpleTransmission">
    <actuator name="Theta_tranny"/>
    <joint name="Theta"/>
    <mechanicalReduction>1</mechanicalReduction>
  </transmission>
</robot>

