<?xml version="1.0"?>

<robot name="CompassGait" xmlns:xacro="http://ros.org/wiki/xacro">

  <xacro:property name="mh" value="10" />
  <xacro:property name="m" value="2.5" />
  <xacro:property name="a" value=".5" />

  <xacro:macro name="leg" params="lr cname color">
    <link name="${lr}_leg">
      <inertial>
	<origin  xyz = "0 0 ${-(a)/2}"/>
	<mass value = "${m}"/>
	<inertia ixx="0.01"  ixy="0"  ixz="0" iyy="0.01" iyz="0" izz="0.01" />
      </inertial>
      <visual>
      	<origin xyz="0 0 ${-(a)/2}" />
	      <geometry>
	        <cylinder radius="0.0075" length="${a}"/>
      	</geometry>
        <material name="${cname}">
          <color rgba="${color}" />
        </material>
      </visual>
      <collision>
	      <origin xyz="0 0 ${-a}" />
	      <geometry>
	        <sphere radius="0.01"/>
	      </geometry>
      </collision>
    </link>


  
  </xacro:macro>

  
  <!--<link name="world">
  </link>-->
  <link name="hip">
    <inertial>
      <origin  xyz = "0.0 0.00 0"/>
      <mass value="${mh}" />
      <inertia ixx="0.01"  ixy="0"  ixz="0" iyy="0.01" iyz="0" izz="0.01" />
    </inertial>
    <visual>    
      <geometry>
        <sphere radius="${.005*mh}" />
      </geometry>
      <material name="green">
        <color rgba="0 1 0 1" />
      </material>
    </visual>
  </link>

<link name="left_foot">
      <inertial>
	<origin  xyz = "0 0 ${-(a)}"/>
	<mass value = "${m}"/>
	<inertia ixx="0.01"  ixy="0"  ixz="0" iyy="0.01" iyz="0" izz="0.01" />
      </inertial>
      <visual>
      	<origin xyz="0 0 ${-(a)}" />
	      <geometry>
	        <sphere radius="0.01"/>
      	</geometry>
      </visual>
      <collision>
	      <origin xyz="0 0 ${-a}" />
	      <geometry>
	        <sphere radius="0.01"/>
	      </geometry>
      </collision>
</link>

<link name="right_foot">
      <inertial>
	<origin  xyz = "0 0 0"/>
	<mass value = "${m}"/>
	<inertia ixx="0.01"  ixy="0"  ixz="0" iyy="0.01" iyz="0" izz="0.01" />
      </inertial>
      <visual>
      	<origin xyz="0 0 0" />
	      <geometry>
	        <sphere radius="0.01"/>
      	</geometry>
      </visual>
      <collision>
	      <origin xyz="0 0 0" />
	      <geometry>
	        <sphere radius="0.01"/>
	      </geometry>
      </collision>
</link>

  <joint name="right_foot_joint" type="fixed">
    <parent link="right_leg" />
    <child link="right_foot" /> 
  </joint>

  <joint name="left_foot_joint" type="fixed">
    <parent link="hip" />
    <child link="left_foot" /> 
  </joint>
  
  <!--<joint name="floating_base" type="planar">
    <parent link="world" />
    <child link="hip" />
    <axis xyz="0 1 0" />    
  </joint>-->

  <xacro:leg lr="left" cname="red" color="1 0 0 1" />
  <xacro:leg lr="right"  cname="blue" color="0 0 1 1" />

  <joint name="left_leg_weld" type="fixed">
    <parent link="hip" />
    <child link="left_leg" /> 
  </joint>
  
 

  <joint name="hip_pin" type="continuous">
    <parent link="hip" />
    <child link="right_leg" />
    <axis xyz="0 1 0"/> 
  </joint>

 

  <transmission type="SimpleTransmission" name="hip_trans">
    <actuator name="hip_torque" />
    <joint name="hip_pin" />
    <mechanicalReduction>1</mechanicalReduction>
  </transmission>

<gazebo>
    <!-- robot model offset -->
    <pose>0 0 1 0 0 0</pose>
  </gazebo>
  <gazebo>
    <plugin filename="libjoint_actuation_plugin.so" name="joint_torque_controller">
      <alwaysOn>true</alwaysOn>
      <topicName>actuator_cmd</topicName>
    </plugin>
    <plugin filename="libgazebo_ros_pub_robot_state.so" name="gazebo_ros_pub_robot_controller">
      <alwaysOn>true</alwaysOn>
      <updateRate>100.0</updateRate>
      <topicName>true_robot_state</topicName>
    </plugin>
  </gazebo>

</robot>
