<?xml version="1.0" ?>
<!-- =================================================================================== -->
<!-- |    This document was autogenerated by xacro from compass_gait.xacro             | -->
<!-- |    EDITING THIS FILE BY HAND IS NOT RECOMMENDED                                 | -->
<!-- =================================================================================== -->
<robot name="CompassGait" xmlns:xacro="http://ros.org/wiki/xacro">
  <!--<link name="world">
  </link>-->
  <link name="hip">
    <inertial>
      <origin xyz="0.0 0.00 0"/>
      <mass value="10"/>
      <inertia ixx="0" ixy="0" ixz="0" iyy="0" iyz="0" izz="0"/>
    </inertial>
    <visual>
      <geometry>
        <sphere radius="0.05"/>
      </geometry>
      <material name="green">
        <color rgba="0 1 0 1"/>
      </material>
    </visual>
  </link>
  <link name="left_leg">
    <inertial>
      <origin xyz="0 0 -0.25"/>
      <mass value="2.5"/>
      <inertia ixx="0" ixy="0" ixz="0" iyy="0" iyz="0" izz="0"/>
    </inertial>
    <visual>
      <origin xyz="0 0 -0.25"/>
      <geometry>
        <cylinder length="0.5" radius="0.0075"/>
      </geometry>
      <material name="red">
        <color rgba="1 0 0 1"/>
      </material>
    </visual>
  </link>
  <link name="left_toe">
    <inertial>
      <mass value="1"/>
      <inertia ixx="0" ixy="0" ixz="0" iyy="0" iyz="0" izz="0"/>
    </inertial>
    <visual>
      <geometry>
        <cylinder length="0.1" radius="0.0025"/>
      </geometry>
    </visual>
    <collision>
      <origin xyz="0 0 -0.05"/>
      <geometry>
        <sphere radius="0"/>
      </geometry>
    </collision>
  </link>
  <joint name="left_toe_joint" type="prismatic">
    <origin xyz="0 0 -0.5"/>
    <parent link="left_leg"/>
    <child link="left_toe"/>
    <axis xyz="0 0 1"/>
    <limit effort="1000" lower="-0.05" upper="0.05" velocity="1000"/>
  </joint>
  <transmission name="left_toe_trans" type="SimpleTransmission">
    <actuator name="left_toe_torque"/>
    <joint name="left_toe_joint"/>
    <mechanicalReduction>1</mechanicalReduction>
  </transmission>
  <link name="right_leg">
    <inertial>
      <origin xyz="0 0 -0.25"/>
      <mass value="2.5"/>
      <inertia ixx="0" ixy="0" ixz="0" iyy="0" iyz="0" izz="0"/>
    </inertial>
    <visual>
      <origin xyz="0 0 -0.25"/>
      <geometry>
        <cylinder length="0.5" radius="0.0075"/>
      </geometry>
      <material name="blue">
        <color rgba="0 0 1 1"/>
      </material>
    </visual>
  </link>
  <link name="right_toe">
    <inertial>
      <mass value="1"/>
      <inertia ixx="0" ixy="0" ixz="0" iyy="0" iyz="0" izz="0"/>
    </inertial>
    <visual>
      <geometry>
        <cylinder length="0.1" radius="0.0025"/>
      </geometry>
    </visual>
    <collision>
      <origin xyz="0 0 -0.05"/>
      <geometry>
        <sphere radius="0"/>
      </geometry>
    </collision>
  </link>
  <joint name="right_toe_joint" type="prismatic">
    <origin xyz="0 0 -0.5"/>
    <parent link="right_leg"/>
    <child link="right_toe"/>
    <axis xyz="0 0 1"/>
    <limit effort="1000" lower="-0.05" upper="0.05" velocity="1000"/>
  </joint>
  <transmission name="right_toe_trans" type="SimpleTransmission">
    <actuator name="right_toe_torque"/>
    <joint name="right_toe_joint"/>
    <mechanicalReduction>1</mechanicalReduction>
  </transmission>
  <joint name="leftLegWeld" type="fixed">
    <parent link="hip"/>
    <child link="left_leg"/>
  </joint>
  <joint name="hipPin" type="continuous">
    <parent link="hip"/>
    <child link="right_leg"/>
    <axis xyz="0 1 0"/>
  </joint>
  <transmission name="hip_trans" type="SimpleTransmission">
    <actuator name="hip_torque"/>
    <joint name="hipPin"/>
    <mechanicalReduction>1</mechanicalReduction>
  </transmission>
  <gazebo>
    <!-- robot model offset -->
    <pose>0 0 0.6 0 0 0</pose>
  </gazebo>
  <gazebo>
    <plugin filename="libjoint_actuation_plugin.so" name="joint_torque_controller">
      <alwaysOn>true</alwaysOn>
      <topicName>actuator_cmd</topicName>
    </plugin>
    <plugin filename="libgazebo_ros_pub_robot_state.so" name="gazebo_ros_pub_robot_controller">
      <alwaysOn>true</alwaysOn>
      <updateRate>100.0</updateRate>
      <topicName>true_robot_state</topicName>
    </plugin>
  </gazebo>
</robot>

