<?xml version="1.0" ?>
<!-- =================================================================================== -->
<!-- |    This document was autogenerated by xacro from compass_gait.xacro             | -->
<!-- |    EDITING THIS FILE BY HAND IS NOT RECOMMENDED                                 | -->
<!-- =================================================================================== -->
<robot name="CompassGait" xmlns:controller="http://playerstage.sourceforge.net/gazebo/xmlschema/#controller" xmlns:interface="http://playerstage.sourceforge.net/gazebo/xmlschema/#interface" xmlns:sensor="http://playerstage.sourceforge.net/gazebo/xmlschema/#sensor" xmlns:xacro="http://www.ros.org/wiki/xacro">

  <link name="hip">
    <inertial>
      <mass value="10"/>
      <inertia ixx="0" ixy="0" ixz="0" iyy="0" iyz="0" izz="0"/>
    </inertial>
    <visual>
      <geometry>
        <sphere radius="0.05"/>
      </geometry>
      <material name="green">
        <color rgba="0 1 0 1"/>
      </material>
    </visual>
  </link>

  <link name="left_leg">
    <visual>
      <origin xyz="0 0 -0.25"/>
      <geometry>
        <cylinder length="0.5" radius="0.0075"/>
      </geometry>
      <material name="red">
        <color rgba="1 0 0 1"/>
      </material>
    </visual>
    <collision>
      <origin xyz="0 0 -0.5"/>
      <geometry>
        <sphere radius="0.01"/>
      </geometry>
    </collision>
   </link>
  <link name="left_leg_mass">
    <visual>
      <origin xyz="0 0 -0.5"/>
      <geometry>
        <sphere radius="0.025"/>
      </geometry>
      <material name="red">
        <color rgba="1 0 0 1"/>
      </material>
    </visual>
    <inertial>
      <origin xyz="0 0 -0.5"/>
      <mass value="2.5"/>
      <inertia ixx="0" ixy="0" ixz="0" iyy="0" iyz="0" izz="0"/>
    </inertial>
  </link>

  <link name="right_leg">
    <visual>
      <origin xyz="0 0 -0.25"/>
      <geometry>
        <cylinder length="0.5" radius="0.0075"/>
      </geometry>
      <material name="blue">
        <color rgba="0 0 1 1"/>
      </material>
    </visual>
    <collision>
      <origin xyz="0 0 -0.5"/>
      <geometry>
        <sphere radius="0.01"/>
      </geometry>
    </collision>
  </link>
  <link name="right_leg_mass">
    <visual>
      <origin xyz="0 0 -0.5"/>
      <geometry>
        <sphere radius="0.025"/>
      </geometry>
      <material name="blue">
        <color rgba="0 0 1 1"/>
      </material>
    </visual>
    <inertial>
      <origin xyz="0 0 -0.5"/>
      <mass value="2.5"/>
      <inertia ixx="0" ixy="0" ixz="0" iyy="0" iyz="0" izz="0"/>
    </inertial>
  </link>
  <joint name="right_leg_mass_weld" type="fixed">
    <parent link="right_leg"/>
    <child link="right_leg_mass"/>
  </joint>
 <!-- <joint name="left_leg_weld" type="fixed">
    <parent link="hip"/>
    <child link="left_leg"/>
  </joint> -->
  <joint name="hip_pin" type="continuous">
    <parent link="hip"/>
    <child link="right_leg"/>
    <axis xyz="0 1 0"/>
  </joint>
  <joint name="left_leg" type="fixed">
    <parent link="hip"/>
    <child link="left_leg"/>
    <origin rpy="0 0 0" xyz="0 0.0 0"/>
  </joint>
  <joint name="left_leg_mass_weld" type="fixed">
    <parent link="left_leg"/>
    <child link="left_leg_mass"/>
  </joint> 
  <transmission name="hip_trans" type="SimpleTransmission">
    <actuator name="hip_torque"/>
    <joint name="hip_pin"/>
    <mechanicalReduction>1</mechanicalReduction>
  </transmission>
<gazebo>
    <!-- robot model offset -->
    <pose>0 0 1 0 0 0</pose>
  </gazebo>
  <gazebo>
    <plugin filename="libjoint_actuation_plugin.so" name="joint_torque_controller">
      <alwaysOn>true</alwaysOn>
      <topicName>actuator_cmd</topicName>
    </plugin>
    <plugin filename="libgazebo_ros_pub_robot_state.so" name="gazebo_ros_pub_robot_controller">
      <alwaysOn>true</alwaysOn>
      <updateRate>100.0</updateRate>
      <topicName>true_robot_state</topicName>
    </plugin>
  </gazebo>
</robot>

