<?xml version="1.0" ?>
<robot name="hovering_atlas" xmlns:body="http://playerstage.sourceforge.net/gazebo/xmlschema/#body" xmlns:controller="http://playerstage.sourceforge.net/gazebo/xmlschema/#controller" xmlns:geom="http://playerstage.sourceforge.net/gazebo/xmlschema/#geom" xmlns:interface="http://playerstage.sourceforge.net/gazebo/xmlschema/#interface" xmlns:joint="http://playerstage.sourceforge.net/gazebo/xmlschema/#slider" xmlns:sensor="http://playerstage.sourceforge.net/gazebo/xmlschema/#sensor" xmlns:xacro="http://ros.org/wiki/xacro">  

  <material name="LightGrey">
    <color rgba="0.8 0.8 0.8 1.0"/>
  </material>
  <material name="Grey">
    <color rgba="0.6 0.6 0.6 1.0"/>
  </material>
  <material name="DarkGrey">
    <color rgba="0.3 0.3 0.3 1.0"/>
  </material>
  <material name="Black">
    <color rgba="0.1 0.1 0.1 1.0"/>
  </material>
<!--Superheavy base_link-->
<!-- <link name="base_link">
    <inertial>
      <origin rpy="0 0 0" xyz="0 0 0"/>
      <mass value="10000"/>
      <inertia ixx="10000" ixy="0" ixz="0" iyy="10000" iyz="0" izz="10000"/>
    </inertial>
   <visual>
      <origin rpy="0 0 0" xyz="0 0 0"/>
      <geometry>
        <box size="0.8 0.8 0.02"/>
      </geometry>
    </visual>
    <collision>
      <origin rpy="0 0 0" xyz="0 0 0"/>
      <geometry>
        <box size="0.8 0.8 0.02"/>
      </geometry>
    </collision>
</link>-->

<link name="Torso">
    <!-- assuming the rotational inertia of the torso is of a cuboid -->
    <inertial>
      <mass value="19.267"/>
      <inertia ixx="0.769042349872" ixy="0.0" ixz="0.0" iyy="0.418881944536" iyz="0.0" izz="0.452546488768"/>
    </inertial>
    <visual>
      <origin rpy="0 0 0" xyz="0.0 0.0 0.43927308"/>
      <geometry>
        <cylinder length="0.97854616" radius="0.025"/>
      </geometry>
      <material name="LightGrey"/>
    </visual>
    <collision>
      <origin rpy="0 0 0" xyz="0.0 0.0 0.43927308"/>
      <geometry>
        <box size=" 0.178562 0.4999736 0.97854616"/>
      </geometry>
    </collision>
  </link>

   <link name="NeckYaw_link">
    <inertial>
      <mass value="0.9"/>
      <inertia ixx="0.00530271247008" ixy="0.0" ixz="0.0" iyy="0.00530271247008" iyz="0.0" izz="0.00201768391825"/>
    </inertial>
  </link>
  <link name="NeckPitch_link">
    <inertial>
      <mass value="0.9"/>
      <inertia ixx="0.00530271247008" ixy="0.0" ixz="0.0" iyy="0.00530271247008" iyz="0.0" izz="0.00201768391825"/>
    </inertial>
    <visual>
      <origin rpy="1.57079632679 0 0" xyz="0 0 0.13749274"/>
      <geometry>
        <cylinder length="0.22141688" radius="0.06696075"/>
        <!--  <sphere radius="${(l_head/2)*height}"/>-->
      </geometry>
      <material name="LightGrey"/>
    </visual>
    <collision>
      <origin rpy="1.57 0 0" xyz="0 0 0.13749274"/>
      <geometry>
        <cylinder length="0.23927308" radius="0.06696075"/>
      </geometry>
    </collision>
  </link>
   <link name="LShoulderYaw_link">
    <inertial>
      <mass value="2.18522222222"/>
     <inertia ixx="0.0231667622255" ixy="0.0" ixz="0.0" iyy="0.0231667622255" iyz="0.0" izz="0.00217732727683"/>
    </inertial>
  </link>
  <link name="LShoulderPitch_link">
    <inertial>
      <mass value="2.18522222222"/>
      <inertia ixx="0.0231667622255" ixy="0.0" ixz="0.0" iyy="0.0231667622255" iyz="0.0" izz="0.00217732727683"/>
    </inertial>
  </link>
  <link name="LShoulderRoll_link">
    <inertial>
      <mass value="2.18522222222"/>
      <inertia ixx="0.0231667622255" ixy="0.0" ixz="0.0" iyy="0.0231667622255" iyz="0.0" izz="0.00217732727683"/>
    </inertial>
    <visual>
      <origin rpy="0 0 0" xyz="0 0 -0.17409795"/>
      <geometry>
        <cylinder length="0.3081959" radius="0.025"/>
      </geometry>
      <material name="LightGrey"/>
    </visual>
    <collision>
      <origin rpy="0 0 0" xyz="0 0 -0.17409795"/>
      <geometry>
        <cylinder length="0.3481959" radius="0.025"/>
      </geometry>
    </collision>
  </link>
  <link name="LElbowPitch_link">
    <inertial>
      <mass value="3.27783333333"/>
      <inertia ixx="0.0268028987778" ixy="0.0" ixz="0.0" iyy="0.0268028987778" iyz="0.0" izz="0.00326599091525"/>
    </inertial>
    <visual>
      <origin rpy="0 0 0" xyz="0 0 -0.1517777"/>
      <geometry>
        <cylinder length="0.2635554" radius="0.025"/>
      </geometry>
      <material name="LightGrey"/>
    </visual>
    <collision>
      <origin rpy="0 0 0" xyz="0 0 -0.1517777"/>
      <geometry>
        <cylinder length="0.3035554" radius="0.025"/>
      </geometry>
    </collision>
  </link>
  <link name="LWristYaw_link">
    <inertial>
      <mass value="1.0"/>
      <inertia ixx="0.0048720194876" ixy="0.0" ixz="0.0" iyy="0.0048720194876" iyz="0.0" izz="0.00199277424025"/>
    </inertial>
  </link>
  <link name="LWristRoll_link">
    <inertial>
      <mass value="1.0"/>
  <inertia ixx="0.0048720194876" ixy="0.0" ixz="0.0" iyy="0.0048720194876" iyz="0.0" izz="0.00199277424025"/>
    </inertial>
    <visual>
      <origin rpy="0 0 0" xyz="0 0 -0.076245974"/>
      <geometry>
        <cylinder length="0.112491948" radius="0.025"/>
      </geometry>
      <material name="LightGrey"/>
    </visual>
    <collision>
      <origin rpy="0 0 0" xyz="0 0 -0.076245974"/>
      <geometry>
        <cylinder length="0.152491948" radius="0.025"/>
      </geometry>
    </collision>
  </link>
  <link name="RShoulderYaw_link">
    <inertial>
      <mass value="2.18522222222"/>
      <inertia ixx="0.0231667622255" ixy="0.0" ixz="0.0" iyy="0.0231667622255" iyz="0.0" izz="0.00217732727683"/>
    </inertial>
  </link>
  <link name="RShoulderPitch_link">
    <inertial>
      <mass value="2.18522222222"/>
      <inertia ixx="0.0231667622255" ixy="0.0" ixz="0.0" iyy="0.0231667622255" iyz="0.0" izz="0.00217732727683"/>
    </inertial>
  </link>
  <link name="RShoulderRoll_link">
    <inertial>
      <mass value="2.18522222222"/>
      <inertia ixx="0.0231667622255" ixy="0.0" ixz="0.0" iyy="0.0231667622255" iyz="0.0" izz="0.00217732727683"/>
    </inertial>
    <visual>
      <origin rpy="0 0 0" xyz="0 0 -0.17409795"/>
      <geometry>
        <cylinder length="0.3081959" radius="0.025"/>
      </geometry>
      <material name="LightGrey"/>
    </visual>
    <collision>
      <origin rpy="0 0 0" xyz="0 0 -0.17409795"/>
      <geometry>
        <cylinder length="0.3481959" radius="0.025"/>
      </geometry>
    </collision>
  </link>
  <link name="RElbowPitch_link">
    <inertial>
      <mass value="3.27783333333"/>
      <inertia ixx="0.0268028987778" ixy="0.0" ixz="0.0" iyy="0.0268028987778" iyz="0.0" izz="0.00326599091525"/>
    </inertial>
    <visual>
      <origin rpy="0 0 0" xyz="0 0 -0.1517777"/>
      <geometry>
        <cylinder length="0.2635554" radius="0.025"/>
      </geometry>
      <material name="LightGrey"/>
    </visual>
    <collision>
      <origin rpy="0 0 0" xyz="0 0 -0.1517777"/>
      <geometry>
        <cylinder length="0.3035554" radius="0.025"/>
      </geometry>
    </collision>
  </link>
  <link name="RWristYaw_link">
    <inertial>
      <mass value="1.0"/>
   <inertia ixx="0.0048720194876" ixy="0.0" ixz="0.0" iyy="0.0048720194876" iyz="0.0" izz="0.00199277424025"/>
    </inertial>
  </link>
  <link name="RWristRoll_link">
    <inertial>
      <mass value="1.0"/>
     <inertia ixx="0.0048720194876" ixy="0.0" ixz="0.0" iyy="0.0048720194876" iyz="0.0" izz="0.00199277424025"/>
    </inertial>
    <visual>
      <origin rpy="0 0 0" xyz="0 0 -0.076245974"/>
      <geometry>
        <cylinder length="0.112491948" radius="0.025"/>
      </geometry>
      <material name="LightGrey"/>
    </visual>
    <collision>
      <origin rpy="0 0 0" xyz="0 0 -0.076245974"/>
      <geometry>
        <cylinder length="0.152491948" radius="0.025"/>
      </geometry>
    </collision>
  </link>

 <!-- Base and Wheels -->
  <link name="base">
    <inertial>
      <mass value="121.06"/>
      <inertia ixx="1.70235" ixy="0" ixz="0" iyy="1.70235" iyz="0" izz="0.5616"/>
    </inertial>
    <visual>
      <origin rpy="0 0 0" xyz="0 0 0"/>
      <geometry>
        <box size="0.4 0.4 0.3"/>
      </geometry>
      <material name="Lgrey">
        <color rgba=".6 .6 .6 1"/>
      </material>
    </visual>
    <collision>
      <origin rpy="0 0 0" xyz="0 0 0"/>
      <geometry>
        <box size="0.4 0.4 0.3"/>
      </geometry>
    </collision>
  </link>

   <link name="X_link">
    <inertial>
      <origin rpy="0 0 0" xyz="0 0 0"/>
      <mass value="121.06"/>
      <inertia ixx="1.70235" ixy="0" ixz="0" iyy="1.70235" iyz="0" izz="0.5616"/>
    </inertial>

  </link> 
 <link name="Y_link">
    <inertial>
        <origin rpy="0 0 0" xyz="0 0 0"/>
      <mass value="121.06"/>
      <inertia ixx="1.70235" ixy="0" ixz="0" iyy="1.70235" iyz="0" izz="0.5616"/>
    </inertial>
  </link> 

  <link name="world"/>
 <!-- JOINTS -->
<!--<gazebo reference="base">
    <turnGravityOff>true</turnGravityOff>
</gazebo>-->
<!--<gazebo reference="X_link">
    <turnGravityOff>true</turnGravityOff>
</gazebo>
<gazebo reference="Y_link">
    <turnGravityOff>true</turnGravityOff>
</gazebo>-->
<!--  <joint name="base_Joint" type="fixed">
    <parent link="world"/>
    <child link="base_link"/>
    <origin rpy="0 0 0" xyz="0 0 0.0"/>
  </joint>-->
  <joint name="X_Joint" type="prismatic">
    <parent link="world"/>
    <child link="X_link"/>
    <origin rpy="0 0 0" xyz="0 0 0.5"/>
     <axis xyz="1 0 0"/>
    <dynamics damping="0.0" friction="0"/>
    <limit effort="200" lower="-150" upper="150" velocity="30.0"/>
  </joint>
  
  <joint name="Y_Joint" type="prismatic">
    <parent link="X_link"/>
    <child link="Y_link"/>
    <origin rpy="0 0 0" xyz="0 0 0.0"/>
     <axis xyz="0 1 0"/>
    <dynamics damping="0.0" friction="0"/>
    <limit effort="200" lower="-150" upper="150" velocity="30.0"/>
  </joint>
    
  <joint name="Theta_Joint" type="continuous">
    <parent link="Y_link"/>
    <child link="base"/>
    <axis xyz="0 0 1"/>
    <origin rpy="0 0 0" xyz="0 0 0.17"/>
    <dynamics damping="0.0" friction="0"/> 
  </joint>


  <joint name="Base_Torso_joint" type="fixed">
    <child link="Torso"/>
    <parent link="base"/>
    <origin rpy="0 0 0" xyz="0 0 0.15"/>
  </joint>

  <joint name="NeckYaw" type="revolute">
    <parent link="Torso"/>
    <child link="NeckYaw_link"/>
    <origin rpy="0 0 0" xyz="0 0 0.87854616"/>
    <axis xyz="0 0 1"/>
    <limit effort="54" lower="-1.5707963259" upper="1.5707963259" velocity="3"/>
    <dynamics damping="1" friction="10"/>
  </joint>
  <joint name="NeckPitch" type="revolute">
    <parent link="NeckYaw_link"/>
    <child link="NeckPitch_link"/>
    <origin rpy="0 0 0" xyz="0 0 0"/>
    <axis xyz="0 1 0"/>
    <limit effort="25" lower="-0.78539816295" upper="0.78539816295" velocity="3"/>
      <dynamics damping="1" friction="10"/>
  </joint>
  <joint name="LShoulderRoll" type="revolute">
    <parent link="LShoulderPitch_link"/>
    <child link="LShoulderRoll_link"/>
    <origin rpy="0 0 0" xyz="0 0 0"/>
    <axis xyz="1 0 0"/>
    <limit effort="110" lower="0.0" upper="2.00712863865" velocity="3"/>
    <dynamics damping="1" friction="10"/>
  </joint>
  <joint name="RShoulderRoll" type="revolute">
    <parent link="RShoulderPitch_link"/>
    <child link="RShoulderRoll_link"/>
    <origin rpy="0 0 0" xyz="0 0 0"/>
    <axis xyz="1 0 0"/>
    <limit effort="110" lower="-2.00712863865" upper="-0.0" velocity="3"/>
    <dynamics damping="1" friction="10"/>
  </joint>
  <joint name="LShoulderYaw" type="revolute">
    <parent link="base"/>
    <child link="LShoulderYaw_link"/>
    <origin rpy="0 0 0" xyz="0 0.2410587 0.96426384"/>
    <axis xyz="0 0 1"/>
    <limit effort="80" lower="-0.6981317004" upper="1.745329251" velocity="3"/>
    <dynamics damping="1" friction="10"/>
  </joint>
  <joint name="LShoulderPitch" type="revolute">
    <parent link="LShoulderYaw_link"/>
    <child link="LShoulderPitch_link"/>
    <origin rpy="0 0 0" xyz="0 0 0"/>
    <axis xyz="0 1 0"/>
    <limit effort="110" lower="-1.5707963259" upper="0.8726646255" velocity="3"/>
    <dynamics damping="1" friction="10"/>
  </joint>
  <joint name="LElbowPitch" type="revolute">
    <parent link="LShoulderRoll_link"/>
    <child link="LElbowPitch_link"/>
    <origin rpy="0 0 0" xyz="0 0 -0.3481959"/>
    <axis xyz="0 1 0"/>
    <limit effort="100" lower="-2.35619448885" upper="0.0" velocity="3"/>
    <dynamics damping="1" friction="10"/>
  </joint>
  <joint name="LWristYaw" type="revolute">
    <parent link="LElbowPitch_link"/>
    <child link="LWristYaw_link"/>
    <origin rpy="0 0 0" xyz="0 0 -0.3035554"/>
    <axis xyz="0 0 1"/>
    <limit effort="15" lower="-1.48352986335" upper="1.48352986335" velocity="3"/>
    <dynamics damping="1" friction="10"/>
  </joint>
  <joint name="RShoulderYaw" type="revolute">
    <parent link="base"/>
    <child link="RShoulderYaw_link"/>
    <origin rpy="0 0 0" xyz="0 -0.2410587 0.96426384"/>
    <axis xyz="0 0 1"/>
    <limit effort="80" lower="-0.6981317004" upper="1.745329251" velocity="3"/>
    <dynamics damping="1" friction="10"/>
  </joint>
  <joint name="RShoulderPitch" type="revolute">
    <parent link="RShoulderYaw_link"/>
    <child link="RShoulderPitch_link"/>
    <origin rpy="0 0 0" xyz="0 0 0"/>
    <axis xyz="0 1 0"/>
    <limit effort="110" lower="-1.5707963259" upper="0.8726646255" velocity="3"/>
    <dynamics damping="1" friction="10"/>
  </joint>
  <joint name="RElbowPitch" type="revolute">
    <parent link="RShoulderRoll_link"/>
    <child link="RElbowPitch_link"/>
    <origin rpy="0 0 0" xyz="0 0 -0.3481959"/>
    <axis xyz="0 1 0"/>
    <limit effort="100" lower="-2.35619448885" upper="0.0" velocity="3"/>
    <dynamics damping="1" friction="10"/>
  </joint>
  <joint name="RWristYaw" type="revolute">
    <parent link="RElbowPitch_link"/>
    <child link="RWristYaw_link"/>
    <origin rpy="0 0 0" xyz="0 0 -0.3035554"/>
    <axis xyz="0 0 1"/>
    <limit effort="15" lower="-1.48352986335" upper="1.48352986335" velocity="3"/>
    <dynamics damping="1" friction="10"/>
  </joint>
  <joint name="LWristRoll" type="revolute">
    <parent link="LWristYaw_link"/>
    <child link="LWristRoll_link"/>
    <origin rpy="0 0 0" xyz="0 0 0"/>
    <axis xyz="1 0 0"/>
    <limit effort="30" lower="-0.5235987753" upper="1.0471975506" velocity="3"/>
    <dynamics damping="1" friction="10"/>
  </joint>
  <joint name="RWristRoll" type="revolute">
    <parent link="RWristYaw_link"/>
    <child link="RWristRoll_link"/>
    <origin rpy="0 0 0" xyz="0 0 0"/>
    <axis xyz="1 0 0"/>
    <limit effort="30" lower="-1.0471975506" upper="0.5235987753" velocity="3"/>
    <dynamics damping="1" friction="10"/>
  </joint>

  <gazebo>

    <controller:planar_hover_plugin name="planar_hover_controller" plugin="libplanar_hover_plugin_pre_fuerte.so">
        <alwaysOn>true</alwaysOn>
	<update>100</update>
	<updateRate>100.0</updateRate>
        <YJoint>Y_Joint</YJoint>
        <XJoint>X_Joint</XJoint>
        <ThetaJoint>Theta_Joint</ThetaJoint>
	<MovingBase>base</MovingBase>
        <torque>300</torque>
        <interface:position name="position_iface_0"/>
        <topicName>cmd_vel</topicName>
      </controller:planar_hover_plugin> 


   <!-- <controller:joint_actuation_plugin name="joint_torque_controller" plugin="libjoint_actuation_plugin.so">
       <alwaysOn>true</alwaysOn>
       <topicName>actuator_cmd</topicName>
    </controller:joint_actuation_plugin>-->


    <controller:gazebo_ros_pub_robot_state name="gazebo_ros_pub_robot_controller" plugin="libgazebo_ros_pub_robot_state_pre_fuerte.so">
     	<alwaysOn>true</alwaysOn>
     	<updateRate>100.0</updateRate>
      	 <topicName>true_robot_state</topicName>
     </controller:gazebo_ros_pub_robot_state>      
   <!--     zero gravity-->
  <!--<enableGravity>false</enableGravity>    -->
   </gazebo>


</robot>

