<?xml version="1.0"?>
<!--
   Aldebaran Robotics Romeo URDF model

   FIXME: fill missing data: sole, gripper and sensors
  -->
<robot xmlns:xacro="http://ros.org/wiki/xacro" name="romeo">

  <link name="base_link">
    <!-- dummy inertial -->
     <inertial>
      <origin xyz="0 0 0" rpy="0 0 0"/>
      <mass value="0.01"/>
      <inertia ixx="1"  ixy="0"  ixz="0" iyy="1" iyz="0" izz="1" />
    </inertial> 
</link>

  <link name="body">
    <inertial>
      <origin xyz="0.00932 0.0005 -0.2119" rpy="0 0 0"/>
      <mass value="4.16277"/>
      <inertia ixx="0.24187936706" ixy="-6.889635e-05" ixz="0.00282915469" iyy="0.23816771319" iyz="0.00030625215" izz="0.02147385599" />
    </inertial>
  </link>

  <link name="torso">
    <inertial>
      <origin xyz="0.0023 0.00038 -0.04854" rpy="0 0 0"/>
      <mass value="9.9216"/>
      <inertia ixx="0.12933235299" ixy="-0.00035965149" ixz="0.00283888003" iyy="0.12683108985" iyz="-0.00200842624" izz="0.11062739082" />
    </inertial>
    <visual>
      <origin xyz="0 0 0" rpy="0 0 0" />
      <geometry>
	<mesh filename="package://romeo_description/meshes/Torso.dae" />
      </geometry>
    </visual>
     
     <collision>
    	<origin xyz="0 0 0" rpy="0 0 0" />
 	<geometry>
	<mesh filename="package://romeo_description/meshes/Torso.dae" />
 	</geometry>
      </collision>
   
  </link>

  <link name="NeckYaw_link">
    <inertial>
      <origin xyz="0 -0.00183 -0.03074" rpy="0 0 0"/>
      <mass value="0.51016"/>
      <inertia ixx="0.00122158912" ixy="-8.014e-08" ixz="1.145e-08" iyy="0.00124607826" iyz="-1.84095e-06" izz="0.00018796505" />
    </inertial>
  </link>

  <link name="NeckPitch_link">
    <inertial>
      <origin xyz="-0.00472 -0.00054 0.04432" rpy="0 0 0"/>
      <mass value="0.23875"/>
      <inertia ixx="0.0008660225" ixy="-1.57263e-06" ixz="6.138255e-05" iyy="0.00081828666" iyz="9.69515e-06" izz="0.00023891895" />
    </inertial>
    <visual>
      <origin xyz="0 0 0" rpy="0 0 0" />
      <geometry>
	<mesh filename="package://romeo_description/meshes/NeckPitch.dae" />
      </geometry>
    </visual>
    <collision>
      <origin xyz="0 0 0" rpy="0 0 0" />
      <geometry>
	<mesh filename="package://romeo_description/meshes/NeckPitch.dae" />
      </geometry>
    </collision>
  </link>

  <link name="HeadPitch_link">
    <inertial>
      <origin xyz="0.00137 0.00027 -0.00641" rpy="0 0 0"/>
      <mass value="0.13981"/>
      <inertia ixx="3.89601e-05" ixy="-3.814e-08" ixz="-2.29622e-06" iyy="7.254653e-05" iyz="-6.46e-09" izz="5.376501e-05" />
    </inertial>
  </link>

  <link name="HeadRoll_link">
    <inertial>
      <origin xyz="0.01617 0.00168 0.0757" rpy="0 0 0"/>
      <mass value="1.41282"/>
      <inertia ixx="0.01490874108" ixy="-5.142093e-05" ixz="-0.00068489344" iyy="0.01731891079" iyz="-0.00019152738" izz="0.00735474589" />
    </inertial>
    <visual>
      <origin xyz="0 0 0" rpy="0 0 0" />
      <geometry>
	<mesh filename="package://romeo_description/meshes/HeadRoll.dae" />
      </geometry>
    </visual>
    <collision>
     <origin xyz="0 0 0" rpy="0 0 0" />
      <geometry>
	<mesh filename="package://romeo_description/meshes/HeadRoll.dae" />
      </geometry>
    </collision>
  </link>


  <link name="LShoulderPitch_link">
    <inertial>
      <origin xyz="0.00149 -0.03299 0.00018" rpy="0 0 0"/>
      <mass value="0.69402"/>
      <inertia ixx="0.00201004114" ixy="2.37595e-06" ixz="-2.16793e-06" iyy="0.00057062588" iyz="8.27832e-06" izz="0.00194067879" />
    </inertial>
  </link>

  <link name="LShoulderYaw_link">
    <inertial>
      <origin xyz="0.09367 0.01373 0.00103" rpy="0 0 0"/>
      <mass value="0.57151"/>
      <inertia ixx="0.00074281758" ixy="-0.00061767526" ixz="-7.28438e-05" iyy="0.00650202304" iyz="-1.251569e-05" izz="0.00664433886" />
    </inertial>

    <visual>
      <origin xyz="0 0 0" rpy="0 0 0" />
      <geometry>
	<mesh filename="package://romeo_description/meshes/LShoulderYaw.dae" />
      </geometry>
    </visual>

    <collision>
      <origin xyz="0 0 0" rpy="0 0 0" />
      <geometry>
	<mesh filename="package://romeo_description/meshes/LShoulderYaw.dae" />
      </geometry>
    </collision>
  </link>

  <link name="LElbowRoll_link">
    <inertial>
      <origin xyz="-0.02231 -0.0024 0" rpy="0 0 0"/>
      <mass value="0.39848"/>
      <inertia ixx="0.00017900324" ixy="-2.25555e-06" ixz="1.376e-08" iyy="0.00080432225" iyz="8.007e-08" izz="0.00077956048" />
    </inertial>
  </link>

  <link name="LElbowYaw_link">
    <inertial>
      <origin xyz="0.06738 0.01043 -0.00031" rpy="0 0 0"/>
      <mass value="0.31265"/>
      <inertia ixx="0.00037509574" ixy="-0.00022528338" ixz="2.58073e-06" iyy="0.00209727597" iyz="2.74613e-06" izz="0.00211064798" />
    </inertial>
    <visual>
      <origin xyz="0 0 0" rpy="0 0 0" />
      <geometry>
	<mesh filename="package://romeo_description/meshes/LElbowYaw.dae" />
      </geometry>
    </visual>
      <collision>
      <origin xyz="0 0 0" rpy="0 0 0" />
      <geometry>
	<mesh filename="package://romeo_description/meshes/LElbowYaw.dae" />
      </geometry>
      </collision>
  </link>

  <link name="LWristRoll_link">
    <inertial>
      <origin xyz="-0.0593 -5e-05 -0.00069" rpy="0 0 0"/>
      <mass value="0.17563"/>
      <inertia ixx="6.721454e-05" ixy="-6.373e-07" ixz="-1.358095e-05" iyy="0.00085119568" iyz="-2.443e-08" izz="0.00084034753" />
    </inertial>
    <visual>
      <origin xyz="0 0 0" rpy="0 0 0" />
      <geometry>
	<mesh filename="package://romeo_description/meshes/LWristRoll.dae" />
      </geometry>
    </visual>

    <collision>
      <origin xyz="0 0 0" rpy="0 0 0" />
      <geometry>
	<mesh filename="package://romeo_description/meshes/LWristRoll.dae" />
      </geometry>
    </collision>
  </link>

  <link name="LWristYaw_link">
    <inertial>
      <origin xyz="-0.00746 -0.00016 -0.00022" rpy="0 0 0"/>
      <mass value="0.07595"/>
      <inertia ixx="1.454017e-05" ixy="-4.157e-08" ixz="7.674e-08" iyy="3.919069e-05" iyz="3.08e-09" izz="3.817871e-05" />
    </inertial>
    <visual>
      <origin xyz="0 0 0" rpy="0 0 0" />
      <geometry>
	<mesh filename="package://romeo_description/meshes/WristYaw.dae" />
      </geometry>
    </visual>
     <collision>
      <origin xyz="0 0 0" rpy="0 0 0" />
      <geometry>
	<mesh filename="package://romeo_description/meshes/WristYaw.dae" />
      </geometry>
     </collision>
  </link>

  <link name="l_wrist">
    <inertial>
      <origin xyz="0.06987 -0.00381 -0.00165" rpy="0 0 0"/>
      <mass value="0.16569"/>
      <inertia ixx="0.00011252888" ixy="4.725831e-05" ixz="1.704036e-05" iyy="0.00107981778" iyz="-1.54761e-05" izz="0.00115367043" />
    </inertial>
    <visual>
      <origin xyz="0 0 0" rpy="0 0 0" />
      <geometry>
	<mesh filename="package://romeo_description/meshes/LHand.dae" />
      </geometry>
    </visual>

    <collision>
      <origin xyz="0 0 0" rpy="0 0 0" />
      <geometry>
	<mesh filename="package://romeo_description/meshes/LHand.dae" />
      </geometry>
    </collision>
  </link>

  <link name="RShoulderPitch_link">
    <inertial>
      <origin xyz="0.00149 0.03299 -0.00018" rpy="0 0 0"/>
      <mass value="0.69402"/>
      <inertia ixx="0.00201004114" ixy="-2.37595e-06" ixz="2.16793e-06" iyy="0.00057062588" iyz="8.27832e-06" izz="0.00194067879" />
    </inertial>
  </link>

  <link name="RShoulderYaw_link">
    <inertial>
      <origin xyz="0.0937 -0.01373 -0.00069" rpy="0 0 0"/>
      <mass value="0.57071"/>
      <inertia ixx="0.00074235595" ixy="0.00061720176" ixz="5.985213e-06" iyy="0.00649988502" iyz="-1.074174e-06" izz="0.000664209089" />
    </inertial>

    <visual>
      <origin xyz="0 0 0" rpy="0 0 0" />
      <geometry>
	<mesh filename="package://romeo_description/meshes/RShoulderYaw.dae" />
      </geometry>
    </visual>

    <collision>
      <origin xyz="0 0 0" rpy="0 0 0" />
      <geometry>
	<mesh filename="package://romeo_description/meshes/RShoulderYaw.dae" />
      </geometry>
    </collision>
  </link>

  <link name="RElbowRoll_link">
    <inertial>
      <origin xyz="-0.02231 -0.0024 0" rpy="0 0 0"/>
      <mass value="0.39848"/>
      <inertia ixx="0.00017900324" ixy="-2.25555e-06" ixz="1.376e-08" iyy="0.00080432225" iyz="8.007e-08" izz="0.00077956048" />
    </inertial>
  </link>

  <link name="RElbowYaw_link">
    <inertial>
      <origin xyz="0.06753 -0.00889 0.00022" rpy="0 0 0"/>
      <mass value="0.31403"/>
      <inertia ixx="0.00036672778" ixy="0.00018563123" ixz="-5.37905e-07" iyy="0.00211103842" iyz="3.1932e-07" izz="0.000211493035" />
    </inertial>
    <visual>
      <origin xyz="0 0 0" rpy="0 0 0" />
      <geometry>
	<mesh filename="package://romeo_description/meshes/RElbowYaw.dae" />
      </geometry>
    </visual>
    <collision>
      <origin xyz="0 0 0" rpy="0 0 0" />
      <geometry>
	<mesh filename="package://romeo_description/meshes/RElbowYaw.dae" />
  	</geometry>
    </collision>
  </link>



  <link name="RWristRoll_link">
    <inertial>
      <origin xyz="-0.0593 -5e-05 -0.00069" rpy="0 0 0"/>
      <mass value="0.17563"/>
      <inertia ixx="6.721454e-05" ixy="-6.373e-07" ixz="-1.358095e-05" iyy="0.00085119568" iyz="-2.443e-08" izz="0.00084034753" />
    </inertial>
    <visual>
      <origin xyz="0 0 0" rpy="0 0 0" />
      <geometry>
	<mesh filename="package://romeo_description/meshes/RWristRoll.dae" />
      </geometry>
    </visual>
     <collision>
      <origin xyz="0 0 0" rpy="0 0 0" />
      <geometry>
	<mesh filename="package://romeo_description/meshes/RWristRoll.dae" />
     </geometry>
     </collision>
  </link>


  <link name="RWristYaw_link">
    <inertial>
      <origin xyz="-0.00746 -0.00016 -0.00022" rpy="0 0 0"/>
      <mass value="0.07595"/>
      <inertia ixx="1.454017e-05" ixy="-4.157e-08" ixz="7.674e-08" iyy="3.919069e-05" iyz="3.08e-09" izz="3.817871e-05" />
    </inertial>
    <visual>
      <origin xyz="0 0 0" rpy="0 0 0" />
      <geometry>
	<mesh filename="package://romeo_description/meshes/WristYaw.dae" />
      </geometry>
    </visual>
    <collision>
      <origin xyz="0 0 0" rpy="0 0 0" />
      <geometry>
	<mesh filename="package://romeo_description/meshes/WristYaw.dae" />
      </geometry>
     </collision>
  </link>

  <link name="r_wrist">
    <inertial>
      <origin xyz="0.06987 0.00381 -0.00165" rpy="0 0 0"/>
      <mass value="0.16569"/>
      <inertia ixx="0.00011252888" ixy="0" ixz="0" iyy="0.00107981778" iyz="0" izz="0.00115367043" />
    </inertial>
    <visual>
      <origin xyz="0 0 0" rpy="0 0 0" />
      <geometry>
	<mesh filename="package://romeo_description/meshes/RHand.dae" />
      </geometry>
    </visual>
    <collision>
      <origin xyz="0 0 0" rpy="0 0 0" />
      <geometry>
	<mesh filename="package://romeo_description/meshes/RHand.dae" />
      </geometry>
     </collision>
  </link>



  <link name="LHipYaw_link">
    <inertial>
      <origin xyz="-0.00871 -0.00022 0.06319" rpy="0 0 0"/>
      <mass value="0.49477"/>
      <inertia ixx="0.00303667904" ixy="0" ixz="0" iyy="0.0034799778" iyz="0" izz="0.00062277265" />
    </inertial>
  </link>

  <link name="LHipRoll_link">
    <inertial>
      <origin xyz="0.00293 -0.00027 0.00011" rpy="0 0 0"/>
      <mass value="0.6607"/>
      <inertia ixx="0.00089862024" ixy="0" ixz="0" iyy="0.00050955901" iyz="0" izz="0.00093539188" />
    </inertial>
  </link>

  <link name="LHipPitch_link">
    <inertial>
      <origin xyz="-0.00971 0.00135 -0.15083" rpy="0 0 0"/>
      <mass value="4.33935"/>
      <inertia ixx="0.13289504951" ixy="0" ixz="0" iyy="0.13397739558" iyz="0" izz="0.01216872585" />
    </inertial>
    <visual>
      <origin xyz="0 0 0" rpy="0 0 0" />
      <geometry>
	<mesh filename="package://romeo_description/meshes/LHipPitch.dae" />
      </geometry>
    </visual>
    <collision>
      <origin xyz="0 0 0" rpy="0 0 0" />
      <geometry>
	<mesh filename="package://romeo_description/meshes/LHipPitch.dae" />
     </geometry>
    </collision>
  </link>

  <link name="LKneePitch_link">
    <inertial>
      <origin xyz="-0.00532 -0.00075 -0.12258" rpy="0 0 0"/>
      <mass value="2.61063"/>
      <inertia ixx="0.05491303061" ixy="0" ixz="0" iyy="0.05496634755" iyz="0" izz="0.00398481696" />
    </inertial>
    <visual>
      <origin xyz="0 0 0" rpy="0 0 0" />
      <geometry>
	<mesh filename="package://romeo_description/meshes/LKneePitch.dae" />
      </geometry>
    </visual>
    <collision>
      <origin xyz="0 0 0" rpy="0 0 0" />
      <geometry>
	<mesh filename="package://romeo_description/meshes/LKneePitch.dae" />
      </geometry>
    </collision>
  </link>

  <link name="LAnklePitch_link">
    <inertial>
      <origin xyz="0.00059 0.00051 0.00038" rpy="0 0 0"/>
      <mass value="0.5008"/>
      <inertia ixx="0.00042995195" ixy="0" ixz="0" iyy="0.00028145145" iyz="0" izz="0.00052766479" />
    </inertial>
  </link>

  <link name="l_ankle">
    <inertial>
      <origin xyz="0.02618 0.00259 -0.03683" rpy="0 0 0"/>
      <mass value="0.64224"/>
      <inertia ixx="0.00139908277" ixy="0" ixz="0" iyy="0.00349259103" iyz="0" izz="0.00266359477" />
    </inertial>
    <visual>
      <origin xyz="0 0 0" rpy="0 0 0" />
      <geometry>
	<mesh filename="package://romeo_description/meshes/LAnkleRoll.dae" />
      </geometry>
    </visual>
    <collision>
      <origin xyz="0 0 0" rpy="0 0 0" />
      <geometry>
	<mesh filename="package://romeo_description/meshes/LAnkleRoll.dae" />
      </geometry>
     </collision>
  </link>

  <link name="l_sole">
    <!-- dummy inertial -->
     <inertial>
      <origin xyz="0 0 0" rpy="0 0 0"/>
      <mass value="0.01"/>
      <inertia ixx="1"  ixy="0"  ixz="0" iyy="1" iyz="0" izz="1" />
    </inertial> 
</link>

  <link name="l_toe">
    <inertial>
      <origin xyz="0.01636 -0.00167 -0.00812" rpy="0 0 0"/>
      <mass value="0.2889"/>
      <inertia ixx="0.00025411726" ixy="0" ixz="0" iyy="0.00029543601" iyz="0" izz="0.0004436638" />
    </inertial>
    <visual>
      <origin xyz="0 0 0" rpy="0 0 0" />
      <geometry>
	<mesh filename="package://romeo_description/meshes/LToePitch.dae" />
      </geometry>
    </visual>
    <collision>
      <origin xyz="0 0 0" rpy="0 0 0" />
      <geometry>
	<mesh filename="package://romeo_description/meshes/LToePitch.dae" />
      </geometry>
    </collision>
  </link>

  <link name="RHipYaw_link">
    <inertial>
      <origin xyz="-0.00871 0.00022 0.06319" rpy="0 0 0"/>
      <mass value="0.49477"/>
      <inertia ixx="0.00303667904" ixy="0" ixz="0" iyy="0.0034799778" iyz="0" izz="0.00062277265" />
    </inertial>
  </link>

  <link name="RHipRoll_link">
    <inertial>
      <origin xyz="0.00293 -0.00027 0.00011" rpy="0 0 0"/>
      <mass value="0.6607"/>
      <inertia ixx="0.00089862024" ixy="0" ixz="0" iyy="0.00050955901" iyz="0" izz="0.00093539188" />
    </inertial>
  </link>

  <link name="RHipPitch_link">
    <inertial>
      <origin xyz="-0.00971 -0.00135 -0.15083" rpy="0 0 0"/>
      <mass value="4.33935"/>
      <inertia ixx="0.13289504951" ixy="0" ixz="0" iyy="0.13397739558" iyz="0" izz="0.01216872585" />
    </inertial>
    <visual>
      <origin xyz="0 0 0" rpy="0 0 0" />
      <geometry>
	<mesh filename="package://romeo_description/meshes/RHipPitch.dae" />
      </geometry>
    </visual>
    <collision>
      <origin xyz="0 0 0" rpy="0 0 0" />
      <geometry>
	<mesh filename="package://romeo_description/meshes/RHipPitch.dae" />
      </geometry>
    </collision>
  </link>


  <link name="RKneePitch_link">
    <inertial>
      <origin xyz="-0.00532 0.00075 -0.12258" rpy="0 0 0"/>
      <mass value="2.61063"/>
      <inertia ixx="0.05491303061" ixy="0" ixz="0" iyy="0.05496634755" iyz="0" izz="0.00398481696" />
    </inertial>
    <visual>
      <origin xyz="0 0 0" rpy="0 0 0" />
      <geometry>
	<mesh filename="package://romeo_description/meshes/RKneePitch.dae" />
      </geometry>
    </visual>
      <collision>
      <origin xyz="0 0 0" rpy="0 0 0" />
      <geometry>
	<mesh filename="package://romeo_description/meshes/RKneePitch.dae" />
  	</geometry>
      </collision>
  </link>



  <link name="RAnklePitch_link">
    <inertial>
      <origin xyz="0.00059 -0.00051 0.00038" rpy="0 0 0"/>
      <mass value="0.5008"/>
      <inertia ixx="0.00042995195" ixy="0" ixz="0" iyy="0.00028145145" iyz="0" izz="0.00052766479" />
    </inertial>
  </link>

  <link name="r_ankle">
    <inertial>
      <origin xyz="0.02618 -0.00259 -0.03683" rpy="0 0 0"/>
      <mass value="0.64224"/>
      <inertia ixx="0.00139908277" ixy="0" ixz="0" iyy="0.00349259103" iyz="0" izz="0.00266359477" />
    </inertial>
    <visual>
      <origin xyz="0 0 0" rpy="0 0 0" />
      <geometry>
	<mesh filename="package://romeo_description/meshes/RAnkleRoll.dae" />
      </geometry>
    </visual>
    <collision>
      <origin xyz="0 0 0" rpy="0 0 0" />
      <geometry>
	<mesh filename="package://romeo_description/meshes/RAnkleRoll.dae" />
      </geometry>
    </collision>
  </link>


  <link name="r_sole">
    <!-- dummy inertial -->
     <inertial>
      <origin xyz="0 0 0" rpy="0 0 0"/>
      <mass value="0.01"/>
      <inertia ixx="1"  ixy="0"  ixz="0" iyy="1" iyz="0" izz="1" />
    </inertial> 
</link>


  <link name="r_toe">
    <inertial>
      <origin xyz="0.01636 0.00167 -0.00812" rpy="0 0 0"/>
      <mass value="0.2889"/>
      <inertia ixx="0.00025411726" ixy="0" ixz="0" iyy="0.00029543601" iyz="0" izz="0.0004436638" />
    </inertial>
    <visual>
      <origin xyz="0 0 0" rpy="0 0 0" />
      <geometry>
	<mesh filename="package://romeo_description/meshes/RToePitch.dae" />
      </geometry>
    </visual>
    <collision>
      <origin xyz="0 0 0" rpy="0 0 0" />
      <geometry>
	<mesh filename="package://romeo_description/meshes/RToePitch.dae" />
      </geometry>
    </collision>
  </link>


  <!--   Joints following below -->

  <joint name="waist" type="fixed">
    <parent link="base_link"/>
    <child link="body"/>
    <origin xyz="0 0 0" rpy="0 0 0"/>
  </joint>
  <joint name="TrunkYaw" type="revolute">
    <origin xyz="-0 -0 0.2" rpy="0 0 0"/>
    <axis xyz="0 0 1"/>
    <parent link="body"/>
    <child link="torso"/>
    <limit effort="30" lower="-0.78539815" upper="0.78539815" velocity="0" />
  </joint>

  <joint name="NeckYaw" type="revolute">
    <origin xyz="0 0 0.0835" rpy="0 0 0"/>
    <axis xyz="0 0 1"/>
    <parent link="torso"/>
    <child link="NeckYaw_link"/>
    <limit effort="30" lower="-1.5707963" upper="1.5707963" velocity="5.8886917" />
  </joint>

  <joint name="NeckPitch" type="revolute">
    <origin xyz="0 0 0" rpy="0 0 0"/>
    <axis xyz="0 1 0"/>
    <parent link="NeckYaw_link"/>
    <child link="NeckPitch_link"/>
    <limit effort="30" lower="-0.698131688888889" upper="0.698131688888889" velocity="6.17848" />
  </joint>

  <joint name="HeadPitch" type="revolute">
    <origin xyz="0 0 0.09511" rpy="0 0 0"/>
    <axis xyz="0 1 0"/>
    <parent link="NeckPitch_link"/>
    <child link="HeadPitch_link"/>
    <limit effort="30" lower="-0.289724650888889" upper="0.349065844444444" velocity="7.2988824" />
  </joint>

  <joint name="HeadRoll" type="revolute">
    <origin xyz="0 0 0" rpy="0 0 0"/>
    <axis xyz="1 0 0"/>
    <parent link="HeadPitch_link"/>
    <child link="HeadRoll_link"/>
    <limit effort="30" lower="-0.523598766666667" upper="0.523598766666667" velocity="4.7442645" />
  </joint>

  <joint name="LShoulderPitch" type="revolute">
    <origin xyz="0.005 0.19 0" rpy="0 0 0"/>
    <axis xyz="0 1 0"/>
    <parent link="torso"/>
    <child link="LShoulderPitch_link"/>
    <limit effort="30" lower="-1.51843642333333" upper="2.09439506666667" velocity="6.52664058" />
  </joint>

  <joint name="LShoulderYaw" type="revolute">
    <origin xyz="0 0 0" rpy="0 0 0"/>
    <axis xyz="0 0 1"/>
    <parent link="LShoulderPitch_link"/>
    <child link="LShoulderYaw_link"/>
    <limit effort="30" lower="-0.200712860555556" upper="1.43989660833333" velocity="10.333784" />
  </joint>

  <joint name="LElbowRoll" type="revolute">
    <origin xyz="0.205 0 0" rpy="0 0 0"/>
    <axis xyz="1 0 0"/>
    <parent link="LShoulderYaw_link"/>
    <child link="LElbowRoll_link"/>
    <limit effort="30" lower="-2.60054054111111" upper="1.39626337777778" velocity="10.333784" />
  </joint>

  <joint name="LElbowYaw" type="revolute">
    <origin xyz="0 0 0" rpy="0 0 0"/>
    <axis xyz="0 0 1"/>
    <parent link="LElbowRoll_link"/>
    <child link="LElbowYaw_link"/>
    <limit effort="30" lower="-1.5707963" upper="0.401425721111111" velocity="10.3810644" />
  </joint>

  <joint name="LWristRoll" type="revolute">
    <origin xyz="0.182 0 0" rpy="0 0 0"/>
    <axis xyz="1 0 0"/>
    <parent link="LElbowYaw_link"/>
    <child link="LWristRoll_link"/>
    <limit effort="30" lower="-3.66519136666667" upper="0.523598766666667" velocity="0" />
  </joint>

  <joint name="LWristYaw" type="revolute">
    <origin xyz="0 0 0" rpy="0 0 0"/>
    <axis xyz="0 1 0"/>
    <parent link="LWristRoll_link"/>
    <child link="LWristYaw_link"/>
    <limit effort="30" lower="-0.488692182222222" upper="0.488692182222222" velocity="0" />
  </joint>

  <joint name="LWristPitch" type="revolute">
    <origin xyz="0 0 0" rpy="0 0 0"/>
    <axis xyz="0 0 1"/>
    <parent link="LWristYaw_link"/>
    <child link="l_wrist"/>
    <limit effort="30" lower="-0.977384364444444" upper="0.977384364444444" velocity="0" />
  </joint>

  <joint name="RShoulderPitch" type="revolute">
    <origin xyz="0.005 -0.19 0" rpy="0 0 0"/>
    <axis xyz="0 1 0"/>
    <parent link="torso"/>
    <child link="RShoulderPitch_link"/>
    <limit effort="30" lower="-1.51843642333333" upper="2.09439506666667" velocity="6.52664058" />
  </joint>

  <joint name="RShoulderYaw" type="revolute">
    <origin xyz="0 0 0" rpy="0 0 0"/>
    <axis xyz="0 0 1"/>
    <parent link="RShoulderPitch_link"/>
    <child link="RShoulderYaw_link"/>
    <limit effort="30" lower="-1.43989660833333" upper="0.200712860555556" velocity="10.333784" />
  </joint>

  <joint name="RElbowRoll" type="revolute">
    <origin xyz="0.205 0 0" rpy="0 0 0"/>
    <axis xyz="1 0 0"/>
    <parent link="RShoulderYaw_link"/>
    <child link="RElbowRoll_link"/>
    <limit effort="30" lower="-1.39626337777778" upper="2.60054054111111" velocity="10.333784" />
  </joint>

  <joint name="RElbowYaw" type="revolute">
    <origin xyz="0 0 0" rpy="0 0 0"/>
    <axis xyz="0 0 1"/>
    <parent link="RElbowRoll_link"/>
    <child link="RElbowYaw_link"/>
    <limit effort="30" lower="-0.401425721111111" upper="1.5707963" velocity="10.3810644" />
  </joint>

  <joint name="RWristRoll" type="revolute">
    <origin xyz="0.182 0 0" rpy="0 0 0"/>
    <axis xyz="1 0 0"/>
    <parent link="RElbowYaw_link"/>
    <child link="RWristRoll_link"/>
    <limit effort="30" lower="-0.523598766666667" upper="3.66519136666667" velocity="0" />
  </joint>

  <joint name="RWristYaw" type="revolute">
    <origin xyz="0 0 0" rpy="0 0 0"/>
    <axis xyz="0 1 0"/>
    <parent link="RWristRoll_link"/>
    <child link="RWristYaw_link"/>
    <limit effort="30" lower="-0.488692182222222" upper="0.488692182222222" velocity="0" />
  </joint>

  <joint name="RWristPitch" type="revolute">
    <origin xyz="0 0 0" rpy="0 0 0"/>
    <axis xyz="0 0 1"/>
    <parent link="RWristYaw_link"/>
    <child link="r_wrist"/>
    <limit effort="30" lower="-0.977384364444444" upper="0.977384364444444" velocity="0" />
  </joint>

  <joint name="LHipYaw" type="revolute">
    <origin xyz="0 0.096 -0.20004" rpy="0 0 0"/>
    <axis xyz="0 0 1"/>
    <parent link="body"/>
    <child link="LHipYaw_link"/>
    <limit effort="30" lower="-0.261799383333333" upper="0.261799383333333" velocity="8.082461" />
  </joint>

  <joint name="LHipRoll" type="revolute">
    <origin xyz="0 0 0" rpy="0 0 0"/>
    <axis xyz="1 0 0"/>
    <parent link="LHipYaw_link"/>
    <child link="LHipRoll_link"/>
    <limit effort="30" lower="-0.261799383333333" upper="0.523598766666667" velocity="10.289294" />
  </joint>

  <joint name="LHipPitch" type="revolute">
    <origin xyz="0 0 0" rpy="0 0 0"/>
    <axis xyz="0 1 0"/>
    <parent link="LHipRoll_link"/>
    <child link="LHipPitch_link"/>
    <limit effort="30" lower="-1.71042263777778" upper="0.523598766666667" velocity="6.7799634" />
  </joint>

  <joint name="LKneePitch" type="revolute">
    <origin xyz="0 0 -0.32" rpy="0 0 0"/>
    <axis xyz="0 1 0"/>
    <parent link="LHipPitch_link"/>
    <child link="LKneePitch_link"/>
    <limit effort="30" lower="-0.0523598766666667" upper="2.25147469666667" velocity="8.27600953" />
  </joint>

  <joint name="LAnklePitch" type="revolute">
    <origin xyz="0 0 -0.29" rpy="0 0 0"/>
    <axis xyz="0 1 0"/>
    <parent link="LKneePitch_link"/>
    <child link="LAnklePitch_link"/>
    <limit effort="30" lower="-0.78539815" upper="0.523598766666667" velocity="6.7799634" />
  </joint>

  <joint name="LAnkleRoll" type="revolute">
    <origin xyz="0 0 0" rpy="0 0 0"/>
    <axis xyz="1 0 0"/>
    <parent link="LAnklePitch_link"/>
    <child link="l_ankle"/>
    <limit effort="30" lower="-0.349065844444444" upper="0.349065844444444" velocity="10.28929" />
  </joint>

  <joint name="LToePitch" type="revolute">
    <origin xyz="0.1135 0 -0.0524" rpy="0 0 0"/>
    <axis xyz="0 1 0"/>
    <parent link="l_ankle"/>
    <child link="l_toe"/>
    <limit effort="30" lower="-0.78539815" upper="0" velocity="0" />
  </joint>

  <joint name="RHipYaw" type="revolute">
    <origin xyz="0 -0.096 -0.20004" rpy="0 0 0"/>
    <axis xyz="0 0 1"/>
    <parent link="body"/>
    <child link="RHipYaw_link"/>
    <limit effort="30" lower="-0.261799383333333" upper="0.261799383333333" velocity="8.082461" />
  </joint>

  <joint name="RHipRoll" type="revolute">
    <origin xyz="0 0 0" rpy="0 0 0"/>
    <axis xyz="1 0 0"/>
    <parent link="RHipYaw_link"/>
    <child link="RHipRoll_link"/>
    <limit effort="30" lower="-0.523598766666667" upper="0.261799383333333" velocity="10.289294" />
  </joint>

  <joint name="RHipPitch" type="revolute">
    <origin xyz="0 0 0" rpy="0 0 0"/>
    <axis xyz="0 1 0"/>
    <parent link="RHipRoll_link"/>
    <child link="RHipPitch_link"/>
    <limit effort="30" lower="-1.71042263777778" upper="0.523598766666667" velocity="6.7799634" />
  </joint>

  <joint name="RKneePitch" type="revolute">
    <origin xyz="0 0 -0.32" rpy="0 0 0"/>
    <axis xyz="0 1 0"/>
    <parent link="RHipPitch_link"/>
    <child link="RKneePitch_link"/>
    <limit effort="30" lower="-0.0523598766666667" upper="2.25147469666667" velocity="8.27600953" />
  </joint>

  <joint name="RAnklePitch" type="revolute">
    <origin xyz="0 0 -0.29" rpy="0 0 0"/>
    <axis xyz="0 1 0"/>
    <parent link="RKneePitch_link"/>
    <child link="RAnklePitch_link"/>
    <limit effort="30" lower="-0.78539815" upper="0.523598766666667" velocity="6.7799634" />
  </joint>

  <joint name="RAnkleRoll" type="revolute">
    <origin xyz="0 0 0" rpy="0 0 0"/>
    <axis xyz="1 0 0"/>
    <parent link="RAnklePitch_link"/>
    <child link="r_ankle"/>
    <limit effort="30" lower="-0.349065844444444" upper="0.349065844444444" velocity="10.28929" />
  </joint>

  <joint name="RToePitch" type="revolute">
    <origin xyz="0.1135 0 -0.0524" rpy="0 0 0"/>
    <axis xyz="0 1 0"/>
    <parent link="r_ankle"/>
    <child link="r_toe"/>
    <limit effort="30" lower="-0.78539815" upper="0" velocity="0" />
  </joint>

  <joint name="l_sole_joint" type="fixed">
    <parent link="l_ankle"/>
    <child link="l_sole"/>
    <origin xyz="0 0 -0.067" rpy="0 0 0"/>
  </joint>
  <joint name="r_sole_joint" type="fixed">
    <parent link="r_ankle"/>
    <child link="r_sole"/>
    <origin xyz="0 0 -0.067" rpy="0 0 0"/>
  </joint>

<gazebo reference="torso">
     <material>Gazebo/White</material>
  </gazebo>
<gazebo reference="HeadRoll_link">
     <material>Gazebo/White</material>
  </gazebo>
<gazebo reference="r_toe">
     <material>Gazebo/WhiteEmissive</material>
  </gazebo>
<gazebo reference="l_toe">
     <material>Gazebo/WhiteEmissive</material>
  </gazebo>
<gazebo reference="RKneePitch_link">
     <material>Gazebo/Grey</material>
  </gazebo>
<gazebo reference="LKneePitch_link">
     <material>Gazebo/Grey</material>
  </gazebo>

<gazebo reference="RShoulderYaw_link">
     <material>Gazebo/Green</material>
  </gazebo>
<gazebo reference="LShoulderYaw_link">
     <material>Gazebo/Green</material>
  </gazebo>
<gazebo reference="RHipPitch_link">
     <material>Gazebo/Blue</material>
  </gazebo>
<gazebo reference="LHipPitch_link">
     <material>Gazebo/Blue</material>
  </gazebo>
<gazebo reference="r_wrist">
     <material>Gazebo/RedEmissive</material>
  </gazebo>
<gazebo reference="l_wrist">
     <material>Gazebo/RedEmissive</material>
  </gazebo>
<gazebo reference="LWristRoll_link">
     <material>Gazebo/White</material>
  </gazebo>
<gazebo reference="RWristRoll_link">
     <material>Gazebo/White</material>
  </gazebo>
<gazebo reference="LElbowYaw_link">
     <material>Gazebo/Red</material>
  </gazebo>
<gazebo reference="RElbowYaw_link">
     <material>Gazebo/Red</material>
  </gazebo>
</robot>
