<?xml version="1.0" ?>
<!-- =================================================================================== -->
<!-- |    This document was autogenerated by xacro from irobot_hand_drake_right.urdf.xacro | -->
<!-- |    EDITING THIS FILE BY HAND IS NOT RECOMMENDED                                 | -->
<!-- =================================================================================== -->
<robot name="irobot_hand_right" xmlns:controller="http://playerstage.sourceforge.net/gazebo/xmlschema/#controller" xmlns:interface="http://playerstage.sourceforge.net/gazebo/xmlschema/#interface" xmlns:sensor="http://playerstage.sourceforge.net/gazebo/xmlschema/#sensor" xmlns:xacro="http://www.ros.org/wiki/xacro">
  <!--  <include filename="$(find handle_description)/src/irobot_hand_simple.urdf.xacro" />-->
  <link name="base">
    <inertial>
      <mass value="0.001"/>
      <origin rpy="0 0 0" xyz="0 0 0.25"/>
      <inertia ixx="0.000001" ixy="0" ixz="0" iyy="0.000001" iyz="0" izz="0.000001"/>
    </inertial>
  </link>
  <joint name="right_finger[0]/joint_flex" type="revolute">
    <parent link="right_finger[0]/proximal_link"/>
    <child link="right_finger[0]/distal_link"/>
    <origin xyz="0 0 0.078"/>
    <axis xyz="-1 0 0"/>
    <limit effort="1000.0" lower="0.0" upper="1.57" velocity="0.5"/>
  </joint>
  <joint name="right_finger[1]/joint_flex" type="revolute">
    <parent link="right_finger[1]/proximal_link"/>
    <child link="right_finger[1]/distal_link"/>
    <origin xyz="0 0 0.078"/>
    <axis xyz="-1 0 0"/>
    <limit effort="1000.0" lower="0.0" upper="1.57" velocity="0.5"/>
  </joint>
  <joint name="right_finger[2]/joint_flex" type="revolute">
    <parent link="right_finger[2]/proximal_link"/>
    <child link="right_finger[2]/distal_link"/>
    <origin xyz="0 0 0.078"/>
    <axis xyz="-1 0 0"/>
    <limit effort="1000.0" lower="0.0" upper="1.57" velocity="0.5"/>
  </joint>
  <joint name="right_irobot_hand_joint" type="fixed">
    <origin rpy="1.57 0 -1.57" xyz="0 0 0"/>
    <parent link="base"/>
    <child link="right_base_link"/>
  </joint>
  <link name="right_base_link">
    <inertial>
      <mass value="0.1"/>
      <origin xyz="0 0 0"/>
      <inertia ixx="0.001" ixy="0.0" ixz="0.0" iyy="0.001" iyz="0.0" izz="0.001"/>
    </inertial>
    <!--    <collision>-->
    <!--      <geometry>-->
    <!--        <mesh filename="package://mit_drcsim_scripts/models/irobot_hand/meshes/palm.wrl"/>-->
    <!--      </geometry>-->
    <!--      <origin rpy="0 0 0" xyz="0 -0.038 -0.023"/>-->
    <!--    </collision>-->
    <collision>
      <origin rpy="0 0 0" xyz="0.0 0.012 0.083"/>
      <geometry>
        <sphere radius="0"/>
      </geometry>
    </collision>
    <collision>
      <origin rpy="0 0 0" xyz="0.0 -0.005 0.083"/>
      <geometry>
        <sphere radius="0"/>
      </geometry>
    </collision>
    <collision>
      <origin rpy="0 0 0" xyz="0.012 0.0 0.083"/>
      <geometry>
        <sphere radius="0"/>
      </geometry>
    </collision>
    <collision>
      <origin rpy="0 0 0" xyz="-0.012 0.0 0.083"/>
      <geometry>
        <sphere radius="0"/>
      </geometry>
    </collision>
    <visual>
      <geometry>
        <mesh filename="package://mit_drcsim_scripts/models/irobot_hand/meshes/palm.wrl"/>
      </geometry>
      <material name="darkgray">
        <color rgba="0.2 0.2 0.2 1"/>
      </material>
      <origin rpy="0 0 0" xyz="0 -0.038 -0.023"/>
    </visual>
  </link>
  <link name="right_finger[0]/base_rotation_link">
    <inertial>
      <mass value="0.1"/>
      <origin xyz="0 0 0"/>
      <inertia ixx="0.001" ixy="0.0" ixz="0.0" iyy="0.001" iyz="0.0" izz="0.001"/>
    </inertial>
    <!--    <collision>-->
    <!--      <geometry>-->
    <!--        <mesh filename="package://mit_drcsim_scripts/models/irobot_hand/meshes/finger_base.wrl"/>-->
    <!--      </geometry>-->
    <!--      <origin rpy="${pi/2} 0 0" xyz="0 0 0"/>-->
    <!--    </collision>-->
    <visual>
      <geometry>
        <mesh filename="package://mit_drcsim_scripts/models/irobot_hand/meshes/finger_base.wrl"/>
      </geometry>
      <material name="darkgray">
        <color rgba="0.2 0.2 0.2 1"/>
      </material>
      <origin rpy="1.57 0 0" xyz="0 0 0"/>
    </visual>
  </link>
  <link name="right_finger[0]/proximal_link">
    <inertial>
      <mass value="0.1"/>
      <origin xyz="0 0 0"/>
      <inertia ixx="0.001" ixy="0.0" ixz="0.0" iyy="0.001" iyz="0.0" izz="0.001"/>
    </inertial>
    <!--    <collision>-->
    <!--      <geometry>-->
    <!--        <mesh filename="package://mit_drcsim_scripts/models/irobot_hand/meshes/finger_proximal.wrl"/>-->
    <!--      </geometry>-->
    <!--      <origin rpy="${pi/2} -${pi/2} 0" xyz="0 0 0"/>-->
    <!--    </collision>-->
    <collision>
      <origin rpy="0 0 0" xyz="0.0 0.01 0.034"/>
      <geometry>
        <sphere radius="0"/>
      </geometry>
    </collision>
    <collision>
      <origin rpy="0 0 0" xyz="0.0 0.01 0.051"/>
      <geometry>
        <sphere radius="0"/>
      </geometry>
    </collision>
    <visual>
      <geometry>
        <mesh filename="package://mit_drcsim_scripts/models/irobot_hand/meshes/finger_proximal.wrl"/>
      </geometry>
      <material name="green">
        <color rgba="0.1 0.6 0.1 1"/>
      </material>
      <origin rpy="1.57 -1.57 0" xyz="0 0 0"/>
    </visual>
  </link>
  <link name="right_finger[0]/distal_link">
    <inertial>
      <mass value="0.1"/>
      <origin xyz="0 0 0"/>
      <inertia ixx="0.001" ixy="0.0" ixz="0.0" iyy="0.001" iyz="0.0" izz="0.001"/>
    </inertial>
    <!--    <collision>-->
    <!--      <geometry>-->
    <!--        <mesh filename="package://mit_drcsim_scripts/models/irobot_hand/meshes/finger_distal.wrl"/>-->
    <!--      </geometry>-->
    <!--      <origin rpy="0 ${pi} 0" xyz="0 0 0"/>-->
    <!--    </collision>-->
    <collision>
      <origin rpy="0 0 0" xyz="0.0 0.01 0.02"/>
      <geometry>
        <sphere radius="0"/>
      </geometry>
    </collision>
    <collision>
      <origin rpy="0 0 0" xyz="0.0 -0.01 0.02"/>
      <geometry>
        <sphere radius="0"/>
      </geometry>
    </collision>
    <visual>
      <geometry>
        <mesh filename="package://mit_drcsim_scripts/models/irobot_hand/meshes/finger_distal.wrl"/>
      </geometry>
      <material name="green">
        <color rgba="0.1 0.6 0.1 1"/>
      </material>
      <origin rpy="0 3.14 0" xyz="0 0 0"/>
    </visual>
  </link>
  <link name="right_finger[1]/base_rotation_link">
    <inertial>
      <mass value="0.1"/>
      <origin xyz="0 0 0"/>
      <inertia ixx="0.001" ixy="0.0" ixz="0.0" iyy="0.001" iyz="0.0" izz="0.001"/>
    </inertial>
    <!--    <collision>-->
    <!--      <geometry>-->
    <!--        <mesh filename="package://mit_drcsim_scripts/models/irobot_hand/meshes/finger_base.wrl"/>-->
    <!--      </geometry>-->
    <!--      <origin rpy="${pi/2} 0 0" xyz="0 0 0"/>-->
    <!--    </collision>-->
    <visual>
      <geometry>
        <mesh filename="package://mit_drcsim_scripts/models/irobot_hand/meshes/finger_base.wrl"/>
      </geometry>
      <material name="darkgray">
        <color rgba="0.2 0.2 0.2 1"/>
      </material>
      <origin rpy="1.57 0 0" xyz="0 0 0"/>
    </visual>
  </link>
  <link name="right_finger[1]/proximal_link">
    <inertial>
      <mass value="0.1"/>
      <origin xyz="0 0 0"/>
      <inertia ixx="0.001" ixy="0.0" ixz="0.0" iyy="0.001" iyz="0.0" izz="0.001"/>
    </inertial>
    <!--    <collision>-->
    <!--      <geometry>-->
    <!--        <mesh filename="package://mit_drcsim_scripts/models/irobot_hand/meshes/finger_proximal.wrl"/>-->
    <!--      </geometry>-->
    <!--      <origin rpy="${pi/2} -${pi/2} 0" xyz="0 0 0"/>-->
    <!--    </collision>-->
    <collision>
      <origin rpy="0 0 0" xyz="0.0 0.01 0.034"/>
      <geometry>
        <sphere radius="0"/>
      </geometry>
    </collision>
    <collision>
      <origin rpy="0 0 0" xyz="0.0 0.01 0.051"/>
      <geometry>
        <sphere radius="0"/>
      </geometry>
    </collision>
    <visual>
      <geometry>
        <mesh filename="package://mit_drcsim_scripts/models/irobot_hand/meshes/finger_proximal.wrl"/>
      </geometry>
      <material name="green">
        <color rgba="0.1 0.6 0.1 1"/>
      </material>
      <origin rpy="1.57 -1.57 0" xyz="0 0 0"/>
    </visual>
  </link>
  <link name="right_finger[1]/distal_link">
    <inertial>
      <mass value="0.1"/>
      <origin xyz="0 0 0"/>
      <inertia ixx="0.001" ixy="0.0" ixz="0.0" iyy="0.001" iyz="0.0" izz="0.001"/>
    </inertial>
    <!--    <collision>-->
    <!--      <geometry>-->
    <!--        <mesh filename="package://mit_drcsim_scripts/models/irobot_hand/meshes/finger_distal.wrl"/>-->
    <!--      </geometry>-->
    <!--      <origin rpy="0 ${pi} 0" xyz="0 0 0"/>-->
    <!--    </collision>-->
    <collision>
      <origin rpy="0 0 0" xyz="0.0 0.01 0.02"/>
      <geometry>
        <sphere radius="0"/>
      </geometry>
    </collision>
    <collision>
      <origin rpy="0 0 0" xyz="0.0 -0.01 0.02"/>
      <geometry>
        <sphere radius="0"/>
      </geometry>
    </collision>
    <visual>
      <geometry>
        <mesh filename="package://mit_drcsim_scripts/models/irobot_hand/meshes/finger_distal.wrl"/>
      </geometry>
      <material name="green">
        <color rgba="0.1 0.6 0.1 1"/>
      </material>
      <origin rpy="0 3.14 0" xyz="0 0 0"/>
    </visual>
  </link>
  <link name="right_finger[2]/proximal_link">
    <inertial>
      <mass value="0.1"/>
      <origin xyz="0 0 0"/>
      <inertia ixx="0.001" ixy="0.0" ixz="0.0" iyy="0.001" iyz="0.0" izz="0.001"/>
    </inertial>
    <!--    <collision>-->
    <!--      <geometry>-->
    <!--        <mesh filename="package://mit_drcsim_scripts/models/irobot_hand/meshes/finger_proximal.wrl"/>-->
    <!--      </geometry>-->
    <!--      <origin rpy="${pi/2} -${pi/2} 0" xyz="0 0 0"/>-->
    <!--    </collision>-->
    <collision>
      <origin rpy="0 0 0" xyz="0.0 0.01 0.034"/>
      <geometry>
        <sphere radius="0"/>
      </geometry>
    </collision>
    <collision>
      <origin rpy="0 0 0" xyz="0.0 0.01 0.051"/>
      <geometry>
        <sphere radius="0"/>
      </geometry>
    </collision>
    <visual>
      <geometry>
        <mesh filename="package://mit_drcsim_scripts/models/irobot_hand/meshes/finger_proximal.wrl"/>
      </geometry>
      <material name="green">
        <color rgba="0.1 0.6 0.1 1"/>
      </material>
      <origin rpy="1.57 -1.57 0" xyz="0 0 0"/>
    </visual>
  </link>
  <link name="right_finger[2]/distal_link">
    <inertial>
      <mass value="0.1"/>
      <origin xyz="0 0 0"/>
      <inertia ixx="0.001" ixy="0.0" ixz="0.0" iyy="0.001" iyz="0.0" izz="0.001"/>
    </inertial>
    <!--    <collision>-->
    <!--      <geometry>-->
    <!--        <mesh filename="package://mit_drcsim_scripts/models/irobot_hand/meshes/finger_distal.wrl"/>-->
    <!--      </geometry>-->
    <!--      <origin rpy="0 ${pi} 0" xyz="0 0 0"/>-->
    <!--    </collision>-->
    <collision>
      <origin rpy="0 0 0" xyz="0.0 0.01 0.02"/>
      <geometry>
        <sphere radius="0"/>
      </geometry>
    </collision>
    <collision>
      <origin rpy="0 0 0" xyz="0.0 -0.01 0.02"/>
      <geometry>
        <sphere radius="0"/>
      </geometry>
    </collision>
    <visual>
      <geometry>
        <mesh filename="package://mit_drcsim_scripts/models/irobot_hand/meshes/finger_distal.wrl"/>
      </geometry>
      <material name="green">
        <color rgba="0.1 0.6 0.1 1"/>
      </material>
      <origin rpy="0 3.14 0" xyz="0 0 0"/>
    </visual>
  </link>
  <joint name="right_finger[0]/joint_base_rotation" type="revolute">
    <parent link="right_base_link"/>
    <child link="right_finger[0]/base_rotation_link"/>
    <origin rpy="0 0 0" xyz="0.03075 0.038 0.069477"/>
    <axis xyz="0 0 -1"/>
    <limit effort="1000.0" lower="0.0" upper="1.57" velocity="0.5"/>
  </joint>
  <joint name="right_finger[0]/joint_base" type="revolute">
    <parent link="right_finger[0]/base_rotation_link"/>
    <child link="right_finger[0]/proximal_link"/>
    <origin rpy="1.57 0 -3.14" xyz="0 0 0.0135"/>
    <axis xyz="-1 0 0"/>
    <limit effort="1000.0" lower="0.0" upper="1.57" velocity="0.5"/>
  </joint>
  <joint name="right_finger[1]/joint_base_rotation" type="revolute">
    <parent link="right_base_link"/>
    <child link="right_finger[1]/base_rotation_link"/>
    <origin rpy="0 0 0" xyz="-0.03075 0.038 0.069477"/>
    <axis xyz="0 0 1"/>
    <limit effort="1000.0" lower="0.0" upper="1.57" velocity="0.5"/>
  </joint>
  <joint name="right_finger[1]/joint_base" type="revolute">
    <parent link="right_finger[1]/base_rotation_link"/>
    <child link="right_finger[1]/proximal_link"/>
    <origin rpy="1.57 0 -3.14" xyz="0 0 0.0135"/>
    <axis xyz="-1 0 0"/>
    <limit effort="1000.0" lower="0.0" upper="1.57" velocity="0.5"/>
  </joint>
  <joint name="right_finger[2]/joint_base" type="revolute">
    <parent link="right_base_link"/>
    <child link="right_finger[2]/proximal_link"/>
    <origin rpy="1.57 0 0" xyz="0 -0.038 0.082755"/>
    <axis xyz="-1 0 0"/>
    <limit effort="1000.0" lower="0.0" upper="1.57" velocity="0.5"/>
  </joint>
</robot>
