<?xml version="1.0" ?>
<!-- =================================================================================== -->
<!-- |    This document was autogenerated by xacro from sandia_hand_left_drake.urdf.xacro | -->
<!-- |    EDITING THIS FILE BY HAND IS NOT RECOMMENDED                                 | -->
<!-- =================================================================================== -->
<robot name="sandia_hand_left" xmlns:controller="http://playerstage.sourceforge.net/gazebo/xmlschema/#controller" xmlns:interface="http://playerstage.sourceforge.net/gazebo/xmlschema/#interface" xmlns:sensor="http://playerstage.sourceforge.net/gazebo/xmlschema/#sensor" xmlns:xacro="http://www.ros.org/wiki/xacro">
  <link name="base">
    <inertial>
      <mass value="0.1"/>
      <origin rpy="0 0 0" xyz="0 0 0.25"/>
      <inertia ixx="0.01" ixy="0" ixz="0" iyy="0.01" iyz="0" izz="0.01"/>
    </inertial>
    <!-- <visual>
        <origin xyz="0 0 0.25" rpy="0 0 0" />
        <geometry>
            <box size="0.5 0.5 0.5" />
        </geometry>
    </visual>
    <collision>
        <origin xyz="0 0 0.25" rpy="0 0 0" />
        <geometry>
            <box size="0.5 0.5 0.5" />
        </geometry>
    </collision> -->
  </link>
  <link name="l_palm">
    <origin rpy="0 0 0" xyz="0 0 0"/>
    <inertial>
      <mass value="0.1"/>
      <origin xyz="0 0 0"/>
      <inertia ixx="0.01" ixy="0" ixz="0" iyy="0.01" iyz="0" izz="0.01"/>
    </inertial>
    <visual>
      <origin rpy="0 0 0" xyz="0 0 0"/>
      <geometry>
        <mesh filename="/home/drc/drc/ros_workspace/mit_drcsim_scripts/models/sandia_hand/meshes/palm.wrl"/>
      </geometry>
      <material name="l_sandia_hand_skin">
        <color rgba="0.835 0.655 0.345 1.0"/>
      </material>
    </visual>
    <!-- <collision>
        <origin xyz="0 0 0" rpy="0 0 0"/>
        <geometry>
          <mesh filename="$(find mit_drcsim_scripts)/models/sandia_hand/meshes/palm.stl"/>
        </geometry>
  </collision> -->
  </link>
  <joint name="l_sandia_hand_joint" type="fixed">
    <parent link="base"/>
    <child link="l_palm"/>
    <origin rpy="0 -1.57079 0" xyz="0 0 0.0"/>
  </joint>
  <link name="l_f0_base">
    <origin rpy="0 0 0" xyz="0 0 0"/>
    <inertial>
      <mass value="0.1"/>
      <origin xyz="0 0 0"/>
      <inertia ixx="0.01" ixy="0" ixz="0" iyy="0.01" iyz="0" izz="0.01"/>
    </inertial>
  </link>
  <link name="l_f0_fixed_accel">
    <origin rpy="0 0 0" xyz="0 0 0"/>
    <inertial>
      <mass value="0.1"/>
      <origin xyz="0 0 0"/>
      <inertia ixx="0.01" ixy="0" ixz="0" iyy="0.01" iyz="0" izz="0.01"/>
    </inertial>
    <collision>
      <origin rpy="0 0 0" xyz="0 0 0.05"/>
      <geometry>
        <sphere radius="0"/>
      </geometry>
    </collision>
  </link>
  <link name="l_f0_knuckle_dummy_contact">
    <origin rpy="0 0 0" xyz="0 0 0"/>
    <inertial>
      <mass value="0.001"/>
      <origin xyz="0 0 0"/>
      <inertia ixx="0.001" ixy="0" ixz="0" iyy="0.001" iyz="0" izz="0.001"/>
    </inertial>
    <collision>
      <origin rpy="0 0 0" xyz="0.1 0 0.05"/>
      <geometry>
        <sphere radius="0"/>
      </geometry>
    </collision>
  </link>
  <link name="l_f0_0">
    <origin rpy="0 0 0" xyz="0 0 0"/>
    <inertial>
      <mass value="0.1"/>
      <origin xyz="0 0 0"/>
      <inertia ixx="0.01" ixy="0" ixz="0" iyy="0.01" iyz="0" izz="0.01"/>
    </inertial>
    <visual>
      <origin rpy="0 0 0" xyz="0 0 0"/>
      <geometry>
        <mesh filename="/home/drc/drc/ros_workspace/mit_drcsim_scripts/models/sandia_hand/meshes/f0.wrl"/>
      </geometry>
      <material name="l_sandia_hand_skin_suntan">
        <color rgba="0.7 0.4 0.2 1.0"/>
      </material>
    </visual>
    <!-- <collision>
        <origin xyz="0 0 0" rpy="0 0 0"/>
        <geometry>
          <mesh filename="$(find mit_drcsim_scripts)/models/sandia_hand/meshes/f0.stl"/>
        </geometry>
  </collision> -->
  </link>
  <link name="l_f0_1">
    <origin rpy="0 0 0" xyz="0 0 0"/>
    <inertial>
      <mass value="0.1"/>
      <origin xyz="0 0 0"/>
      <inertia ixx="0.01" ixy="0" ixz="0" iyy="0.01" iyz="0" izz="0.01"/>
    </inertial>
    <visual>
      <origin rpy="0 0 0" xyz="0 0 0"/>
      <geometry>
        <mesh filename="/home/drc/drc/ros_workspace/mit_drcsim_scripts/models/sandia_hand/meshes/f1.wrl"/>
      </geometry>
      <material name="l_sandia_hand_skin">
        <color rgba="0.835 0.655 0.345 1.0"/>
      </material>
    </visual>
    <!-- <collision>
        <origin xyz="0 0 0" rpy="0 0 0"/>
        <geometry>
          <mesh filename="$(find mit_drcsim_scripts)/models/sandia_hand/meshes/f1.stl"/>
        </geometry>
  </collision> -->
  </link>
  <link name="l_f0_1_accel">
    <origin rpy="0 0 0" xyz="0 0 0"/>
    <inertial>
      <mass value="0.1"/>
      <origin xyz="0 0 0"/>
      <inertia ixx="0.01" ixy="0" ixz="0" iyy="0.01" iyz="0" izz="0.01"/>
    </inertial>
    <collision>
      <origin rpy="0 0 0" xyz="0 0 0.01"/>
      <geometry>
        <sphere radius="0"/>
      </geometry>
    </collision>
  </link>
  <link name="l_f0_2">
    <origin rpy="0 0 0" xyz="0 0 0"/>
    <inertial>
      <mass value="0.1"/>
      <origin xyz="0 0 0"/>
      <inertia ixx="0.01" ixy="0" ixz="0" iyy="0.01" iyz="0" izz="0.01"/>
    </inertial>
    <visual>
      <origin rpy="0 0 0" xyz="0 0 0"/>
      <geometry>
        <mesh filename="/home/drc/drc/ros_workspace/mit_drcsim_scripts/models/sandia_hand/meshes/f2.wrl"/>
      </geometry>
      <material name="l_sandia_hand_skin_suntan">
        <color rgba="0.8 0.6 0.3 1.0"/>
      </material>
    </visual>
    <!-- <collision>
        <origin xyz="0 0 0" rpy="0 0 0"/>
        <geometry>
          <mesh filename="$(find mit_drcsim_scripts)/models/sandia_hand/meshes/f2.stl"/>
        </geometry>
  </collision> -->
  </link>
  <link name="l_f0_2_accel">
    <origin rpy="0 0 0" xyz="0 0 0"/>
    <inertial>
      <mass value="0.1"/>
      <origin xyz="0 0 0"/>
      <inertia ixx="0.01" ixy="0" ixz="0" iyy="0.01" iyz="0" izz="0.01"/>
    </inertial>
    <collision>
      <origin rpy="0 0 0" xyz="0 0 0.01"/>
      <geometry>
        <sphere radius="0"/>
      </geometry>
    </collision>
  </link>
  <joint name="l_f0_base" type="fixed">
    <parent link="l_palm"/>
    <child link="l_f0_base"/>
    <origin rpy="0 0 0.3" xyz="0.14 0.0 0"/>
  </joint>
  <joint name="l_f0_j0" type="revolute">
    <axis xyz="0 0 1"/>
    <parent link="l_f0_base"/>
    <child link="l_f0_0"/>
    <!--    <limit effort="1" lower="-1.57079" upper="1.57079" velocity="1"/>-->
    <limit effort="1" lower="-1.57079" upper="0" velocity="1"/>
    <safety_controller k_position="1000.0" k_velocity="1000.0" soft_lower_limit="-11.57079" soft_upper_limit="11.57079"/>
    <dynamics damping="0.1"/>
    <origin rpy="0 0 0" xyz="0 0 0"/>
  </joint>
  <joint name="l_f0_j1" type="revolute">
    <axis xyz="0 0 1"/>
    <parent link="l_f0_0"/>
    <child link="l_f0_1"/>
    <limit effort="1" lower="-1.57079" upper="1.57079" velocity="1"/>
    <safety_controller k_position="1000.0" k_velocity="1000.0" soft_lower_limit="-11.57079" soft_upper_limit="11.57079"/>
    <dynamics damping="0.1"/>
    <origin rpy="1.57079 0 0" xyz="0.028 0 0"/>
  </joint>
  <joint name="l_f0_j2" type="revolute">
    <axis xyz="0 0 1"/>
    <parent link="l_f0_1"/>
    <child link="l_f0_2"/>
    <origin rpy="0 0 0" xyz="0.05 0 0"/>
    <safety_controller k_position="1000.0" k_velocity="1000.0" soft_lower_limit="-11.57079" soft_upper_limit="11.57079"/>
    <dynamics damping="0.1"/>
    <limit effort="1" lower="-1.57079" upper="1.57079" velocity="1"/>
  </joint>
  <joint name="l_f0_fixed_accel" type="fixed">
    <parent link="l_f0_base"/>
    <child link="l_f0_fixed_accel"/>
    <origin rpy="0 0 0" xyz="-0.05 0 0"/>
  </joint>
  <joint name="l_f0_knuckle_dummy_contact" type="fixed">
    <parent link="l_f0_base"/>
    <child link="l_f0_knuckle_dummy_contact"/>
    <origin rpy="0 0 0" xyz="-0.05 0 0"/>
  </joint>
  <joint name="l_f0_1_accel" type="fixed">
    <parent link="l_f0_1"/>
    <child link="l_f0_1_accel"/>
    <origin rpy="-1.5709 0 0" xyz="0.03 0 0"/>
  </joint>
  <joint name="l_f0_2_accel" type="fixed">
    <parent link="l_f0_2"/>
    <child link="l_f0_2_accel"/>
    <origin rpy="-1.5709 0 0" xyz="0.04 0 0"/>
  </joint>
  <transmission name="l_f0_j0" type="pr2_mechanism_model/SimpleTransmission">
    <joint name="l_f0_j0"/>
    <actuator name="l_f0_j0_motor"/>
    <mechanicalReduction>1</mechanicalReduction>
  </transmission>
  <transmission name="l_f0_j1" type="pr2_mechanism_model/SimpleTransmission">
    <joint name="l_f0_j1"/>
    <actuator name="l_f0_j1_motor"/>
    <mechanicalReduction>1</mechanicalReduction>
  </transmission>
  <transmission name="l_f0_j2" type="pr2_mechanism_model/SimpleTransmission">
    <joint name="l_f0_j2"/>
    <actuator name="l_f0_j2_motor"/>
    <mechanicalReduction>1</mechanicalReduction>
  </transmission>
  <link name="l_f1_base">
    <origin rpy="0 0 0" xyz="0 0 0"/>
    <inertial>
      <mass value="0.1"/>
      <origin xyz="0 0 0"/>
      <inertia ixx="0.01" ixy="0" ixz="0" iyy="0.01" iyz="0" izz="0.01"/>
    </inertial>
  </link>
  <link name="l_f1_fixed_accel">
    <origin rpy="0 0 0" xyz="0 0 0"/>
    <inertial>
      <mass value="0.1"/>
      <origin xyz="0 0 0"/>
      <inertia ixx="0.01" ixy="0" ixz="0" iyy="0.01" iyz="0" izz="0.01"/>
    </inertial>
    <collision>
      <origin rpy="0 0 0" xyz="0 0 0.05"/>
      <geometry>
        <sphere radius="0"/>
      </geometry>
    </collision>
  </link>
  <link name="l_f1_knuckle_dummy_contact">
    <origin rpy="0 0 0" xyz="0 0 0"/>
    <inertial>
      <mass value="0.001"/>
      <origin xyz="0 0 0"/>
      <inertia ixx="0.001" ixy="0" ixz="0" iyy="0.001" iyz="0" izz="0.001"/>
    </inertial>
    <collision>
      <origin rpy="0 0 0" xyz="0.1 0 0.05"/>
      <geometry>
        <sphere radius="0"/>
      </geometry>
    </collision>
  </link>
  <link name="l_f1_0">
    <origin rpy="0 0 0" xyz="0 0 0"/>
    <inertial>
      <mass value="0.1"/>
      <origin xyz="0 0 0"/>
      <inertia ixx="0.01" ixy="0" ixz="0" iyy="0.01" iyz="0" izz="0.01"/>
    </inertial>
    <visual>
      <origin rpy="0 0 0" xyz="0 0 0"/>
      <geometry>
        <mesh filename="/home/drc/drc/ros_workspace/mit_drcsim_scripts/models/sandia_hand/meshes/f0.wrl"/>
      </geometry>
      <material name="l_sandia_hand_skin_suntan">
        <color rgba="0.7 0.4 0.2 1.0"/>
      </material>
    </visual>
    <!-- <collision>
        <origin xyz="0 0 0" rpy="0 0 0"/>
        <geometry>
          <mesh filename="$(find mit_drcsim_scripts)/models/sandia_hand/meshes/f0.stl"/>
        </geometry>
  </collision> -->
  </link>
  <link name="l_f1_1">
    <origin rpy="0 0 0" xyz="0 0 0"/>
    <inertial>
      <mass value="0.1"/>
      <origin xyz="0 0 0"/>
      <inertia ixx="0.01" ixy="0" ixz="0" iyy="0.01" iyz="0" izz="0.01"/>
    </inertial>
    <visual>
      <origin rpy="0 0 0" xyz="0 0 0"/>
      <geometry>
        <mesh filename="/home/drc/drc/ros_workspace/mit_drcsim_scripts/models/sandia_hand/meshes/f1.wrl"/>
      </geometry>
      <material name="l_sandia_hand_skin">
        <color rgba="0.835 0.655 0.345 1.0"/>
      </material>
    </visual>
    <!-- <collision>
        <origin xyz="0 0 0" rpy="0 0 0"/>
        <geometry>
          <mesh filename="$(find mit_drcsim_scripts)/models/sandia_hand/meshes/f1.stl"/>
        </geometry>
  </collision> -->
  </link>
  <link name="l_f1_1_accel">
    <origin rpy="0 0 0" xyz="0 0 0"/>
    <inertial>
      <mass value="0.1"/>
      <origin xyz="0 0 0"/>
      <inertia ixx="0.01" ixy="0" ixz="0" iyy="0.01" iyz="0" izz="0.01"/>
    </inertial>
    <collision>
      <origin rpy="0 0 0" xyz="0 0 0.01"/>
      <geometry>
        <sphere radius="0"/>
      </geometry>
    </collision>
  </link>
  <link name="l_f1_2">
    <origin rpy="0 0 0" xyz="0 0 0"/>
    <inertial>
      <mass value="0.1"/>
      <origin xyz="0 0 0"/>
      <inertia ixx="0.01" ixy="0" ixz="0" iyy="0.01" iyz="0" izz="0.01"/>
    </inertial>
    <visual>
      <origin rpy="0 0 0" xyz="0 0 0"/>
      <geometry>
        <mesh filename="/home/drc/drc/ros_workspace/mit_drcsim_scripts/models/sandia_hand/meshes/f2.wrl"/>
      </geometry>
      <material name="l_sandia_hand_skin_suntan">
        <color rgba="0.8 0.6 0.3 1.0"/>
      </material>
    </visual>
    <!-- <collision>
        <origin xyz="0 0 0" rpy="0 0 0"/>
        <geometry>
          <mesh filename="$(find mit_drcsim_scripts)/models/sandia_hand/meshes/f2.stl"/>
        </geometry>
  </collision> -->
  </link>
  <link name="l_f1_2_accel">
    <origin rpy="0 0 0" xyz="0 0 0"/>
    <inertial>
      <mass value="0.1"/>
      <origin xyz="0 0 0"/>
      <inertia ixx="0.01" ixy="0" ixz="0" iyy="0.01" iyz="0" izz="0.01"/>
    </inertial>
    <collision>
      <origin rpy="0 0 0" xyz="0 0 0.01"/>
      <geometry>
        <sphere radius="0"/>
      </geometry>
    </collision>
  </link>
  <joint name="l_f1_base" type="fixed">
    <parent link="l_palm"/>
    <child link="l_f1_base"/>
    <origin rpy="0 0 0.3" xyz="0.115 0.03122 0"/>
  </joint>
  <joint name="l_f1_j0" type="revolute">
    <axis xyz="0 0 1"/>
    <parent link="l_f1_base"/>
    <child link="l_f1_0"/>
    <!--    <limit effort="1" lower="-1.57079" upper="1.57079" velocity="1"/>-->
    <limit effort="1" lower="-0.09" upper="0.09" velocity="1"/>
    <safety_controller k_position="1000.0" k_velocity="1000.0" soft_lower_limit="-11.57079" soft_upper_limit="11.57079"/>
    <dynamics damping="0.1"/>
    <origin rpy="0 0 0" xyz="0 0 0"/>
  </joint>
  <joint name="l_f1_j1" type="revolute">
    <axis xyz="0 0 1"/>
    <parent link="l_f1_0"/>
    <child link="l_f1_1"/>
    <limit effort="1" lower="-1.57079" upper="1.57079" velocity="1"/>
    <safety_controller k_position="1000.0" k_velocity="1000.0" soft_lower_limit="-11.57079" soft_upper_limit="11.57079"/>
    <dynamics damping="0.1"/>
    <origin rpy="1.57079 0 0" xyz="0.028 0 0"/>
  </joint>
  <joint name="l_f1_j2" type="revolute">
    <axis xyz="0 0 1"/>
    <parent link="l_f1_1"/>
    <child link="l_f1_2"/>
    <origin rpy="0 0 0" xyz="0.05 0 0"/>
    <safety_controller k_position="1000.0" k_velocity="1000.0" soft_lower_limit="-11.57079" soft_upper_limit="11.57079"/>
    <dynamics damping="0.1"/>
    <limit effort="1" lower="-1.57079" upper="1.57079" velocity="1"/>
  </joint>
  <joint name="l_f1_fixed_accel" type="fixed">
    <parent link="l_f1_base"/>
    <child link="l_f1_fixed_accel"/>
    <origin rpy="0 0 0" xyz="-0.05 0 0"/>
  </joint>
  <joint name="l_f1_knuckle_dummy_contact" type="fixed">
    <parent link="l_f1_base"/>
    <child link="l_f1_knuckle_dummy_contact"/>
    <origin rpy="0 0 0" xyz="-0.05 0 0"/>
  </joint>
  <joint name="l_f1_1_accel" type="fixed">
    <parent link="l_f1_1"/>
    <child link="l_f1_1_accel"/>
    <origin rpy="-1.5709 0 0" xyz="0.03 0 0"/>
  </joint>
  <joint name="l_f1_2_accel" type="fixed">
    <parent link="l_f1_2"/>
    <child link="l_f1_2_accel"/>
    <origin rpy="-1.5709 0 0" xyz="0.04 0 0"/>
  </joint>
  <transmission name="l_f1_j0" type="pr2_mechanism_model/SimpleTransmission">
    <joint name="l_f1_j0"/>
    <actuator name="l_f1_j0_motor"/>
    <mechanicalReduction>1</mechanicalReduction>
  </transmission>
  <transmission name="l_f1_j1" type="pr2_mechanism_model/SimpleTransmission">
    <joint name="l_f1_j1"/>
    <actuator name="l_f1_j1_motor"/>
    <mechanicalReduction>1</mechanicalReduction>
  </transmission>
  <transmission name="l_f1_j2" type="pr2_mechanism_model/SimpleTransmission">
    <joint name="l_f1_j2"/>
    <actuator name="l_f1_j2_motor"/>
    <mechanicalReduction>1</mechanicalReduction>
  </transmission>
  <link name="l_f2_base">
    <origin rpy="0 0 0" xyz="0 0 0"/>
    <inertial>
      <mass value="0.1"/>
      <origin xyz="0 0 0"/>
      <inertia ixx="0.01" ixy="0" ixz="0" iyy="0.01" iyz="0" izz="0.01"/>
    </inertial>
  </link>
  <link name="l_f2_fixed_accel">
    <origin rpy="0 0 0" xyz="0 0 0"/>
    <inertial>
      <mass value="0.1"/>
      <origin xyz="0 0 0"/>
      <inertia ixx="0.01" ixy="0" ixz="0" iyy="0.01" iyz="0" izz="0.01"/>
    </inertial>
    <collision>
      <origin rpy="0 0 0" xyz="0 0 0.05"/>
      <geometry>
        <sphere radius="0"/>
      </geometry>
    </collision>
  </link>
  <link name="l_f2_knuckle_dummy_contact">
    <origin rpy="0 0 0" xyz="0 0 0"/>
    <inertial>
      <mass value="0.001"/>
      <origin xyz="0 0 0"/>
      <inertia ixx="0.001" ixy="0" ixz="0" iyy="0.001" iyz="0" izz="0.001"/>
    </inertial>
    <collision>
      <origin rpy="0 0 0" xyz="0.1 0 0.05"/>
      <geometry>
        <sphere radius="0"/>
      </geometry>
    </collision>
  </link>
  <link name="l_f2_0">
    <origin rpy="0 0 0" xyz="0 0 0"/>
    <inertial>
      <mass value="0.1"/>
      <origin xyz="0 0 0"/>
      <inertia ixx="0.01" ixy="0" ixz="0" iyy="0.01" iyz="0" izz="0.01"/>
    </inertial>
    <visual>
      <origin rpy="0 0 0" xyz="0 0 0"/>
      <geometry>
        <mesh filename="/home/drc/drc/ros_workspace/mit_drcsim_scripts/models/sandia_hand/meshes/f0.wrl"/>
      </geometry>
      <material name="l_sandia_hand_skin_suntan">
        <color rgba="0.7 0.4 0.2 1.0"/>
      </material>
    </visual>
    <!-- <collision>
        <origin xyz="0 0 0" rpy="0 0 0"/>
        <geometry>
          <mesh filename="$(find mit_drcsim_scripts)/models/sandia_hand/meshes/f0.stl"/>
        </geometry>
  </collision> -->
  </link>
  <link name="l_f2_1">
    <origin rpy="0 0 0" xyz="0 0 0"/>
    <inertial>
      <mass value="0.1"/>
      <origin xyz="0 0 0"/>
      <inertia ixx="0.01" ixy="0" ixz="0" iyy="0.01" iyz="0" izz="0.01"/>
    </inertial>
    <visual>
      <origin rpy="0 0 0" xyz="0 0 0"/>
      <geometry>
        <mesh filename="/home/drc/drc/ros_workspace/mit_drcsim_scripts/models/sandia_hand/meshes/f1.wrl"/>
      </geometry>
      <material name="l_sandia_hand_skin">
        <color rgba="0.835 0.655 0.345 1.0"/>
      </material>
    </visual>
    <!-- <collision>
        <origin xyz="0 0 0" rpy="0 0 0"/>
        <geometry>
          <mesh filename="$(find mit_drcsim_scripts)/models/sandia_hand/meshes/f1.stl"/>
        </geometry>
  </collision> -->
  </link>
  <link name="l_f2_1_accel">
    <origin rpy="0 0 0" xyz="0 0 0"/>
    <inertial>
      <mass value="0.1"/>
      <origin xyz="0 0 0"/>
      <inertia ixx="0.01" ixy="0" ixz="0" iyy="0.01" iyz="0" izz="0.01"/>
    </inertial>
    <collision>
      <origin rpy="0 0 0" xyz="0 0 0.01"/>
      <geometry>
        <sphere radius="0"/>
      </geometry>
    </collision>
  </link>
  <link name="l_f2_2">
    <origin rpy="0 0 0" xyz="0 0 0"/>
    <inertial>
      <mass value="0.1"/>
      <origin xyz="0 0 0"/>
      <inertia ixx="0.01" ixy="0" ixz="0" iyy="0.01" iyz="0" izz="0.01"/>
    </inertial>
    <visual>
      <origin rpy="0 0 0" xyz="0 0 0"/>
      <geometry>
        <mesh filename="/home/drc/drc/ros_workspace/mit_drcsim_scripts/models/sandia_hand/meshes/f2.wrl"/>
      </geometry>
      <material name="l_sandia_hand_skin_suntan">
        <color rgba="0.8 0.6 0.3 1.0"/>
      </material>
    </visual>
    <!-- <collision>
        <origin xyz="0 0 0" rpy="0 0 0"/>
        <geometry>
          <mesh filename="$(find mit_drcsim_scripts)/models/sandia_hand/meshes/f2.stl"/>
        </geometry>
  </collision> -->
  </link>
  <link name="l_f2_2_accel">
    <origin rpy="0 0 0" xyz="0 0 0"/>
    <inertial>
      <mass value="0.1"/>
      <origin xyz="0 0 0"/>
      <inertia ixx="0.01" ixy="0" ixz="0" iyy="0.01" iyz="0" izz="0.01"/>
    </inertial>
    <collision>
      <origin rpy="0 0 0" xyz="0 0 0.01"/>
      <geometry>
        <sphere radius="0"/>
      </geometry>
    </collision>
  </link>
  <joint name="l_f2_base" type="fixed">
    <parent link="l_palm"/>
    <child link="l_f2_base"/>
    <origin rpy="0 0 0.3" xyz="0.09 0.06245 0"/>
  </joint>
  <joint name="l_f2_j0" type="revolute">
    <axis xyz="0 0 1"/>
    <parent link="l_f2_base"/>
    <child link="l_f2_0"/>
    <!--    <limit effort="1" lower="-1.57079" upper="1.57079" velocity="1"/>-->
    <limit effort="1" lower="0" upper="1.57079" velocity="1"/>
    <safety_controller k_position="1000.0" k_velocity="1000.0" soft_lower_limit="-11.57079" soft_upper_limit="11.57079"/>
    <dynamics damping="0.1"/>
    <origin rpy="0 0 0" xyz="0 0 0"/>
  </joint>
  <joint name="l_f2_j1" type="revolute">
    <axis xyz="0 0 1"/>
    <parent link="l_f2_0"/>
    <child link="l_f2_1"/>
    <limit effort="1" lower="-1.57079" upper="1.57079" velocity="1"/>
    <safety_controller k_position="1000.0" k_velocity="1000.0" soft_lower_limit="-11.57079" soft_upper_limit="11.57079"/>
    <dynamics damping="0.1"/>
    <origin rpy="1.57079 0 0" xyz="0.028 0 0"/>
  </joint>
  <joint name="l_f2_j2" type="revolute">
    <axis xyz="0 0 1"/>
    <parent link="l_f2_1"/>
    <child link="l_f2_2"/>
    <origin rpy="0 0 0" xyz="0.05 0 0"/>
    <safety_controller k_position="1000.0" k_velocity="1000.0" soft_lower_limit="-11.57079" soft_upper_limit="11.57079"/>
    <dynamics damping="0.1"/>
    <limit effort="1" lower="-1.57079" upper="1.57079" velocity="1"/>
  </joint>
  <joint name="l_f2_fixed_accel" type="fixed">
    <parent link="l_f2_base"/>
    <child link="l_f2_fixed_accel"/>
    <origin rpy="0 0 0" xyz="-0.05 0 0"/>
  </joint>
  <joint name="l_f2_knuckle_dummy_contact" type="fixed">
    <parent link="l_f2_base"/>
    <child link="l_f2_knuckle_dummy_contact"/>
    <origin rpy="0 0 0" xyz="-0.05 0 0"/>
  </joint>
  <joint name="l_f2_1_accel" type="fixed">
    <parent link="l_f2_1"/>
    <child link="l_f2_1_accel"/>
    <origin rpy="-1.5709 0 0" xyz="0.03 0 0"/>
  </joint>
  <joint name="l_f2_2_accel" type="fixed">
    <parent link="l_f2_2"/>
    <child link="l_f2_2_accel"/>
    <origin rpy="-1.5709 0 0" xyz="0.04 0 0"/>
  </joint>
  <transmission name="l_f2_j0" type="pr2_mechanism_model/SimpleTransmission">
    <joint name="l_f2_j0"/>
    <actuator name="l_f2_j0_motor"/>
    <mechanicalReduction>1</mechanicalReduction>
  </transmission>
  <transmission name="l_f2_j1" type="pr2_mechanism_model/SimpleTransmission">
    <joint name="l_f2_j1"/>
    <actuator name="l_f2_j1_motor"/>
    <mechanicalReduction>1</mechanicalReduction>
  </transmission>
  <transmission name="l_f2_j2" type="pr2_mechanism_model/SimpleTransmission">
    <joint name="l_f2_j2"/>
    <actuator name="l_f2_j2_motor"/>
    <mechanicalReduction>1</mechanicalReduction>
  </transmission>
  <link name="l_f3_base">
    <origin rpy="0 0 0" xyz="0 0 0"/>
    <inertial>
      <mass value="0.1"/>
      <origin xyz="0 0 0"/>
      <inertia ixx="0.01" ixy="0" ixz="0" iyy="0.01" iyz="0" izz="0.01"/>
    </inertial>
  </link>
  <link name="l_f3_fixed_accel">
    <origin rpy="0 0 0" xyz="0 0 0"/>
    <inertial>
      <mass value="0.1"/>
      <origin xyz="0 0 0"/>
      <inertia ixx="0.01" ixy="0" ixz="0" iyy="0.01" iyz="0" izz="0.01"/>
    </inertial>
  </link>
  <link name="l_f3_0">
    <origin rpy="0 0 0" xyz="0 0 0"/>
    <inertial>
      <mass value="0.1"/>
      <origin xyz="0 0 0"/>
      <inertia ixx="0.01" ixy="0" ixz="0" iyy="0.01" iyz="0" izz="0.01"/>
    </inertial>
    <visual>
      <origin rpy="0 0 0" xyz="0 0 0"/>
      <geometry>
        <mesh filename="/home/drc/drc/ros_workspace/mit_drcsim_scripts/models/sandia_hand/meshes/f0.wrl"/>
      </geometry>
      <material name="l_sandia_hand_skin_suntan">
        <color rgba="0.7 0.4 0.2 1.0"/>
      </material>
    </visual>
    <!-- <collision>
        <origin xyz="0 0 0" rpy="0 0 0"/>
        <geometry>
          <mesh filename="$(find mit_drcsim_scripts)/models/sandia_hand/meshes/f0.stl"/>
        </geometry>
  </collision> -->
  </link>
  <link name="l_f3_1">
    <origin rpy="0 0 0" xyz="0 0 0"/>
    <inertial>
      <mass value="0.1"/>
      <origin xyz="0 0 0"/>
      <inertia ixx="0.01" ixy="0" ixz="0" iyy="0.01" iyz="0" izz="0.01"/>
    </inertial>
    <visual>
      <origin rpy="0 0 0" xyz="0 0 0"/>
      <geometry>
        <mesh filename="/home/drc/drc/ros_workspace/mit_drcsim_scripts/models/sandia_hand/meshes/f1.wrl"/>
      </geometry>
      <material name="l_sandia_hand_skin">
        <color rgba="0.835 0.655 0.345 1.0"/>
      </material>
    </visual>
    <!-- <collision>
        <origin xyz="0 0 0" rpy="0 0 0"/>
        <geometry>
          <mesh filename="$(find mit_drcsim_scripts)/models/sandia_hand/meshes/f1.stl"/>
        </geometry>
  </collision> -->
  </link>
  <link name="l_f3_1_accel">
    <origin rpy="0 0 0" xyz="0 0 0"/>
    <inertial>
      <mass value="0.1"/>
      <origin xyz="0 0 0"/>
      <inertia ixx="0.01" ixy="0" ixz="0" iyy="0.01" iyz="0" izz="0.01"/>
    </inertial>
  </link>
  <link name="l_f3_2">
    <origin rpy="0 0 0" xyz="0 0 0"/>
    <inertial>
      <mass value="0.1"/>
      <origin xyz="0 0 0"/>
      <inertia ixx="0.01" ixy="0" ixz="0" iyy="0.01" iyz="0" izz="0.01"/>
    </inertial>
    <visual>
      <origin rpy="0 0 0" xyz="0 0 0"/>
      <geometry>
        <mesh filename="/home/drc/drc/ros_workspace/mit_drcsim_scripts/models/sandia_hand/meshes/f2.wrl"/>
      </geometry>
      <material name="l_sandia_hand_skin_suntan">
        <color rgba="0.8 0.6 0.3 1.0"/>
      </material>
    </visual>
    <!-- <collision>
        <origin xyz="0 0 0" rpy="0 0 0"/>
        <geometry>
          <mesh filename="$(find mit_drcsim_scripts)/models/sandia_hand/meshes/f2.stl"/>
        </geometry>
  </collision> -->
  </link>
  <link name="l_f3_2_accel">
    <origin rpy="0 0 0" xyz="0 0 0"/>
    <inertial>
      <mass value="0.1"/>
      <origin xyz="0 0 0"/>
      <inertia ixx="0.01" ixy="0" ixz="0" iyy="0.01" iyz="0" izz="0.01"/>
    </inertial>
    <collision>
      <origin rpy="0 0 0" xyz="0 0 0.01"/>
      <geometry>
        <sphere radius="0"/>
      </geometry>
    </collision>
  </link>
  <joint name="l_f3_base" type="fixed">
    <parent link="l_palm"/>
    <child link="l_f3_base"/>
    <origin rpy="0 -1.57079 -2.3562" xyz="0.03995 -0.04383 0.014"/>
  </joint>
  <joint name="l_f3_j0" type="revolute">
    <axis xyz="0 0 1"/>
    <parent link="l_f3_base"/>
    <child link="l_f3_0"/>
    <limit effort="1" lower="-1.57079" upper="1.57079" velocity="1"/>
    <safety_controller k_position="1000.0" k_velocity="1000.0" soft_lower_limit="-11.57079" soft_upper_limit="11.57079"/>
    <dynamics damping="0.1"/>
    <origin rpy="0 0 0" xyz="0 0 0"/>
  </joint>
  <joint name="l_f3_j1" type="revolute">
    <axis xyz="0 0 1"/>
    <parent link="l_f3_0"/>
    <child link="l_f3_1"/>
    <limit effort="1" lower="-1.57079" upper="1.57079" velocity="1"/>
    <safety_controller k_position="1000.0" k_velocity="1000.0" soft_lower_limit="-11.57079" soft_upper_limit="11.57079"/>
    <dynamics damping="0.1"/>
    <origin rpy="1.57079 0 0" xyz="0.028 0 0"/>
  </joint>
  <joint name="l_f3_j2" type="revolute">
    <axis xyz="0 0 1"/>
    <parent link="l_f3_1"/>
    <child link="l_f3_2"/>
    <origin rpy="0 0 0" xyz="0.05 0 0"/>
    <safety_controller k_position="1000.0" k_velocity="1000.0" soft_lower_limit="-11.57079" soft_upper_limit="11.57079"/>
    <dynamics damping="0.1"/>
    <limit effort="1" lower="-1.57079" upper="1.57079" velocity="1"/>
  </joint>
  <joint name="l_f3_fixed_accel" type="fixed">
    <parent link="l_f3_base"/>
    <child link="l_f3_fixed_accel"/>
    <origin rpy="0 0 0" xyz="-0.05 0 0"/>
  </joint>
  <joint name="l_f3_1_accel" type="fixed">
    <parent link="l_f3_1"/>
    <child link="l_f3_1_accel"/>
    <origin rpy="-1.5709 0 0" xyz="0.03 0 0"/>
  </joint>
  <joint name="l_f3_2_accel" type="fixed">
    <parent link="l_f3_2"/>
    <child link="l_f3_2_accel"/>
    <origin rpy="-1.5709 0 0" xyz="0.04 0 0"/>
  </joint>
  <transmission name="l_f3_j0" type="pr2_mechanism_model/SimpleTransmission">
    <joint name="l_f3_j0"/>
    <actuator name="l_f3_j0_motor"/>
    <mechanicalReduction>1</mechanicalReduction>
  </transmission>
  <transmission name="l_f3_j1" type="pr2_mechanism_model/SimpleTransmission">
    <joint name="l_f3_j1"/>
    <actuator name="l_f3_j1_motor"/>
    <mechanicalReduction>1</mechanicalReduction>
  </transmission>
  <transmission name="l_f3_j2" type="pr2_mechanism_model/SimpleTransmission">
    <joint name="l_f3_j2"/>
    <actuator name="l_f3_j2_motor"/>
    <mechanicalReduction>1</mechanicalReduction>
  </transmission>
</robot>

