<?xml version="1.0" ?>
<!-- =================================================================================== -->
<!-- |    This document was autogenerated by xacro from xacro/schunk_hand_left.urdf.xacro | -->
<!-- |    EDITING THIS FILE BY HAND IS NOT RECOMMENDED                                 | -->
<!-- =================================================================================== -->
<robot name="schunk_hand_left" xmlns:controller="http://playerstage.sourceforge.net/gazebo/xmlschema/#controller" xmlns:interface="http://playerstage.sourceforge.net/gazebo/xmlschema/#interface" xmlns:sensor="http://playerstage.sourceforge.net/gazebo/xmlschema/#sensor" xmlns:xacro="http://www.ros.org/wiki/xacro">
  <link name="plane::xy::base">
    <inertial>
      <mass value="0.1"/>
      <origin rpy="0 0 0" xyz="0 0 0.0"/>
      <inertia ixx="0.01" ixy="0" ixz="0" iyy="0.01" iyz="0" izz="0.01"/>
    </inertial>
  </link>
  <joint name="sdh_palm_joint" type="fixed">
    <origin rpy="0 1.57 1.57" xyz="0 0 0"/>
    <parent link="plane::xy::base"/>
    <child link="sdh_palm_link"/>
  </joint>
  <link name="sdh_palm_link">
    <inertial>
      <origin rpy="0 0 0" xyz="0 0 0"/>
      <mass value="1"/>
      <inertia ixx="0.01" ixy="0" ixz="0" iyy="0.01" iyz="0" izz="0.01"/>
    </inertial>
    <visual>
      <origin rpy="0 0 0" xyz="0 0 0"/>
      <geometry>
        <mesh filename="package://schunk_description/meshes/sdh/palm.stl"/>
      </geometry>
      <material name="grey"><color rgba="0.7 0.7 0.7 1"/> </material>
    </visual>
    <collision>
      <origin rpy="0 0 0" xyz="0 0 0"/>
      <geometry>
        <mesh filename="package://schunk_description/meshes/sdh/palm.stl"/>
      </geometry>
    </collision>
  </link>
  <joint name="sdh_grasp_joint" type="fixed">
    <origin rpy="0 0 0" xyz="0 0 0.15"/>
    <parent link="sdh_palm_link"/>
    <child link="sdh_grasp_link"/>
  </joint>
  <link name="sdh_grasp_link"/>
  <joint name="sdh_tip_joint" type="fixed">
    <origin rpy="0 0 0" xyz="0 0 0.22"/>
    <parent link="sdh_palm_link"/>
    <child link="sdh_tip_link"/>
  </joint>
  <link name="sdh_tip_link"/>
  <joint name="sdh_knuckle_joint" type="revolute">
    <origin rpy="0 0 3.14159265" xyz="0.01905 0.033 0.0745"/>
    <parent link="sdh_palm_link"/>
    <child link="sdh_finger_11_link"/>
    <axis xyz="0 0 1"/>
    <dynamics damping="1"/>
    <limit effort="100" lower="0" upper="1.570796327" velocity="5"/>
  </joint>
  <link name="sdh_finger_11_link">
    <inertial>
      <origin rpy="0 0 0" xyz="0 0 0"/>
      <mass value="0.1"/>
      <inertia ixx="0.01" ixy="0" ixz="0" iyy="0.01" iyz="0" izz="0.01"/>
    </inertial>
    <visual>
      <origin rpy="0 0 0" xyz="0 0 0"/>
      <geometry>
        <mesh filename="package://schunk_description/meshes/sdh/knuckle.stl"/>
      </geometry>
      <material name="grey"><color rgba="0.7 0.7 0.7 1"/> </material>
    </visual>
    <collision>
      <origin rpy="0 0 0" xyz="0 0 0"/>
      <geometry>
        <mesh filename="package://schunk_description/meshes/sdh/knuckle.stl"/>
      </geometry>
    </collision>
  </link>
  <joint name="sdh_finger_12_joint" type="revolute">
    <origin rpy="0 0 0" xyz="0 0 0.0165"/>
    <parent link="sdh_finger_11_link"/>
    <child link="sdh_finger_12_link"/>
    <axis xyz="0 1 0"/>
    <dynamics damping="1"/>
    <limit effort="100" lower="-1.570796327" upper="1.570796327" velocity="5"/>
  </joint>
  <link name="sdh_finger_12_link">
    <inertial>
      <origin rpy="0 0 0" xyz="0 0 0"/>
      <mass value="0.1"/>
      <inertia ixx="0.01" ixy="0" ixz="0" iyy="0.01" iyz="0" izz="0.01"/>
    </inertial>
    <visual>
      <origin rpy="0 0 0" xyz="0 0 0"/>
      <geometry>
        <mesh filename="package://schunk_description/meshes/sdh/finger.stl"/>
      </geometry>
      <material name="grey"><color rgba="0.7 0.7 0.7 1"/> </material>
    </visual>
    <collision>
      <origin rpy="0 0 0" xyz="0 0 0"/>
      <geometry>
        <mesh filename="package://schunk_description/meshes/sdh/finger.stl"/>
      </geometry>
    </collision>
  </link>
  <joint name="sdh_finger_13_joint" type="revolute">
    <origin rpy="0 0 0" xyz="0 0 0.0865"/>
    <parent link="sdh_finger_12_link"/>
    <child link="sdh_finger_13_link"/>
    <axis xyz="0 1 0"/>
    <dynamics damping="1"/>
    <limit effort="100" lower="-1.570796327" upper="1.570796327" velocity="5"/>
  </joint>
  <link name="sdh_finger_13_link">
    <inertial>
      <origin rpy="0 0 0" xyz="0 0 0"/>
      <mass value="0.1"/>
      <inertia ixx="0.01" ixy="0" ixz="0" iyy="0.01" iyz="0" izz="0.01"/>
    </inertial>
    <visual>
      <origin rpy="0 0 0" xyz="0 0 0"/>
      <geometry>
        <mesh filename="package://schunk_description/meshes/sdh/finger_tip.stl"/>
      </geometry>
      <material name="grey"><color rgba="0.7 0.7 0.7 1"/> </material>
    </visual>
    <collision>
      <origin rpy="0 0 0" xyz="0 0 0"/>
      <geometry>
        <mesh filename="package://schunk_description/meshes/sdh/finger_tip.stl"/>
      </geometry>
    </collision>
  </link>
  <joint name="sdh_finger_21_joint" type="revolute">
    <mimic joint="sdh_knuckle_joint" multiplier="1" offset="0"/>
    <origin rpy="0 0 3.14159265" xyz="0.01905 -0.033 0.0745"/>
    <parent link="sdh_palm_link"/>
    <child link="sdh_finger_21_link"/>
    <axis xyz="0 0 -1"/>
    <dynamics damping="1"/>
    <limit effort="100" lower="0" upper="1.570796327" velocity="5"/>
  </joint>
  <link name="sdh_finger_21_link">
    <inertial>
      <origin rpy="0 0 0" xyz="0 0 0"/>
      <mass value="0.1"/>
      <inertia ixx="0.01" ixy="0" ixz="0" iyy="0.01" iyz="0" izz="0.01"/>
    </inertial>
    <visual>
      <origin rpy="0 0 0" xyz="0 0 0"/>
      <geometry>
        <mesh filename="package://schunk_description/meshes/sdh/knuckle.stl"/>
      </geometry>
      <material name="grey"><color rgba="0.7 0.7 0.7 1"/> </material>
    </visual>
    <collision>
      <origin rpy="0 0 0" xyz="0 0 0"/>
      <geometry>
        <mesh filename="package://schunk_description/meshes/sdh/knuckle.stl"/>
      </geometry>
    </collision>
  </link>
  <joint name="sdh_finger_22_joint" type="revolute">
    <origin rpy="0 0 0" xyz="0 0 0.0165"/>
    <parent link="sdh_finger_21_link"/>
    <child link="sdh_finger_22_link"/>
    <axis xyz="0 1 0"/>
    <dynamics damping="1"/>
    <limit effort="100" lower="-1.570796327" upper="1.570796327" velocity="5"/>
  </joint>
  <link name="sdh_finger_22_link">
    <inertial>
      <origin rpy="0 0 0" xyz="0 0 0"/>
      <mass value="0.1"/>
      <inertia ixx="0.01" ixy="0" ixz="0" iyy="0.01" iyz="0" izz="0.01"/>
    </inertial>
    <visual>
      <origin rpy="0 0 0" xyz="0 0 0"/>
      <geometry>
        <mesh filename="package://schunk_description/meshes/sdh/finger.stl"/>
      </geometry>
      <material name="grey"><color rgba="0.7 0.7 0.7 1"/> </material>
    </visual>
    <collision>
      <origin rpy="0 0 0" xyz="0 0 0"/>
      <geometry>
        <mesh filename="package://schunk_description/meshes/sdh/finger.stl"/>
      </geometry>
    </collision>
  </link>
  <joint name="sdh_finger_23_joint" type="revolute">
    <origin rpy="0 0 0" xyz="0 0 0.0865"/>
    <parent link="sdh_finger_22_link"/>
    <child link="sdh_finger_23_link"/>
    <axis xyz="0 1 0"/>
    <dynamics damping="1"/>
    <limit effort="100" lower="-1.570796327" upper="1.570796327" velocity="5"/>
  </joint>
  <link name="sdh_finger_23_link">
    <inertial>
      <origin rpy="0 0 0" xyz="0 0 0"/>
      <mass value="0.1"/>
      <inertia ixx="0.01" ixy="0" ixz="0" iyy="0.01" iyz="0" izz="0.01"/>
    </inertial>
    <visual>
      <origin rpy="0 0 0" xyz="0 0 0"/>
      <geometry>
        <mesh filename="package://schunk_description/meshes/sdh/finger_tip.stl"/>
      </geometry>
      <material name="grey"><color rgba="0.7 0.7 0.7 1"/> </material>
    </visual>
    <collision>
      <origin rpy="0 0 0" xyz="0 0 0"/>
      <geometry>
        <mesh filename="package://schunk_description/meshes/sdh/finger_tip.stl"/>
      </geometry>
    </collision>
  </link>
  <joint name="sdh_thumb_1_joint" type="fixed">
    <origin rpy="0 0 0" xyz="-0.03811 0 0.0745 "/>
    <parent link="sdh_palm_link"/>
    <child link="sdh_thumb_1_link"/>
  </joint>
  <link name="sdh_thumb_1_link">
    <inertial>
      <origin rpy="0 0 0" xyz="0 0 0"/>
      <mass value="0.1"/>
      <inertia ixx="0.01" ixy="0" ixz="0" iyy="0.01" iyz="0" izz="0.01"/>
    </inertial>
    <visual>
      <origin rpy="0 0 0" xyz="0 0 0"/>
      <geometry>
        <mesh filename="package://schunk_description/meshes/sdh/knuckle.stl"/>
      </geometry>
      <material name="grey"><color rgba="0.7 0.7 0.7 1"/> </material>
    </visual>
    <collision>
      <origin rpy="0 0 0" xyz="0 0 0"/>
      <geometry>
        <mesh filename="package://schunk_description/meshes/sdh/knuckle.stl"/>
      </geometry>
    </collision>
  </link>
  <joint name="sdh_thumb_2_joint" type="revolute">
    <origin rpy="0 0 0" xyz="0 0 0.0165"/>
    <parent link="sdh_thumb_1_link"/>
    <child link="sdh_thumb_2_link"/>
    <axis xyz="0 1 0"/>
    <dynamics damping="1"/>
    <limit effort="100" lower="-1.570796327" upper="1.570796327" velocity="5"/>
  </joint>
  <link name="sdh_thumb_2_link">
    <inertial>
      <origin rpy="0 0 0" xyz="0 0 0"/>
      <mass value="0.1"/>
      <inertia ixx="0.01" ixy="0" ixz="0" iyy="0.01" iyz="0" izz="0.01"/>
    </inertial>
    <visual>
      <origin rpy="0 0 0" xyz="0 0 0"/>
      <geometry>
        <mesh filename="package://schunk_description/meshes/sdh/finger.stl"/>
      </geometry>
      <material name="grey"><color rgba="0.7 0.7 0.7 1"/> </material>
    </visual>
    <collision>
      <origin rpy="0 0 0" xyz="0 0 0"/>
      <geometry>
        <mesh filename="package://schunk_description/meshes/sdh/finger.stl"/>
      </geometry>
    </collision>
  </link>
  <joint name="sdh_thumb_3_joint" type="revolute">
    <origin rpy="0 0 0" xyz="0 0 0.0865"/>
    <parent link="sdh_thumb_2_link"/>
    <child link="sdh_thumb_3_link"/>
    <axis xyz="0 1 0"/>
    <dynamics damping="1"/>
    <limit effort="100" lower="-1.570796327" upper="1.570796327" velocity="5"/>
  </joint>
  <link name="sdh_thumb_3_link">
    <inertial>
      <origin rpy="0 0 0" xyz="0 0 0"/>
      <mass value="0.1"/>
      <inertia ixx="0.01" ixy="0" ixz="0" iyy="0.01" iyz="0" izz="0.01"/>
    </inertial>
    <visual>
      <origin rpy="0 0 0" xyz="0 0 0"/>
      <geometry>
        <mesh filename="package://schunk_description/meshes/sdh/finger_tip.stl"/>
      </geometry>
      <material name="grey"><color rgba="0.7 0.7 0.7 1"/> </material>
    </visual>
    <collision>
      <origin rpy="0 0 0" xyz="0 0 0"/>
      <geometry>
        <mesh filename="package://schunk_description/meshes/sdh/finger_tip.stl"/>
      </geometry>
    </collision>
  </link>
  <gazebo reference="sdh_palm_link">
    <material>Schunk/LightGrey</material>
    <turnGravityOff>false</turnGravityOff>
  </gazebo>
  <gazebo reference="sdh_finger_11_link">
    <material>Schunk/LightGrey</material>
    <turnGravityOff>false</turnGravityOff>
  </gazebo>
  <gazebo reference="sdh_finger_12_link">
    <selfCollide>true</selfCollide>
    <sensor name="sdh_finger_12_contact_sensor" type="contact">
      <always_on>true</always_on>
      <update_rate>100</update_rate>
      <contact>
        <collision>sdh_finger_12_link_geom</collision>
      </contact>
      <plugin filename="libgazebo_ros_bumper.so" name="sdh_finger_12_gazebo_ros_bumper_controller">
        <alwaysOn>true</alwaysOn>
        <updateRate>100.0</updateRate>
        <frameName>sdh_finger_12_link</frameName>
        <bumperTopicName>sdh_finger_12_bumper</bumperTopicName>
      </plugin>
    </sensor>
    <material>Schunk/LightGrey</material>
    <turnGravityOff>false</turnGravityOff>
  </gazebo>
  <gazebo reference="sdh_finger_13_link">
    <selfCollide>true</selfCollide>
    <sensor name="sdh_finger_13_contact_sensor" type="contact">
      <always_on>true</always_on>
      <update_rate>100</update_rate>
      <contact>
        <collision>sdh_finger_13_link_geom</collision>
      </contact>
      <plugin filename="libgazebo_ros_bumper.so" name="sdh_finger_13_gazebo_ros_bumper_controller">
        <alwaysOn>true</alwaysOn>
        <updateRate>100.0</updateRate>
        <frameName>sdh_finger_13_link</frameName>
        <bumperTopicName>sdh_finger_13_bumper</bumperTopicName>
      </plugin>
    </sensor>
    <material>Schunk/LightGrey</material>
  </gazebo>
  <gazebo reference="sdh_finger_21_link">
    <material>Schunk/LightGrey</material>
    <turnGravityOff>true</turnGravityOff>
    <mu1 value="500"/>
    <mu2 value="500"/>
    <kp value="1000000.0"/>
    <kd value="1.0"/>
  </gazebo>
  <gazebo reference="sdh_finger_22_link">
    <selfCollide>true</selfCollide>
    <sensor name="sdh_finger_22_contact_sensor" type="contact">
      <always_on>true</always_on>
      <update_rate>100</update_rate>
      <contact>
        <collision>sdh_finger_22_link_geom</collision>
      </contact>
      <plugin filename="libgazebo_ros_bumper.so" name="sdh_finger_22_gazebo_ros_bumper_controller">
        <alwaysOn>true</alwaysOn>
        <updateRate>100.0</updateRate>
        <frameName>sdh_finger_22_link</frameName>
        <bumperTopicName>sdh_finger_22_bumper</bumperTopicName>
      </plugin>
    </sensor>
    <material>Schunk/LightGrey</material>
    <turnGravityOff>false</turnGravityOff>
  </gazebo>
  <gazebo reference="sdh_finger_23_link">
    <selfCollide>true</selfCollide>
    <sensor name="sdh_finger_23_contact_sensor" type="contact">
      <always_on>true</always_on>
      <update_rate>100</update_rate>
      <contact>
        <collision>sdh_finger_23_link_geom</collision>
      </contact>
      <plugin filename="libgazebo_ros_bumper.so" name="sdh_finger_23_gazebo_ros_bumper_controller">
        <alwaysOn>true</alwaysOn>
        <updateRate>100.0</updateRate>
        <frameName>sdh_finger_23_link</frameName>
        <bumperTopicName>sdh_finger_23_bumper</bumperTopicName>
      </plugin>
    </sensor>
    <material>Schunk/LightGrey</material>
  </gazebo>
  <gazebo reference="sdh_thumb_1_link">
    <material>Schunk/LightGrey</material>
    <turnGravityOff>false</turnGravityOff>
  </gazebo>
  <gazebo reference="sdh_thumb_2_link">
    <selfCollide>true</selfCollide>
    <sensor name="sdh_thumb_2_contact_sensor" type="contact">
      <always_on>true</always_on>
      <update_rate>100</update_rate>
      <contact>
        <collision>sdh_thumb_2_link_geom</collision>
      </contact>
      <plugin filename="libgazebo_ros_bumper.so" name="sdh_thumb_2_gazebo_ros_bumper_controller">
        <alwaysOn>true</alwaysOn>
        <updateRate>100.0</updateRate>
        <frameName>sdh_thumb_2_link</frameName>
        <bumperTopicName>sdh_thumb_2_bumper</bumperTopicName>
      </plugin>
    </sensor>
    <material>Schunk/LightGrey</material>
    <turnGravityOff>false</turnGravityOff>
  </gazebo>
  <gazebo reference="sdh_thumb_3_link">
    <selfCollide>true</selfCollide>
    <sensor name="sdh_thumb_3_contact_sensor" type="contact">
      <always_on>true</always_on>
      <update_rate>100</update_rate>
      <contact>
        <collision>sdh_thumb_3_link_geom</collision>
      </contact>
      <plugin filename="libgazebo_ros_bumper.so" name="sdh_thumb_3_gazebo_ros_bumper_controller">
        <alwaysOn>true</alwaysOn>
        <updateRate>100.0</updateRate>
        <frameName>sdh_thumb_3_link</frameName>
        <bumperTopicName>sdh_thumb_3_bumper</bumperTopicName>
      </plugin>
    </sensor>
    <material>Schunk/LightGrey</material>
  </gazebo>
  <gazebo reference="sdh_finger_21_joint">
    <stopKd value="1.0"/>
    <stopKp value="10000000"/>
    <fudgeFactor value="1.0"/>
    <provideFeedback value="true"/>
  </gazebo>
  <transmission name="sdh_knuckle_trans">
    <type>transmission_interface/SimpleTransmission</type>
    <joint name="sdh_finger_21_joint"/>
    <actuator name="sdh_knuckle_motor">
      <hardwareInterface>EffortJointInterface</hardwareInterface>
      <mechanicalReduction>1</mechanicalReduction>
    </actuator>
  </transmission>
  <transmission name="sdh_knuckle_trans">
    <type>transmission_interface/SimpleTransmission</type>
    <joint name="sdh_knuckle_joint"/>
    <actuator name="sdh_knuckle_motor">
      <hardwareInterface>EffortJointInterface</hardwareInterface>
      <mechanicalReduction>1</mechanicalReduction>
    </actuator>
  </transmission>
  <transmission name="sdh_finger_12_trans">
    <type>transmission_interface/SimpleTransmission</type>
    <joint name="sdh_finger_12_joint"/>
    <actuator name="sdh_finger_12_motor">
      <hardwareInterface>EffortJointInterface</hardwareInterface>
      <mechanicalReduction>1</mechanicalReduction>
    </actuator>
  </transmission>
  <transmission name="sdh_finger_13_trans">
    <type>transmission_interface/SimpleTransmission</type>
    <joint name="sdh_finger_13_joint"/>
    <actuator name="sdh_finger_13_motor">
      <hardwareInterface>EffortJointInterface</hardwareInterface>
      <mechanicalReduction>1</mechanicalReduction>
    </actuator>
  </transmission>
  <transmission name="sdh_finger_22_trans">
    <type>transmission_interface/SimpleTransmission</type>
    <joint name="sdh_finger_22_joint"/>
    <actuator name="sdh_finger_22_motor">
      <hardwareInterface>EffortJointInterface</hardwareInterface>
      <mechanicalReduction>1</mechanicalReduction>
    </actuator>
  </transmission>
  <transmission name="sdh_finger_23_trans">
    <type>transmission_interface/SimpleTransmission</type>
    <joint name="sdh_finger_23_joint"/>
    <actuator name="sdh_finger_23_motor">
      <hardwareInterface>EffortJointInterface</hardwareInterface>
      <mechanicalReduction>1</mechanicalReduction>
    </actuator>
  </transmission>
  <transmission name="sdh_thumb_2_trans">
    <type>transmission_interface/SimpleTransmission</type>
    <joint name="sdh_thumb_2_joint"/>
    <actuator name="sdh_thumb_2_motor">
      <hardwareInterface>EffortJointInterface</hardwareInterface>
      <mechanicalReduction>1</mechanicalReduction>
    </actuator>
  </transmission>
  <transmission name="sdh_thumb_3_trans">
    <type>transmission_interface/SimpleTransmission</type>
    <joint name="sdh_thumb_3_joint"/>
    <actuator name="sdh_thumb_3_motor">
      <hardwareInterface>EffortJointInterface</hardwareInterface>
      <mechanicalReduction>1</mechanicalReduction>
    </actuator>
  </transmission>
</robot>

