<!-- =================================================================================== -->
<!-- |    This document was autogenerated by xacro from ../components/osrf_original/atlas_v5.urdf | -->
<!-- |    EDITING THIS FILE BY HAND IS NOT RECOMMENDED                                 | -->
<!-- =================================================================================== -->
<robot name="drc_skeleton">
  <link name="l_clav">
    <inertial>
      <mass value="4.466"/>
      <origin rpy="0 0 0" xyz="0 0 -0.084"/>
      <inertia ixx="0.011" ixy="0" ixz="0" iyy="0.009" iyz="0.004" izz="0.004"/>
    </inertial>
    <visual>
      <geometry>
        <mesh filename="package://atlas_v5/meshes/r_clav.obj"/>
      </geometry>
    </visual>
    <collision>
      <geometry>
        <mesh filename="package://atlas_v5/meshes/r_clav_chull.obj"/>
      </geometry>
    </collision>
    </link>
  <link name="l_foot">
    <inertial>
      <mass value="2.410"/>
      <origin rpy="0 0 0" xyz="0.027 0 -0.067"/>
      <inertia ixx="0.002" ixy="0" ixz="0" iyy="0.007" iyz="0" izz="0.008"/>
    </inertial>
    <visual>
      <geometry>
        <mesh filename="package://atlas_v5/meshes/l_foot.obj"/>
      </geometry>
    </visual>
    <collision>
      <geometry>
        <mesh filename="package://atlas_v5/meshes/l_foot_chull.obj"/>
      </geometry>
    </collision>
    <collision group="heel"><origin rpy="0 0 0" xyz="-0.0876 0.066 -0.07645"/><geometry><sphere radius="0.0"/></geometry></collision><visual group="heel"><origin rpy="0 0 0" xyz="-0.0876 0.066 -0.07645"/><geometry><sphere radius="0.01"/></geometry></visual><collision group="heel"><origin rpy="0 0 0" xyz="-0.0876 -0.0626 -0.07645"/><geometry><sphere radius="0.0"/></geometry></collision><visual group="heel"><origin rpy="0 0 0" xyz="-0.0876 -0.0626 -0.07645"/><geometry><sphere radius="0.01"/></geometry></visual><collision group="toe"><origin rpy="0 0 0" xyz="0.1728 0.066 -0.07645"/><geometry><sphere radius="0.0"/></geometry></collision><visual group="toe"><origin rpy="0 0 0" xyz="0.1728 0.066 -0.07645"/><geometry><sphere radius="0.01"/></geometry></visual><collision group="toe"><origin rpy="0 0 0" xyz="0.1728 -0.0626 -0.07645"/><geometry><sphere radius="0.0"/></geometry></collision><visual group="toe"><origin rpy="0 0 0" xyz="0.1728 -0.0626 -0.07645"/><geometry><sphere radius="0.01"/></geometry></visual><collision group="midfoot"><origin rpy="0 0 0" xyz="0.0426 0.066 -0.07645"/><geometry><sphere radius="0.0"/></geometry></collision><visual group="midfoot"><origin rpy="0 0 0" xyz="0.0426 0.066 -0.07645"/><geometry><sphere radius="0.01"/></geometry></visual><collision group="midfoot"><origin rpy="0 0 0" xyz="0.0426 -0.0626 -0.07645"/><geometry><sphere radius="0.0"/></geometry></collision><visual group="midfoot"><origin rpy="0 0 0" xyz="0.0426 -0.0626 -0.07645"/><geometry><sphere radius="0.01"/></geometry></visual></link>
  <link name="l_hand">
    <inertial>
      <mass value="0.5839"/>
      <origin rpy="0 0 0" xyz="0.00016 -0.08159 0.00002"/>
      <inertia ixx="0.000388" ixy="0" ixz="0" iyy="0.000477" iyz="0" izz="0.000379"/>
    </inertial>
  </link>
  <link name="l_larm">
    <inertial>
      <mass value="3.248"/>
      <origin rpy="0 0 0" xyz="0 0 0"/>
      <inertia ixx="0.00265" ixy="0" ixz="0" iyy="0.00446" iyz="0" izz="0.00446"/>
    </inertial>
    <visual>
      <geometry>
        <mesh filename="package://atlas_v5/meshes/r_larm.obj"/>
      </geometry>
    </visual>
    <collision>
      <geometry>
        <mesh filename="package://atlas_v5/meshes/r_larm_chull.obj"/>
      </geometry>
    </collision>
    </link>
  <link name="l_lfarm">
    <inertial>
      <mass value="0.648"/>
      <origin rpy="0 0 0" xyz="0.00017 -0.02515 0.00163"/>
      <inertia ixx="0.000764" ixy="0" ixz="0" iyy="0.000429" iyz="0" izz="0.000825"/>
    </inertial>
    <visual>
      <geometry>
        <mesh filename="package://atlas_v5/meshes/r_hand.obj"/>
      </geometry>
    </visual>
    <collision>
      <geometry>
        <mesh filename="package://atlas_v5/meshes/r_hand_chull.obj"/>
      </geometry>
    </collision>
    </link>
  <link name="l_lglut">
    <inertial>
      <mass value="0.898"/>
      <origin rpy="0 0 0" xyz="0.0133341 0.0170484 -0.0312052"/>
      <inertia ixx="0.000691326" ixy="-2.24344e-05" ixz="2.50508e-06" iyy="0.00126856" iyz="0.000137862" izz="0.00106487"/>
    </inertial>
    <visual>
      <geometry>
        <mesh filename="package://atlas_v5/meshes/l_lglut.obj"/>
      </geometry>
    </visual>
    <collision>
      <geometry>
        <mesh filename="package://atlas_v5/meshes/l_lglut_chull.obj"/>
      </geometry>
    </collision>
    </link>
  <link name="l_lleg">
    <inertial>
      <mass value="4.515"/>
      <origin rpy="0 0 0" xyz="0.001 0 -0.187"/>
      <inertia ixx="0.077" ixy="0" ixz="-0.003" iyy="0.076" iyz="0" izz="0.01"/>
    </inertial>
    <visual>
      <geometry>
        <mesh filename="package://atlas_v5/meshes/l_lleg.obj"/>
      </geometry>
    </visual>
    <collision>
      <geometry>
        <mesh filename="package://atlas_v5/meshes/l_lleg_chull.obj"/>
      </geometry>
    </collision>
    </link>
  <link name="l_scap">
    <inertial>
      <mass value="3.899"/>
      <origin rpy="0 0 0" xyz="0 0 0"/>
      <inertia ixx="0.00319" ixy="0" ixz="0" iyy="0.00583" iyz="0" izz="0.00583"/>
    </inertial>
    <visual>
      <geometry>
        <mesh filename="package://atlas_v5/meshes/r_scap.obj"/>
      </geometry>
    </visual>
    <collision>
      <geometry>
        <mesh filename="package://atlas_v5/meshes/r_scap_chull.obj"/>
      </geometry>
    </collision>
    </link>
  <link name="l_talus">
    <inertial>
      <mass value="0.125"/>
      <origin rpy="0 0 0" xyz="0 0 0"/>
      <inertia ixx="1.01674e-05" ixy="0" ixz="0" iyy="8.42775e-06" iyz="0" izz="1.30101e-05"/>
    </inertial>
    <visual>
      <geometry>
        <mesh filename="package://atlas_v5/meshes/l_talus.obj"/>
      </geometry>
    </visual>
    </link>
  <link name="l_uarm">
    <inertial>
      <mass value="4.386"/>
      <origin rpy="0 0 0" xyz="0 0.065 0"/>
      <inertia ixx="0.00656" ixy="0" ixz="0" iyy="0.00358" iyz="0" izz="0.00656"/>
    </inertial>
    <visual>
      <geometry>
        <mesh filename="package://atlas_v5/meshes/r_uarm.obj"/>
      </geometry>
    </visual>
    <collision>
      <geometry>
        <mesh filename="package://atlas_v5/meshes/r_uarm_chull.obj"/>
      </geometry>
    </collision>
    </link>
  <link name="l_ufarm">
    <inertial>
      <mass value="2.4798"/>
      <origin rpy="0 0 0" xyz="0.00015 0.08296 0.00037"/>
      <inertia ixx="0.012731" ixy="0" ixz="0" iyy="0.002857" iyz="0" izz="0.011948"/>
    </inertial>
    <visual>
      <geometry>
        <mesh filename="package://atlas_v5/meshes/r_farm.obj"/>
      </geometry>
    </visual>
    <collision>
      <geometry>
        <mesh filename="package://atlas_v5/meshes/r_farm_chull.obj"/>
      </geometry>
    </collision>
    </link>
  <link name="l_uglut">
    <inertial>
      <mass value="1.959"/>
      <origin rpy="0 0 0" xyz="0.00529262 -0.00344732 0.00313046"/>
      <inertia ixx="0.00074276" ixy="-3.79607e-08" ixz="-2.79549e-05" iyy="0.000688179" iyz="-3.2735e-08" izz="0.00041242"/>
    </inertial>
    <visual>
      <geometry>
        <mesh filename="package://atlas_v5/meshes/l_uglut.obj"/>
      </geometry>
    </visual>
    <collision>
      <geometry>
        <mesh filename="package://atlas_v5/meshes/l_uglut_chull.obj"/>
      </geometry>
    </collision>
    </link>
  <link name="l_uleg">
    <inertial>
      <mass value="8.204"/>
      <origin rpy="0 0 0" xyz="0 0 -0.21"/>
      <inertia ixx="0.09" ixy="0" ixz="0" iyy="0.09" iyz="0" izz="0.02"/>
    </inertial>
    <visual>
      <geometry>
        <mesh filename="package://atlas_v5/meshes/l_uleg.obj"/>
      </geometry>
    </visual>
    <!-- to cover the logo shield -->
    <!-- inside strut -->
    <!-- outside strut -->
    <collision>
      <geometry>
        <mesh filename="package://atlas_v5/meshes/l_uleg_chull.obj"/>
      </geometry>
    </collision>
    </link>
  <link name="ltorso">
    <inertial>
      <mass value="2.270"/>
      <origin rpy="0 0 0" xyz="-0.0112984 -3.15366e-06 0.0746835"/>
      <inertia ixx="0.0039092" ixy="-5.04491e-08" ixz="-0.000342157" iyy="0.00341694" iyz="4.87119e-07" izz="0.00174492"/>
    </inertial>
    <visual>
      <geometry>
        <mesh filename="package://atlas_v5/meshes/ltorso.obj"/>
      </geometry>
    </visual>
  </link>
  <link name="mtorso">
    <inertial>
      <mass value="0.799"/>
      <origin rpy="0 0 0" xyz="-0.00816266 -0.0131245 0.0305974"/>
      <inertia ixx="0.000454181" ixy="-6.10764e-05" ixz="3.94009e-05" iyy="0.000483282" iyz="5.27463e-05" izz="0.000444215"/>
    </inertial>
    <visual>
      <geometry>
        <mesh filename="package://atlas_v5/meshes/mtorso.obj"/>
      </geometry>
    </visual>
    </link>
  <link name="pelvis">
    <inertial>
      <mass value="9.509"/>
      <origin rpy="0 0 0" xyz="0.0111 0 0.0271"/>
      <inertia ixx="0.1244" ixy="0.0008" ixz="-0.0007" iyy="0.0958" iyz="-0.0005" izz="0.1167"/>
    </inertial>
    <visual>
      <geometry>
        <mesh filename="package://atlas_v5/meshes/pelvis.obj"/>
      </geometry>
    </visual>
    <collision>
      <geometry>
        <mesh filename="package://atlas_v5/meshes/pelvis_chull.obj"/>
      </geometry>
    </collision>
    </link>
  <link name="r_clav">
    <inertial>
      <mass value="4.466"/>
      <origin rpy="0 0 0" xyz="0 0 -0.084"/>
      <inertia ixx="0.011" ixy="0" ixz="0" iyy="0.009" iyz="0.004" izz="0.004"/>
    </inertial>
    <visual>
      <geometry>
        <mesh filename="package://atlas_v5/meshes/r_clav.obj"/>
      </geometry>
    </visual>
    <collision>
      <geometry>
        <mesh filename="package://atlas_v5/meshes/r_clav_chull.obj"/>
      </geometry>
    </collision>
    </link>
  <link name="r_foot">
    <inertial>
      <mass value="2.41"/>
      <origin rpy="0 0 0" xyz="0.027 0 -0.067"/>
      <inertia ixx="0.002" ixy="0" ixz="0" iyy="0.007" iyz="0" izz="0.008"/>
    </inertial>
    <visual>
      <geometry>
        <mesh filename="package://atlas_v5/meshes/r_foot.obj"/>
      </geometry>
    </visual>
    <collision>
      <geometry>
        <mesh filename="package://atlas_v5/meshes/r_foot_chull.obj"/>
      </geometry>
    </collision>
    <collision group="heel"><origin rpy="0 0 0" xyz="-0.0876 0.0626 -0.07645"/><geometry><sphere radius="0.0"/></geometry></collision><visual group="heel"><origin rpy="0 0 0" xyz="-0.0876 0.0626 -0.07645"/><geometry><sphere radius="0.01"/></geometry></visual><collision group="heel"><origin rpy="0 0 0" xyz="-0.0876 -0.066 -0.07645"/><geometry><sphere radius="0.0"/></geometry></collision><visual group="heel"><origin rpy="0 0 0" xyz="-0.0876 -0.066 -0.07645"/><geometry><sphere radius="0.01"/></geometry></visual><collision group="toe"><origin rpy="0 0 0" xyz="0.1728 0.0626 -0.07645"/><geometry><sphere radius="0.0"/></geometry></collision><visual group="toe"><origin rpy="0 0 0" xyz="0.1728 0.0626 -0.07645"/><geometry><sphere radius="0.01"/></geometry></visual><collision group="toe"><origin rpy="0 0 0" xyz="0.1728 -0.066 -0.07645"/><geometry><sphere radius="0.0"/></geometry></collision><visual group="toe"><origin rpy="0 0 0" xyz="0.1728 -0.066 -0.07645"/><geometry><sphere radius="0.01"/></geometry></visual><collision group="midfoot"><origin rpy="0 0 0" xyz="0.0426 0.0626 -0.07645"/><geometry><sphere radius="0.0"/></geometry></collision><visual group="midfoot"><origin rpy="0 0 0" xyz="0.0426 0.0626 -0.07645"/><geometry><sphere radius="0.01"/></geometry></visual><collision group="midfoot"><origin rpy="0 0 0" xyz="0.0426 -0.066 -0.07645"/><geometry><sphere radius="0.0"/></geometry></collision><visual group="midfoot"><origin rpy="0 0 0" xyz="0.0426 -0.066 -0.07645"/><geometry><sphere radius="0.01"/></geometry></visual></link>
  <link name="r_hand">
    <inertial>
      <mass value="0.5839"/>
      <origin rpy="0 0 0" xyz="0.00016 -0.08159 0.00002"/>
      <inertia ixx="0.000388" ixy="0" ixz="0" iyy="0.000477" iyz="0" izz="0.000379"/>
    </inertial>
  </link>
  <link name="r_larm">
    <inertial>
      <mass value="3.248"/>
      <origin rpy="0 0 0" xyz="0 0 0"/>
      <inertia ixx="0.00265" ixy="0" ixz="0" iyy="0.00446" iyz="0" izz="0.00446"/>
    </inertial>
    <visual>
      <geometry>
        <mesh filename="package://atlas_v5/meshes/r_larm.obj"/>
      </geometry>
    </visual>
    <collision>
      <geometry>
        <mesh filename="package://atlas_v5/meshes/r_larm_chull.obj"/>
      </geometry>
    </collision>
    </link>
  <link name="r_lfarm">
    <inertial>
      <mass value="0.648"/>
      <origin rpy="0 0 0" xyz="0.00017 -0.02515 0.00163"/>
      <inertia ixx="0.000764" ixy="0" ixz="0" iyy="0.000429" iyz="0" izz="0.000825"/>
    </inertial>
    <visual>
      <geometry>
        <mesh filename="package://atlas_v5/meshes/r_hand.obj"/>
      </geometry>
    </visual>
    <collision>
      <geometry>
        <mesh filename="package://atlas_v5/meshes/r_hand_chull.obj"/>
      </geometry>
    </collision>
    </link>
  <link name="r_lglut">
    <inertial>
      <mass value="0.898"/>
      <origin rpy="0 0 0" xyz="0.0133341 -0.0170484 -0.0312052"/>
      <inertia ixx="0.000691326" ixy="2.24344e-05" ixz="2.50508e-06" iyy="0.00126856" iyz="-0.000137862" izz="0.00106487"/>
    </inertial>
    <visual>
      <geometry>
        <mesh filename="package://atlas_v5/meshes/r_lglut.obj"/>
      </geometry>
    </visual>
    <collision>
      <geometry>
        <mesh filename="package://atlas_v5/meshes/r_lglut_chull.obj"/>
      </geometry>
    </collision>
    </link>
  <link name="r_lleg">
    <inertial>
      <mass value="4.515"/>
      <origin rpy="0 0 0" xyz="0.001 0 -0.187"/>
      <inertia ixx="0.077" ixy="-0" ixz="-0.003" iyy="0.076" iyz="-0" izz="0.01"/>
    </inertial>
    <visual>
      <geometry>
        <mesh filename="package://atlas_v5/meshes/r_lleg.obj"/>
      </geometry>
    </visual>
    <collision>
      <geometry>
        <mesh filename="package://atlas_v5/meshes/r_lleg_chull.obj"/>
      </geometry>
    </collision>
    </link>
  <link name="r_scap">
    <inertial>
      <mass value="3.899"/>
      <origin rpy="0 0 0" xyz="0 0 0"/>
      <inertia ixx="0.00319" ixy="0" ixz="0" iyy="0.00583" iyz="0" izz="0.00583"/>
    </inertial>
    <visual>
      <geometry>
        <mesh filename="package://atlas_v5/meshes/r_scap.obj"/>
      </geometry>
    </visual>
    <collision>
      <geometry>
        <mesh filename="package://atlas_v5/meshes/r_scap_chull.obj"/>
      </geometry>
    </collision>
    </link>
  <link name="r_talus">
    <inertial>
      <mass value="0.125"/>
      <origin rpy="0 0 0" xyz="0 0 0"/>
      <inertia ixx="1.01674e-05" ixy="0" ixz="0" iyy="8.42775e-06" iyz="0" izz="1.30101e-05"/>
    </inertial>
    <visual>
      <geometry>
        <mesh filename="package://atlas_v5/meshes/r_talus.obj"/>
      </geometry>
    </visual>
    </link>
  <link name="r_uarm">
    <inertial>
      <mass value="4.386"/>
      <origin rpy="0 0 0" xyz="0 0.065 0"/>
      <inertia ixx="0.00656" ixy="0" ixz="0" iyy="0.00358" iyz="0" izz="0.00656"/>
    </inertial>
    <visual>
      <geometry>
        <mesh filename="package://atlas_v5/meshes/r_uarm.obj"/>
      </geometry>
    </visual>
    <collision>
      <geometry>
        <mesh filename="package://atlas_v5/meshes/r_uarm_chull.obj"/>
      </geometry>
    </collision>
    </link>
  <link name="r_ufarm">
    <inertial>
      <mass value="2.4798"/>
      <origin rpy="0 0 0" xyz="0.00015 0.08296 0.00037"/>
      <inertia ixx="0.012731" ixy="0" ixz="0" iyy="0.002857" iyz="0" izz="0.011948"/>
    </inertial>
    <visual>
      <geometry>
        <mesh filename="package://atlas_v5/meshes/r_farm.obj"/>
      </geometry>
    </visual>
    <collision>
      <geometry>
        <mesh filename="package://atlas_v5/meshes/r_farm_chull.obj"/>
      </geometry>
    </collision>
    </link>
  <link name="r_uglut">
    <inertial>
      <mass value="1.959"/>
      <origin rpy="0 0 0" xyz="0.00529262 0.00344732 0.00313046"/>
      <inertia ixx="0.00074276" ixy="3.79607e-08" ixz="-2.79549e-05" iyy="0.000688179" iyz="3.2735e-08" izz="0.00041242"/>
    </inertial>
    <visual>
      <geometry>
        <mesh filename="package://atlas_v5/meshes/r_uglut.obj"/>
      </geometry>
    </visual>
    <collision>
      <geometry>
        <mesh filename="package://atlas_v5/meshes/r_uglut_chull.obj"/>
      </geometry>
    </collision>
    </link>
  <link name="r_uleg">
    <inertial>
      <mass value="8.204"/>
      <origin rpy="0 0 0" xyz="0 0 -0.21"/>
      <inertia ixx="0.09" ixy="0" ixz="0" iyy="0.09" iyz="0" izz="0.02"/>
    </inertial>
    <visual>
      <geometry>
        <mesh filename="package://atlas_v5/meshes/r_uleg.obj"/>
      </geometry>
    </visual>
    <!-- to cover the logo shield -->
    <!-- inside strut -->
    <!-- outside strut -->
    <collision>
      <geometry>
        <mesh filename="package://atlas_v5/meshes/r_uleg_chull.obj"/>
      </geometry>
    </collision>
    </link>
  <link name="utorso">
    <inertial>
      <mass value="84.409"/>
      <origin rpy="0 0 0" xyz="-0.0622 0.0023 0.3157"/>
      <inertia ixx="1.577" ixy="-0.032" ixz="0.102" iyy="1.602" iyz="0.047" izz="0.565"/>
    </inertial>
    <visual>
      <geometry>
        <mesh filename="package://atlas_v5/meshes/utorso.obj"/>
      </geometry>
    </visual>
    <collision>
      <geometry>
        <mesh filename="package://atlas_v5/meshes/utorso_chull.obj"/>
      </geometry>
    </collision>
    </link>
  <joint name="back_bkx" type="revolute">
    <origin rpy="0 0 0" xyz="0 0 0.05"/>
    <axis xyz="1 0 0"/>
    <parent link="mtorso"/>
    <child link="utorso"/>
    <dynamics damping="0.1" friction="0"/>
    <limit effort="300" lower="-0.523599" upper="0.523599" velocity="12"/>
    <safety_controller k_position="100" k_velocity="100" soft_lower_limit="-10.5236" soft_upper_limit="10.5236"/>
  </joint>
  <joint name="back_bky" type="revolute">
    <origin rpy="0 0 0" xyz="0 0 0.162"/>
    <axis xyz="0 1 0"/>
    <parent link="ltorso"/>
    <child link="mtorso"/>
    <dynamics damping="0.1" friction="0"/>
    <limit effort="445" lower="-0.219388" upper="0.538783" velocity="9"/>
    <safety_controller k_position="100" k_velocity="100" soft_lower_limit="-10.2194" soft_upper_limit="10.5388"/>
  </joint>
  <joint name="back_bkz" type="revolute">
    <origin rpy="0 0 0" xyz="-0.0125 0 0"/>
    <axis xyz="0 0 1"/>
    <parent link="pelvis"/>
    <child link="ltorso"/>
    <dynamics damping="0.1" friction="0"/>
    <limit effort="106" lower="-0.663225" upper="0.663225" velocity="12"/>
    <safety_controller k_position="100" k_velocity="100" soft_lower_limit="-10.6632" soft_upper_limit="10.6632"/>
  </joint>
  <joint name="l_arm_elx" type="revolute">
    <origin rpy="0 0 0" xyz="0 -0.119 0.0092"/>
    <axis xyz="-1.0 -0.0 -0.0"/>
    <parent link="l_uarm"/>
    <child link="l_larm"/>
    <dynamics damping="0.1" friction="0"/>
    <limit effort="112" lower="0" upper="2.35619" velocity="12"/>
    <safety_controller k_position="100" k_velocity="100" soft_lower_limit="-10" soft_upper_limit="12.3562"/>
  </joint>
  <joint name="l_arm_ely" type="revolute">
    <origin rpy="0 0 0" xyz="0 -0.187 -0.016"/>
    <axis xyz="-0.0 -1.0 -0.0"/>
    <parent link="l_scap"/>
    <child link="l_uarm"/>
    <dynamics damping="0.1" friction="0"/>
    <limit effort="63" lower="0" upper="3.14159" velocity="12"/>
    <safety_controller k_position="100" k_velocity="100" soft_lower_limit="-10" soft_upper_limit="13.1416"/>
  </joint>
  <joint name="l_arm_shx" type="revolute">
    <origin rpy="0 0 0" xyz="0 -0.11 -0.245"/>
    <axis xyz="-1.0 -0.0 -0.0"/>
    <parent link="l_clav"/>
    <child link="l_scap"/>
    <dynamics damping="0.1" friction="0"/>
    <limit effort="99" lower="-1.5708" upper="1.5708" velocity="12"/>
    <safety_controller k_position="100" k_velocity="100" soft_lower_limit="-11.5708" soft_upper_limit="11.5708"/>
  </joint>
  <joint name="l_arm_shz" type="revolute">
    <origin rpy="0 0 3.14159265359" xyz="0.1406 0.2256 0.4776"/>
    <axis xyz="0 0 1"/>
    <parent link="utorso"/>
    <child link="l_clav"/>
    <dynamics damping="0.1" friction="0"/>
    <limit effort="87" lower="-1.5708" upper="0.785398" velocity="12"/>
    <safety_controller k_position="100" k_velocity="100" soft_lower_limit="-11.5708" soft_upper_limit="10.7854"/>
  </joint>
  <joint name="l_arm_mwx" type="revolute">
    <origin rpy="0 0 0" xyz="0 0 0"/>
    <axis xyz="1 0 0"/>
    <parent link="l_ufarm"/>
    <child link="l_lfarm"/>
    <dynamics damping="0.1" friction="0"/>
    <limit effort="25" lower="-1.7628" upper="1.7628" velocity="10"/>
    <safety_controller k_position="100" k_velocity="100" soft_lower_limit="-11.7628" soft_upper_limit="11.7628"/>
  </joint>
  <joint name="l_arm_uwy" type="revolute">
    <origin rpy="0 3.14159265359 0" xyz="0 -0.29955 -0.00921"/>
    <axis xyz="-0.0 -1.0 -0.0"/>
    <parent link="l_larm"/>
    <child link="l_ufarm"/>
    <dynamics damping="0.1" friction="0"/>
    <limit effort="25" lower="-3.011" upper="3.011" velocity="10"/>
    <safety_controller k_position="100" k_velocity="100" soft_lower_limit="-13.011" soft_upper_limit="13.011"/>
  </joint>
  <joint name="l_arm_lwy" type="revolute">
    <origin rpy="0 3.14159265359 0" xyz="0 0 0"/>
    <axis xyz="-0.0 -1.0 -0.0"/>
    <parent link="l_lfarm"/>
    <child link="l_hand"/>
    <dynamics damping="0.1" friction="0"/>
    <limit effort="25" lower="-2.9671" upper="2.9671" velocity="10"/>
    <safety_controller k_position="100" k_velocity="100" soft_lower_limit="-12.9671" soft_upper_limit="12.9671"/>
  </joint>
  <joint name="l_leg_akx" type="revolute">
    <origin rpy="0 0 0" xyz="0 0 0"/>
    <axis xyz="1 0 0"/>
    <parent link="l_talus"/>
    <child link="l_foot"/>
    <dynamics damping="0.1" friction="0"/>
    <limit effort="360" lower="-0.8" upper="0.8" velocity="12"/>
    <safety_controller k_position="100" k_velocity="100" soft_lower_limit="-10.8" soft_upper_limit="10.8"/>
  </joint>
  <joint name="l_leg_aky" type="revolute">
    <origin rpy="0 0 0" xyz="0 0 -0.422"/>
    <axis xyz="0 1 0"/>
    <parent link="l_lleg"/>
    <child link="l_talus"/>
    <dynamics damping="0.1" friction="0"/>
    <limit effort="740" lower="-1" upper="0.7" velocity="12"/>
    <safety_controller k_position="100" k_velocity="100" soft_lower_limit="-11" soft_upper_limit="10.7"/>
  </joint>
  <joint name="l_leg_hpx" type="revolute">
    <origin rpy="0 0 0" xyz="0 0 0"/>
    <axis xyz="1 0 0"/>
    <parent link="l_uglut"/>
    <child link="l_lglut"/>
    <dynamics damping="0.1" friction="0"/>
    <limit effort="530" lower="-0.523599" upper="0.523599" velocity="12"/>
    <safety_controller k_position="100" k_velocity="100" soft_lower_limit="-10.5236" soft_upper_limit="10.5236"/>
  </joint>
  <joint name="l_leg_hpy" type="revolute">
    <origin rpy="0 0 0" xyz="0.05 0.0225 -0.066"/>
    <axis xyz="0 1 0"/>
    <parent link="l_lglut"/>
    <child link="l_uleg"/>
    <dynamics damping="0.1" friction="0"/>
    <limit effort="840" lower="-1.61234" upper="0.65764" velocity="12"/>
    <safety_controller k_position="100" k_velocity="100" soft_lower_limit="-11.6123" soft_upper_limit="10.6576"/>
  </joint>
  <joint name="l_leg_hpz" type="revolute">
    <origin rpy="0 0 0" xyz="0 0.089 0"/>
    <axis xyz="0 0 1"/>
    <parent link="pelvis"/>
    <child link="l_uglut"/>
    <dynamics damping="0.1" friction="0"/>
    <limit effort="275" lower="-0.174358" upper="0.786794" velocity="12"/>
    <safety_controller k_position="100" k_velocity="100" soft_lower_limit="-10.1744" soft_upper_limit="10.7868"/>
  </joint>
  <joint name="l_leg_kny" type="revolute">
    <origin rpy="0 0 0" xyz="-0.05 0 -0.374"/>
    <axis xyz="0 1 0"/>
    <parent link="l_uleg"/>
    <child link="l_lleg"/>
    <dynamics damping="0.1" friction="0"/>
    <limit effort="890" lower="0" upper="2.35637" velocity="12"/>
    <safety_controller k_position="100" k_velocity="100" soft_lower_limit="-10" soft_upper_limit="12.3564"/>
  </joint>
  <joint name="neck_ay" type="revolute">
    <origin rpy="0 0 0" xyz="0.2546 0 0.6215"/>
    <axis xyz="0 1 0"/>
    <parent link="utorso"/>
    <child link="head"/>
    <dynamics damping="0.1" friction="0"/>
    <limit effort="25" lower="-0.602139" upper="1.14319" velocity="6.28"/>
    <safety_controller k_position="100" k_velocity="100" soft_lower_limit="-10.6021" soft_upper_limit="11.1432"/>
  </joint>
  <joint name="r_arm_elx" type="revolute">
    <origin rpy="0 0 0" xyz="0 -0.119 0.0092"/>
    <axis xyz="1 0 0"/>
    <parent link="r_uarm"/>
    <child link="r_larm"/>
    <dynamics damping="0.1" friction="0"/>
    <limit effort="112" lower="-2.35619" upper="0" velocity="12"/>
    <safety_controller k_position="100" k_velocity="100" soft_lower_limit="-12.3562" soft_upper_limit="10"/>
  </joint>
  <joint name="r_arm_ely" type="revolute">
    <origin rpy="0 0 0" xyz="0 -0.187 -0.016"/>
    <axis xyz="0 1 0"/>
    <parent link="r_scap"/>
    <child link="r_uarm"/>
    <dynamics damping="0.1" friction="0"/>
    <limit effort="63" lower="0" upper="3.14159" velocity="12"/>
    <safety_controller k_position="100" k_velocity="100" soft_lower_limit="-10" soft_upper_limit="13.1416"/>
  </joint>
  <joint name="r_arm_shx" type="revolute">
    <origin rpy="0 0 0" xyz="0 -0.11 -0.245"/>
    <axis xyz="1 0 0"/>
    <parent link="r_clav"/>
    <child link="r_scap"/>
    <dynamics damping="0.1" friction="0"/>
    <limit effort="99" lower="-1.5708" upper="1.5708" velocity="12"/>
    <safety_controller k_position="100" k_velocity="100" soft_lower_limit="-11.5708" soft_upper_limit="11.5708"/>
  </joint>
  <joint name="r_arm_shz" type="revolute">
    <origin rpy="0 0 0" xyz="0.1406 -0.2256 0.4776"/>
    <axis xyz="0 0 1"/>
    <parent link="utorso"/>
    <child link="r_clav"/>
    <dynamics damping="0.1" friction="0"/>
    <limit effort="87" lower="-0.785398" upper="1.5708" velocity="12"/>
    <safety_controller k_position="100" k_velocity="100" soft_lower_limit="-10.7854" soft_upper_limit="11.5708"/>
  </joint>
  <joint name="r_arm_mwx" type="revolute">
    <origin rpy="0 0 0" xyz="0 0 0"/>
    <axis xyz="1 0 0"/>
    <parent link="r_ufarm"/>
    <child link="r_lfarm"/>
    <dynamics damping="0.1" friction="0"/>
    <limit effort="25" lower="-1.7628" upper="1.7628" velocity="10"/>
    <safety_controller k_position="100" k_velocity="100" soft_lower_limit="-11.7628" soft_upper_limit="11.7628"/>
  </joint>
  <joint name="r_arm_uwy" type="revolute">
    <origin rpy="0 0 0" xyz="0 -0.29955 -0.00921"/>
    <axis xyz="0 1 0"/>
    <parent link="r_larm"/>
    <child link="r_ufarm"/>
    <dynamics damping="0.1" friction="0"/>
    <limit effort="25" lower="-3.011" upper="3.011" velocity="10"/>
    <safety_controller k_position="100" k_velocity="100" soft_lower_limit="-13.011" soft_upper_limit="13.011"/>
  </joint>
  <joint name="r_arm_lwy" type="revolute">
    <origin rpy="0 0 0" xyz="0 0 0"/>
    <axis xyz="0 1 0"/>
    <parent link="r_lfarm"/>
    <child link="r_hand"/>
    <dynamics damping="0.1" friction="0"/>
    <limit effort="25" lower="-2.9671" upper="2.9671" velocity="10"/>
    <safety_controller k_position="100" k_velocity="100" soft_lower_limit="-12.9671" soft_upper_limit="12.9671"/>
  </joint>
  <joint name="r_leg_akx" type="revolute">
    <origin rpy="0 0 0" xyz="0 0 0"/>
    <axis xyz="1 0 0"/>
    <parent link="r_talus"/>
    <child link="r_foot"/>
    <dynamics damping="0.1" friction="0"/>
    <limit effort="360" lower="-0.8" upper="0.8" velocity="12"/>
    <safety_controller k_position="100" k_velocity="100" soft_lower_limit="-10.8" soft_upper_limit="10.8"/>
  </joint>
  <joint name="r_leg_aky" type="revolute">
    <origin rpy="0 0 0" xyz="0 0 -0.422"/>
    <axis xyz="0 1 0"/>
    <parent link="r_lleg"/>
    <child link="r_talus"/>
    <dynamics damping="0.1" friction="0"/>
    <limit effort="740" lower="-1" upper="0.7" velocity="12"/>
    <safety_controller k_position="100" k_velocity="100" soft_lower_limit="-11" soft_upper_limit="10.7"/>
  </joint>
  <joint name="r_leg_hpx" type="revolute">
    <origin rpy="0 0 0" xyz="0 0 0"/>
    <axis xyz="1 0 0"/>
    <parent link="r_uglut"/>
    <child link="r_lglut"/>
    <dynamics damping="0.1" friction="0"/>
    <limit effort="530" lower="-0.523599" upper="0.523599" velocity="12"/>
    <safety_controller k_position="100" k_velocity="100" soft_lower_limit="-10.5236" soft_upper_limit="10.5236"/>
  </joint>
  <joint name="r_leg_hpy" type="revolute">
    <origin rpy="0 0 0" xyz="0.05 -0.0225 -0.066"/>
    <axis xyz="0 1 0"/>
    <parent link="r_lglut"/>
    <child link="r_uleg"/>
    <dynamics damping="0.1" friction="0"/>
    <limit effort="840" lower="-1.61234" upper="0.65764" velocity="12"/>
    <safety_controller k_position="100" k_velocity="100" soft_lower_limit="-11.6123" soft_upper_limit="10.6576"/>
  </joint>
  <joint name="r_leg_hpz" type="revolute">
    <origin rpy="0 0 0" xyz="0 -0.089 0"/>
    <axis xyz="0 0 1"/>
    <parent link="pelvis"/>
    <child link="r_uglut"/>
    <dynamics damping="0.1" friction="0"/>
    <limit effort="275" lower="-0.786794" upper="0.174358" velocity="12"/>
    <safety_controller k_position="100" k_velocity="100" soft_lower_limit="-10.7868" soft_upper_limit="10.1744"/>
  </joint>
  <joint name="r_leg_kny" type="revolute">
    <origin rpy="0 0 0" xyz="-0.05 0 -0.374"/>
    <axis xyz="0 1 0"/>
    <parent link="r_uleg"/>
    <child link="r_lleg"/>
    <dynamics damping="0.1" friction="0"/>
    <limit effort="890" lower="0" upper="2.35637" velocity="12"/>
    <safety_controller k_position="100" k_velocity="100" soft_lower_limit="-10" soft_upper_limit="12.3564"/>
  </joint>
  <link name="r_situational_awareness_camera_link">
    <inertial>
      <mass value="0.1"/>
      <origin xyz="0 0 0"/>
      <inertia ixx="0.00001" ixy="0" ixz="0" iyy="0.00001" iyz="0" izz="0.00001"/>
    </inertial>
    <visual>
      <origin rpy="0 0 0" xyz="0 0 0"/>
      <geometry>
        <box size="0.01 0.01 0.01"/>
      </geometry>
    </visual>
  <collision>
      <origin rpy="0 0 0" xyz="0 0 0"/>
      <geometry>
        <box size="0.01 0.01 0.01"/>
      </geometry>
    </collision>
  </link>
  <joint name="r_situational_awareness_camera_joint" type="fixed">
    <parent link="utorso"/>
    <child link="r_situational_awareness_camera_link"/>
    <!-- SA camera mounted above the multisense head -->
    <origin rpy="0 0 -1.309" xyz="0.155 -0.121 0.785"/>
  </joint>
  <joint name="r_situational_awareness_camera_optical_frame_joint" type="fixed">
    <origin rpy="-1.5708 0.0 -1.5708" xyz="0 0 0"/>
    <parent link="r_situational_awareness_camera_link"/>
    <child link="r_situational_awareness_camera_optical_frame"/>
  </joint>
  <link name="r_situational_awareness_camera_optical_frame"/>
  <link name="l_situational_awareness_camera_link">
    <inertial>
      <mass value="0.1"/>
      <origin xyz="0 0 0"/>
      <inertia ixx="0.00001" ixy="0" ixz="0" iyy="0.00001" iyz="0" izz="0.00001"/>
    </inertial>
    <visual>
      <origin rpy="0 0 0" xyz="0 0 0"/>
      <geometry>
        <box size="0.01 0.01 0.01"/>
      </geometry>
    </visual>
  <collision>
      <origin rpy="0 0 0" xyz="0 0 0"/>
      <geometry>
        <box size="0.01 0.01 0.01"/>
      </geometry>
    </collision>
  </link>
  <joint name="l_situational_awareness_camera_joint" type="fixed">
    <parent link="utorso"/>
    <child link="l_situational_awareness_camera_link"/>
    <!-- SA camera mounted above the multisense head -->
    <origin rpy="0 0 1.309" xyz="0.155 0.121 0.785"/>
  </joint>
  <joint name="l_situational_awareness_camera_optical_frame_joint" type="fixed">
    <origin rpy="-1.5708 0.0 -1.5708" xyz="0 0 0"/>
    <parent link="l_situational_awareness_camera_link"/>
    <child link="l_situational_awareness_camera_optical_frame"/>
  </joint>
  <link name="l_situational_awareness_camera_optical_frame"/>
<frame name="l_foot_sole" link="l_foot" xyz="0.0426  0.0017 -0.07645" rpy="0 0 0"/><frame name="r_foot_sole" link="r_foot" xyz="0.0426 -0.0017 -0.07645" rpy="0 0 0"/><frame name="l_foot_toe" link="l_foot" xyz="0.1728 0.0017 -0.07645" rpy="0 0 0"/><frame name="r_foot_toe" link="r_foot" xyz="0.1728 -0.0017 -0.07645" rpy="0 0 0"/><collision_filter_group name="feet"><member link="l_foot"/><member link="r_foot"/><ignored_collision_filter_group collision_filter_group="feet"/></collision_filter_group><collision_filter_group name="core"><member link="utorso"/><member link="pelvis"/><ignored_collision_filter_group collision_filter_group="core"/></collision_filter_group><collision_filter_group name="ignore_core"><member link="r_scap"/><member link="l_scap"/><member link="r_clav"/><member link="l_clav"/><ignored_collision_filter_group collision_filter_group="core"/></collision_filter_group><collision_filter_group name="r_uleg"><member link="r_uglut"/><member link="r_lglut"/><member link="r_uleg"/><ignored_collision_filter_group collision_filter_group="core"/><ignored_collision_filter_group collision_filter_group="r_uleg"/><ignored_collision_filter_group collision_filter_group="l_uleg"/></collision_filter_group><collision_filter_group name="l_uleg"><member link="l_uglut"/><member link="l_lglut"/><member link="l_uleg"/><ignored_collision_filter_group collision_filter_group="core"/><ignored_collision_filter_group collision_filter_group="l_uleg"/><ignored_collision_filter_group collision_filter_group="l_uleg"/></collision_filter_group><collision_filter_group name="r_leg"><member link="r_lleg"/><member link="r_talus"/><member link="r_foot"/><ignored_collision_filter_group collision_filter_group="r_leg"/><ignored_collision_filter_group collision_filter_group="r_uleg"/></collision_filter_group><collision_filter_group name="l_leg"><member link="l_lleg"/><member link="l_talus"/><member link="l_foot"/><ignored_collision_filter_group collision_filter_group="l_leg"/><ignored_collision_filter_group collision_filter_group="l_uleg"/></collision_filter_group><collision_filter_group name="r_arm"><member link="r_clav"/><member link="r_scap"/><member link="r_uarm"/><member link="r_larm"/><member link="r_ufarm"/><member link="r_lfarm"/><member link="r_hand"/><ignored_collision_filter_group collision_filter_group="r_arm"/></collision_filter_group><collision_filter_group name="l_arm"><member link="l_clav"/><member link="l_scap"/><member link="l_uarm"/><member link="l_larm"/><member link="l_ufarm"/><member link="l_lfarm"/><member link="l_hand"/><ignored_collision_filter_group collision_filter_group="l_arm"/></collision_filter_group></robot>
