<?xml version="1.0" ?>
<!-- =================================================================================== -->
<!-- |    This document was autogenerated by xacro from kuka_lwr_arm.urdf.xml          | -->
<!-- |    EDITING THIS FILE BY HAND IS NOT RECOMMENDED                                 | -->
<!-- =================================================================================== -->
<robot name="lwr" xmlns:controller="http://playerstage.sourceforge.net/gazebo/xmlschema/#controller" xmlns:interface="http://playerstage.sourceforge.net/gazebo/xmlschema/#interface" xmlns:sensor="http://playerstage.sourceforge.net/gazebo/xmlschema/#sensor" xmlns:xacro="http://www.ros.org/wiki/xacro">
  <gazebo>
    <plugin filename="librtt_gazebo_plugin.so" name="rtt_gazebo">
      <opsScript>
        import(&quot;rtt_ros&quot;);
        ros.import(&quot;rtt_roscomm&quot;);
        ros.import(&quot;rtt_rosparam&quot;);
        ros.import(&quot;rtt_sensor_msgs&quot;);
        ros.import(&quot;lwr_simulation&quot;);
        ros.import(&quot;oro_joint_state_publisher&quot;);
        
        loadComponent(&quot;FRI&quot;,&quot;LWRController&quot;);
        loadComponent(&quot;joints&quot;,&quot;JointStatePublisher&quot;);
        
        loadService(&quot;FRI&quot;,&quot;rosparam&quot;);
        loadService(&quot;joints&quot;,&quot;rosparam&quot;);
        
        setActivity(&quot;FRI&quot;, 0.0, 5, ORO_SCHED_RT);
        setActivity(&quot;joints&quot;, 0.02, 5, ORO_SCHED_RT);
        
        connect(&quot;FRI.JointPosition&quot;,&quot;joints.msrJntPos&quot;, ConnPolicy());
        stream(&quot;joints.joints_state&quot;, rostopic.connection(&quot;/joints_state&quot;));
        
        joints.rosparam.refreshProperties();
        joints.configure();
        joints.start();
      </opsScript>
      <component>FRI</component>
    </plugin>
  </gazebo>
  <material name="DarkGrey">
    <color rgba="0.3 0.3 0.3 1.0"/>
  </material>
  <material name="Red">
    <color rgba="0.3 0.3 0.3 1.0"/>
  </material>
  <material name="Black">
    <color rgba="0 0 0 1.0"/>
  </material>
  <material name="Orange">
    <!--color rgba="1.0 0.487 0 1.0"/-->
    <color rgba="0.0 0.15 0.7 1.0"/>
  </material>
  <material name="Silver">
    <color rgba="1.0 1.0 1.0 1.0"/>
  </material>
  <material name="Grey">
    <color rgba="0.7 0.7 0.7 1.0"/>
  </material>
  <material name="Blue">
    <color rgba="0.0 0.0 0.8 1.0"/>
  </material>
  <material name="HandGray">
    <color rgba="0.953 0.996 0.694 1.0"/>
  </material>
  <material name="SickBlue">
    <color rgba="0.3058 0.5921 0.7294 1.0"/>
  </material>
  <property name="M_PI" value="3.1415926535897931" />
  <!--
  <link name="dupa" >
  </link>
  
  <joint name="arm_world_joint" type="fixed">
    <origin xyz="0 0 0.3" rpy="0 0 0"/>
    <parent link="world"/>
    <child link="world_link"/>
  </joint>
-->
  <link name="base">
    <inertial>
      <mass value="50.0"/>
      <com xyz="0 0 0"/>
      <inertia ixx="0.01" ixy="0.00" ixz="0.00" iyy="0.01" iyz="0.00" izz="0.01"/>
    </inertial>
    <visual>
      <origin rpy="0 0 0" xyz="0 0 0"/>
      <geometry>
        <box size="1 1 0.04"/>
      </geometry>
      <material name="DarkGrey"/>
    </visual>
    <collision>
      <origin rpy="0 0 0" xyz="0 0 0"/>
      <geometry>
        <box size="1 1 0.04"/>
      </geometry>
    </collision>
  </link>
  <joint name="base_joint" type="fixed">
    <origin rpy="0 0 3.14159265359" xyz="0 0 0.02"/>
    <parent link="base"/>
    <child link="lwr_arm_0_link"/>
  </joint>
  <link name="lwr_arm_0_link">
    <inertial>
      <mass value="2.0"/>
      <origin xyz="0 0 0"/>
      <inertia ixx="0.00381666666667" ixy="0" ixz="0" iyy="0.0036" iyz="0" izz="0.00381666666667"/>
    </inertial>
    <visual>
      <origin rpy="0 0 0" xyz="0 0 0"/>
      <geometry>
        <mesh filename="package://lwr_defs/meshes/lwr/base.stl"/>
      </geometry>
      <material name="Orange"/>
    </visual>
    <collision>
      <origin rpy="0 0 3.14159265359" xyz="0 0 0"/>
      <geometry>
        <mesh filename="package://lwr_defs/meshes/lwr/convex/arm_base_convex.stl"/>
        <!--cylinder length="0.11" radius="0.07"/-->
      </geometry>
    </collision>
  </link>
  <joint name="lwr_arm_0_joint" type="revolute">
    <origin rpy="0 0 0" xyz="0 0 0.11"/>
    <axis xyz="0 0 1"/>
    <limit effort="204" lower="-2.96705972839" upper="2.96705972839" velocity="1.91986217719"/>
    <safety_controller k_position="30" k_velocity="30" soft_lower_limit="-2.93215314335" soft_upper_limit="2.93215314335"/>
    <dynamics damping="1.0"/>
    <parent link="lwr_arm_0_link"/>
    <child link="lwr_arm_1_link"/>
  </joint>
  <link name="lwr_arm_1_link">
    <inertial>
      <mass value="2.0"/>
      <origin rpy="0 0 0" xyz="0 -0.06 0.130"/>
      <inertia ixx="0.0136666666667" ixy="0" ixz="0" iyy="0.003" iyz="0" izz="0.0118666666667"/>
    </inertial>
    <visual>
      <origin rpy="0 0 0" xyz="0 0 -0.008"/>
      <geometry>
        <mesh filename="package://lwr_defs/meshes/lwr/link_1.stl"/>
      </geometry>
      <material name="Orange"/>
    </visual>
      <collision>
        <origin xyz="0 0 0" rpy="0 0 0"/>
        <geometry>
          <mesh filename="package://lwr_defs/meshes/lwr/convex/arm_segment_a_convex.stl"/>
        </geometry>
      </collision>
    <!--collision>
      <origin rpy="0 0 0" xyz="0 0 0.0"/>
      <geometry>
        <sphere radius="0.07"/>
      </geometry>
    </collision>
    <collision>
      <origin rpy="0 0 0" xyz="0 -0.06 0.2"/>
      <geometry>
        <sphere radius="0.07"/>
      </geometry>
    </collision>
    <collision>
      <origin rpy="0.291 0 0" xyz="0 -0.03 0.1"/>
      <geometry>
        <cylinder length="0.208" radius="0.07"/>
      </geometry>
    </collision-->
  </link>
  <gazebo reference="lwr_arm_1_link">
    <gravity>false</gravity>
  </gazebo>
  <transmission name="lwr_arm_0_trans" type="SimpleTransmission">
    <actuator name="lwr_arm_0_motor"/>
    <joint name="lwr_arm_0_joint"/>
    <mechanicalReduction>1.0</mechanicalReduction>
  </transmission>
  <joint name="lwr_arm_1_joint" type="revolute">
    <origin rpy="0 0 0" xyz="0 0 0.2005"/>
    <axis xyz="0 1 0"/>
    <limit effort="306" lower="-2.09439510239" upper="2.09439510239" velocity="1.91986217719"/>
    <safety_controller k_position="30" k_velocity="30" soft_lower_limit="-2.05948851735" soft_upper_limit="2.05948851735"/>
    <dynamics damping="1.0" friction="10"/>
    <parent link="lwr_arm_1_link"/>
    <child link="lwr_arm_2_link"/>
  </joint>
  <link name="lwr_arm_2_link">
    <inertial>
      <mass value="2.0"/>
      <origin rpy="0 0 0" xyz="0 0.06 0.07"/>
      <inertia ixx="0.0136666666667" ixy="0" ixz="0" iyy="0.003" iyz="0" izz="0.0118666666667"/>
    </inertial>
    <visual>
      <origin rpy="0 0 0" xyz="0 0 0.0"/>
      <geometry>
        <mesh filename="package://lwr_defs/meshes/lwr/link_2.stl"/>
      </geometry>
      <material name="Orange"/>
    </visual>
      <collision>
        <origin xyz="0 0 0.2" rpy="3.14159265359 0 0"/>
        <geometry>
          <mesh filename="package://lwr_defs/meshes/lwr/convex/arm_segment_b_convex.stl"/>
        </geometry>
      </collision>
    <!--collision>
      <origin rpy="0 0 0" xyz="0 0 0.2"/>
      <geometry>
        <sphere radius="0.07"/>
      </geometry>
    </collision>
    <collision>
      <origin rpy="0 0 0" xyz="0 0.06 0.0"/>
      <geometry>
        <sphere radius="0.07"/>
      </geometry>
    </collision>
    <collision>
      <origin rpy="0.291 0 0" xyz="0 0.03 0.1"/>
      <geometry>
        <cylinder length="0.208" radius="0.07"/>
      </geometry>
    </collision-->
  </link>
  <gazebo reference="lwr_arm_2_link">
    <gravity>false</gravity>
  </gazebo>
  <transmission name="lwr_arm_1_trans" type="SimpleTransmission">
    <actuator name="lwr_arm_1_motor"/>
    <joint name="lwr_arm_1_joint"/>
    <mechanicalReduction>1.0</mechanicalReduction>
  </transmission>
  <joint name="lwr_arm_2_joint" type="revolute">
    <origin rpy="0 0 0" xyz="0 0 0.20"/>
    <axis xyz="0 0 1"/>
    <limit effort="204" lower="-2.96705972839" upper="2.96705972839" velocity="2.26892802759"/>
    <safety_controller k_position="30" k_velocity="30" soft_lower_limit="-2.93215314335" soft_upper_limit="2.93215314335"/>
    <dynamics damping="1.0"/>
    <parent link="lwr_arm_2_link"/>
    <child link="lwr_arm_3_link"/>
  </joint>
  <link name="lwr_arm_3_link">
    <inertial>
      <mass value="2.0"/>
      <origin rpy="0 0 0" xyz="0 0.06 0.130"/>
      <inertia ixx="0.0136666666667" ixy="0" ixz="0" iyy="0.003" iyz="0" izz="0.0118666666667"/>
    </inertial>
    <visual>
      <origin rpy="0 0 0" xyz="0 0 -0.008"/>
      <geometry>
        <mesh filename="package://lwr_defs/meshes/lwr/link_3.stl"/>
      </geometry>
      <material name="Orange"/>
    </visual>
      <collision>
        <origin xyz="0 0 0" rpy="0 0 3.1415926535897931"/>
        <geometry>
          <mesh filename="package://lwr_defs/meshes/lwr/convex/arm_segment_a_convex.stl"/>
        </geometry>
      </collision>
    <!--collision>
      <origin rpy="0 0 0" xyz="0 0 0.0"/>
      <geometry>
        <sphere radius="0.07"/>
      </geometry>
    </collision>
    <collision>
      <origin rpy="0 0 0" xyz="0 0.06 0.2"/>
      <geometry>
        <sphere radius="0.07"/>
      </geometry>
    </collision>
    <collision>
      <origin rpy="-0.291 0 0" xyz="0 0.03 0.1"/>
      <geometry>
        <cylinder length="0.208" radius="0.07"/>
      </geometry>
    </collision-->
  </link>
  <gazebo reference="lwr_arm_3_link">
    <gravity>false</gravity>
  </gazebo>
  <transmission name="lwr_arm_2_trans" type="SimpleTransmission">
    <actuator name="lwr_arm_2_motor"/>
    <joint name="lwr_arm_2_joint"/>
    <mechanicalReduction>1.0</mechanicalReduction>
  </transmission>
  <joint name="lwr_arm_3_joint" type="revolute">
    <origin rpy="0 0 0" xyz="0 0 0.20"/>
    <axis xyz="0 -1 0"/>
    <limit effort="306" lower="-2.09439510239" upper="2.09439510239" velocity="2.26892802759"/>
    <safety_controller k_position="30" k_velocity="30" soft_lower_limit="-2.05948851735" soft_upper_limit="2.05948851735"/>
    <dynamics damping="1.0"/>
    <parent link="lwr_arm_3_link"/>
    <child link="lwr_arm_4_link"/>
  </joint>
  <link name="lwr_arm_4_link">
    <inertial>
      <mass value="2.0"/>
      <origin rpy="0 0 0" xyz="0 -0.06 0.07"/>
      <inertia ixx="0.0136666666667" ixy="0" ixz="0" iyy="0.003" iyz="0" izz="0.0118666666667"/>
    </inertial>
    <visual>
      <origin rpy="0 0 0" xyz="0 0 0.0"/>
      <geometry>
        <mesh filename="package://lwr_defs/meshes/lwr/link_4.stl"/>
      </geometry>
      <material name="Orange"/>
    </visual>

      <collision>
        <origin xyz="0 0 0.2" rpy="0 3.1415926535897931 0"/>
        <geometry>
          <mesh filename="package://lwr_defs/meshes/lwr/convex/arm_segment_b_convex.stl"/>
        </geometry>
      </collision>

    <!--collision>
      <origin rpy="0 0 0" xyz="0 0 0.2"/>
      <geometry>
        <sphere radius="0.07"/>
      </geometry>
    </collision>
    <collision>
      <origin rpy="0 0 0" xyz="0 -0.06 0.0"/>
      <geometry>
        <sphere radius="0.07"/>
      </geometry>
    </collision>
    <collision>
      <origin rpy="-0.291 0 0" xyz="0 -0.03 0.1"/>
      <geometry>
        <cylinder length="0.208" radius="0.07"/>
      </geometry>
    </collision-->
  </link>
  <gazebo reference="lwr_arm_4_link">
    <gravity>false</gravity>
  </gazebo>
  <transmission name="lwr_arm_3_trans" type="SimpleTransmission">
    <actuator name="lwr_arm_3_motor"/>
    <joint name="lwr_arm_3_joint"/>
    <mechanicalReduction>1.0</mechanicalReduction>
  </transmission>
  <joint name="lwr_arm_4_joint" type="revolute">
    <origin rpy="0 0 0" xyz="0 0 0.20"/>
    <axis xyz="0 0 1"/>
    <limit effort="204" lower="-2.96705972839" upper="2.96705972839" velocity="2.26892802759"/>
    <safety_controller k_position="30" k_velocity="30" soft_lower_limit="-2.93215314335" soft_upper_limit="2.93215314335"/>
    <dynamics damping="1.0"/>
    <parent link="lwr_arm_4_link"/>
    <child link="lwr_arm_5_link"/>
  </joint>
  <link name="lwr_arm_5_link">
    <inertial>
      <mass value="2.0"/>
      <origin rpy="0 0 0" xyz="0 0 0.124"/>
      <inertia ixx="0.0126506666667" ixy="0" ixz="0" iyy="0.003" iyz="0" izz="0.0108506666667"/>
    </inertial>
    <visual>
      <origin rpy="0 0 0" xyz="0 0 -0.008"/>
      <geometry name="lwr_arm_5_geom">
        <mesh filename="package://lwr_defs/meshes/lwr/link_5.stl"/>
      </geometry>
      <material name="Orange"/>
    </visual>
      <collision>
        <origin xyz="0 0 0" rpy="0 0 0"/>
        <geometry>
          <mesh filename="package://lwr_defs/meshes/lwr/convex/arm_segment_last_convex.stl"/>
        </geometry>
      </collision>
    <!--collision>
      <origin rpy="0 0 0" xyz="0 0 0.0"/>
      <geometry>
        <sphere radius="0.07"/>
      </geometry>
    </collision>
    <collision>
      <origin rpy="0 0 0" xyz="0 -0.04 0.19"/>
      <geometry>
        <sphere radius="0.07"/>
      </geometry>
    </collision>
    <collision>
      <origin rpy="0.207 0 0" xyz="0 -0.02 0.095"/>
      <geometry>
        <cylinder length="0.198" radius="0.07"/>
      </geometry>
    </collision-->
  </link>
  <gazebo reference="lwr_arm_5_link">
    <gravity>false</gravity>
  </gazebo>
  <transmission name="lwr_arm_4_trans" type="SimpleTransmission">
    <actuator name="lwr_arm_4_motor"/>
    <joint name="lwr_arm_4_joint"/>
    <mechanicalReduction>1.0</mechanicalReduction>
  </transmission>
  <joint name="lwr_arm_5_joint" type="revolute">
    <origin rpy="0 0 0" xyz="0 0 0.19"/>
    <axis xyz="0 1 0"/>
    <limit effort="306" lower="-2.09439510239" upper="2.09439510239" velocity="3.14159265359"/>
    <safety_controller k_position="30" k_velocity="30" soft_lower_limit="-2.05948851735" soft_upper_limit="2.05948851735"/>
    <dynamics damping="1.0"/>
    <parent link="lwr_arm_5_link"/>
    <child link="lwr_arm_6_link"/>
  </joint>
  <link name="lwr_arm_6_link">
    <inertial>
      <mass value="0.2"/>
      <origin rpy="0 0 0" xyz="0 0 0.0625"/>
      <inertia ixx="0.000520833333333" ixy="0" ixz="0" iyy="0.000520833333333" iyz="0" izz="0.000520833333333"/>
    </inertial>
    <visual>
      <origin rpy="0 0 0" xyz="0 0 0"/>
      <geometry>
        <mesh filename="package://lwr_defs/meshes/lwr/link_6.stl"/>
      </geometry>
      <material name="Grey"/>
    </visual>
    <collision>
      <origin rpy="0 0 0" xyz="0 0 0"/>
      <geometry>
        <mesh filename="package://lwr_defs/meshes/lwr/convex/arm_wrist_convex.stl"/>
      </geometry>
    </collision>
  </link>
  <gazebo reference="lwr_arm_6_link">
    <gravity>false</gravity>
  </gazebo>
  <transmission name="lwr_arm_5_trans" type="SimpleTransmission">
    <actuator name="lwr_arm_5_motor"/>
    <joint name="lwr_arm_5_joint"/>
    <mechanicalReduction>1.0</mechanicalReduction>
  </transmission>
  <joint name="lwr_arm_6_joint" type="revolute">
    <origin rpy="0 0 0" xyz="0 0 0.078"/>
    <axis xyz="0 0 1"/>
    <limit effort="204" lower="-2.96705972839" upper="2.96705972839" velocity="3.14159265359"/>
    <safety_controller k_position="30" k_velocity="30" soft_lower_limit="-2.93215314335" soft_upper_limit="2.93215314335"/>
    <dynamics damping="1.0"/>
    <parent link="lwr_arm_6_link"/>
    <child link="lwr_arm_7_link"/>
  </joint>
  <link name="lwr_arm_7_link">
    <inertial>
      <mass value="0.2"/>
      <origin xyz="0 0 0"/>
      <inertia ixx="0.0333333333333" ixy="0" ixz="0" iyy="0.0333333333333" iyz="0" izz="0.0333333333333"/>
    </inertial>
    <visual>
      <origin rpy="0 0 0" xyz="0 0 0"/>
      <geometry>
        <mesh filename="package://lwr_defs/meshes/lwr/link_7.stl"/>
      </geometry>
      <material name="Grey"/>
    </visual>
    <collision>
      <origin rpy="0 0 -0.785398163397" xyz="0 0 0"/>
      <geometry>
        <cylinder length="0.05" radius="0.04"/>
      </geometry>
    </collision>
  </link>
  <gazebo reference="lwr_arm_7_link">
    <gravity>false</gravity>
  </gazebo>
  <transmission name="lwr_arm_6_trans" type="SimpleTransmission">
    <actuator name="lwr_arm_6_motor"/>
    <joint name="lwr_arm_6_joint"/>
    <mechanicalReduction>1.0</mechanicalReduction>
  </transmission>

  <!-- Components for bonus robotiq hand frames -->
  <link name="l_hand_force_torque">
    <inertial>
      <mass value="0.1"/>
      <origin xyz="0 0 0"/>
      <inertia ixx="0.00001" ixy="0" ixz="0" iyy="0.00001" iyz="0" izz="0.00001"/>
    </inertial>
    <visual>
      <origin rpy="0 0 0" xyz="0 0 0"/>
      <geometry>
        <box size="0.01 0.01 0.01"/>
      </geometry>
    </visual>
  </link>
  <joint name="l_hand_force_torque_joint" type="fixed">
    <origin rpy="1.57079 0 -1.57079" xyz="0 0 -0.015"/>
    <parent link="lwr_arm_7_link"/>
    <child link="l_hand_force_torque"/>
  </joint>
  <joint name="l_hand_face_joint" type="fixed">
    <origin rpy="0.0 0.0 0.0" xyz="0 0.12 0"/>
    <parent link="l_hand_force_torque"/>
    <child link="l_hand_face"/>
  </joint>
  <link name="l_hand_face"/>
  <joint name="l_hand_gripper_joint" type="fixed">
    <origin rpy="0.0 0.0 0.0" xyz="0 0.18 0"/>
    <parent link="l_hand_force_torque"/>
    <child link="l_hand_gripper"/>
  </joint>
  <link name="l_hand_gripper"/>


  <!-- Robotiq Hand -->
  <joint name="left_robotiq_hand_joint" type="fixed">
    <origin rpy="0 -1.57079 0" xyz="0 0.06566 0.0"/>
    <parent link="l_hand_force_torque"/>
    <child link="left_palm"/>
  </joint>
  <link name="left_finger_1_link_0">
    <visual>
      <origin rpy="0 0 0" xyz="0.020 0 0"/>
      <geometry>
        <mesh filename="package://robotiq_hand_description/meshes/s-model_articulated/visual/link_0.obj"/>
      </geometry>
      <material name="green">
        <color rgba="0 1 0 1"/>
      </material>
    </visual>
    <collision>
      <origin rpy="0 3.1416 -1.57" xyz="-0.0455 0.0414 0.036"/>
      <geometry>
        <mesh filename="package://robotiq_hand_description/meshes/s-model_articulated/collision/link_0.obj"/>
      </geometry>
      <material name="yellow">
        <color rgba="0 1 1 1"/>
      </material>
    </collision>
  </link>
  <link name="left_finger_1_link_1">
    <visual>
      <origin rpy="0 0 -0.52" xyz="0.050 -.028 0"/>
      <geometry>
        <mesh filename="package://robotiq_hand_description/meshes/s-model_articulated/visual/link_1.obj"/>
      </geometry>
      <material name="green"/>
    </visual>
    <collision>
      <origin rpy="0 0 -0.52" xyz="0.050 -.028 0"/>
      <geometry>
        <mesh filename="package://robotiq_hand_description/meshes/s-model_articulated/collision/link_1.obj"/>
      </geometry>
      <material name="yellow"/>
    </collision>
  </link>
  <link name="left_finger_1_link_2">
    <!--
			NOTE: This link has an offset in the z-direction based on the models that were
			used to generate grap-it poses.  With the offset below the model appears visually
			correct, but it is suspect.
			-->
    <visual>
      <origin rpy="0 0 0" xyz="0.039 0 0.0075"/>
      <geometry>
        <mesh filename="package://robotiq_hand_description/meshes/s-model_articulated/visual/link_2.obj"/>
      </geometry>
      <material name="green"/>
    </visual>
    <collision>
      <origin rpy="0 0 0" xyz="0.039 0 0.0075"/>
      <geometry>
        <mesh filename="package://robotiq_hand_description/meshes/s-model_articulated/collision/link_2.obj"/>
      </geometry>
      <material name="yellow"/>
    </collision>
  </link>
  <link name="left_finger_1_link_3">
    <visual>
      <origin rpy="0 0 0.52" xyz="0 0 0"/>
      <geometry>
        <mesh filename="package://robotiq_hand_description/meshes/s-model_articulated/visual/link_3.obj"/>
      </geometry>
      <material name="green"/>
    </visual>
    <collision>
      <origin rpy="0 0 0.52" xyz="0 0 0"/>
      <geometry>
        <mesh filename="package://robotiq_hand_description/meshes/s-model_articulated/collision/link_3.obj"/>
      </geometry>
      <material name="yellow"/>
    </collision>
  </link>
  <joint name="left_finger_1_joint_1" type="revolute">
    <parent link="left_finger_1_link_0"/>
    <child link="left_finger_1_link_1"/>
    <axis xyz="0 0 1"/>
    <origin rpy="0 0 0" xyz="0.020 0 0"/>
    <limit effort="100" lower="0" upper="3.1416" velocity="100"/>
  </joint>
  <joint name="left_finger_1_joint_2" type="revolute">
    <parent link="left_finger_1_link_1"/>
    <child link="left_finger_1_link_2"/>
    <axis xyz="0 0 1"/>
    <origin rpy="0 0 -0.52" xyz="0.050 -.028 0"/>
    <limit effort="100" lower="0" upper="3.1416" velocity="100"/>
  </joint>
  <joint name="left_finger_1_joint_3" type="revolute">
    <parent link="left_finger_1_link_2"/>
    <child link="left_finger_1_link_3"/>
    <axis xyz="0 0 1"/>
    <origin rpy="0 0 0" xyz="0.039 0 0"/>
    <limit effort="100" lower="0" upper="3.1416" velocity="100"/>
  </joint>
  <link name="left_finger_2_link_0">
    <visual>
      <origin rpy="0 0 0" xyz="0.020 0 0"/>
      <geometry>
        <mesh filename="package://robotiq_hand_description/meshes/s-model_articulated/visual/link_0.obj"/>
      </geometry>
      <material name="green">
        <color rgba="0 1 0 1"/>
      </material>
    </visual>
    <collision>
      <origin rpy="0 3.1416 -1.57" xyz="-0.0455 0.0414 0.036"/>
      <geometry>
        <mesh filename="package://robotiq_hand_description/meshes/s-model_articulated/collision/link_0.obj"/>
      </geometry>
      <material name="yellow">
        <color rgba="0 1 1 1"/>
      </material>
    </collision>
  </link>
  <link name="left_finger_2_link_1">
    <visual>
      <origin rpy="0 0 -0.52" xyz="0.050 -.028 0"/>
      <geometry>
        <mesh filename="package://robotiq_hand_description/meshes/s-model_articulated/visual/link_1.obj"/>
      </geometry>
      <material name="green"/>
    </visual>
    <collision>
      <origin rpy="0 0 -0.52" xyz="0.050 -.028 0"/>
      <geometry>
        <mesh filename="package://robotiq_hand_description/meshes/s-model_articulated/collision/link_1.obj"/>
      </geometry>
      <material name="yellow"/>
    </collision>
  </link>
  <link name="left_finger_2_link_2">
    <!--
			NOTE: This link has an offset in the z-direction based on the models that were
			used to generate grap-it poses.  With the offset below the model appears visually
			correct, but it is suspect.
			-->
    <visual>
      <origin rpy="0 0 0" xyz="0.039 0 0.0075"/>
      <geometry>
        <mesh filename="package://robotiq_hand_description/meshes/s-model_articulated/visual/link_2.obj"/>
      </geometry>
      <material name="green"/>
    </visual>
    <collision>
      <origin rpy="0 0 0" xyz="0.039 0 0.0075"/>
      <geometry>
        <mesh filename="package://robotiq_hand_description/meshes/s-model_articulated/collision/link_2.obj"/>
      </geometry>
      <material name="yellow"/>
    </collision>
  </link>
  <link name="left_finger_2_link_3">
    <visual>
      <origin rpy="0 0 0.52" xyz="0 0 0"/>
      <geometry>
        <mesh filename="package://robotiq_hand_description/meshes/s-model_articulated/visual/link_3.obj"/>
      </geometry>
      <material name="green"/>
    </visual>
    <collision>
      <origin rpy="0 0 0.52" xyz="0 0 0"/>
      <geometry>
        <mesh filename="package://robotiq_hand_description/meshes/s-model_articulated/collision/link_3.obj"/>
      </geometry>
      <material name="yellow"/>
    </collision>
  </link>
  <joint name="left_finger_2_joint_1" type="revolute">
    <parent link="left_finger_2_link_0"/>
    <child link="left_finger_2_link_1"/>
    <axis xyz="0 0 1"/>
    <origin rpy="0 0 0" xyz="0.020 0 0"/>
    <limit effort="100" lower="0" upper="3.1416" velocity="100"/>
  </joint>
  <joint name="left_finger_2_joint_2" type="revolute">
    <parent link="left_finger_2_link_1"/>
    <child link="left_finger_2_link_2"/>
    <axis xyz="0 0 1"/>
    <origin rpy="0 0 -0.52" xyz="0.050 -.028 0"/>
    <limit effort="100" lower="0" upper="3.1416" velocity="100"/>
  </joint>
  <joint name="left_finger_2_joint_3" type="revolute">
    <parent link="left_finger_2_link_2"/>
    <child link="left_finger_2_link_3"/>
    <axis xyz="0 0 1"/>
    <origin rpy="0 0 0" xyz="0.039 0 0"/>
    <limit effort="100" lower="0" upper="3.1416" velocity="100"/>
  </joint>
  <link name="left_finger_middle_link_0">
    <visual>
      <origin rpy="0 0 0" xyz="0.020 0 0"/>
      <geometry>
        <mesh filename="package://robotiq_hand_description/meshes/s-model_articulated/visual/link_0.obj"/>
      </geometry>
      <material name="green">
        <color rgba="0 1 0 1"/>
      </material>
    </visual>
    <collision>
      <origin rpy="0 3.1416 -1.57" xyz="-0.0455 0.0414 0.036"/>
      <geometry>
        <mesh filename="package://robotiq_hand_description/meshes/s-model_articulated/collision/link_0.obj"/>
      </geometry>
      <material name="yellow">
        <color rgba="0 1 1 1"/>
      </material>
    </collision>
  </link>
  <link name="left_finger_middle_link_1">
    <visual>
      <origin rpy="0 0 -0.52" xyz="0.050 -.028 0"/>
      <geometry>
        <mesh filename="package://robotiq_hand_description/meshes/s-model_articulated/visual/link_1.obj"/>
      </geometry>
      <material name="green"/>
    </visual>
    <collision>
      <origin rpy="0 0 -0.52" xyz="0.050 -.028 0"/>
      <geometry>
        <mesh filename="package://robotiq_hand_description/meshes/s-model_articulated/collision/link_1.obj"/>
      </geometry>
      <material name="yellow"/>
    </collision>
  </link>
  <link name="left_finger_middle_link_2">
    <!--
			NOTE: This link has an offset in the z-direction based on the models that were
			used to generate grap-it poses.  With the offset below the model appears visually
			correct, but it is suspect.
			-->
    <visual>
      <origin rpy="0 0 0" xyz="0.039 0 0.0075"/>
      <geometry>
        <mesh filename="package://robotiq_hand_description/meshes/s-model_articulated/visual/link_2.obj"/>
      </geometry>
      <material name="green"/>
    </visual>
    <collision>
      <origin rpy="0 0 0" xyz="0.039 0 0.0075"/>
      <geometry>
        <mesh filename="package://robotiq_hand_description/meshes/s-model_articulated/collision/link_2.obj"/>
      </geometry>
      <material name="yellow"/>
    </collision>
  </link>
  <link name="left_finger_middle_link_3">
    <visual>
      <origin rpy="0 0 0.52" xyz="0 0 0"/>
      <geometry>
        <mesh filename="package://robotiq_hand_description/meshes/s-model_articulated/visual/link_3.obj"/>
      </geometry>
      <material name="green"/>
    </visual>
    <collision>
      <origin rpy="0 0 0.52" xyz="0 0 0"/>
      <geometry>
        <mesh filename="package://robotiq_hand_description/meshes/s-model_articulated/collision/link_3.obj"/>
      </geometry>
      <material name="yellow"/>
    </collision>
  </link>
  <joint name="left_finger_middle_joint_1" type="revolute">
    <parent link="left_finger_middle_link_0"/>
    <child link="left_finger_middle_link_1"/>
    <axis xyz="0 0 1"/>
    <origin rpy="0 0 0" xyz="0.020 0 0"/>
    <limit effort="100" lower="0" upper="3.1416" velocity="100"/>
  </joint>
  <joint name="left_finger_middle_joint_2" type="revolute">
    <parent link="left_finger_middle_link_1"/>
    <child link="left_finger_middle_link_2"/>
    <axis xyz="0 0 1"/>
    <origin rpy="0 0 -0.52" xyz="0.050 -.028 0"/>
    <limit effort="100" lower="0" upper="3.1416" velocity="100"/>
  </joint>
  <joint name="left_finger_middle_joint_3" type="revolute">
    <parent link="left_finger_middle_link_2"/>
    <child link="left_finger_middle_link_3"/>
    <axis xyz="0 0 1"/>
    <origin rpy="0 0 0" xyz="0.039 0 0"/>
    <limit effort="100" lower="0" upper="3.1416" velocity="100"/>
  </joint>
  <link name="left_palm">
    <visual>
      <geometry>
        <mesh filename="package://robotiq_hand_description/meshes/s-model_articulated/visual/palm.obj"/>
      </geometry>
      <material name="green">
        <color rgba="0 1 0 1"/>
      </material>
    </visual>
    <collision>
      <geometry>
        <mesh filename="package://robotiq_hand_description/meshes/s-model_articulated/collision/palm.obj"/>
      </geometry>
      <material name="yellow">
        <color rgba="0 1 1 1"/>
      </material>
    </collision>
  </link>
  <joint name="left_palm_finger_1_joint" type="revolute">
    <parent link="left_palm"/>
    <child link="left_finger_1_link_0"/>
    <axis xyz="0 1 0"/>
    <origin rpy="0 3.1416 -1.57" xyz="-0.0455 0.0214 0.036"/>
    <limit effort="100" lower="-0.16" upper="0.25" velocity="100"/>
  </joint>
  <joint name="left_palm_finger_2_joint" type="revolute">
    <parent link="left_palm"/>
    <child link="left_finger_2_link_0"/>
    <axis xyz="0 1 0"/>
    <origin rpy="0 3.1416 -1.57" xyz="-0.0455 0.0214 -0.036"/>
    <limit effort="100" lower="-0.25" upper="0.16" velocity="100"/>
  </joint>
  <joint name="left_palm_finger_middle_joint" type="fixed">
    <parent link="left_palm"/>
    <child link="left_finger_middle_link_0"/>
    <axis xyz="0 0 1"/>
    <origin rpy="0 0 1.57" xyz="0.0455 0.0214 0"/>
  </joint>


</robot>

