<?xml version="1.0" ?>
<!-- =================================================================================== -->
<!-- |    This document was autogenerated by xacro from irobot_hand_left.urdf.xacro    | -->
<!-- |    EDITING THIS FILE BY HAND IS NOT RECOMMENDED                                 | -->
<!-- =================================================================================== -->
<robot name="irobot_hand_left" xmlns:controller="http://playerstage.sourceforge.net/gazebo/xmlschema/#controller" xmlns:interface="http://playerstage.sourceforge.net/gazebo/xmlschema/#interface" xmlns:sensor="http://playerstage.sourceforge.net/gazebo/xmlschema/#sensor" xmlns:xacro="http://www.ros.org/wiki/xacro">
  <link name="plane::xy::base">
    <inertial>
      <mass value="0.1"/>
      <origin rpy="0 0 0" xyz="0 0 0.0"/>
      <inertia ixx="0.01" ixy="0" ixz="0" iyy="0.01" iyz="0" izz="0.01"/>
    </inertial>
  </link>
  <joint name="left_finger[0]/joint_flex" type="revolute">
    <parent link="left_finger[0]/proximal_link"/>
    <child link="left_finger[0]/distal_link"/>
    <origin xyz="0 0 0.078"/>
    <axis xyz="-1 0 0"/>
    <limit effort="1000.0" lower="0.0" upper="1.57" velocity="0.5"/>
  </joint>
  <joint name="left_finger[1]/joint_flex" type="revolute">
    <parent link="left_finger[1]/proximal_link"/>
    <child link="left_finger[1]/distal_link"/>
    <origin xyz="0 0 0.078"/>
    <axis xyz="-1 0 0"/>
    <limit effort="1000.0" lower="0.0" upper="1.57" velocity="0.5"/>
  </joint>
  <joint name="left_finger[2]/joint_flex" type="revolute">
    <parent link="left_finger[2]/proximal_link"/>
    <child link="left_finger[2]/distal_link"/>
    <origin xyz="0 0 0.078"/>
    <axis xyz="-1 0 0"/>
    <limit effort="1000.0" lower="0.0" upper="1.57" velocity="0.5"/>
  </joint>
  <joint name="left_irobot_hand_joint" type="fixed">
    <origin rpy="1.57 0 -1.57" xyz="0 0 0"/>
    <parent link="plane::xy::base"/>
    <child link="left_base_link"/>
  </joint>
  <link name="left_base_link">
    <inertial>
      <mass value="0.1"/>
      <origin xyz="0 0 0"/>
      <inertia ixx="0.001" ixy="0.0" ixz="0.0" iyy="0.001" iyz="0.0" izz="0.001"/>
    </inertial>
    <collision>
      <geometry>
        <mesh filename="package://irobot_hand/meshes/palm.stl"/>
      </geometry>
      <origin rpy="0 0 0" xyz="0 -0.038 -0.023"/>
    </collision>
    <visual>
      <geometry>
        <mesh filename="package://irobot_hand/meshes/palm.stl"/>
      </geometry>
      <material name="darkgray">
        <color rgba="0.2 0.2 0.2 1"/>
      </material>
      <origin rpy="0 0 0" xyz="0 -0.038 -0.023"/>
    </visual>
  </link>
  <link name="left_finger[0]/base_rotation_link">
    <inertial>
      <mass value="0.1"/>
      <origin xyz="0 0 0"/>
      <inertia ixx="0.001" ixy="0.0" ixz="0.0" iyy="0.001" iyz="0.0" izz="0.001"/>
    </inertial>
    <collision>
      <geometry>
        <mesh filename="package://irobot_hand/meshes/finger_base.stl"/>
      </geometry>
      <origin rpy="1.57 0 0" xyz="0 0 0"/>
    </collision>
    <visual>
      <geometry>
        <mesh filename="package://irobot_hand/meshes/finger_base.stl"/>
      </geometry>
      <material name="darkgray">
        <color rgba="0.2 0.2 0.2 1"/>
      </material>
      <origin rpy="1.57 0 0" xyz="0 0 0"/>
    </visual>
  </link>
  <link name="left_finger[0]/proximal_link">
    <inertial>
      <mass value="0.1"/>
      <origin xyz="0 0 0"/>
      <inertia ixx="0.001" ixy="0.0" ixz="0.0" iyy="0.001" iyz="0.0" izz="0.001"/>
    </inertial>
    <collision>
      <geometry>
        <mesh filename="package://irobot_hand/meshes/finger_proximal.stl"/>
      </geometry>
      <origin rpy="1.57 -1.57 0" xyz="0 0 0"/>
    </collision>
    <visual>
      <geometry>
        <mesh filename="package://irobot_hand/meshes/finger_proximal.stl"/>
      </geometry>
      <material name="green">
        <color rgba="0.1 0.6 0.1 1"/>
      </material>
      <origin rpy="1.57 -1.57 0" xyz="0 0 0"/>
    </visual>
  </link>
  <link name="left_finger[0]/distal_link">
    <inertial>
      <mass value="0.1"/>
      <origin xyz="0 0 0"/>
      <inertia ixx="0.001" ixy="0.0" ixz="0.0" iyy="0.001" iyz="0.0" izz="0.001"/>
    </inertial>
    <collision>
      <geometry>
        <mesh filename="package://irobot_hand/meshes/finger_distal.stl"/>
      </geometry>
      <origin rpy="0 3.14 0" xyz="0 0 0"/>
    </collision>
    <visual>
      <geometry>
        <mesh filename="package://irobot_hand/meshes/finger_distal.stl"/>
      </geometry>
      <material name="green">
        <color rgba="0.1 0.6 0.1 1"/>
      </material>
      <origin rpy="0 3.14 0" xyz="0 0 0"/>
    </visual>
  </link>
  <link name="left_finger[1]/base_rotation_link">
    <inertial>
      <mass value="0.1"/>
      <origin xyz="0 0 0"/>
      <inertia ixx="0.001" ixy="0.0" ixz="0.0" iyy="0.001" iyz="0.0" izz="0.001"/>
    </inertial>
    <collision>
      <geometry>
        <mesh filename="package://irobot_hand/meshes/finger_base.stl"/>
      </geometry>
      <origin rpy="1.57 0 0" xyz="0 0 0"/>
    </collision>
    <visual>
      <geometry>
        <mesh filename="package://irobot_hand/meshes/finger_base.stl"/>
      </geometry>
      <material name="darkgray">
        <color rgba="0.2 0.2 0.2 1"/>
      </material>
      <origin rpy="1.57 0 0" xyz="0 0 0"/>
    </visual>
  </link>
  <link name="left_finger[1]/proximal_link">
    <inertial>
      <mass value="0.1"/>
      <origin xyz="0 0 0"/>
      <inertia ixx="0.001" ixy="0.0" ixz="0.0" iyy="0.001" iyz="0.0" izz="0.001"/>
    </inertial>
    <collision>
      <geometry>
        <mesh filename="package://irobot_hand/meshes/finger_proximal.stl"/>
      </geometry>
      <origin rpy="1.57 -1.57 0" xyz="0 0 0"/>
    </collision>
    <visual>
      <geometry>
        <mesh filename="package://irobot_hand/meshes/finger_proximal.stl"/>
      </geometry>
      <material name="green">
        <color rgba="0.1 0.6 0.1 1"/>
      </material>
      <origin rpy="1.57 -1.57 0" xyz="0 0 0"/>
    </visual>
  </link>
  <link name="left_finger[1]/distal_link">
    <inertial>
      <mass value="0.1"/>
      <origin xyz="0 0 0"/>
      <inertia ixx="0.001" ixy="0.0" ixz="0.0" iyy="0.001" iyz="0.0" izz="0.001"/>
    </inertial>
    <collision>
      <geometry>
        <mesh filename="package://irobot_hand/meshes/finger_distal.stl"/>
      </geometry>
      <origin rpy="0 3.14 0" xyz="0 0 0"/>
    </collision>
    <visual>
      <geometry>
        <mesh filename="package://irobot_hand/meshes/finger_distal.stl"/>
      </geometry>
      <material name="green">
        <color rgba="0.1 0.6 0.1 1"/>
      </material>
      <origin rpy="0 3.14 0" xyz="0 0 0"/>
    </visual>
  </link>
  <link name="left_finger[2]/proximal_link">
    <inertial>
      <mass value="0.1"/>
      <origin xyz="0 0 0"/>
      <inertia ixx="0.001" ixy="0.0" ixz="0.0" iyy="0.001" iyz="0.0" izz="0.001"/>
    </inertial>
    <collision>
      <geometry>
        <mesh filename="package://irobot_hand/meshes/finger_proximal.stl"/>
      </geometry>
      <origin rpy="1.57 -1.57 0" xyz="0 0 0"/>
    </collision>
    <visual>
      <geometry>
        <mesh filename="package://irobot_hand/meshes/finger_proximal.stl"/>
      </geometry>
      <material name="green">
        <color rgba="0.1 0.6 0.1 1"/>
      </material>
      <origin rpy="1.57 -1.57 0" xyz="0 0 0"/>
    </visual>
  </link>
  <link name="left_finger[2]/distal_link">
    <inertial>
      <mass value="0.1"/>
      <origin xyz="0 0 0"/>
      <inertia ixx="0.001" ixy="0.0" ixz="0.0" iyy="0.001" iyz="0.0" izz="0.001"/>
    </inertial>
    <collision>
      <geometry>
        <mesh filename="package://irobot_hand/meshes/finger_distal.stl"/>
      </geometry>
      <origin rpy="0 3.14 0" xyz="0 0 0"/>
    </collision>
    <visual>
      <geometry>
        <mesh filename="package://irobot_hand/meshes/finger_distal.stl"/>
      </geometry>
      <material name="green">
        <color rgba="0.1 0.6 0.1 1"/>
      </material>
      <origin rpy="0 3.14 0" xyz="0 0 0"/>
    </visual>
  </link>
  <joint name="left_finger[0]/joint_base_rotation" type="revolute">
    <parent link="left_base_link"/>
    <child link="left_finger[0]/base_rotation_link"/>
    <origin rpy="0 0 0" xyz="0.03075 0.038 0.069477"/>
    <axis xyz="0 0 -1"/>
    <limit effort="1000.0" lower="0.0" upper="1.57" velocity="0.5"/>
  </joint>
  <joint name="left_finger[0]/joint_base" type="revolute">
    <parent link="left_finger[0]/base_rotation_link"/>
    <child link="left_finger[0]/proximal_link"/>
    <origin rpy="1.57 0 -3.14" xyz="0 0 0.0135"/>
    <axis xyz="-1 0 0"/>
    <limit effort="1000.0" lower="0.0" upper="1.57" velocity="0.5"/>
  </joint>
  <joint name="left_finger[1]/joint_base_rotation" type="revolute">
    <parent link="left_base_link"/>
    <child link="left_finger[1]/base_rotation_link"/>
    <origin rpy="0 0 0" xyz="-0.03075 0.038 0.069477"/>
    <axis xyz="0 0 1"/>
    <limit effort="1000.0" lower="0.0" upper="1.57" velocity="0.5"/>
  </joint>
  <joint name="left_finger[1]/joint_base" type="revolute">
    <parent link="left_finger[1]/base_rotation_link"/>
    <child link="left_finger[1]/proximal_link"/>
    <origin rpy="1.57 0 -3.14" xyz="0 0 0.0135"/>
    <axis xyz="-1 0 0"/>
    <limit effort="1000.0" lower="0.0" upper="1.57" velocity="0.5"/>
  </joint>
  <joint name="left_finger[2]/joint_base" type="revolute">
    <parent link="left_base_link"/>
    <child link="left_finger[2]/proximal_link"/>
    <origin rpy="1.57 0 0" xyz="0 -0.038 0.082755"/>
    <axis xyz="-1 0 0"/>
    <limit effort="1000.0" lower="0.0" upper="1.57" velocity="0.5"/>
  </joint>
</robot>

