<?xml version="1.0" ?>
<!-- =================================================================================== -->
<!-- |    This document was autogenerated by xacro from sandia_hand_right.urdf.xacro   | -->
<!-- |    EDITING THIS FILE BY HAND IS NOT RECOMMENDED                                 | -->
<!-- =================================================================================== -->
<robot name="sandia_hand_right" xmlns:controller="http://playerstage.sourceforge.net/gazebo/xmlschema/#controller" xmlns:interface="http://playerstage.sourceforge.net/gazebo/xmlschema/#interface" xmlns:sensor="http://playerstage.sourceforge.net/gazebo/xmlschema/#sensor" xmlns:xacro="http://www.ros.org/wiki/xacro">
  <!--  derived from /usr/share/sandia-hand-5.1/ros/sandia_hand_description/robots/sandia_hand_right_on_box.urdf.xacro-->
  <!-- Commenting out urdf with meshes, using simple collision shapes instead -->
  <!--<include filename="$(find sandia_hand_description)/urdf/sandia_hand.urdf.xacro" />-->
  <link name="base">
    <inertial>
      <mass value="0.1"/>
      <origin rpy="0 0 0" xyz="0 0 0.25"/>
      <inertia ixx="0.01" ixy="0" ixz="0" iyy="0.01" iyz="0" izz="0.01"/>
    </inertial>
    <!--   <visual>
        <origin xyz="0 0 0.25" rpy="0 0 0" />
        <geometry>
            <box size="0.5 0.5 0.5" />
        </geometry>
    </visual>
    <collision>
        <origin xyz="0 0 0.25" rpy="0 0 0" />
        <geometry>
            <box size="0.5 0.5 0.5" />
        </geometry>
    </collision> -->
  </link>
  <link name="r_palm">
    <origin rpy="0 0 0" xyz="0 0 0"/>
    <inertial>
      <mass value="0.3"/>
      <origin xyz="0 0 0"/>
      <inertia ixx="0.01" ixy="0" ixz="0" iyy="0.01" iyz="0" izz="0.01"/>
    </inertial>
    <!-- begin simple shape approximation of palm -->
    <collision group="default">
      <origin rpy="0 1.57079632679 -0.9" xyz="0.069 0.016 0.038"/>
      <geometry>
        <cylinder length="0.100" radius="0.013"/>
      </geometry>
    </collision>
    <collision group="other">
      <origin rpy="0.41 0 -0.9" xyz="0.064 0.008 0.021"/>
      <geometry>
        <box size="0.09 .035 .05"/>
      </geometry>
    </collision>
    <collision group="other">
      <origin rpy="0 1.57079632679 0" xyz="0.02 0 -0.005"/>
      <geometry>
        <cylinder length="0.05" radius="0.038"/>
      </geometry>
    </collision>
    <collision group="other">
      <origin rpy="0 0 0.37" xyz="0.11 -0.01 -0.005"/>
      <geometry>
        <box size="0.09 .03 .06"/>
      </geometry>
    </collision>
    <collision group="other">
      <origin rpy="0 0 0.37" xyz="0.09 0.02 -0.005"/>
      <geometry>
        <box size="0.09 .03 .06"/>
      </geometry>
    </collision>
    <collision group="other">
      <origin rpy="0 0 0.37" xyz="0.060 0.05 -0.005"/>
      <geometry>
        <box size="0.09 .03 .06"/>
      </geometry>
    </collision>
    <collision group="other">
      <origin rpy="0 0 0.79" xyz="0.044 -0.04 -0.005"/>
      <geometry>
        <box size="0.09 .03 .06"/>
      </geometry>
    </collision>
    <!--   end simple shape approximation of palm -->
    <!-- begin visual shape approximation of palm -->
    <visual>
      <origin rpy="0 1.57079632679 -0.9" xyz="0.069 0.016 0.038"/>
      <geometry>
        <cylinder length="0.100" radius="0.013"/>
      </geometry>
      <material name="r_sandia_hand_skin">
        <color rgba="0.835 0.655 0.345 1.0"/>
      </material>
    </visual>
    <visual>
      <origin rpy="0.41 0 -0.9" xyz="0.064 0.008 0.021"/>
      <geometry>
        <box size="0.09 .035 .05"/>
      </geometry>
      <material name="r_sandia_hand_skin">
        <color rgba="0.835 0.655 0.345 1.0"/>
      </material>
    </visual>
    <visual>
      <origin rpy="0 1.57079632679 0" xyz="0.02 0 -0.005"/>
      <geometry>
        <cylinder length="0.05" radius="0.038"/>
      </geometry>
      <material name="r_sandia_hand_skin">
        <color rgba="0.835 0.655 0.345 1.0"/>
      </material>
    </visual>
    <visual>
      <origin rpy="0 0 0.37" xyz="0.11 -0.01 -0.005"/>
      <geometry>
        <box size="0.09 .03 .06"/>
      </geometry>
      <material name="r_sandia_hand_skin">
        <color rgba="0.835 0.655 0.345 1.0"/>
      </material>
    </visual>
    <visual>
      <origin rpy="0 0 0.37" xyz="0.09 0.02 -0.005"/>
      <geometry>
        <box size="0.09 .03 .06"/>
      </geometry>
      <material name="r_sandia_hand_skin">
        <color rgba="0.835 0.655 0.345 1.0"/>
      </material>
    </visual>
    <visual>
      <origin rpy="0 0 0.37" xyz="0.060 0.05 -0.005"/>
      <geometry>
        <box size="0.09 .03 .06"/>
      </geometry>
      <material name="r_sandia_hand_skin">
        <color rgba="0.835 0.655 0.345 1.0"/>
      </material>
    </visual>
    <visual>
      <origin rpy="0 0 0.79" xyz="0.044 -0.04 -0.005"/>
      <geometry>
        <box size="0.09 .03 .06"/>
      </geometry>
      <material name="r_sandia_hand_skin">
        <color rgba="0.835 0.655 0.345 1.0"/>
      </material>
    </visual>
    <!--   end visual shape approximation of palm -->
    <!-- begin collision mesh of f2 ->
      <collision group="default">
        <origin xyz="0 0 0" rpy="0 0 0"/>
        <geometry>
          <mesh filename="package://sandia_hand_description/meshes/palm.stl"/>
        </geometry>
      </collision>
      <!-   end collision mesh of f2 -->
    <!-- begin visual mesh of f2    ->
      <visual>
        <origin xyz="0 0 0" rpy="0 0 0"/>
        <geometry>
          <mesh filename="package://sandia_hand_description/meshes/palm.stl"/>
        </geometry>
        <material name="${side}_sandia_hand_skin">
          <color rgba="0.835 0.655 0.345 1.0"/>
        </material>
      </visual>
      <!-   end visual mesh of f2 -->
  </link>
  <joint name="r_sandia_hand_joint" type="fixed">
    <parent link="base"/>
    <child link="r_palm"/>
    <origin rpy="0 -1.57079 0" xyz="0 0 0.0"/>
  </joint>
  <link name="r_f0_base">
    <origin rpy="0 0 0" xyz="0 0 0"/>
    <inertial>
      <mass value="0.35"/>
      <origin xyz="0 0 0"/>
      <inertia ixx="0.01" ixy="0" ixz="0" iyy="0.01" iyz="0" izz="0.01"/>
    </inertial>
  </link>
  <link name="r_f0_fixed_accel">
    <origin rpy="0 0 0" xyz="0 0 0"/>
    <inertial>
      <mass value="0.001"/>
      <origin xyz="0 0 0"/>
      <inertia ixx="0.01" ixy="0" ixz="0" iyy="0.01" iyz="0" izz="0.01"/>
    </inertial>
  </link>
  <link name="r_f0_0">
    <origin rpy="0 0 0" xyz="0 0 0"/>
    <inertial>
      <mass value="0.05"/>
      <origin xyz="0 0 0"/>
      <inertia ixx="0.01" ixy="0" ixz="0" iyy="0.01" iyz="0" izz="0.01"/>
    </inertial>
    <!-- begin simple shape approximation of f0 -->
    <collision group="default">
      <origin rpy="0 0 0" xyz="0 0 0.003"/>
      <geometry>
        <cylinder length="0.023" radius="0.015"/>
      </geometry>
    </collision>
    <collision group="other">
      <origin rpy="1.57079632679 0 0" xyz="0.011 0 0.003"/>
      <geometry>
        <cylinder length="0.023" radius="0.01"/>
      </geometry>
    </collision>
    <!--   end simple shape approximation of f0 -->
    <!-- begin visual shape approximation of f0 -->
    <visual>
      <origin rpy="0 0 0" xyz="0 0 0.003"/>
      <geometry>
        <cylinder length="0.023" radius="0.015"/>
      </geometry>
      <material name="r_sandia_hand_skin_suntan">
        <color rgba="0.7 0.4 0.2 1.0"/>
      </material>
    </visual>
    <visual>
      <origin rpy="1.57079632679 0 0" xyz="0.011 0 0.003"/>
      <geometry>
        <cylinder length="0.023" radius="0.01"/>
      </geometry>
      <material name="r_sandia_hand_skin_suntan">
        <color rgba="0.7 0.4 0.2 1.0"/>
      </material>
    </visual>
    <!--   end visual shape approximation of f0 -->
    <!-- begin collision mesh of f0 ->
      <collision group="default">
        <origin xyz="0 0 0" rpy="0 0 0"/>
        <geometry>
          <mesh filename="package://sandia_hand_description/meshes/f0.stl"/>
        </geometry>
      </collision>
      <!-   end collision mesh of f0 -->
    <!-- begin visual mesh of f0 ->
      <visual>
        <origin xyz="0 0 0" rpy="0 0 0"/>
        <geometry>
          <mesh filename="package://sandia_hand_description/meshes/f0.stl"/>
        </geometry>
        <material name="${side}_sandia_hand_skin_suntan">
          <color rgba="0.7 0.4 0.2 1.0"/>
        </material>
      </visual>
      <!-   end visual mesh of f0 -->
  </link>
  <link name="r_f0_1">
    <origin rpy="0 0 0" xyz="0 0 0"/>
    <inertial>
      <mass value="0.05"/>
      <origin xyz="0 0 0"/>
      <inertia ixx="0.01" ixy="0" ixz="0" iyy="0.01" iyz="0" izz="0.01"/>
    </inertial>
    <!-- begin simple shape approximation of f1 -->
    <collision group="default">
      <origin rpy="0 1.57079632679 0" xyz="0.024 0 0"/>
      <geometry>
        <cylinder length="0.067" radius="0.01"/>
      </geometry>
    </collision>
    <!--   end simple shape approximation of f1 -->
    <!-- begin visual shape approximation of f1 -->
    <visual>
      <origin rpy="0 1.57079632679 0" xyz="0.024 0 0"/>
      <geometry>
        <cylinder length="0.067" radius="0.01"/>
      </geometry>
      <material name="r_sandia_hand_skin">
        <color rgba="0.835 0.655 0.345 1.0"/>
      </material>
    </visual>
    <!--   end visual shape approximation of f1 -->
    <!-- begin collision mesh of f1 ->
      <collision group="default">
        <origin xyz="0 0 0" rpy="0 0 0"/>
        <geometry>
          <mesh filename="package://sandia_hand_description/meshes/f1.stl"/>
        </geometry>
      </collision>
      <!-   end collision mesh of f1 -->
    <!-- begin visual mesh of f1 ->
      <visual>
        <origin xyz="0 0 0" rpy="0 0 0"/>
        <geometry>
          <mesh filename="package://sandia_hand_description/meshes/f1.stl"/>
        </geometry>
        <material name="${side}_sandia_hand_skin">
          <color rgba="0.835 0.655 0.345 1.0"/>
        </material>
      </visual>
      <!-   end visual mesh of f1 -->
  </link>
  <link name="r_f0_1_accel">
    <origin rpy="0 0 0" xyz="0 0 0"/>
    <inertial>
      <mass value="0.001"/>
      <origin xyz="0 0 0"/>
      <inertia ixx="0.01" ixy="0" ixz="0" iyy="0.01" iyz="0" izz="0.01"/>
    </inertial>
  </link>
  <link name="r_f0_2">
    <origin rpy="0 0 0" xyz="0 0 0"/>
    <inertial>
      <mass value="0.05"/>
      <origin xyz="0 0 0"/>
      <inertia ixx="0.01" ixy="0" ixz="0" iyy="0.01" iyz="0" izz="0.01"/>
    </inertial>
    <!-- begin simple shape approximation of f2 -->
    <collision group="default">
      <origin rpy="0 1.57079632679 0" xyz="0.024 0 0"/>
      <geometry>
        <cylinder length="0.057" radius="0.009"/>
      </geometry>
    </collision>
    <collision group="other">
      <origin rpy="0 0 0" xyz="0.052 0 0"/>
      <geometry>
        <sphere radius="0.009"/>
      </geometry>
    </collision>
    <!--   end simple shape approximation of f2 -->
    <!-- begin visual shape approximation of f2 -->
    <visual>
      <origin rpy="0 1.57079632679 0" xyz="0.024 0 0"/>
      <geometry>
        <cylinder length="0.057" radius="0.009"/>
      </geometry>
      <material name="r_sandia_hand_skin_suntan">
        <color rgba="0.8 0.6 0.3 1.0"/>
      </material>
    </visual>
    <visual>
      <origin rpy="0 0 0" xyz="0.052 0 0"/>
      <geometry>
        <sphere radius="0.009"/>
      </geometry>
      <material name="r_sandia_hand_skin_suntan">
        <color rgba="0.8 0.6 0.3 1.0"/>
      </material>
    </visual>
    <!-- begin collision mesh of f2    ->
      <collision group="default">
        <origin xyz="0 0 0" rpy="0 0 0"/>
        <geometry>
          <mesh filename="package://sandia_hand_description/meshes/f2.stl"/>
        </geometry>
      </collision>
      <!-   end collision mesh of f2 -->
    <!-- begin visual mesh of f2    ->
      <visual>
        <origin xyz="0 0 0" rpy="0 0 0"/>
        <geometry>
          <mesh filename="package://sandia_hand_description/meshes/f2.stl"/>
        </geometry>
        <material name="${side}_sandia_hand_skin_suntan">
          <color rgba="0.8 0.6 0.3 1.0"/>
        </material>
      </visual>
      <!-   end visual mesh of f2 -->
  </link>
  <link name="r_f0_2_accel">
    <origin rpy="0 0 0" xyz="0 0 0"/>
    <inertial>
      <mass value="0.001"/>
      <origin xyz="0 0 0"/>
      <inertia ixx="0.01" ixy="0" ixz="0" iyy="0.01" iyz="0" izz="0.01"/>
    </inertial>
  </link>
  <joint name="r_f0_base" type="fixed">
    <parent link="r_palm"/>
    <child link="r_f0_base"/>
    <origin rpy="0 0 0.3" xyz="0.14 0.0 0"/>
  </joint>
  <joint name="r_f0_j0" type="revolute">
    <axis xyz="0 0 1"/>
    <parent link="r_f0_base"/>
    <child link="r_f0_0"/>
    <limit effort="1" lower="-1.57079632679" upper="1.57079632679" velocity="1"/>
    <safety_controller k_position="1000.0" k_velocity="1000.0" soft_lower_limit="-11.57079" soft_upper_limit="11.57079"/>
    <dynamics damping="0.2"/>
    <origin rpy="0 0 0" xyz="0 0 0"/>
  </joint>
  <joint name="r_f0_j1" type="revolute">
    <axis xyz="0 0 1"/>
    <parent link="r_f0_0"/>
    <child link="r_f0_1"/>
    <limit effort="1" lower="-1.57079632679" upper="1.57079632679" velocity="1"/>
    <safety_controller k_position="1000.0" k_velocity="1000.0" soft_lower_limit="-11.57079" soft_upper_limit="11.57079"/>
    <dynamics damping="0.2"/>
    <origin rpy="1.57079632679 0 0" xyz="0.028 0 0"/>
  </joint>
  <joint name="r_f0_j2" type="revolute">
    <axis xyz="0 0 1"/>
    <parent link="r_f0_1"/>
    <child link="r_f0_2"/>
    <origin rpy="0 0 0" xyz="0.05 0 0"/>
    <safety_controller k_position="1000.0" k_velocity="1000.0" soft_lower_limit="-11.57079" soft_upper_limit="11.57079"/>
    <dynamics damping="0.2"/>
    <limit effort="1" lower="-1.57079632679" upper="1.57079632679" velocity="1"/>
  </joint>
  <joint name="r_f0_fixed_accel" type="fixed">
    <parent link="r_f0_base"/>
    <child link="r_f0_fixed_accel"/>
    <origin rpy="0 0 0" xyz="-0.05 0 0"/>
  </joint>
  <joint name="r_f0_1_accel" type="fixed">
    <parent link="r_f0_1"/>
    <child link="r_f0_1_accel"/>
    <origin rpy="-1.57079632679 0 0" xyz="0.03 0 0"/>
  </joint>
  <joint name="r_f0_2_accel" type="fixed">
    <parent link="r_f0_2"/>
    <child link="r_f0_2_accel"/>
    <origin rpy="-1.57079632679 0 0" xyz="0.04 0 0"/>
  </joint>
  <transmission name="r_f0_j0" type="pr2_mechanism_model/SimpleTransmission">
    <joint name="r_f0_j0"/>
    <actuator name="r_f0_j0_motor"/>
    <mechanicalReduction>1</mechanicalReduction>
  </transmission>
  <transmission name="r_f0_j1" type="pr2_mechanism_model/SimpleTransmission">
    <joint name="r_f0_j1"/>
    <actuator name="r_f0_j1_motor"/>
    <mechanicalReduction>1</mechanicalReduction>
  </transmission>
  <transmission name="r_f0_j2" type="pr2_mechanism_model/SimpleTransmission">
    <joint name="r_f0_j2"/>
    <actuator name="r_f0_j2_motor"/>
    <mechanicalReduction>1</mechanicalReduction>
  </transmission>
  <link name="r_f1_base">
    <origin rpy="0 0 0" xyz="0 0 0"/>
    <inertial>
      <mass value="0.35"/>
      <origin xyz="0 0 0"/>
      <inertia ixx="0.01" ixy="0" ixz="0" iyy="0.01" iyz="0" izz="0.01"/>
    </inertial>
  </link>
  <link name="r_f1_fixed_accel">
    <origin rpy="0 0 0" xyz="0 0 0"/>
    <inertial>
      <mass value="0.001"/>
      <origin xyz="0 0 0"/>
      <inertia ixx="0.01" ixy="0" ixz="0" iyy="0.01" iyz="0" izz="0.01"/>
    </inertial>
  </link>
  <link name="r_f1_0">
    <origin rpy="0 0 0" xyz="0 0 0"/>
    <inertial>
      <mass value="0.05"/>
      <origin xyz="0 0 0"/>
      <inertia ixx="0.01" ixy="0" ixz="0" iyy="0.01" iyz="0" izz="0.01"/>
    </inertial>
    <!-- begin simple shape approximation of f0 -->
    <collision group="default">
      <origin rpy="0 0 0" xyz="0 0 0.003"/>
      <geometry>
        <cylinder length="0.023" radius="0.015"/>
      </geometry>
    </collision>
    <collision group="other">
      <origin rpy="1.57079632679 0 0" xyz="0.011 0 0.003"/>
      <geometry>
        <cylinder length="0.023" radius="0.01"/>
      </geometry>
    </collision>
    <!--   end simple shape approximation of f0 -->
    <!-- begin visual shape approximation of f0 -->
    <visual>
      <origin rpy="0 0 0" xyz="0 0 0.003"/>
      <geometry>
        <cylinder length="0.023" radius="0.015"/>
      </geometry>
      <material name="r_sandia_hand_skin_suntan">
        <color rgba="0.7 0.4 0.2 1.0"/>
      </material>
    </visual>
    <visual>
      <origin rpy="1.57079632679 0 0" xyz="0.011 0 0.003"/>
      <geometry>
        <cylinder length="0.023" radius="0.01"/>
      </geometry>
      <material name="r_sandia_hand_skin_suntan">
        <color rgba="0.7 0.4 0.2 1.0"/>
      </material>
    </visual>
    <!--   end visual shape approximation of f0 -->
    <!-- begin collision mesh of f0 ->
      <collision group="default">
        <origin xyz="0 0 0" rpy="0 0 0"/>
        <geometry>
          <mesh filename="package://sandia_hand_description/meshes/f0.stl"/>
        </geometry>
      </collision>
      <!-   end collision mesh of f0 -->
    <!-- begin visual mesh of f0 ->
      <visual>
        <origin xyz="0 0 0" rpy="0 0 0"/>
        <geometry>
          <mesh filename="package://sandia_hand_description/meshes/f0.stl"/>
        </geometry>
        <material name="${side}_sandia_hand_skin_suntan">
          <color rgba="0.7 0.4 0.2 1.0"/>
        </material>
      </visual>
      <!-   end visual mesh of f0 -->
  </link>
  <link name="r_f1_1">
    <origin rpy="0 0 0" xyz="0 0 0"/>
    <inertial>
      <mass value="0.05"/>
      <origin xyz="0 0 0"/>
      <inertia ixx="0.01" ixy="0" ixz="0" iyy="0.01" iyz="0" izz="0.01"/>
    </inertial>
    <!-- begin simple shape approximation of f1 -->
    <collision group="default">
      <origin rpy="0 1.57079632679 0" xyz="0.024 0 0"/>
      <geometry>
        <cylinder length="0.067" radius="0.01"/>
      </geometry>
    </collision>
    <!--   end simple shape approximation of f1 -->
    <!-- begin visual shape approximation of f1 -->
    <visual>
      <origin rpy="0 1.57079632679 0" xyz="0.024 0 0"/>
      <geometry>
        <cylinder length="0.067" radius="0.01"/>
      </geometry>
      <material name="r_sandia_hand_skin">
        <color rgba="0.835 0.655 0.345 1.0"/>
      </material>
    </visual>
    <!--   end visual shape approximation of f1 -->
    <!-- begin collision mesh of f1 ->
      <collision group="default">
        <origin xyz="0 0 0" rpy="0 0 0"/>
        <geometry>
          <mesh filename="package://sandia_hand_description/meshes/f1.stl"/>
        </geometry>
      </collision>
      <!-   end collision mesh of f1 -->
    <!-- begin visual mesh of f1 ->
      <visual>
        <origin xyz="0 0 0" rpy="0 0 0"/>
        <geometry>
          <mesh filename="package://sandia_hand_description/meshes/f1.stl"/>
        </geometry>
        <material name="${side}_sandia_hand_skin">
          <color rgba="0.835 0.655 0.345 1.0"/>
        </material>
      </visual>
      <!-   end visual mesh of f1 -->
  </link>
  <link name="r_f1_1_accel">
    <origin rpy="0 0 0" xyz="0 0 0"/>
    <inertial>
      <mass value="0.001"/>
      <origin xyz="0 0 0"/>
      <inertia ixx="0.01" ixy="0" ixz="0" iyy="0.01" iyz="0" izz="0.01"/>
    </inertial>
  </link>
  <link name="r_f1_2">
    <origin rpy="0 0 0" xyz="0 0 0"/>
    <inertial>
      <mass value="0.05"/>
      <origin xyz="0 0 0"/>
      <inertia ixx="0.01" ixy="0" ixz="0" iyy="0.01" iyz="0" izz="0.01"/>
    </inertial>
    <!-- begin simple shape approximation of f2 -->
    <collision group="default">
      <origin rpy="0 1.57079632679 0" xyz="0.024 0 0"/>
      <geometry>
        <cylinder length="0.057" radius="0.009"/>
      </geometry>
    </collision>
    <collision group="other">
      <origin rpy="0 0 0" xyz="0.052 0 0"/>
      <geometry>
        <sphere radius="0.009"/>
      </geometry>
    </collision>
    <!--   end simple shape approximation of f2 -->
    <!-- begin visual shape approximation of f2 -->
    <visual>
      <origin rpy="0 1.57079632679 0" xyz="0.024 0 0"/>
      <geometry>
        <cylinder length="0.057" radius="0.009"/>
      </geometry>
      <material name="r_sandia_hand_skin_suntan">
        <color rgba="0.8 0.6 0.3 1.0"/>
      </material>
    </visual>
    <visual>
      <origin rpy="0 0 0" xyz="0.052 0 0"/>
      <geometry>
        <sphere radius="0.009"/>
      </geometry>
      <material name="r_sandia_hand_skin_suntan">
        <color rgba="0.8 0.6 0.3 1.0"/>
      </material>
    </visual>
    <!-- begin collision mesh of f2    ->
      <collision group="default">
        <origin xyz="0 0 0" rpy="0 0 0"/>
        <geometry>
          <mesh filename="package://sandia_hand_description/meshes/f2.stl"/>
        </geometry>
      </collision>
      <!-   end collision mesh of f2 -->
    <!-- begin visual mesh of f2    ->
      <visual>
        <origin xyz="0 0 0" rpy="0 0 0"/>
        <geometry>
          <mesh filename="package://sandia_hand_description/meshes/f2.stl"/>
        </geometry>
        <material name="${side}_sandia_hand_skin_suntan">
          <color rgba="0.8 0.6 0.3 1.0"/>
        </material>
      </visual>
      <!-   end visual mesh of f2 -->
  </link>
  <link name="r_f1_2_accel">
    <origin rpy="0 0 0" xyz="0 0 0"/>
    <inertial>
      <mass value="0.001"/>
      <origin xyz="0 0 0"/>
      <inertia ixx="0.01" ixy="0" ixz="0" iyy="0.01" iyz="0" izz="0.01"/>
    </inertial>
  </link>
  <joint name="r_f1_base" type="fixed">
    <parent link="r_palm"/>
    <child link="r_f1_base"/>
    <origin rpy="0 0 0.3" xyz="0.115 0.03122 0"/>
  </joint>
  <joint name="r_f1_j0" type="revolute">
    <axis xyz="0 0 1"/>
    <parent link="r_f1_base"/>
    <child link="r_f1_0"/>
    <limit effort="1" lower="-1.57079632679" upper="1.57079632679" velocity="1"/>
    <safety_controller k_position="1000.0" k_velocity="1000.0" soft_lower_limit="-11.57079" soft_upper_limit="11.57079"/>
    <dynamics damping="0.2"/>
    <origin rpy="0 0 0" xyz="0 0 0"/>
  </joint>
  <joint name="r_f1_j1" type="revolute">
    <axis xyz="0 0 1"/>
    <parent link="r_f1_0"/>
    <child link="r_f1_1"/>
    <limit effort="1" lower="-1.57079632679" upper="1.57079632679" velocity="1"/>
    <safety_controller k_position="1000.0" k_velocity="1000.0" soft_lower_limit="-11.57079" soft_upper_limit="11.57079"/>
    <dynamics damping="0.2"/>
    <origin rpy="1.57079632679 0 0" xyz="0.028 0 0"/>
  </joint>
  <joint name="r_f1_j2" type="revolute">
    <axis xyz="0 0 1"/>
    <parent link="r_f1_1"/>
    <child link="r_f1_2"/>
    <origin rpy="0 0 0" xyz="0.05 0 0"/>
    <safety_controller k_position="1000.0" k_velocity="1000.0" soft_lower_limit="-11.57079" soft_upper_limit="11.57079"/>
    <dynamics damping="0.2"/>
    <limit effort="1" lower="-1.57079632679" upper="1.57079632679" velocity="1"/>
  </joint>
  <joint name="r_f1_fixed_accel" type="fixed">
    <parent link="r_f1_base"/>
    <child link="r_f1_fixed_accel"/>
    <origin rpy="0 0 0" xyz="-0.05 0 0"/>
  </joint>
  <joint name="r_f1_1_accel" type="fixed">
    <parent link="r_f1_1"/>
    <child link="r_f1_1_accel"/>
    <origin rpy="-1.57079632679 0 0" xyz="0.03 0 0"/>
  </joint>
  <joint name="r_f1_2_accel" type="fixed">
    <parent link="r_f1_2"/>
    <child link="r_f1_2_accel"/>
    <origin rpy="-1.57079632679 0 0" xyz="0.04 0 0"/>
  </joint>
  <transmission name="r_f1_j0" type="pr2_mechanism_model/SimpleTransmission">
    <joint name="r_f1_j0"/>
    <actuator name="r_f1_j0_motor"/>
    <mechanicalReduction>1</mechanicalReduction>
  </transmission>
  <transmission name="r_f1_j1" type="pr2_mechanism_model/SimpleTransmission">
    <joint name="r_f1_j1"/>
    <actuator name="r_f1_j1_motor"/>
    <mechanicalReduction>1</mechanicalReduction>
  </transmission>
  <transmission name="r_f1_j2" type="pr2_mechanism_model/SimpleTransmission">
    <joint name="r_f1_j2"/>
    <actuator name="r_f1_j2_motor"/>
    <mechanicalReduction>1</mechanicalReduction>
  </transmission>
  <link name="r_f2_base">
    <origin rpy="0 0 0" xyz="0 0 0"/>
    <inertial>
      <mass value="0.35"/>
      <origin xyz="0 0 0"/>
      <inertia ixx="0.01" ixy="0" ixz="0" iyy="0.01" iyz="0" izz="0.01"/>
    </inertial>
  </link>
  <link name="r_f2_fixed_accel">
    <origin rpy="0 0 0" xyz="0 0 0"/>
    <inertial>
      <mass value="0.001"/>
      <origin xyz="0 0 0"/>
      <inertia ixx="0.01" ixy="0" ixz="0" iyy="0.01" iyz="0" izz="0.01"/>
    </inertial>
  </link>
  <link name="r_f2_0">
    <origin rpy="0 0 0" xyz="0 0 0"/>
    <inertial>
      <mass value="0.05"/>
      <origin xyz="0 0 0"/>
      <inertia ixx="0.01" ixy="0" ixz="0" iyy="0.01" iyz="0" izz="0.01"/>
    </inertial>
    <!-- begin simple shape approximation of f0 -->
    <collision group="default">
      <origin rpy="0 0 0" xyz="0 0 0.003"/>
      <geometry>
        <cylinder length="0.023" radius="0.015"/>
      </geometry>
    </collision>
    <collision group="other">
      <origin rpy="1.57079632679 0 0" xyz="0.011 0 0.003"/>
      <geometry>
        <cylinder length="0.023" radius="0.01"/>
      </geometry>
    </collision>
    <!--   end simple shape approximation of f0 -->
    <!-- begin visual shape approximation of f0 -->
    <visual>
      <origin rpy="0 0 0" xyz="0 0 0.003"/>
      <geometry>
        <cylinder length="0.023" radius="0.015"/>
      </geometry>
      <material name="r_sandia_hand_skin_suntan">
        <color rgba="0.7 0.4 0.2 1.0"/>
      </material>
    </visual>
    <visual>
      <origin rpy="1.57079632679 0 0" xyz="0.011 0 0.003"/>
      <geometry>
        <cylinder length="0.023" radius="0.01"/>
      </geometry>
      <material name="r_sandia_hand_skin_suntan">
        <color rgba="0.7 0.4 0.2 1.0"/>
      </material>
    </visual>
    <!--   end visual shape approximation of f0 -->
    <!-- begin collision mesh of f0 ->
      <collision group="default">
        <origin xyz="0 0 0" rpy="0 0 0"/>
        <geometry>
          <mesh filename="package://sandia_hand_description/meshes/f0.stl"/>
        </geometry>
      </collision>
      <!-   end collision mesh of f0 -->
    <!-- begin visual mesh of f0 ->
      <visual>
        <origin xyz="0 0 0" rpy="0 0 0"/>
        <geometry>
          <mesh filename="package://sandia_hand_description/meshes/f0.stl"/>
        </geometry>
        <material name="${side}_sandia_hand_skin_suntan">
          <color rgba="0.7 0.4 0.2 1.0"/>
        </material>
      </visual>
      <!-   end visual mesh of f0 -->
  </link>
  <link name="r_f2_1">
    <origin rpy="0 0 0" xyz="0 0 0"/>
    <inertial>
      <mass value="0.05"/>
      <origin xyz="0 0 0"/>
      <inertia ixx="0.01" ixy="0" ixz="0" iyy="0.01" iyz="0" izz="0.01"/>
    </inertial>
    <!-- begin simple shape approximation of f1 -->
    <collision group="default">
      <origin rpy="0 1.57079632679 0" xyz="0.024 0 0"/>
      <geometry>
        <cylinder length="0.067" radius="0.01"/>
      </geometry>
    </collision>
    <!--   end simple shape approximation of f1 -->
    <!-- begin visual shape approximation of f1 -->
    <visual>
      <origin rpy="0 1.57079632679 0" xyz="0.024 0 0"/>
      <geometry>
        <cylinder length="0.067" radius="0.01"/>
      </geometry>
      <material name="r_sandia_hand_skin">
        <color rgba="0.835 0.655 0.345 1.0"/>
      </material>
    </visual>
    <!--   end visual shape approximation of f1 -->
    <!-- begin collision mesh of f1 ->
      <collision group="default">
        <origin xyz="0 0 0" rpy="0 0 0"/>
        <geometry>
          <mesh filename="package://sandia_hand_description/meshes/f1.stl"/>
        </geometry>
      </collision>
      <!-   end collision mesh of f1 -->
    <!-- begin visual mesh of f1 ->
      <visual>
        <origin xyz="0 0 0" rpy="0 0 0"/>
        <geometry>
          <mesh filename="package://sandia_hand_description/meshes/f1.stl"/>
        </geometry>
        <material name="${side}_sandia_hand_skin">
          <color rgba="0.835 0.655 0.345 1.0"/>
        </material>
      </visual>
      <!-   end visual mesh of f1 -->
  </link>
  <link name="r_f2_1_accel">
    <origin rpy="0 0 0" xyz="0 0 0"/>
    <inertial>
      <mass value="0.001"/>
      <origin xyz="0 0 0"/>
      <inertia ixx="0.01" ixy="0" ixz="0" iyy="0.01" iyz="0" izz="0.01"/>
    </inertial>
  </link>
  <link name="r_f2_2">
    <origin rpy="0 0 0" xyz="0 0 0"/>
    <inertial>
      <mass value="0.05"/>
      <origin xyz="0 0 0"/>
      <inertia ixx="0.01" ixy="0" ixz="0" iyy="0.01" iyz="0" izz="0.01"/>
    </inertial>
    <!-- begin simple shape approximation of f2 -->
    <collision group="default">
      <origin rpy="0 1.57079632679 0" xyz="0.024 0 0"/>
      <geometry>
        <cylinder length="0.057" radius="0.009"/>
      </geometry>
    </collision>
    <collision group="other">
      <origin rpy="0 0 0" xyz="0.052 0 0"/>
      <geometry>
        <sphere radius="0.009"/>
      </geometry>
    </collision>
    <!--   end simple shape approximation of f2 -->
    <!-- begin visual shape approximation of f2 -->
    <visual>
      <origin rpy="0 1.57079632679 0" xyz="0.024 0 0"/>
      <geometry>
        <cylinder length="0.057" radius="0.009"/>
      </geometry>
      <material name="r_sandia_hand_skin_suntan">
        <color rgba="0.8 0.6 0.3 1.0"/>
      </material>
    </visual>
    <visual>
      <origin rpy="0 0 0" xyz="0.052 0 0"/>
      <geometry>
        <sphere radius="0.009"/>
      </geometry>
      <material name="r_sandia_hand_skin_suntan">
        <color rgba="0.8 0.6 0.3 1.0"/>
      </material>
    </visual>
    <!-- begin collision mesh of f2    ->
      <collision group="default">
        <origin xyz="0 0 0" rpy="0 0 0"/>
        <geometry>
          <mesh filename="package://sandia_hand_description/meshes/f2.stl"/>
        </geometry>
      </collision>
      <!-   end collision mesh of f2 -->
    <!-- begin visual mesh of f2    ->
      <visual>
        <origin xyz="0 0 0" rpy="0 0 0"/>
        <geometry>
          <mesh filename="package://sandia_hand_description/meshes/f2.stl"/>
        </geometry>
        <material name="${side}_sandia_hand_skin_suntan">
          <color rgba="0.8 0.6 0.3 1.0"/>
        </material>
      </visual>
      <!-   end visual mesh of f2 -->
  </link>
  <link name="r_f2_2_accel">
    <origin rpy="0 0 0" xyz="0 0 0"/>
    <inertial>
      <mass value="0.001"/>
      <origin xyz="0 0 0"/>
      <inertia ixx="0.01" ixy="0" ixz="0" iyy="0.01" iyz="0" izz="0.01"/>
    </inertial>
  </link>
  <joint name="r_f2_base" type="fixed">
    <parent link="r_palm"/>
    <child link="r_f2_base"/>
    <origin rpy="0 0 0.3" xyz="0.09 0.06245 0"/>
  </joint>
  <joint name="r_f2_j0" type="revolute">
    <axis xyz="0 0 1"/>
    <parent link="r_f2_base"/>
    <child link="r_f2_0"/>
    <limit effort="1" lower="-1.57079632679" upper="1.57079632679" velocity="1"/>
    <safety_controller k_position="1000.0" k_velocity="1000.0" soft_lower_limit="-11.57079" soft_upper_limit="11.57079"/>
    <dynamics damping="0.2"/>
    <origin rpy="0 0 0" xyz="0 0 0"/>
  </joint>
  <joint name="r_f2_j1" type="revolute">
    <axis xyz="0 0 1"/>
    <parent link="r_f2_0"/>
    <child link="r_f2_1"/>
    <limit effort="1" lower="-1.57079632679" upper="1.57079632679" velocity="1"/>
    <safety_controller k_position="1000.0" k_velocity="1000.0" soft_lower_limit="-11.57079" soft_upper_limit="11.57079"/>
    <dynamics damping="0.2"/>
    <origin rpy="1.57079632679 0 0" xyz="0.028 0 0"/>
  </joint>
  <joint name="r_f2_j2" type="revolute">
    <axis xyz="0 0 1"/>
    <parent link="r_f2_1"/>
    <child link="r_f2_2"/>
    <origin rpy="0 0 0" xyz="0.05 0 0"/>
    <safety_controller k_position="1000.0" k_velocity="1000.0" soft_lower_limit="-11.57079" soft_upper_limit="11.57079"/>
    <dynamics damping="0.2"/>
    <limit effort="1" lower="-1.57079632679" upper="1.57079632679" velocity="1"/>
  </joint>
  <joint name="r_f2_fixed_accel" type="fixed">
    <parent link="r_f2_base"/>
    <child link="r_f2_fixed_accel"/>
    <origin rpy="0 0 0" xyz="-0.05 0 0"/>
  </joint>
  <joint name="r_f2_1_accel" type="fixed">
    <parent link="r_f2_1"/>
    <child link="r_f2_1_accel"/>
    <origin rpy="-1.57079632679 0 0" xyz="0.03 0 0"/>
  </joint>
  <joint name="r_f2_2_accel" type="fixed">
    <parent link="r_f2_2"/>
    <child link="r_f2_2_accel"/>
    <origin rpy="-1.57079632679 0 0" xyz="0.04 0 0"/>
  </joint>
  <transmission name="r_f2_j0" type="pr2_mechanism_model/SimpleTransmission">
    <joint name="r_f2_j0"/>
    <actuator name="r_f2_j0_motor"/>
    <mechanicalReduction>1</mechanicalReduction>
  </transmission>
  <transmission name="r_f2_j1" type="pr2_mechanism_model/SimpleTransmission">
    <joint name="r_f2_j1"/>
    <actuator name="r_f2_j1_motor"/>
    <mechanicalReduction>1</mechanicalReduction>
  </transmission>
  <transmission name="r_f2_j2" type="pr2_mechanism_model/SimpleTransmission">
    <joint name="r_f2_j2"/>
    <actuator name="r_f2_j2_motor"/>
    <mechanicalReduction>1</mechanicalReduction>
  </transmission>
  <link name="r_f3_base">
    <origin rpy="0 0 0" xyz="0 0 0"/>
    <inertial>
      <mass value="0.35"/>
      <origin xyz="0 0 0"/>
      <inertia ixx="0.01" ixy="0" ixz="0" iyy="0.01" iyz="0" izz="0.01"/>
    </inertial>
  </link>
  <link name="r_f3_fixed_accel">
    <origin rpy="0 0 0" xyz="0 0 0"/>
    <inertial>
      <mass value="0.001"/>
      <origin xyz="0 0 0"/>
      <inertia ixx="0.01" ixy="0" ixz="0" iyy="0.01" iyz="0" izz="0.01"/>
    </inertial>
  </link>
  <link name="r_f3_0">
    <origin rpy="0 0 0" xyz="0 0 0"/>
    <inertial>
      <mass value="0.05"/>
      <origin xyz="0 0 0"/>
      <inertia ixx="0.01" ixy="0" ixz="0" iyy="0.01" iyz="0" izz="0.01"/>
    </inertial>
    <!-- begin simple shape approximation of f0 -->
    <collision group="default">
      <origin rpy="0 0 0" xyz="0 0 0.003"/>
      <geometry>
        <cylinder length="0.023" radius="0.015"/>
      </geometry>
    </collision>
    <collision group="other">
      <origin rpy="1.57079632679 0 0" xyz="0.011 0 0.003"/>
      <geometry>
        <cylinder length="0.023" radius="0.01"/>
      </geometry>
    </collision>
    <!--   end simple shape approximation of f0 -->
    <!-- begin visual shape approximation of f0 -->
    <visual>
      <origin rpy="0 0 0" xyz="0 0 0.003"/>
      <geometry>
        <cylinder length="0.023" radius="0.015"/>
      </geometry>
      <material name="r_sandia_hand_skin_suntan">
        <color rgba="0.7 0.4 0.2 1.0"/>
      </material>
    </visual>
    <visual>
      <origin rpy="1.57079632679 0 0" xyz="0.011 0 0.003"/>
      <geometry>
        <cylinder length="0.023" radius="0.01"/>
      </geometry>
      <material name="r_sandia_hand_skin_suntan">
        <color rgba="0.7 0.4 0.2 1.0"/>
      </material>
    </visual>
    <!--   end visual shape approximation of f0 -->
    <!-- begin collision mesh of f0 ->
      <collision group="default">
        <origin xyz="0 0 0" rpy="0 0 0"/>
        <geometry>
          <mesh filename="package://sandia_hand_description/meshes/f0.stl"/>
        </geometry>
      </collision>
      <!-   end collision mesh of f0 -->
    <!-- begin visual mesh of f0 ->
      <visual>
        <origin xyz="0 0 0" rpy="0 0 0"/>
        <geometry>
          <mesh filename="package://sandia_hand_description/meshes/f0.stl"/>
        </geometry>
        <material name="${side}_sandia_hand_skin_suntan">
          <color rgba="0.7 0.4 0.2 1.0"/>
        </material>
      </visual>
      <!-   end visual mesh of f0 -->
  </link>
  <link name="r_f3_1">
    <origin rpy="0 0 0" xyz="0 0 0"/>
    <inertial>
      <mass value="0.05"/>
      <origin xyz="0 0 0"/>
      <inertia ixx="0.01" ixy="0" ixz="0" iyy="0.01" iyz="0" izz="0.01"/>
    </inertial>
    <!-- begin simple shape approximation of f1 -->
    <collision group="default">
      <origin rpy="0 1.57079632679 0" xyz="0.024 0 0"/>
      <geometry>
        <cylinder length="0.067" radius="0.01"/>
      </geometry>
    </collision>
    <!--   end simple shape approximation of f1 -->
    <!-- begin visual shape approximation of f1 -->
    <visual>
      <origin rpy="0 1.57079632679 0" xyz="0.024 0 0"/>
      <geometry>
        <cylinder length="0.067" radius="0.01"/>
      </geometry>
      <material name="r_sandia_hand_skin">
        <color rgba="0.835 0.655 0.345 1.0"/>
      </material>
    </visual>
    <!--   end visual shape approximation of f1 -->
    <!-- begin collision mesh of f1 ->
      <collision group="default">
        <origin xyz="0 0 0" rpy="0 0 0"/>
        <geometry>
          <mesh filename="package://sandia_hand_description/meshes/f1.stl"/>
        </geometry>
      </collision>
      <!-   end collision mesh of f1 -->
    <!-- begin visual mesh of f1 ->
      <visual>
        <origin xyz="0 0 0" rpy="0 0 0"/>
        <geometry>
          <mesh filename="package://sandia_hand_description/meshes/f1.stl"/>
        </geometry>
        <material name="${side}_sandia_hand_skin">
          <color rgba="0.835 0.655 0.345 1.0"/>
        </material>
      </visual>
      <!-   end visual mesh of f1 -->
  </link>
  <link name="r_f3_1_accel">
    <origin rpy="0 0 0" xyz="0 0 0"/>
    <inertial>
      <mass value="0.001"/>
      <origin xyz="0 0 0"/>
      <inertia ixx="0.01" ixy="0" ixz="0" iyy="0.01" iyz="0" izz="0.01"/>
    </inertial>
  </link>
  <link name="r_f3_2">
    <origin rpy="0 0 0" xyz="0 0 0"/>
    <inertial>
      <mass value="0.05"/>
      <origin xyz="0 0 0"/>
      <inertia ixx="0.01" ixy="0" ixz="0" iyy="0.01" iyz="0" izz="0.01"/>
    </inertial>
    <!-- begin simple shape approximation of f2 -->
    <collision group="default">
      <origin rpy="0 1.57079632679 0" xyz="0.024 0 0"/>
      <geometry>
        <cylinder length="0.057" radius="0.009"/>
      </geometry>
    </collision>
    <collision group="other">
      <origin rpy="0 0 0" xyz="0.052 0 0"/>
      <geometry>
        <sphere radius="0.009"/>
      </geometry>
    </collision>
    <!--   end simple shape approximation of f2 -->
    <!-- begin visual shape approximation of f2 -->
    <visual>
      <origin rpy="0 1.57079632679 0" xyz="0.024 0 0"/>
      <geometry>
        <cylinder length="0.057" radius="0.009"/>
      </geometry>
      <material name="r_sandia_hand_skin_suntan">
        <color rgba="0.8 0.6 0.3 1.0"/>
      </material>
    </visual>
    <visual>
      <origin rpy="0 0 0" xyz="0.052 0 0"/>
      <geometry>
        <sphere radius="0.009"/>
      </geometry>
      <material name="r_sandia_hand_skin_suntan">
        <color rgba="0.8 0.6 0.3 1.0"/>
      </material>
    </visual>
    <!-- begin collision mesh of f2    ->
      <collision group="default">
        <origin xyz="0 0 0" rpy="0 0 0"/>
        <geometry>
          <mesh filename="package://sandia_hand_description/meshes/f2.stl"/>
        </geometry>
      </collision>
      <!-   end collision mesh of f2 -->
    <!-- begin visual mesh of f2    ->
      <visual>
        <origin xyz="0 0 0" rpy="0 0 0"/>
        <geometry>
          <mesh filename="package://sandia_hand_description/meshes/f2.stl"/>
        </geometry>
        <material name="${side}_sandia_hand_skin_suntan">
          <color rgba="0.8 0.6 0.3 1.0"/>
        </material>
      </visual>
      <!-   end visual mesh of f2 -->
  </link>
  <link name="r_f3_2_accel">
    <origin rpy="0 0 0" xyz="0 0 0"/>
    <inertial>
      <mass value="0.001"/>
      <origin xyz="0 0 0"/>
      <inertia ixx="0.01" ixy="0" ixz="0" iyy="0.01" iyz="0" izz="0.01"/>
    </inertial>
  </link>
  <joint name="r_f3_base" type="fixed">
    <parent link="r_palm"/>
    <child link="r_f3_base"/>
    <origin rpy="0 -1.57079632679 -2.3562" xyz="0.03995 -0.04383 0.014"/>
  </joint>
  <joint name="r_f3_j0" type="revolute">
    <axis xyz="0 0 1"/>
    <parent link="r_f3_base"/>
    <child link="r_f3_0"/>
    <limit effort="1" lower="-1.57079632679" upper="1.57079632679" velocity="1"/>
    <safety_controller k_position="1000.0" k_velocity="1000.0" soft_lower_limit="-11.57079" soft_upper_limit="11.57079"/>
    <dynamics damping="0.2"/>
    <origin rpy="0 0 0" xyz="0 0 0"/>
  </joint>
  <joint name="r_f3_j1" type="revolute">
    <axis xyz="0 0 1"/>
    <parent link="r_f3_0"/>
    <child link="r_f3_1"/>
    <limit effort="1" lower="-1.57079632679" upper="1.57079632679" velocity="1"/>
    <safety_controller k_position="1000.0" k_velocity="1000.0" soft_lower_limit="-11.57079" soft_upper_limit="11.57079"/>
    <dynamics damping="0.2"/>
    <origin rpy="1.57079632679 0 0" xyz="0.028 0 0"/>
  </joint>
  <joint name="r_f3_j2" type="revolute">
    <axis xyz="0 0 1"/>
    <parent link="r_f3_1"/>
    <child link="r_f3_2"/>
    <origin rpy="0 0 0" xyz="0.05 0 0"/>
    <safety_controller k_position="1000.0" k_velocity="1000.0" soft_lower_limit="-11.57079" soft_upper_limit="11.57079"/>
    <dynamics damping="0.2"/>
    <limit effort="1" lower="-1.57079632679" upper="1.57079632679" velocity="1"/>
  </joint>
  <joint name="r_f3_fixed_accel" type="fixed">
    <parent link="r_f3_base"/>
    <child link="r_f3_fixed_accel"/>
    <origin rpy="0 0 0" xyz="-0.05 0 0"/>
  </joint>
  <joint name="r_f3_1_accel" type="fixed">
    <parent link="r_f3_1"/>
    <child link="r_f3_1_accel"/>
    <origin rpy="-1.57079632679 0 0" xyz="0.03 0 0"/>
  </joint>
  <joint name="r_f3_2_accel" type="fixed">
    <parent link="r_f3_2"/>
    <child link="r_f3_2_accel"/>
    <origin rpy="-1.57079632679 0 0" xyz="0.04 0 0"/>
  </joint>
  <transmission name="r_f3_j0" type="pr2_mechanism_model/SimpleTransmission">
    <joint name="r_f3_j0"/>
    <actuator name="r_f3_j0_motor"/>
    <mechanicalReduction>1</mechanicalReduction>
  </transmission>
  <transmission name="r_f3_j1" type="pr2_mechanism_model/SimpleTransmission">
    <joint name="r_f3_j1"/>
    <actuator name="r_f3_j1_motor"/>
    <mechanicalReduction>1</mechanicalReduction>
  </transmission>
  <transmission name="r_f3_j2" type="pr2_mechanism_model/SimpleTransmission">
    <joint name="r_f3_j2"/>
    <actuator name="r_f3_j2_motor"/>
    <mechanicalReduction>1</mechanicalReduction>
  </transmission>
</robot>

<?xml version="1.0" ?>
<!-- =================================================================================== -->
<!-- |    This document was autogenerated by xacro from sandia_hand_right.urdf.xacro   | -->
<!-- |    EDITING THIS FILE BY HAND IS NOT RECOMMENDED                                 | -->
<!-- =================================================================================== -->
<robot name="sandia_hand_right" xmlns:controller="http://playerstage.sourceforge.net/gazebo/xmlschema/#controller" xmlns:interface="http://playerstage.sourceforge.net/gazebo/xmlschema/#interface" xmlns:sensor="http://playerstage.sourceforge.net/gazebo/xmlschema/#sensor" xmlns:xacro="http://www.ros.org/wiki/xacro">
  <!--  derived from /usr/share/sandia-hand-5.1/ros/sandia_hand_description/robots/sandia_hand_right_on_box.urdf.xacro-->
  <!-- Commenting out urdf with meshes, using simple collision shapes instead -->
  <!--<include filename="$(find sandia_hand_description)/urdf/sandia_hand.urdf.xacro" />-->
  <link name="base">
    <inertial>
      <mass value="0.1"/>
      <origin rpy="0 0 0" xyz="0 0 0.25"/>
      <inertia ixx="0.01" ixy="0" ixz="0" iyy="0.01" iyz="0" izz="0.01"/>
    </inertial>
    <!--   <visual>
        <origin xyz="0 0 0.25" rpy="0 0 0" />
        <geometry>
            <box size="0.5 0.5 0.5" />
        </geometry>
    </visual>
    <collision>
        <origin xyz="0 0 0.25" rpy="0 0 0" />
        <geometry>
            <box size="0.5 0.5 0.5" />
        </geometry>
    </collision> -->
  </link>
  <link name="right_palm">
    <origin rpy="0 0 0" xyz="0 0 0"/>
    <inertial>
      <mass value="0.3"/>
      <origin xyz="0 0 0"/>
      <inertia ixx="0.01" ixy="0" ixz="0" iyy="0.01" iyz="0" izz="0.01"/>
    </inertial>
    <!-- begin simple shape approximation of palm -->
    <collision group="default">
      <origin rpy="0 1.57079632679 -0.9" xyz="0.069 0.016 0.038"/>
      <geometry>
        <cylinder length="0.100" radius="0.013"/>
      </geometry>
    </collision>
    <collision group="other">
      <origin rpy="0.41 0 -0.9" xyz="0.064 0.008 0.021"/>
      <geometry>
        <box size="0.09 .035 .05"/>
      </geometry>
    </collision>
    <collision group="other">
      <origin rpy="0 1.57079632679 0" xyz="0.02 0 -0.005"/>
      <geometry>
        <cylinder length="0.05" radius="0.038"/>
      </geometry>
    </collision>
    <collision group="other">
      <origin rpy="0 0 0.37" xyz="0.11 -0.01 -0.005"/>
      <geometry>
        <box size="0.09 .03 .06"/>
      </geometry>
    </collision>
    <collision group="other">
      <origin rpy="0 0 0.37" xyz="0.09 0.02 -0.005"/>
      <geometry>
        <box size="0.09 .03 .06"/>
      </geometry>
    </collision>
    <collision group="other">
      <origin rpy="0 0 0.37" xyz="0.060 0.05 -0.005"/>
      <geometry>
        <box size="0.09 .03 .06"/>
      </geometry>
    </collision>
    <collision group="other">
      <origin rpy="0 0 0.79" xyz="0.044 -0.04 -0.005"/>
      <geometry>
        <box size="0.09 .03 .06"/>
      </geometry>
    </collision>
    <!--   end simple shape approximation of palm -->
    <!-- begin visual shape approximation of palm -->
    <visual>
      <origin rpy="0 1.57079632679 -0.9" xyz="0.069 0.016 0.038"/>
      <geometry>
        <cylinder length="0.100" radius="0.013"/>
      </geometry>
      <material name="right_sandia_hand_skin">
        <color rgba="0.835 0.655 0.345 1.0"/>
      </material>
    </visual>
    <visual>
      <origin rpy="0.41 0 -0.9" xyz="0.064 0.008 0.021"/>
      <geometry>
        <box size="0.09 .035 .05"/>
      </geometry>
      <material name="right_sandia_hand_skin">
        <color rgba="0.835 0.655 0.345 1.0"/>
      </material>
    </visual>
    <visual>
      <origin rpy="0 1.57079632679 0" xyz="0.02 0 -0.005"/>
      <geometry>
        <cylinder length="0.05" radius="0.038"/>
      </geometry>
      <material name="right_sandia_hand_skin">
        <color rgba="0.835 0.655 0.345 1.0"/>
      </material>
    </visual>
    <visual>
      <origin rpy="0 0 0.37" xyz="0.11 -0.01 -0.005"/>
      <geometry>
        <box size="0.09 .03 .06"/>
      </geometry>
      <material name="right_sandia_hand_skin">
        <color rgba="0.835 0.655 0.345 1.0"/>
      </material>
    </visual>
    <visual>
      <origin rpy="0 0 0.37" xyz="0.09 0.02 -0.005"/>
      <geometry>
        <box size="0.09 .03 .06"/>
      </geometry>
      <material name="right_sandia_hand_skin">
        <color rgba="0.835 0.655 0.345 1.0"/>
      </material>
    </visual>
    <visual>
      <origin rpy="0 0 0.37" xyz="0.060 0.05 -0.005"/>
      <geometry>
        <box size="0.09 .03 .06"/>
      </geometry>
      <material name="right_sandia_hand_skin">
        <color rgba="0.835 0.655 0.345 1.0"/>
      </material>
    </visual>
    <visual>
      <origin rpy="0 0 0.79" xyz="0.044 -0.04 -0.005"/>
      <geometry>
        <box size="0.09 .03 .06"/>
      </geometry>
      <material name="right_sandia_hand_skin">
        <color rgba="0.835 0.655 0.345 1.0"/>
      </material>
    </visual>
    <!--   end visual shape approximation of palm -->
    <!-- begin collision mesh of f2 ->
      <collision group="default">
        <origin xyz="0 0 0" rpy="0 0 0"/>
        <geometry>
          <mesh filename="package://sandia_hand_description/meshes/palm.stl"/>
        </geometry>
      </collision>
      <!-   end collision mesh of f2 -->
    <!-- begin visual mesh of f2    ->
      <visual>
        <origin xyz="0 0 0" rpy="0 0 0"/>
        <geometry>
          <mesh filename="package://sandia_hand_description/meshes/palm.stl"/>
        </geometry>
        <material name="${side}_sandia_hand_skin">
          <color rgba="0.835 0.655 0.345 1.0"/>
        </material>
      </visual>
      <!-   end visual mesh of f2 -->
  </link>
  <joint name="right_sandia_hand_joint" type="fixed">
    <parent link="base"/>
    <child link="right_palm"/>
    <origin rpy="0 -1.57079 0" xyz="0 0 0.0"/>
  </joint>
  <link name="right_f0_base">
    <origin rpy="0 0 0" xyz="0 0 0"/>
    <inertial>
      <mass value="0.35"/>
      <origin xyz="0 0 0"/>
      <inertia ixx="0.01" ixy="0" ixz="0" iyy="0.01" iyz="0" izz="0.01"/>
    </inertial>
  </link>
  <link name="right_f0_fixed_accel">
    <origin rpy="0 0 0" xyz="0 0 0"/>
    <inertial>
      <mass value="0.001"/>
      <origin xyz="0 0 0"/>
      <inertia ixx="0.01" ixy="0" ixz="0" iyy="0.01" iyz="0" izz="0.01"/>
    </inertial>
  </link>
  <link name="right_f0_0">
    <origin rpy="0 0 0" xyz="0 0 0"/>
    <inertial>
      <mass value="0.05"/>
      <origin xyz="0 0 0"/>
      <inertia ixx="0.01" ixy="0" ixz="0" iyy="0.01" iyz="0" izz="0.01"/>
    </inertial>
    <!-- begin simple shape approximation of f0 -->
    <collision group="default">
      <origin rpy="0 0 0" xyz="0 0 0.003"/>
      <geometry>
        <cylinder length="0.023" radius="0.015"/>
      </geometry>
    </collision>
    <collision group="other">
      <origin rpy="1.57079632679 0 0" xyz="0.011 0 0.003"/>
      <geometry>
        <cylinder length="0.023" radius="0.01"/>
      </geometry>
    </collision>
    <!--   end simple shape approximation of f0 -->
    <!-- begin visual shape approximation of f0 -->
    <visual>
      <origin rpy="0 0 0" xyz="0 0 0.003"/>
      <geometry>
        <cylinder length="0.023" radius="0.015"/>
      </geometry>
      <material name="right_sandia_hand_skin_suntan">
        <color rgba="0.7 0.4 0.2 1.0"/>
      </material>
    </visual>
    <visual>
      <origin rpy="1.57079632679 0 0" xyz="0.011 0 0.003"/>
      <geometry>
        <cylinder length="0.023" radius="0.01"/>
      </geometry>
      <material name="right_sandia_hand_skin_suntan">
        <color rgba="0.7 0.4 0.2 1.0"/>
      </material>
    </visual>
    <!--   end visual shape approximation of f0 -->
    <!-- begin collision mesh of f0 ->
      <collision group="default">
        <origin xyz="0 0 0" rpy="0 0 0"/>
        <geometry>
          <mesh filename="package://sandia_hand_description/meshes/f0.stl"/>
        </geometry>
      </collision>
      <!-   end collision mesh of f0 -->
    <!-- begin visual mesh of f0 ->
      <visual>
        <origin xyz="0 0 0" rpy="0 0 0"/>
        <geometry>
          <mesh filename="package://sandia_hand_description/meshes/f0.stl"/>
        </geometry>
        <material name="${side}_sandia_hand_skin_suntan">
          <color rgba="0.7 0.4 0.2 1.0"/>
        </material>
      </visual>
      <!-   end visual mesh of f0 -->
  </link>
  <link name="right_f0_1">
    <origin rpy="0 0 0" xyz="0 0 0"/>
    <inertial>
      <mass value="0.05"/>
      <origin xyz="0 0 0"/>
      <inertia ixx="0.01" ixy="0" ixz="0" iyy="0.01" iyz="0" izz="0.01"/>
    </inertial>
    <!-- begin simple shape approximation of f1 -->
    <collision group="default">
      <origin rpy="0 1.57079632679 0" xyz="0.024 0 0"/>
      <geometry>
        <cylinder length="0.067" radius="0.01"/>
      </geometry>
    </collision>
    <!--   end simple shape approximation of f1 -->
    <!-- begin visual shape approximation of f1 -->
    <visual>
      <origin rpy="0 1.57079632679 0" xyz="0.024 0 0"/>
      <geometry>
        <cylinder length="0.067" radius="0.01"/>
      </geometry>
      <material name="right_sandia_hand_skin">
        <color rgba="0.835 0.655 0.345 1.0"/>
      </material>
    </visual>
    <!--   end visual shape approximation of f1 -->
    <!-- begin collision mesh of f1 ->
      <collision group="default">
        <origin xyz="0 0 0" rpy="0 0 0"/>
        <geometry>
          <mesh filename="package://sandia_hand_description/meshes/f1.stl"/>
        </geometry>
      </collision>
      <!-   end collision mesh of f1 -->
    <!-- begin visual mesh of f1 ->
      <visual>
        <origin xyz="0 0 0" rpy="0 0 0"/>
        <geometry>
          <mesh filename="package://sandia_hand_description/meshes/f1.stl"/>
        </geometry>
        <material name="${side}_sandia_hand_skin">
          <color rgba="0.835 0.655 0.345 1.0"/>
        </material>
      </visual>
      <!-   end visual mesh of f1 -->
  </link>
  <link name="right_f0_1_accel">
    <origin rpy="0 0 0" xyz="0 0 0"/>
    <inertial>
      <mass value="0.001"/>
      <origin xyz="0 0 0"/>
      <inertia ixx="0.01" ixy="0" ixz="0" iyy="0.01" iyz="0" izz="0.01"/>
    </inertial>
  </link>
  <link name="right_f0_2">
    <origin rpy="0 0 0" xyz="0 0 0"/>
    <inertial>
      <mass value="0.05"/>
      <origin xyz="0 0 0"/>
      <inertia ixx="0.01" ixy="0" ixz="0" iyy="0.01" iyz="0" izz="0.01"/>
    </inertial>
    <!-- begin simple shape approximation of f2 -->
    <collision group="default">
      <origin rpy="0 1.57079632679 0" xyz="0.024 0 0"/>
      <geometry>
        <cylinder length="0.057" radius="0.009"/>
      </geometry>
    </collision>
    <collision group="other">
      <origin rpy="0 0 0" xyz="0.052 0 0"/>
      <geometry>
        <sphere radius="0.009"/>
      </geometry>
    </collision>
    <!--   end simple shape approximation of f2 -->
    <!-- begin visual shape approximation of f2 -->
    <visual>
      <origin rpy="0 1.57079632679 0" xyz="0.024 0 0"/>
      <geometry>
        <cylinder length="0.057" radius="0.009"/>
      </geometry>
      <material name="right_sandia_hand_skin_suntan">
        <color rgba="0.8 0.6 0.3 1.0"/>
      </material>
    </visual>
    <visual>
      <origin rpy="0 0 0" xyz="0.052 0 0"/>
      <geometry>
        <sphere radius="0.009"/>
      </geometry>
      <material name="right_sandia_hand_skin_suntan">
        <color rgba="0.8 0.6 0.3 1.0"/>
      </material>
    </visual>
    <!-- begin collision mesh of f2    ->
      <collision group="default">
        <origin xyz="0 0 0" rpy="0 0 0"/>
        <geometry>
          <mesh filename="package://sandia_hand_description/meshes/f2.stl"/>
        </geometry>
      </collision>
      <!-   end collision mesh of f2 -->
    <!-- begin visual mesh of f2    ->
      <visual>
        <origin xyz="0 0 0" rpy="0 0 0"/>
        <geometry>
          <mesh filename="package://sandia_hand_description/meshes/f2.stl"/>
        </geometry>
        <material name="${side}_sandia_hand_skin_suntan">
          <color rgba="0.8 0.6 0.3 1.0"/>
        </material>
      </visual>
      <!-   end visual mesh of f2 -->
  </link>
  <link name="right_f0_2_accel">
    <origin rpy="0 0 0" xyz="0 0 0"/>
    <inertial>
      <mass value="0.001"/>
      <origin xyz="0 0 0"/>
      <inertia ixx="0.01" ixy="0" ixz="0" iyy="0.01" iyz="0" izz="0.01"/>
    </inertial>
  </link>
  <joint name="right_f0_base" type="fixed">
    <parent link="right_palm"/>
    <child link="right_f0_base"/>
    <origin rpy="0 0 0.3" xyz="0.14 0.0 0"/>
  </joint>
  <joint name="right_f0_j0" type="revolute">
    <axis xyz="0 0 1"/>
    <parent link="right_f0_base"/>
    <child link="right_f0_0"/>
    <limit effort="1" lower="-1.57079632679" upper="1.57079632679" velocity="1"/>
    <safety_controller k_position="1000.0" k_velocity="1000.0" soft_lower_limit="-11.57079" soft_upper_limit="11.57079"/>
    <dynamics damping="0.2"/>
    <origin rpy="0 0 0" xyz="0 0 0"/>
  </joint>
  <joint name="right_f0_j1" type="revolute">
    <axis xyz="0 0 1"/>
    <parent link="right_f0_0"/>
    <child link="right_f0_1"/>
    <limit effort="1" lower="-1.57079632679" upper="1.57079632679" velocity="1"/>
    <safety_controller k_position="1000.0" k_velocity="1000.0" soft_lower_limit="-11.57079" soft_upper_limit="11.57079"/>
    <dynamics damping="0.2"/>
    <origin rpy="1.57079632679 0 0" xyz="0.028 0 0"/>
  </joint>
  <joint name="right_f0_j2" type="revolute">
    <axis xyz="0 0 1"/>
    <parent link="right_f0_1"/>
    <child link="right_f0_2"/>
    <origin rpy="0 0 0" xyz="0.05 0 0"/>
    <safety_controller k_position="1000.0" k_velocity="1000.0" soft_lower_limit="-11.57079" soft_upper_limit="11.57079"/>
    <dynamics damping="0.2"/>
    <limit effort="1" lower="-1.57079632679" upper="1.57079632679" velocity="1"/>
  </joint>
  <joint name="right_f0_fixed_accel" type="fixed">
    <parent link="right_f0_base"/>
    <child link="right_f0_fixed_accel"/>
    <origin rpy="0 0 0" xyz="-0.05 0 0"/>
  </joint>
  <joint name="right_f0_1_accel" type="fixed">
    <parent link="right_f0_1"/>
    <child link="right_f0_1_accel"/>
    <origin rpy="-1.57079632679 0 0" xyz="0.03 0 0"/>
  </joint>
  <joint name="right_f0_2_accel" type="fixed">
    <parent link="right_f0_2"/>
    <child link="right_f0_2_accel"/>
    <origin rpy="-1.57079632679 0 0" xyz="0.04 0 0"/>
  </joint>
  <transmission name="right_f0_j0" type="pr2_mechanism_model/SimpleTransmission">
    <joint name="right_f0_j0"/>
    <actuator name="right_f0_j0_motor"/>
    <mechanicalReduction>1</mechanicalReduction>
  </transmission>
  <transmission name="right_f0_j1" type="pr2_mechanism_model/SimpleTransmission">
    <joint name="right_f0_j1"/>
    <actuator name="right_f0_j1_motor"/>
    <mechanicalReduction>1</mechanicalReduction>
  </transmission>
  <transmission name="right_f0_j2" type="pr2_mechanism_model/SimpleTransmission">
    <joint name="right_f0_j2"/>
    <actuator name="right_f0_j2_motor"/>
    <mechanicalReduction>1</mechanicalReduction>
  </transmission>
  <link name="right_f1_base">
    <origin rpy="0 0 0" xyz="0 0 0"/>
    <inertial>
      <mass value="0.35"/>
      <origin xyz="0 0 0"/>
      <inertia ixx="0.01" ixy="0" ixz="0" iyy="0.01" iyz="0" izz="0.01"/>
    </inertial>
  </link>
  <link name="right_f1_fixed_accel">
    <origin rpy="0 0 0" xyz="0 0 0"/>
    <inertial>
      <mass value="0.001"/>
      <origin xyz="0 0 0"/>
      <inertia ixx="0.01" ixy="0" ixz="0" iyy="0.01" iyz="0" izz="0.01"/>
    </inertial>
  </link>
  <link name="right_f1_0">
    <origin rpy="0 0 0" xyz="0 0 0"/>
    <inertial>
      <mass value="0.05"/>
      <origin xyz="0 0 0"/>
      <inertia ixx="0.01" ixy="0" ixz="0" iyy="0.01" iyz="0" izz="0.01"/>
    </inertial>
    <!-- begin simple shape approximation of f0 -->
    <collision group="default">
      <origin rpy="0 0 0" xyz="0 0 0.003"/>
      <geometry>
        <cylinder length="0.023" radius="0.015"/>
      </geometry>
    </collision>
    <collision group="other">
      <origin rpy="1.57079632679 0 0" xyz="0.011 0 0.003"/>
      <geometry>
        <cylinder length="0.023" radius="0.01"/>
      </geometry>
    </collision>
    <!--   end simple shape approximation of f0 -->
    <!-- begin visual shape approximation of f0 -->
    <visual>
      <origin rpy="0 0 0" xyz="0 0 0.003"/>
      <geometry>
        <cylinder length="0.023" radius="0.015"/>
      </geometry>
      <material name="right_sandia_hand_skin_suntan">
        <color rgba="0.7 0.4 0.2 1.0"/>
      </material>
    </visual>
    <visual>
      <origin rpy="1.57079632679 0 0" xyz="0.011 0 0.003"/>
      <geometry>
        <cylinder length="0.023" radius="0.01"/>
      </geometry>
      <material name="right_sandia_hand_skin_suntan">
        <color rgba="0.7 0.4 0.2 1.0"/>
      </material>
    </visual>
    <!--   end visual shape approximation of f0 -->
    <!-- begin collision mesh of f0 ->
      <collision group="default">
        <origin xyz="0 0 0" rpy="0 0 0"/>
        <geometry>
          <mesh filename="package://sandia_hand_description/meshes/f0.stl"/>
        </geometry>
      </collision>
      <!-   end collision mesh of f0 -->
    <!-- begin visual mesh of f0 ->
      <visual>
        <origin xyz="0 0 0" rpy="0 0 0"/>
        <geometry>
          <mesh filename="package://sandia_hand_description/meshes/f0.stl"/>
        </geometry>
        <material name="${side}_sandia_hand_skin_suntan">
          <color rgba="0.7 0.4 0.2 1.0"/>
        </material>
      </visual>
      <!-   end visual mesh of f0 -->
  </link>
  <link name="right_f1_1">
    <origin rpy="0 0 0" xyz="0 0 0"/>
    <inertial>
      <mass value="0.05"/>
      <origin xyz="0 0 0"/>
      <inertia ixx="0.01" ixy="0" ixz="0" iyy="0.01" iyz="0" izz="0.01"/>
    </inertial>
    <!-- begin simple shape approximation of f1 -->
    <collision group="default">
      <origin rpy="0 1.57079632679 0" xyz="0.024 0 0"/>
      <geometry>
        <cylinder length="0.067" radius="0.01"/>
      </geometry>
    </collision>
    <!--   end simple shape approximation of f1 -->
    <!-- begin visual shape approximation of f1 -->
    <visual>
      <origin rpy="0 1.57079632679 0" xyz="0.024 0 0"/>
      <geometry>
        <cylinder length="0.067" radius="0.01"/>
      </geometry>
      <material name="right_sandia_hand_skin">
        <color rgba="0.835 0.655 0.345 1.0"/>
      </material>
    </visual>
    <!--   end visual shape approximation of f1 -->
    <!-- begin collision mesh of f1 ->
      <collision group="default">
        <origin xyz="0 0 0" rpy="0 0 0"/>
        <geometry>
          <mesh filename="package://sandia_hand_description/meshes/f1.stl"/>
        </geometry>
      </collision>
      <!-   end collision mesh of f1 -->
    <!-- begin visual mesh of f1 ->
      <visual>
        <origin xyz="0 0 0" rpy="0 0 0"/>
        <geometry>
          <mesh filename="package://sandia_hand_description/meshes/f1.stl"/>
        </geometry>
        <material name="${side}_sandia_hand_skin">
          <color rgba="0.835 0.655 0.345 1.0"/>
        </material>
      </visual>
      <!-   end visual mesh of f1 -->
  </link>
  <link name="right_f1_1_accel">
    <origin rpy="0 0 0" xyz="0 0 0"/>
    <inertial>
      <mass value="0.001"/>
      <origin xyz="0 0 0"/>
      <inertia ixx="0.01" ixy="0" ixz="0" iyy="0.01" iyz="0" izz="0.01"/>
    </inertial>
  </link>
  <link name="right_f1_2">
    <origin rpy="0 0 0" xyz="0 0 0"/>
    <inertial>
      <mass value="0.05"/>
      <origin xyz="0 0 0"/>
      <inertia ixx="0.01" ixy="0" ixz="0" iyy="0.01" iyz="0" izz="0.01"/>
    </inertial>
    <!-- begin simple shape approximation of f2 -->
    <collision group="default">
      <origin rpy="0 1.57079632679 0" xyz="0.024 0 0"/>
      <geometry>
        <cylinder length="0.057" radius="0.009"/>
      </geometry>
    </collision>
    <collision group="other">
      <origin rpy="0 0 0" xyz="0.052 0 0"/>
      <geometry>
        <sphere radius="0.009"/>
      </geometry>
    </collision>
    <!--   end simple shape approximation of f2 -->
    <!-- begin visual shape approximation of f2 -->
    <visual>
      <origin rpy="0 1.57079632679 0" xyz="0.024 0 0"/>
      <geometry>
        <cylinder length="0.057" radius="0.009"/>
      </geometry>
      <material name="right_sandia_hand_skin_suntan">
        <color rgba="0.8 0.6 0.3 1.0"/>
      </material>
    </visual>
    <visual>
      <origin rpy="0 0 0" xyz="0.052 0 0"/>
      <geometry>
        <sphere radius="0.009"/>
      </geometry>
      <material name="right_sandia_hand_skin_suntan">
        <color rgba="0.8 0.6 0.3 1.0"/>
      </material>
    </visual>
    <!-- begin collision mesh of f2    ->
      <collision group="default">
        <origin xyz="0 0 0" rpy="0 0 0"/>
        <geometry>
          <mesh filename="package://sandia_hand_description/meshes/f2.stl"/>
        </geometry>
      </collision>
      <!-   end collision mesh of f2 -->
    <!-- begin visual mesh of f2    ->
      <visual>
        <origin xyz="0 0 0" rpy="0 0 0"/>
        <geometry>
          <mesh filename="package://sandia_hand_description/meshes/f2.stl"/>
        </geometry>
        <material name="${side}_sandia_hand_skin_suntan">
          <color rgba="0.8 0.6 0.3 1.0"/>
        </material>
      </visual>
      <!-   end visual mesh of f2 -->
  </link>
  <link name="right_f1_2_accel">
    <origin rpy="0 0 0" xyz="0 0 0"/>
    <inertial>
      <mass value="0.001"/>
      <origin xyz="0 0 0"/>
      <inertia ixx="0.01" ixy="0" ixz="0" iyy="0.01" iyz="0" izz="0.01"/>
    </inertial>
  </link>
  <joint name="right_f1_base" type="fixed">
    <parent link="right_palm"/>
    <child link="right_f1_base"/>
    <origin rpy="0 0 0.3" xyz="0.115 0.03122 0"/>
  </joint>
  <joint name="right_f1_j0" type="revolute">
    <axis xyz="0 0 1"/>
    <parent link="right_f1_base"/>
    <child link="right_f1_0"/>
    <limit effort="1" lower="-1.57079632679" upper="1.57079632679" velocity="1"/>
    <safety_controller k_position="1000.0" k_velocity="1000.0" soft_lower_limit="-11.57079" soft_upper_limit="11.57079"/>
    <dynamics damping="0.2"/>
    <origin rpy="0 0 0" xyz="0 0 0"/>
  </joint>
  <joint name="right_f1_j1" type="revolute">
    <axis xyz="0 0 1"/>
    <parent link="right_f1_0"/>
    <child link="right_f1_1"/>
    <limit effort="1" lower="-1.57079632679" upper="1.57079632679" velocity="1"/>
    <safety_controller k_position="1000.0" k_velocity="1000.0" soft_lower_limit="-11.57079" soft_upper_limit="11.57079"/>
    <dynamics damping="0.2"/>
    <origin rpy="1.57079632679 0 0" xyz="0.028 0 0"/>
  </joint>
  <joint name="right_f1_j2" type="revolute">
    <axis xyz="0 0 1"/>
    <parent link="right_f1_1"/>
    <child link="right_f1_2"/>
    <origin rpy="0 0 0" xyz="0.05 0 0"/>
    <safety_controller k_position="1000.0" k_velocity="1000.0" soft_lower_limit="-11.57079" soft_upper_limit="11.57079"/>
    <dynamics damping="0.2"/>
    <limit effort="1" lower="-1.57079632679" upper="1.57079632679" velocity="1"/>
  </joint>
  <joint name="right_f1_fixed_accel" type="fixed">
    <parent link="right_f1_base"/>
    <child link="right_f1_fixed_accel"/>
    <origin rpy="0 0 0" xyz="-0.05 0 0"/>
  </joint>
  <joint name="right_f1_1_accel" type="fixed">
    <parent link="right_f1_1"/>
    <child link="right_f1_1_accel"/>
    <origin rpy="-1.57079632679 0 0" xyz="0.03 0 0"/>
  </joint>
  <joint name="right_f1_2_accel" type="fixed">
    <parent link="right_f1_2"/>
    <child link="right_f1_2_accel"/>
    <origin rpy="-1.57079632679 0 0" xyz="0.04 0 0"/>
  </joint>
  <transmission name="right_f1_j0" type="pr2_mechanism_model/SimpleTransmission">
    <joint name="right_f1_j0"/>
    <actuator name="right_f1_j0_motor"/>
    <mechanicalReduction>1</mechanicalReduction>
  </transmission>
  <transmission name="right_f1_j1" type="pr2_mechanism_model/SimpleTransmission">
    <joint name="right_f1_j1"/>
    <actuator name="right_f1_j1_motor"/>
    <mechanicalReduction>1</mechanicalReduction>
  </transmission>
  <transmission name="right_f1_j2" type="pr2_mechanism_model/SimpleTransmission">
    <joint name="right_f1_j2"/>
    <actuator name="right_f1_j2_motor"/>
    <mechanicalReduction>1</mechanicalReduction>
  </transmission>
  <link name="right_f2_base">
    <origin rpy="0 0 0" xyz="0 0 0"/>
    <inertial>
      <mass value="0.35"/>
      <origin xyz="0 0 0"/>
      <inertia ixx="0.01" ixy="0" ixz="0" iyy="0.01" iyz="0" izz="0.01"/>
    </inertial>
  </link>
  <link name="right_f2_fixed_accel">
    <origin rpy="0 0 0" xyz="0 0 0"/>
    <inertial>
      <mass value="0.001"/>
      <origin xyz="0 0 0"/>
      <inertia ixx="0.01" ixy="0" ixz="0" iyy="0.01" iyz="0" izz="0.01"/>
    </inertial>
  </link>
  <link name="right_f2_0">
    <origin rpy="0 0 0" xyz="0 0 0"/>
    <inertial>
      <mass value="0.05"/>
      <origin xyz="0 0 0"/>
      <inertia ixx="0.01" ixy="0" ixz="0" iyy="0.01" iyz="0" izz="0.01"/>
    </inertial>
    <!-- begin simple shape approximation of f0 -->
    <collision group="default">
      <origin rpy="0 0 0" xyz="0 0 0.003"/>
      <geometry>
        <cylinder length="0.023" radius="0.015"/>
      </geometry>
    </collision>
    <collision group="other">
      <origin rpy="1.57079632679 0 0" xyz="0.011 0 0.003"/>
      <geometry>
        <cylinder length="0.023" radius="0.01"/>
      </geometry>
    </collision>
    <!--   end simple shape approximation of f0 -->
    <!-- begin visual shape approximation of f0 -->
    <visual>
      <origin rpy="0 0 0" xyz="0 0 0.003"/>
      <geometry>
        <cylinder length="0.023" radius="0.015"/>
      </geometry>
      <material name="right_sandia_hand_skin_suntan">
        <color rgba="0.7 0.4 0.2 1.0"/>
      </material>
    </visual>
    <visual>
      <origin rpy="1.57079632679 0 0" xyz="0.011 0 0.003"/>
      <geometry>
        <cylinder length="0.023" radius="0.01"/>
      </geometry>
      <material name="right_sandia_hand_skin_suntan">
        <color rgba="0.7 0.4 0.2 1.0"/>
      </material>
    </visual>
    <!--   end visual shape approximation of f0 -->
    <!-- begin collision mesh of f0 ->
      <collision group="default">
        <origin xyz="0 0 0" rpy="0 0 0"/>
        <geometry>
          <mesh filename="package://sandia_hand_description/meshes/f0.stl"/>
        </geometry>
      </collision>
      <!-   end collision mesh of f0 -->
    <!-- begin visual mesh of f0 ->
      <visual>
        <origin xyz="0 0 0" rpy="0 0 0"/>
        <geometry>
          <mesh filename="package://sandia_hand_description/meshes/f0.stl"/>
        </geometry>
        <material name="${side}_sandia_hand_skin_suntan">
          <color rgba="0.7 0.4 0.2 1.0"/>
        </material>
      </visual>
      <!-   end visual mesh of f0 -->
  </link>
  <link name="right_f2_1">
    <origin rpy="0 0 0" xyz="0 0 0"/>
    <inertial>
      <mass value="0.05"/>
      <origin xyz="0 0 0"/>
      <inertia ixx="0.01" ixy="0" ixz="0" iyy="0.01" iyz="0" izz="0.01"/>
    </inertial>
    <!-- begin simple shape approximation of f1 -->
    <collision group="default">
      <origin rpy="0 1.57079632679 0" xyz="0.024 0 0"/>
      <geometry>
        <cylinder length="0.067" radius="0.01"/>
      </geometry>
    </collision>
    <!--   end simple shape approximation of f1 -->
    <!-- begin visual shape approximation of f1 -->
    <visual>
      <origin rpy="0 1.57079632679 0" xyz="0.024 0 0"/>
      <geometry>
        <cylinder length="0.067" radius="0.01"/>
      </geometry>
      <material name="right_sandia_hand_skin">
        <color rgba="0.835 0.655 0.345 1.0"/>
      </material>
    </visual>
    <!--   end visual shape approximation of f1 -->
    <!-- begin collision mesh of f1 ->
      <collision group="default">
        <origin xyz="0 0 0" rpy="0 0 0"/>
        <geometry>
          <mesh filename="package://sandia_hand_description/meshes/f1.stl"/>
        </geometry>
      </collision>
      <!-   end collision mesh of f1 -->
    <!-- begin visual mesh of f1 ->
      <visual>
        <origin xyz="0 0 0" rpy="0 0 0"/>
        <geometry>
          <mesh filename="package://sandia_hand_description/meshes/f1.stl"/>
        </geometry>
        <material name="${side}_sandia_hand_skin">
          <color rgba="0.835 0.655 0.345 1.0"/>
        </material>
      </visual>
      <!-   end visual mesh of f1 -->
  </link>
  <link name="right_f2_1_accel">
    <origin rpy="0 0 0" xyz="0 0 0"/>
    <inertial>
      <mass value="0.001"/>
      <origin xyz="0 0 0"/>
      <inertia ixx="0.01" ixy="0" ixz="0" iyy="0.01" iyz="0" izz="0.01"/>
    </inertial>
  </link>
  <link name="right_f2_2">
    <origin rpy="0 0 0" xyz="0 0 0"/>
    <inertial>
      <mass value="0.05"/>
      <origin xyz="0 0 0"/>
      <inertia ixx="0.01" ixy="0" ixz="0" iyy="0.01" iyz="0" izz="0.01"/>
    </inertial>
    <!-- begin simple shape approximation of f2 -->
    <collision group="default">
      <origin rpy="0 1.57079632679 0" xyz="0.024 0 0"/>
      <geometry>
        <cylinder length="0.057" radius="0.009"/>
      </geometry>
    </collision>
    <collision group="other">
      <origin rpy="0 0 0" xyz="0.052 0 0"/>
      <geometry>
        <sphere radius="0.009"/>
      </geometry>
    </collision>
    <!--   end simple shape approximation of f2 -->
    <!-- begin visual shape approximation of f2 -->
    <visual>
      <origin rpy="0 1.57079632679 0" xyz="0.024 0 0"/>
      <geometry>
        <cylinder length="0.057" radius="0.009"/>
      </geometry>
      <material name="right_sandia_hand_skin_suntan">
        <color rgba="0.8 0.6 0.3 1.0"/>
      </material>
    </visual>
    <visual>
      <origin rpy="0 0 0" xyz="0.052 0 0"/>
      <geometry>
        <sphere radius="0.009"/>
      </geometry>
      <material name="right_sandia_hand_skin_suntan">
        <color rgba="0.8 0.6 0.3 1.0"/>
      </material>
    </visual>
    <!-- begin collision mesh of f2    ->
      <collision group="default">
        <origin xyz="0 0 0" rpy="0 0 0"/>
        <geometry>
          <mesh filename="package://sandia_hand_description/meshes/f2.stl"/>
        </geometry>
      </collision>
      <!-   end collision mesh of f2 -->
    <!-- begin visual mesh of f2    ->
      <visual>
        <origin xyz="0 0 0" rpy="0 0 0"/>
        <geometry>
          <mesh filename="package://sandia_hand_description/meshes/f2.stl"/>
        </geometry>
        <material name="${side}_sandia_hand_skin_suntan">
          <color rgba="0.8 0.6 0.3 1.0"/>
        </material>
      </visual>
      <!-   end visual mesh of f2 -->
  </link>
  <link name="right_f2_2_accel">
    <origin rpy="0 0 0" xyz="0 0 0"/>
    <inertial>
      <mass value="0.001"/>
      <origin xyz="0 0 0"/>
      <inertia ixx="0.01" ixy="0" ixz="0" iyy="0.01" iyz="0" izz="0.01"/>
    </inertial>
  </link>
  <joint name="right_f2_base" type="fixed">
    <parent link="right_palm"/>
    <child link="right_f2_base"/>
    <origin rpy="0 0 0.3" xyz="0.09 0.06245 0"/>
  </joint>
  <joint name="right_f2_j0" type="revolute">
    <axis xyz="0 0 1"/>
    <parent link="right_f2_base"/>
    <child link="right_f2_0"/>
    <limit effort="1" lower="-1.57079632679" upper="1.57079632679" velocity="1"/>
    <safety_controller k_position="1000.0" k_velocity="1000.0" soft_lower_limit="-11.57079" soft_upper_limit="11.57079"/>
    <dynamics damping="0.2"/>
    <origin rpy="0 0 0" xyz="0 0 0"/>
  </joint>
  <joint name="right_f2_j1" type="revolute">
    <axis xyz="0 0 1"/>
    <parent link="right_f2_0"/>
    <child link="right_f2_1"/>
    <limit effort="1" lower="-1.57079632679" upper="1.57079632679" velocity="1"/>
    <safety_controller k_position="1000.0" k_velocity="1000.0" soft_lower_limit="-11.57079" soft_upper_limit="11.57079"/>
    <dynamics damping="0.2"/>
    <origin rpy="1.57079632679 0 0" xyz="0.028 0 0"/>
  </joint>
  <joint name="right_f2_j2" type="revolute">
    <axis xyz="0 0 1"/>
    <parent link="right_f2_1"/>
    <child link="right_f2_2"/>
    <origin rpy="0 0 0" xyz="0.05 0 0"/>
    <safety_controller k_position="1000.0" k_velocity="1000.0" soft_lower_limit="-11.57079" soft_upper_limit="11.57079"/>
    <dynamics damping="0.2"/>
    <limit effort="1" lower="-1.57079632679" upper="1.57079632679" velocity="1"/>
  </joint>
  <joint name="right_f2_fixed_accel" type="fixed">
    <parent link="right_f2_base"/>
    <child link="right_f2_fixed_accel"/>
    <origin rpy="0 0 0" xyz="-0.05 0 0"/>
  </joint>
  <joint name="right_f2_1_accel" type="fixed">
    <parent link="right_f2_1"/>
    <child link="right_f2_1_accel"/>
    <origin rpy="-1.57079632679 0 0" xyz="0.03 0 0"/>
  </joint>
  <joint name="right_f2_2_accel" type="fixed">
    <parent link="right_f2_2"/>
    <child link="right_f2_2_accel"/>
    <origin rpy="-1.57079632679 0 0" xyz="0.04 0 0"/>
  </joint>
  <transmission name="right_f2_j0" type="pr2_mechanism_model/SimpleTransmission">
    <joint name="right_f2_j0"/>
    <actuator name="right_f2_j0_motor"/>
    <mechanicalReduction>1</mechanicalReduction>
  </transmission>
  <transmission name="right_f2_j1" type="pr2_mechanism_model/SimpleTransmission">
    <joint name="right_f2_j1"/>
    <actuator name="right_f2_j1_motor"/>
    <mechanicalReduction>1</mechanicalReduction>
  </transmission>
  <transmission name="right_f2_j2" type="pr2_mechanism_model/SimpleTransmission">
    <joint name="right_f2_j2"/>
    <actuator name="right_f2_j2_motor"/>
    <mechanicalReduction>1</mechanicalReduction>
  </transmission>
  <link name="right_f3_base">
    <origin rpy="0 0 0" xyz="0 0 0"/>
    <inertial>
      <mass value="0.35"/>
      <origin xyz="0 0 0"/>
      <inertia ixx="0.01" ixy="0" ixz="0" iyy="0.01" iyz="0" izz="0.01"/>
    </inertial>
  </link>
  <link name="right_f3_fixed_accel">
    <origin rpy="0 0 0" xyz="0 0 0"/>
    <inertial>
      <mass value="0.001"/>
      <origin xyz="0 0 0"/>
      <inertia ixx="0.01" ixy="0" ixz="0" iyy="0.01" iyz="0" izz="0.01"/>
    </inertial>
  </link>
  <link name="right_f3_0">
    <origin rpy="0 0 0" xyz="0 0 0"/>
    <inertial>
      <mass value="0.05"/>
      <origin xyz="0 0 0"/>
      <inertia ixx="0.01" ixy="0" ixz="0" iyy="0.01" iyz="0" izz="0.01"/>
    </inertial>
    <!-- begin simple shape approximation of f0 -->
    <collision group="default">
      <origin rpy="0 0 0" xyz="0 0 0.003"/>
      <geometry>
        <cylinder length="0.023" radius="0.015"/>
      </geometry>
    </collision>
    <collision group="other">
      <origin rpy="1.57079632679 0 0" xyz="0.011 0 0.003"/>
      <geometry>
        <cylinder length="0.023" radius="0.01"/>
      </geometry>
    </collision>
    <!--   end simple shape approximation of f0 -->
    <!-- begin visual shape approximation of f0 -->
    <visual>
      <origin rpy="0 0 0" xyz="0 0 0.003"/>
      <geometry>
        <cylinder length="0.023" radius="0.015"/>
      </geometry>
      <material name="right_sandia_hand_skin_suntan">
        <color rgba="0.7 0.4 0.2 1.0"/>
      </material>
    </visual>
    <visual>
      <origin rpy="1.57079632679 0 0" xyz="0.011 0 0.003"/>
      <geometry>
        <cylinder length="0.023" radius="0.01"/>
      </geometry>
      <material name="right_sandia_hand_skin_suntan">
        <color rgba="0.7 0.4 0.2 1.0"/>
      </material>
    </visual>
    <!--   end visual shape approximation of f0 -->
    <!-- begin collision mesh of f0 ->
      <collision group="default">
        <origin xyz="0 0 0" rpy="0 0 0"/>
        <geometry>
          <mesh filename="package://sandia_hand_description/meshes/f0.stl"/>
        </geometry>
      </collision>
      <!-   end collision mesh of f0 -->
    <!-- begin visual mesh of f0 ->
      <visual>
        <origin xyz="0 0 0" rpy="0 0 0"/>
        <geometry>
          <mesh filename="package://sandia_hand_description/meshes/f0.stl"/>
        </geometry>
        <material name="${side}_sandia_hand_skin_suntan">
          <color rgba="0.7 0.4 0.2 1.0"/>
        </material>
      </visual>
      <!-   end visual mesh of f0 -->
  </link>
  <link name="right_f3_1">
    <origin rpy="0 0 0" xyz="0 0 0"/>
    <inertial>
      <mass value="0.05"/>
      <origin xyz="0 0 0"/>
      <inertia ixx="0.01" ixy="0" ixz="0" iyy="0.01" iyz="0" izz="0.01"/>
    </inertial>
    <!-- begin simple shape approximation of f1 -->
    <collision group="default">
      <origin rpy="0 1.57079632679 0" xyz="0.024 0 0"/>
      <geometry>
        <cylinder length="0.067" radius="0.01"/>
      </geometry>
    </collision>
    <!--   end simple shape approximation of f1 -->
    <!-- begin visual shape approximation of f1 -->
    <visual>
      <origin rpy="0 1.57079632679 0" xyz="0.024 0 0"/>
      <geometry>
        <cylinder length="0.067" radius="0.01"/>
      </geometry>
      <material name="right_sandia_hand_skin">
        <color rgba="0.835 0.655 0.345 1.0"/>
      </material>
    </visual>
    <!--   end visual shape approximation of f1 -->
    <!-- begin collision mesh of f1 ->
      <collision group="default">
        <origin xyz="0 0 0" rpy="0 0 0"/>
        <geometry>
          <mesh filename="package://sandia_hand_description/meshes/f1.stl"/>
        </geometry>
      </collision>
      <!-   end collision mesh of f1 -->
    <!-- begin visual mesh of f1 ->
      <visual>
        <origin xyz="0 0 0" rpy="0 0 0"/>
        <geometry>
          <mesh filename="package://sandia_hand_description/meshes/f1.stl"/>
        </geometry>
        <material name="${side}_sandia_hand_skin">
          <color rgba="0.835 0.655 0.345 1.0"/>
        </material>
      </visual>
      <!-   end visual mesh of f1 -->
  </link>
  <link name="right_f3_1_accel">
    <origin rpy="0 0 0" xyz="0 0 0"/>
    <inertial>
      <mass value="0.001"/>
      <origin xyz="0 0 0"/>
      <inertia ixx="0.01" ixy="0" ixz="0" iyy="0.01" iyz="0" izz="0.01"/>
    </inertial>
  </link>
  <link name="right_f3_2">
    <origin rpy="0 0 0" xyz="0 0 0"/>
    <inertial>
      <mass value="0.05"/>
      <origin xyz="0 0 0"/>
      <inertia ixx="0.01" ixy="0" ixz="0" iyy="0.01" iyz="0" izz="0.01"/>
    </inertial>
    <!-- begin simple shape approximation of f2 -->
    <collision group="default">
      <origin rpy="0 1.57079632679 0" xyz="0.024 0 0"/>
      <geometry>
        <cylinder length="0.057" radius="0.009"/>
      </geometry>
    </collision>
    <collision group="other">
      <origin rpy="0 0 0" xyz="0.052 0 0"/>
      <geometry>
        <sphere radius="0.009"/>
      </geometry>
    </collision>
    <!--   end simple shape approximation of f2 -->
    <!-- begin visual shape approximation of f2 -->
    <visual>
      <origin rpy="0 1.57079632679 0" xyz="0.024 0 0"/>
      <geometry>
        <cylinder length="0.057" radius="0.009"/>
      </geometry>
      <material name="right_sandia_hand_skin_suntan">
        <color rgba="0.8 0.6 0.3 1.0"/>
      </material>
    </visual>
    <visual>
      <origin rpy="0 0 0" xyz="0.052 0 0"/>
      <geometry>
        <sphere radius="0.009"/>
      </geometry>
      <material name="right_sandia_hand_skin_suntan">
        <color rgba="0.8 0.6 0.3 1.0"/>
      </material>
    </visual>
    <!-- begin collision mesh of f2    ->
      <collision group="default">
        <origin xyz="0 0 0" rpy="0 0 0"/>
        <geometry>
          <mesh filename="package://sandia_hand_description/meshes/f2.stl"/>
        </geometry>
      </collision>
      <!-   end collision mesh of f2 -->
    <!-- begin visual mesh of f2    ->
      <visual>
        <origin xyz="0 0 0" rpy="0 0 0"/>
        <geometry>
          <mesh filename="package://sandia_hand_description/meshes/f2.stl"/>
        </geometry>
        <material name="${side}_sandia_hand_skin_suntan">
          <color rgba="0.8 0.6 0.3 1.0"/>
        </material>
      </visual>
      <!-   end visual mesh of f2 -->
  </link>
  <link name="right_f3_2_accel">
    <origin rpy="0 0 0" xyz="0 0 0"/>
    <inertial>
      <mass value="0.001"/>
      <origin xyz="0 0 0"/>
      <inertia ixx="0.01" ixy="0" ixz="0" iyy="0.01" iyz="0" izz="0.01"/>
    </inertial>
  </link>
  <joint name="right_f3_base" type="fixed">
    <parent link="right_palm"/>
    <child link="right_f3_base"/>
    <origin rpy="0 -1.57079632679 -2.3562" xyz="0.03995 -0.04383 0.014"/>
  </joint>
  <joint name="right_f3_j0" type="revolute">
    <axis xyz="0 0 1"/>
    <parent link="right_f3_base"/>
    <child link="right_f3_0"/>
    <limit effort="1" lower="-1.57079632679" upper="1.57079632679" velocity="1"/>
    <safety_controller k_position="1000.0" k_velocity="1000.0" soft_lower_limit="-11.57079" soft_upper_limit="11.57079"/>
    <dynamics damping="0.2"/>
    <origin rpy="0 0 0" xyz="0 0 0"/>
  </joint>
  <joint name="right_f3_j1" type="revolute">
    <axis xyz="0 0 1"/>
    <parent link="right_f3_0"/>
    <child link="right_f3_1"/>
    <limit effort="1" lower="-1.57079632679" upper="1.57079632679" velocity="1"/>
    <safety_controller k_position="1000.0" k_velocity="1000.0" soft_lower_limit="-11.57079" soft_upper_limit="11.57079"/>
    <dynamics damping="0.2"/>
    <origin rpy="1.57079632679 0 0" xyz="0.028 0 0"/>
  </joint>
  <joint name="right_f3_j2" type="revolute">
    <axis xyz="0 0 1"/>
    <parent link="right_f3_1"/>
    <child link="right_f3_2"/>
    <origin rpy="0 0 0" xyz="0.05 0 0"/>
    <safety_controller k_position="1000.0" k_velocity="1000.0" soft_lower_limit="-11.57079" soft_upper_limit="11.57079"/>
    <dynamics damping="0.2"/>
    <limit effort="1" lower="-1.57079632679" upper="1.57079632679" velocity="1"/>
  </joint>
  <joint name="right_f3_fixed_accel" type="fixed">
    <parent link="right_f3_base"/>
    <child link="right_f3_fixed_accel"/>
    <origin rpy="0 0 0" xyz="-0.05 0 0"/>
  </joint>
  <joint name="right_f3_1_accel" type="fixed">
    <parent link="right_f3_1"/>
    <child link="right_f3_1_accel"/>
    <origin rpy="-1.57079632679 0 0" xyz="0.03 0 0"/>
  </joint>
  <joint name="right_f3_2_accel" type="fixed">
    <parent link="right_f3_2"/>
    <child link="right_f3_2_accel"/>
    <origin rpy="-1.57079632679 0 0" xyz="0.04 0 0"/>
  </joint>
  <transmission name="right_f3_j0" type="pr2_mechanism_model/SimpleTransmission">
    <joint name="right_f3_j0"/>
    <actuator name="right_f3_j0_motor"/>
    <mechanicalReduction>1</mechanicalReduction>
  </transmission>
  <transmission name="right_f3_j1" type="pr2_mechanism_model/SimpleTransmission">
    <joint name="right_f3_j1"/>
    <actuator name="right_f3_j1_motor"/>
    <mechanicalReduction>1</mechanicalReduction>
  </transmission>
  <transmission name="right_f3_j2" type="pr2_mechanism_model/SimpleTransmission">
    <joint name="right_f3_j2"/>
    <actuator name="right_f3_j2_motor"/>
    <mechanicalReduction>1</mechanicalReduction>
  </transmission>
</robot>

