<?xml version="1.0" ?>
<!-- =================================================================================== -->
<!-- |    This document was autogenerated by xacro from robots/camhand_1.urdf.xacro    | -->
<!-- |    EDITING THIS FILE BY HAND IS NOT RECOMMENDED                                 | -->
<!-- =================================================================================== -->
<robot name="humanoid" xmlns:controller="http://playerstage.sourceforge.net/gazebo/xmlschema/#controller" xmlns:interface="http://playerstage.sourceforge.net/gazebo/xmlschema/#interface" xmlns:sensor="http://playerstage.sourceforge.net/gazebo/xmlschema/#sensor" xmlns:xacro="http://www.ros.org/wiki/xacro">
  <link name="world"/>
  <link name="right_palm">
    <origin rpy="0 0 0" xyz="0 0 0"/>
    <inertial>
      <mass value="0.1"/>
      <origin xyz="0 0 0"/>
      <inertia ixx="0.01" ixy="0" ixz="0" iyy="0.01" iyz="0" izz="0.01"/>
    </inertial>
    <collision>
      <origin rpy="0 0 0" xyz="0 0 0"/>
      <geometry>
        <mesh filename="model://mit_camhand/meshes/palm.stl"/>
      </geometry>
    </collision>
    <visual>
      <origin rpy="0 0 0" xyz="0 0 0"/>
      <geometry>
        <mesh filename="model://mit_camhand/meshes/palm.stl"/>
      </geometry>
      <material name="right_camhand_skin">
        <color rgba="0.835 0.655 0.345 1.0"/>
      </material>
    </visual>
  </link>
  <joint name="right_camhand_joint" type="fixed">
    <parent link="world"/>
    <child link="right_palm"/>
    <origin rpy="0 0 0" xyz="0 0 0"/>
  </joint>
  <link name="right_f0_base">
    <origin rpy="0 0 0" xyz="0 0 0"/>
    <inertial>
      <mass value="0.1"/>
      <origin xyz="0 0 0"/>
      <inertia ixx="0.01" ixy="0" ixz="0" iyy="0.01" iyz="0" izz="0.01"/>
    </inertial>
  </link>
  <link name="right_f0_fixed_accel">
    <origin rpy="0 0 0" xyz="0 0 0"/>
    <inertial>
      <mass value="0.1"/>
      <origin xyz="0 0 0"/>
      <inertia ixx="0.01" ixy="0" ixz="0" iyy="0.01" iyz="0" izz="0.01"/>
    </inertial>
  </link>
  <link name="right_f0_0">
    <origin rpy="0 0 0" xyz="0 0 0"/>
    <inertial>
      <mass value="0.1"/>
      <origin xyz="0 0 0"/>
      <inertia ixx="0.01" ixy="0" ixz="0" iyy="0.01" iyz="0" izz="0.01"/>
    </inertial>
    <collision>
      <origin rpy="0 0 0" xyz="0 0 0"/>
      <geometry>
        <mesh filename="model://mit_camhand/meshes/f0.stl"/>
      </geometry>
    </collision>
    <visual>
      <origin rpy="0 0 0" xyz="0 0 0"/>
      <geometry>
        <mesh filename="model://mit_camhand/meshes/f0.stl"/>
      </geometry>
      <material name="right_camhand_skin_suntan">
        <color rgba="0.7 0.4 0.2 1.0"/>
      </material>
    </visual>
  </link>
  <link name="right_f0_1">
    <origin rpy="0 0 0" xyz="0 0 0"/>
    <inertial>
      <mass value="0.1"/>
      <origin xyz="0 0 0"/>
      <inertia ixx="0.01" ixy="0" ixz="0" iyy="0.01" iyz="0" izz="0.01"/>
    </inertial>
    <collision>
      <origin rpy="0 0 0" xyz="0 0 0"/>
      <geometry>
        <mesh filename="model://mit_camhand/meshes/f1.stl"/>
      </geometry>
    </collision>
    <visual>
      <origin rpy="0 0 0" xyz="0 0 0"/>
      <geometry>
        <mesh filename="model://mit_camhand/meshes/f1.stl"/>
      </geometry>
      <material name="right_camhand_skin">
        <color rgba="0.835 0.655 0.345 1.0"/>
      </material>
    </visual>
  </link>
  <link name="right_f0_1_accel">
    <origin rpy="0 0 0" xyz="0 0 0"/>
    <inertial>
      <mass value="0.1"/>
      <origin xyz="0 0 0"/>
      <inertia ixx="0.01" ixy="0" ixz="0" iyy="0.01" iyz="0" izz="0.01"/>
    </inertial>
  </link>
  <link name="right_f0_2">
    <origin rpy="0 0 0" xyz="0 0 0"/>
    <inertial>
      <mass value="0.1"/>
      <origin xyz="0 0 0"/>
      <inertia ixx="0.01" ixy="0" ixz="0" iyy="0.01" iyz="0" izz="0.01"/>
    </inertial>
    <collision>
      <origin rpy="0 0 0" xyz="0 0 0"/>
      <geometry>
        <mesh filename="model://mit_camhand/meshes/f2.stl"/>
      </geometry>
    </collision>
    <visual>
      <origin rpy="0 0 0" xyz="0 0 0"/>
      <geometry>
        <mesh filename="model://mit_camhand/meshes/f2.stl"/>
      </geometry>
      <material name="right_camhand_skin_suntan">
        <color rgba="0.8 0.6 0.3 1.0"/>
      </material>
    </visual>
  </link>
  <link name="right_f0_2_accel">
    <origin rpy="0 0 0" xyz="0 0 0"/>
    <inertial>
      <mass value="0.1"/>
      <origin xyz="0 0 0"/>
      <inertia ixx="0.01" ixy="0" ixz="0" iyy="0.01" iyz="0" izz="0.01"/>
    </inertial>
  </link>
  <joint name="right_f0_base" type="fixed">
    <parent link="right_palm"/>
    <child link="right_f0_base"/>
    <origin rpy="0 0 0.3" xyz="0.14 0.0 0"/>
  </joint>
  <joint name="right_f0_j0" type="revolute">
    <axis xyz="0 0 1"/>
    <parent link="right_f0_base"/>
    <child link="right_f0_0"/>
    <limit effort="1" lower="-1.57079" upper="1.57079" velocity="1"/>
    <origin rpy="0 0 0" xyz="0 0 0"/>
  </joint>
  <joint name="right_f0_j1" type="revolute">
    <axis xyz="0 0 1"/>
    <parent link="right_f0_0"/>
    <child link="right_f0_1"/>
    <limit effort="1" lower="-1.57079" upper="1.57079" velocity="1"/>
    <origin rpy="1.57079 0 0" xyz="0.028 0 0"/>
  </joint>
  <joint name="right_f0_j2" type="revolute">
    <axis xyz="0 0 1"/>
    <parent link="right_f0_1"/>
    <child link="right_f0_2"/>
    <origin rpy="0 0 0" xyz="0.05 0 0"/>
    <limit effort="1" lower="-1.57079" upper="1.57079" velocity="1"/>
  </joint>
  <joint name="right_f0_fixed_accel" type="fixed">
    <parent link="right_f0_base"/>
    <child link="right_f0_fixed_accel"/>
    <origin rpy="0 0 0" xyz="-0.05 0 0"/>
  </joint>
  <joint name="right_f0_1_accel" type="fixed">
    <parent link="right_f0_1"/>
    <child link="right_f0_1_accel"/>
    <origin rpy="-1.5709 0 0" xyz="0.03 0 0"/>
  </joint>
  <joint name="right_f0_2_accel" type="fixed">
    <parent link="right_f0_2"/>
    <child link="right_f0_2_accel"/>
    <origin rpy="-1.5709 0 0" xyz="0.04 0 0"/>
  </joint>
  <link name="right_f1_base">
    <origin rpy="0 0 0" xyz="0 0 0"/>
    <inertial>
      <mass value="0.1"/>
      <origin xyz="0 0 0"/>
      <inertia ixx="0.01" ixy="0" ixz="0" iyy="0.01" iyz="0" izz="0.01"/>
    </inertial>
  </link>
  <link name="right_f1_fixed_accel">
    <origin rpy="0 0 0" xyz="0 0 0"/>
    <inertial>
      <mass value="0.1"/>
      <origin xyz="0 0 0"/>
      <inertia ixx="0.01" ixy="0" ixz="0" iyy="0.01" iyz="0" izz="0.01"/>
    </inertial>
  </link>
  <link name="right_f1_0">
    <origin rpy="0 0 0" xyz="0 0 0"/>
    <inertial>
      <mass value="0.1"/>
      <origin xyz="0 0 0"/>
      <inertia ixx="0.01" ixy="0" ixz="0" iyy="0.01" iyz="0" izz="0.01"/>
    </inertial>
    <collision>
      <origin rpy="0 0 0" xyz="0 0 0"/>
      <geometry>
        <mesh filename="model://mit_camhand/meshes/f0.stl"/>
      </geometry>
    </collision>
    <visual>
      <origin rpy="0 0 0" xyz="0 0 0"/>
      <geometry>
        <mesh filename="model://mit_camhand/meshes/f0.stl"/>
      </geometry>
      <material name="right_camhand_skin_suntan">
        <color rgba="0.7 0.4 0.2 1.0"/>
      </material>
    </visual>
  </link>
  <link name="right_f1_1">
    <origin rpy="0 0 0" xyz="0 0 0"/>
    <inertial>
      <mass value="0.1"/>
      <origin xyz="0 0 0"/>
      <inertia ixx="0.01" ixy="0" ixz="0" iyy="0.01" iyz="0" izz="0.01"/>
    </inertial>
    <collision>
      <origin rpy="0 0 0" xyz="0 0 0"/>
      <geometry>
        <mesh filename="model://mit_camhand/meshes/f1.stl"/>
      </geometry>
    </collision>
    <visual>
      <origin rpy="0 0 0" xyz="0 0 0"/>
      <geometry>
        <mesh filename="model://mit_camhand/meshes/f1.stl"/>
      </geometry>
      <material name="right_camhand_skin">
        <color rgba="0.835 0.655 0.345 1.0"/>
      </material>
    </visual>
  </link>
  <link name="right_f1_1_accel">
    <origin rpy="0 0 0" xyz="0 0 0"/>
    <inertial>
      <mass value="0.1"/>
      <origin xyz="0 0 0"/>
      <inertia ixx="0.01" ixy="0" ixz="0" iyy="0.01" iyz="0" izz="0.01"/>
    </inertial>
  </link>
  <link name="right_f1_2">
    <origin rpy="0 0 0" xyz="0 0 0"/>
    <inertial>
      <mass value="0.1"/>
      <origin xyz="0 0 0"/>
      <inertia ixx="0.01" ixy="0" ixz="0" iyy="0.01" iyz="0" izz="0.01"/>
    </inertial>
    <collision>
      <origin rpy="0 0 0" xyz="0 0 0"/>
      <geometry>
        <mesh filename="model://mit_camhand/meshes/f2.stl"/>
      </geometry>
    </collision>
    <visual>
      <origin rpy="0 0 0" xyz="0 0 0"/>
      <geometry>
        <mesh filename="model://mit_camhand/meshes/f2.stl"/>
      </geometry>
      <material name="right_camhand_skin_suntan">
        <color rgba="0.8 0.6 0.3 1.0"/>
      </material>
    </visual>
  </link>
  <link name="right_f1_2_accel">
    <origin rpy="0 0 0" xyz="0 0 0"/>
    <inertial>
      <mass value="0.1"/>
      <origin xyz="0 0 0"/>
      <inertia ixx="0.01" ixy="0" ixz="0" iyy="0.01" iyz="0" izz="0.01"/>
    </inertial>
  </link>
  <joint name="right_f1_base" type="fixed">
    <parent link="right_palm"/>
    <child link="right_f1_base"/>
    <origin rpy="0 0 0.3" xyz="0.115 0.03122 0"/>
  </joint>
  <joint name="right_f1_j0" type="revolute">
    <axis xyz="0 0 1"/>
    <parent link="right_f1_base"/>
    <child link="right_f1_0"/>
    <limit effort="1" lower="-1.57079" upper="1.57079" velocity="1"/>
    <origin rpy="0 0 0" xyz="0 0 0"/>
  </joint>
  <joint name="right_f1_j1" type="revolute">
    <axis xyz="0 0 1"/>
    <parent link="right_f1_0"/>
    <child link="right_f1_1"/>
    <limit effort="1" lower="-1.57079" upper="1.57079" velocity="1"/>
    <origin rpy="1.57079 0 0" xyz="0.028 0 0"/>
  </joint>
  <joint name="right_f1_j2" type="revolute">
    <axis xyz="0 0 1"/>
    <parent link="right_f1_1"/>
    <child link="right_f1_2"/>
    <origin rpy="0 0 0" xyz="0.05 0 0"/>
    <limit effort="1" lower="-1.57079" upper="1.57079" velocity="1"/>
  </joint>
  <joint name="right_f1_fixed_accel" type="fixed">
    <parent link="right_f1_base"/>
    <child link="right_f1_fixed_accel"/>
    <origin rpy="0 0 0" xyz="-0.05 0 0"/>
  </joint>
  <joint name="right_f1_1_accel" type="fixed">
    <parent link="right_f1_1"/>
    <child link="right_f1_1_accel"/>
    <origin rpy="-1.5709 0 0" xyz="0.03 0 0"/>
  </joint>
  <joint name="right_f1_2_accel" type="fixed">
    <parent link="right_f1_2"/>
    <child link="right_f1_2_accel"/>
    <origin rpy="-1.5709 0 0" xyz="0.04 0 0"/>
  </joint>
  <link name="right_f2_base">
    <origin rpy="0 0 0" xyz="0 0 0"/>
    <inertial>
      <mass value="0.1"/>
      <origin xyz="0 0 0"/>
      <inertia ixx="0.01" ixy="0" ixz="0" iyy="0.01" iyz="0" izz="0.01"/>
    </inertial>
  </link>
  <link name="right_f2_fixed_accel">
    <origin rpy="0 0 0" xyz="0 0 0"/>
    <inertial>
      <mass value="0.1"/>
      <origin xyz="0 0 0"/>
      <inertia ixx="0.01" ixy="0" ixz="0" iyy="0.01" iyz="0" izz="0.01"/>
    </inertial>
  </link>
  <link name="right_f2_0">
    <origin rpy="0 0 0" xyz="0 0 0"/>
    <inertial>
      <mass value="0.1"/>
      <origin xyz="0 0 0"/>
      <inertia ixx="0.01" ixy="0" ixz="0" iyy="0.01" iyz="0" izz="0.01"/>
    </inertial>
    <collision>
      <origin rpy="0 0 0" xyz="0 0 0"/>
      <geometry>
        <mesh filename="model://mit_camhand/meshes/f0.stl"/>
      </geometry>
    </collision>
    <visual>
      <origin rpy="0 0 0" xyz="0 0 0"/>
      <geometry>
        <mesh filename="model://mit_camhand/meshes/f0.stl"/>
      </geometry>
      <material name="right_camhand_skin_suntan">
        <color rgba="0.7 0.4 0.2 1.0"/>
      </material>
    </visual>
  </link>
  <link name="right_f2_1">
    <origin rpy="0 0 0" xyz="0 0 0"/>
    <inertial>
      <mass value="0.1"/>
      <origin xyz="0 0 0"/>
      <inertia ixx="0.01" ixy="0" ixz="0" iyy="0.01" iyz="0" izz="0.01"/>
    </inertial>
    <collision>
      <origin rpy="0 0 0" xyz="0 0 0"/>
      <geometry>
        <mesh filename="model://mit_camhand/meshes/f1.stl"/>
      </geometry>
    </collision>
    <visual>
      <origin rpy="0 0 0" xyz="0 0 0"/>
      <geometry>
        <mesh filename="model://mit_camhand/meshes/f1.stl"/>
      </geometry>
      <material name="right_camhand_skin">
        <color rgba="0.835 0.655 0.345 1.0"/>
      </material>
    </visual>
  </link>
  <link name="right_f2_1_accel">
    <origin rpy="0 0 0" xyz="0 0 0"/>
    <inertial>
      <mass value="0.1"/>
      <origin xyz="0 0 0"/>
      <inertia ixx="0.01" ixy="0" ixz="0" iyy="0.01" iyz="0" izz="0.01"/>
    </inertial>
  </link>
  <link name="right_f2_2">
    <origin rpy="0 0 0" xyz="0 0 0"/>
    <inertial>
      <mass value="0.1"/>
      <origin xyz="0 0 0"/>
      <inertia ixx="0.01" ixy="0" ixz="0" iyy="0.01" iyz="0" izz="0.01"/>
    </inertial>
    <collision>
      <origin rpy="0 0 0" xyz="0 0 0"/>
      <geometry>
        <mesh filename="model://mit_camhand/meshes/f2.stl"/>
      </geometry>
    </collision>
    <visual>
      <origin rpy="0 0 0" xyz="0 0 0"/>
      <geometry>
        <mesh filename="model://mit_camhand/meshes/f2.stl"/>
      </geometry>
      <material name="right_camhand_skin_suntan">
        <color rgba="0.8 0.6 0.3 1.0"/>
      </material>
    </visual>
  </link>
  <link name="right_f2_2_accel">
    <origin rpy="0 0 0" xyz="0 0 0"/>
    <inertial>
      <mass value="0.1"/>
      <origin xyz="0 0 0"/>
      <inertia ixx="0.01" ixy="0" ixz="0" iyy="0.01" iyz="0" izz="0.01"/>
    </inertial>
  </link>
  <joint name="right_f2_base" type="fixed">
    <parent link="right_palm"/>
    <child link="right_f2_base"/>
    <origin rpy="0 0 0.3" xyz="0.09 0.06245 0"/>
  </joint>
  <joint name="right_f2_j0" type="revolute">
    <axis xyz="0 0 1"/>
    <parent link="right_f2_base"/>
    <child link="right_f2_0"/>
    <limit effort="1" lower="-1.57079" upper="1.57079" velocity="1"/>
    <origin rpy="0 0 0" xyz="0 0 0"/>
  </joint>
  <joint name="right_f2_j1" type="revolute">
    <axis xyz="0 0 1"/>
    <parent link="right_f2_0"/>
    <child link="right_f2_1"/>
    <limit effort="1" lower="-1.57079" upper="1.57079" velocity="1"/>
    <origin rpy="1.57079 0 0" xyz="0.028 0 0"/>
  </joint>
  <joint name="right_f2_j2" type="revolute">
    <axis xyz="0 0 1"/>
    <parent link="right_f2_1"/>
    <child link="right_f2_2"/>
    <origin rpy="0 0 0" xyz="0.05 0 0"/>
    <limit effort="1" lower="-1.57079" upper="1.57079" velocity="1"/>
  </joint>
  <joint name="right_f2_fixed_accel" type="fixed">
    <parent link="right_f2_base"/>
    <child link="right_f2_fixed_accel"/>
    <origin rpy="0 0 0" xyz="-0.05 0 0"/>
  </joint>
  <joint name="right_f2_1_accel" type="fixed">
    <parent link="right_f2_1"/>
    <child link="right_f2_1_accel"/>
    <origin rpy="-1.5709 0 0" xyz="0.03 0 0"/>
  </joint>
  <joint name="right_f2_2_accel" type="fixed">
    <parent link="right_f2_2"/>
    <child link="right_f2_2_accel"/>
    <origin rpy="-1.5709 0 0" xyz="0.04 0 0"/>
  </joint>
  <link name="right_f3_base">
    <origin rpy="0 0 0" xyz="0 0 0"/>
    <inertial>
      <mass value="0.1"/>
      <origin xyz="0 0 0"/>
      <inertia ixx="0.01" ixy="0" ixz="0" iyy="0.01" iyz="0" izz="0.01"/>
    </inertial>
  </link>
  <link name="right_f3_fixed_accel">
    <origin rpy="0 0 0" xyz="0 0 0"/>
    <inertial>
      <mass value="0.1"/>
      <origin xyz="0 0 0"/>
      <inertia ixx="0.01" ixy="0" ixz="0" iyy="0.01" iyz="0" izz="0.01"/>
    </inertial>
  </link>
  <link name="right_f3_0">
    <origin rpy="0 0 0" xyz="0 0 0"/>
    <inertial>
      <mass value="0.1"/>
      <origin xyz="0 0 0"/>
      <inertia ixx="0.01" ixy="0" ixz="0" iyy="0.01" iyz="0" izz="0.01"/>
    </inertial>
    <collision>
      <origin rpy="0 0 0" xyz="0 0 0"/>
      <geometry>
        <mesh filename="model://mit_camhand/meshes/f0.stl"/>
      </geometry>
    </collision>
    <visual>
      <origin rpy="0 0 0" xyz="0 0 0"/>
      <geometry>
        <mesh filename="model://mit_camhand/meshes/f0.stl"/>
      </geometry>
      <material name="right_camhand_skin_suntan">
        <color rgba="0.7 0.4 0.2 1.0"/>
      </material>
    </visual>
  </link>
  <link name="right_f3_1">
    <origin rpy="0 0 0" xyz="0 0 0"/>
    <inertial>
      <mass value="0.1"/>
      <origin xyz="0 0 0"/>
      <inertia ixx="0.01" ixy="0" ixz="0" iyy="0.01" iyz="0" izz="0.01"/>
    </inertial>
    <collision>
      <origin rpy="0 0 0" xyz="0 0 0"/>
      <geometry>
        <mesh filename="model://mit_camhand/meshes/f1.stl"/>
      </geometry>
    </collision>
    <visual>
      <origin rpy="0 0 0" xyz="0 0 0"/>
      <geometry>
        <mesh filename="model://mit_camhand/meshes/f1.stl"/>
      </geometry>
      <material name="right_camhand_skin">
        <color rgba="0.835 0.655 0.345 1.0"/>
      </material>
    </visual>
  </link>
  <link name="right_f3_1_accel">
    <origin rpy="0 0 0" xyz="0 0 0"/>
    <inertial>
      <mass value="0.1"/>
      <origin xyz="0 0 0"/>
      <inertia ixx="0.01" ixy="0" ixz="0" iyy="0.01" iyz="0" izz="0.01"/>
    </inertial>
  </link>
  <link name="right_f3_2">
    <origin rpy="0 0 0" xyz="0 0 0"/>
    <inertial>
      <mass value="0.1"/>
      <origin xyz="0 0 0"/>
      <inertia ixx="0.01" ixy="0" ixz="0" iyy="0.01" iyz="0" izz="0.01"/>
    </inertial>
    <collision>
      <origin rpy="0 0 0" xyz="0 0 0"/>
      <geometry>
        <mesh filename="model://mit_camhand/meshes/f2.stl"/>
      </geometry>
    </collision>
    <visual>
      <origin rpy="0 0 0" xyz="0 0 0"/>
      <geometry>
        <mesh filename="model://mit_camhand/meshes/f2.stl"/>
      </geometry>
      <material name="right_camhand_skin_suntan">
        <color rgba="0.8 0.6 0.3 1.0"/>
      </material>
    </visual>
  </link>
  <link name="right_f3_2_accel">
    <origin rpy="0 0 0" xyz="0 0 0"/>
    <inertial>
      <mass value="0.1"/>
      <origin xyz="0 0 0"/>
      <inertia ixx="0.01" ixy="0" ixz="0" iyy="0.01" iyz="0" izz="0.01"/>
    </inertial>
  </link>
  <joint name="right_f3_base" type="fixed">
    <parent link="right_palm"/>
    <child link="right_f3_base"/>
    <origin rpy="0 -1.57079 -2.3562" xyz="0.03995 -0.04383 0.014"/>
  </joint>
  <joint name="right_f3_j0" type="revolute">
    <axis xyz="0 0 1"/>
    <parent link="right_f3_base"/>
    <child link="right_f3_0"/>
    <limit effort="1" lower="-1.57079" upper="1.57079" velocity="1"/>
    <origin rpy="0 0 0" xyz="0 0 0"/>
  </joint>
  <joint name="right_f3_j1" type="revolute">
    <axis xyz="0 0 1"/>
    <parent link="right_f3_0"/>
    <child link="right_f3_1"/>
    <limit effort="1" lower="-1.57079" upper="1.57079" velocity="1"/>
    <origin rpy="1.57079 0 0" xyz="0.028 0 0"/>
  </joint>
  <joint name="right_f3_j2" type="revolute">
    <axis xyz="0 0 1"/>
    <parent link="right_f3_1"/>
    <child link="right_f3_2"/>
    <origin rpy="0 0 0" xyz="0.05 0 0"/>
    <limit effort="1" lower="-1.57079" upper="1.57079" velocity="1"/>
  </joint>
  <joint name="right_f3_fixed_accel" type="fixed">
    <parent link="right_f3_base"/>
    <child link="right_f3_fixed_accel"/>
    <origin rpy="0 0 0" xyz="-0.05 0 0"/>
  </joint>
  <joint name="right_f3_1_accel" type="fixed">
    <parent link="right_f3_1"/>
    <child link="right_f3_1_accel"/>
    <origin rpy="-1.5709 0 0" xyz="0.03 0 0"/>
  </joint>
  <joint name="right_f3_2_accel" type="fixed">
    <parent link="right_f3_2"/>
    <child link="right_f3_2_accel"/>
    <origin rpy="-1.5709 0 0" xyz="0.04 0 0"/>
  </joint>
  <link name="left_palm">
    <origin rpy="0 0 0" xyz="0 0 0"/>
    <inertial>
      <mass value="0.1"/>
      <origin xyz="0 0 0"/>
      <inertia ixx="0.01" ixy="0" ixz="0" iyy="0.01" iyz="0" izz="0.01"/>
    </inertial>
    <collision>
      <origin rpy="0 0 0" xyz="0 0 0"/>
      <geometry>
        <mesh filename="model://mit_camhand/meshes/palm.stl"/>
      </geometry>
    </collision>
    <visual>
      <origin rpy="0 0 0" xyz="0 0 0"/>
      <geometry>
        <mesh filename="model://mit_camhand/meshes/palm.stl"/>
      </geometry>
      <material name="left_camhand_skin">
        <color rgba="0.835 0.655 0.345 1.0"/>
      </material>
    </visual>
  </link>
  <joint name="left_camhand_joint" type="fixed">
    <parent link="world"/>
    <child link="left_palm"/>
    <origin rpy="0 0 0" xyz="0 1 0"/>
  </joint>
  <link name="left_f0_base">
    <origin rpy="0 0 0" xyz="0 0 0"/>
    <inertial>
      <mass value="0.1"/>
      <origin xyz="0 0 0"/>
      <inertia ixx="0.01" ixy="0" ixz="0" iyy="0.01" iyz="0" izz="0.01"/>
    </inertial>
  </link>
  <link name="left_f0_fixed_accel">
    <origin rpy="0 0 0" xyz="0 0 0"/>
    <inertial>
      <mass value="0.1"/>
      <origin xyz="0 0 0"/>
      <inertia ixx="0.01" ixy="0" ixz="0" iyy="0.01" iyz="0" izz="0.01"/>
    </inertial>
  </link>
  <link name="left_f0_0">
    <origin rpy="0 0 0" xyz="0 0 0"/>
    <inertial>
      <mass value="0.1"/>
      <origin xyz="0 0 0"/>
      <inertia ixx="0.01" ixy="0" ixz="0" iyy="0.01" iyz="0" izz="0.01"/>
    </inertial>
    <collision>
      <origin rpy="0 0 0" xyz="0 0 0"/>
      <geometry>
        <mesh filename="model://mit_camhand/meshes/f0.stl"/>
      </geometry>
    </collision>
    <visual>
      <origin rpy="0 0 0" xyz="0 0 0"/>
      <geometry>
        <mesh filename="model://mit_camhand/meshes/f0.stl"/>
      </geometry>
      <material name="left_camhand_skin_suntan">
        <color rgba="0.7 0.4 0.2 1.0"/>
      </material>
    </visual>
  </link>
  <link name="left_f0_1">
    <origin rpy="0 0 0" xyz="0 0 0"/>
    <inertial>
      <mass value="0.1"/>
      <origin xyz="0 0 0"/>
      <inertia ixx="0.01" ixy="0" ixz="0" iyy="0.01" iyz="0" izz="0.01"/>
    </inertial>
    <collision>
      <origin rpy="0 0 0" xyz="0 0 0"/>
      <geometry>
        <mesh filename="model://mit_camhand/meshes/f1.stl"/>
      </geometry>
    </collision>
    <visual>
      <origin rpy="0 0 0" xyz="0 0 0"/>
      <geometry>
        <mesh filename="model://mit_camhand/meshes/f1.stl"/>
      </geometry>
      <material name="left_camhand_skin">
        <color rgba="0.835 0.655 0.345 1.0"/>
      </material>
    </visual>
  </link>
  <link name="left_f0_1_accel">
    <origin rpy="0 0 0" xyz="0 0 0"/>
    <inertial>
      <mass value="0.1"/>
      <origin xyz="0 0 0"/>
      <inertia ixx="0.01" ixy="0" ixz="0" iyy="0.01" iyz="0" izz="0.01"/>
    </inertial>
  </link>
  <link name="left_f0_2">
    <origin rpy="0 0 0" xyz="0 0 0"/>
    <inertial>
      <mass value="0.1"/>
      <origin xyz="0 0 0"/>
      <inertia ixx="0.01" ixy="0" ixz="0" iyy="0.01" iyz="0" izz="0.01"/>
    </inertial>
    <collision>
      <origin rpy="0 0 0" xyz="0 0 0"/>
      <geometry>
        <mesh filename="model://mit_camhand/meshes/f2.stl"/>
      </geometry>
    </collision>
    <visual>
      <origin rpy="0 0 0" xyz="0 0 0"/>
      <geometry>
        <mesh filename="model://mit_camhand/meshes/f2.stl"/>
      </geometry>
      <material name="left_camhand_skin_suntan">
        <color rgba="0.8 0.6 0.3 1.0"/>
      </material>
    </visual>
  </link>
  <link name="left_f0_2_accel">
    <origin rpy="0 0 0" xyz="0 0 0"/>
    <inertial>
      <mass value="0.1"/>
      <origin xyz="0 0 0"/>
      <inertia ixx="0.01" ixy="0" ixz="0" iyy="0.01" iyz="0" izz="0.01"/>
    </inertial>
  </link>
  <joint name="left_f0_base" type="fixed">
    <parent link="left_palm"/>
    <child link="left_f0_base"/>
    <origin rpy="0 0 0.3" xyz="0.14 0.0 0"/>
  </joint>
  <joint name="left_f0_j0" type="revolute">
    <axis xyz="0 0 1"/>
    <parent link="left_f0_base"/>
    <child link="left_f0_0"/>
    <limit effort="1" lower="-1.57079" upper="1.57079" velocity="1"/>
    <origin rpy="0 0 0" xyz="0 0 0"/>
  </joint>
  <joint name="left_f0_j1" type="revolute">
    <axis xyz="0 0 1"/>
    <parent link="left_f0_0"/>
    <child link="left_f0_1"/>
    <limit effort="1" lower="-1.57079" upper="1.57079" velocity="1"/>
    <origin rpy="1.57079 0 0" xyz="0.028 0 0"/>
  </joint>
  <joint name="left_f0_j2" type="revolute">
    <axis xyz="0 0 1"/>
    <parent link="left_f0_1"/>
    <child link="left_f0_2"/>
    <origin rpy="0 0 0" xyz="0.05 0 0"/>
    <limit effort="1" lower="-1.57079" upper="1.57079" velocity="1"/>
  </joint>
  <joint name="left_f0_fixed_accel" type="fixed">
    <parent link="left_f0_base"/>
    <child link="left_f0_fixed_accel"/>
    <origin rpy="0 0 0" xyz="-0.05 0 0"/>
  </joint>
  <joint name="left_f0_1_accel" type="fixed">
    <parent link="left_f0_1"/>
    <child link="left_f0_1_accel"/>
    <origin rpy="-1.5709 0 0" xyz="0.03 0 0"/>
  </joint>
  <joint name="left_f0_2_accel" type="fixed">
    <parent link="left_f0_2"/>
    <child link="left_f0_2_accel"/>
    <origin rpy="-1.5709 0 0" xyz="0.04 0 0"/>
  </joint>
  <link name="left_f1_base">
    <origin rpy="0 0 0" xyz="0 0 0"/>
    <inertial>
      <mass value="0.1"/>
      <origin xyz="0 0 0"/>
      <inertia ixx="0.01" ixy="0" ixz="0" iyy="0.01" iyz="0" izz="0.01"/>
    </inertial>
  </link>
  <link name="left_f1_fixed_accel">
    <origin rpy="0 0 0" xyz="0 0 0"/>
    <inertial>
      <mass value="0.1"/>
      <origin xyz="0 0 0"/>
      <inertia ixx="0.01" ixy="0" ixz="0" iyy="0.01" iyz="0" izz="0.01"/>
    </inertial>
  </link>
  <link name="left_f1_0">
    <origin rpy="0 0 0" xyz="0 0 0"/>
    <inertial>
      <mass value="0.1"/>
      <origin xyz="0 0 0"/>
      <inertia ixx="0.01" ixy="0" ixz="0" iyy="0.01" iyz="0" izz="0.01"/>
    </inertial>
    <collision>
      <origin rpy="0 0 0" xyz="0 0 0"/>
      <geometry>
        <mesh filename="model://mit_camhand/meshes/f0.stl"/>
      </geometry>
    </collision>
    <visual>
      <origin rpy="0 0 0" xyz="0 0 0"/>
      <geometry>
        <mesh filename="model://mit_camhand/meshes/f0.stl"/>
      </geometry>
      <material name="left_camhand_skin_suntan">
        <color rgba="0.7 0.4 0.2 1.0"/>
      </material>
    </visual>
  </link>
  <link name="left_f1_1">
    <origin rpy="0 0 0" xyz="0 0 0"/>
    <inertial>
      <mass value="0.1"/>
      <origin xyz="0 0 0"/>
      <inertia ixx="0.01" ixy="0" ixz="0" iyy="0.01" iyz="0" izz="0.01"/>
    </inertial>
    <collision>
      <origin rpy="0 0 0" xyz="0 0 0"/>
      <geometry>
        <mesh filename="model://mit_camhand/meshes/f1.stl"/>
      </geometry>
    </collision>
    <visual>
      <origin rpy="0 0 0" xyz="0 0 0"/>
      <geometry>
        <mesh filename="model://mit_camhand/meshes/f1.stl"/>
      </geometry>
      <material name="left_camhand_skin">
        <color rgba="0.835 0.655 0.345 1.0"/>
      </material>
    </visual>
  </link>
  <link name="left_f1_1_accel">
    <origin rpy="0 0 0" xyz="0 0 0"/>
    <inertial>
      <mass value="0.1"/>
      <origin xyz="0 0 0"/>
      <inertia ixx="0.01" ixy="0" ixz="0" iyy="0.01" iyz="0" izz="0.01"/>
    </inertial>
  </link>
  <link name="left_f1_2">
    <origin rpy="0 0 0" xyz="0 0 0"/>
    <inertial>
      <mass value="0.1"/>
      <origin xyz="0 0 0"/>
      <inertia ixx="0.01" ixy="0" ixz="0" iyy="0.01" iyz="0" izz="0.01"/>
    </inertial>
    <collision>
      <origin rpy="0 0 0" xyz="0 0 0"/>
      <geometry>
        <mesh filename="model://mit_camhand/meshes/f2.stl"/>
      </geometry>
    </collision>
    <visual>
      <origin rpy="0 0 0" xyz="0 0 0"/>
      <geometry>
        <mesh filename="model://mit_camhand/meshes/f2.stl"/>
      </geometry>
      <material name="left_camhand_skin_suntan">
        <color rgba="0.8 0.6 0.3 1.0"/>
      </material>
    </visual>
  </link>
  <link name="left_f1_2_accel">
    <origin rpy="0 0 0" xyz="0 0 0"/>
    <inertial>
      <mass value="0.1"/>
      <origin xyz="0 0 0"/>
      <inertia ixx="0.01" ixy="0" ixz="0" iyy="0.01" iyz="0" izz="0.01"/>
    </inertial>
  </link>
  <joint name="left_f1_base" type="fixed">
    <parent link="left_palm"/>
    <child link="left_f1_base"/>
    <origin rpy="0 0 0.3" xyz="0.115 0.03122 0"/>
  </joint>
  <joint name="left_f1_j0" type="revolute">
    <axis xyz="0 0 1"/>
    <parent link="left_f1_base"/>
    <child link="left_f1_0"/>
    <limit effort="1" lower="-1.57079" upper="1.57079" velocity="1"/>
    <origin rpy="0 0 0" xyz="0 0 0"/>
  </joint>
  <joint name="left_f1_j1" type="revolute">
    <axis xyz="0 0 1"/>
    <parent link="left_f1_0"/>
    <child link="left_f1_1"/>
    <limit effort="1" lower="-1.57079" upper="1.57079" velocity="1"/>
    <origin rpy="1.57079 0 0" xyz="0.028 0 0"/>
  </joint>
  <joint name="left_f1_j2" type="revolute">
    <axis xyz="0 0 1"/>
    <parent link="left_f1_1"/>
    <child link="left_f1_2"/>
    <origin rpy="0 0 0" xyz="0.05 0 0"/>
    <limit effort="1" lower="-1.57079" upper="1.57079" velocity="1"/>
  </joint>
  <joint name="left_f1_fixed_accel" type="fixed">
    <parent link="left_f1_base"/>
    <child link="left_f1_fixed_accel"/>
    <origin rpy="0 0 0" xyz="-0.05 0 0"/>
  </joint>
  <joint name="left_f1_1_accel" type="fixed">
    <parent link="left_f1_1"/>
    <child link="left_f1_1_accel"/>
    <origin rpy="-1.5709 0 0" xyz="0.03 0 0"/>
  </joint>
  <joint name="left_f1_2_accel" type="fixed">
    <parent link="left_f1_2"/>
    <child link="left_f1_2_accel"/>
    <origin rpy="-1.5709 0 0" xyz="0.04 0 0"/>
  </joint>
  <link name="left_f2_base">
    <origin rpy="0 0 0" xyz="0 0 0"/>
    <inertial>
      <mass value="0.1"/>
      <origin xyz="0 0 0"/>
      <inertia ixx="0.01" ixy="0" ixz="0" iyy="0.01" iyz="0" izz="0.01"/>
    </inertial>
  </link>
  <link name="left_f2_fixed_accel">
    <origin rpy="0 0 0" xyz="0 0 0"/>
    <inertial>
      <mass value="0.1"/>
      <origin xyz="0 0 0"/>
      <inertia ixx="0.01" ixy="0" ixz="0" iyy="0.01" iyz="0" izz="0.01"/>
    </inertial>
  </link>
  <link name="left_f2_0">
    <origin rpy="0 0 0" xyz="0 0 0"/>
    <inertial>
      <mass value="0.1"/>
      <origin xyz="0 0 0"/>
      <inertia ixx="0.01" ixy="0" ixz="0" iyy="0.01" iyz="0" izz="0.01"/>
    </inertial>
    <collision>
      <origin rpy="0 0 0" xyz="0 0 0"/>
      <geometry>
        <mesh filename="model://mit_camhand/meshes/f0.stl"/>
      </geometry>
    </collision>
    <visual>
      <origin rpy="0 0 0" xyz="0 0 0"/>
      <geometry>
        <mesh filename="model://mit_camhand/meshes/f0.stl"/>
      </geometry>
      <material name="left_camhand_skin_suntan">
        <color rgba="0.7 0.4 0.2 1.0"/>
      </material>
    </visual>
  </link>
  <link name="left_f2_1">
    <origin rpy="0 0 0" xyz="0 0 0"/>
    <inertial>
      <mass value="0.1"/>
      <origin xyz="0 0 0"/>
      <inertia ixx="0.01" ixy="0" ixz="0" iyy="0.01" iyz="0" izz="0.01"/>
    </inertial>
    <collision>
      <origin rpy="0 0 0" xyz="0 0 0"/>
      <geometry>
        <mesh filename="model://mit_camhand/meshes/f1.stl"/>
      </geometry>
    </collision>
    <visual>
      <origin rpy="0 0 0" xyz="0 0 0"/>
      <geometry>
        <mesh filename="model://mit_camhand/meshes/f1.stl"/>
      </geometry>
      <material name="left_camhand_skin">
        <color rgba="0.835 0.655 0.345 1.0"/>
      </material>
    </visual>
  </link>
  <link name="left_f2_1_accel">
    <origin rpy="0 0 0" xyz="0 0 0"/>
    <inertial>
      <mass value="0.1"/>
      <origin xyz="0 0 0"/>
      <inertia ixx="0.01" ixy="0" ixz="0" iyy="0.01" iyz="0" izz="0.01"/>
    </inertial>
  </link>
  <link name="left_f2_2">
    <origin rpy="0 0 0" xyz="0 0 0"/>
    <inertial>
      <mass value="0.1"/>
      <origin xyz="0 0 0"/>
      <inertia ixx="0.01" ixy="0" ixz="0" iyy="0.01" iyz="0" izz="0.01"/>
    </inertial>
    <collision>
      <origin rpy="0 0 0" xyz="0 0 0"/>
      <geometry>
        <mesh filename="model://mit_camhand/meshes/f2.stl"/>
      </geometry>
    </collision>
    <visual>
      <origin rpy="0 0 0" xyz="0 0 0"/>
      <geometry>
        <mesh filename="model://mit_camhand/meshes/f2.stl"/>
      </geometry>
      <material name="left_camhand_skin_suntan">
        <color rgba="0.8 0.6 0.3 1.0"/>
      </material>
    </visual>
  </link>
  <link name="left_f2_2_accel">
    <origin rpy="0 0 0" xyz="0 0 0"/>
    <inertial>
      <mass value="0.1"/>
      <origin xyz="0 0 0"/>
      <inertia ixx="0.01" ixy="0" ixz="0" iyy="0.01" iyz="0" izz="0.01"/>
    </inertial>
  </link>
  <joint name="left_f2_base" type="fixed">
    <parent link="left_palm"/>
    <child link="left_f2_base"/>
    <origin rpy="0 0 0.3" xyz="0.09 0.06245 0"/>
  </joint>
  <joint name="left_f2_j0" type="revolute">
    <axis xyz="0 0 1"/>
    <parent link="left_f2_base"/>
    <child link="left_f2_0"/>
    <limit effort="1" lower="-1.57079" upper="1.57079" velocity="1"/>
    <origin rpy="0 0 0" xyz="0 0 0"/>
  </joint>
  <joint name="left_f2_j1" type="revolute">
    <axis xyz="0 0 1"/>
    <parent link="left_f2_0"/>
    <child link="left_f2_1"/>
    <limit effort="1" lower="-1.57079" upper="1.57079" velocity="1"/>
    <origin rpy="1.57079 0 0" xyz="0.028 0 0"/>
  </joint>
  <joint name="left_f2_j2" type="revolute">
    <axis xyz="0 0 1"/>
    <parent link="left_f2_1"/>
    <child link="left_f2_2"/>
    <origin rpy="0 0 0" xyz="0.05 0 0"/>
    <limit effort="1" lower="-1.57079" upper="1.57079" velocity="1"/>
  </joint>
  <joint name="left_f2_fixed_accel" type="fixed">
    <parent link="left_f2_base"/>
    <child link="left_f2_fixed_accel"/>
    <origin rpy="0 0 0" xyz="-0.05 0 0"/>
  </joint>
  <joint name="left_f2_1_accel" type="fixed">
    <parent link="left_f2_1"/>
    <child link="left_f2_1_accel"/>
    <origin rpy="-1.5709 0 0" xyz="0.03 0 0"/>
  </joint>
  <joint name="left_f2_2_accel" type="fixed">
    <parent link="left_f2_2"/>
    <child link="left_f2_2_accel"/>
    <origin rpy="-1.5709 0 0" xyz="0.04 0 0"/>
  </joint>
  <link name="left_f3_base">
    <origin rpy="0 0 0" xyz="0 0 0"/>
    <inertial>
      <mass value="0.1"/>
      <origin xyz="0 0 0"/>
      <inertia ixx="0.01" ixy="0" ixz="0" iyy="0.01" iyz="0" izz="0.01"/>
    </inertial>
  </link>
  <link name="left_f3_fixed_accel">
    <origin rpy="0 0 0" xyz="0 0 0"/>
    <inertial>
      <mass value="0.1"/>
      <origin xyz="0 0 0"/>
      <inertia ixx="0.01" ixy="0" ixz="0" iyy="0.01" iyz="0" izz="0.01"/>
    </inertial>
  </link>
  <link name="left_f3_0">
    <origin rpy="0 0 0" xyz="0 0 0"/>
    <inertial>
      <mass value="0.1"/>
      <origin xyz="0 0 0"/>
      <inertia ixx="0.01" ixy="0" ixz="0" iyy="0.01" iyz="0" izz="0.01"/>
    </inertial>
    <collision>
      <origin rpy="0 0 0" xyz="0 0 0"/>
      <geometry>
        <mesh filename="model://mit_camhand/meshes/f0.stl"/>
      </geometry>
    </collision>
    <visual>
      <origin rpy="0 0 0" xyz="0 0 0"/>
      <geometry>
        <mesh filename="model://mit_camhand/meshes/f0.stl"/>
      </geometry>
      <material name="left_camhand_skin_suntan">
        <color rgba="0.7 0.4 0.2 1.0"/>
      </material>
    </visual>
  </link>
  <link name="left_f3_1">
    <origin rpy="0 0 0" xyz="0 0 0"/>
    <inertial>
      <mass value="0.1"/>
      <origin xyz="0 0 0"/>
      <inertia ixx="0.01" ixy="0" ixz="0" iyy="0.01" iyz="0" izz="0.01"/>
    </inertial>
    <collision>
      <origin rpy="0 0 0" xyz="0 0 0"/>
      <geometry>
        <mesh filename="model://mit_camhand/meshes/f1.stl"/>
      </geometry>
    </collision>
    <visual>
      <origin rpy="0 0 0" xyz="0 0 0"/>
      <geometry>
        <mesh filename="model://mit_camhand/meshes/f1.stl"/>
      </geometry>
      <material name="left_camhand_skin">
        <color rgba="0.835 0.655 0.345 1.0"/>
      </material>
    </visual>
  </link>
  <link name="left_f3_1_accel">
    <origin rpy="0 0 0" xyz="0 0 0"/>
    <inertial>
      <mass value="0.1"/>
      <origin xyz="0 0 0"/>
      <inertia ixx="0.01" ixy="0" ixz="0" iyy="0.01" iyz="0" izz="0.01"/>
    </inertial>
  </link>
  <link name="left_f3_2">
    <origin rpy="0 0 0" xyz="0 0 0"/>
    <inertial>
      <mass value="0.1"/>
      <origin xyz="0 0 0"/>
      <inertia ixx="0.01" ixy="0" ixz="0" iyy="0.01" iyz="0" izz="0.01"/>
    </inertial>
    <collision>
      <origin rpy="0 0 0" xyz="0 0 0"/>
      <geometry>
        <mesh filename="model://mit_camhand/meshes/f2.stl"/>
      </geometry>
    </collision>
    <visual>
      <origin rpy="0 0 0" xyz="0 0 0"/>
      <geometry>
        <mesh filename="model://mit_camhand/meshes/f2.stl"/>
      </geometry>
      <material name="left_camhand_skin_suntan">
        <color rgba="0.8 0.6 0.3 1.0"/>
      </material>
    </visual>
  </link>
  <link name="left_f3_2_accel">
    <origin rpy="0 0 0" xyz="0 0 0"/>
    <inertial>
      <mass value="0.1"/>
      <origin xyz="0 0 0"/>
      <inertia ixx="0.01" ixy="0" ixz="0" iyy="0.01" iyz="0" izz="0.01"/>
    </inertial>
  </link>
  <joint name="left_f3_base" type="fixed">
    <parent link="left_palm"/>
    <child link="left_f3_base"/>
    <origin rpy="0 -1.57079 -2.3562" xyz="0.03995 -0.04383 0.014"/>
  </joint>
  <joint name="left_f3_j0" type="revolute">
    <axis xyz="0 0 1"/>
    <parent link="left_f3_base"/>
    <child link="left_f3_0"/>
    <limit effort="1" lower="-1.57079" upper="1.57079" velocity="1"/>
    <origin rpy="0 0 0" xyz="0 0 0"/>
  </joint>
  <joint name="left_f3_j1" type="revolute">
    <axis xyz="0 0 1"/>
    <parent link="left_f3_0"/>
    <child link="left_f3_1"/>
    <limit effort="1" lower="-1.57079" upper="1.57079" velocity="1"/>
    <origin rpy="1.57079 0 0" xyz="0.028 0 0"/>
  </joint>
  <joint name="left_f3_j2" type="revolute">
    <axis xyz="0 0 1"/>
    <parent link="left_f3_1"/>
    <child link="left_f3_2"/>
    <origin rpy="0 0 0" xyz="0.05 0 0"/>
    <limit effort="1" lower="-1.57079" upper="1.57079" velocity="1"/>
  </joint>
  <joint name="left_f3_fixed_accel" type="fixed">
    <parent link="left_f3_base"/>
    <child link="left_f3_fixed_accel"/>
    <origin rpy="0 0 0" xyz="-0.05 0 0"/>
  </joint>
  <joint name="left_f3_1_accel" type="fixed">
    <parent link="left_f3_1"/>
    <child link="left_f3_1_accel"/>
    <origin rpy="-1.5709 0 0" xyz="0.03 0 0"/>
  </joint>
  <joint name="left_f3_2_accel" type="fixed">
    <parent link="left_f3_2"/>
    <child link="left_f3_2_accel"/>
    <origin rpy="-1.5709 0 0" xyz="0.04 0 0"/>
  </joint>
</robot>

