<?xml version='1.0'?>
<gazebo version='1.2'>
  <model name="Gazebo Steering Wheel">
    <static>false</static>
      <link name='base_block'>
	<pose>0 0 0.65 0 0 0</pose>

        <inertial>
          <mass>100.0</mass>
          <pose>0 0 0 0 0 0</pose>
          <inertia>
            <ixx>100.0</ixx>
            <ixy>0</ixy>
            <ixz>0</ixz>
            <iyy>100.0</iyy>
            <iyz>0</iyz>
            <izz>100.0</izz>
          </inertia>
        </inertial>


	<collision name='collision'>
	  <geometry>
	    <box>
	      <size>0.25 0.125 1.3</size>	
	    </box>
	  </geometry>
	</collision>
	
	<visual name='visual'>
	  <geometry>
	    <box>
	      <size>0.25 0.125 1.3</size>
	    </box>
	  </geometry>

          <material>
          <script>
            <uri>file://media/materials/scripts/gazebo.material</uri>
            <name>Gazebo/Wood</name>
          </script>
          <ambient>0.2 0.2 0.2 1</ambient>
	    <diffuse>0.2 0.2 0.2 1</diffuse>
          <specular>0.2 0.2 0.2 1</specular>
          <emissive>0.5 0.5 0.5 1</emissive>
          </material>


	</visual>
      </link>

      <link name="steering_wheel">
	<pose>-0.125 0 1.3208 0 1.57 0</pose>
	<inertial>
	  <mass>1.0</mass>
	  <pose>0 0 0 0 0 0</pose>
	  <inertia>
	    <ixx>1000.0</ixx>
	    <ixy>0</ixy>
	    <ixz>0</ixz>
	    <iyy>0.1</iyy>
	    <iyz>0</iyz>
	    <izz>0.1</izz>
	  </inertia>
	</inertial>


	<collision name="collision">
	  <geometry>
	    <cylinder>
	      <radius>0.22</radius>
	      <length>0.025</length>
	    </cylinder>
	  </geometry>
	</collision>

	<visual name="visual">
	  <geometry>
	    <cylinder>
	      <radius>0.22</radius>
	      <length>0.02</length>
	    </cylinder>
	  </geometry>
	  
	  <material>
          <script>
            <uri>file://media/materials/scripts/gazebo.material</uri>
            <name>Gazebo/Wood</name>
          </script>
          <ambient>0.2 0.2 0.2 1</ambient>
          <diffuse>0.2 0.2 0.2 1</diffuse>
          <specular>0.2 0.2 0.2 1</specular>
          <emissive>0.5 0.5 0.5 1</emissive>
	  </material>
	</visual>

      <velocity_decay>0.1</velocity_decay>

      </link>

  <joint type="revolute" name="base_to_steering">
    <pose>0 0 0 0 0 0</pose>
    <child>steering_wheel</child>
    <parent>base_block</parent>
    <axis>
      <xyz>1 0 0</xyz>
    </axis>
  </joint>

  <joint type="revolute" name="ground_link">
    <parent>world</parent>
    <child>base_block</child>
    <axis> <xyz> 0 0 1.0</xyz>
    <limit>
      <lower>0.0</lower>
      <upper>0.0</upper>
    </limit>
    <dynamics/>
    </axis>
  </joint>


    </model>
</gazebo>


