<?xml version="1.0" ?>
<!-- =================================================================================== -->
<!-- |    This document was autogenerated by xacro from /home/val/release_13.12/drc_configuration/V1/models/V1/xacro/V1_sim.xacro | -->
<!-- |    EDITING THIS FILE BY HAND IS NOT RECOMMENDED                                 | -->
<!-- =================================================================================== -->
<robot name="V1" xmlns:xacro="http://www.ros.org/wiki/xacro">
  <!-- ======================================================= -->
  <!-- DO NOT MODIFY URDF BY HAND! YOU ARE A FOOL IF YOU DO! -->
  <!-- ======================================================= -->
  <material name="White">
    <color rgba="1.0 1.0 1.0 1.0"/>
  </material>
  <material name="Gold">
    <color rgba="1.0 0.67 0 1.0"/>
  </material>
  <material name="Gray">
    <color rgba="0.5 0.5 0.5 1.0"/>
  </material>
  <material name="Pink">
    <color rgba="0.8 0 0.45 1.0"/>
  </material>
  <gazebo>
    <plugin filename="libSMInterface.so" name="SharedMemoryInterface">
      <updateRate>1000</updateRate>
      <robotDescriptionParam>/robot_description_sim</robotDescriptionParam>
    </plugin>
    <plugin filename="libJointStatePublisher.so" name="JointStatePublisher">
      <updateRate>1000.0</updateRate>
      <topicName>joint_states_sim</topicName>
    </plugin>
    <plugin filename="libPinPlugin.so" name="PinPlugin">
      <node>/pin_plugin</node>
    </plugin>
  </gazebo>
  <gazebo>
    <plugin filename="libgazebo_ros_p3d.so" name="pos_plugin_ros">
      <alwaysOn>true</alwaysOn>
      <updateRate>1000.0</updateRate>
      <bodyName>utorso</bodyName>
      <topicName>/v1/pose</topicName>
      <frameName>world</frameName>
      <rpyOffset>0 0 0</rpyOffset>
      <xyzOffset>0 0 0</xyzOffset>
    </plugin>
  </gazebo>
  <gazebo>
    <plugin filename="libgazebo_ros_p3d.so" name="pos_plugin_ros">
      <alwaysOn>true</alwaysOn>
      <updateRate>1000.0</updateRate>
      <bodyName>pelvis</bodyName>
      <topicName>/v1/Pelvis/pose</topicName>
      <frameName>world</frameName>
      <rpyOffset>0 0 0</rpyOffset>
      <xyzOffset>0 0 0</xyzOffset>
    </plugin>
  </gazebo>
  <link name="pelvis">
    <inertial>
      <mass value="5.15"/>
      <origin rpy="0 0 0" xyz="0.0005 -0.0009 -0.0704"/>
      <inertia ixx="0.109221629167" ixy="0.0" ixz="0.0" iyy="0.0928072916667" iyz="0.0" izz="0.0851573958333"/>
    </inertial>
    <visual>
      <geometry>
        <mesh filename="package://V1/models/V1/meshes/2013_05_16/pelvis.wrl"/>
        <!-- <box size="${width} ${height} ${depth}"/> -->
      </geometry>
      <origin rpy="0 0 0" xyz="0 0 0"/>
      <!-- <origin rpy="${origin_rpy}" xyz="${origin_xyz}"/> -->
      <material name="White"/>
    </visual>
    <collision>
      <geometry>
        <mesh filename="package://V1/models/V1/meshes/2013_05_16/pelvis.wrl"/>
      </geometry>
      <origin rpy="0 0 0" xyz="0 0 0"/>
    </collision>
  </link>
  <gazebo reference="pelvis">
    <material>Gazebo/White</material>
  </gazebo>
  <link name="utorso">
    <inertial>
      <mass value="38.3"/>
      <origin rpy="0 0 0" xyz="0.255 0 -0.0981"/>
      <inertia ixx="1.08700825833" ixy="0.0" ixz="0.0" iyy="1.29998179167" iyz="0.0" izz="1.23941991667"/>
    </inertial>
    <visual>
      <geometry>
        <mesh filename="package://V1/models/V1/meshes/2013_05_16/wj3.wrl"/>
        <!-- <box size="${width} ${height} ${depth}"/> -->
      </geometry>
      <origin rpy="0 0 0" xyz="0 0 0"/>
      <!-- <origin rpy="${origin_rpy}" xyz="${origin_xyz}"/> -->
      <material name="White"/>
    </visual>
    <collision>
      <geometry>
        <mesh filename="package://V1/models/V1/meshes/2013_05_16/wj3.wrl"/>
      </geometry>
      <origin rpy="0 0 0" xyz="0 0 0"/>
    </collision>
  </link>
  <gazebo reference="utorso">
    <material>Gazebo/White</material>
  </gazebo>
  <link name="ltorso">
    <!-- Virtual Link -->
    <inertial>
      <mass value="0.1"/>
      <origin rpy="0 0 0" xyz="0 0 0"/>
      <inertia ixx="8.33333333333e-05" ixy="0.0" ixz="0.0" iyy="8.33333333333e-05" iyz="0.0" izz="0.000125"/>
    </inertial>
  </link>
  <link name="mtorso">
    <!-- Virtual Link -->
    <inertial>
      <mass value="0.1"/>
      <origin rpy="0 0 0" xyz="0 0 0"/>
      <inertia ixx="8.33333333333e-05" ixy="0.0" ixz="0.0" iyy="8.33333333333e-05" iyz="0.0" izz="0.000125"/>
    </inertial>
  </link>
  <joint name="back_bkz" type="revolute">
    <origin rpy="0 0 0" xyz="0 0 0"/>
    <axis xyz="0 0 1"/>
    <parent link="pelvis"/>
    <child link="ltorso"/>
    <limit effort="190" lower="-0.6981317004" upper="0.6981317004" velocity="5.89"/>
    <controller_gains Kd="400" Kp="20000"/>
    <dynamics damping="1.0" friction="0.0"/>
  </joint>
  <gazebo reference="back_bkz">
    <provideFeedback>1</provideFeedback>
  </gazebo>
  <joint name="back_bky" type="revolute">
    <origin rpy="1.57079632679 0 0" xyz="0.04191 0 0"/>
    <axis xyz="0 0 1"/>
    <parent link="ltorso"/>
    <child link="mtorso"/>
    <limit effort="150" lower="-0.6981317004" upper="0.08726646255" velocity="9"/>
    <controller_gains Kd="400" Kp="20000"/>
    <dynamics damping="1.0" friction="0.0"/>
  </joint>
  <gazebo reference="back_bky">
    <provideFeedback>1</provideFeedback>
  </gazebo>
  <joint name="back_bkx" type="revolute">
    <origin rpy="1.57079632679 0 1.57079632679" xyz="0 0.020352 0"/>
    <axis xyz="0 0 1"/>
    <parent link="mtorso"/>
    <child link="utorso"/>
    <limit effort="150" lower="-0.26179938765" upper="0.26179938765" velocity="9"/>
    <controller_gains Kd="400" Kp="20000"/>
    <dynamics damping="1.0" friction="0.0"/>
  </joint>
  <gazebo reference="back_bkx">
    <provideFeedback>1</provideFeedback>
  </gazebo>
  <actuator name="/pelvis/wj1" type="turbodriver_api/TurbodriverAPI_DRCv4"/>
  <actuator name="/trunk/wj2" type="turbodriver_api/TurbodriverAPI_DRCv4_linear"/>
  <actuator name="/trunk/wj3" type="turbodriver_api/TurbodriverAPI_DRCv4_linear"/>
  <mode name="WaistRotatorMode" type="mode_plugins/ModeInterface">
    <translator name="WaistRotatorModeData" type="SimpleActuatorToJointMode">
      <joint data="mode" name="back_bkz"/>
      <actuator data="mode" name="/pelvis/wj1"/>
    </translator>
    <translator name="WaistRotatorModeCommand" type="SimpleJointToActuatorMode">
      <joint data="modeCommand" name="back_bkz"/>
      <actuator data="modeCommand" name="/pelvis/wj1"/>
    </translator>
  </mode>
  <mode name="WaistExtensorMode" type="mode_plugins/ModeInterface">
    <translator name="WaistExtensorModeData" type="SimpleActuatorToJointMode">
      <joint data="mode" name="back_bky"/>
      <actuator data="mode" name="/trunk/wj2"/>
    </translator>
    <translator name="WaistExtensorModeCommand" type="SimpleJointToActuatorMode">
      <joint data="modeCommand" name="back_bky"/>
      <actuator data="modeCommand" name="/trunk/wj2"/>
    </translator>
  </mode>
  <mode name="WaistLateralExtensorMode" type="mode_plugins/ModeInterface">
    <translator name="WaistLateralExtensorModeData" type="SimpleActuatorToJointMode">
      <joint data="mode" name="back_bkx"/>
      <actuator data="mode" name="/trunk/wj3"/>
    </translator>
    <translator name="WaistLateralExtensorModeCommand" type="SimpleJointToActuatorMode">
      <joint data="modeCommand" name="back_bkx"/>
      <actuator data="modeCommand" name="/trunk/wj3"/>
    </translator>
  </mode>
  <link name="/v1/RightIMU_Frame">
    <inertial>
      <mass value="0.018"/>
      <origin rpy="0 0 0" xyz="0 0 0"/>
      <inertia ixx="3.0855e-06" ixy="0.0" ixz="0.0" iyy="3.768e-06" iyz="0.0" izz="1.0455e-06"/>
    </inertial>
    <visual>
      <geometry>
        <box size="0.024 0.011 0.044"/>
      </geometry>
      <origin rpy="0 0 0" xyz="0 0 0"/>
      <material name="Gray"/>
    </visual>
    <collision>
      <geometry>
        <box size="0.024 0.011 0.044"/>
      </geometry>
      <origin rpy="0 0 0" xyz="0 0 0"/>
    </collision>
  </link>
  <gazebo>
    <plugin filename="libgazebo_ros_imu.so" name="imu_plugin_ros">
      <alwaysOn>true</alwaysOn>
      <bodyName>utorso</bodyName>
      <topicName>/v1/RightIMU/imu</topicName>
      <serviceName>/v1/RightIMU/imu_service</serviceName>
    </plugin>
  </gazebo>
  <joint name="/v1/RightIMU_Offset" type="fixed">
    <origin rpy="-1.57079632679 1.57079632679 0" xyz="0.363038 0.134239 -0.0468630"/>
    <axis xyz="0 0 1"/>
    <parent link="utorso"/>
    <child link="/v1/RightIMU_Frame"/>
  </joint>
  <link name="/v1/LeftIMU_Frame">
    <inertial>
      <mass value="0.018"/>
      <origin rpy="0 0 0" xyz="0 0 0"/>
      <inertia ixx="3.0855e-06" ixy="0.0" ixz="0.0" iyy="3.768e-06" iyz="0.0" izz="1.0455e-06"/>
    </inertial>
    <visual>
      <geometry>
        <box size="0.024 0.011 0.044"/>
      </geometry>
      <origin rpy="0 0 0" xyz="0 0 0"/>
      <material name="Gray"/>
    </visual>
    <collision>
      <geometry>
        <box size="0.024 0.011 0.044"/>
      </geometry>
      <origin rpy="0 0 0" xyz="0 0 0"/>
    </collision>
  </link>
  <gazebo>
    <plugin filename="libgazebo_ros_imu.so" name="imu_plugin_ros">
      <alwaysOn>true</alwaysOn>
      <bodyName>utorso</bodyName>
      <topicName>/v1/LeftIMU/imu</topicName>
      <serviceName>/v1/LeftIMU/imu_service</serviceName>
    </plugin>
  </gazebo>
  <joint name="/v1/LeftIMU_Offset" type="fixed">
    <origin rpy="1.57079632679 1.57079632679 0" xyz="0.363038 -0.134239  -0.0468630"/>
    <axis xyz="0 0 1"/>
    <parent link="utorso"/>
    <child link="/v1/LeftIMU_Frame"/>
  </joint>
  <link name="/v1/RightHazardCamera_Frame">
    <!-- Virtual Link -->
    <inertial>
      <mass value="0.1"/>
      <origin rpy="0 0 0" xyz="0 0 0"/>
      <inertia ixx="8.33333333333e-05" ixy="0.0" ixz="0.0" iyy="8.33333333333e-05" iyz="0.0" izz="0.000125"/>
    </inertial>
  </link>
  <gazebo reference="/v1/RightHazardCamera_Frame">
    <sensor name="/v1/RightHazardCamera" type="camera">
      <camera>
        <image>
          <width>1280</width>
          <height>1024</height>
          <format>R8G8B8</format>
        </image>
        <horizontal_fov>1.378</horizontal_fov>
        <clip>
          <near>0.1</near>
          <far>100</far>
        </clip>
      </camera>
      <update_rate>60</update_rate>
      <plugin filename="libgazebo_ros_camera.so" name="/v1/RightHazardCamera_controller">
        <frameName>/v1/RightHazardCamera_Frame</frameName>
        <imageTopicName>image_raw</imageTopicName>
        <cameraName>/v1/RightHazardCamera</cameraName>
      </plugin>
    </sensor>
  </gazebo>
  <joint name="/v1/RightHazardCamera_Offset" type="fixed">
    <origin rpy="0 0 0" xyz="0.0446987 0.0406146 0.0182674"/>
    <axis xyz="0 0 1"/>
    <parent link="utorso"/>
    <child link="/v1/RightHazardCamera_Frame"/>
  </joint>
  <link name="/v1/LeftHazardCamera_Frame">
    <!-- Virtual Link -->
    <inertial>
      <mass value="0.1"/>
      <origin rpy="0 0 0" xyz="0 0 0"/>
      <inertia ixx="8.33333333333e-05" ixy="0.0" ixz="0.0" iyy="8.33333333333e-05" iyz="0.0" izz="0.000125"/>
    </inertial>
  </link>
  <gazebo reference="/v1/LeftHazardCamera_Frame">
    <sensor name="/v1/LeftHazardCamera" type="camera">
      <camera>
        <image>
          <width>1280</width>
          <height>1024</height>
          <format>R8G8B8</format>
        </image>
        <horizontal_fov>1.378</horizontal_fov>
        <clip>
          <near>0.1</near>
          <far>100</far>
        </clip>
      </camera>
      <update_rate>60</update_rate>
      <plugin filename="libgazebo_ros_camera.so" name="/v1/LeftHazardCamera_controller">
        <frameName>/v1/LeftHazardCamera_Frame</frameName>
        <imageTopicName>image_raw</imageTopicName>
        <cameraName>/v1/LeftHazardCamera</cameraName>
      </plugin>
    </sensor>
  </gazebo>
  <joint name="/v1/LeftHazardCamera_Offset" type="fixed">
    <origin rpy="0 0 0" xyz="0.0446987 -0.0406146 0.0182674"/>
    <axis xyz="0 0 1"/>
    <parent link="utorso"/>
    <child link="/v1/LeftHazardCamera_Frame"/>
  </joint>
  <link name="/v1/StereoHazardCamera_Frame">
    <!-- Virtual Link -->
    <inertial>
      <mass value="0.1"/>
      <origin rpy="0 0 0" xyz="0 0 0"/>
      <inertia ixx="8.33333333333e-05" ixy="0.0" ixz="0.0" iyy="8.33333333333e-05" iyz="0.0" izz="0.000125"/>
    </inertial>
  </link>
  <joint name="/v1/StereoHazardCamera_Offset" type="fixed">
    <origin rpy="0 0 1.57" xyz=".1723 -0.04535 0.0344"/>
    <axis xyz="0 0 1"/>
    <parent link="utorso"/>
    <child link="/v1/StereoHazardCamera_Frame"/>
  </joint>
  <link name="head">
    <!-- Virtual Link -->
    <inertial>
      <mass value="0.1"/>
      <origin rpy="0 0 0" xyz="0 0 0"/>
      <inertia ixx="8.33333333333e-05" ixy="0.0" ixz="0.0" iyy="8.33333333333e-05" iyz="0.0" izz="0.000125"/>
    </inertial>
    <visual>
      <origin rpy="0 0 0" xyz="0 0 0"/>
      <geometry>
        <mesh filename="package://V1/models/V1/meshes/2013_05_16/nj1.wrl"/>
      </geometry>
      <material name="gold">
        <color rgba="1 0.67 0 1"/>
      </material>
    </visual>
    <collision>
      <origin rpy="0 0 0" xyz="0 0 0"/>
      <geometry>
        <mesh filename="package://V1/models/V1/meshes/2013_05_16/nj1.wrl"/>
      </geometry>
    </collision>
  </link>
  <link name="mhead">
    <!-- Virtual Link -->
    <inertial>
      <mass value="0.1"/>
      <origin rpy="0 0 0" xyz="0 0 0"/>
      <inertia ixx="8.33333333333e-05" ixy="0.0" ixz="0.0" iyy="8.33333333333e-05" iyz="0.0" izz="0.000125"/>
    </inertial>
    <visual>
      <origin rpy="0 0 0" xyz="0 0 0"/>
      <geometry>
        <mesh filename="package://V1/models/V1/meshes/2013_05_16/nj2.wrl"/>
      </geometry>
      <material name="gold">
        <color rgba="1 0.67 0 1"/>
      </material>
    </visual>
    <collision>
      <origin rpy="0 0 0" xyz="0 0 0"/>
      <geometry>
        <mesh filename="package://V1/models/V1/meshes/2013_05_16/nj2.wrl"/>
      </geometry>
    </collision>
  </link>
  <link name="uhead">
    <inertial>
      <mass value="3.842"/>
      <origin rpy="0 0 0" xyz="-0.079 0.009 0"/>
      <inertia ixx="0.03012128" ixy="0.0" ixz="0.0" iyy="0.03012128" iyz="0.0" izz="0.03012128"/>
    </inertial>
    <visual>
      <origin rpy="0 0 0" xyz="0 0 0"/>
      <!-- <origin rpy="${origin_rpy}" xyz="${origin_xyz}"/> -->
      <geometry>
        <mesh filename="package://V1/models/V1/meshes/2013_05_16/head.wrl"/>
        <!-- <sphere radius="${radius}"/> -->
      </geometry>
      <material name="White"/>
    </visual>
    <collision>
      <origin rpy="0 0 0" xyz="0 0 0"/>
      <geometry>
        <mesh filename="package://V1/models/V1/meshes/2013_05_16/head.wrl"/>
      </geometry>
    </collision>
  </link>
  <gazebo reference="uhead">
    <material>Gazebo/White</material>
  </gazebo>
  <joint name="neck_ay" type="revolute">
    <origin rpy="-1.57079632679 0 0" xyz="0.3383 0 0.0519"/>
    <axis xyz="0 0 1"/>
    <parent link="utorso"/>
    <child link="head"/>
    <limit effort="26" lower="-1.5707963259" upper="0" velocity="5"/>
    <controller_gains Kd="0" Kp="20000"/>
    <dynamics damping="1.0" friction="0.0"/>
  </joint>
  <gazebo reference="neck_ay">
    <provideFeedback>1</provideFeedback>
  </gazebo>
  <joint name="neck_by" type="revolute">
    <origin rpy="1.57079632679 0 1.57079632679" xyz="0 0.0519 0"/>
    <axis xyz="0 0 1"/>
    <parent link="head"/>
    <child link="mhead"/>
    <limit effort="26" lower="-1.5707963259" upper="1.5707963259" velocity="5"/>
    <controller_gains Kd="0" Kp="20000"/>
    <dynamics damping="1.0" friction="0.0"/>
  </joint>
  <gazebo reference="neck_by">
    <provideFeedback>1</provideFeedback>
  </gazebo>
  <joint name="neck_cy" type="revolute">
    <origin rpy="-1.57079632679 0 0" xyz="0.06 0 0.196"/>
    <axis xyz="0 0 1"/>
    <parent link="mhead"/>
    <child link="uhead"/>
    <limit effort="26" lower="-0.08726646255" upper="0.78539816295" velocity="5"/>
    <controller_gains Kd="0" Kp="20000"/>
    <dynamics damping="1.0" friction="0.0"/>
  </joint>
  <gazebo reference="neck_cy">
    <provideFeedback>1</provideFeedback>
  </gazebo>
  <actuator name="/neck/j1" type="turbodriver_api/TurbodriverAPI_DRCv3"/>
  <actuator name="/neck/j2" type="turbodriver_api/TurbodriverAPI_DRCv3"/>
  <actuator name="/neck/j3" type="turbodriver_api/TurbodriverAPI_DRCv3"/>
  <mode name="LowerNeckExtensorMode" type="mode_plugins/ModeInterface">
    <translator name="LowerNeckExtensorModeData" type="SimpleActuatorToJointMode">
      <joint data="mode" name="neck_ay"/>
      <actuator data="mode" name="/neck/j1"/>
    </translator>
    <translator name="LowerNeckExtensorModeCommand" type="SimpleJointToActuatorMode">
      <joint data="modeCommand" name="neck_ay"/>
      <actuator data="modeCommand" name="/neck/j1"/>
    </translator>
  </mode>
  <mode name="NeckRotatorMode" type="mode_plugins/ModeInterface">
    <translator name="NeckRotatorModeData" type="SimpleActuatorToJointMode">
      <joint data="mode" name="neck_by"/>
      <actuator data="mode" name="/neck/j2"/>
    </translator>
    <translator name="NeckRotatorModeCommand" type="SimpleJointToActuatorMode">
      <joint data="modeCommand" name="neck_by"/>
      <actuator data="modeCommand" name="/neck/j2"/>
    </translator>
  </mode>
  <mode name="UpperNeckExtensorMode" type="mode_plugins/ModeInterface">
    <translator name="UpperNeckExtensorModeData" type="SimpleActuatorToJointMode">
      <joint data="mode" name="neck_cy"/>
      <actuator data="mode" name="/neck/j3"/>
    </translator>
    <translator name="UpperNeckExtensorModeCommand" type="SimpleJointToActuatorMode">
      <joint data="modeCommand" name="neck_cy"/>
      <actuator data="modeCommand" name="/neck/j3"/>
    </translator>
  </mode>
  <link name="/v1/HeadCamBoard_Frame">
    <!-- Virtual Link -->
    <inertial>
      <mass value="0.1"/>
      <origin rpy="0 0 0" xyz="0 0 0"/>
      <inertia ixx="8.33333333333e-05" ixy="0.0" ixz="0.0" iyy="8.33333333333e-05" iyz="0.0" izz="0.000125"/>
    </inertial>
  </link>
  <gazebo reference="/v1/HeadCamBoard_Frame">
    <sensor name="asus/ir" type="depth">
      <camera>
        <image>
          <width>160</width>
          <height>120</height>
          <format>L8</format>
        </image>
        <horizontal_fov>1.57079632679</horizontal_fov>
        <clip>
          <near>0.01</near>
          <far>1</far>
        </clip>
      </camera>
      <update_rate>30</update_rate>
      <plugin filename="libAsusXtionPluginRos.so" name="/v1/HeadCamBoard_Controller">
        <updateRate>30</updateRate>
        <cameraName>/v1/HeadCamBoard</cameraName>
        <imageTopicName>rgb/image_raw</imageTopicName>
        <cameraInfoTopicName>rgb/camera_info</cameraInfoTopicName>
        <depthImageTopicName>depth/image_raw</depthImageTopicName>
        <depthCameraInfoTopicName>depth/camera_info</depthCameraInfoTopicName>
        <pointCloudTopicName>depth/points</pointCloudTopicName>
        <frameName>/v1/HeadCamBoardIR_Frame</frameName>
        <pointCloudCutoff>0.2</pointCloudCutoff>
        <hack_baseline>0.2</hack_baseline>
      </plugin>
    </sensor>
  </gazebo>
  <joint name="/v1/HeadCamBoard_Offset" type="fixed">
    <origin rpy="1.57079632679 3.14159265359 -.61" xyz="-0.186861111 0.085358875 -0.008499998"/>
    <axis xyz="0 0 1"/>
    <parent link="uhead"/>
    <child link="/v1/HeadCamBoard_Frame"/>
  </joint>
  <link name="/v1/HeadCamBoardIR_Frame">
    <!-- Virtual Link -->
    <inertial>
      <mass value="0.1"/>
      <origin rpy="0 0 0" xyz="0 0 0"/>
      <inertia ixx="8.33333333333e-05" ixy="0.0" ixz="0.0" iyy="8.33333333333e-05" iyz="0.0" izz="0.000125"/>
    </inertial>
  </link>
  <joint name="/v1/HeadCamBoardIR_Offset" type="fixed">
    <origin rpy="-1.4279169 0.057186 -1.603747" xyz="-0.05180 -0.0013 0.030237"/>
    <axis xyz="0 0 1"/>
    <parent link="/v1/HeadCamBoard_Frame"/>
    <child link="/v1/HeadCamBoardIR_Frame"/>
  </joint>
  <link name="/v1/Ibeo_Frame">
    <!-- Virtual Link -->
    <inertial>
      <mass value="0.1"/>
      <origin rpy="0 0 0" xyz="0 0 0"/>
      <inertia ixx="8.33333333333e-05" ixy="0.0" ixz="0.0" iyy="8.33333333333e-05" iyz="0.0" izz="0.000125"/>
    </inertial>
  </link>
  <gazebo reference="/v1/Ibeo_Frame">
    <sensor name="/v1/Ibeo_sensor" type="ray">
      <pose>0 0 0 0 0 0</pose>
      <visualize>false</visualize>
      <update_rate>40</update_rate>
      <ray>
        <scan>
          <horizontal>
            <samples>880</samples>
            <min_angle>-1.0472</min_angle>
            <max_angle>0.8727</max_angle>
          </horizontal>
          <vertical>
            <samples>8</samples>
            <min_angle>-0.055851</min_angle>
            <max_angle>0.055851</max_angle>
          </vertical>
        </scan>
        <range>
          <min>0.08</min>
          <max>10</max>
          <resolution>0.01</resolution>
        </range>
      </ray>
      <plugin filename="libgazebo_ros_laser.so" name="/v1/Ibeo_controller">
        <gaussianNoise>0.005</gaussianNoise>
        <alwaysOn>true</alwaysOn>
        <updateRate>40</updateRate>
        <topicName>/v1/Ibeo/scan</topicName>
        <frameName>/v1/Ibeo_Frame</frameName>
      </plugin>
    </sensor>
  </gazebo>
  <joint name="/v1/Ibeo_Offset" type="fixed">
    <origin rpy="-1.57079632679 0 -3.14159265359" xyz="-0.133 0.0065 -0.02325"/>
    <axis xyz="0 0 1"/>
    <parent link="uhead"/>
    <child link="/v1/Ibeo_Frame"/>
  </joint>
  <link name="/v1/Ensenso_Frame">
    <!-- Virtual Link -->
    <inertial>
      <mass value="0.1"/>
      <origin rpy="0 0 0" xyz="0 0 0"/>
      <inertia ixx="8.33333333333e-05" ixy="0.0" ixz="0.0" iyy="8.33333333333e-05" iyz="0.0" izz="0.000125"/>
    </inertial>
  </link>
  <joint name="/v1/Ensenso_Offset" type="fixed">
    <origin rpy="0 -1.57079632679 0" xyz="-.1836 -.0645 -.00311"/>
    <axis xyz="0 0 1"/>
    <parent link="uhead"/>
    <child link="/v1/Ensenso_Frame"/>
  </joint>
  <link name="/v1/EnsensoIR_Frame">
    <!-- Virtual Link -->
    <inertial>
      <mass value="0.1"/>
      <origin rpy="0 0 0" xyz="0 0 0"/>
      <inertia ixx="8.33333333333e-05" ixy="0.0" ixz="0.0" iyy="8.33333333333e-05" iyz="0.0" izz="0.000125"/>
    </inertial>
  </link>
  <joint name="/v1/EnsensoIR_Offset" type="fixed">
    <origin rpy="-0.31182 0.0562965 -0.0034575" xyz="0.0 0.006939 0.014954"/>
    <axis xyz="0 0 1"/>
    <parent link="/v1/Ensenso_Frame"/>
    <child link="/v1/EnsensoIR_Frame"/>
  </joint>
  <link name="/v1/HeadIMU_Frame">
    <inertial>
      <mass value="0.018"/>
      <origin rpy="0 0 0" xyz="0 0 0"/>
      <inertia ixx="3.0855e-06" ixy="0.0" ixz="0.0" iyy="3.768e-06" iyz="0.0" izz="1.0455e-06"/>
    </inertial>
    <visual>
      <geometry>
        <box size="0.024 0.011 0.044"/>
      </geometry>
      <origin rpy="0 0 0" xyz="0 0 0"/>
      <material name="Gray"/>
    </visual>
    <collision>
      <geometry>
        <box size="0.024 0.011 0.044"/>
      </geometry>
      <origin rpy="0 0 0" xyz="0 0 0"/>
    </collision>
  </link>
  <gazebo>
    <plugin filename="libgazebo_ros_imu.so" name="imu_plugin_ros">
      <alwaysOn>true</alwaysOn>
      <bodyName>uhead</bodyName>
      <topicName>/v1/HeadIMU/imu</topicName>
      <serviceName>/v1/HeadIMU/imu_service</serviceName>
    </plugin>
  </gazebo>
  <joint name="/v1/HeadIMU_Offset" type="fixed">
    <origin rpy="-1.57079632679 0  0" xyz="-0.103 -0.05239 0.00022730"/>
    <axis xyz="0 0 1"/>
    <parent link="uhead"/>
    <child link="/v1/HeadIMU_Frame"/>
  </joint>
  <link name="r_clav">
    <inertial>
      <mass value="2.45"/>
      <origin rpy="0 0 0" xyz="0 -0.01204 -0.251"/>
      <inertia ixx="0.0126828333333" ixy="0.0" ixz="0.0" iyy="0.00971016666667" iyz="0.0" izz="0.0136889666667"/>
    </inertial>
    <visual>
      <geometry>
        <mesh filename="package://V1/models/V1/meshes/2013_05_16/aj1_Right.wrl"/>
        <!-- <box size="${width} ${height} ${depth}"/> -->
      </geometry>
      <origin rpy="0 0 0" xyz="0 0 0"/>
      <!-- <origin rpy="${origin_rpy}" xyz="${origin_xyz}"/> -->
      <material name="Gold"/>
    </visual>
    <collision>
      <geometry>
        <mesh filename="package://V1/models/V1/meshes/2013_05_16/aj1_Right.wrl"/>
      </geometry>
      <origin rpy="0 0 0" xyz="0 0 0"/>
    </collision>
  </link>
  <gazebo reference="r_clav">
    <material>Gazebo/Gold</material>
  </gazebo>
  <link name="r_scap">
    <inertial>
      <mass value="3.67"/>
      <origin rpy="0 0 0" xyz="0.044 -0.0034 0"/>
      <inertia ixx="0.0115718158333" ixy="0.0" ixz="0.0" iyy="0.0166486491667" iyz="0.0" izz="0.0172373783333"/>
    </inertial>
    <visual>
      <geometry>
        <mesh filename="package://V1/models/V1/meshes/2013_05_16/aj2.wrl"/>
        <!-- <box size="${width} ${height} ${depth}"/> -->
      </geometry>
      <origin rpy="0 0 0" xyz="0 0 0"/>
      <!-- <origin rpy="${origin_rpy}" xyz="${origin_xyz}"/> -->
      <material name="White"/>
    </visual>
    <collision>
      <geometry>
        <mesh filename="package://V1/models/V1/meshes/2013_05_16/aj2.wrl"/>
      </geometry>
      <origin rpy="0 0 0" xyz="0 0 0"/>
    </collision>
  </link>
  <gazebo reference="r_scap">
    <material>Gazebo/White</material>
  </gazebo>
  <link name="r_uarm">
    <inertial>
      <mass value="2.575"/>
      <origin rpy="0 0 0" xyz="0 0.006 -0.236"/>
      <inertia ixx="0.0227863895833" ixy="0.0" ixz="0.0" iyy="0.0213984645833" iyz="0.0" izz="0.00932579166667"/>
    </inertial>
    <visual>
      <geometry>
        <mesh filename="package://V1/models/V1/meshes/2013_05_16/aj3_Right.wrl"/>
        <!-- <box size="${width} ${height} ${depth}"/> -->
      </geometry>
      <origin rpy="0 0 0" xyz="0 0 0"/>
      <!-- <origin rpy="${origin_rpy}" xyz="${origin_xyz}"/> -->
      <material name="White"/>
    </visual>
    <collision>
      <geometry>
        <mesh filename="package://V1/models/V1/meshes/2013_05_16/aj3_Right.wrl"/>
      </geometry>
      <origin rpy="0 0 0" xyz="0 0 0"/>
    </collision>
  </link>
  <gazebo reference="r_uarm">
    <material>Gazebo/White</material>
  </gazebo>
  <link name="r_larm">
    <inertial>
      <mass value="1.367"/>
      <origin rpy="0 0 0" xyz="0.0270 0.0302 0"/>
      <inertia ixx="0.004941705" ixy="0.0" ixz="0.0" iyy="0.00469849291667" iyz="0.0" izz="0.00530133991667"/>
    </inertial>
    <visual>
      <geometry>
        <mesh filename="package://V1/models/V1/meshes/2013_05_16/aj4.wrl"/>
        <!-- <box size="${width} ${height} ${depth}"/> -->
      </geometry>
      <origin rpy="0 0 0" xyz="0 0 0"/>
      <!-- <origin rpy="${origin_rpy}" xyz="${origin_xyz}"/> -->
      <material name="Gold"/>
    </visual>
    <collision>
      <geometry>
        <mesh filename="package://V1/models/V1/meshes/2013_05_16/aj4.wrl"/>
      </geometry>
      <origin rpy="0 0 0" xyz="0 0 0"/>
    </collision>
  </link>
  <gazebo reference="r_larm">
    <material>Gazebo/Gold</material>
  </gazebo>
  <joint name="r_arm_usy" type="revolute">
    <origin rpy="1.57079632679 0 0" xyz="0.29842 0 -0.03157"/>
    <axis xyz="0 0 1"/>
    <parent link="utorso"/>
    <child link="r_clav"/>
    <limit effort="190" lower="-3.1415926518" upper="3.1415926518" velocity="5.89"/>
    <controller_gains Kd="400" Kp="20000"/>
    <dynamics damping="1.0" friction="0.0"/>
  </joint>
  <gazebo reference="r_arm_usy">
    <provideFeedback>1</provideFeedback>
  </gazebo>
  <joint name="r_arm_shx" type="revolute">
    <origin rpy="1.57079632679 0 3.14159265359" xyz="0 0 -0.246"/>
    <axis xyz="0 0 1"/>
    <parent link="r_clav"/>
    <child link="r_scap"/>
    <limit effort="190" lower="-3.05432618925" upper="-0.1745329251" velocity="5.89"/>
    <controller_gains Kd="400" Kp="20000"/>
    <dynamics damping="1.0" friction="0.0"/>
  </joint>
  <gazebo reference="r_arm_shx">
    <provideFeedback>1</provideFeedback>
  </gazebo>
  <joint name="r_arm_ely" type="revolute">
    <origin rpy="-1.57079632679 0 1.57079632679" xyz="0 0 0"/>
    <axis xyz="0 0 1"/>
    <parent link="r_scap"/>
    <child link="r_uarm"/>
    <limit effort="65" lower="-1.5707963259" upper="1.5707963259" velocity="11.5"/>
    <controller_gains Kd="400" Kp="20000"/>
    <dynamics damping="1.0" friction="0.0"/>
  </joint>
  <gazebo reference="r_arm_ely">
    <provideFeedback>1</provideFeedback>
  </gazebo>
  <joint name="r_arm_elx" type="revolute">
    <origin rpy="1.57079632679 0 1.57079632679" xyz="0 -0.0254 -0.33"/>
    <axis xyz="0 0 1"/>
    <parent link="r_uarm"/>
    <child link="r_larm"/>
    <limit effort="65" lower="-1.9198621761" upper="-0.08726646255" velocity="11.5"/>
    <controller_gains Kd="400" Kp="20000"/>
    <dynamics damping="1.0" friction="0.0"/>
  </joint>
  <gazebo reference="r_arm_elx">
    <provideFeedback>1</provideFeedback>
  </gazebo>
  <link name="r_farm">
    <inertial>
      <mass value="2.703"/>
      <origin rpy="0 0 0" xyz="0 0.0006 -0.12"/>
      <inertia ixx="0.01633175125" ixy="0.0" ixz="0.0" iyy="0.0169338445" iyz="0.0" izz="0.00666402125"/>
    </inertial>
    <visual>
      <geometry>
        <mesh filename="package://V1/models/V1/meshes/2013_05_16/aj5_Right.wrl"/>
        <!-- <box size="${width} ${height} ${depth}"/> -->
      </geometry>
      <origin rpy="0 0 0" xyz="0 0 0"/>
      <!-- <origin rpy="${origin_rpy}" xyz="${origin_xyz}"/> -->
      <material name="White"/>
    </visual>
    <collision>
      <geometry>
        <mesh filename="package://V1/models/V1/meshes/2013_05_16/aj5_Right.wrl"/>
      </geometry>
      <origin rpy="0 0 0" xyz="0 0 0"/>
    </collision>
  </link>
  <gazebo reference="r_farm">
    <material>Gazebo/White</material>
  </gazebo>
  <link name="r_hand">
    <inertial>
      <mass value="0.1"/>
      <origin rpy="0 0 0" xyz="0 0 0"/>
      <inertia ixx="2.25083333333e-05" ixy="0.0" ixz="0.0" iyy="2.9175e-05" iyz="0.0" izz="8.33333333333e-06"/>
    </inertial>
    <visual>
      <geometry>
        <box size="0.03 0.01 0.051"/>
      </geometry>
      <origin rpy="0 0 0" xyz="0 0 0"/>
      <material name="Gray"/>
    </visual>
    <collision>
      <geometry>
        <box size="0.03 0.01 0.051"/>
      </geometry>
      <origin rpy="0 0 0" xyz="0 0 0"/>
    </collision>
  </link>
  <link name="right_palm">
    <inertial>
      <mass value="0.712"/>
      <origin rpy="0 0 0" xyz="0.0425 0 0"/>
      <inertia ixx="0.000679010666667" ixy="0.0" ixz="0.0" iyy="0.000514360666667" iyz="0.0" izz="0.00102201666667"/>
    </inertial>
    <visual>
      <geometry>
        <mesh filename="package://V1/models/V1/meshes/2013_05_16/palm_Right.wrl"/>
        <!-- <box size="${width} ${height} ${depth}"/> -->
      </geometry>
      <origin rpy="0 0 0" xyz="0 0 0"/>
      <!-- <origin rpy="${origin_rpy}" xyz="${origin_xyz}"/> -->
      <material name="Gold"/>
    </visual>
    <collision>
      <geometry>
        <mesh filename="package://V1/models/V1/meshes/2013_05_16/palm_Right.wrl"/>
      </geometry>
      <origin rpy="0 0 0" xyz="0 0 0"/>
    </collision>
  </link>
  <gazebo reference="right_palm">
    <material>Gazebo/Gold</material>
  </gazebo>
  <joint name="r_arm_uwy" type="revolute">
    <origin rpy="1.57079632679 0 3.14159265359" xyz="0.0254 0 0"/>
    <axis xyz="0 0 1"/>
    <parent link="r_larm"/>
    <child link="r_farm"/>
    <limit effort="26" lower="-2.35619448885" upper="2.35619448885" velocity="5"/>
    <controller_gains Kd="0" Kp="20000"/>
    <dynamics damping="1.0" friction="0.0"/>
  </joint>
  <gazebo reference="r_arm_uwy">
    <provideFeedback>1</provideFeedback>
  </gazebo>
  <joint name="r_arm_mwx" type="revolute">
    <origin rpy="-1.57079632679 0 1.57079632679" xyz="0 0 -0.287"/>
    <axis xyz="0 0 1"/>
    <parent link="r_farm"/>
    <child link="r_hand"/>
    <limit effort="14" lower="-0.8726646255" upper="0.6981317004" velocity="1"/>
    <controller_gains Kd="400" Kp="20000"/>
    <dynamics damping="1.0" friction="0.0"/>
  </joint>
  <gazebo reference="r_arm_mwx">
    <provideFeedback>1</provideFeedback>
  </gazebo>
  <joint name="r_arm_lwz" type="revolute">
    <origin rpy="1.57079632679 0 1.57079632679" xyz="0 0 0"/>
    <axis xyz="0 0 1"/>
    <parent link="r_hand"/>
    <child link="right_palm"/>
    <limit effort="14" lower="-0.5235987753" upper="0.43633231275" velocity="1"/>
    <controller_gains Kd="400" Kp="20000"/>
    <dynamics damping="1.0" friction="0.0"/>
  </joint>
  <gazebo reference="r_arm_lwz">
    <provideFeedback>1</provideFeedback>
  </gazebo>
  <actuator name="/trunk/raj1" type="turbodriver_api/TurbodriverAPI_DRCv4"/>
  <actuator name="/right_arm/j2" type="turbodriver_api/TurbodriverAPI_DRCv4"/>
  <actuator name="/right_arm/j3" type="turbodriver_api/TurbodriverAPI_DRCv4"/>
  <actuator name="/right_arm/j4" type="turbodriver_api/TurbodriverAPI_DRCv4"/>
  <actuator name="/right_arm/j5" type="turbodriver_api/TurbodriverAPI_DRCv3"/>
  <actuator name="/right_arm/forearm_driver1/wrist_right" type="forearm_api/WristAPI_DRCv1"/>
  <actuator name="/right_arm/forearm_driver1/wrist_left" type="forearm_api/WristAPI_DRCv1"/>
  <mode name="RightShoulderExtensorMode" type="mode_plugins/ModeInterface">
    <translator name="RightShoulderExtensorModeData" type="SimpleActuatorToJointMode">
      <joint data="mode" name="r_arm_usy"/>
      <actuator data="mode" name="/trunk/raj1"/>
    </translator>
    <translator name="RightShoulderExtensorModeCommand" type="SimpleJointToActuatorMode">
      <joint data="modeCommand" name="r_arm_usy"/>
      <actuator data="modeCommand" name="/trunk/raj1"/>
    </translator>
  </mode>
  <mode name="RightShoulderAdductorMode" type="mode_plugins/ModeInterface">
    <translator name="RightShoulderAdductorModeData" type="SimpleActuatorToJointMode">
      <joint data="mode" name="r_arm_shx"/>
      <actuator data="mode" name="/right_arm/j2"/>
    </translator>
    <translator name="RightShoulderAdductorModeCommand" type="SimpleJointToActuatorMode">
      <joint data="modeCommand" name="r_arm_shx"/>
      <actuator data="modeCommand" name="/right_arm/j2"/>
    </translator>
  </mode>
  <mode name="RightShoulderSupinatorMode" type="mode_plugins/ModeInterface">
    <translator name="RightShoulderSupinatorModeData" type="SimpleActuatorToJointMode">
      <joint data="mode" name="r_arm_ely"/>
      <actuator data="mode" name="/right_arm/j3"/>
    </translator>
    <translator name="RightShoulderSupinatorModeCommand" type="SimpleJointToActuatorMode">
      <joint data="modeCommand" name="r_arm_ely"/>
      <actuator data="modeCommand" name="/right_arm/j3"/>
    </translator>
  </mode>
  <mode name="RightElbowExtensorMode" type="mode_plugins/ModeInterface">
    <translator name="RightElbowExtensorModeData" type="SimpleActuatorToJointMode">
      <joint data="mode" name="r_arm_elx"/>
      <actuator data="mode" name="/right_arm/j4"/>
    </translator>
    <translator name="RightElbowExtensorModeCommand" type="SimpleJointToActuatorMode">
      <joint data="modeCommand" name="r_arm_elx"/>
      <actuator data="modeCommand" name="/right_arm/j4"/>
    </translator>
  </mode>
  <mode name="RightForearmSupinatorMode" type="mode_plugins/ModeInterface">
    <translator name="RightForearmSupinatorModeData" type="SimpleActuatorToJointMode">
      <joint data="mode" name="r_arm_uwy"/>
      <actuator data="mode" name="/right_arm/j5"/>
    </translator>
    <translator name="RightForearmSupinatorModeCommand" type="SimpleJointToActuatorMode">
      <joint data="modeCommand" name="r_arm_uwy"/>
      <actuator data="modeCommand" name="/right_arm/j5"/>
    </translator>
  </mode>
  <mode name="RightWristExtensorMode" type="mode_plugins/ModeInterface">
    <translator name="RightWristExtensorModeData" type="SimpleActuatorToJointMode">
      <joint data="mode" name="r_arm_mwx"/>
      <actuator data="mode" name="/right_arm/forearm_driver1/wrist_right"/>
    </translator>
    <translator name="RightWristExtensorModeCommand" type="SimpleJointToActuatorMode">
      <joint data="modeCommand" name="r_arm_mwx"/>
      <actuator data="modeCommand" name="/right_arm/forearm_driver1/wrist_right"/>
    </translator>
  </mode>
  <mode name="RightWristMode" type="mode_plugins/ModeInterface">
    <translator name="RightWristModeData" type="SimpleActuatorToJointMode">
      <joint data="mode" name="r_arm_lwz"/>
      <actuator data="mode" name="/right_arm/forearm_driver1/wrist_left"/>
    </translator>
    <translator name="RightWristModeCommand" type="SimpleJointToActuatorMode">
      <joint data="modeCommand" name="r_arm_lwz"/>
      <actuator data="modeCommand" name="/right_arm/forearm_driver1/wrist_left"/>
    </translator>
  </mode>
  <link name="/v1/RightCamBoard_Frame">
    <!-- Virtual Link -->
    <inertial>
      <mass value="0.1"/>
      <origin rpy="0 0 0" xyz="0 0 0"/>
      <inertia ixx="8.33333333333e-05" ixy="0.0" ixz="0.0" iyy="8.33333333333e-05" iyz="0.0" izz="0.000125"/>
    </inertial>
  </link>
  <gazebo reference="/v1/RightCamBoard_Frame">
    <sensor name="asus/ir" type="depth">
      <camera>
        <image>
          <width>160</width>
          <height>120</height>
          <format>L8</format>
        </image>
        <horizontal_fov>1.57079632679</horizontal_fov>
        <clip>
          <near>0.01</near>
          <far>1</far>
        </clip>
      </camera>
      <update_rate>30</update_rate>
      <plugin filename="libAsusXtionPluginRos.so" name="/v1/RightCamBoard_Controller">
        <updateRate>30</updateRate>
        <cameraName>/v1/RightCamBoard</cameraName>
        <imageTopicName>rgb/image_raw</imageTopicName>
        <cameraInfoTopicName>rgb/camera_info</cameraInfoTopicName>
        <depthImageTopicName>depth/image_raw</depthImageTopicName>
        <depthCameraInfoTopicName>depth/camera_info</depthCameraInfoTopicName>
        <pointCloudTopicName>depth/points</pointCloudTopicName>
        <frameName>/v1/RightCamBoardIR_Frame</frameName>
        <pointCloudCutoff>0.2</pointCloudCutoff>
        <hack_baseline>0.2</hack_baseline>
      </plugin>
    </sensor>
  </gazebo>
  <joint name="/v1/RightCamBoard_Offset" type="fixed">
    <origin rpy="3.14159265359 1.57079632679 3.14159265359" xyz="0.049237 0.006877 -0.250708"/>
    <axis xyz="0 0 1"/>
    <parent link="r_farm"/>
    <child link="/v1/RightCamBoard_Frame"/>
  </joint>
  <link name="/v1/RightCamBoardIR_Frame">
    <!-- Virtual Link -->
    <inertial>
      <mass value="0.1"/>
      <origin rpy="0 0 0" xyz="0 0 0"/>
      <inertia ixx="8.33333333333e-05" ixy="0.0" ixz="0.0" iyy="8.33333333333e-05" iyz="0.0" izz="0.000125"/>
    </inertial>
  </link>
  <joint name="/v1/RightCamBoardIR_Offset" type="fixed">
    <origin rpy="-1.4279169 0.057186 -1.603747" xyz="-0.05180 -0.0013 0.030237"/>
    <axis xyz="0 0 1"/>
    <parent link="/v1/RightCamBoard_Frame"/>
    <child link="/v1/RightCamBoardIR_Frame"/>
  </joint>
  <link name="/v1/LeftCamBoard_Frame">
    <!-- Virtual Link -->
    <inertial>
      <mass value="0.1"/>
      <origin rpy="0 0 0" xyz="0 0 0"/>
      <inertia ixx="8.33333333333e-05" ixy="0.0" ixz="0.0" iyy="8.33333333333e-05" iyz="0.0" izz="0.000125"/>
    </inertial>
  </link>
  <gazebo reference="/v1/LeftCamBoard_Frame">
    <sensor name="asus/ir" type="depth">
      <camera>
        <image>
          <width>160</width>
          <height>120</height>
          <format>L8</format>
        </image>
        <horizontal_fov>1.57079632679</horizontal_fov>
        <clip>
          <near>0.01</near>
          <far>1</far>
        </clip>
      </camera>
      <update_rate>30</update_rate>
      <plugin filename="libAsusXtionPluginRos.so" name="/v1/LeftCamBoard_Controller">
        <updateRate>30</updateRate>
        <cameraName>/v1/LeftCamBoard</cameraName>
        <imageTopicName>rgb/image_raw</imageTopicName>
        <cameraInfoTopicName>rgb/camera_info</cameraInfoTopicName>
        <depthImageTopicName>depth/image_raw</depthImageTopicName>
        <depthCameraInfoTopicName>depth/camera_info</depthCameraInfoTopicName>
        <pointCloudTopicName>depth/points</pointCloudTopicName>
        <frameName>/v1/LeftCamBoardIR_Frame</frameName>
        <pointCloudCutoff>0.2</pointCloudCutoff>
        <hack_baseline>0.2</hack_baseline>
      </plugin>
    </sensor>
  </gazebo>
  <joint name="/v1/LeftCamBoard_Offset" type="fixed">
    <origin rpy="3.14159265359 -1.57079632679 0" xyz="0.045536 -0.0085 0.250708"/>
    <axis xyz="0 0 1"/>
    <parent link="l_farm"/>
    <child link="/v1/LeftCamBoard_Frame"/>
  </joint>
  <link name="/v1/LeftCamBoardIR_Frame">
    <!-- Virtual Link -->
    <inertial>
      <mass value="0.1"/>
      <origin rpy="0 0 0" xyz="0 0 0"/>
      <inertia ixx="8.33333333333e-05" ixy="0.0" ixz="0.0" iyy="8.33333333333e-05" iyz="0.0" izz="0.000125"/>
    </inertial>
  </link>
  <joint name="/v1/LeftCamBoardIR_Offset" type="fixed">
    <origin rpy="-1.4279169 0.057186 -1.603747" xyz="-0.05180 -0.0013 0.030237"/>
    <axis xyz="0 0 1"/>
    <parent link="/v1/LeftCamBoard_Frame"/>
    <child link="/v1/LeftCamBoardIR_Frame"/>
  </joint>
  <link name="/v1/RightThumbMetacarpal">
    <inertial>
      <mass value="0.017"/>
      <origin rpy="0 0 0" xyz="0 0 0"/>
      <inertia ixx="2.83333333333e-07" ixy="0.0" ixz="0.0" iyy="2.83333333333e-07" iyz="0.0" izz="2.83333333333e-07"/>
    </inertial>
    <visual>
      <geometry>
        <mesh filename="package://V1/models/V1/meshes/2013_05_16/tf1_Right.wrl"/>
        <!-- <box size="${width} ${height} ${depth}"/> -->
      </geometry>
      <origin rpy="0 0 0" xyz="0 0 0"/>
      <!-- <origin rpy="${origin_rpy}" xyz="${origin_xyz}"/> -->
      <material name="Gold"/>
    </visual>
    <collision>
      <geometry>
        <mesh filename="package://V1/models/V1/meshes/2013_05_16/tf1_Right.wrl"/>
      </geometry>
      <origin rpy="0 0 0" xyz="0 0 0"/>
    </collision>
  </link>
  <gazebo reference="/v1/RightThumbMetacarpal">
    <material>Gazebo/Gold</material>
  </gazebo>
  <link name="/v1/RightThumbProximalPhalanx">
    <inertial>
      <mass value="0.02"/>
      <origin rpy="0 0 0" xyz="0.017 0 0"/>
      <inertia ixx="1.72833333333e-06" ixy="0.0" ixz="0.0" iyy="5.98666666667e-06" iyz="0.0" izz="5.46166666667e-06"/>
    </inertial>
    <visual>
      <geometry>
        <mesh filename="package://V1/models/V1/meshes/2013_05_16/tf2.wrl"/>
        <!-- <box size="${width} ${height} ${depth}"/> -->
      </geometry>
      <origin rpy="0 0 0" xyz="0 0 0"/>
      <!-- <origin rpy="${origin_rpy}" xyz="${origin_xyz}"/> -->
      <material name="Gold"/>
    </visual>
    <collision>
      <geometry>
        <mesh filename="package://V1/models/V1/meshes/2013_05_16/tf2.wrl"/>
      </geometry>
      <origin rpy="0 0 0" xyz="0 0 0"/>
    </collision>
  </link>
  <gazebo reference="/v1/RightThumbProximalPhalanx">
    <material>Gazebo/Gold</material>
  </gazebo>
  <link name="/v1/RightThumbMedialPhalanx">
    <inertial>
      <mass value="0.013"/>
      <origin rpy="0 0 0" xyz="0.011 0 0"/>
      <inertia ixx="7.07416666667e-07" ixy="0.0" ixz="0.0" iyy="1.77666666667e-06" iyz="0.0" izz="1.43541666667e-06"/>
    </inertial>
    <visual>
      <geometry>
        <mesh filename="package://V1/models/V1/meshes/2013_05_16/tf3.wrl"/>
        <!-- <box size="${width} ${height} ${depth}"/> -->
      </geometry>
      <origin rpy="0 0 0" xyz="0 0 0"/>
      <!-- <origin rpy="${origin_rpy}" xyz="${origin_xyz}"/> -->
      <material name="Gold"/>
    </visual>
    <collision>
      <geometry>
        <mesh filename="package://V1/models/V1/meshes/2013_05_16/tf3.wrl"/>
      </geometry>
      <origin rpy="0 0 0" xyz="0 0 0"/>
    </collision>
  </link>
  <gazebo reference="/v1/RightThumbMedialPhalanx">
    <material>Gazebo/Gold</material>
  </gazebo>
  <link name="/v1/RightThumbDistalPhalanx">
    <inertial>
      <mass value="0.006"/>
      <origin rpy="0 0 0" xyz="0.0086 0 0"/>
      <inertia ixx="2.525e-07" ixy="0.0" ixz="0.0" iyy="5.45e-07" iyz="0.0" izz="4.365e-07"/>
    </inertial>
    <visual>
      <geometry>
        <mesh filename="package://V1/models/V1/meshes/2013_05_16/tf4.wrl"/>
        <!-- <box size="${width} ${height} ${depth}"/> -->
      </geometry>
      <origin rpy="0 0 0" xyz="0 0 0"/>
      <!-- <origin rpy="${origin_rpy}" xyz="${origin_xyz}"/> -->
      <material name="Gold"/>
    </visual>
    <collision>
      <geometry>
        <mesh filename="package://V1/models/V1/meshes/2013_05_16/tf4.wrl"/>
      </geometry>
      <origin rpy="0 0 0" xyz="0 0 0"/>
    </collision>
  </link>
  <gazebo reference="/v1/RightThumbDistalPhalanx">
    <material>Gazebo/Gold</material>
  </gazebo>
  <joint name="RightThumbMPYaw" type="fixed">
    <origin rpy="1.57079632679 0 -1.34390352" xyz="0.00748367180673 -0.0324153432851 0.005182"/>
    <axis xyz="0 0 1"/>
    <parent link="right_palm"/>
    <child link="/v1/RightThumbMetacarpal"/>
  </joint>
  <joint name="RightThumbMPExtensor" type="fixed">
    <origin rpy="1.57079632679 0 0" xyz="0.02286 0 -0.025091"/>
    <axis xyz="0 0 1"/>
    <parent link="/v1/RightThumbMetacarpal"/>
    <child link="/v1/RightThumbProximalPhalanx"/>
  </joint>
  <joint name="RightThumbPIPExtensor" type="fixed">
    <origin rpy="0 0 0" xyz="0.0381 0 0"/>
    <axis xyz="0 0 1"/>
    <parent link="/v1/RightThumbProximalPhalanx"/>
    <child link="/v1/RightThumbMedialPhalanx"/>
  </joint>
  <joint name="RightThumbDIPExtensor" type="fixed">
    <origin rpy="0 0 0" xyz="0.02794 0 0"/>
    <axis xyz="0 0 1"/>
    <parent link="/v1/RightThumbMedialPhalanx"/>
    <child link="/v1/RightThumbDistalPhalanx"/>
  </joint>
  <link name="/v1/RightPrimaryMetacarpal">
    <inertial>
      <mass value="0.006"/>
      <origin rpy="0 0 0" xyz="-0.0048 0 0"/>
      <inertia ixx="4.225e-07" ixy="0.0" ixz="0.0" iyy="6.625e-07" iyz="0.0" izz="6.01e-07"/>
    </inertial>
    <visual>
      <geometry>
        <mesh filename="package://V1/models/V1/meshes/2013_05_16/pf1.wrl"/>
        <!-- <box size="${width} ${height} ${depth}"/> -->
      </geometry>
      <origin rpy="0 0 0" xyz="0 0 0"/>
      <!-- <origin rpy="${origin_rpy}" xyz="${origin_xyz}"/> -->
      <material name="Gold"/>
    </visual>
    <collision>
      <geometry>
        <mesh filename="package://V1/models/V1/meshes/2013_05_16/pf1.wrl"/>
      </geometry>
      <origin rpy="0 0 0" xyz="0 0 0"/>
    </collision>
  </link>
  <gazebo reference="/v1/RightPrimaryMetacarpal">
    <material>Gazebo/Gold</material>
  </gazebo>
  <link name="/v1/RightPrimaryProximalPhalanx">
    <inertial>
      <mass value="0.018"/>
      <origin rpy="0 0 0" xyz="0.0175 0 0"/>
      <inertia ixx="1.203e-06" ixy="0.0" ixz="0.0" iyy="5.0355e-06" iyz="0.0" izz="4.9155e-06"/>
    </inertial>
    <visual>
      <geometry>
        <mesh filename="package://V1/models/V1/meshes/2013_05_16/pf2.wrl"/>
        <!-- <box size="${width} ${height} ${depth}"/> -->
      </geometry>
      <origin rpy="0 0 0" xyz="0 0 0"/>
      <!-- <origin rpy="${origin_rpy}" xyz="${origin_xyz}"/> -->
      <material name="Gold"/>
    </visual>
    <collision>
      <geometry>
        <mesh filename="package://V1/models/V1/meshes/2013_05_16/pf2.wrl"/>
      </geometry>
      <origin rpy="0 0 0" xyz="0 0 0"/>
    </collision>
  </link>
  <gazebo reference="/v1/RightPrimaryProximalPhalanx">
    <material>Gazebo/Gold</material>
  </gazebo>
  <link name="/v1/RightPrimaryMedialPhalanx">
    <inertial>
      <mass value="0.01"/>
      <origin rpy="0 0 0" xyz="0.0108 -0.0003 0"/>
      <inertia ixx="3.81666666667e-07" ixy="0.0" ixz="0.0" iyy="1.20416666667e-06" iyz="0.0" izz="1.10416666667e-06"/>
    </inertial>
    <visual>
      <geometry>
        <mesh filename="package://V1/models/V1/meshes/2013_05_16/pf3.wrl"/>
        <!-- <box size="${width} ${height} ${depth}"/> -->
      </geometry>
      <origin rpy="0 0 0" xyz="0 0 0"/>
      <!-- <origin rpy="${origin_rpy}" xyz="${origin_xyz}"/> -->
      <material name="Gold"/>
    </visual>
    <collision>
      <geometry>
        <mesh filename="package://V1/models/V1/meshes/2013_05_16/pf3.wrl"/>
      </geometry>
      <origin rpy="0 0 0" xyz="0 0 0"/>
    </collision>
  </link>
  <gazebo reference="/v1/RightPrimaryMedialPhalanx">
    <material>Gazebo/Gold</material>
  </gazebo>
  <link name="/v1/RightPrimaryDistalPhalanx">
    <inertial>
      <mass value="0.005"/>
      <origin rpy="0 0 0" xyz="0.00857 -0.000696 0"/>
      <inertia ixx="1.5375e-07" ixy="0.0" ixz="0.0" iyy="3.975e-07" iyz="0.0" izz="3.6375e-07"/>
    </inertial>
    <visual>
      <geometry>
        <mesh filename="package://V1/models/V1/meshes/2013_05_16/pf4.wrl"/>
        <!-- <box size="${width} ${height} ${depth}"/> -->
      </geometry>
      <origin rpy="0 0 0" xyz="0 0 0"/>
      <!-- <origin rpy="${origin_rpy}" xyz="${origin_xyz}"/> -->
      <material name="Gold"/>
    </visual>
    <collision>
      <geometry>
        <mesh filename="package://V1/models/V1/meshes/2013_05_16/pf4.wrl"/>
      </geometry>
      <origin rpy="0 0 0" xyz="0 0 0"/>
    </collision>
  </link>
  <gazebo reference="/v1/RightPrimaryDistalPhalanx">
    <material>Gazebo/Gold</material>
  </gazebo>
  <joint name="RightPrimaryMPYaw" type="fixed">
    <origin rpy="0.0 0 -0.366519143" xyz="0.0776738914821 -0.0298162134085 0.00254"/>
    <axis xyz="0 0 1"/>
    <parent link="right_palm"/>
    <child link="/v1/RightPrimaryMetacarpal"/>
  </joint>
  <joint name="RightPrimaryMPExtensor" type="fixed">
    <origin rpy="-1.57079632679 0 0.0568977336" xyz="0.0169724899301 0.000966739661347 0"/>
    <axis xyz="0 0 1"/>
    <parent link="/v1/RightPrimaryMetacarpal"/>
    <child link="/v1/RightPrimaryProximalPhalanx"/>
  </joint>
  <joint name="RightPrimaryPIPExtensor" type="fixed">
    <origin rpy="0 0 0" xyz="0.0381 0 0"/>
    <axis xyz="0 0 1"/>
    <parent link="/v1/RightPrimaryProximalPhalanx"/>
    <child link="/v1/RightPrimaryMedialPhalanx"/>
  </joint>
  <joint name="RightPrimaryDIPExtensor" type="fixed">
    <origin rpy="0 0 0" xyz="0.02286 0 0"/>
    <axis xyz="0 0 1"/>
    <parent link="/v1/RightPrimaryMedialPhalanx"/>
    <child link="/v1/RightPrimaryDistalPhalanx"/>
  </joint>
  <link name="r_hand_face">
    <inertial>
      <mass value="0.02"/>
      <origin rpy="0 0 0" xyz="0.017 0 0"/>
      <inertia ixx="1.72833333333e-06" ixy="0.0" ixz="0.0" iyy="5.98666666667e-06" iyz="0.0" izz="5.46166666667e-06"/>
    </inertial>
    <visual>
      <geometry>
        <mesh filename="package://V1/models/V1/meshes/2013_05_16/sf1.wrl"/>
        <!-- <box size="${width} ${height} ${depth}"/> -->
      </geometry>
      <origin rpy="0 0 0" xyz="0 0 0"/>
      <!-- <origin rpy="${origin_rpy}" xyz="${origin_xyz}"/> -->
      <material name="Gold"/>
    </visual>
    <collision>
      <geometry>
        <mesh filename="package://V1/models/V1/meshes/2013_05_16/sf1.wrl"/>
      </geometry>
      <origin rpy="0 0 0" xyz="0 0 0"/>
    </collision>
  </link>
  <gazebo reference="r_hand_face">
    <material>Gazebo/Gold</material>
  </gazebo>
  <link name="/v1/RightMiddleMedialPhalanx">
    <inertial>
      <mass value="0.011"/>
      <origin rpy="0 0 0" xyz="0.011 0 0"/>
      <inertia ixx="5.98583333333e-07" ixy="0.0" ixz="0.0" iyy="1.50333333333e-06" iyz="0.0" izz="1.21458333333e-06"/>
    </inertial>
    <visual>
      <geometry>
        <mesh filename="package://V1/models/V1/meshes/2013_05_16/sf2_ssf3.wrl"/>
        <!-- <box size="${width} ${height} ${depth}"/> -->
      </geometry>
      <origin rpy="0 0 0" xyz="0 0 0"/>
      <!-- <origin rpy="${origin_rpy}" xyz="${origin_xyz}"/> -->
      <material name="Gold"/>
    </visual>
    <collision>
      <geometry>
        <mesh filename="package://V1/models/V1/meshes/2013_05_16/sf2_ssf3.wrl"/>
      </geometry>
      <origin rpy="0 0 0" xyz="0 0 0"/>
    </collision>
  </link>
  <gazebo reference="/v1/RightMiddleMedialPhalanx">
    <material>Gazebo/Gold</material>
  </gazebo>
  <link name="/v1/RightMiddleDistalPhalanx">
    <inertial>
      <mass value="0.006"/>
      <origin rpy="0 0 0" xyz="0.0086 0 0"/>
      <inertia ixx="2.525e-07" ixy="0.0" ixz="0.0" iyy="5.45e-07" iyz="0.0" izz="4.365e-07"/>
    </inertial>
    <visual>
      <geometry>
        <mesh filename="package://V1/models/V1/meshes/2013_05_16/sf3_ssf4.wrl"/>
        <!-- <box size="${width} ${height} ${depth}"/> -->
      </geometry>
      <origin rpy="0 0 0" xyz="0 0 0"/>
      <!-- <origin rpy="${origin_rpy}" xyz="${origin_xyz}"/> -->
      <material name="Gold"/>
    </visual>
    <collision>
      <geometry>
        <mesh filename="package://V1/models/V1/meshes/2013_05_16/sf3_ssf4.wrl"/>
      </geometry>
      <origin rpy="0 0 0" xyz="0 0 0"/>
    </collision>
  </link>
  <gazebo reference="/v1/RightMiddleDistalPhalanx">
    <material>Gazebo/Gold</material>
  </gazebo>
  <joint name="RightMiddleMPExtensor" type="fixed">
    <origin rpy="-1.57079632679 0 0" xyz="0.09767 0 0.00254"/>
    <axis xyz="0 0 1"/>
    <parent link="right_palm"/>
    <child link="r_hand_face"/>
  </joint>
  <joint name="RightMiddlePIPExtensor" type="fixed">
    <origin rpy="0 0 0" xyz="0.0381 0 0"/>
    <axis xyz="0 0 1"/>
    <parent link="r_hand_face"/>
    <child link="/v1/RightMiddleMedialPhalanx"/>
  </joint>
  <joint name="RightMiddleDIPExtensor" type="fixed">
    <origin rpy="0 0 0" xyz="0.02286 0 0"/>
    <axis xyz="0 0 1"/>
    <parent link="/v1/RightMiddleMedialPhalanx"/>
    <child link="/v1/RightMiddleDistalPhalanx"/>
  </joint>
  <link name="r_hand_force_torque">
    <inertial>
      <mass value="0.047"/>
      <origin rpy="0 0 0" xyz="0 0 0"/>
      <inertia ixx="7.83333333333e-07" ixy="0.0" ixz="0.0" iyy="7.83333333333e-07" iyz="0.0" izz="7.83333333333e-07"/>
    </inertial>
    <visual>
      <geometry>
        <mesh filename="package://V1/models/V1/meshes/2013_05_16/ssf1_Right.wrl"/>
        <!-- <box size="${width} ${height} ${depth}"/> -->
      </geometry>
      <origin rpy="0 0 0" xyz="0 0 0"/>
      <!-- <origin rpy="${origin_rpy}" xyz="${origin_xyz}"/> -->
      <material name="Gold"/>
    </visual>
    <collision>
      <geometry>
        <mesh filename="package://V1/models/V1/meshes/2013_05_16/ssf1_Right.wrl"/>
      </geometry>
      <origin rpy="0 0 0" xyz="0 0 0"/>
    </collision>
  </link>
  <gazebo reference="r_hand_force_torque">
    <material>Gazebo/Gold</material>
  </gazebo>
  <link name="/v1/RightLittleProximalPhalanx">
    <inertial>
      <mass value="0.02"/>
      <origin rpy="0 0 0" xyz="0 0.017 0.050169"/>
      <inertia ixx="5.98666666667e-06" ixy="0.0" ixz="0.0" iyy="1.72833333333e-06" iyz="0.0" izz="5.46166666667e-06"/>
    </inertial>
    <visual>
      <geometry>
        <mesh filename="package://V1/models/V1/meshes/2013_05_16/ssf2_Right.wrl"/>
        <!-- <box size="${width} ${height} ${depth}"/> -->
      </geometry>
      <origin rpy="0 0 0" xyz="0 0 0"/>
      <!-- <origin rpy="${origin_rpy}" xyz="${origin_xyz}"/> -->
      <material name="Gold"/>
    </visual>
    <collision>
      <geometry>
        <mesh filename="package://V1/models/V1/meshes/2013_05_16/ssf2_Right.wrl"/>
      </geometry>
      <origin rpy="0 0 0" xyz="0 0 0"/>
    </collision>
  </link>
  <gazebo reference="/v1/RightLittleProximalPhalanx">
    <material>Gazebo/Gold</material>
  </gazebo>
  <link name="/v1/RightLittleMedialPhalanx">
    <inertial>
      <mass value="0.011"/>
      <origin rpy="0 0 0" xyz="0.011 0 0"/>
      <inertia ixx="5.98583333333e-07" ixy="0.0" ixz="0.0" iyy="1.50333333333e-06" iyz="0.0" izz="1.21458333333e-06"/>
    </inertial>
    <visual>
      <geometry>
        <mesh filename="package://V1/models/V1/meshes/2013_05_16/sf2_ssf3.wrl"/>
        <!-- <box size="${width} ${height} ${depth}"/> -->
      </geometry>
      <origin rpy="0 0 0" xyz="0 0 0"/>
      <!-- <origin rpy="${origin_rpy}" xyz="${origin_xyz}"/> -->
      <material name="Gold"/>
    </visual>
    <collision>
      <geometry>
        <mesh filename="package://V1/models/V1/meshes/2013_05_16/sf2_ssf3.wrl"/>
      </geometry>
      <origin rpy="0 0 0" xyz="0 0 0"/>
    </collision>
  </link>
  <gazebo reference="/v1/RightLittleMedialPhalanx">
    <material>Gazebo/Gold</material>
  </gazebo>
  <link name="/v1/RightLittleDistalPhalanx">
    <inertial>
      <mass value="0.006"/>
      <origin rpy="0 0 0" xyz="0.0086 0 0"/>
      <inertia ixx="2.525e-07" ixy="0.0" ixz="0.0" iyy="5.45e-07" iyz="0.0" izz="4.365e-07"/>
    </inertial>
    <visual>
      <geometry>
        <mesh filename="package://V1/models/V1/meshes/2013_05_16/sf3_ssf4.wrl"/>
        <!-- <box size="${width} ${height} ${depth}"/> -->
      </geometry>
      <origin rpy="0 0 0" xyz="0 0 0"/>
      <!-- <origin rpy="${origin_rpy}" xyz="${origin_xyz}"/> -->
      <material name="Gold"/>
    </visual>
    <collision>
      <geometry>
        <mesh filename="package://V1/models/V1/meshes/2013_05_16/sf3_ssf4.wrl"/>
      </geometry>
      <origin rpy="0 0 0" xyz="0 0 0"/>
    </collision>
  </link>
  <gazebo reference="/v1/RightLittleDistalPhalanx">
    <material>Gazebo/Gold</material>
  </gazebo>
  <joint name="RightLittleMPYaw" type="fixed">
    <origin rpy="-1.57079632679 0 0.690626785" xyz="0.0427072303336 0.0352928446888 -0.007747"/>
    <axis xyz="0 0 1"/>
    <parent link="right_palm"/>
    <child link="r_hand_force_torque"/>
  </joint>
  <joint name="RightLittleMPExtensor" type="fixed">
    <origin rpy="-0.690626785 0 -1.57079632679" xyz="0 -0.010287 -0.071327"/>
    <axis xyz="0 0 1"/>
    <parent link="r_hand_force_torque"/>
    <child link="/v1/RightLittleProximalPhalanx"/>
  </joint>
  <joint name="RightLittlePIPExtensor" type="fixed">
    <origin rpy="0 0 1.57079632679" xyz="0 0.0381 0.050169"/>
    <axis xyz="0 0 1"/>
    <parent link="/v1/RightLittleProximalPhalanx"/>
    <child link="/v1/RightLittleMedialPhalanx"/>
  </joint>
  <joint name="RightLittleDIPExtensor" type="fixed">
    <origin rpy="0 0 0" xyz="0.02286 0 0"/>
    <axis xyz="0 0 1"/>
    <parent link="/v1/RightLittleMedialPhalanx"/>
    <child link="/v1/RightLittleDistalPhalanx"/>
  </joint>
  <link name="l_clav">
    <inertial>
      <mass value="2.45"/>
      <origin rpy="0 0 0" xyz="0 -0.01204 0.251"/>
      <inertia ixx="0.0126828333333" ixy="0.0" ixz="0.0" iyy="0.00971016666667" iyz="0.0" izz="0.0136889666667"/>
    </inertial>
    <visual>
      <geometry>
        <mesh filename="package://V1/models/V1/meshes/2013_05_16/aj1_Left.wrl"/>
        <!-- <box size="${width} ${height} ${depth}"/> -->
      </geometry>
      <origin rpy="0 0 0" xyz="0 0 0"/>
      <!-- <origin rpy="${origin_rpy}" xyz="${origin_xyz}"/> -->
      <material name="Gold"/>
    </visual>
    <collision>
      <geometry>
        <mesh filename="package://V1/models/V1/meshes/2013_05_16/aj1_Left.wrl"/>
      </geometry>
      <origin rpy="0 0 0" xyz="0 0 0"/>
    </collision>
  </link>
  <gazebo reference="l_clav">
    <material>Gazebo/Gold</material>
  </gazebo>
  <link name="l_scap">
    <inertial>
      <mass value="3.67"/>
      <origin rpy="0 0 0" xyz="0.044 -0.0034 0"/>
      <inertia ixx="0.0115718158333" ixy="0.0" ixz="0.0" iyy="0.0166486491667" iyz="0.0" izz="0.0172373783333"/>
    </inertial>
    <visual>
      <geometry>
        <mesh filename="package://V1/models/V1/meshes/2013_05_16/aj2.wrl"/>
        <!-- <box size="${width} ${height} ${depth}"/> -->
      </geometry>
      <origin rpy="0 0 0" xyz="0 0 0"/>
      <!-- <origin rpy="${origin_rpy}" xyz="${origin_xyz}"/> -->
      <material name="White"/>
    </visual>
    <collision>
      <geometry>
        <mesh filename="package://V1/models/V1/meshes/2013_05_16/aj2.wrl"/>
      </geometry>
      <origin rpy="0 0 0" xyz="0 0 0"/>
    </collision>
  </link>
  <gazebo reference="l_scap">
    <material>Gazebo/White</material>
  </gazebo>
  <link name="l_uarm">
    <inertial>
      <mass value="2.575"/>
      <origin rpy="0 0 0" xyz="0 -0.006 0.236"/>
      <inertia ixx="0.0227863895833" ixy="0.0" ixz="0.0" iyy="0.0213984645833" iyz="0.0" izz="0.00932579166667"/>
    </inertial>
    <visual>
      <geometry>
        <mesh filename="package://V1/models/V1/meshes/2013_05_16/aj3_Left.wrl"/>
        <!-- <box size="${width} ${height} ${depth}"/> -->
      </geometry>
      <origin rpy="0 0 0" xyz="0 0 0"/>
      <!-- <origin rpy="${origin_rpy}" xyz="${origin_xyz}"/> -->
      <material name="White"/>
    </visual>
    <collision>
      <geometry>
        <mesh filename="package://V1/models/V1/meshes/2013_05_16/aj3_Left.wrl"/>
      </geometry>
      <origin rpy="0 0 0" xyz="0 0 0"/>
    </collision>
  </link>
  <gazebo reference="l_uarm">
    <material>Gazebo/White</material>
  </gazebo>
  <link name="l_larm">
    <inertial>
      <mass value="1.367"/>
      <origin rpy="0 0 0" xyz="0.0270 0.0302 0"/>
      <inertia ixx="0.004941705" ixy="0.0" ixz="0.0" iyy="0.00469849291667" iyz="0.0" izz="0.00530133991667"/>
    </inertial>
    <visual>
      <geometry>
        <mesh filename="package://V1/models/V1/meshes/2013_05_16/aj4.wrl"/>
        <!-- <box size="${width} ${height} ${depth}"/> -->
      </geometry>
      <origin rpy="0 0 0" xyz="0 0 0"/>
      <!-- <origin rpy="${origin_rpy}" xyz="${origin_xyz}"/> -->
      <material name="Gold"/>
    </visual>
    <collision>
      <geometry>
        <mesh filename="package://V1/models/V1/meshes/2013_05_16/aj4.wrl"/>
      </geometry>
      <origin rpy="0 0 0" xyz="0 0 0"/>
    </collision>
  </link>
  <gazebo reference="l_larm">
    <material>Gazebo/Gold</material>
  </gazebo>
  <joint name="l_arm_usy" type="revolute">
    <origin rpy="1.57079632679 0 0" xyz="0.29842 0 -0.03157"/>
    <axis xyz="0 0 1"/>
    <parent link="utorso"/>
    <child link="l_clav"/>
    <limit effort="190" lower="-3.1415926518" upper="3.1415926518" velocity="5.89"/>
    <controller_gains Kd="400" Kp="20000"/>
    <dynamics damping="1.0" friction="0.0"/>
  </joint>
  <gazebo reference="l_arm_usy">
    <provideFeedback>1</provideFeedback>
  </gazebo>
  <joint name="l_arm_shx" type="revolute">
    <origin rpy="-1.57079632679 0 3.14159265359" xyz="0 0 0.246"/>
    <axis xyz="0 0 1"/>
    <parent link="l_clav"/>
    <child link="l_scap"/>
    <limit effort="190" lower="-3.05432618925" upper="-0.1745329251" velocity="5.89"/>
    <controller_gains Kd="400" Kp="20000"/>
    <dynamics damping="1.0" friction="0.0"/>
  </joint>
  <gazebo reference="l_arm_shx">
    <provideFeedback>1</provideFeedback>
  </gazebo>
  <joint name="l_arm_ely" type="revolute">
    <origin rpy="-1.57079632679 0 -1.57079632679" xyz="0 0 0"/>
    <axis xyz="0 0 1"/>
    <parent link="l_scap"/>
    <child link="l_uarm"/>
    <limit effort="65" lower="-1.5707963259" upper="1.5707963259" velocity="11.5"/>
    <controller_gains Kd="400" Kp="20000"/>
    <dynamics damping="1.0" friction="0.0"/>
  </joint>
  <gazebo reference="l_arm_ely">
    <provideFeedback>1</provideFeedback>
  </gazebo>
  <joint name="l_arm_elx" type="revolute">
    <origin rpy="-1.57079632679 0 -1.57079632679" xyz="0 0.0254 0.33"/>
    <axis xyz="0 0 1"/>
    <parent link="l_uarm"/>
    <child link="l_larm"/>
    <limit effort="65" lower="-1.9198621761" upper="-0.08726646255" velocity="11.5"/>
    <controller_gains Kd="400" Kp="20000"/>
    <dynamics damping="1.0" friction="0.0"/>
  </joint>
  <gazebo reference="l_arm_elx">
    <provideFeedback>1</provideFeedback>
  </gazebo>
  <link name="l_farm">
    <inertial>
      <mass value="2.703"/>
      <origin rpy="0 0 0" xyz="0 -0.0006 0.12"/>
      <inertia ixx="0.01633175125" ixy="0.0" ixz="0.0" iyy="0.0169338445" iyz="0.0" izz="0.00666402125"/>
    </inertial>
    <visual>
      <geometry>
        <mesh filename="package://V1/models/V1/meshes/2013_05_16/aj5_Left.wrl"/>
        <!-- <box size="${width} ${height} ${depth}"/> -->
      </geometry>
      <origin rpy="0 0 0" xyz="0 0 0"/>
      <!-- <origin rpy="${origin_rpy}" xyz="${origin_xyz}"/> -->
      <material name="White"/>
    </visual>
    <collision>
      <geometry>
        <mesh filename="package://V1/models/V1/meshes/2013_05_16/aj5_Left.wrl"/>
      </geometry>
      <origin rpy="0 0 0" xyz="0 0 0"/>
    </collision>
  </link>
  <gazebo reference="l_farm">
    <material>Gazebo/White</material>
  </gazebo>
  <link name="l_hand">
    <inertial>
      <mass value="0.1"/>
      <origin rpy="0 0 0" xyz="0 0 0"/>
      <inertia ixx="2.25083333333e-05" ixy="0.0" ixz="0.0" iyy="2.9175e-05" iyz="0.0" izz="8.33333333333e-06"/>
    </inertial>
    <visual>
      <geometry>
        <box size="0.03 0.01 0.051"/>
      </geometry>
      <origin rpy="0 0 0" xyz="0 0 0"/>
      <material name="Gray"/>
    </visual>
    <collision>
      <geometry>
        <box size="0.03 0.01 0.051"/>
      </geometry>
      <origin rpy="0 0 0" xyz="0 0 0"/>
    </collision>
  </link>
  <link name="left_palm">
    <inertial>
      <mass value="0.712"/>
      <origin rpy="0 0 0" xyz="0.0425 0 0"/>
      <inertia ixx="0.000679010666667" ixy="0.0" ixz="0.0" iyy="0.000514360666667" iyz="0.0" izz="0.00102201666667"/>
    </inertial>
    <visual>
      <geometry>
        <mesh filename="package://V1/models/V1/meshes/2013_05_16/palm_Left.wrl"/>
        <!-- <box size="${width} ${height} ${depth}"/> -->
      </geometry>
      <origin rpy="0 0 0" xyz="0 0 0"/>
      <!-- <origin rpy="${origin_rpy}" xyz="${origin_xyz}"/> -->
      <material name="Gold"/>
    </visual>
    <collision>
      <geometry>
        <mesh filename="package://V1/models/V1/meshes/2013_05_16/palm_Left.wrl"/>
      </geometry>
      <origin rpy="0 0 0" xyz="0 0 0"/>
    </collision>
  </link>
  <gazebo reference="left_palm">
    <material>Gazebo/Gold</material>
  </gazebo>
  <joint name="l_arm_uwy" type="revolute">
    <origin rpy="-1.57079632679 0 3.14159265359" xyz="0.0254 0 0"/>
    <axis xyz="0 0 1"/>
    <parent link="l_larm"/>
    <child link="l_farm"/>
    <limit effort="26" lower="-2.35619448885" upper="2.35619448885" velocity="5"/>
    <controller_gains Kd="0" Kp="20000"/>
    <dynamics damping="1.0" friction="0.0"/>
  </joint>
  <gazebo reference="l_arm_uwy">
    <provideFeedback>1</provideFeedback>
  </gazebo>
  <joint name="l_arm_mwx" type="revolute">
    <origin rpy="-1.57079632679 0 -1.57079632679" xyz="0 0 0.287"/>
    <axis xyz="0 0 1"/>
    <parent link="l_farm"/>
    <child link="l_hand"/>
    <limit effort="14" lower="-0.8726646255" upper="0.6981317004" velocity="1"/>
    <controller_gains Kd="400" Kp="20000"/>
    <dynamics damping="1.0" friction="0.0"/>
  </joint>
  <gazebo reference="l_arm_mwx">
    <provideFeedback>1</provideFeedback>
  </gazebo>
  <joint name="l_arm_lwz" type="revolute">
    <origin rpy="-1.57079632679 0 -1.57079632679" xyz="0 0 0"/>
    <axis xyz="0 0 1"/>
    <parent link="l_hand"/>
    <child link="left_palm"/>
    <limit effort="14" lower="-0.5235987753" upper="0.43633231275" velocity="1"/>
    <controller_gains Kd="400" Kp="20000"/>
    <dynamics damping="1.0" friction="0.0"/>
  </joint>
  <gazebo reference="l_arm_lwz">
    <provideFeedback>1</provideFeedback>
  </gazebo>
  <actuator name="/trunk/laj1" type="turbodriver_api/TurbodriverAPI_DRCv4"/>
  <actuator name="/left_arm/j2" type="turbodriver_api/TurbodriverAPI_DRCv4"/>
  <actuator name="/left_arm/j3" type="turbodriver_api/TurbodriverAPI_DRCv4"/>
  <actuator name="/left_arm/j4" type="turbodriver_api/TurbodriverAPI_DRCv4"/>
  <actuator name="/left_arm/j5" type="turbodriver_api/TurbodriverAPI_DRCv3"/>
  <actuator name="/left_arm/forearm_driver1/wrist_left" type="forearm_api/WristAPI_DRCv1"/>
  <actuator name="/left_arm/forearm_driver1/wrist_right" type="forearm_api/WristAPI_DRCv1"/>
  <mode name="LeftShoulderExtensorMode" type="mode_plugins/ModeInterface">
    <translator name="LeftShoulderExtensorModeData" type="SimpleActuatorToJointMode">
      <joint data="mode" name="l_arm_usy"/>
      <actuator data="mode" name="/trunk/laj1"/>
    </translator>
    <translator name="LeftShoulderExtensorModeCommand" type="SimpleJointToActuatorMode">
      <joint data="modeCommand" name="l_arm_usy"/>
      <actuator data="modeCommand" name="/trunk/laj1"/>
    </translator>
  </mode>
  <mode name="LeftShoulderAdductorMode" type="mode_plugins/ModeInterface">
    <translator name="LeftShoulderAdductorModeData" type="SimpleActuatorToJointMode">
      <joint data="mode" name="l_arm_shx"/>
      <actuator data="mode" name="/left_arm/j2"/>
    </translator>
    <translator name="LeftShoulderAdductorModeCommand" type="SimpleJointToActuatorMode">
      <joint data="modeCommand" name="l_arm_shx"/>
      <actuator data="modeCommand" name="/left_arm/j2"/>
    </translator>
  </mode>
  <mode name="LeftShoulderSupinatorMode" type="mode_plugins/ModeInterface">
    <translator name="LeftShoulderSupinatorModeData" type="SimpleActuatorToJointMode">
      <joint data="mode" name="l_arm_ely"/>
      <actuator data="mode" name="/left_arm/j3"/>
    </translator>
    <translator name="LeftShoulderSupinatorModeCommand" type="SimpleJointToActuatorMode">
      <joint data="modeCommand" name="l_arm_ely"/>
      <actuator data="modeCommand" name="/left_arm/j3"/>
    </translator>
  </mode>
  <mode name="LeftElbowExtensorMode" type="mode_plugins/ModeInterface">
    <translator name="LeftElbowExtensorModeData" type="SimpleActuatorToJointMode">
      <joint data="mode" name="l_arm_elx"/>
      <actuator data="mode" name="/left_arm/j4"/>
    </translator>
    <translator name="LeftElbowExtensorModeCommand" type="SimpleJointToActuatorMode">
      <joint data="modeCommand" name="l_arm_elx"/>
      <actuator data="modeCommand" name="/left_arm/j4"/>
    </translator>
  </mode>
  <mode name="LeftForearmSupinatorMode" type="mode_plugins/ModeInterface">
    <translator name="LeftForearmSupinatorModeData" type="SimpleActuatorToJointMode">
      <joint data="mode" name="l_arm_uwy"/>
      <actuator data="mode" name="/left_arm/j5"/>
    </translator>
    <translator name="LeftForearmSupinatorModeCommand" type="SimpleJointToActuatorMode">
      <joint data="modeCommand" name="l_arm_uwy"/>
      <actuator data="modeCommand" name="/left_arm/j5"/>
    </translator>
  </mode>
  <mode name="LeftWristExtensorMode" type="mode_plugins/ModeInterface">
    <translator name="LeftWristExtensorModeData" type="SimpleActuatorToJointMode">
      <joint data="mode" name="l_arm_mwx"/>
      <actuator data="mode" name="/left_arm/forearm_driver1/wrist_left"/>
    </translator>
    <translator name="LeftWristExtensorModeCommand" type="SimpleJointToActuatorMode">
      <joint data="modeCommand" name="l_arm_mwx"/>
      <actuator data="modeCommand" name="/left_arm/forearm_driver1/wrist_left"/>
    </translator>
  </mode>
  <mode name="LeftWristMode" type="mode_plugins/ModeInterface">
    <translator name="LeftWristModeData" type="SimpleActuatorToJointMode">
      <joint data="mode" name="l_arm_lwz"/>
      <actuator data="mode" name="/left_arm/forearm_driver1/wrist_right"/>
    </translator>
    <translator name="LeftWristModeCommand" type="SimpleJointToActuatorMode">
      <joint data="modeCommand" name="l_arm_lwz"/>
      <actuator data="modeCommand" name="/left_arm/forearm_driver1/wrist_right"/>
    </translator>
  </mode>
  <link name="/v1/LeftThumbMetacarpal">
    <inertial>
      <mass value="0.017"/>
      <origin rpy="0 0 0" xyz="0 0 0"/>
      <inertia ixx="2.83333333333e-07" ixy="0.0" ixz="0.0" iyy="2.83333333333e-07" iyz="0.0" izz="2.83333333333e-07"/>
    </inertial>
    <visual>
      <geometry>
        <mesh filename="package://V1/models/V1/meshes/2013_05_16/tf1_Left.wrl"/>
        <!-- <box size="${width} ${height} ${depth}"/> -->
      </geometry>
      <origin rpy="0 0 0" xyz="0 0 0"/>
      <!-- <origin rpy="${origin_rpy}" xyz="${origin_xyz}"/> -->
      <material name="Gold"/>
    </visual>
    <collision>
      <geometry>
        <mesh filename="package://V1/models/V1/meshes/2013_05_16/tf1_Left.wrl"/>
      </geometry>
      <origin rpy="0 0 0" xyz="0 0 0"/>
    </collision>
  </link>
  <gazebo reference="/v1/LeftThumbMetacarpal">
    <material>Gazebo/Gold</material>
  </gazebo>
  <link name="/v1/LeftThumbProximalPhalanx">
    <inertial>
      <mass value="0.02"/>
      <origin rpy="0 0 0" xyz="0.017 0 0"/>
      <inertia ixx="1.72833333333e-06" ixy="0.0" ixz="0.0" iyy="5.98666666667e-06" iyz="0.0" izz="5.46166666667e-06"/>
    </inertial>
    <visual>
      <geometry>
        <mesh filename="package://V1/models/V1/meshes/2013_05_16/tf2.wrl"/>
        <!-- <box size="${width} ${height} ${depth}"/> -->
      </geometry>
      <origin rpy="0 0 0" xyz="0 0 0"/>
      <!-- <origin rpy="${origin_rpy}" xyz="${origin_xyz}"/> -->
      <material name="Gold"/>
    </visual>
    <collision>
      <geometry>
        <mesh filename="package://V1/models/V1/meshes/2013_05_16/tf2.wrl"/>
      </geometry>
      <origin rpy="0 0 0" xyz="0 0 0"/>
    </collision>
  </link>
  <gazebo reference="/v1/LeftThumbProximalPhalanx">
    <material>Gazebo/Gold</material>
  </gazebo>
  <link name="/v1/LeftThumbMedialPhalanx">
    <inertial>
      <mass value="0.013"/>
      <origin rpy="0 0 0" xyz="0.011 0 0"/>
      <inertia ixx="7.07416666667e-07" ixy="0.0" ixz="0.0" iyy="1.77666666667e-06" iyz="0.0" izz="1.43541666667e-06"/>
    </inertial>
    <visual>
      <geometry>
        <mesh filename="package://V1/models/V1/meshes/2013_05_16/tf3.wrl"/>
        <!-- <box size="${width} ${height} ${depth}"/> -->
      </geometry>
      <origin rpy="0 0 0" xyz="0 0 0"/>
      <!-- <origin rpy="${origin_rpy}" xyz="${origin_xyz}"/> -->
      <material name="Gold"/>
    </visual>
    <collision>
      <geometry>
        <mesh filename="package://V1/models/V1/meshes/2013_05_16/tf3.wrl"/>
      </geometry>
      <origin rpy="0 0 0" xyz="0 0 0"/>
    </collision>
  </link>
  <gazebo reference="/v1/LeftThumbMedialPhalanx">
    <material>Gazebo/Gold</material>
  </gazebo>
  <link name="/v1/LeftThumbDistalPhalanx">
    <inertial>
      <mass value="0.006"/>
      <origin rpy="0 0 0" xyz="0.0086 0 0"/>
      <inertia ixx="2.525e-07" ixy="0.0" ixz="0.0" iyy="5.45e-07" iyz="0.0" izz="4.365e-07"/>
    </inertial>
    <visual>
      <geometry>
        <mesh filename="package://V1/models/V1/meshes/2013_05_16/tf4.wrl"/>
        <!-- <box size="${width} ${height} ${depth}"/> -->
      </geometry>
      <origin rpy="0 0 0" xyz="0 0 0"/>
      <!-- <origin rpy="${origin_rpy}" xyz="${origin_xyz}"/> -->
      <material name="Gold"/>
    </visual>
    <collision>
      <geometry>
        <mesh filename="package://V1/models/V1/meshes/2013_05_16/tf4.wrl"/>
      </geometry>
      <origin rpy="0 0 0" xyz="0 0 0"/>
    </collision>
  </link>
  <gazebo reference="/v1/LeftThumbDistalPhalanx">
    <material>Gazebo/Gold</material>
  </gazebo>
  <joint name="LeftThumbMPYaw" type="fixed">
    <origin rpy="-1.57079632679 0 -1.34390352" xyz="0.00748367180673 -0.0324153432851 -0.005182"/>
    <axis xyz="0 0 1"/>
    <parent link="left_palm"/>
    <child link="/v1/LeftThumbMetacarpal"/>
  </joint>
  <joint name="LeftThumbMPExtensor" type="fixed">
    <origin rpy="-1.57079632679 0 0" xyz="0.02286 0 0.025091"/>
    <axis xyz="0 0 1"/>
    <parent link="/v1/LeftThumbMetacarpal"/>
    <child link="/v1/LeftThumbProximalPhalanx"/>
  </joint>
  <joint name="LeftThumbPIPExtensor" type="fixed">
    <origin rpy="0 0 0" xyz="0.0381 0 0"/>
    <axis xyz="0 0 1"/>
    <parent link="/v1/LeftThumbProximalPhalanx"/>
    <child link="/v1/LeftThumbMedialPhalanx"/>
  </joint>
  <joint name="LeftThumbDIPExtensor" type="fixed">
    <origin rpy="0 0 0" xyz="0.02794 0 0"/>
    <axis xyz="0 0 1"/>
    <parent link="/v1/LeftThumbMedialPhalanx"/>
    <child link="/v1/LeftThumbDistalPhalanx"/>
  </joint>
  <link name="/v1/LeftPrimaryMetacarpal">
    <inertial>
      <mass value="0.006"/>
      <origin rpy="0 0 0" xyz="-0.0048 0 0"/>
      <inertia ixx="4.225e-07" ixy="0.0" ixz="0.0" iyy="6.625e-07" iyz="0.0" izz="6.01e-07"/>
    </inertial>
    <visual>
      <geometry>
        <mesh filename="package://V1/models/V1/meshes/2013_05_16/pf1.wrl"/>
        <!-- <box size="${width} ${height} ${depth}"/> -->
      </geometry>
      <origin rpy="0 0 0" xyz="0 0 0"/>
      <!-- <origin rpy="${origin_rpy}" xyz="${origin_xyz}"/> -->
      <material name="Gold"/>
    </visual>
    <collision>
      <geometry>
        <mesh filename="package://V1/models/V1/meshes/2013_05_16/pf1.wrl"/>
      </geometry>
      <origin rpy="0 0 0" xyz="0 0 0"/>
    </collision>
  </link>
  <gazebo reference="/v1/LeftPrimaryMetacarpal">
    <material>Gazebo/Gold</material>
  </gazebo>
  <link name="/v1/LeftPrimaryProximalPhalanx">
    <inertial>
      <mass value="0.018"/>
      <origin rpy="0 0 0" xyz="0.0175 0 0"/>
      <inertia ixx="1.203e-06" ixy="0.0" ixz="0.0" iyy="5.0355e-06" iyz="0.0" izz="4.9155e-06"/>
    </inertial>
    <visual>
      <geometry>
        <mesh filename="package://V1/models/V1/meshes/2013_05_16/pf2.wrl"/>
        <!-- <box size="${width} ${height} ${depth}"/> -->
      </geometry>
      <origin rpy="0 0 0" xyz="0 0 0"/>
      <!-- <origin rpy="${origin_rpy}" xyz="${origin_xyz}"/> -->
      <material name="Gold"/>
    </visual>
    <collision>
      <geometry>
        <mesh filename="package://V1/models/V1/meshes/2013_05_16/pf2.wrl"/>
      </geometry>
      <origin rpy="0 0 0" xyz="0 0 0"/>
    </collision>
  </link>
  <gazebo reference="/v1/LeftPrimaryProximalPhalanx">
    <material>Gazebo/Gold</material>
  </gazebo>
  <link name="/v1/LeftPrimaryMedialPhalanx">
    <inertial>
      <mass value="0.01"/>
      <origin rpy="0 0 0" xyz="0.0108 -0.0003 0"/>
      <inertia ixx="3.81666666667e-07" ixy="0.0" ixz="0.0" iyy="1.20416666667e-06" iyz="0.0" izz="1.10416666667e-06"/>
    </inertial>
    <visual>
      <geometry>
        <mesh filename="package://V1/models/V1/meshes/2013_05_16/pf3.wrl"/>
        <!-- <box size="${width} ${height} ${depth}"/> -->
      </geometry>
      <origin rpy="0 0 0" xyz="0 0 0"/>
      <!-- <origin rpy="${origin_rpy}" xyz="${origin_xyz}"/> -->
      <material name="Gold"/>
    </visual>
    <collision>
      <geometry>
        <mesh filename="package://V1/models/V1/meshes/2013_05_16/pf3.wrl"/>
      </geometry>
      <origin rpy="0 0 0" xyz="0 0 0"/>
    </collision>
  </link>
  <gazebo reference="/v1/LeftPrimaryMedialPhalanx">
    <material>Gazebo/Gold</material>
  </gazebo>
  <link name="/v1/LeftPrimaryDistalPhalanx">
    <inertial>
      <mass value="0.005"/>
      <origin rpy="0 0 0" xyz="0.00857 -0.000696 0"/>
      <inertia ixx="1.5375e-07" ixy="0.0" ixz="0.0" iyy="3.975e-07" iyz="0.0" izz="3.6375e-07"/>
    </inertial>
    <visual>
      <geometry>
        <mesh filename="package://V1/models/V1/meshes/2013_05_16/pf4.wrl"/>
        <!-- <box size="${width} ${height} ${depth}"/> -->
      </geometry>
      <origin rpy="0 0 0" xyz="0 0 0"/>
      <!-- <origin rpy="${origin_rpy}" xyz="${origin_xyz}"/> -->
      <material name="Gold"/>
    </visual>
    <collision>
      <geometry>
        <mesh filename="package://V1/models/V1/meshes/2013_05_16/pf4.wrl"/>
      </geometry>
      <origin rpy="0 0 0" xyz="0 0 0"/>
    </collision>
  </link>
  <gazebo reference="/v1/LeftPrimaryDistalPhalanx">
    <material>Gazebo/Gold</material>
  </gazebo>
  <joint name="LeftPrimaryMPYaw" type="fixed">
    <origin rpy="-3.14159265359 0 -0.366519143" xyz="0.0776738914821 -0.0298162134085 -0.00254"/>
    <axis xyz="0 0 1"/>
    <parent link="left_palm"/>
    <child link="/v1/LeftPrimaryMetacarpal"/>
  </joint>
  <joint name="LeftPrimaryMPExtensor" type="fixed">
    <origin rpy="-1.57079632679 0 0.0568977336" xyz="0.0169724899301 0.000966739661347 0"/>
    <axis xyz="0 0 1"/>
    <parent link="/v1/LeftPrimaryMetacarpal"/>
    <child link="/v1/LeftPrimaryProximalPhalanx"/>
  </joint>
  <joint name="LeftPrimaryPIPExtensor" type="fixed">
    <origin rpy="0 0 0" xyz="0.0381 0 0"/>
    <axis xyz="0 0 1"/>
    <parent link="/v1/LeftPrimaryProximalPhalanx"/>
    <child link="/v1/LeftPrimaryMedialPhalanx"/>
  </joint>
  <joint name="LeftPrimaryDIPExtensor" type="fixed">
    <origin rpy="0 0 0" xyz="0.02286 0 0"/>
    <axis xyz="0 0 1"/>
    <parent link="/v1/LeftPrimaryMedialPhalanx"/>
    <child link="/v1/LeftPrimaryDistalPhalanx"/>
  </joint>
  <link name="l_hand_face">
    <inertial>
      <mass value="0.02"/>
      <origin rpy="0 0 0" xyz="0.017 0 0"/>
      <inertia ixx="1.72833333333e-06" ixy="0.0" ixz="0.0" iyy="5.98666666667e-06" iyz="0.0" izz="5.46166666667e-06"/>
    </inertial>
    <visual>
      <geometry>
        <mesh filename="package://V1/models/V1/meshes/2013_05_16/sf1.wrl"/>
        <!-- <box size="${width} ${height} ${depth}"/> -->
      </geometry>
      <origin rpy="0 0 0" xyz="0 0 0"/>
      <!-- <origin rpy="${origin_rpy}" xyz="${origin_xyz}"/> -->
      <material name="Gold"/>
    </visual>
    <collision>
      <geometry>
        <mesh filename="package://V1/models/V1/meshes/2013_05_16/sf1.wrl"/>
      </geometry>
      <origin rpy="0 0 0" xyz="0 0 0"/>
    </collision>
  </link>
  <gazebo reference="l_hand_face">
    <material>Gazebo/Gold</material>
  </gazebo>
  <link name="/v1/LeftMiddleMedialPhalanx">
    <inertial>
      <mass value="0.011"/>
      <origin rpy="0 0 0" xyz="0.011 0 0"/>
      <inertia ixx="5.98583333333e-07" ixy="0.0" ixz="0.0" iyy="1.50333333333e-06" iyz="0.0" izz="1.21458333333e-06"/>
    </inertial>
    <visual>
      <geometry>
        <mesh filename="package://V1/models/V1/meshes/2013_05_16/sf2_ssf3.wrl"/>
        <!-- <box size="${width} ${height} ${depth}"/> -->
      </geometry>
      <origin rpy="0 0 0" xyz="0 0 0"/>
      <!-- <origin rpy="${origin_rpy}" xyz="${origin_xyz}"/> -->
      <material name="Gold"/>
    </visual>
    <collision>
      <geometry>
        <mesh filename="package://V1/models/V1/meshes/2013_05_16/sf2_ssf3.wrl"/>
      </geometry>
      <origin rpy="0 0 0" xyz="0 0 0"/>
    </collision>
  </link>
  <gazebo reference="/v1/LeftMiddleMedialPhalanx">
    <material>Gazebo/Gold</material>
  </gazebo>
  <link name="/v1/LeftMiddleDistalPhalanx">
    <inertial>
      <mass value="0.006"/>
      <origin rpy="0 0 0" xyz="0.0086 0 0"/>
      <inertia ixx="2.525e-07" ixy="0.0" ixz="0.0" iyy="5.45e-07" iyz="0.0" izz="4.365e-07"/>
    </inertial>
    <visual>
      <geometry>
        <mesh filename="package://V1/models/V1/meshes/2013_05_16/sf3_ssf4.wrl"/>
        <!-- <box size="${width} ${height} ${depth}"/> -->
      </geometry>
      <origin rpy="0 0 0" xyz="0 0 0"/>
      <!-- <origin rpy="${origin_rpy}" xyz="${origin_xyz}"/> -->
      <material name="Gold"/>
    </visual>
    <collision>
      <geometry>
        <mesh filename="package://V1/models/V1/meshes/2013_05_16/sf3_ssf4.wrl"/>
      </geometry>
      <origin rpy="0 0 0" xyz="0 0 0"/>
    </collision>
  </link>
  <gazebo reference="/v1/LeftMiddleDistalPhalanx">
    <material>Gazebo/Gold</material>
  </gazebo>
  <joint name="LeftMiddleMPExtensor" type="fixed">
    <origin rpy="1.57079632679 0 0" xyz="0.09767 0 -0.00254"/>
    <axis xyz="0 0 1"/>
    <parent link="left_palm"/>
    <child link="l_hand_face"/>
  </joint>
  <joint name="LeftMiddlePIPExtensor" type="fixed">
    <origin rpy="0 0 0" xyz="0.0381 0 0"/>
    <axis xyz="0 0 1"/>
    <parent link="l_hand_face"/>
    <child link="/v1/LeftMiddleMedialPhalanx"/>
  </joint>
  <joint name="LeftMiddleDIPExtensor" type="fixed">
    <origin rpy="0 0 0" xyz="0.02286 0 0"/>
    <axis xyz="0 0 1"/>
    <parent link="/v1/LeftMiddleMedialPhalanx"/>
    <child link="/v1/LeftMiddleDistalPhalanx"/>
  </joint>
  <link name="l_hand_force_torque">
    <inertial>
      <mass value="0.047"/>
      <origin rpy="0 0 0" xyz="0 0 0"/>
      <inertia ixx="7.83333333333e-07" ixy="0.0" ixz="0.0" iyy="7.83333333333e-07" iyz="0.0" izz="7.83333333333e-07"/>
    </inertial>
    <visual>
      <geometry>
        <mesh filename="package://V1/models/V1/meshes/2013_05_16/ssf1_Left.wrl"/>
        <!-- <box size="${width} ${height} ${depth}"/> -->
      </geometry>
      <origin rpy="0 0 0" xyz="0 0 0"/>
      <!-- <origin rpy="${origin_rpy}" xyz="${origin_xyz}"/> -->
      <material name="Gold"/>
    </visual>
    <collision>
      <geometry>
        <mesh filename="package://V1/models/V1/meshes/2013_05_16/ssf1_Left.wrl"/>
      </geometry>
      <origin rpy="0 0 0" xyz="0 0 0"/>
    </collision>
  </link>
  <gazebo reference="l_hand_force_torque">
    <material>Gazebo/Gold</material>
  </gazebo>
  <link name="/v1/LeftLittleProximalPhalanx">
    <inertial>
      <mass value="0.02"/>
      <origin rpy="0 0 0" xyz="0 -0.017 -0.050169"/>
      <inertia ixx="5.98666666667e-06" ixy="0.0" ixz="0.0" iyy="1.72833333333e-06" iyz="0.0" izz="5.46166666667e-06"/>
    </inertial>
    <visual>
      <geometry>
        <mesh filename="package://V1/models/V1/meshes/2013_05_16/ssf2_Left.wrl"/>
        <!-- <box size="${width} ${height} ${depth}"/> -->
      </geometry>
      <origin rpy="0 0 0" xyz="0 0 0"/>
      <!-- <origin rpy="${origin_rpy}" xyz="${origin_xyz}"/> -->
      <material name="Gold"/>
    </visual>
    <collision>
      <geometry>
        <mesh filename="package://V1/models/V1/meshes/2013_05_16/ssf2_Left.wrl"/>
      </geometry>
      <origin rpy="0 0 0" xyz="0 0 0"/>
    </collision>
  </link>
  <gazebo reference="/v1/LeftLittleProximalPhalanx">
    <material>Gazebo/Gold</material>
  </gazebo>
  <link name="/v1/LeftLittleMedialPhalanx">
    <inertial>
      <mass value="0.011"/>
      <origin rpy="0 0 0" xyz="0.011 0 0"/>
      <inertia ixx="5.98583333333e-07" ixy="0.0" ixz="0.0" iyy="1.50333333333e-06" iyz="0.0" izz="1.21458333333e-06"/>
    </inertial>
    <visual>
      <geometry>
        <mesh filename="package://V1/models/V1/meshes/2013_05_16/sf2_ssf3.wrl"/>
        <!-- <box size="${width} ${height} ${depth}"/> -->
      </geometry>
      <origin rpy="0 0 0" xyz="0 0 0"/>
      <!-- <origin rpy="${origin_rpy}" xyz="${origin_xyz}"/> -->
      <material name="Gold"/>
    </visual>
    <collision>
      <geometry>
        <mesh filename="package://V1/models/V1/meshes/2013_05_16/sf2_ssf3.wrl"/>
      </geometry>
      <origin rpy="0 0 0" xyz="0 0 0"/>
    </collision>
  </link>
  <gazebo reference="/v1/LeftLittleMedialPhalanx">
    <material>Gazebo/Gold</material>
  </gazebo>
  <link name="/v1/LeftLittleDistalPhalanx">
    <inertial>
      <mass value="0.006"/>
      <origin rpy="0 0 0" xyz="0.0086 0 0"/>
      <inertia ixx="2.525e-07" ixy="0.0" ixz="0.0" iyy="5.45e-07" iyz="0.0" izz="4.365e-07"/>
    </inertial>
    <visual>
      <geometry>
        <mesh filename="package://V1/models/V1/meshes/2013_05_16/sf3_ssf4.wrl"/>
        <!-- <box size="${width} ${height} ${depth}"/> -->
      </geometry>
      <origin rpy="0 0 0" xyz="0 0 0"/>
      <!-- <origin rpy="${origin_rpy}" xyz="${origin_xyz}"/> -->
      <material name="Gold"/>
    </visual>
    <collision>
      <geometry>
        <mesh filename="package://V1/models/V1/meshes/2013_05_16/sf3_ssf4.wrl"/>
      </geometry>
      <origin rpy="0 0 0" xyz="0 0 0"/>
    </collision>
  </link>
  <gazebo reference="/v1/LeftLittleDistalPhalanx">
    <material>Gazebo/Gold</material>
  </gazebo>
  <joint name="LeftLittleMPYaw" type="fixed">
    <origin rpy="1.57079632679 0 0.690626785" xyz="0.0427072303336 0.0352928446888 0.007747"/>
    <axis xyz="0 0 1"/>
    <parent link="left_palm"/>
    <child link="l_hand_force_torque"/>
  </joint>
  <joint name="LeftLittleMPExtensor" type="fixed">
    <origin rpy="-0.690626785 0 1.57079632679" xyz="0 -0.010287 0.071327"/>
    <axis xyz="0 0 1"/>
    <parent link="l_hand_force_torque"/>
    <child link="/v1/LeftLittleProximalPhalanx"/>
  </joint>
  <joint name="LeftLittlePIPExtensor" type="fixed">
    <origin rpy="0 0 -1.57079632679" xyz="0 -0.0381 -0.050169"/>
    <axis xyz="0 0 1"/>
    <parent link="/v1/LeftLittleProximalPhalanx"/>
    <child link="/v1/LeftLittleMedialPhalanx"/>
  </joint>
  <joint name="LeftLittleDIPExtensor" type="fixed">
    <origin rpy="0 0 0" xyz="0.02286 0 0"/>
    <axis xyz="0 0 1"/>
    <parent link="/v1/LeftLittleMedialPhalanx"/>
    <child link="/v1/LeftLittleDistalPhalanx"/>
  </joint>
  <link name="r_uglut">
    <inertial>
      <mass value="2.39"/>
      <origin rpy="0 0 0" xyz="0.001307857 0.021764163 0.038670367"/>
      <inertia ixx="0.0172609783333" ixy="0.0" ixz="0.0" iyy="0.0148661983333" iyz="0.0" izz="0.0112381783333"/>
    </inertial>
    <visual>
      <geometry>
        <mesh filename="package://V1/models/V1/meshes/2013_05_16/lj1_Right.wrl"/>
        <!-- <box size="${width} ${height} ${depth}"/> -->
      </geometry>
      <origin rpy="0 0 0" xyz="0 0 0"/>
      <!-- <origin rpy="${origin_rpy}" xyz="${origin_xyz}"/> -->
      <material name="Gold"/>
    </visual>
    <collision>
      <geometry>
        <mesh filename="package://V1/models/V1/meshes/2013_05_16/lj1_Right.wrl"/>
      </geometry>
      <origin rpy="0 0 0" xyz="0 0 0"/>
    </collision>
  </link>
  <gazebo reference="r_uglut">
    <material>Gazebo/Gold</material>
  </gazebo>
  <link name="r_lglut">
    <inertial>
      <mass value="5.15"/>
      <origin rpy="0 0 0" xyz="0.024260044 0.019261751 -0.0018458616"/>
      <inertia ixx="0.0211810916667" ixy="0.0" ixz="0.0" iyy="0.0138577916667" iyz="0.0" izz="0.0220531583333"/>
    </inertial>
    <visual>
      <geometry>
        <mesh filename="package://V1/models/V1/meshes/2013_05_16/lj2.wrl"/>
        <!-- <box size="${width} ${height} ${depth}"/> -->
      </geometry>
      <origin rpy="0 0 0" xyz="0 0 0"/>
      <!-- <origin rpy="${origin_rpy}" xyz="${origin_xyz}"/> -->
      <material name="White"/>
    </visual>
    <collision>
      <geometry>
        <mesh filename="package://V1/models/V1/meshes/2013_05_16/lj2.wrl"/>
      </geometry>
      <origin rpy="0 0 0" xyz="0 0 0"/>
    </collision>
  </link>
  <gazebo reference="r_lglut">
    <material>Gazebo/White</material>
  </gazebo>
  <link name="r_uleg">
    <inertial>
      <mass value="7.14"/>
      <origin rpy="0 0 0" xyz="0.25533364 -0.016460667 -0.035"/>
      <inertia ixx="0.065433935" ixy="0.0" ixz="0.0" iyy="0.2413439" iyz="0.0" izz="0.258221075"/>
    </inertial>
    <visual>
      <geometry>
        <mesh filename="package://V1/models/V1/meshes/2013_05_16/lj3_Right.wrl"/>
        <!-- <box size="${width} ${height} ${depth}"/> -->
      </geometry>
      <origin rpy="0 0 0" xyz="0 0 0"/>
      <!-- <origin rpy="${origin_rpy}" xyz="${origin_xyz}"/> -->
      <material name="White"/>
    </visual>
    <collision>
      <geometry>
        <mesh filename="package://V1/models/V1/meshes/2013_05_16/lj3_Right.wrl"/>
      </geometry>
      <origin rpy="0 0 0" xyz="0 0 0"/>
    </collision>
  </link>
  <gazebo reference="r_uleg">
    <material>Gazebo/White</material>
  </gazebo>
  <link name="r_lleg">
    <inertial>
      <mass value="6.902"/>
      <origin rpy="0 0 0" xyz="0.12342688 -0.0087741035 0.006614093"/>
      <inertia ixx="0.0435245871667" ixy="0.0" ixz="0.0" iyy="0.120902909167" iyz="0.0" izz="0.11978421"/>
    </inertial>
    <visual>
      <geometry>
        <mesh filename="package://V1/models/V1/meshes/2013_05_16/lj4_Right.wrl"/>
        <!-- <box size="${width} ${height} ${depth}"/> -->
      </geometry>
      <origin rpy="0 0 0" xyz="0 0 0"/>
      <!-- <origin rpy="${origin_rpy}" xyz="${origin_xyz}"/> -->
      <material name="White"/>
    </visual>
    <collision>
      <geometry>
        <mesh filename="package://V1/models/V1/meshes/2013_05_16/lj4_Right.wrl"/>
      </geometry>
      <origin rpy="0 0 0" xyz="0 0 0"/>
    </collision>
  </link>
  <gazebo reference="r_lleg">
    <material>Gazebo/White</material>
  </gazebo>
  <link name="r_talus">
    <inertial>
      <mass value="0.395"/>
      <origin rpy="0 0 0" xyz="0.0057963439 0.0020433211 9.0424431e-05"/>
      <inertia ixx="0.000210699583333" ixy="0.0" ixz="0.0" iyy="5.64191666667e-05" iyz="0.0" izz="0.000225972916667"/>
    </inertial>
    <visual>
      <geometry>
        <box size="0.033 0.076 0.025"/>
      </geometry>
      <origin rpy="0 0 0" xyz="0.0057963439 0.0020433211 9.0424431e-05"/>
      <material name="Gray"/>
    </visual>
    <collision>
      <geometry>
        <box size="0.033 0.076 0.025"/>
      </geometry>
      <origin rpy="0 0 0" xyz="0.0057963439 0.0020433211 9.0424431e-05"/>
    </collision>
  </link>
  <link name="r_foot">
    <inertial>
      <mass value="1.888"/>
      <origin rpy="0 0 0" xyz="0.048263578 -3.1591183e-05 0.077849126"/>
      <inertia ixx="0.0167377493333" ixy="0.0" ixz="0.0" iyy="0.0152179093333" iyz="0.0" izz="0.00363565866667"/>
    </inertial>
    <visual>
      <geometry>
        <mesh filename="package://V1/models/V1/meshes/2013_05_16/lj6_Right.wrl"/>
        <!-- <box size="${width} ${height} ${depth}"/> -->
      </geometry>
      <origin rpy="0 0 0" xyz="0 0 0"/>
      <!-- <origin rpy="${origin_rpy}" xyz="${origin_xyz}"/> -->
      <material name="White"/>
    </visual>
    <collision group="heel">
      <origin rpy="0 0 0" xyz="0.082 0.0624435 -0.07"/>
      <geometry>
        <sphere radius="0"/>
      </geometry>
    </collision>
    <visual>
      <origin rpy="0 0 0" xyz="0.082 0.0624435 -0.07"/>
      <geometry>
        <sphere radius="0.01"/>
      </geometry>
    </visual>
    <collision group="heel">
      <origin rpy="0 0 0" xyz="0.082 -0.0624435 -0.07"/>
      <geometry>
        <sphere radius="0"/>
      </geometry>
    </collision>
    <visual>
      <origin rpy="0 0 0" xyz="0.082 -0.0624435 -0.07"/>
      <geometry>
        <sphere radius="0.01"/>
      </geometry>
    </visual>
    <collision group="toe">
      <origin rpy="0 0 0" xyz="0.082 0.0624435 0.21"/>
      <geometry>
        <sphere radius="0"/>
      </geometry>
    </collision>
    <visual>
      <origin rpy="0 0 0" xyz="0.082 0.0624435 0.21"/>
      <geometry>
        <sphere radius="0.01"/>
      </geometry>
    </visual>
    <collision group="toe">
      <origin rpy="0 0 0" xyz="0.082 -0.0624435 0.21"/>
      <geometry>
        <sphere radius="0"/>
      </geometry>
    </collision>
    <visual>
      <origin rpy="0 0 0" xyz="0.082 -0.0624435 0.21"/>
      <geometry>
        <sphere radius="0.01"/>
      </geometry>
    </visual>
  </link>
  <gazebo reference="r_foot">
    <material>Gazebo/White</material>
  </gazebo>
  <gazebo reference="r_foot">
    <kp>100000.0</kp>
    <kd>1000.0</kd>
    <mu1>1.5</mu1>
    <mu2>1.5</mu2>
    <fdir1>0 0 1</fdir1>
    <maxVel>1.0</maxVel>
    <minDepth>0.00</minDepth>
  </gazebo>
  <joint name="r_leg_hpz" type="revolute">
    <origin rpy="0.0 0 -1.57079632679" xyz="0 -0.1016 -0.183"/>
    <axis xyz="0 0 1"/>
    <parent link="pelvis"/>
    <child link="r_uglut"/>
    <limit effort="190" lower="-1.0471975506" upper="0.5235987753" velocity="5.89"/>
    <controller_gains Kd="500" Kp="15000"/>
    <dynamics damping="1.0" friction="0.0"/>
  </joint>
  <gazebo reference="r_leg_hpz">
    <provideFeedback>1</provideFeedback>
  </gazebo>
  <joint name="r_leg_hpx" type="revolute">
    <origin rpy="-1.57079632679 0 0" xyz="0 0 0"/>
    <axis xyz="0 0 1"/>
    <parent link="r_uglut"/>
    <child link="r_lglut"/>
    <limit effort="350" lower="-0.5235987753" upper="0.26179938765" velocity="7"/>
    <controller_gains Kd="500" Kp="15000"/>
    <dynamics damping="1.0" friction="0.0"/>
  </joint>
  <gazebo reference="r_leg_hpx">
    <provideFeedback>1</provideFeedback>
  </gazebo>
  <joint name="r_leg_hpy" type="revolute">
    <origin rpy="-1.57079632679 0 1.57079632679" xyz="0 0.061 0"/>
    <axis xyz="0 0 1"/>
    <parent link="r_lglut"/>
    <child link="r_uleg"/>
    <limit effort="350" lower="-2.35619448885" upper="1.71042266598" velocity="6.11"/>
    <controller_gains Kd="500" Kp="15000"/>
    <dynamics damping="1.0" friction="0.0"/>
  </joint>
  <gazebo reference="r_leg_hpy">
    <provideFeedback>1</provideFeedback>
  </gazebo>
  <joint name="r_leg_kny" type="revolute">
    <origin rpy="3.14159265359 0 0" xyz="0.431 0 -0.0374"/>
    <axis xyz="0 0 1"/>
    <parent link="r_uleg"/>
    <child link="r_lleg"/>
    <limit effort="350" lower="-1.90240888359" upper="0.218166156375" velocity="6.11"/>
    <controller_gains Kd="500" Kp="15000"/>
    <dynamics damping="1.0" friction="0.0"/>
  </joint>
  <gazebo reference="r_leg_kny">
    <provideFeedback>1</provideFeedback>
  </gazebo>
  <joint name="r_leg_aky" type="revolute">
    <origin rpy="3.14159265359 0 0.13" xyz="0.406 0 0"/>
    <axis xyz="0 0 1"/>
    <parent link="r_lleg"/>
    <child link="r_talus"/>
    <limit effort="205" lower="-0.8726646255" upper="0.8726646255" velocity="11"/>
    <controller_gains Kd="400" Kp="15000"/>
    <dynamics damping="1.0" friction="0.0"/>
  </joint>
  <gazebo reference="r_leg_aky">
    <provideFeedback>1</provideFeedback>
  </gazebo>
  <joint name="r_leg_akx" type="revolute">
    <origin rpy="1.57079632679 0 0" xyz="0.0127 0 0"/>
    <axis xyz="0 0 1"/>
    <parent link="r_talus"/>
    <child link="r_foot"/>
    <limit effort="205" lower="-0.3490658502" upper="0.3490658502" velocity="11"/>
    <controller_gains Kd="400" Kp="15000"/>
    <dynamics damping="1.0" friction="0.0"/>
  </joint>
  <gazebo reference="r_leg_akx">
    <provideFeedback>1</provideFeedback>
  </gazebo>
  <actuator name="/pelvis/rj1" type="turbodriver_api/TurbodriverAPI_DRCv4"/>
  <actuator name="/right_leg/j2" type="turbodriver_api/TurbodriverAPI_DRCv4"/>
  <actuator name="/right_leg/j3" type="turbodriver_api/TurbodriverAPI_DRCv4"/>
  <actuator name="/right_leg/j4" type="turbodriver_api/TurbodriverAPI_DRCv4"/>
  <actuator name="/right_leg/j5" type="turbodriver_api/TurbodriverAPI_DRCv4_linear"/>
  <actuator name="/right_leg/j6" type="turbodriver_api/TurbodriverAPI_DRCv4_linear"/>
  <mode name="RightHipRotatorMode" type="mode_plugins/ModeInterface">
    <translator name="RightHipRotatorModeData" type="SimpleActuatorToJointMode">
      <joint data="mode" name="r_leg_hpz"/>
      <actuator data="mode" name="/pelvis/rj1"/>
    </translator>
    <translator name="RightHipRotatorModeCommand" type="SimpleJointToActuatorMode">
      <joint data="modeCommand" name="r_leg_hpz"/>
      <actuator data="modeCommand" name="/pelvis/rj1"/>
    </translator>
  </mode>
  <mode name="RightHipAdductorMode" type="mode_plugins/ModeInterface">
    <translator name="RightHipAdductorModeData" type="SimpleActuatorToJointMode">
      <joint data="mode" name="r_leg_hpx"/>
      <actuator data="mode" name="/right_leg/j2"/>
    </translator>
    <translator name="RightHipAdductorModeCommand" type="SimpleJointToActuatorMode">
      <joint data="modeCommand" name="r_leg_hpx"/>
      <actuator data="modeCommand" name="/right_leg/j2"/>
    </translator>
  </mode>
  <mode name="RightHipExtensorMode" type="mode_plugins/ModeInterface">
    <translator name="RightHipExtensorModeData" type="SimpleActuatorToJointMode">
      <joint data="mode" name="r_leg_hpy"/>
      <actuator data="mode" name="/right_leg/j3"/>
    </translator>
    <translator name="RightHipExtensorModeCommand" type="SimpleJointToActuatorMode">
      <joint data="modeCommand" name="r_leg_hpy"/>
      <actuator data="modeCommand" name="/right_leg/j3"/>
    </translator>
  </mode>
  <mode name="RightKneeExtensorMode" type="mode_plugins/ModeInterface">
    <translator name="RightKneeExtensorModeData" type="SimpleActuatorToJointMode">
      <joint data="mode" name="r_leg_kny"/>
      <actuator data="mode" name="/right_leg/j4"/>
    </translator>
    <translator name="RightKneeExtensorModeCommand" type="SimpleJointToActuatorMode">
      <joint data="modeCommand" name="r_leg_kny"/>
      <actuator data="modeCommand" name="/right_leg/j4"/>
    </translator>
  </mode>
  <mode name="RightAnkleExtensorMode" type="mode_plugins/ModeInterface">
    <translator name="RightAnkleExtensorModeData" type="SimpleActuatorToJointMode">
      <joint data="mode" name="r_leg_aky"/>
      <actuator data="mode" name="/right_leg/j5"/>
    </translator>
    <translator name="RightAnkleExtensorModeCommand" type="SimpleJointToActuatorMode">
      <joint data="modeCommand" name="r_leg_aky"/>
      <actuator data="modeCommand" name="/right_leg/j5"/>
    </translator>
  </mode>
  <mode name="RightAnkleMode" type="mode_plugins/ModeInterface">
    <translator name="RightAnkleModeData" type="SimpleActuatorToJointMode">
      <joint data="mode" name="r_leg_akx"/>
      <actuator data="mode" name="/right_leg/j6"/>
    </translator>
    <translator name="RightAnkleModeCommand" type="SimpleJointToActuatorMode">
      <joint data="modeCommand" name="r_leg_akx"/>
      <actuator data="modeCommand" name="/right_leg/j6"/>
    </translator>
  </mode>
  <link name="/v1/RightLegHokuyo_Frame">
    <!-- Virtual Link -->
    <inertial>
      <mass value="0.1"/>
      <origin rpy="0 0 0" xyz="0 0 0"/>
      <inertia ixx="8.33333333333e-05" ixy="0.0" ixz="0.0" iyy="8.33333333333e-05" iyz="0.0" izz="0.000125"/>
    </inertial>
  </link>
  <gazebo reference="/v1/RightLegHokuyo_Frame">
    <sensor name="/v1/RightLegHokuyo" type="ray">
      <pose>0 0 0 0 0 0</pose>
      <visualize>false</visualize>
      <update_rate>40.0</update_rate>
      <ray>
        <scan>
          <horizontal>
            <samples>1080</samples>
            <resolution>0.0043611</resolution>
            <min_angle>-2.355</min_angle>
            <max_angle>2.355</max_angle>
          </horizontal>
        </scan>
        <range>
          <min>0.1</min>
          <max>30</max>
          <resolution>0.03</resolution>
        </range>
        <!-- Noise data from DRCSIM -->
        <noise>
          <type>gaussian</type>
          <!-- Noise parameters based on published spec for Hokuyo laser
               achieving "+-30mm" accuracy at range < 10m.  A mean of 0.0m and
               stddev of 0.01m will put 99.7% of samples within 0.03m of the true
               reading. -->
          <mean>0.0</mean>
          <stddev>0.01</stddev>
        </noise>
      </ray>
      <plugin filename="libgazebo_ros_laser.so" name="/v1/RightLegHokuyo_Controller">
        <gaussianNoise>0.005</gaussianNoise>
        <alwaysOn>true</alwaysOn>
        <updateRate>40.0</updateRate>
        <topicName>/v1/RightLegHokuyo/scan</topicName>
        <frameName>/v1/RightLegHokuyo_Frame</frameName>
      </plugin>
    </sensor>
  </gazebo>
  <joint name="/v1/RightLegHokuyo_Offset" type="fixed">
    <origin rpy="1.57079632679 0 -0.38394" xyz="0.350849 -0.098349 -0.036021"/>
    <axis xyz="0 0 1"/>
    <parent link="r_uleg"/>
    <child link="/v1/RightLegHokuyo_Frame"/>
  </joint>
  <link name="/v1/RightLegCamBoard_Frame">
    <!-- Virtual Link -->
    <inertial>
      <mass value="0.1"/>
      <origin rpy="0 0 0" xyz="0 0 0"/>
      <inertia ixx="8.33333333333e-05" ixy="0.0" ixz="0.0" iyy="8.33333333333e-05" iyz="0.0" izz="0.000125"/>
    </inertial>
  </link>
  <gazebo reference="/v1/RightLegCamBoard_Frame">
    <sensor name="asus/ir" type="depth">
      <camera>
        <image>
          <width>160</width>
          <height>120</height>
          <format>L8</format>
        </image>
        <horizontal_fov>1.57079632679</horizontal_fov>
        <clip>
          <near>0.01</near>
          <far>1</far>
        </clip>
      </camera>
      <update_rate>30</update_rate>
      <plugin filename="libAsusXtionPluginRos.so" name="/v1/RightLegCamBoard_Controller">
        <updateRate>30</updateRate>
        <cameraName>/v1/RightLegCamBoard</cameraName>
        <imageTopicName>rgb/image_raw</imageTopicName>
        <cameraInfoTopicName>rgb/camera_info</cameraInfoTopicName>
        <depthImageTopicName>depth/image_raw</depthImageTopicName>
        <depthCameraInfoTopicName>depth/camera_info</depthCameraInfoTopicName>
        <pointCloudTopicName>depth/points</pointCloudTopicName>
        <frameName>/v1/RightLegCamBoardIR_Frame</frameName>
        <pointCloudCutoff>0.2</pointCloudCutoff>
        <hack_baseline>0.2</hack_baseline>
      </plugin>
    </sensor>
  </gazebo>
  <joint name="/v1/RightLegCamBoard_Offset" type="fixed">
    <origin rpy="-1.57079632679 0 1.3" xyz="0.344887 0.069118 -0.0085"/>
    <axis xyz="0 0 1"/>
    <parent link="r_lleg"/>
    <child link="/v1/RightLegCamBoard_Frame"/>
  </joint>
  <link name="/v1/RightLegCamBoardIR_Frame">
    <!-- Virtual Link -->
    <inertial>
      <mass value="0.1"/>
      <origin rpy="0 0 0" xyz="0 0 0"/>
      <inertia ixx="8.33333333333e-05" ixy="0.0" ixz="0.0" iyy="8.33333333333e-05" iyz="0.0" izz="0.000125"/>
    </inertial>
  </link>
  <joint name="/v1/RightLegCamBoardIR_Offset" type="fixed">
    <origin rpy="-1.4279169 0.057186 -1.603747" xyz="-0.05180 -0.0013 0.030237"/>
    <axis xyz="0 0 1"/>
    <parent link="/v1/RightLegCamBoard_Frame"/>
    <child link="/v1/RightLegCamBoardIR_Frame"/>
  </joint>
  <link name="/v1/RightCOP_Frame">
    <!-- Virtual Link -->
    <inertial>
      <mass value="0.1"/>
      <origin rpy="0 0 0" xyz="0 0 0"/>
      <inertia ixx="8.33333333333e-05" ixy="0.0" ixz="0.0" iyy="8.33333333333e-05" iyz="0.0" izz="0.000125"/>
    </inertial>
  </link>
  <joint name="/v1/RightCOP_Offset" type="fixed">
    <origin rpy="0.0 -1.57079632679 0" xyz="0.0845 0 0"/>
    <axis xyz="0 0 1"/>
    <parent link="r_foot"/>
    <child link="/v1/RightCOP_Frame"/>
  </joint>
  <link name="/v1/RightLeg6Axis_Frame">
    <!-- Virtual Link -->
    <inertial>
      <mass value="0.1"/>
      <origin rpy="0 0 0" xyz="0 0 0"/>
      <inertia ixx="8.33333333333e-05" ixy="0.0" ixz="0.0" iyy="8.33333333333e-05" iyz="0.0" izz="0.000125"/>
    </inertial>
  </link>
  <joint name="/v1/RightLeg6Axis_Offset" type="fixed">
    <origin rpy="-1.42079632679 -0.518666 -1.64601" xyz="0.0551839 0 0.0291731"/>
    <axis xyz="0 0 1"/>
    <parent link="r_foot"/>
    <child link="/v1/RightLeg6Axis_Frame"/>
  </joint>
  <link name="/v1/RightLegHermes_Frame">
    <!-- Virtual Link -->
    <inertial>
      <mass value="0.1"/>
      <origin rpy="0 0 0" xyz="0 0 0"/>
      <inertia ixx="8.33333333333e-05" ixy="0.0" ixz="0.0" iyy="8.33333333333e-05" iyz="0.0" izz="0.000125"/>
    </inertial>
  </link>
  <joint name="/v1/RightLegHermes_Offset" type="fixed">
    <origin rpy="0.0 -1.57079632679 0" xyz="0.0845 0 0"/>
    <axis xyz="0 0 1"/>
    <parent link="r_foot"/>
    <child link="/v1/RightLegHermes_Frame"/>
  </joint>
  <link name="/v1/RightMPU6000_Frame">
    <!-- Virtual Link -->
    <inertial>
      <mass value="0.1"/>
      <origin rpy="0 0 0" xyz="0 0 0"/>
      <inertia ixx="8.33333333333e-05" ixy="0.0" ixz="0.0" iyy="8.33333333333e-05" iyz="0.0" izz="0.000125"/>
    </inertial>
  </link>
  <joint name="/v1/RightMPU6000_Offset" type="fixed">
    <origin rpy="0 1.44079632679 3.14159265358" xyz="0.0471 0.00722 0.0843"/>
    <axis xyz="0 0 1"/>
    <parent link="r_foot"/>
    <child link="/v1/RightMPU6000_Frame"/>
  </joint>
  <copSensor frame="/v1/RightValkyrieCOP_Frame" name="/v1/RightValkyrieCOP" nodePath="/right_leg/cop" type="ValkyrieCOPSensor"/>
  <imuSensor frame="/v1/RightMPU6000_Frame" name="/v1/RightMPU6000" nodePath="/right_leg/hermes" type="IMUSensorMPU6000"/>
  <link name="l_uglut">
    <inertial>
      <mass value="2.39"/>
      <origin rpy="0 0 0" xyz="0.001307857 0.021764163 -0.038670367"/>
      <inertia ixx="0.0172609783333" ixy="0.0" ixz="0.0" iyy="0.0148661983333" iyz="0.0" izz="0.0112381783333"/>
    </inertial>
    <visual>
      <geometry>
        <mesh filename="package://V1/models/V1/meshes/2013_05_16/lj1_Left.wrl"/>
        <!-- <box size="${width} ${height} ${depth}"/> -->
      </geometry>
      <origin rpy="0 0 0" xyz="0 0 0"/>
      <!-- <origin rpy="${origin_rpy}" xyz="${origin_xyz}"/> -->
      <material name="Gold"/>
    </visual>
    <collision>
      <geometry>
        <mesh filename="package://V1/models/V1/meshes/2013_05_16/lj1_Left.wrl"/>
      </geometry>
      <origin rpy="0 0 0" xyz="0 0 0"/>
    </collision>
  </link>
  <gazebo reference="l_uglut">
    <material>Gazebo/Gold</material>
  </gazebo>
  <link name="l_lglut">
    <inertial>
      <mass value="5.15"/>
      <origin rpy="0 0 0" xyz="0.024260044 0.019261751 -0.0018458616"/>
      <inertia ixx="0.0211810916667" ixy="0.0" ixz="0.0" iyy="0.0138577916667" iyz="0.0" izz="0.0220531583333"/>
    </inertial>
    <visual>
      <geometry>
        <mesh filename="package://V1/models/V1/meshes/2013_05_16/lj2.wrl"/>
        <!-- <box size="${width} ${height} ${depth}"/> -->
      </geometry>
      <origin rpy="0 0 0" xyz="0 0 0"/>
      <!-- <origin rpy="${origin_rpy}" xyz="${origin_xyz}"/> -->
      <material name="White"/>
    </visual>
    <collision>
      <geometry>
        <mesh filename="package://V1/models/V1/meshes/2013_05_16/lj2.wrl"/>
      </geometry>
      <origin rpy="0 0 0" xyz="0 0 0"/>
    </collision>
  </link>
  <gazebo reference="l_lglut">
    <material>Gazebo/White</material>
  </gazebo>
  <link name="l_uleg">
    <inertial>
      <mass value="7.14"/>
      <origin rpy="0 0 0" xyz="0.25533364 -0.016460667 0.035"/>
      <inertia ixx="0.065433935" ixy="0.0" ixz="0.0" iyy="0.2413439" iyz="0.0" izz="0.258221075"/>
    </inertial>
    <visual>
      <geometry>
        <mesh filename="package://V1/models/V1/meshes/2013_05_16/lj3_Left.wrl"/>
        <!-- <box size="${width} ${height} ${depth}"/> -->
      </geometry>
      <origin rpy="0 0 0" xyz="0 0 0"/>
      <!-- <origin rpy="${origin_rpy}" xyz="${origin_xyz}"/> -->
      <material name="White"/>
    </visual>
    <collision>
      <geometry>
        <mesh filename="package://V1/models/V1/meshes/2013_05_16/lj3_Left.wrl"/>
      </geometry>
      <origin rpy="0 0 0" xyz="0 0 0"/>
    </collision>
  </link>
  <gazebo reference="l_uleg">
    <material>Gazebo/White</material>
  </gazebo>
  <link name="l_lleg">
    <inertial>
      <mass value="6.902"/>
      <origin rpy="0 0 0" xyz="0.12342688 -0.0087741035 -0.006614093"/>
      <inertia ixx="0.0435245871667" ixy="0.0" ixz="0.0" iyy="0.120902909167" iyz="0.0" izz="0.11978421"/>
    </inertial>
    <visual>
      <geometry>
        <mesh filename="package://V1/models/V1/meshes/2013_05_16/lj4_Left.wrl"/>
        <!-- <box size="${width} ${height} ${depth}"/> -->
      </geometry>
      <origin rpy="0 0 0" xyz="0 0 0"/>
      <!-- <origin rpy="${origin_rpy}" xyz="${origin_xyz}"/> -->
      <material name="White"/>
    </visual>
    <collision>
      <geometry>
        <mesh filename="package://V1/models/V1/meshes/2013_05_16/lj4_Left.wrl"/>
      </geometry>
      <origin rpy="0 0 0" xyz="0 0 0"/>
    </collision>
  </link>
  <gazebo reference="l_lleg">
    <material>Gazebo/White</material>
  </gazebo>
  <link name="l_talus">
    <inertial>
      <mass value="0.395"/>
      <origin rpy="0 0 0" xyz="0.0057963439 0.0020433211 9.0424431e-05"/>
      <inertia ixx="0.000210699583333" ixy="0.0" ixz="0.0" iyy="5.64191666667e-05" iyz="0.0" izz="0.000225972916667"/>
    </inertial>
    <visual>
      <geometry>
        <box size="0.033 0.076 0.025"/>
      </geometry>
      <origin rpy="0 0 0" xyz="0.0057963439 0.0020433211 9.0424431e-05"/>
      <material name="Gray"/>
    </visual>
    <collision>
      <geometry>
        <box size="0.033 0.076 0.025"/>
      </geometry>
      <origin rpy="0 0 0" xyz="0.0057963439 0.0020433211 9.0424431e-05"/>
    </collision>
  </link>
  <link name="l_foot">
    <inertial>
      <mass value="1.888"/>
      <origin rpy="0 0 0" xyz="0.048263578 -3.1591183e-05 -0.077849126"/>
      <inertia ixx="0.0167377493333" ixy="0.0" ixz="0.0" iyy="0.0152179093333" iyz="0.0" izz="0.00363565866667"/>
    </inertial>
    <visual>
      <geometry>
        <mesh filename="package://V1/models/V1/meshes/2013_05_16/lj6_Left.wrl"/>
        <!-- <box size="${width} ${height} ${depth}"/> -->
      </geometry>
      <origin rpy="0 0 0" xyz="0 0 0"/>
      <!-- <origin rpy="${origin_rpy}" xyz="${origin_xyz}"/> -->
      <material name="White"/>
    </visual>
    <collision group="heel">
      <origin rpy="0 0 0" xyz="-0.082 0.0624435 -0.081119"/>
      <geometry>
        <sphere radius="0"/>
      </geometry>
    </collision>
    <visual>
      <origin rpy="0 0 0" xyz="-0.082 0.0624435 -0.081119"/>
      <geometry>
        <sphere radius="0.01"/>
      </geometry>
    </visual>
    <collision group="heel">
      <origin rpy="0 0 0" xyz="-0.082 -0.0624435 -0.081119"/>
      <geometry>
        <sphere radius="0"/>
      </geometry>
    </collision>
    <visual>
      <origin rpy="0 0 0" xyz="-0.082 -0.0624435 -0.081119"/>
      <geometry>
        <sphere radius="0.01"/>
      </geometry>
    </visual>
    <collision group="toe">
      <origin rpy="0 0 0" xyz="0.178 0.0624435 -0.081119"/>
      <geometry>
        <sphere radius="0"/>
      </geometry>
    </collision>
    <visual>
      <origin rpy="0 0 0" xyz="0.178 0.0624435 -0.081119"/>
      <geometry>
        <sphere radius="0.01"/>
      </geometry>
    </visual>
    <collision group="toe">
      <origin rpy="0 0 0" xyz="0.178 -0.0624435 -0.081119"/>
      <geometry>
        <sphere radius="0"/>
      </geometry>
    </collision>
  </link>
  <gazebo reference="l_foot">
    <material>Gazebo/White</material>
  </gazebo>
  <gazebo reference="l_foot">
    <kp>100000.0</kp>
    <kd>1000.0</kd>
    <mu1>1.5</mu1>
    <mu2>1.5</mu2>
    <fdir1>0 0 1</fdir1>
    <maxVel>1.0</maxVel>
    <minDepth>0.00</minDepth>
  </gazebo>
  <joint name="l_leg_hpz" type="revolute">
    <origin rpy="3.14159265359 0 1.57079632679" xyz="0 0.1016 -0.183"/>
    <axis xyz="0 0 1"/>
    <parent link="pelvis"/>
    <child link="l_uglut"/>
    <limit effort="190" lower="-1.0471975506" upper="0.5235987753" velocity="5.89"/>
    <controller_gains Kd="500" Kp="15000"/>
    <dynamics damping="1.0" friction="0.0"/>
  </joint>
  <gazebo reference="l_leg_hpz">
    <provideFeedback>1</provideFeedback>
  </gazebo>
  <joint name="l_leg_hpx" type="revolute">
    <origin rpy="1.57079632679 0 0" xyz="0 0 0"/>
    <axis xyz="0 0 1"/>
    <parent link="l_uglut"/>
    <child link="l_lglut"/>
    <limit effort="350" lower="-0.5235987753" upper="0.26179938765" velocity="7"/>
    <controller_gains Kd="500" Kp="15000"/>
    <dynamics damping="1.0" friction="0.0"/>
  </joint>
  <gazebo reference="l_leg_hpx">
    <provideFeedback>1</provideFeedback>
  </gazebo>
  <joint name="l_leg_hpy" type="revolute">
    <origin rpy="1.57079632679 0 1.57079632679" xyz="0 0.061 0"/>
    <axis xyz="0 0 1"/>
    <parent link="l_lglut"/>
    <child link="l_uleg"/>
    <limit effort="350" lower="-2.35619448885" upper="1.71042266598" velocity="6.11"/>
    <controller_gains Kd="500" Kp="15000"/>
    <dynamics damping="1.0" friction="0.0"/>
  </joint>
  <gazebo reference="l_leg_hpy">
    <provideFeedback>1</provideFeedback>
  </gazebo>
  <joint name="l_leg_kny" type="revolute">
    <origin rpy="3.14159265359 0 0" xyz="0.431 0 0.0374"/>
    <axis xyz="0 0 1"/>
    <parent link="l_uleg"/>
    <child link="l_lleg"/>
    <limit effort="350" lower="-1.90240888359" upper="0.218166156375" velocity="6.11"/>
    <controller_gains Kd="500" Kp="15000"/>
    <dynamics damping="1.0" friction="0.0"/>
  </joint>
  <gazebo reference="l_leg_kny">
    <provideFeedback>1</provideFeedback>
  </gazebo>
  <joint name="l_leg_aky" type="revolute">
    <origin rpy="3.14159265359 0 0.13" xyz="0.406 0 0"/>
    <axis xyz="0 0 1"/>
    <parent link="l_lleg"/>
    <child link="l_talus"/>
    <limit effort="205" lower="-0.8726646255" upper="0.8726646255" velocity="11"/>
    <controller_gains Kd="400" Kp="15000"/>
    <dynamics damping="1.0" friction="0.0"/>
  </joint>
  <gazebo reference="l_leg_aky">
    <provideFeedback>1</provideFeedback>
  </gazebo>
  <joint name="l_leg_akx" type="revolute">
    <origin rpy="-1.57079632679 0 0" xyz="0.0127 0 0"/>
    <axis xyz="0 0 1"/>
    <parent link="l_talus"/>
    <child link="l_foot"/>
    <limit effort="205" lower="-0.3490658502" upper="0.3490658502" velocity="11"/>
    <controller_gains Kd="400" Kp="15000"/>
    <dynamics damping="1.0" friction="0.0"/>
  </joint>
  <gazebo reference="l_leg_akx">
    <provideFeedback>1</provideFeedback>
  </gazebo>
  <actuator name="/pelvis/lj1" type="turbodriver_api/TurbodriverAPI_DRCv4"/>
  <actuator name="/left_leg/j2" type="turbodriver_api/TurbodriverAPI_DRCv4"/>
  <actuator name="/left_leg/j3" type="turbodriver_api/TurbodriverAPI_DRCv4"/>
  <actuator name="/left_leg/j4" type="turbodriver_api/TurbodriverAPI_DRCv4"/>
  <actuator name="/left_leg/j5" type="turbodriver_api/TurbodriverAPI_DRCv4_linear"/>
  <actuator name="/left_leg/j6" type="turbodriver_api/TurbodriverAPI_DRCv4_linear"/>
  <mode name="LeftHipRotatorMode" type="mode_plugins/ModeInterface">
    <translator name="LeftHipRotatorModeData" type="SimpleActuatorToJointMode">
      <joint data="mode" name="l_leg_hpz"/>
      <actuator data="mode" name="/pelvis/lj1"/>
    </translator>
    <translator name="LeftHipRotatorModeCommand" type="SimpleJointToActuatorMode">
      <joint data="modeCommand" name="l_leg_hpz"/>
      <actuator data="modeCommand" name="/pelvis/lj1"/>
    </translator>
  </mode>
  <mode name="LeftHipAdductorMode" type="mode_plugins/ModeInterface">
    <translator name="LeftHipAdductorModeData" type="SimpleActuatorToJointMode">
      <joint data="mode" name="l_leg_hpx"/>
      <actuator data="mode" name="/left_leg/j2"/>
    </translator>
    <translator name="LeftHipAdductorModeCommand" type="SimpleJointToActuatorMode">
      <joint data="modeCommand" name="l_leg_hpx"/>
      <actuator data="modeCommand" name="/left_leg/j2"/>
    </translator>
  </mode>
  <mode name="LeftHipExtensorMode" type="mode_plugins/ModeInterface">
    <translator name="LeftHipExtensorModeData" type="SimpleActuatorToJointMode">
      <joint data="mode" name="l_leg_hpy"/>
      <actuator data="mode" name="/left_leg/j3"/>
    </translator>
    <translator name="LeftHipExtensorModeCommand" type="SimpleJointToActuatorMode">
      <joint data="modeCommand" name="l_leg_hpy"/>
      <actuator data="modeCommand" name="/left_leg/j3"/>
    </translator>
  </mode>
  <mode name="LeftKneeExtensorMode" type="mode_plugins/ModeInterface">
    <translator name="LeftKneeExtensorModeData" type="SimpleActuatorToJointMode">
      <joint data="mode" name="l_leg_kny"/>
      <actuator data="mode" name="/left_leg/j4"/>
    </translator>
    <translator name="LeftKneeExtensorModeCommand" type="SimpleJointToActuatorMode">
      <joint data="modeCommand" name="l_leg_kny"/>
      <actuator data="modeCommand" name="/left_leg/j4"/>
    </translator>
  </mode>
  <mode name="LeftAnkleExtensorMode" type="mode_plugins/ModeInterface">
    <translator name="LeftAnkleExtensorModeData" type="SimpleActuatorToJointMode">
      <joint data="mode" name="l_leg_aky"/>
      <actuator data="mode" name="/left_leg/j5"/>
    </translator>
    <translator name="LeftAnkleExtensorModeCommand" type="SimpleJointToActuatorMode">
      <joint data="modeCommand" name="l_leg_aky"/>
      <actuator data="modeCommand" name="/left_leg/j5"/>
    </translator>
  </mode>
  <mode name="LeftAnkleMode" type="mode_plugins/ModeInterface">
    <translator name="LeftAnkleModeData" type="SimpleActuatorToJointMode">
      <joint data="mode" name="l_leg_akx"/>
      <actuator data="mode" name="/left_leg/j6"/>
    </translator>
    <translator name="LeftAnkleModeCommand" type="SimpleJointToActuatorMode">
      <joint data="modeCommand" name="l_leg_akx"/>
      <actuator data="modeCommand" name="/left_leg/j6"/>
    </translator>
  </mode>
  <link name="/v1/LeftLegHokuyo_Frame">
    <!-- Virtual Link -->
    <inertial>
      <mass value="0.1"/>
      <origin rpy="0 0 0" xyz="0 0 0"/>
      <inertia ixx="8.33333333333e-05" ixy="0.0" ixz="0.0" iyy="8.33333333333e-05" iyz="0.0" izz="0.000125"/>
    </inertial>
  </link>
  <gazebo reference="/v1/LeftLegHokuyo_Frame">
    <sensor name="/v1/LeftLegHokuyo" type="ray">
      <pose>0 0 0 0 0 0</pose>
      <visualize>false</visualize>
      <update_rate>40.0</update_rate>
      <ray>
        <scan>
          <horizontal>
            <samples>1080</samples>
            <resolution>0.0043611</resolution>
            <min_angle>-2.355</min_angle>
            <max_angle>2.355</max_angle>
          </horizontal>
        </scan>
        <range>
          <min>0.1</min>
          <max>30</max>
          <resolution>0.03</resolution>
        </range>
        <!-- Noise data from DRCSIM -->
        <noise>
          <type>gaussian</type>
          <!-- Noise parameters based on published spec for Hokuyo laser
               achieving "+-30mm" accuracy at range < 10m.  A mean of 0.0m and
               stddev of 0.01m will put 99.7% of samples within 0.03m of the true
               reading. -->
          <mean>0.0</mean>
          <stddev>0.01</stddev>
        </noise>
      </ray>
      <plugin filename="libgazebo_ros_laser.so" name="/v1/LeftLegHokuyo_Controller">
        <gaussianNoise>0.005</gaussianNoise>
        <alwaysOn>true</alwaysOn>
        <updateRate>40.0</updateRate>
        <topicName>/v1/LeftLegHokuyo/scan</topicName>
        <frameName>/v1/LeftLegHokuyo_Frame</frameName>
      </plugin>
    </sensor>
  </gazebo>
  <joint name="/v1/LeftLegHokuyo_Offset" type="fixed">
    <origin rpy="1.57079632679 0 -0.38394" xyz="0.350849 -0.098349 0.036021"/>
    <axis xyz="0 0 1"/>
    <parent link="l_uleg"/>
    <child link="/v1/LeftLegHokuyo_Frame"/>
  </joint>
  <link name="/v1/LeftLegCamBoard_Frame">
    <!-- Virtual Link -->
    <inertial>
      <mass value="0.1"/>
      <origin rpy="0 0 0" xyz="0 0 0"/>
      <inertia ixx="8.33333333333e-05" ixy="0.0" ixz="0.0" iyy="8.33333333333e-05" iyz="0.0" izz="0.000125"/>
    </inertial>
  </link>
  <gazebo reference="/v1/LeftLegCamBoard_Frame">
    <sensor name="asus/ir" type="depth">
      <camera>
        <image>
          <width>160</width>
          <height>120</height>
          <format>L8</format>
        </image>
        <horizontal_fov>1.57079632679</horizontal_fov>
        <clip>
          <near>0.01</near>
          <far>1</far>
        </clip>
      </camera>
      <update_rate>30</update_rate>
      <plugin filename="libAsusXtionPluginRos.so" name="/v1/LeftLegCamBoard_Controller">
        <updateRate>30</updateRate>
        <cameraName>/v1/LeftLegCamBoard</cameraName>
        <imageTopicName>rgb/image_raw</imageTopicName>
        <cameraInfoTopicName>rgb/camera_info</cameraInfoTopicName>
        <depthImageTopicName>depth/image_raw</depthImageTopicName>
        <depthCameraInfoTopicName>depth/camera_info</depthCameraInfoTopicName>
        <pointCloudTopicName>depth/points</pointCloudTopicName>
        <frameName>/v1/LeftLegCamBoardIR_Frame</frameName>
        <pointCloudCutoff>0.2</pointCloudCutoff>
        <hack_baseline>0.2</hack_baseline>
      </plugin>
    </sensor>
  </gazebo>
  <joint name="/v1/LeftLegCamBoard_Offset" type="fixed">
    <origin rpy="-1.57079632679 0 1.3" xyz="0.344887 0.069118 0.0085"/>
    <axis xyz="0 0 1"/>
    <parent link="l_lleg"/>
    <child link="/v1/LeftLegCamBoard_Frame"/>
  </joint>
  <link name="/v1/LeftLegCamBoardIR_Frame">
    <!-- Virtual Link -->
    <inertial>
      <mass value="0.1"/>
      <origin rpy="0 0 0" xyz="0 0 0"/>
      <inertia ixx="8.33333333333e-05" ixy="0.0" ixz="0.0" iyy="8.33333333333e-05" iyz="0.0" izz="0.000125"/>
    </inertial>
  </link>
  <joint name="/v1/LeftLegCamBoardIR_Offset" type="fixed">
    <origin rpy="-1.4279169 0.057186 -1.603747" xyz="-0.05180 -0.0013 0.030237"/>
    <axis xyz="0 0 1"/>
    <parent link="/v1/LeftLegCamBoard_Frame"/>
    <child link="/v1/LeftLegCamBoardIR_Frame"/>
  </joint>
  <link name="/v1/LeftCOP_Frame">
    <!-- Virtual Link -->
    <inertial>
      <mass value="0.1"/>
      <origin rpy="0 0 0" xyz="0 0 0"/>
      <inertia ixx="8.33333333333e-05" ixy="0.0" ixz="0.0" iyy="8.33333333333e-05" iyz="0.0" izz="0.000125"/>
    </inertial>
  </link>
  <joint name="/v1/LeftCOP_Offset" type="fixed">
    <origin rpy="3.14159265358 1.57079632679 0" xyz="0.0845 0 0"/>
    <axis xyz="0 0 1"/>
    <parent link="l_foot"/>
    <child link="/v1/LeftCOP_Frame"/>
  </joint>
  <link name="/v1/LeftLeg6Axis_Frame">
    <!-- Virtual Link -->
    <inertial>
      <mass value="0.1"/>
      <origin rpy="0 0 0" xyz="0 0 0"/>
      <inertia ixx="8.33333333333e-05" ixy="0.0" ixz="0.0" iyy="8.33333333333e-05" iyz="0.0" izz="0.000125"/>
    </inertial>
  </link>
  <joint name="/v1/LeftLeg6Axis_Offset" type="fixed">
    <origin rpy="1.72079632679 0.518666 1.64601" xyz="0.0551839 0 -0.0291731"/>
    <axis xyz="0 0 1"/>
    <parent link="l_foot"/>
    <child link="/v1/LeftLeg6Axis_Frame"/>
  </joint>
  <link name="/v1/LeftLegHermes_Frame">
    <!-- Virtual Link -->
    <inertial>
      <mass value="0.1"/>
      <origin rpy="0 0 0" xyz="0 0 0"/>
      <inertia ixx="8.33333333333e-05" ixy="0.0" ixz="0.0" iyy="8.33333333333e-05" iyz="0.0" izz="0.000125"/>
    </inertial>
  </link>
  <joint name="/v1/LeftLegHermes_Offset" type="fixed">
    <origin rpy="3.14159265358 1.57079632679 0" xyz="0.0845 0 0"/>
    <axis xyz="0 0 1"/>
    <parent link="l_foot"/>
    <child link="/v1/LeftLegHermes_Frame"/>
  </joint>
  <link name="/v1/LeftMPU6000_Frame">
    <!-- Virtual Link -->
    <inertial>
      <mass value="0.1"/>
      <origin rpy="0 0 0" xyz="0 0 0"/>
      <inertia ixx="8.33333333333e-05" ixy="0.0" ixz="0.0" iyy="8.33333333333e-05" iyz="0.0" izz="0.000125"/>
    </inertial>
  </link>
  <joint name="/v1/LeftMPU6000_Offset" type="fixed">
    <origin rpy="0 -1.70079632679 0.0" xyz="0.0471 -0.00722 -0.0843"/>
    <axis xyz="0 0 1"/>
    <parent link="l_foot"/>
    <child link="/v1/LeftMPU6000_Frame"/>
  </joint>
  <copSensor frame="/v1/LeftValkyrieCOP_Frame" name="/v1/LeftValkyrieCOP" nodePath="/left_leg/cop" type="ValkyrieCOPSensor"/>
  <imuSensor frame="/v1/LeftMPU6000_Frame" name="/v1/LeftMPU6000" nodePath="/left_leg/hermes" type="IMUSensorMPU6000"/>
  <transmission name="back_bkz_trans" type="pr2_mechanism_model/SimpleTransmission">
    <joint name="back_bkz"/>
    <actuator name="back_bkz_motor"/>
    <mechanicalReduction>1</mechanicalReduction>
  </transmission>
  <transmission name="back_bky_trans" type="pr2_mechanism_model/SimpleTransmission">
    <actuator name="back_bky_motor"/>
    <joint name="back_bky"/>
    <mechanicalReduction>1</mechanicalReduction>
  </transmission>
  <transmission name="back_bkx_trans" type="pr2_mechanism_model/SimpleTransmission">
    <actuator name="back_bkx_motor"/>
    <joint name="back_bkx"/>
    <mechanicalReduction>1</mechanicalReduction>
  </transmission>
  <transmission name="l_arm_elx_trans" type="pr2_mechanism_model/SimpleTransmission">
    <actuator name="l_arm_elx_motor"/>
    <joint name="l_arm_elx"/>
    <mechanicalReduction>1</mechanicalReduction>
  </transmission>
  <transmission name="l_arm_ely_trans" type="pr2_mechanism_model/SimpleTransmission">
    <actuator name="l_arm_ely_motor"/>
    <joint name="l_arm_ely"/>
    <mechanicalReduction>1</mechanicalReduction>
  </transmission>
  <transmission name="l_arm_mwx_trans" type="pr2_mechanism_model/SimpleTransmission">
    <actuator name="l_arm_mwx_motor"/>
    <joint name="l_arm_mwx"/>
    <mechanicalReduction>1</mechanicalReduction>
  </transmission>
  <transmission name="l_arm_shx_trans" type="pr2_mechanism_model/SimpleTransmission">
    <actuator name="l_arm_shx_motor"/>
    <joint name="l_arm_shx"/>
    <mechanicalReduction>1</mechanicalReduction>
  </transmission>
  <transmission name="l_arm_usy_trans" type="pr2_mechanism_model/SimpleTransmission">
    <actuator name="l_arm_usy_motor"/>
    <joint name="l_arm_usy"/>
    <mechanicalReduction>1</mechanicalReduction>
  </transmission>
  <transmission name="l_arm_uwy_trans" type="pr2_mechanism_model/SimpleTransmission">
    <actuator name="l_arm_uwy_motor"/>
    <joint name="l_arm_uwy"/>
    <mechanicalReduction>1</mechanicalReduction>
  </transmission>
  <transmission name="l_leg_kny_trans" type="pr2_mechanism_model/SimpleTransmission">
    <actuator name="l_leg_kny_motor"/>
    <joint name="l_leg_kny"/>
    <mechanicalReduction>1</mechanicalReduction>
  </transmission>
  <transmission name="l_leg_akx_trans" type="pr2_mechanism_model/SimpleTransmission">
    <actuator name="l_leg_akx_motor"/>
    <joint name="l_leg_akx"/>
    <mechanicalReduction>1</mechanicalReduction>
  </transmission>
  <transmission name="l_leg_hpy_trans" type="pr2_mechanism_model/SimpleTransmission">
    <actuator name="l_leg_hpy_motor"/>
    <joint name="l_leg_hpy"/>
    <mechanicalReduction>1</mechanicalReduction>
  </transmission>
  <transmission name="l_leg_hpx_trans" type="pr2_mechanism_model/SimpleTransmission">
    <actuator name="l_leg_hpx_motor"/>
    <joint name="l_leg_hpx"/>
    <mechanicalReduction>1</mechanicalReduction>
  </transmission>
  <transmission name="l_leg_aky_trans" type="pr2_mechanism_model/SimpleTransmission">
    <actuator name="l_leg_aky_motor"/>
    <joint name="l_leg_aky"/>
    <mechanicalReduction>1</mechanicalReduction>
  </transmission>
  <transmission name="l_leg_hpz_trans" type="pr2_mechanism_model/SimpleTransmission">
    <actuator name="l_leg_hpz_motor"/>
    <joint name="l_leg_hpz"/>
    <mechanicalReduction>1</mechanicalReduction>
  </transmission>
  <transmission name="neck_ay_trans" type="pr2_mechanism_model/SimpleTransmission">
    <actuator name="neck_ay_motor"/>
    <joint name="neck_ay"/>
    <mechanicalReduction>1</mechanicalReduction>
  </transmission>
  <transmission name="r_arm_elx_trans" type="pr2_mechanism_model/SimpleTransmission">
    <actuator name="r_arm_elx_motor"/>
    <joint name="r_arm_elx"/>
    <mechanicalReduction>1</mechanicalReduction>
  </transmission>
  <transmission name="r_arm_ely_trans" type="pr2_mechanism_model/SimpleTransmission">
    <actuator name="r_arm_ely_motor"/>
    <joint name="r_arm_ely"/>
    <mechanicalReduction>1</mechanicalReduction>
  </transmission>
  <transmission name="r_arm_mwx_trans" type="pr2_mechanism_model/SimpleTransmission">
    <actuator name="r_arm_mwx_motor"/>
    <joint name="r_arm_mwx"/>
    <mechanicalReduction>1</mechanicalReduction>
  </transmission>
  <transmission name="r_arm_shx_trans" type="pr2_mechanism_model/SimpleTransmission">
    <actuator name="r_arm_shx_motor"/>
    <joint name="r_arm_shx"/>
    <mechanicalReduction>1</mechanicalReduction>
  </transmission>
  <transmission name="r_arm_usy_trans" type="pr2_mechanism_model/SimpleTransmission">
    <actuator name="r_arm_usy_motor"/>
    <joint name="r_arm_usy"/>
    <mechanicalReduction>1</mechanicalReduction>
  </transmission>
  <transmission name="r_arm_uwy_trans" type="pr2_mechanism_model/SimpleTransmission">
    <actuator name="r_arm_uwy_motor"/>
    <joint name="r_arm_uwy"/>
    <mechanicalReduction>1</mechanicalReduction>
  </transmission>
  <transmission name="r_leg_kny_trans" type="pr2_mechanism_model/SimpleTransmission">
    <actuator name="r_leg_kny_motor"/>
    <joint name="r_leg_kny"/>
    <mechanicalReduction>1</mechanicalReduction>
  </transmission>
  <transmission name="r_leg_akx_trans" type="pr2_mechanism_model/SimpleTransmission">
    <actuator name="r_leg_akx_motor"/>
    <joint name="r_leg_akx"/>
    <mechanicalReduction>1</mechanicalReduction>
  </transmission>
  <transmission name="r_leg_hpy_trans" type="pr2_mechanism_model/SimpleTransmission">
    <actuator name="r_leg_hpy_motor"/>
    <joint name="r_leg_hpy"/>
    <mechanicalReduction>1</mechanicalReduction>
  </transmission>
  <transmission name="r_leg_hpx_trans" type="pr2_mechanism_model/SimpleTransmission">
    <actuator name="r_leg_hpx_motor"/>
    <joint name="r_leg_hpx"/>
    <mechanicalReduction>1</mechanicalReduction>
  </transmission>
  <transmission name="r_leg_aky_trans" type="pr2_mechanism_model/SimpleTransmission">
    <actuator name="r_leg_aky_motor"/>
    <joint name="r_leg_aky"/>
    <mechanicalReduction>1</mechanicalReduction>
  </transmission>
  <transmission name="r_leg_hpz_trans" type="pr2_mechanism_model/SimpleTransmission">
    <actuator name="r_leg_hpz_motor"/>
    <joint name="r_leg_hpz"/>
    <mechanicalReduction>1</mechanicalReduction>
  </transmission>
</robot>
