<robot name="simple_cylinder">
  <link name="world"/>
  <joint name="my_cylinder_joint" type="continuous" >
    <!-- axis is in the parent link frame coordintates -->
    <axis xyz="0 1 0" />
    <parent link="world" />
    <child link="my_cylinder" />
    <!-- initial pose of my_cylinder in the parent frame coordiantes -->
    <origin xyz="0 0 0" rpy="0 1.57 0.5" />
  </joint>
  <link name="my_cylinder">
    <inertial>
      <mass value="1.0" />
      <!-- center of mass (com) is defined w.r.t. link local coordinate system -->
      <origin xyz="0 0 0.5" /> 
      <inertia  ixx="1.0" ixy="0.0"  ixz="0.0"  iyy="100.0"  iyz="0.0"  izz="1.0" />
    </inertial>
    <visual>
      <!-- visual origin is defined w.r.t. link local coordinate system -->
      <origin xyz="0 0 0.5" rpy="0 0 0" />
      <geometry>
        <cylinder radius="0.05" length="1.0" />
      </geometry>
    </visual>
    <collision>
      <!-- collision origin is defined w.r.t. link local coordinate system -->
      <origin xyz="0 0 0.5" rpy="0 0 0 " />
      <geometry>
        <cylinder radius="0.05" length="1.0" />
      </geometry>
    </collision>
  </link>
  <gazebo reference="my_cylinder">
    <material>Gazebo/Blue</material>
    <turnGravityOff>false</turnGravityOff>
  </gazebo>
</robot>
