<robot name="simple_box">
  <link name="world"/>
  <joint name="my_box_joint" type="continuous" >
    <!-- axis is in the parent link frame coordintates -->
    <axis xyz="0 1 0" />
    <parent link="world" />
    <child link="my_box" />
    <!-- initial pose of my_box joint/link in the parent frame coordiantes -->
    <origin xyz="0 0 2" rpy="0 0 0" />
  </joint>
  <link name="my_box">
    <inertial>
      <mass value="1.0" />
      <!-- center of mass (com) is defined w.r.t. link local coordinate system -->
      <origin xyz="1 0 0" /> 
      <inertia  ixx="1.0" ixy="0.0"  ixz="0.0"  iyy="100.0"  iyz="0.0"  izz="1.0" />
    </inertial>
    <visual>
      <!-- visual origin is defined w.r.t. link local coordinate system -->
      <origin xyz="1 0 0" rpy="0 0 0" />
      <geometry>
        <box size="0.05 0.05 0.10" />
      </geometry>
    </visual>
    <collision>
      <!-- collision origin is defined w.r.t. link local coordinate system -->
      <origin xyz="1 0 0" rpy="0 0 0 " />
      <geometry>
        <box size="0.05 0.05 0.10" />
      </geometry>
    </collision>
  </link>
  <gazebo reference="my_box">
    <material>Gazebo/Blue</material>
    <turnGravityOff>false</turnGravityOff>
  </gazebo>
</robot>
