<?xml version="1.0" ?>
<gazebo version='1.2'>
  <model name='mit_golf_cart'>
    <link name='chassis'>
      <!-- mesh width 51.1811 -->
      <!-- mesh height 99.8878 -->
      <!-- mesh origin at corner -->
      <inertial>
        <mass>840</mass>
        <pose>0 0 0 0 0 0</pose>
        <inertia>
          <ixx>160</ixx>
          <ixy>0</ixy>
          <ixz>0</ixz>
          <iyy>630</iyy>
          <iyz>0</iyz>
          <izz>630</izz>
        </inertia>
      </inertial>
      <!-- decompose into simple geom
      <collision name='chassis_collision'>
        <pose>-1.498 -0.7677165 0.200000 0.000000 -0.000000 -1.57079</pose>
        <geometry>
          <mesh>
            <uri>model://golf_cart/meshes/no_wheels.dae</uri>
            <scale>0.030 0.030 0.030</scale>
          </mesh>
        </geometry>
      </collision>
      -->

      <visual name='chassis_visual'>
        <pose>-2.28 -1.18 0.200000 0.000000 -0.000000 -1.57079</pose>
        <geometry>
          <mesh>
            <uri>model://mit_golf_cart/meshes/no_wheels.dae</uri>
            <scale>0.045 0.045 0.045</scale>
          </mesh>
        </geometry>
      </visual>

      <!-- chassis base visual
      <visual name='chassis_base_vis'>
        <pose>0.0 0.0 0.425000 0.000000 0 0</pose>
        <geometry>
          <box>
            <size>4.3 2.4 0.135</size>
          </box>
        </geometry>
      </visual>
      -->

      <collision name='chassis_base_col'>
        <pose>0.0 0.0 0.425000 0.000000 0 0</pose>
        <geometry>
          <box>
            <size>4.3 2.4 0.135</size>
          </box>
        </geometry>
        <surface>
          <contact>
            <ode>
              <max_vel>1</max_vel>
              <min_depth>0.01</min_depth>
            </ode>
          </contact>
        </surface>
      </collision>

      <!-- box seat
      <visual name='chassis_seat_vis'>
        <pose>0.55 0.0 0.60000 0.000000 0 0</pose>
        <geometry>
          <box>
            <size>0.45 2.4 0.4</size>
          </box>
        </geometry>
      </visual>
      -->
      <collision name='chassis_seat_col'>
        <pose>0.55 0.0 0.60000 0.000000 0 0</pose>
        <geometry>
          <box>
            <size>0.45 2.4 0.4</size>
          </box>
        </geometry>
        <surface>
          <contact>
            <ode>
              <max_vel>0</max_vel>
              <min_depth>0.10</min_depth>
            </ode>
          </contact>
        </surface>
      </collision>

      <!-- box seat back
      <visual name='chassis_seat_back_vis'>
        <pose>0.35 0.0 1.05000 0.000000 0 0</pose>
        <geometry>
          <box>
            <size>0.05 2.4 0.6</size>
          </box>
        </geometry>
      </visual>
      -->
      <collision name='chassis_seat_back_col'>
        <pose>0.35 0.0 1.05000 0.000000 0 0</pose>
        <geometry>
          <box>
            <size>0.05 2.4 0.6</size>
          </box>
        </geometry>
      </collision>

      <!-- box back seat
      <visual name='chassis_back_seat_vis'>
        <pose>-0.88 0.0 0.60000 0.000000 0 0</pose>
        <geometry>
          <box>
            <size>0.45 2.4 0.4</size>
          </box>
        </geometry>
      </visual>
      -->
      <collision name='chassis_back_seat_col'>
        <pose>-0.88 0.0 0.60000 0.000000 0 0</pose>
        <geometry>
          <box>
            <size>0.45 2.4 0.4</size>
          </box>
        </geometry>
      </collision>

      <!-- box back seat back
      <visual name='chassis_back_seat_back_vis'>
        <pose>-1.08 0.0 1.05000 0.000000 0 0</pose>
        <geometry>
          <box>
            <size>0.05 2.4 0.6</size>
          </box>
        </geometry>
      </visual>
      -->
      <collision name='chassis_back_seat_back_col'>
        <pose>-1.08 0.0 1.05000 0.000000 0 0</pose>
        <geometry>
          <box>
            <size>0.05 2.4 0.6</size>
          </box>
        </geometry>
      </collision>

      <velocity_decay>0.01</velocity_decay>
    </link>

    <link name='front_left_wheel_steering_block'>
      <pose>1.800000 1.017700 0.300000 -0.000000 1.570700 1.570700</pose>
      <inertial>
        <mass>10</mass>
        <pose>0 0 0 0 0 0</pose>
        <inertia>
          <ixx>1</ixx>
          <ixy>0</ixy>
          <ixz>0</ixz>
          <iyy>1</iyy>
          <iyz>0</iyz>
          <izz>1</izz>
        </inertia>
      </inertial>
      <collision name='front_left_wheel_collision'>
        <geometry>
          <cylinder>
            <radius>0.050000</radius>
            <length>0.010000</length>
          </cylinder>
        </geometry>
      </collision>
      <visual name='front_left_wheel_visual'>
        <geometry>
          <cylinder>
            <radius>0.050000</radius>
            <length>0.010000</length>
          </cylinder>
        </geometry>
        <material>
          <script>
            <uri>file://media/materials/scripts/gazebo.material</uri>
            <name>Gazebo/Black</name>
          </script>
        </material>
      </visual>
      <velocity_decay/>
    </link>
    <link name='front_left_wheel'>
      <pose>1.800000 1.117700 0.300000 -0.000000 1.570700 1.570700</pose>
      <inertial>
        <mass>10</mass>
        <pose>0 0 0 0 0 0</pose>
        <inertia>
          <ixx>1</ixx>
          <ixy>0</ixy>
          <ixz>0</ixz>
          <iyy>1</iyy>
          <iyz>0</iyz>
          <izz>1</izz>
        </inertia>
      </inertial>
      <collision name='front_left_wheel_collision'>
        <geometry>
          <cylinder>
            <radius>0.320000</radius>
            <length>0.100000</length>
          </cylinder>
        </geometry>
      </collision>
      <visual name='front_left_wheel_visual'>
        <geometry>
          <cylinder>
            <radius>0.320000</radius>
            <length>0.100000</length>
          </cylinder>
        </geometry>
        <material>
          <script>
            <uri>file://media/materials/scripts/gazebo.material</uri>
            <name>Gazebo/PaintedWall</name>
          </script>
        </material>
      </visual>
      <velocity_decay/>
    </link>

    <link name='front_right_wheel_steering_block'>
      <pose>1.800000 -1.017700 0.300000 -0.000000 1.570700 1.570700</pose>
      <inertial>
        <mass>10</mass>
        <pose>0 0 0 0 0 0</pose>
        <inertia>
          <ixx>1</ixx>
          <ixy>0</ixy>
          <ixz>0</ixz>
          <iyy>1</iyy>
          <iyz>0</iyz>
          <izz>1</izz>
        </inertia>
      </inertial>
      <collision name='front_right_wheel_collision'>
        <geometry>
          <cylinder>
            <radius>0.050000</radius>
            <length>0.010000</length>
          </cylinder>
        </geometry>
      </collision>
      <visual name='front_right_wheel_visual'>
        <geometry>
          <cylinder>
            <radius>0.050000</radius>
            <length>0.010000</length>
          </cylinder>
        </geometry>
        <material>
          <script>
            <uri>file://media/materials/scripts/gazebo.material</uri>
            <name>Gazebo/Black</name>
          </script>
        </material>
      </visual>
      <velocity_decay/>
    </link>
    <link name='front_right_wheel'>
      <pose>1.800000 -1.117700 0.300000 -0.000000 1.570700 1.570700</pose>
      <inertial>
        <mass>10</mass>
        <pose>0 0 0 0 0 0</pose>
        <inertia>
          <ixx>1</ixx>
          <ixy>0</ixy>
          <ixz>0</ixz>
          <iyy>1</iyy>
          <iyz>0</iyz>
          <izz>1</izz>
        </inertia>
      </inertial>
      <collision name='front_right_wheel_collision'>
        <geometry>
          <cylinder>
            <radius>0.320000</radius>
            <length>0.100000</length>
          </cylinder>
        </geometry>
      </collision>
      <visual name='front_right_wheel_visual'>
        <geometry>
          <cylinder>
            <radius>0.320000</radius>
            <length>0.100000</length>
          </cylinder>
        </geometry>
        <material>
          <script>
            <uri>file://media/materials/scripts/gazebo.material</uri>
            <name>Gazebo/PaintedWall</name>
          </script>
        </material>
      </visual>
      <velocity_decay/>
    </link>

    <link name='back_right_wheel'>
      <pose>-1.250000 -1.117700 0.300000 -0.000000 1.570700 1.570700</pose>
      <inertial>
        <mass>10</mass>
        <pose>0 0 0 0 0 0</pose>
        <inertia>
          <ixx>1</ixx>
          <ixy>0</ixy>
          <ixz>0</ixz>
          <iyy>1</iyy>
          <iyz>0</iyz>
          <izz>1</izz>
        </inertia>
      </inertial>
      <collision name='back_right_wheel_collision'>
        <geometry>
          <cylinder>
            <radius>0.320000</radius>
            <length>0.100000</length>
          </cylinder>
        </geometry>
      </collision>
      <visual name='back_right_wheel_visual'>
        <geometry>
          <cylinder>
            <radius>0.320000</radius>
            <length>0.100000</length>
          </cylinder>
        </geometry>
        <material>
          <script>
            <uri>file://media/materials/scripts/gazebo.material</uri>
            <name>Gazebo/PaintedWall</name>
          </script>
        </material>
      </visual>
      <velocity_decay/>
    </link>
    <link name='back_left_wheel'>
      <pose>-1.250000 1.117700 0.300000 -0.000000 1.570700 1.570700</pose>
      <inertial>
        <mass>10</mass>
        <pose>0 0 0 0 0 0</pose>
        <inertia>
          <ixx>1</ixx>
          <ixy>0</ixy>
          <ixz>0</ixz>
          <iyy>1</iyy>
          <iyz>0</iyz>
          <izz>1</izz>
        </inertia>
      </inertial>
      <collision name='back_left_wheel_collision'>
        <geometry>
          <cylinder>
            <radius>0.320000</radius>
            <length>0.100000</length>
          </cylinder>
        </geometry>
      </collision>
      <visual name='back_left_wheel_visual'>
        <geometry>
          <cylinder>
            <radius>0.320000</radius>
            <length>0.100000</length>
          </cylinder>
        </geometry>
        <material>
          <script>
            <uri>file://media/materials/scripts/gazebo.material</uri>
            <name>Gazebo/PaintedWall</name>
          </script>
        </material>
      </visual>
      <velocity_decay/>
    </link>

    <link name='gas_pedal'>
      <pose>1.150000 0.300000 0.660000 0.000000 -0.5 0.000000</pose>
      <gravity>false</gravity>
      <inertial>
        <mass>1.0</mass>
        <pose>0 0 0 0 0 0</pose>
        <inertia>
          <ixx>0.01</ixx>
          <ixy>0</ixy>
          <ixz>0</ixz>
          <iyy>0.01</iyy>
          <iyz>0</iyz>
          <izz>0.01</izz>
        </inertia>
      </inertial>
      <collision name='gas_pedal_collision'>
        <geometry>
          <box>
            <size>0.280000 0.070000 0.030000</size>
          </box>
        </geometry>
      </collision>
      <visual name='gas_pedal_visual'>
        <geometry>
          <box>
            <size>0.280000 0.070000 0.030000</size>
          </box>
        </geometry>
        <material>
          <script>
            <uri>file://media/materials/scripts/gazebo.material</uri>
            <name>Gazebo/Wood</name>
          </script>
          <ambient>0.2 0.2 0.2 1</ambient>
          <diffuse>0.2 0.2 0.2 1</diffuse>
          <specular>0.2 0.2 0.2 1</specular>
          <emissive>0.5 0.5 0.5 1</emissive>
        </material>
      </visual>
      <velocity_decay/>
    </link>

    <link name='brake_pedal'>
      <gravity>false</gravity>
      <pose>1.280000 0.550000 0.730000 0.000000 0.300000 0.000000</pose>
      <inertial>
        <mass>1</mass>
        <pose>0 0 0 0 0 0</pose>
        <inertia>
          <ixx>0.01</ixx>
          <ixy>0</ixy>
          <ixz>0</ixz>
          <iyy>0.01</iyy>
          <iyz>0</iyz>
          <izz>0.01</izz>
        </inertia>
      </inertial>
      <collision name='brake_pedal_collision'>
        <geometry>
          <box>
            <size>0.020000 0.140000 0.050000</size>
          </box>
        </geometry>
      </collision>
      <visual name='brake_pedal_visual'>
        <geometry>
          <box>
            <size>0.020000 0.140000 0.050000</size>
          </box>
        </geometry>
        <material>
          <script>
            <uri>file://media/materials/scripts/gazebo.material</uri>
            <name>Gazebo/Wood</name>
          </script>
          <ambient>0.2 0.2 0.2 1</ambient>
          <diffuse>0.2 0.2 0.2 1</diffuse>
          <specular>0.2 0.2 0.2 1</specular>
          <emissive>0.5 0.5 0.5 1</emissive>
        </material>
      </visual>
      <velocity_decay/>
    </link>

    <link name='steering_wheel'>

      <pose>1.130000 0.4950000 1.300000 -.2293915 0.0 -1.5200000</pose>

      <inertial>
        <mass>1.0</mass>
        <pose>0 0 0 0 0 0</pose>
        <inertia>
          <ixx>0.1</ixx>
          <ixy>0</ixy>
          <ixz>0</ixz>
          <iyy>0.1</iyy>
          <iyz>0</iyz>
          <izz>1.0</izz>
        </inertia>
      </inertial>
      <collision name='steering_wheel_collision'>

        <pose>-0.22 0.00 -0.22 0.0 0.00 0.00</pose>
        <geometry>
          <mesh>
            <uri>model://modified_golf_cart/meshes/SimpleSteeringWheel_3.STL</uri>
            <scale>0.001 0.001 0.001</scale>
          </mesh>
	</geometry>

      </collision>

      <visual name='steering_wheel_visual'>
	<pose>-0.22 0.00 -0.22 0.0 0.00 0.00</pose>
        <geometry> 
          <mesh>                                                                                                
            <uri>model://modified_golf_cart/meshes/SimpleSteeringWheel_3.STL</uri>                            
	    <scale>0.001 0.001 0.001</scale>                                                                    
          </mesh>                                                                                               
        </geometry>


        <material>
          <script>
            <uri>file://media/materials/scripts/gazebo.material</uri>
            <name>Gazebo/Wood</name>
          </script>
          <ambient>0.2 0.2 0.2 1</ambient>
          <diffuse>0.2 0.2 0.2 1</diffuse>
          <specular>0.2 0.2 0.2 1</specular>
          <emissive>0.5 0.5 0.5 1</emissive>
        </material>
      </visual>
      <velocity_decay>0.1</velocity_decay>
    </link>
    <link name='hand_brake'>
      <pose>1.35 0.0 1.300000 0.000000 2.8 0.000000</pose>
      <inertial>
        <mass>1.0</mass>
        <pose>0 0 -0.15 0 0 0</pose>
        <inertia>
          <ixx>0.1</ixx>
          <ixy>0</ixy>
          <ixz>0</ixz>
          <iyy>0.1</iyy>
          <iyz>0</iyz>
          <izz>1.0</izz>
        </inertia>
      </inertial>
      <collision name="hand_brake_collision">
        <pose>0 0 -0.15 0 0 0</pose>
        <geometry>
          <cylinder>
            <radius>0.02</radius>
            <length>0.3</length>
          </cylinder>
        </geometry>
      </collision>
      <visual name="hand_brake_visual">
        <pose>0 0 -0.15 0 0 0</pose>
        <geometry>
          <cylinder>
            <radius>0.02</radius>
            <length>0.3</length>
          </cylinder>
        </geometry>
        <material>
          <script>
            <uri>file://media/materials/scripts/gazebo.material</uri>
            <name>Gazebo/Wood</name>
          </script>
        </material>
      </visual>
    </link>
    <joint name='gas_joint' type='prismatic'>
      <parent>chassis</parent>
      <child>gas_pedal</child>
      <axis>
        <xyz>1.000000 0.000000 -1.000000</xyz>
        <limit>
          <lower>0.000000</lower>
          <upper>0.090000</upper>
        </limit>
      </axis>
    </joint>
    <joint name='brake_joint' type='prismatic'>
      <parent>chassis</parent>
      <child>brake_pedal</child>
      <axis>
        <xyz>1.000000 0.000000 -0.600000</xyz>
        <limit>
          <lower>0.000000</lower>
          <upper>0.100000</upper>
        </limit>
      </axis>
    </joint>
    <joint name='steering_joint' type='revolute'>
      <parent>chassis</parent>
      <child>steering_wheel</child>
      <axis>
        <xyz>-4.286262 0.000000 1.000000</xyz>
        <limit>
          <lower>-7.853000</lower>
          <upper>7.853000</upper>
        </limit>
      </axis>
    </joint>
    <joint name='hand_brake_joint' type='revolute'>
      <parent>chassis</parent>
      <child>hand_brake</child>
      <axis>
        <xyz>0.0 -1.0 0.0</xyz>
        <limit>
          <lower>0</lower>
          <upper>1</upper>
        </limit>
      </axis>
    </joint>

    <joint name='front_right_steering_joint' type='revolute'>
      <parent>chassis</parent>
      <child>front_right_wheel_steering_block</child>
      <axis>
        <xyz>0.000000 0.000000 1.000000</xyz>
        <limit>
          <lower>-1.000000</lower>
          <upper>1.000000</upper>
        </limit>
      </axis>
      <physics>
        <ode>
          <limit>
            <cfm>0.000000</cfm>
            <erp>0.900000</erp>
          </limit>
        </ode>
      </physics>
    </joint>

    <joint name='front_left_steering_joint' type='revolute'>
      <parent>chassis</parent>
      <child>front_left_wheel_steering_block</child>
      <axis>
        <xyz>0.000000 0.000000 1.000000</xyz>
        <limit>
          <lower>-1.000000</lower>
          <upper>1.000000</upper>
        </limit>
      </axis>
      <physics>
        <ode>
          <limit>
            <cfm>0.000000</cfm>
            <erp>0.900000</erp>
          </limit>
        </ode>
      </physics>
    </joint>

    <joint name='front_left_joint' type='revolute'>
      <parent>front_left_wheel_steering_block</parent>
      <child>front_left_wheel</child>
      <axis>
        <xyz>0.000000 1.000000 0.000000</xyz>
      </axis>
      <physics>
        <ode>
          <limit>
            <cfm>0.000000</cfm>
            <erp>0.900000</erp>
          </limit>
        </ode>
      </physics>
    </joint>

    <joint name='front_right_joint' type='revolute'>
      <parent>front_right_wheel_steering_block</parent>
      <child>front_right_wheel</child>
      <axis>
        <xyz>0.000000 1.000000 0.000000</xyz>
      </axis>
      <physics>
        <ode>
          <limit>
            <cfm>0.000000</cfm>
            <erp>0.900000</erp>
          </limit>
        </ode>
      </physics>
    </joint>
    <joint name='back_right_joint' type='revolute'>
      <parent>chassis</parent>
      <child>back_right_wheel</child>
      <axis>
        <xyz>0.000000 1.000000 0.000000</xyz>
      </axis>
      <physics>
        <ode>
          <limit>
            <cfm>0.000000</cfm>
            <erp>0.900000</erp>
          </limit>
        </ode>
      </physics>
    </joint>
    <joint name='back_left_joint' type='revolute'>
      <parent>chassis</parent>
      <child>back_left_wheel</child>
      <axis>
        <xyz>0.000000 1.000000 0.000000</xyz>
      </axis>
      <physics>
        <ode>
          <limit>
            <cfm>0.000000</cfm>
            <erp>0.900000</erp>
          </limit>
        </ode>
      </physics>
    </joint>
    <plugin name='vehicle' filename='libDRCVehicleROSPlugin.so'>
      <front_left_wheel>front_left_joint</front_left_wheel>
      <front_right_wheel>front_right_joint</front_right_wheel>
      <front_left_wheel_steering>front_left_steering_joint</front_left_wheel_steering>
      <front_right_wheel_steering>front_right_steering_joint</front_right_wheel_steering>
      <back_left_wheel>back_left_joint</back_left_wheel>
      <back_right_wheel>back_right_joint</back_right_wheel>
      <gas_pedal>gas_joint</gas_pedal>
      <brake_pedal>brake_joint</brake_pedal>
      <steering_wheel>steering_joint</steering_wheel>
      <hand_brake>hand_brake_joint</hand_brake>
      <front_torque>0</front_torque>
      <back_torque>2000</back_torque>
      <front_brake_torque>2000</front_brake_torque>
      <back_brake_torque>2000</back_brake_torque>
      <tire_angle_range>0.5</tire_angle_range>
      <max_speed>10</max_speed>
      <aero_load>0.1</aero_load>
    </plugin>
  </model>
</gazebo>
