<?xml version="1.0"?>
<robot name="steering_assembly">

<param name="mass" default_value="5.0"/>

  <link name="world">
  </link>
  <link name="steering_base">
    <inertial>
      <mass value="500"/>
      <origin rpy="0 0 0" xyz="0 0 0"/>
      <inertia ixx="10" ixy="0" ixz="0" iyy="10" iyz="0" izz="10"/>
    </inertial>
    <visual>
      <origin rpy="1.570 0 0" xyz="0 0 0"/>
      <geometry>
	<mesh filename="package://steering_assembly/meshes/SteeringWheelPost_3.STL" scale="0.001 0.001 0.001"/>
      </geometry>
    </visual>
    <collision>
      <origin rpy="1.570 0 0" xyz="0 0 0"/>
      <geometry>
	<mesh filename="package://steering_assembly/meshes/SteeringWheelPost_3.STL" scale="0.001 0.001 0.001"/>
      </geometry>
    </collision>
  </link>
  
  <link name="steering_wheel">
    <inertial>
      <mass value="5"/>
      <origin rpy="0 3.14 0" xyz="0 0 0"/>
      <inertia ixx="1.0" ixy="0" ixz="0" iyy="10.0" iyz="0" izz="1.0"/>                                                 
    </inertial>
    <visual>
      <origin rpy="0 03.14 0" xyz=".22 0 .220"/>
      <geometry>
	<mesh filename="package://steering_assembly/meshes/SimpleSteeringWheel_3.STL" scale="0.001 0.001 0.001"/>
      </geometry>
    </visual>
    <collision>
      <origin rpy="0 3.14 0" xyz=".22 0 .220"/>
      <geometry>
	<mesh filename="package://steering_assembly/meshes/SimpleSteeringWheel_3.STL" scale="0.001 0.001 0.001"/>
      </geometry>
    </collision>
  </link>

  <joint name="base_to_steering" type="continuous">
    <origin rpy="0 0 0" xyz="0.1524 0 1.3208 "/>
    <axis xyz="0 1 0"/>
    <parent link="steering_base"/>
    <child link="steering_wheel"/>
    <limit effort="5" velocity="12"/>
    <safety_controller k_position="100" k_velocity="100.0" soft_lower_limit="-9.2146" soft_upper_limit="10.7854"/>
  </joint>

  <joint name="grounded" type="fixed">
    <parent link="world"/>
    <child link="steering_base"/>
  </joint>
  

</robot>
      
  