<?xml version="1.0" ?>
<!-- =================================================================================== -->
<!-- |    This document was autogenerated by xacro from WheeledAtlas.urdf.xacro        | -->
<!-- |    EDITING THIS FILE BY HAND IS NOT RECOMMENDED                                 | -->
<!-- =================================================================================== -->
<robot name="wheeled_atlas" xmlns:controller="http://playerstage.sourceforge.net/gazebo/xmlschema/#controller" xmlns:interface="http://playerstage.sourceforge.net/gazebo/xmlschema/#interface" xmlns:sensor="http://playerstage.sourceforge.net/gazebo/xmlschema/#sensor" xmlns:xacro="http://ros.org/wiki/xacro">
  <!--Properties of the robot-->
  <!--Inertial element for cylinder, axis along z-->
  <!--Inertial element for a box-->
  <!--Create the visual element for a cylinder-->
  <!--Create the visual element for a box-->
  <!--Creates a link in the form of a cylinder-->
  <!--Creates a link in the form of a box-->
  <!--Creates a simple joint between two cylindrical links.-->
  <!--Creates a simple joint between two cylindrical links.-->
  <!--Creates a simple fixed joint-->
  <!--Creates a left and a right of some cylinder-->
  <!--Creates a left and a right of some cylinder-->
  <!--Creates a SIMPLE left and a right joints-->
  <!--Creates a COMPLEX left and a right joints-->
  <!--Creates a COMPLEX left and a right joints-->
  <!--Creates two fixed joints-->
  <!--Creates a transmission at a joint.-->
  <!--Creates a pair of transmissions-->

  <material name="LightGrey">
    <color rgba="0.8 0.8 0.8 1.0"/>
  </material>
  <material name="Grey">
    <color rgba="0.6 0.6 0.6 1.0"/>
  </material>
  <material name="DarkGrey">
    <color rgba="0.3 0.3 0.3 1.0"/>
  </material>
  <material name="Black">
    <color rgba="0.1 0.1 0.1 1.0"/>
  </material>

 <link name="base_link">
    <inertial>
      <origin rpy="0 0 0" xyz="0 0 0"/>
      <mass value=".01"/>
      <inertia ixx=".0001" ixy="0" ixz="0" iyy=".0001" iyz="0" izz=".001"/>
    </inertial>
  </link>

<link name="Torso">
    <!-- assuming the rotational inertia of the torso is of a cuboid -->
    <inertial>
      <mass value="19.267"/>
      <inertia ixx="0.769042349872" ixy="0.0" ixz="0.0" iyy="0.418881944536" iyz="0.0" izz="0.452546488768"/>
    </inertial>
    <visual>
      <origin rpy="0 0 0" xyz="0.0 0.0 0.43927308"/>
      <geometry>
        <cylinder length="0.97854616" radius="0.025"/>
      </geometry>
      <material name="LightGrey"/>
    </visual>
    <collision>
      <origin rpy="0 0 0" xyz="0.0 0.0 0.43927308"/>
      <geometry>
        <box size=" 0.178562 0.4999736 0.97854616"/>
      </geometry>
    </collision>
  </link>

<link name="NeckYaw_link">
    <inertial>
      <origin rpy="0 0 0" xyz="0 0 0"/>
      <mass value="0.01"/>
      <inertia ixx="0.0001" ixy="0.0" ixz="0.0" iyy="0.0001" iyz="0.0" izz="0.0001"/>
    </inertial>
  </link>
  <link name="NeckPitch_link">
    <inertial>
      <mass value="1.8"/>
      <inertia ixx="0.0106054249402" ixy="0.0" ixz="0.0" iyy="0.0106054249402" iyz="0.0" izz="0.00403536783651"/>
    </inertial>
    <visual>
      <origin rpy="1.57079632679 0 0" xyz="0 0 0.13749274"/>
      <geometry>
        <cylinder length="0.22141688" radius="0.06696075"/>
        <!--  <sphere radius="${(l_head/2)*height}"/>-->
      </geometry>
      <material name="LightGrey"/>
    </visual>
    <collision>
      <origin rpy="1.57 0 0" xyz="0 0 0.13749274"/>
      <geometry>
        <cylinder length="0.23927308" radius="0.06696075"/>
      </geometry>
    </collision>
  </link>
  <link name="LShoulderYaw_link">
    <inertial>
      <origin rpy="0 0 0" xyz="0 0 0"/>
      <mass value="0.01"/>
      <inertia ixx="0.0001" ixy="0.0" ixz="0.0" iyy="0.0001" iyz="0.0" izz="0.0001"/>
    </inertial>
  </link>
  <link name="LShoulderPitch_link">
    <inertial>
      <origin rpy="0 0 0" xyz="0 0 0"/>
      <mass value="0.01"/>
      <inertia ixx="0.0001" ixy="0.0" ixz="0.0" iyy="0.0001" iyz="0.0" izz="0.0001"/>
    </inertial>
  </link>
  <link name="LShoulderRoll_link">
    <inertial>
      <mass value="4.91675"/>
      <inertia ixx="0.0500676407308" ixy="0.0" ixz="0.0" iyy="0.0500676407308" iyz="0.0" izz="0.00078383781966"/>
    </inertial>
    <visual>
      <origin rpy="0 0 0" xyz="0 0 -0.17409795"/>
      <geometry>
        <cylinder length="0.3081959" radius="0.025"/>
      </geometry>
      <material name="LightGrey"/>
    </visual>
    <collision>
      <origin rpy="0 0 0" xyz="0 0 -0.17409795"/>
      <geometry>
        <cylinder length="0.3481959" radius="0.025"/>
      </geometry>
    </collision>
  </link>
  <link name="LElbowPitch_link">
    <inertial>
      <mass value="4.91675"/>
      <inertia ixx="0.0381467738901" ixy="0.0" ixz="0.0" iyy="0.0381467738901" iyz="0.0" izz="0.00078383781966"/>
    </inertial>
    <visual>
      <origin rpy="0 0 0" xyz="0 0 -0.1517777"/>
      <geometry>
        <cylinder length="0.2635554" radius="0.025"/>
      </geometry>
      <material name="LightGrey"/>
    </visual>
    <collision>
      <origin rpy="0 0 0" xyz="0 0 -0.1517777"/>
      <geometry>
        <cylinder length="0.3035554" radius="0.025"/>
      </geometry>
    </collision>
  </link>
  <link name="LWristYaw_link">
    <inertial>
      <origin rpy="0 0 0" xyz="0 0 0"/>
      <mass value="0.01"/>
      <inertia ixx="0.0001" ixy="0.0" ixz="0.0" iyy="0.0001" iyz="0.0" izz="0.0001"/>
    </inertial>
  </link>
  <link name="LWristRoll_link">
    <inertial>
      <mass value="0.01"/>
      <inertia ixx="2.01752715335e-05" ixy="0.0" ixz="0.0" iyy="2.01752715335e-05" iyz="0.0" izz="1.5942193922e-06"/>
    </inertial>
    <visual>
      <origin rpy="0 0 0" xyz="0 0 -0.076245974"/>
      <geometry>
        <cylinder length="0.112491948" radius="0.025"/>
      </geometry>
      <material name="LightGrey"/>
    </visual>
    <collision>
      <origin rpy="0 0 0" xyz="0 0 -0.076245974"/>
      <geometry>
        <cylinder length="0.152491948" radius="0.025"/>
      </geometry>
    </collision>
  </link>
  <link name="RShoulderYaw_link">
    <inertial>
      <origin rpy="0 0 0" xyz="0 0 0"/>
      <mass value="0.01"/>
      <inertia ixx="0.0001" ixy="0.0" ixz="0.0" iyy="0.0001" iyz="0.0" izz="0.0001"/>
    </inertial>
  </link>
  <link name="RShoulderPitch_link">
    <inertial>
      <origin rpy="0 0 0" xyz="0 0 0"/>
      <mass value="0.01"/>
      <inertia ixx="0.0001" ixy="0.0" ixz="0.0" iyy="0.0001" iyz="0.0" izz="0.0001"/>
    </inertial>
  </link>
  <link name="RShoulderRoll_link">
    <inertial>
      <mass value="4.91675"/>
      <inertia ixx="0.0500676407308" ixy="0.0" ixz="0.0" iyy="0.0500676407308" iyz="0.0" izz="0.00078383781966"/>
    </inertial>
    <visual>
      <origin rpy="0 0 0" xyz="0 0 -0.17409795"/>
      <geometry>
        <cylinder length="0.3081959" radius="0.025"/>
      </geometry>
      <material name="LightGrey"/>
    </visual>
    <collision>
      <origin rpy="0 0 0" xyz="0 0 -0.17409795"/>
      <geometry>
        <cylinder length="0.3481959" radius="0.025"/>
      </geometry>
    </collision>
  </link>
  <link name="RElbowPitch_link">
    <inertial>
      <mass value="4.91675"/>
      <inertia ixx="0.0381467738901" ixy="0.0" ixz="0.0" iyy="0.0381467738901" iyz="0.0" izz="0.00078383781966"/>
    </inertial>
    <visual>
      <origin rpy="0 0 0" xyz="0 0 -0.1517777"/>
      <geometry>
        <cylinder length="0.2635554" radius="0.025"/>
      </geometry>
      <material name="LightGrey"/>
    </visual>
    <collision>
      <origin rpy="0 0 0" xyz="0 0 -0.1517777"/>
      <geometry>
        <cylinder length="0.3035554" radius="0.025"/>
      </geometry>
    </collision>
  </link>
  <link name="RWristYaw_link">
    <inertial>
      <origin rpy="0 0 0" xyz="0 0 0"/>
      <mass value="0.01"/>
      <inertia ixx="0.0001" ixy="0.0" ixz="0.0" iyy="0.0001" iyz="0.0" izz="0.0001"/>
    </inertial>
  </link>
  <link name="RWristRoll_link">
    <inertial>
      <mass value="0.01"/>
      <inertia ixx="2.01752715335e-05" ixy="0.0" ixz="0.0" iyy="2.01752715335e-05" iyz="0.0" izz="1.5942193922e-06"/>
    </inertial>
    <visual>
      <origin rpy="0 0 0" xyz="0 0 -0.076245974"/>
      <geometry>
        <cylinder length="0.112491948" radius="0.025"/>
      </geometry>
      <material name="LightGrey"/>
    </visual>
    <collision>
      <origin rpy="0 0 0" xyz="0 0 -0.076245974"/>
      <geometry>
        <cylinder length="0.152491948" radius="0.025"/>
      </geometry>
    </collision>
  </link>

  <!--   <link name="head">
    <inertial>
      <mass value="1.8"/>
      <inertia ixx="0.012" ixy="0" ixz="0" iyy="0.012" iyz="0" izz="0.012"/>
    </inertial>
    <visual>
      <origin rpy="0 0 0" xyz="0 0 0"/>
      <geometry>
        <sphere radius="0.1"/>
      </geometry>
      <material name="Lgrey">
        <color rgba=".6 .6 .6 1"/>
      </material>
    </visual>
  </link>
  <link name="Lhumerus">
    <inertial>
      <mass value="4.1"/>
      <inertia ixx="0.0402474900573" ixy="0" ixz="0" iyy="0.0402474900573" iyz="0" izz="0.00408235078125"/>
    </inertial>
    <visual>
      <origin rpy="0 0 0" xyz="0 0 -0.1672"/>
      <geometry>
        <cylinder length="0.3344" radius="0.044625"/>
      </geometry>
      <material name="red">
        <color rgba="1 0 0 1"/>
      </material>
    </visual>
  </link>
  <link name="Rhumerus">
    <inertial>
      <mass value="4.1"/>
      <inertia ixx="0.0402474900573" ixy="0" ixz="0" iyy="0.0402474900573" iyz="0" izz="0.00408235078125"/>
    </inertial>
    <visual>
      <origin rpy="0 0 0" xyz="0 0 -0.1672"/>
      <geometry>
        <cylinder length="0.3344" radius="0.044625"/>
      </geometry>
      <material name="blue">
        <color rgba="0 0 1 1"/>
      </material>
    </visual>
  </link>
  <link name="Lforearm">
    <inertial>
      <mass value="3.8"/>
      <inertia ixx="0.0363768210938" ixy="0" ixz="0" iyy="0.0363768210938" iyz="0" izz="0.0037836421875"/>
    </inertial>
    <visual>
      <origin rpy="0 0 0" xyz="0 0 -0.165"/>
      <geometry>
        <cylinder length="0.33" radius="0.044625"/>
      </geometry>
      <material name="red">
        <color rgba="1 0 0 1"/>
      </material>
    </visual>
  </link>
  <link name="Rforearm">
    <inertial>
      <mass value="3.8"/>
      <inertia ixx="0.0363768210938" ixy="0" ixz="0" iyy="0.0363768210938" iyz="0" izz="0.0037836421875"/>
    </inertial>
    <visual>
      <origin rpy="0 0 0" xyz="0 0 -0.165"/>
      <geometry>
        <cylinder length="0.33" radius="0.044625"/>
      </geometry>
      <material name="blue">
        <color rgba="0 0 1 1"/>
      </material>
    </visual>
  </link>
  <link name="Lhand">
    <inertial>
      <mass value="1.2"/>
      <inertia ixx="0.0016075" ixy="0" ixz="0" iyy="0.0016075" iyz="0" izz="0.001215"/>
    </inertial>
    <visual>
      <origin rpy="0 0 0" xyz="0 0 -0.05"/>
      <geometry>
        <cylinder length="0.1" radius="0.045"/>
      </geometry>
      <material name="red">
        <color rgba="1 0 0 1"/>
      </material>
    </visual>
  </link>
  <link name="Rhand">
    <inertial>
      <mass value="1.2"/>
      <inertia ixx="0.0016075" ixy="0" ixz="0" iyy="0.0016075" iyz="0" izz="0.001215"/>
    </inertial>
    <visual>
      <origin rpy="0 0 0" xyz="0 0 -0.05"/>
      <geometry>
        <cylinder length="0.1" radius="0.045"/>
      </geometry>
      <material name="blue">
        <color rgba="0 0 1 1"/>
      </material>
    </visual>
  </link>
  <link name="torso">
    <inertial>
      <mass value="17"/>
      <inertia ixx="0.750691666667" ixy="0" ixz="0" iyy="0.750691666667" iyz="0" izz="0.19125"/>
    </inertial>
    <visual>
      <origin rpy="0 0 0" xyz="0 0 0.34"/>
      <geometry>
        <cylinder length="0.68" radius="0.15"/>
      </geometry>
      <material name="grey">
        <color rgba=".8 .8 .8 1"/>
      </material>
    </visual>
  </link>
  <link name="neck">
    <inertial>
      <mass value="1"/>
      <inertia ixx="0.000937324033333" ixy="0" ixz="0" iyy="0.000937324033333" iyz="0" izz="0.00125"/>
    </inertial>
    <visual>
      <origin rpy="0 0 0" xyz="0 0 0.03061"/>
      <geometry>
        <cylinder length="0.06122" radius="0.05"/>
      </geometry>
      <material name="Lgrey">
        <color rgba=".6 .6 .6 1"/>
      </material>
    </visual>
  </link> -->
  <link name="base">
    <inertial>
      <mass value="121.06"/>
      <inertia ixx="1.70235" ixy="0" ixz="0" iyy="1.70235" iyz="0" izz="0.5616"/>
    </inertial>
    <visual>
      <origin rpy="0 0 0" xyz="0 0 0"/>
      <geometry>
        <box size="0.4 0.4 0.3"/>
      </geometry>
      <material name="Lgrey">
        <color rgba=".6 .6 .6 1"/>
      </material>
    </visual>
    <collision>
      <origin rpy="0 0 0" xyz="0 0 0"/>
      <geometry>
        <box size="0.4 0.4 0.3"/>
      </geometry>
    </collision>
  </link>
  <link name="LfrontWheel">
    <inertial>
      <mass value="13.51"/>
      <inertia ixx="0.021177" ixy="0" ixz="0" iyy="0.021177" iyz="0" izz="0.0394875"/>
    </inertial>
    <visual>
      <origin rpy="0 0 0" xyz="0 0 0"/>
      <geometry>
        <cylinder length="0.07" radius="0.15"/>
      </geometry>
      <material name="red">
        <color rgba="1 0 0 1"/>
      </material>
    </visual>
    <collision>
      <origin rpy="0 0 0" xyz="0 0 0"/>
      <geometry>
        <cylinder length="0.07" radius="0.15"/>
      </geometry>
    </collision>
  </link>
  <link name="RfrontWheel">
    <inertial>
      <mass value="13.51"/>
      <inertia ixx="0.021177" ixy="0" ixz="0" iyy="0.021177" iyz="0" izz="0.0394875"/>
    </inertial>
    <visual>
      <origin rpy="0 0 0" xyz="0 0 0"/>
      <geometry>
        <cylinder length="0.07" radius="0.15"/>
      </geometry>
      <material name="blue">
        <color rgba="0 0 1 1"/>
      </material>
    </visual>
    <collision>
      <origin rpy="0 0 0" xyz="0 0 0"/>
      <geometry>
        <cylinder length="0.07" radius="0.15"/>
      </geometry>
    </collision>
  </link>
  <link name="LbackWheel">
    <inertial>
      <mass value="13.51"/>
      <inertia ixx="0.021177" ixy="0" ixz="0" iyy="0.021177" iyz="0" izz="0.0394875"/>
    </inertial>
    <visual>
      <origin rpy="0 0 0" xyz="0 0 0"/>
      <geometry>
        <cylinder length="0.07" radius="0.15"/>
      </geometry>
      <material name="red">
        <color rgba="1 0 0 1"/>
      </material>
    </visual>
    <collision>
      <origin rpy="0 0 0" xyz="0 0 0"/>
      <geometry>
        <cylinder length="0.07" radius="0.15"/>
      </geometry>
    </collision>
  </link>
  <link name="RbackWheel">
    <inertial>
      <mass value="13.51"/>
      <inertia ixx="0.021177" ixy="0" ixz="0" iyy="0.021177" iyz="0" izz="0.0394875"/>
    </inertial>
    <visual>
      <origin rpy="0 0 0" xyz="0 0 0"/>
      <geometry>
        <cylinder length="0.07" radius="0.15"/>
      </geometry>
      <material name="blue">
        <color rgba="0 0 1 1"/>
      </material>
    </visual>
    <collision>
      <origin rpy="0 0 0" xyz="0 0 0"/>
      <geometry>
        <cylinder length="0.07" radius="0.15"/>
      </geometry>
    </collision>
  </link>

  <joint name="base_joint" type="fixed">
    <child link="base"/>
    <parent link="base_link"/>
    <origin rpy="0 0 0" xyz="0 0 0"/>
  </joint>

  <joint name="Base_Torso_joint" type="fixed">
    <child link="Torso"/>
    <parent link="base"/>
    <origin rpy="0 0 0" xyz="0 0 0.15"/>
  </joint>

  <joint name="NeckYaw" type="revolute">
    <parent link="Torso"/>
    <child link="NeckYaw_link"/>
    <origin rpy="0 0 0" xyz="0 0 0.87854616"/>
    <axis xyz="0 0 1"/>
    <limit effort="30" lower="-1.5707963259" upper="1.5707963259" velocity="3.0"/>
  </joint>
  <joint name="NeckPitch" type="revolute">
    <parent link="NeckYaw_link"/>
    <child link="NeckPitch_link"/>
    <origin rpy="0 0 0" xyz="0 0 0"/>
    <axis xyz="0 1 0"/>
    <limit effort="30" lower="-0.78539816295" upper="0.78539816295" velocity="3.0"/>
  </joint>
  <joint name="LShoulderRoll" type="revolute">
    <parent link="LShoulderPitch_link"/>
    <child link="LShoulderRoll_link"/>
    <origin rpy="0 0 0" xyz="0 0 0"/>
    <axis xyz="1 0 0"/>
    <limit effort="30" lower="0.0" upper="2.00712863865" velocity="3.0"/>
  </joint>
  <joint name="RShoulderRoll" type="revolute">
    <parent link="RShoulderPitch_link"/>
    <child link="RShoulderRoll_link"/>
    <origin rpy="0 0 0" xyz="0 0 0"/>
    <axis xyz="1 0 0"/>
    <limit effort="30" lower="-2.00712863865" upper="-0.0" velocity="3.0"/>
  </joint>
  <joint name="LShoulderYaw" type="revolute">
    <parent link="base"/>
    <child link="LShoulderYaw_link"/>
    <origin rpy="0 0 0" xyz="0 0.2410587 0.96426384"/>
    <axis xyz="0 0 1"/>
    <limit effort="30" lower="-0.6981317004" upper="1.745329251" velocity="3.0"/>
  </joint>
  <joint name="LShoulderPitch" type="revolute">
    <parent link="LShoulderYaw_link"/>
    <child link="LShoulderPitch_link"/>
    <origin rpy="0 0 0" xyz="0 0 0"/>
    <axis xyz="0 1 0"/>
    <limit effort="30" lower="-1.5707963259" upper="0.8726646255" velocity="3.0"/>
  </joint>
  <joint name="LElbowPitch" type="revolute">
    <parent link="LShoulderRoll_link"/>
    <child link="LElbowPitch_link"/>
    <origin rpy="0 0 0" xyz="0 0 -0.3481959"/>
    <axis xyz="0 1 0"/>
    <limit effort="30" lower="-2.35619448885" upper="0.0" velocity="3.0"/>
  </joint>
  <joint name="LWristYaw" type="revolute">
    <parent link="LElbowPitch_link"/>
    <child link="LWristYaw_link"/>
    <origin rpy="0 0 0" xyz="0 0 -0.3035554"/>
    <axis xyz="0 0 1"/>
    <limit effort="30" lower="-1.48352986335" upper="1.48352986335" velocity="3.0"/>
  </joint>
  <joint name="RShoulderYaw" type="revolute">
    <parent link="base"/>
    <child link="RShoulderYaw_link"/>
    <origin rpy="0 0 0" xyz="0 -0.2410587 0.96426384"/>
    <axis xyz="0 0 1"/>
    <limit effort="30" lower="-0.6981317004" upper="1.745329251" velocity="3.0"/>
  </joint>
  <joint name="RShoulderPitch" type="revolute">
    <parent link="RShoulderYaw_link"/>
    <child link="RShoulderPitch_link"/>
    <origin rpy="0 0 0" xyz="0 0 0"/>
    <axis xyz="0 1 0"/>
    <limit effort="30" lower="-1.5707963259" upper="0.8726646255" velocity="3.0"/>
  </joint>
  <joint name="RElbowPitch" type="revolute">
    <parent link="RShoulderRoll_link"/>
    <child link="RElbowPitch_link"/>
    <origin rpy="0 0 0" xyz="0 0 -0.3481959"/>
    <axis xyz="0 1 0"/>
    <limit effort="30" lower="-2.35619448885" upper="0.0" velocity="3.0"/>
  </joint>
  <joint name="RWristYaw" type="revolute">
    <parent link="RElbowPitch_link"/>
    <child link="RWristYaw_link"/>
    <origin rpy="0 0 0" xyz="0 0 -0.3035554"/>
    <axis xyz="0 0 1"/>
    <limit effort="30" lower="-1.48352986335" upper="1.48352986335" velocity="3.0"/>
  </joint>
  <joint name="LWristRoll" type="revolute">
    <parent link="LWristYaw_link"/>
    <child link="LWristRoll_link"/>
    <origin rpy="0 0 0" xyz="0 0 0"/>
    <axis xyz="1 0 0"/>
    <limit effort="30" lower="-0.5235987753" upper="1.0471975506" velocity="3.0"/>
  </joint>
  <joint name="RWristRoll" type="revolute">
    <parent link="RWristYaw_link"/>
    <child link="RWristRoll_link"/>
    <origin rpy="0 0 0" xyz="0 0 0"/>
    <axis xyz="1 0 0"/>
    <limit effort="30" lower="-1.0471975506" upper="0.5235987753" velocity="3.0"/>
  </joint>

 <!--    <joint name="Rshoulder_pitch" type="revolute">
    <parent link="torso"/>
    <child link="Rhumerus"/>
    <origin rpy="0 0 0" xyz="0 -.175 0.62"/>
    <axis xyz="0 1 0"/>
    <dynamics damping="1"/>
    <limit effort="110" lower="-0.872664625" upper="1.570796325" velocity="30.0"/>
  </joint>
  <joint name="Lshoulder_pitch" type="revolute">
    <parent link="torso"/>
    <child link="Lhumerus"/>
    <origin rpy="0 0 0" xyz="0 .175 0.62"/>
    <axis xyz="0 1 0"/>
    <dynamics damping="1"/>
    <limit effort="110" lower="-0.872664625" upper="1.570796325" velocity="30.0"/>
  </joint>
  <joint name="Lelbow_pitch" type="revolute">
    <parent link="Lhumerus"/>
    <child link="Lforearm"/>
    <origin rpy="0 0 0" xyz="0 0 -0.3344"/>
    <axis xyz="0 1 0"/>
    <dynamics damping="1"/>
    <limit effort="100" lower="0.0" upper="2.3561944875" velocity="30.0"/>
  </joint>
  <joint name="Relbow_pitch" type="revolute">
    <parent link="Rhumerus"/>
    <child link="Rforearm"/>
    <origin rpy="0 0 0" xyz="0 0 -0.3344"/>
    <axis xyz="0 1 0"/>
    <dynamics damping="1"/>
    <limit effort="100" lower="0.0" upper="2.3561944875" velocity="30.0"/>
  </joint>
  <joint name="Lwrist" type="fixed">
    <parent link="Lforearm"/>
    <child link="Lhand"/>
    <origin rpy="0 0 0" xyz="0 0 -0.33"/>
  </joint>
  <joint name="Rwrist" type="fixed">
    <parent link="Rforearm"/>
    <child link="Rhand"/>
    <origin rpy="0 0 0" xyz="0 0 -0.33"/>
  </joint>
  <joint name="neck_pitch" type="revolute">
    <parent link="torso"/>
    <child link="neck"/>
    <origin rpy="0 0 0" xyz="0 0 0.68"/>
    <axis xyz="0 1 0"/>
    <dynamics damping="1"/>
    <limit effort="25" lower="-0.7853981625" upper="0.7853981625" velocity="30.0"/>
  </joint>
  <joint name="head" type="fixed">
    <parent link="neck"/>
    <child link="head"/>
    <origin rpy="0 0 0" xyz="0 0 0.13122"/>
  </joint>
  <joint name="hip" type="fixed">
    <parent link="torso"/>
    <child link="base"/>
    <origin rpy="0 0 0" xyz="0 0 -0.45"/>
  </joint> -->
  <joint name="RfrontWheel_joint" type="continuous">
    <parent link="base"/>
    <child link="RfrontWheel"/>
    <origin rpy="0 1.570796325 1.570796325" xyz="-0.2 -0.235 -0.15"/>
    <axis xyz="0 0 1"/>
     <dynamics damping="1"/> 
  </joint>
  <joint name="LfrontWheel_joint" type="continuous">
    <parent link="base"/>
    <child link="LfrontWheel"/>
    <origin rpy="0 1.570796325 1.570796325" xyz="-0.2 0.235 -0.15"/>
    <axis xyz="0 0 1"/>
     <dynamics damping="1"/> 
  </joint>
  <joint name="RbackWheel_joint" type="continuous">
    <parent link="base"/>
    <child link="RbackWheel"/>
    <origin rpy="0 1.570796325 1.570796325" xyz="0.2 -0.235 -0.15"/>
    <axis xyz="0 0 1"/>
     <dynamics damping="1"/> 
  </joint>
  <joint name="LbackWheel_joint" type="continuous">
    <parent link="base"/>
    <child link="LbackWheel"/>
    <origin rpy="0 1.570796325 1.570796325" xyz="0.2 0.235 -0.15"/>
    <axis xyz="0 0 1"/>
    <dynamics damping="1"/> 
  </joint>
 <!--  <transmission name="Lshoulder_pitch_act" type="SimpleTransmission">
    <actuator name="Lshoulder_pitch_tranny"/>
    <joint name="Lshoulder_pitch"/>
    <mechanicalReduction>1</mechanicalReduction>
  </transmission>
  <transmission name="Rshoulder_pitch_act" type="SimpleTransmission">
    <actuator name="Rshoulder_pitch_tranny"/>
    <joint name="Rshoulder_pitch"/>
    <mechanicalReduction>1</mechanicalReduction>
  </transmission>
  <transmission name="Lelbow_pitch_act" type="SimpleTransmission">
    <actuator name="Lelbow_pitch_tranny"/>
    <joint name="Lelbow_pitch"/>
    <mechanicalReduction>1</mechanicalReduction>
  </transmission>
  <transmission name="Relbow_pitch_act" type="SimpleTransmission">
    <actuator name="Relbow_pitch_tranny"/>
    <joint name="Relbow_pitch"/>
    <mechanicalReduction>1</mechanicalReduction>
  </transmission>
  <transmission name="LbackWheel_act" type="SimpleTransmission">
    <actuator name="LbackWheel_tranny"/>
    <joint name="LbackWheel"/>
    <mechanicalReduction>1</mechanicalReduction>
  </transmission>
  <transmission name="RbackWheel_act" type="SimpleTransmission">
    <actuator name="RbackWheel_tranny"/>
    <joint name="RbackWheel"/>
    <mechanicalReduction>1</mechanicalReduction>
  </transmission>
  <transmission name="LfrontWheel_act" type="SimpleTransmission">
    <actuator name="LfrontWheel_tranny"/>
    <joint name="LfrontWheel"/>
    <mechanicalReduction>1</mechanicalReduction>
  </transmission>
  <transmission name="RfrontWheel_act" type="SimpleTransmission">
    <actuator name="RfrontWheel_tranny"/>
    <joint name="RfrontWheel"/>
    <mechanicalReduction>1</mechanicalReduction>
  </transmission>
  <transmission name="neck_pitch_act" type="SimpleTransmission">
    <actuator name="neck_pitch_tranny"/>
    <joint name="neck_pitch"/>
    <mechanicalReduction>1</mechanicalReduction>
  </transmission> -->

        <gazebo>
            <controller:diffdrive_plugin name="differential_drive_controller" plugin="libfourWheeled_diffdrive_plugin_pre_fuerte.so">
                <alwaysOn>true</alwaysOn>
		<update>100</update>
		<updateRate>100.0</updateRate>
                <frontleftJoint>LfrontWheel_joint</frontleftJoint>
                <frontrightJoint>RfrontWheel_joint</frontrightJoint>
                <rearleftJoint>LbackWheel_joint</rearleftJoint>
                <rearrightJoint>RbackWheel_joint</rearrightJoint>
                <wheelSeparation>0.47</wheelSeparation>
                <wheelDiameter>0.15</wheelDiameter>
                <torque>100</torque>
                <interface:position name="position_iface_0"/>
                <topicName>cmd_vel</topicName>
            </controller:diffdrive_plugin>

    	  <controller:gazebo_ros_pub_robot_state name="gazebo_ros_pub_robot_controller" plugin="libgazebo_ros_pub_robot_state_pre_fuerte.so">
     	   	<alwaysOn>true</alwaysOn>
     	   	<updateRate>100.0</updateRate>
      	  	<topicName>true_robot_state</topicName>
     	 </controller:gazebo_ros_pub_robot_state>                
	    
	</gazebo>

</robot>

